Workbook

Sheet Height
A1: CCID | B1: DOY152 | C1: DOY157 | D1: DOY164 | E1: DOY178 | F1: DOY186 | G1: DOY192 | H1: DOY206 | I1: DOY220 | J1: DOY227 | K1: DOY234 | L1: DOY241 | M1: DOY251
A2: p01-1N | B2: 7 | C2: 13 | D2: 23 | E2: 43 | F2: 58 | G2: 70 | H2: 85 | I2: 83 | J2: 84 | K2: 85 | L2: 82 | M2: 87
A3: p01-1M | B3: 7 | C3: 13 | D3: 21 | E3: 44 | F3: 68 | G3: 76 | H3: 81 | I3: 102 | J3: 106 | K3: 110 | L3: 112 | M3: 113
A4: p01-1S | B4: 5 | C4: 11 | D4: 23 | E4: 46 | F4: 61 | G4: 70 | H4: 85 | I4: 102 | J4: 108 | K4: 113 | L4: 115 | M4: 122
A5: p01-2N | B5: 6 | C5: 13 | D5: 20 | E5: 40 | F5: 52 | G5: 53 | H5: 58 | I5: 74 | J5: 78 | K5: 80 | L5: 81 | M5: 74
A6: p01-2M | B6: 5 | C6: 11 | D6: 17 | E6: 37 | F6: 63 | G6: 69 | H6: 84 | I6: 103 | J6: 104 | K6: 106 | L6: 102 | M6: 108
A7: p01-2S | B7: 6 | C7: 11 | D7: 16 | E7: 35 | F7: 56 | G7: 56 | H7: 59 | I7: 76 | J7: 75 | K7: 76 | L7: 75 | M7: 77
A8: p01-3N | B8: 6 | C8: 10 | D8: 14 | E8: 37 | F8: 53 | G8: 62 | H8: 77 | I8: 94 | J8: 93 | K8: 94 | L8: 93 | M8: 87
A9: p01-3M | B9: 6 | C9: 11 | D9: 16 | E9: 38 | F9: 60 | G9: 65 | H9: 79 | I9: 95 | J9: 97 | K9: 97 | L9: 96 | M9: 95
A10: p01-3S | B10: 5 | C10: 9 | D10: 16 | E10: 35 | F10: 46 | G10: 49 | H10: 59 | I10: 62 | J10: 65 | K10: 67 | L10: 68 | M10: 53
A11: p01-4N | B11: 5 | C11: 9 | D11: 10 | E11: 24 | F11: 32 | G11: 37 | H11: 44 | I11: 57 | J11: 66 | K11: 69 | L11: 70 | M11: 72
A12: p01-4M | B12: 7 | C12: 10 | D12: 14 | E12: 38 | F12: 51 | G12: 60 | H12: 81 | I12: 103 | J12: 108 | K12: 113 | L12: 116 | M12: 117
A13: p01-4S | B13: 6 | C13: 9 | D13: 11 | E13: 31 | F13: 47 | G13: 55 | H13: 72 | I13: 83 | J13: 87 | K13: 88 | L13: 89 | M13: 88
... A145: p12-4S | B145: 6 | C145: 10 | D145: 15 | E145: 37 | F145: 52 | G145: 56 | H145: 65 | I145: 72 | J145: 75 | K145: 78 | L145: 80 | M145: 80

Sheet Width
A1: CCID | B1: DOY152 | C1: DOY157 | D1: DOY164 | E1: DOY178 | F1: DOY186 | G1: DOY192 | H1: DOY206 | I1: DOY220 | J1: DOY227 | K1: DOY234 | L1: DOY241 | M1: DOY251
A2: p01-1N | B2: 8 | C2: 14 | D2: 24 | E2: 42 | F2: 51 | G2: 65 | H2: 81 | I2: 83 | J2: 83 | K2: 84 | L2: 84 | M2: 84
A3: p01-1M | B3: 7 | C3: 15 | D3: 23 | E3: 41 | F3: 53 | G3: 61 | H3: 67 | I3: 91 | J3: 95 | K3: 98 | L3: 100 | M3: 102
A4: p01-1S | B4: 6 | C4: 13 | D4: 23 | E4: 45 | F4: 58 | G4: 67 | H4: 74 | I4: 102 | J4: 102 | K4: 102 | L4: 102 | M4: 102
A5: p01-2N | B5: 7 | C5: 13 | D5: 21 | E5: 38 | F5: 49 | G5: 53 | H5: 56 | I5: 72 | J5: 76 | K5: 80 | L5: 83 | M5: 90
A6: p01-2M | B6: 6 | C6: 13 | D6: 18 | E6: 37 | F6: 60 | G6: 69 | H6: 75 | I6: 102 | J6: 102 | K6: 102 | L6: 102 | M6: 102
A7: p01-2S | B7: 8 | C7: 12 | D7: 18 | E7: 34 | F7: 51 | G7: 58 | H7: 61 | I7: 66 | J7: 73 | K7: 81 | L7: 85 | M7: 89
A8: p01-3N | B8: 7 | C8: 12 | D8: 15 | E8: 40 | F8: 49 | G8: 60 | H8: 68 | I8: 83 | J8: 93 | K8: 98 | L8: 100 | M8: 100
A9: p01-3M | B9: 8 | C9: 12 | D9: 16 | E9: 37 | F9: 53 | G9: 68 | H9: 77 | I9: 91 | J9: 91 | K9: 90 | L9: 91 | M9: 99
A10: p01-3S | B10: 5 | C10: 11 | D10: 17 | E10: 36 | F10: 43 | G10: 46 | H10: 50 | I10: 54 | J10: 56 | K10: 57 | L10: 58 | M10: 50
A11: p01-4N | B11: 6 | C11: 11 | D11: 11 | E11: 25 | F11: 31 | G11: 34 | H11: 38 | I11: 45 | J11: 49 | K11: 52 | L11: 54 | M11: 102
A12: p01-4M | B12: 8 | C12: 11 | D12: 16 | E12: 40 | F12: 47 | G12: 64 | H12: 77 | I12: 94 | J12: 101 | K12: 102 | L12: 102 | M12: 102
A13: p01-4S | B13: 7 | C13: 10 | D13: 13 | E13: 32 | F13: 42 | G13: 54 | H13: 62 | I13: 80 | J13: 86 | K13: 88 | L13: 92 | M13: 102
... A145: p12-4S | B145: 7 | C145: 13 | D145: 16 | E145: 34 | F145: 43 | G145: 53 | H145: 61 | I145: 66 | J145: 76 | K145: 81 | L145: 82 | M145: 83

Sheet Density
A1: CCID | B1: PLAPD
A2: p01-1M | B2: 7.6552931
A3: p01-2M | B3: 7.6552931
A4: p01-3M | B4: 9.4050744
A5: p01-4M | B5: 9.1863517
A6: p02-1M | B6: 8.3114611
A7: p02-2M | B7: 7.6552931
A8: p02-3M | B8: 8.0927384
A9: p02-4M | B9: 8.5301837
A10: p03-1M | B10: 7.2178478
A11: p03-2M | B11: 10.061242
A12: p03-3M | B12: 6.9991251
A13: p03-4M | B13: 8.5301837
... A49: p12-4M | B49: 4.5931759

Sheet Develop
A1: CCID | B1: EDATE | C1: PLYRE | D1: PLDOE | E1: LF1D
A2: p01-1M | B2: 44685 | C2: 2022 | D2: 124.25 | E2: 44695
A3: p01-2M | B3: 44684 | C3: 2022 | D3: 122.5 | E3: 44695
A4: p01-3M | B4: 44685 | C4: 2022 | D4: 124.1 | E4: 44696
A5: p01-4M | B5: 44684 | C5: 2022 | D5: 123 | E5: 44695
A6: p02-1M | B6: 44682 | C6: 2022 | D6: 121.25 | E6: 44693
A7: p02-2M | B7: 44682 | C7: 2022 | D7: 121 | E7: 44694
A8: p02-3M | B8: 44682 | C8: 2022 | D8: 120.5 | E8: 44692
A9: p02-4M | B9: 44682 | C9: 2022 | D9: 120.8 | E9: 44693
A10: p03-1M | B10: 44685 | C10: 2022 | D10: 124.25 | E10: 44696
A11: p03-2M | B11: 44682 | C11: 2022 | D11: 121.35714 | E11: 44695
A12: p03-3M | B12: 44682 | C12: 2022 | D12: 120.8 | E12: 44695
A13: p03-4M | B13: 44685 | C13: 2022 | D13: 124.125 | E13: 44697
... A49: p12-4M | B49: 44684 | C49: 2022 | D49: 122.75 | E49: 44701

Sheet PlotDevelop
A1: Plot | B1: EDATE | C1: PLYRE | D1: PLDOE | E1: LF1D | F1: NAWF186 | G1: NAWF192 | H1: NAWF206 | I1: NAWF220 | J1: NAWF227 | K1: NAWF234 | L1: NAWF241 | M1: NAWF251
A2: p01-1 | B2: 44685 | C2: 2022 | D2: 124.25 | E2: 44695 | F2: 8.5 | G2: 6.4444444 | H2: 2.7777778 | I2: 3.5555556 | J2: 3 | K2: 2.8888889 | L2: 3.1111111 | M2: 0.66666667
A3: p01-2 | B3: 44684 | C3: 2022 | D3: 122.5 | E3: 44695 | F3: 7.3333333 | G3: 5.7777778 | H3: 2.8888889 | I3: 3.3333333 | J3: 1.4444444 | K3: 1.1111111 | L3: 0.88888889 | M3: 0.11111111
A4: p01-3 | B4: 44685 | C4: 2022 | D4: 124.1 | E4: 44696 | F4: 8 | G4: 6.3333333 | H4: 3.3333333 | I4: 3.3333333 | J4: 1.4444444 | K4: 1 | L4: 0.55555556 | M4: 0
A5: p01-4 | B5: 44684 | C5: 2022 | D5: 123 | E5: 44695 | F5: 8.3333333 | G5: 6.4444444 | H5: 3.5555556 | I5: 3.4444444 | J5: 3 | K5: 3 | L5: 2.6666667 | M5: 1.3333333
A6: p02-1 | B6: 44682 | C6: 2022 | D6: 121.25 | E6: 44693 | F6: 8.6666667 | G6: 6.6666667 | H6: 3.7777778 | I6: 3.6666667 | J6: 3.4444444 | K6: 3.5555556 | L6: 3 | M6: 1.3333333
A7: p02-2 | B7: 44682 | C7: 2022 | D7: 121 | E7: 44694 | F7: 8.2222222 | G7: 6.3333333 | H7: 2.6666667 | I7: 3.3333333 | J7: 1.7777778 | K7: 1.3333333 | L7: 0.66666667 | M7: 0.77777778
A8: p02-3 | B8: 44682 | C8: 2022 | D8: 120.5 | E8: 44692 | F8: 8.4444444 | G8: 6.1111111 | H8: 2.6666667 | I8: 3 | J8: 1.7777778 | K8: 1.6666667 | L8: 1.1111111 | M8: 0.4
A9: p02-4 | B9: 44682 | C9: 2022 | D9: 120.8 | E9: 44693 | F9: 7.3333333 | G9: 5.6666667 | H9: 3.3333333 | I9: 4.8888889 | J9: 3.8888889 | K9: 3.6666667 | L9: 3 | M9: 0.77777778
A10: p03-1 | B10: 44685 | C10: 2022 | D10: 124.25 | E10: 44696 | F10: 7.7777778 | G10: 6.1111111 | H10: 3.4444444 | I10: 3.6666667 | J10: 3.1111111 | K10: 3.2222222 | L10: 2.2222222 | M10: 1.5555556
A11: p03-2 | B11: 44682 | C11: 2022 | D11: 121.35714 | E11: 44695 | F11: 8.4444444 | G11: 6.2222222 | H11: 2.6666667 | I11: 3.6666667 | J11: 3.4444444 | K11: 3.2222222 | L11: 2.6666667 | M11: 1.4444444
A12: p03-3 | B12: 44682 | C12: 2022 | D12: 120.8 | E12: 44695 | F12: 8.7777778 | G12: 6.8888889 | H12: 3.8888889 | I12: 3.6666667 | J12: 3.1111111 | K12: 3.2222222 | L12: 2.5555556 | M12: 0.55555556
A13: p03-4 | B13: 44685 | C13: 2022 | D13: 124.125 | E13: 44697 | F13: 8.8888889 | G13: 7.1111111 | H13: 4 | I13: 4.8888889 | J13: 4.5555556 | K13: 4.3333333 | L13: 3.5555556 | M13: 1.5555556
... A49: p12-4 | B49: 44684 | C49: 2022 | D49: 122.75 | E49: 44701 | F49: 8.3333333 | G49: 6.4444444 | H49: 3.2222222 | I49: 3.5555556 | J49: 2 | K49: 1.5555556 | L49: 0.88888889 | M49: 0.6

Sheet Ordering
A1: 1 | B1: 1 | C1: N | D1: =_xlfn.CONCAT("p",TEXT(A1,"00"),"-",TEXT(B1,"0"),C1) -> p01-1N | F1: 1
A2: 1 | B2: 1 | C2: M | D2: =_xlfn.CONCAT("p",TEXT(A2,"00"),"-",TEXT(B2,"0"),C2) -> p01-1M | F2: 2
A3: 1 | B3: 1 | C3: S | D3: =_xlfn.CONCAT("p",TEXT(A3,"00"),"-",TEXT(B3,"0"),C3) -> p01-1S | F3: 3
A4: 1 | B4: 2 | C4: N | D4: =_xlfn.CONCAT("p",TEXT(A4,"00"),"-",TEXT(B4,"0"),C4) -> p01-2N | F4: 4
A5: 1 | B5: 2 | C5: M | D5: =_xlfn.CONCAT("p",TEXT(A5,"00"),"-",TEXT(B5,"0"),C5) -> p01-2M | F5: 5
A6: 1 | B6: 2 | C6: S | D6: =_xlfn.CONCAT("p",TEXT(A6,"00"),"-",TEXT(B6,"0"),C6) -> p01-2S | F6: 6
A7: 1 | B7: 3 | C7: N | D7: =_xlfn.CONCAT("p",TEXT(A7,"00"),"-",TEXT(B7,"0"),C7) -> p01-3N | F7: 7
A8: 1 | B8: 3 | C8: M | D8: =_xlfn.CONCAT("p",TEXT(A8,"00"),"-",TEXT(B8,"0"),C8) -> p01-3M | F8: 8
A9: 1 | B9: 3 | C9: S | D9: =_xlfn.CONCAT("p",TEXT(A9,"00"),"-",TEXT(B9,"0"),C9) -> p01-3S | F9: 9
A10: 1 | B10: 4 | C10: N | D10: =_xlfn.CONCAT("p",TEXT(A10,"00"),"-",TEXT(B10,"0"),C10) -> p01-4N | F10: 10
A11: 1 | B11: 4 | C11: M | D11: =_xlfn.CONCAT("p",TEXT(A11,"00"),"-",TEXT(B11,"0"),C11) -> p01-4M | F11: 11
A12: 1 | B12: 4 | C12: S | D12: =_xlfn.CONCAT("p",TEXT(A12,"00"),"-",TEXT(B12,"0"),C12) -> p01-4S | F12: 12
... A144: 12 | B144: 1 | C144: N | D144: =_xlfn.CONCAT("p",TEXT(A144,"00"),"-",TEXT(B144,"0"),C144) -> p12-1N | F144: 133

Sheet Blank Data Sheet
A1: 2022 | B1: F13b4 | E1: date: | I1: doy:
B2: Cotton | F2: time:
A3: Canopy Heights & Widths | F3: by:
B5: Canopy Heights in row 5. Three measurements per plot.
B6: At both the Canopy Measurement points and the LAI (?) measurement flags.
B7: Canopy Height & LAI flags may not be exactly at the GPS points - I adjusted depending on skips in rows. SMM
B8: Plot | D8: Flag | E8: Canopy Height (cm) | F8: Canopy Width (cm) | G8: NAWF | H8: NAWF | I8: NAWF
B9: 01- | C9: 1 | D9: North
D10: Mid
D11: South
B12: 01- | C12: 2 | D12: North
D13: Mid
D14: South
B15: 01- | C15: 3 | D15: North
D16: Mid
D17: South
B18: 01- | C18: 4 | D18: North
D19: Mid
D20: South
B21: 02- | C21: 4 | D21: South
D22: Mid
D23: North
B24: 02- | C24: 3 | D24: South
D25: Mid
D26: North
B27: 02- | C27: 2 | D27: South
D28: Mid
D29: North
B30: 02- | C30: 1 | D30: South
D31: Mid
D32: North
B33: 03- | C33: 1 | D33: North
D34: Mid
D35: South
B36: 03- | C36: 2 | D36: North
D37: Mid
D38: South
B39: 03- | C39: 3 | D39: North
D40: Mid
D41: South
...

Sheet Height Summary
A1: Summary | B1: 2022 | D1: F13b4 | G1: Cotton
B3: Canopy Heights - Summary
D8: Initials: | G8: SMM | H8: SMM | I8: SMM | J8: SMM | K8: SMM | L8: SMM | M8: SMM | N8: SMM | O8: SMM | P8: SMM | Q8: SMM | R8: SMM
D9: Date: | G9: 44713 | H9: 44718 | I9: 44725 | J9: 44739 | K9: 44747 | L9: 44753 | M9: 44767 | N9: 44781 | O9: 44788 | P9: 22-23 Aug 2022 | Q9: 44802 | R9: 44812
D10: DOY: | G10: 152 | H10: 157 | I10: 164 | J10: 178 | K10: 186 | L10: 192 | M10: 206 | N10: 220 | O10: 227 | P10: 234-235 | Q10: 241 | R10: 251
D11: Time: | G11: 1400-1515h | H11: 1030-1145 | I11: 0940-1045 | J11: 1015-1245 | K11: 1300-1715 | L11: 0945-1230 | M11: 1015-1315 | N11: 1030-1345 | O11: 1000-13:15 | Q11: 1200-1415 | R11: 1015-1245
B12: Plot | D12: Flag | E12: TRT | F12: Var | G12: Height (cm) | H12: Height (cm) | I12: Height (cm) | J12: Height (cm) | K12: Height (cm) | L12: Height (cm) | M12: Height (cm) | N12: Height (cm) | O12: Height (cm) | P12: Height (cm) | Q12: Height (cm) | R12: Height (cm)
B13: 01- | C13: 1 | D13: North | E13: FAO | F13: NG4936 | G13: 7 | H13: 13 | I13: 23 | J13: 43 | K13: 58 | L13: 70 | M13: 85 | N13: 83 | O13: 84 | P13: 85 | Q13: 82 | R13: 87
D14: Mid | E14: FAO | F14: NG4936 | G14: 7 | H14: 13 | I14: 21 | J14: 44 | K14: 68 | L14: 76 | M14: 81 | N14: 102 | O14: 106 | P14: 110 | Q14: 112 | R14: 113
D15: South | E15: FAO | F15: NG4936 | G15: 5 | H15: 11 | I15: 23 | J15: 46 | K15: 61 | L15: 70 | M15: 85 | N15: 102 | O15: 108 | P15: 113 | Q15: 115 | R15: 122
B16: 01- | C16: 2 | D16: North | E16: FAO-N | F16: NG4936 | G16: 6 | H16: 13 | I16: 20 | J16: 40 | K16: 52 | L16: 53 | M16: 58 | N16: 74 | O16: 78 | P16: 80 | Q16: 81 | R16: 74
D17: Mid | E17: FAO-N | F17: NG4936 | G17: 5 | H17: 11 | I17: 17 | J17: 37 | K17: 63 | L17: 69 | M17: 84 | N17: 103 | O17: 104 | P17: 106 | Q17: 102 | R17: 108
D18: South | E18: FAO-N | F18: NG4936 | G18: 6 | H18: 11 | I18: 16 | J18: 35 | K18: 56 | L18: 56 | M18: 59 | N18: 76 | O18: 75 | P18: 76 | Q18: 75 | R18: 77
B19: 01- | C19: 3 | D19: North | E19: AQC-N | F19: NG4936 | G19: 6 | H19: 10 | I19: 14 | J19: 37 | K19: 53 | L19: 62 | M19: 77 | N19: 94 | O19: 93 | P19: 94 | Q19: 93 | R19: 87
D20: Mid | E20: AQC-N | F20: NG4936 | G20: 6 | H20: 11 | I20: 16 | J20: 38 | K20: 60 | L20: 65 | M20: 79 | N20: 95 | O20: 97 | P20: 97 | Q20: 96 | R20: 95
D21: South | E21: AQC-N | F21: NG4936 | G21: 5 | H21: 9 | I21: 16 | J21: 35 | K21: 46 | L21: 49 | M21: 59 | N21: 62 | O21: 65 | P21: 67 | Q21: 68 | R21: 53
B22: 01- | C22: 4 | D22: North | E22: CSM | F22: NG4936 | G22: 5 | H22: 9 | I22: 10 | J22: 24 | K22: 32 | L22: 37 | M22: 44 | N22: 57 | O22: 66 | P22: 69 | Q22: 70 | R22: 72
D23: Mid | E23: CSM | F23: NG4936 | G23: 7 | H23: 10 | I23: 14 | J23: 38 | K23: 51 | L23: 60 | M23: 81 | N23: 103 | O23: 108 | P23: 113 | Q23: 116 | R23: 117
D24: South | E24: CSM | F24: NG4936 | G24: 6 | H24: 9 | I24: 11 | J24: 31 | K24: 47 | L24: 55 | M24: 72 | N24: 83 | O24: 87 | P24: 88 | Q24: 89 | R24: 88
B25: 02- | C25: 4 | D25: South | E25: CSM | F25: NG3195 | G25: 10 | H25: 15 | I25: 23 | J25: 39 | K25: 50 | L25: 56 | M25: 66 | N25: 79 | O25: 86 | P25: 95 | Q25: 97 | R25: 94
D26: Mid | E26: CSM | F26: NG3195 | G26: 12 | H26: 16 | I26: 23 | J26: 59 | K26: 67 | L26: 70 | M26: 80 | N26: 93 | O26: 99 | P26: 101 | Q26: 102 | R26: 101
D27: North | E27: CSM | F27: NG3195 | G27: 10 | H27: 15 | I27: 23 | J27: 57 | K27: 72 | L27: 79 | M27: 89 | N27: 96 | O27: 100 | P27: 106 | Q27: 108 | R27: 105
B28: 02- | C28: 3 | D28: South | E28: AQC-N | F28: NG3195 | G28: 11 | H28: 16 | I28: 22 | J28: 56 | K28: 72 | L28: 75 | M28: 77 | N28: 87 | O28: 89 | P28: 90 | Q28: 86 | R28: 86
D29: Mid | E29: AQC-N | F29: NG3195 | G29: 10 | H29: 15 | I29: 23 | J29: 58 | K29: 73 | L29: 77 | M29: 89 | N29: 103 | O29: 106 | P29: 107 | Q29: 110 | R29: 108
D30: North | E30: AQC-N | F30: NG3195 | G30: 12 | H30: 17 | I30: 26 | J30: 52 | K30: 69 | L30: 71 | M30: 79 | N30: 91 | O30: 93 | P30: 95 | Q30: 94 | R30: 92
B31: 02- | C31: 2 | D31: South | E31: FAO-N | F31: NG3195 | G31: 10 | H31: 15 | I31: 24 | J31: 58 | K31: 74 | L31: 73 | M31: 77 | N31: 90 | O31: 94 | P31: 93 | Q31: 93 | R31: 91
D32: Mid | E32: FAO-N | F32: NG3195 | G32: 11 | H32: 16 | I32: 22 | J32: 52 | K32: 71 | L32: 73 | M32: 80 | N32: 100 | O32: 103 | P32: 105 | Q32: 105 | R32: 106
D33: North | E33: FAO-N | F33: NG3195 | G33: 13 | H33: 19 | I33: 28 | J33: 68 | K33: 82 | L33: 83 | M33: 91 | N33: 111 | O33: 114 | P33: 116 | Q33: 117 | R33: 113
B34: 02- | C34: 1 | D34: South | E34: FAO | F34: NG3195 | G34: 14 | H34: 20 | I34: 23 | J34: 63 | K34: 71 | L34: 80 | M34: 93 | N34: 105 | O34: 110 | P34: 113 | Q34: 116 | R34: 115
D35: Mid | E35: FAO | F35: NG3195 | G35: 11 | H35: 18 | I35: 30 | J35: 59 | K35: 78 | L35: 83 | M35: 97 | N35: 114 | O35: 119 | P35: 122 | Q35: 124 | R35: 128
D36: North | E36: FAO | F36: NG3195 | G36: 15 | H36: 22 | I36: 33 | J36: 65 | K36: 84 | L36: 89 | M36: 99 | N36: 116 | O36: 118 | P36: 120 | Q36: 121 | R36: 120
B37: 03- | C37: 1 | D37: North | E37: CSM | F37: NG4936 | G37: 8 | H37: 13 | I37: 26 | J37: 57 | K37: 75 | L37: 87 | M37: 102 | N37: 115 | O37: 118 | P37: 121 | Q37: 123 | R37: 122
D38: Mid | E38: CSM | F38: NG4936 | G38: 8 | H38: 12 | I38: 19 | J38: 35 | K38: 53 | L38: 57 | M38: 70 | N38: 81 | O38: 86 | P38: 90 | Q38: 93 | R38: 92
D39: South | E39: CSM | F39: NG4936 | G39: 7 | H39: 11 | I39: 21 | J39: 51 | K39: 73 | L39: 83 | M39: 97 | N39: 121 | O39: 123 | P39: 125 | Q39: 126 | R39: 131
B40: 03- | C40: 2 | D40: North | E40: CSM-N | F40: NG4936 | G40: 11 | H40: 15 | I40: 20 | J40: 45 | K40: 63 | L40: 65 | M40: 71 | N40: 84 | O40: 90 | P40: 94 | Q40: 99 | R40: 104
D41: Mid | E41: CSM-N | F41: NG4936 | G41: 7 | H41: 11 | I41: 17 | J41: 41 | K41: 62 | L41: 69 | M41: 79 | N41: 98 | O41: 99 | P41: 100 | Q41: 103 | R41: 105
D42: South | E42: CSM-N | F42: NG4936 | G42: 9 | H42: 13 | I42: 22 | J42: 55 | K42: 78 | L42: 82 | M42: 93 | N42: 96 | O42: 100 | P42: 113 | Q42: 112 | R42: 115
B43: 03- | C43: 3 | D43: North | E43: AQC | F43: NG4936 | G43: 10 | H43: 15 | I43: 24 | J43: 52 | K43: 73 | L43: 75 | M43: 84 | N43: 101 | O43: 104 | P43: 108 | Q43: 109 | R43: 111
D44: Mid | E44: AQC | F44: NG4936 | G44: 9 | H44: 14 | I44: 20 | J44: 45 | K44: 70 | L44: 76 | M44: 92 | N44: 108 | O44: 109 | P44: 107 | Q44: 108 | R44: 104
D45: South | E45: AQC | F45: NG4936 | G45: 7 | H45: 13 | I45: 18 | J45: 31 | K45: 50 | L45: 51 | M45: 54 | N45: 64 | O45: 69 | P45: 71 | Q45: 76 | R45: 79
...

Sheet Cover Summary
A1: Summary | B1: 2022 | D1: F13b4 | G1: Cotton
B3: Canopy Heights - Summary | H3: "--" = closed canopy
D8: Initials: | G8: ='Height Summary'!G8 -> SMM | H8: ='Height Summary'!H8 -> SMM | I8: ='Height Summary'!I8 -> SMM | J8: ='Height Summary'!J8 -> SMM | K8: ='Height Summary'!K8 -> SMM | L8: ='Height Summary'!L8 -> SMM | M8: ='Height Summary'!M8 -> SMM | N8: ='Height Summary'!N8 -> SMM | ... R8: ='Height Summary'!R8 -> SMM
D9: Date: | G9: ='Height Summary'!G9 -> 44713 | H9: ='Height Summary'!H9 -> 44718 | I9: ='Height Summary'!I9 -> 44725 | J9: ='Height Summary'!J9 -> 44739 | K9: ='Height Summary'!K9 -> 44747 | L9: ='Height Summary'!L9 -> 44753 | M9: ='Height Summary'!M9 -> 44767 | N9: ='Height Summary'!N9 -> 44781 | ... R9: ='Height Summary'!R9 -> 44812
D10: DOY: | G10: ='Height Summary'!G10 -> 152 | H10: ='Height Summary'!H10 -> 157 | I10: ='Height Summary'!I10 -> 164 | J10: ='Height Summary'!J10 -> 178 | K10: ='Height Summary'!K10 -> 186 | L10: ='Height Summary'!L10 -> 192 | M10: ='Height Summary'!M10 -> 206 | N10: ='Height Summary'!N10 -> 220 | ... R10: ='Height Summary'!R10 -> 251
D11: Time: | G11: ='Height Summary'!G11 -> 1400-1515h | H11: ='Height Summary'!H11 -> 1030-1145 | I11: ='Height Summary'!I11 -> 0940-1045 | J11: ='Height Summary'!J11 -> 1015-1245 | K11: ='Height Summary'!K11 -> 1300-1715 | L11: ='Height Summary'!L11 -> 0945-1230 | M11: ='Height Summary'!M11 -> 1015-1315 | N11: ='Height Summary'!N11 -> 1030-1345 | ... R11: ='Height Summary'!R11 -> 1015-1245
B12: Plot | D12: Flag | E12: TRT | F12: Var | G12: Width (cm) | H12: Width (cm) | I12: Width (cm) | J12: Width (cm) | K12: Width (cm) | L12: Width (cm) | M12: Width (cm) | N12: Width (cm) | O12: Width (cm) | P12: Width (cm) | Q12: Width (cm) | R12: Width (cm)
B13: 01- | C13: 1 | D13: North | E13: FAO | F13: NG4936 | G13: 8 | H13: 14 | I13: 24 | J13: 42 | K13: 51 | L13: 65 | M13: 81 | N13: 83 | O13: 83 | P13: 84 | Q13: 84 | R13: 84
D14: Mid | E14: FAO | F14: NG4936 | G14: 7 | H14: 15 | I14: 23 | J14: 41 | K14: 53 | L14: 61 | M14: 67 | N14: 91 | O14: 95 | P14: 98 | Q14: 100 | R14: --
D15: South | E15: FAO | F15: NG4936 | G15: 6 | H15: 13 | I15: 23 | J15: 45 | K15: 58 | L15: 67 | M15: 74 | N15: -- | O15: -- | P15: -- | Q15: -- | R15: --
B16: 01- | C16: 2 | D16: North | E16: FAO-N | F16: NG4936 | G16: 7 | H16: 13 | I16: 21 | J16: 38 | K16: 49 | L16: 53 | M16: 56 | N16: 72 | O16: 76 | P16: 80 | Q16: 83 | R16: 90
D17: Mid | E17: FAO-N | F17: NG4936 | G17: 6 | H17: 13 | I17: 18 | J17: 37 | K17: 60 | L17: 69 | M17: 75 | N17: -- | O17: -- | P17: -- | Q17: -- | R17: --
D18: South | E18: FAO-N | F18: NG4936 | G18: 8 | H18: 12 | I18: 18 | J18: 34 | K18: 51 | L18: 58 | M18: 61 | N18: 66 | O18: 73 | P18: 81 | Q18: 85 | R18: 89
B19: 01- | C19: 3 | D19: North | E19: AQC-N | F19: NG4936 | G19: 7 | H19: 12 | I19: 15 | J19: 40 | K19: 49 | L19: 60 | M19: 68 | N19: 83 | O19: 93 | P19: 98 | Q19: 100 | R19: 100
D20: Mid | E20: AQC-N | F20: NG4936 | G20: 8 | H20: 12 | I20: 16 | J20: 37 | K20: 53 | L20: 68 | M20: 77 | N20: 91 | O20: 91 | P20: 90 | Q20: 91 | R20: 99
D21: South | E21: AQC-N | F21: NG4936 | G21: 5 | H21: 11 | I21: 17 | J21: 36 | K21: 43 | L21: 46 | M21: 50 | N21: 54 | O21: 56 | P21: 57 | Q21: 58 | R21: 50
B22: 01- | C22: 4 | D22: North | E22: CSM | F22: NG4936 | G22: 6 | H22: 11 | I22: 11 | J22: 25 | K22: 31 | L22: 34 | M22: 38 | N22: 45 | O22: 49 | P22: 52 | Q22: 54 | R22: --
D23: Mid | E23: CSM | F23: NG4936 | G23: 8 | H23: 11 | I23: 16 | J23: 40 | K23: 47 | L23: 64 | M23: 77 | N23: 94 | O23: 101 | P23: -- | Q23: -- | R23: --
D24: South | E24: CSM | F24: NG4936 | G24: 7 | H24: 10 | I24: 13 | J24: 32 | K24: 42 | L24: 54 | M24: 62 | N24: 80 | O24: 86 | P24: 88 | Q24: 92 | R24: --
B25: 02- | C25: 4 | D25: South | E25: CSM | F25: NG3195 | G25: 11 | H25: 17 | I25: 21 | J25: 38 | K25: 42 | L25: 47 | M25: 51 | N25: 67 | O25: 79 | P25: 90 | Q25: -- | R25: --
D26: Mid | E26: CSM | F26: NG3195 | G26: 14 | H26: 17 | I26: 22 | J26: 54 | K26: 57 | L26: 65 | M26: 69 | N26: 86 | O26: 92 | P26: 97 | Q26: 101 | R26: --
D27: North | E27: CSM | F27: NG3195 | G27: 10 | H27: 15 | I27: 23 | J27: 54 | K27: 61 | L27: 68 | M27: 72 | N27: 95 | O27: -- | P27: -- | Q27: -- | R27: --
B28: 02- | C28: 3 | D28: South | E28: AQC-N | F28: NG3195 | G28: 13 | H28: 19 | I28: 23 | J28: 51 | K28: 62 | L28: 67 | M28: 72 | N28: 84 | O28: 88 | P28: 91 | Q28: 95 | R28: --
D29: Mid | E29: AQC-N | F29: NG3195 | G29: 11 | H29: 16 | I29: 24 | J29: 54 | K29: 66 | L29: 77 | M29: 84 | N29: 96 | O29: -- | P29: -- | Q29: -- | R29: --
D30: North | E30: AQC-N | F30: NG3195 | G30: 15 | H30: 20 | I30: 26 | J30: 49 | K30: 57 | L30: 71 | M30: 80 | N30: 79 | O30: 82 | P30: 84 | Q30: 87 | R30: 88
B31: 02- | C31: 2 | D31: South | E31: FAO-N | F31: NG3195 | G31: 11 | H31: 16 | I31: 24 | J31: 52 | K31: 62 | L31: 59 | M31: 59 | N31: 78 | O31: 80 | P31: 82 | Q31: 83 | R31: 82
D32: Mid | E32: FAO-N | F32: NG3195 | G32: 12 | H32: 16 | I32: 21 | J32: 48 | K32: 58 | L32: 64 | M32: 68 | N32: 91 | O32: -- | P32: -- | Q32: -- | R32: --
D33: North | E33: FAO-N | F33: NG3195 | G33: 13 | H33: 20 | I33: 27 | J33: 61 | K33: 75 | L33: 87 | M33: 93 | N33: -- | O33: -- | P33: -- | Q33: -- | R33: --
B34: 02- | C34: 1 | D34: South | E34: FAO | F34: NG3195 | G34: 16 | H34: 23 | I34: 23 | J34: 57 | K34: 68 | L34: 81 | M34: 88 | N34: 98 | O34: -- | P34: -- | Q34: -- | R34: --
D35: Mid | E35: FAO | F35: NG3195 | G35: 13 | H35: 20 | I35: 28 | J35: 58 | K35: 67 | L35: 83 | M35: 92 | N35: -- | O35: -- | P35: -- | Q35: -- | R35: --
D36: North | E36: FAO | F36: NG3195 | G36: 15 | H36: 21 | I36: 31 | J36: 60 | K36: 77 | L36: 88 | M36: 95 | N36: -- | O36: -- | P36: -- | Q36: -- | R36: --
B37: 03- | C37: 1 | D37: North | E37: CSM | F37: NG4936 | G37: 9 | H37: 15 | I37: 26 | J37: 57 | K37: 73 | L37: 87 | M37: 98 | N37: -- | O37: -- | P37: -- | Q37: -- | R37: --
D38: Mid | E38: CSM | F38: NG4936 | G38: 9 | H38: 14 | I38: 16 | J38: 34 | K38: 48 | L38: 61 | M38: 72 | N38: 80 | O38: 86 | P38: 94 | Q38: 100 | R38: 98
D39: South | E39: CSM | F39: NG4936 | G39: 8 | H39: 12 | I39: 22 | J39: 48 | K39: 65 | L39: 78 | M39: 91 | N39: -- | O39: -- | P39: -- | Q39: -- | R39: --
B40: 03- | C40: 2 | D40: North | E40: CSM-N | F40: NG4936 | G40: 12 | H40: 15 | I40: 21 | J40: 41 | K40: 53 | L40: 61 | M40: 67 | N40: 71 | O40: 82 | P40: 91 | Q40: -- | R40: --
D41: Mid | E41: CSM-N | F41: NG4936 | G41: 8 | H41: 13 | I41: 17 | J41: 36 | K41: 55 | L41: 65 | M41: 70 | N41: 82 | O41: 90 | P41: 94 | Q41: 97 | R41: --
D42: South | E42: CSM-N | F42: NG4936 | G42: 10 | H42: 15 | I42: 24 | J42: 53 | K42: 72 | L42: 77 | M42: 80 | N42: 96 | O42: -- | P42: -- | Q42: -- | R42: --
B43: 03- | C43: 3 | D43: North | E43: AQC | F43: NG4936 | G43: 12 | H43: 19 | I43: 26 | J43: 48 | K43: 67 | L43: 74 | M43: 79 | N43: 93 | O43: -- | P43: -- | Q43: -- | R43: --
D44: Mid | E44: AQC | F44: NG4936 | G44: 10 | H44: 17 | I44: 21 | J44: 44 | K44: 64 | L44: 77 | M44: 85 | N44: 95 | O44: -- | P44: -- | Q44: -- | R44: 100
D45: South | E45: AQC | F45: NG4936 | G45: 7 | H45: 15 | I45: 18 | J45: 28 | K45: 43 | L45: 41 | M45: 42 | N45: 50 | O45: 57 | P45: 66 | Q45: 72 | R45: 68
...

Sheet Averages
A1: 2022 - Averages by treatments | E1: 2021
A4: Average Canopy Heights | S4: Average Canopy Heights
D5: 44348 | E5: 44354 | F5: ='Height Summary'!G9 -> 44713 | G5: ='Height Summary'!H9 -> 44718 | H5: ='Height Summary'!I9 -> 44725 | I5: ='Height Summary'!J9 -> 44739 | J5: ='Height Summary'!K9 -> 44747 | K5: ='Height Summary'!L9 -> 44753 | L5: ='Height Summary'!M9 -> 44767 | M5: ='Height Summary'!N9 -> 44781 | ... Q5: ='Height Summary'!R9 -> 44812 | U5: ='Height Summary'!G9 -> 44713 | V5: ='Height Summary'!H9 -> 44718 | W5: ='Height Summary'!I9 -> 44725 | X5: ='Height Summary'!J9 -> 44739 | Y5: ='Height Summary'!K9 -> 44747 | Z5: ='Height Summary'!L9 -> 44753 | AA5: ='Height Summary'!M9 -> 44767 | AB5: ='Height Summary'!N9 -> 44781 | ... AF5: ='Height Summary'!R9 -> 44812
A6: NG3195 | D6: 152 | E6: 158 | F6: ='Height Summary'!G10 -> 152 | G6: ='Height Summary'!H10 -> 157 | H6: ='Height Summary'!I10 -> 164 | I6: ='Height Summary'!J10 -> 178 | J6: ='Height Summary'!K10 -> 186 | K6: ='Height Summary'!L10 -> 192 | L6: ='Height Summary'!M10 -> 206 | M6: ='Height Summary'!N10 -> 220 | ... Q6: ='Height Summary'!R10 -> 251 | S6: NG4936 | U6: ='Height Summary'!G10 -> 152 | V6: ='Height Summary'!H10 -> 157 | W6: ='Height Summary'!I10 -> 164 | X6: ='Height Summary'!J10 -> 178 | Y6: ='Height Summary'!K10 -> 186 | Z6: ='Height Summary'!L10 -> 192 | AA6: ='Height Summary'!M10 -> 206 | AB6: ='Height Summary'!N10 -> 220 | ... AF6: ='Height Summary'!R10 -> 251
B7: AQC | D7: #VALUE! | E7: #VALUE! | F7: =AVERAGEIFS('Height Summary'!G$13:G$156,'Height Summary'!$F$13:$F$156, "NG3195",'Height Summary'!$E$13:$E$156, "AQC") -> 12.833333 | G7: =AVERAGEIFS('Height Summary'!H$13:H$156,'Height Summary'!$F$13:$F$156, "NG3195",'Height Summary'!$E$13:$E$156, "AQC") -> 19.416667 | H7: =AVERAGEIFS('Height Summary'!I$13:I$156,'Height Summary'!$F$13:$F$156, "NG3195",'Height Summary'!$E$13:$E$156, "AQC") -> 28.5 | I7: =AVERAGEIFS('Height Summary'!J$13:J$156,'Height Summary'!$F$13:$F$156, "NG3195",'Height Summary'!$E$13:$E$156, "AQC") -> 60.416667 | J7: =AVERAGEIFS('Height Summary'!K$13:K$156,'Height Summary'!$F$13:$F$156, "NG3195",'Height Summary'!$E$13:$E$156, "AQC") -> 78.833333 | K7: =AVERAGEIFS('Height Summary'!L$13:L$156,'Height Summary'!$F$13:$F$156, "NG3195",'Height Summary'!$E$13:$E$156, "AQC") -> 85.666667 | L7: =AVERAGEIFS('Height Summary'!M$13:M$156,'Height Summary'!$F$13:$F$156, "NG3195",'Height Summary'!$E$13:$E$156, "AQC") -> 97.5 | M7: =AVERAGEIFS('Height Summary'!N$13:N$156,'Height Summary'!$F$13:$F$156, "NG3195",'Height Summary'!$E$13:$E$156, "AQC") -> 103.08333 | ... Q7: =AVERAGEIFS('Height Summary'!R$13:R$156,'Height Summary'!$F$13:$F$156, "NG3195",'Height Summary'!$E$13:$E$156, "AQC") -> 107.66667 | T7: AQC | U7: =AVERAGEIFS('Height Summary'!G$13:G$156,'Height Summary'!$F$13:$F$156, "NG4936",'Height Summary'!$E$13:$E$156, "AQC") -> 7.5 | V7: =AVERAGEIFS('Height Summary'!H$13:H$156,'Height Summary'!$F$13:$F$156, "NG4936",'Height Summary'!$E$13:$E$156, "AQC") -> 12.666667 | W7: =AVERAGEIFS('Height Summary'!I$13:I$156,'Height Summary'!$F$13:$F$156, "NG4936",'Height Summary'!$E$13:$E$156, "AQC") -> 18.833333 | X7: =AVERAGEIFS('Height Summary'!J$13:J$156,'Height Summary'!$F$13:$F$156, "NG4936",'Height Summary'!$E$13:$E$156, "AQC") -> 41.583333 | Y7: =AVERAGEIFS('Height Summary'!K$13:K$156,'Height Summary'!$F$13:$F$156, "NG4936",'Height Summary'!$E$13:$E$156, "AQC") -> 62.583333 | Z7: =AVERAGEIFS('Height Summary'!L$13:L$156,'Height Summary'!$F$13:$F$156, "NG4936",'Height Summary'!$E$13:$E$156, "AQC") -> 68.5 | AA7: =AVERAGEIFS('Height Summary'!M$13:M$156,'Height Summary'!$F$13:$F$156, "NG4936",'Height Summary'!$E$13:$E$156, "AQC") -> 80.833333 | AB7: =AVERAGEIFS('Height Summary'!N$13:N$156,'Height Summary'!$F$13:$F$156, "NG4936",'Height Summary'!$E$13:$E$156, "AQC") -> 92 | ... AF7: =AVERAGEIFS('Height Summary'!R$13:R$156,'Height Summary'!$F$13:$F$156, "NG4936",'Height Summary'!$E$13:$E$156, "AQC") -> 98.916667
B9: AQC-N | D9: #VALUE! | E9: #VALUE! | F9: =AVERAGEIFS('Height Summary'!G$13:G$156,'Height Summary'!$F$13:$F$156, "NG3195",'Height Summary'!$E$13:$E$156, "AQC-N") -> 12.25 | G9: =AVERAGEIFS('Height Summary'!H$13:H$156,'Height Summary'!$F$13:$F$156, "NG3195",'Height Summary'!$E$13:$E$156, "AQC-N") -> 18.75 | H9: =AVERAGEIFS('Height Summary'!I$13:I$156,'Height Summary'!$F$13:$F$156, "NG3195",'Height Summary'!$E$13:$E$156, "AQC-N") -> 25.25 | I9: =AVERAGEIFS('Height Summary'!J$13:J$156,'Height Summary'!$F$13:$F$156, "NG3195",'Height Summary'!$E$13:$E$156, "AQC-N") -> 55.333333 | J9: =AVERAGEIFS('Height Summary'!K$13:K$156,'Height Summary'!$F$13:$F$156, "NG3195",'Height Summary'!$E$13:$E$156, "AQC-N") -> 72.583333 | K9: =AVERAGEIFS('Height Summary'!L$13:L$156,'Height Summary'!$F$13:$F$156, "NG3195",'Height Summary'!$E$13:$E$156, "AQC-N") -> 75 | L9: =AVERAGEIFS('Height Summary'!M$13:M$156,'Height Summary'!$F$13:$F$156, "NG3195",'Height Summary'!$E$13:$E$156, "AQC-N") -> 81.416667 | M9: =AVERAGEIFS('Height Summary'!N$13:N$156,'Height Summary'!$F$13:$F$156, "NG3195",'Height Summary'!$E$13:$E$156, "AQC-N") -> 89 | ... Q9: =AVERAGEIFS('Height Summary'!R$13:R$156,'Height Summary'!$F$13:$F$156, "NG3195",'Height Summary'!$E$13:$E$156, "AQC-N") -> 91.666667 | T9: AQC-N | U9: =AVERAGEIFS('Height Summary'!G$13:G$156,'Height Summary'!$F$13:$F$156, "NG4936",'Height Summary'!$E$13:$E$156, "AQC-N") -> 5.0833333 | V9: =AVERAGEIFS('Height Summary'!H$13:H$156,'Height Summary'!$F$13:$F$156, "NG4936",'Height Summary'!$E$13:$E$156, "AQC-N") -> 9.9166667 | W9: =AVERAGEIFS('Height Summary'!I$13:I$156,'Height Summary'!$F$13:$F$156, "NG4936",'Height Summary'!$E$13:$E$156, "AQC-N") -> 15.583333 | X9: =AVERAGEIFS('Height Summary'!J$13:J$156,'Height Summary'!$F$13:$F$156, "NG4936",'Height Summary'!$E$13:$E$156, "AQC-N") -> 37.916667 | Y9: =AVERAGEIFS('Height Summary'!K$13:K$156,'Height Summary'!$F$13:$F$156, "NG4936",'Height Summary'!$E$13:$E$156, "AQC-N") -> 56 | Z9: =AVERAGEIFS('Height Summary'!L$13:L$156,'Height Summary'!$F$13:$F$156, "NG4936",'Height Summary'!$E$13:$E$156, "AQC-N") -> 62.416667 | AA9: =AVERAGEIFS('Height Summary'!M$13:M$156,'Height Summary'!$F$13:$F$156, "NG4936",'Height Summary'!$E$13:$E$156, "AQC-N") -> 77 | AB9: =AVERAGEIFS('Height Summary'!N$13:N$156,'Height Summary'!$F$13:$F$156, "NG4936",'Height Summary'!$E$13:$E$156, "AQC-N") -> 85.5 | ... AF9: =AVERAGEIFS('Height Summary'!R$13:R$156,'Height Summary'!$F$13:$F$156, "NG4936",'Height Summary'!$E$13:$E$156, "AQC-N") -> 87.833333
B11: CSM | D11: #VALUE! | E11: #VALUE! | F11: =AVERAGEIFS('Height Summary'!G$13:G$156,'Height Summary'!$F$13:$F$156, "NG3195",'Height Summary'!$E$13:$E$156, "CSM") -> 12.916667 | G11: =AVERAGEIFS('Height Summary'!H$13:H$156,'Height Summary'!$F$13:$F$156, "NG3195",'Height Summary'!$E$13:$E$156, "CSM") -> 18.583333 | H11: =AVERAGEIFS('Height Summary'!I$13:I$156,'Height Summary'!$F$13:$F$156, "NG3195",'Height Summary'!$E$13:$E$156, "CSM") -> 27.083333 | I11: =AVERAGEIFS('Height Summary'!J$13:J$156,'Height Summary'!$F$13:$F$156, "NG3195",'Height Summary'!$E$13:$E$156, "CSM") -> 57 | J11: =AVERAGEIFS('Height Summary'!K$13:K$156,'Height Summary'!$F$13:$F$156, "NG3195",'Height Summary'!$E$13:$E$156, "CSM") -> 75.083333 | K11: =AVERAGEIFS('Height Summary'!L$13:L$156,'Height Summary'!$F$13:$F$156, "NG3195",'Height Summary'!$E$13:$E$156, "CSM") -> 79.833333 | L11: =AVERAGEIFS('Height Summary'!M$13:M$156,'Height Summary'!$F$13:$F$156, "NG3195",'Height Summary'!$E$13:$E$156, "CSM") -> 89.583333 | M11: =AVERAGEIFS('Height Summary'!N$13:N$156,'Height Summary'!$F$13:$F$156, "NG3195",'Height Summary'!$E$13:$E$156, "CSM") -> 97.583333 | ... Q11: =AVERAGEIFS('Height Summary'!R$13:R$156,'Height Summary'!$F$13:$F$156, "NG3195",'Height Summary'!$E$13:$E$156, "CSM") -> 108.5 | T11: CSM | U11: =AVERAGEIFS('Height Summary'!G$13:G$156,'Height Summary'!$F$13:$F$156, "NG4936",'Height Summary'!$E$13:$E$156, "CSM") -> 6.0833333 | V11: =AVERAGEIFS('Height Summary'!H$13:H$156,'Height Summary'!$F$13:$F$156, "NG4936",'Height Summary'!$E$13:$E$156, "CSM") -> 10.583333 | W11: =AVERAGEIFS('Height Summary'!I$13:I$156,'Height Summary'!$F$13:$F$156, "NG4936",'Height Summary'!$E$13:$E$156, "CSM") -> 16.166667 | X11: =AVERAGEIFS('Height Summary'!J$13:J$156,'Height Summary'!$F$13:$F$156, "NG4936",'Height Summary'!$E$13:$E$156, "CSM") -> 38.75 | Y11: =AVERAGEIFS('Height Summary'!K$13:K$156,'Height Summary'!$F$13:$F$156, "NG4936",'Height Summary'!$E$13:$E$156, "CSM") -> 57.166667 | Z11: =AVERAGEIFS('Height Summary'!L$13:L$156,'Height Summary'!$F$13:$F$156, "NG4936",'Height Summary'!$E$13:$E$156, "CSM") -> 66.166667 | AA11: =AVERAGEIFS('Height Summary'!M$13:M$156,'Height Summary'!$F$13:$F$156, "NG4936",'Height Summary'!$E$13:$E$156, "CSM") -> 79.5 | AB11: =AVERAGEIFS('Height Summary'!N$13:N$156,'Height Summary'!$F$13:$F$156, "NG4936",'Height Summary'!$E$13:$E$156, "CSM") -> 91.833333 | ... AF11: =AVERAGEIFS('Height Summary'!R$13:R$156,'Height Summary'!$F$13:$F$156, "NG4936",'Height Summary'!$E$13:$E$156, "CSM") -> 101.16667
B13: CSM-N | D13: #VALUE! | E13: #VALUE! | F13: =AVERAGEIFS('Height Summary'!G$13:G$156,'Height Summary'!$F$13:$F$156, "NG3195",'Height Summary'!$E$13:$E$156, "CSM-N") -> 12.416667 | G13: =AVERAGEIFS('Height Summary'!H$13:H$156,'Height Summary'!$F$13:$F$156, "NG3195",'Height Summary'!$E$13:$E$156, "CSM-N") -> 19.333333 | H13: =AVERAGEIFS('Height Summary'!I$13:I$156,'Height Summary'!$F$13:$F$156, "NG3195",'Height Summary'!$E$13:$E$156, "CSM-N") -> 27.833333 | I13: =AVERAGEIFS('Height Summary'!J$13:J$156,'Height Summary'!$F$13:$F$156, "NG3195",'Height Summary'!$E$13:$E$156, "CSM-N") -> 58.5 | J13: =AVERAGEIFS('Height Summary'!K$13:K$156,'Height Summary'!$F$13:$F$156, "NG3195",'Height Summary'!$E$13:$E$156, "CSM-N") -> 79.083333 | K13: =AVERAGEIFS('Height Summary'!L$13:L$156,'Height Summary'!$F$13:$F$156, "NG3195",'Height Summary'!$E$13:$E$156, "CSM-N") -> 82 | L13: =AVERAGEIFS('Height Summary'!M$13:M$156,'Height Summary'!$F$13:$F$156, "NG3195",'Height Summary'!$E$13:$E$156, "CSM-N") -> 86.75 | M13: =AVERAGEIFS('Height Summary'!N$13:N$156,'Height Summary'!$F$13:$F$156, "NG3195",'Height Summary'!$E$13:$E$156, "CSM-N") -> 92.833333 | ... Q13: =AVERAGEIFS('Height Summary'!R$13:R$156,'Height Summary'!$F$13:$F$156, "NG3195",'Height Summary'!$E$13:$E$156, "CSM-N") -> 101 | T13: CSM-N | U13: =AVERAGEIFS('Height Summary'!G$13:G$156,'Height Summary'!$F$13:$F$156, "NG4936",'Height Summary'!$E$13:$E$156, "CSM-N") -> 7.3333333 | V13: =AVERAGEIFS('Height Summary'!H$13:H$156,'Height Summary'!$F$13:$F$156, "NG4936",'Height Summary'!$E$13:$E$156, "CSM-N") -> 11.75 | W13: =AVERAGEIFS('Height Summary'!I$13:I$156,'Height Summary'!$F$13:$F$156, "NG4936",'Height Summary'!$E$13:$E$156, "CSM-N") -> 17.833333 | X13: =AVERAGEIFS('Height Summary'!J$13:J$156,'Height Summary'!$F$13:$F$156, "NG4936",'Height Summary'!$E$13:$E$156, "CSM-N") -> 43.333333 | Y13: =AVERAGEIFS('Height Summary'!K$13:K$156,'Height Summary'!$F$13:$F$156, "NG4936",'Height Summary'!$E$13:$E$156, "CSM-N") -> 62.666667 | Z13: =AVERAGEIFS('Height Summary'!L$13:L$156,'Height Summary'!$F$13:$F$156, "NG4936",'Height Summary'!$E$13:$E$156, "CSM-N") -> 68.333333 | AA13: =AVERAGEIFS('Height Summary'!M$13:M$156,'Height Summary'!$F$13:$F$156, "NG4936",'Height Summary'!$E$13:$E$156, "CSM-N") -> 77 | AB13: =AVERAGEIFS('Height Summary'!N$13:N$156,'Height Summary'!$F$13:$F$156, "NG4936",'Height Summary'!$E$13:$E$156, "CSM-N") -> 86.833333 | ... AF13: =AVERAGEIFS('Height Summary'!R$13:R$156,'Height Summary'!$F$13:$F$156, "NG4936",'Height Summary'!$E$13:$E$156, "CSM-N") -> 99.333333
B15: FAO | D15: #VALUE! | E15: #VALUE! | F15: =AVERAGEIFS('Height Summary'!G$13:G$156,'Height Summary'!$F$13:$F$156, "NG3195",'Height Summary'!$E$13:$E$156, "FAO") -> 12.5 | G15: =AVERAGEIFS('Height Summary'!H$13:H$156,'Height Summary'!$F$13:$F$156, "NG3195",'Height Summary'!$E$13:$E$156, "FAO") -> 18.833333 | H15: =AVERAGEIFS('Height Summary'!I$13:I$156,'Height Summary'!$F$13:$F$156, "NG3195",'Height Summary'!$E$13:$E$156, "FAO") -> 26.333333 | I15: =AVERAGEIFS('Height Summary'!J$13:J$156,'Height Summary'!$F$13:$F$156, "NG3195",'Height Summary'!$E$13:$E$156, "FAO") -> 56.25 | J15: =AVERAGEIFS('Height Summary'!K$13:K$156,'Height Summary'!$F$13:$F$156, "NG3195",'Height Summary'!$E$13:$E$156, "FAO") -> 71.833333 | K15: =AVERAGEIFS('Height Summary'!L$13:L$156,'Height Summary'!$F$13:$F$156, "NG3195",'Height Summary'!$E$13:$E$156, "FAO") -> 78.166667 | L15: =AVERAGEIFS('Height Summary'!M$13:M$156,'Height Summary'!$F$13:$F$156, "NG3195",'Height Summary'!$E$13:$E$156, "FAO") -> 90.583333 | M15: =AVERAGEIFS('Height Summary'!N$13:N$156,'Height Summary'!$F$13:$F$156, "NG3195",'Height Summary'!$E$13:$E$156, "FAO") -> 102.58333 | ... Q15: =AVERAGEIFS('Height Summary'!R$13:R$156,'Height Summary'!$F$13:$F$156, "NG3195",'Height Summary'!$E$13:$E$156, "FAO") -> 113.08333 | T15: FAO | U15: =AVERAGEIFS('Height Summary'!G$13:G$156,'Height Summary'!$F$13:$F$156, "NG4936",'Height Summary'!$E$13:$E$156, "FAO") -> 6.75 | V15: =AVERAGEIFS('Height Summary'!H$13:H$156,'Height Summary'!$F$13:$F$156, "NG4936",'Height Summary'!$E$13:$E$156, "FAO") -> 12.25 | W15: =AVERAGEIFS('Height Summary'!I$13:I$156,'Height Summary'!$F$13:$F$156, "NG4936",'Height Summary'!$E$13:$E$156, "FAO") -> 19 | X15: =AVERAGEIFS('Height Summary'!J$13:J$156,'Height Summary'!$F$13:$F$156, "NG4936",'Height Summary'!$E$13:$E$156, "FAO") -> 41.083333 | Y15: =AVERAGEIFS('Height Summary'!K$13:K$156,'Height Summary'!$F$13:$F$156, "NG4936",'Height Summary'!$E$13:$E$156, "FAO") -> 59.333333 | Z15: =AVERAGEIFS('Height Summary'!L$13:L$156,'Height Summary'!$F$13:$F$156, "NG4936",'Height Summary'!$E$13:$E$156, "FAO") -> 68 | AA15: =AVERAGEIFS('Height Summary'!M$13:M$156,'Height Summary'!$F$13:$F$156, "NG4936",'Height Summary'!$E$13:$E$156, "FAO") -> 83.833333 | AB15: =AVERAGEIFS('Height Summary'!N$13:N$156,'Height Summary'!$F$13:$F$156, "NG4936",'Height Summary'!$E$13:$E$156, "FAO") -> 93.916667 | ... AF15: =AVERAGEIFS('Height Summary'!R$13:R$156,'Height Summary'!$F$13:$F$156, "NG4936",'Height Summary'!$E$13:$E$156, "FAO") -> 105.16667
B17: FAO-N | D17: #VALUE! | E17: #VALUE! | F17: =AVERAGEIFS('Height Summary'!G$13:G$156,'Height Summary'!$F$13:$F$156, "NG3195",'Height Summary'!$E$13:$E$156, "FAO-N") -> 11.666667 | G17: =AVERAGEIFS('Height Summary'!H$13:H$156,'Height Summary'!$F$13:$F$156, "NG3195",'Height Summary'!$E$13:$E$156, "FAO-N") -> 17.916667 | H17: =AVERAGEIFS('Height Summary'!I$13:I$156,'Height Summary'!$F$13:$F$156, "NG3195",'Height Summary'!$E$13:$E$156, "FAO-N") -> 26 | I17: =AVERAGEIFS('Height Summary'!J$13:J$156,'Height Summary'!$F$13:$F$156, "NG3195",'Height Summary'!$E$13:$E$156, "FAO-N") -> 56.25 | J17: =AVERAGEIFS('Height Summary'!K$13:K$156,'Height Summary'!$F$13:$F$156, "NG3195",'Height Summary'!$E$13:$E$156, "FAO-N") -> 75.416667 | K17: =AVERAGEIFS('Height Summary'!L$13:L$156,'Height Summary'!$F$13:$F$156, "NG3195",'Height Summary'!$E$13:$E$156, "FAO-N") -> 77.166667 | L17: =AVERAGEIFS('Height Summary'!M$13:M$156,'Height Summary'!$F$13:$F$156, "NG3195",'Height Summary'!$E$13:$E$156, "FAO-N") -> 81.75 | M17: =AVERAGEIFS('Height Summary'!N$13:N$156,'Height Summary'!$F$13:$F$156, "NG3195",'Height Summary'!$E$13:$E$156, "FAO-N") -> 92.5 | ... Q17: =AVERAGEIFS('Height Summary'!R$13:R$156,'Height Summary'!$F$13:$F$156, "NG3195",'Height Summary'!$E$13:$E$156, "FAO-N") -> 97 | T17: FAO-N | U17: =AVERAGEIFS('Height Summary'!G$13:G$156,'Height Summary'!$F$13:$F$156, "NG4936",'Height Summary'!$E$13:$E$156, "FAO-N") -> 6.0833333 | V17: =AVERAGEIFS('Height Summary'!H$13:H$156,'Height Summary'!$F$13:$F$156, "NG4936",'Height Summary'!$E$13:$E$156, "FAO-N") -> 11.75 | W17: =AVERAGEIFS('Height Summary'!I$13:I$156,'Height Summary'!$F$13:$F$156, "NG4936",'Height Summary'!$E$13:$E$156, "FAO-N") -> 17.416667 | X17: =AVERAGEIFS('Height Summary'!J$13:J$156,'Height Summary'!$F$13:$F$156, "NG4936",'Height Summary'!$E$13:$E$156, "FAO-N") -> 41.25 | Y17: =AVERAGEIFS('Height Summary'!K$13:K$156,'Height Summary'!$F$13:$F$156, "NG4936",'Height Summary'!$E$13:$E$156, "FAO-N") -> 59.583333 | Z17: =AVERAGEIFS('Height Summary'!L$13:L$156,'Height Summary'!$F$13:$F$156, "NG4936",'Height Summary'!$E$13:$E$156, "FAO-N") -> 65 | AA17: =AVERAGEIFS('Height Summary'!M$13:M$156,'Height Summary'!$F$13:$F$156, "NG4936",'Height Summary'!$E$13:$E$156, "FAO-N") -> 76.916667 | AB17: =AVERAGEIFS('Height Summary'!N$13:N$156,'Height Summary'!$F$13:$F$156, "NG4936",'Height Summary'!$E$13:$E$156, "FAO-N") -> 86.166667 | ... AF17: =AVERAGEIFS('Height Summary'!R$13:R$156,'Height Summary'!$F$13:$F$156, "NG4936",'Height Summary'!$E$13:$E$156, "FAO-N") -> 91
A20: Average Canopy Widths | S20: Average Canopy Widths
D22: 44348 | E22: 44354 | F22: ='Cover Summary'!G9 -> 44713 | G22: ='Cover Summary'!H9 -> 44718 | H22: ='Cover Summary'!I9 -> 44725 | I22: ='Cover Summary'!J9 -> 44739 | J22: ='Cover Summary'!K9 -> 44747 | K22: ='Cover Summary'!L9 -> 44753 | L22: ='Cover Summary'!M9 -> 44767 | M22: ='Cover Summary'!N9 -> 44781 | ... Q22: ='Cover Summary'!R9 -> 44812 | U22: ='Cover Summary'!G9 -> 44713 | V22: ='Cover Summary'!H9 -> 44718 | W22: ='Cover Summary'!I9 -> 44725 | X22: ='Cover Summary'!J9 -> 44739 | Y22: ='Cover Summary'!K9 -> 44747 | Z22: ='Cover Summary'!L9 -> 44753 | AA22: ='Cover Summary'!M9 -> 44767 | AB22: ='Cover Summary'!N9 -> 44781 | ... AF22: ='Cover Summary'!R9 -> 44812
A23: NG3195 | D23: 152 | E23: 158 | F23: ='Cover Summary'!G10 -> 152 | G23: ='Cover Summary'!H10 -> 157 | H23: ='Cover Summary'!I10 -> 164 | I23: ='Cover Summary'!J10 -> 178 | J23: ='Cover Summary'!K10 -> 186 | K23: ='Cover Summary'!L10 -> 192 | L23: ='Cover Summary'!M10 -> 206 | M23: ='Cover Summary'!N10 -> 220 | ... Q23: ='Cover Summary'!R10 -> 251 | S23: NG4936 | U23: ='Cover Summary'!G10 -> 152 | V23: ='Cover Summary'!H10 -> 157 | W23: ='Cover Summary'!I10 -> 164 | X23: ='Cover Summary'!J10 -> 178 | Y23: ='Cover Summary'!K10 -> 186 | Z23: ='Cover Summary'!L10 -> 192 | AA23: ='Cover Summary'!M10 -> 206 | AB23: ='Cover Summary'!N10 -> 220 | ... AF23: ='Cover Summary'!R10 -> 251
B24: AQC | D24: #VALUE! | E24: #VALUE! | F24: =AVERAGEIFS('Cover Summary'!G$13:G$156,'Cover Summary'!$F$13:$F$156, "NG3195",'Cover Summary'!$E$13:$E$156, "AQC") -> 13.916667 | G24: =AVERAGEIFS('Cover Summary'!H$13:H$156,'Cover Summary'!$F$13:$F$156, "NG3195",'Cover Summary'!$E$13:$E$156, "AQC") -> 20.916667 | H24: =AVERAGEIFS('Cover Summary'!I$13:I$156,'Cover Summary'!$F$13:$F$156, "NG3195",'Cover Summary'!$E$13:$E$156, "AQC") -> 27.916667 | I24: =AVERAGEIFS('Cover Summary'!J$13:J$156,'Cover Summary'!$F$13:$F$156, "NG3195",'Cover Summary'!$E$13:$E$156, "AQC") -> 55.083333 | J24: =AVERAGEIFS('Cover Summary'!K$13:K$156,'Cover Summary'!$F$13:$F$156, "NG3195",'Cover Summary'!$E$13:$E$156, "AQC") -> 67.666667 | K24: =AVERAGEIFS('Cover Summary'!L$13:L$156,'Cover Summary'!$F$13:$F$156, "NG3195",'Cover Summary'!$E$13:$E$156, "AQC") -> 80.25 | L24: =AVERAGEIFS('Cover Summary'!M$13:M$156,'Cover Summary'!$F$13:$F$156, "NG3195",'Cover Summary'!$E$13:$E$156, "AQC") -> 83.25 | M24: =AVERAGEIFS('Cover Summary'!N$13:N$156,'Cover Summary'!$F$13:$F$156, "NG3195",'Cover Summary'!$E$13:$E$156, "AQC") -> 89.5 | ... Q24: =AVERAGEIFS('Cover Summary'!R$13:R$156,'Cover Summary'!$F$13:$F$156, "NG3195",'Cover Summary'!$E$13:$E$156, "AQC") -> 93.5 | T24: AQC | U24: =AVERAGEIFS('Cover Summary'!G$13:G$156,'Cover Summary'!$F$13:$F$156, "NG4936",'Cover Summary'!$E$13:$E$156, "AQC") -> 8.3333333 | V24: =AVERAGEIFS('Cover Summary'!H$13:H$156,'Cover Summary'!$F$13:$F$156, "NG4936",'Cover Summary'!$E$13:$E$156, "AQC") -> 14.916667 | W24: =AVERAGEIFS('Cover Summary'!I$13:I$156,'Cover Summary'!$F$13:$F$156, "NG4936",'Cover Summary'!$E$13:$E$156, "AQC") -> 20 | X24: =AVERAGEIFS('Cover Summary'!J$13:J$156,'Cover Summary'!$F$13:$F$156, "NG4936",'Cover Summary'!$E$13:$E$156, "AQC") -> 39.583333 | Y24: =AVERAGEIFS('Cover Summary'!K$13:K$156,'Cover Summary'!$F$13:$F$156, "NG4936",'Cover Summary'!$E$13:$E$156, "AQC") -> 54.583333 | Z24: =AVERAGEIFS('Cover Summary'!L$13:L$156,'Cover Summary'!$F$13:$F$156, "NG4936",'Cover Summary'!$E$13:$E$156, "AQC") -> 66.916667 | AA24: =AVERAGEIFS('Cover Summary'!M$13:M$156,'Cover Summary'!$F$13:$F$156, "NG4936",'Cover Summary'!$E$13:$E$156, "AQC") -> 75.333333 | AB24: =AVERAGEIFS('Cover Summary'!N$13:N$156,'Cover Summary'!$F$13:$F$156, "NG4936",'Cover Summary'!$E$13:$E$156, "AQC") -> 82.583333 | ... AF24: =AVERAGEIFS('Cover Summary'!R$13:R$156,'Cover Summary'!$F$13:$F$156, "NG4936",'Cover Summary'!$E$13:$E$156, "AQC") -> 89.285714
B26: AQC-N | D26: #VALUE! | E26: #VALUE! | F26: =AVERAGEIFS('Cover Summary'!G$13:G$156,'Cover Summary'!$F$13:$F$156, "NG3195",'Cover Summary'!$E$13:$E$156, "AQC-N") -> 13.583333 | G26: =AVERAGEIFS('Cover Summary'!H$13:H$156,'Cover Summary'!$F$13:$F$156, "NG3195",'Cover Summary'!$E$13:$E$156, "AQC-N") -> 20.666667 | H26: =AVERAGEIFS('Cover Summary'!I$13:I$156,'Cover Summary'!$F$13:$F$156, "NG3195",'Cover Summary'!$E$13:$E$156, "AQC-N") -> 24.666667 | I26: =AVERAGEIFS('Cover Summary'!J$13:J$156,'Cover Summary'!$F$13:$F$156, "NG3195",'Cover Summary'!$E$13:$E$156, "AQC-N") -> 50.5 | J26: =AVERAGEIFS('Cover Summary'!K$13:K$156,'Cover Summary'!$F$13:$F$156, "NG3195",'Cover Summary'!$E$13:$E$156, "AQC-N") -> 58.583333 | K26: =AVERAGEIFS('Cover Summary'!L$13:L$156,'Cover Summary'!$F$13:$F$156, "NG3195",'Cover Summary'!$E$13:$E$156, "AQC-N") -> 66.75 | L26: =AVERAGEIFS('Cover Summary'!M$13:M$156,'Cover Summary'!$F$13:$F$156, "NG3195",'Cover Summary'!$E$13:$E$156, "AQC-N") -> 72.5 | M26: =AVERAGEIFS('Cover Summary'!N$13:N$156,'Cover Summary'!$F$13:$F$156, "NG3195",'Cover Summary'!$E$13:$E$156, "AQC-N") -> 77 | ... Q26: =AVERAGEIFS('Cover Summary'!R$13:R$156,'Cover Summary'!$F$13:$F$156, "NG3195",'Cover Summary'!$E$13:$E$156, "AQC-N") -> 78 | T26: AQC-N | U26: =AVERAGEIFS('Cover Summary'!G$13:G$156,'Cover Summary'!$F$13:$F$156, "NG4936",'Cover Summary'!$E$13:$E$156, "AQC-N") -> 5.5833333 | V26: =AVERAGEIFS('Cover Summary'!H$13:H$156,'Cover Summary'!$F$13:$F$156, "NG4936",'Cover Summary'!$E$13:$E$156, "AQC-N") -> 11.75 | W26: =AVERAGEIFS('Cover Summary'!I$13:I$156,'Cover Summary'!$F$13:$F$156, "NG4936",'Cover Summary'!$E$13:$E$156, "AQC-N") -> 16.416667 | X26: =AVERAGEIFS('Cover Summary'!J$13:J$156,'Cover Summary'!$F$13:$F$156, "NG4936",'Cover Summary'!$E$13:$E$156, "AQC-N") -> 36.333333 | Y26: =AVERAGEIFS('Cover Summary'!K$13:K$156,'Cover Summary'!$F$13:$F$156, "NG4936",'Cover Summary'!$E$13:$E$156, "AQC-N") -> 47.583333 | Z26: =AVERAGEIFS('Cover Summary'!L$13:L$156,'Cover Summary'!$F$13:$F$156, "NG4936",'Cover Summary'!$E$13:$E$156, "AQC-N") -> 59.583333 | AA26: =AVERAGEIFS('Cover Summary'!M$13:M$156,'Cover Summary'!$F$13:$F$156, "NG4936",'Cover Summary'!$E$13:$E$156, "AQC-N") -> 67.25 | AB26: =AVERAGEIFS('Cover Summary'!N$13:N$156,'Cover Summary'!$F$13:$F$156, "NG4936",'Cover Summary'!$E$13:$E$156, "AQC-N") -> 74.833333 | ... AF26: =AVERAGEIFS('Cover Summary'!R$13:R$156,'Cover Summary'!$F$13:$F$156, "NG4936",'Cover Summary'!$E$13:$E$156, "AQC-N") -> 84.909091
B28: CSM | D28: #VALUE! | E28: #VALUE! | F28: =AVERAGEIFS('Cover Summary'!G$13:G$156,'Cover Summary'!$F$13:$F$156, "NG3195",'Cover Summary'!$E$13:$E$156, "CSM") -> 13.666667 | G28: =AVERAGEIFS('Cover Summary'!H$13:H$156,'Cover Summary'!$F$13:$F$156, "NG3195",'Cover Summary'!$E$13:$E$156, "CSM") -> 19.416667 | H28: =AVERAGEIFS('Cover Summary'!I$13:I$156,'Cover Summary'!$F$13:$F$156, "NG3195",'Cover Summary'!$E$13:$E$156, "CSM") -> 25.833333 | I28: =AVERAGEIFS('Cover Summary'!J$13:J$156,'Cover Summary'!$F$13:$F$156, "NG3195",'Cover Summary'!$E$13:$E$156, "CSM") -> 52.833333 | J28: =AVERAGEIFS('Cover Summary'!K$13:K$156,'Cover Summary'!$F$13:$F$156, "NG3195",'Cover Summary'!$E$13:$E$156, "CSM") -> 62.166667 | K28: =AVERAGEIFS('Cover Summary'!L$13:L$156,'Cover Summary'!$F$13:$F$156, "NG3195",'Cover Summary'!$E$13:$E$156, "CSM") -> 72.666667 | L28: =AVERAGEIFS('Cover Summary'!M$13:M$156,'Cover Summary'!$F$13:$F$156, "NG3195",'Cover Summary'!$E$13:$E$156, "CSM") -> 72.777778 | M28: =AVERAGEIFS('Cover Summary'!N$13:N$156,'Cover Summary'!$F$13:$F$156, "NG3195",'Cover Summary'!$E$13:$E$156, "CSM") -> 83.666667 | ... Q28: =AVERAGEIFS('Cover Summary'!R$13:R$156,'Cover Summary'!$F$13:$F$156, "NG3195",'Cover Summary'!$E$13:$E$156, "CSM") -> 87.5 | T28: CSM | U28: =AVERAGEIFS('Cover Summary'!G$13:G$156,'Cover Summary'!$F$13:$F$156, "NG4936",'Cover Summary'!$E$13:$E$156, "CSM") -> 6.8333333 | V28: =AVERAGEIFS('Cover Summary'!H$13:H$156,'Cover Summary'!$F$13:$F$156, "NG4936",'Cover Summary'!$E$13:$E$156, "CSM") -> 12 | W28: =AVERAGEIFS('Cover Summary'!I$13:I$156,'Cover Summary'!$F$13:$F$156, "NG4936",'Cover Summary'!$E$13:$E$156, "CSM") -> 16.833333 | X28: =AVERAGEIFS('Cover Summary'!J$13:J$156,'Cover Summary'!$F$13:$F$156, "NG4936",'Cover Summary'!$E$13:$E$156, "CSM") -> 37.666667 | Y28: =AVERAGEIFS('Cover Summary'!K$13:K$156,'Cover Summary'!$F$13:$F$156, "NG4936",'Cover Summary'!$E$13:$E$156, "CSM") -> 51.25 | Z28: =AVERAGEIFS('Cover Summary'!L$13:L$156,'Cover Summary'!$F$13:$F$156, "NG4936",'Cover Summary'!$E$13:$E$156, "CSM") -> 63.583333 | AA28: =AVERAGEIFS('Cover Summary'!M$13:M$156,'Cover Summary'!$F$13:$F$156, "NG4936",'Cover Summary'!$E$13:$E$156, "CSM") -> 73.333333 | AB28: =AVERAGEIFS('Cover Summary'!N$13:N$156,'Cover Summary'!$F$13:$F$156, "NG4936",'Cover Summary'!$E$13:$E$156, "CSM") -> 76.3 | ... AF28: =AVERAGEIFS('Cover Summary'!R$13:R$156,'Cover Summary'!$F$13:$F$156, "NG4936",'Cover Summary'!$E$13:$E$156, "CSM") -> 91.285714
B30: CSM-N | D30: #VALUE! | E30: #VALUE! | F30: =AVERAGEIFS('Cover Summary'!G$13:G$156,'Cover Summary'!$F$13:$F$156, "NG3195",'Cover Summary'!$E$13:$E$156, "CSM-N") -> 13.333333 | G30: =AVERAGEIFS('Cover Summary'!H$13:H$156,'Cover Summary'!$F$13:$F$156, "NG3195",'Cover Summary'!$E$13:$E$156, "CSM-N") -> 21.083333 | H30: =AVERAGEIFS('Cover Summary'!I$13:I$156,'Cover Summary'!$F$13:$F$156, "NG3195",'Cover Summary'!$E$13:$E$156, "CSM-N") -> 26.583333 | I30: =AVERAGEIFS('Cover Summary'!J$13:J$156,'Cover Summary'!$F$13:$F$156, "NG3195",'Cover Summary'!$E$13:$E$156, "CSM-N") -> 52.333333 | J30: =AVERAGEIFS('Cover Summary'!K$13:K$156,'Cover Summary'!$F$13:$F$156, "NG3195",'Cover Summary'!$E$13:$E$156, "CSM-N") -> 61.75 | K30: =AVERAGEIFS('Cover Summary'!L$13:L$156,'Cover Summary'!$F$13:$F$156, "NG3195",'Cover Summary'!$E$13:$E$156, "CSM-N") -> 71.416667 | L30: =AVERAGEIFS('Cover Summary'!M$13:M$156,'Cover Summary'!$F$13:$F$156, "NG3195",'Cover Summary'!$E$13:$E$156, "CSM-N") -> 75.727273 | M30: =AVERAGEIFS('Cover Summary'!N$13:N$156,'Cover Summary'!$F$13:$F$156, "NG3195",'Cover Summary'!$E$13:$E$156, "CSM-N") -> 79.3 | ... Q30: =AVERAGEIFS('Cover Summary'!R$13:R$156,'Cover Summary'!$F$13:$F$156, "NG3195",'Cover Summary'!$E$13:$E$156, "CSM-N") -> 74 | T30: CSM-N | U30: =AVERAGEIFS('Cover Summary'!G$13:G$156,'Cover Summary'!$F$13:$F$156, "NG4936",'Cover Summary'!$E$13:$E$156, "CSM-N") -> 8.3333333 | V30: =AVERAGEIFS('Cover Summary'!H$13:H$156,'Cover Summary'!$F$13:$F$156, "NG4936",'Cover Summary'!$E$13:$E$156, "CSM-N") -> 13.25 | W30: =AVERAGEIFS('Cover Summary'!I$13:I$156,'Cover Summary'!$F$13:$F$156, "NG4936",'Cover Summary'!$E$13:$E$156, "CSM-N") -> 18.583333 | X30: =AVERAGEIFS('Cover Summary'!J$13:J$156,'Cover Summary'!$F$13:$F$156, "NG4936",'Cover Summary'!$E$13:$E$156, "CSM-N") -> 40.75 | Y30: =AVERAGEIFS('Cover Summary'!K$13:K$156,'Cover Summary'!$F$13:$F$156, "NG4936",'Cover Summary'!$E$13:$E$156, "CSM-N") -> 52.583333 | Z30: =AVERAGEIFS('Cover Summary'!L$13:L$156,'Cover Summary'!$F$13:$F$156, "NG4936",'Cover Summary'!$E$13:$E$156, "CSM-N") -> 62.583333 | AA30: =AVERAGEIFS('Cover Summary'!M$13:M$156,'Cover Summary'!$F$13:$F$156, "NG4936",'Cover Summary'!$E$13:$E$156, "CSM-N") -> 69.583333 | AB30: =AVERAGEIFS('Cover Summary'!N$13:N$156,'Cover Summary'!$F$13:$F$156, "NG4936",'Cover Summary'!$E$13:$E$156, "CSM-N") -> 78.416667 | ... AF30: =AVERAGEIFS('Cover Summary'!R$13:R$156,'Cover Summary'!$F$13:$F$156, "NG4936",'Cover Summary'!$E$13:$E$156, "CSM-N") -> 78.75
B32: FAO | D32: #VALUE! | E32: #VALUE! | F32: =AVERAGEIFS('Cover Summary'!G$13:G$156,'Cover Summary'!$F$13:$F$156, "NG3195",'Cover Summary'!$E$13:$E$156, "FAO") -> 13.833333 | G32: =AVERAGEIFS('Cover Summary'!H$13:H$156,'Cover Summary'!$F$13:$F$156, "NG3195",'Cover Summary'!$E$13:$E$156, "FAO") -> 20.416667 | H32: =AVERAGEIFS('Cover Summary'!I$13:I$156,'Cover Summary'!$F$13:$F$156, "NG3195",'Cover Summary'!$E$13:$E$156, "FAO") -> 25.583333 | I32: =AVERAGEIFS('Cover Summary'!J$13:J$156,'Cover Summary'!$F$13:$F$156, "NG3195",'Cover Summary'!$E$13:$E$156, "FAO") -> 51.333333 | J32: =AVERAGEIFS('Cover Summary'!K$13:K$156,'Cover Summary'!$F$13:$F$156, "NG3195",'Cover Summary'!$E$13:$E$156, "FAO") -> 63.166667 | K32: =AVERAGEIFS('Cover Summary'!L$13:L$156,'Cover Summary'!$F$13:$F$156, "NG3195",'Cover Summary'!$E$13:$E$156, "FAO") -> 75.083333 | L32: =AVERAGEIFS('Cover Summary'!M$13:M$156,'Cover Summary'!$F$13:$F$156, "NG3195",'Cover Summary'!$E$13:$E$156, "FAO") -> 82 | M32: =AVERAGEIFS('Cover Summary'!N$13:N$156,'Cover Summary'!$F$13:$F$156, "NG3195",'Cover Summary'!$E$13:$E$156, "FAO") -> 87.571429 | ... Q32: =AVERAGEIFS('Cover Summary'!R$13:R$156,'Cover Summary'!$F$13:$F$156, "NG3195",'Cover Summary'!$E$13:$E$156, "FAO") -> 89.666667 | T32: FAO | U32: =AVERAGEIFS('Cover Summary'!G$13:G$156,'Cover Summary'!$F$13:$F$156, "NG4936",'Cover Summary'!$E$13:$E$156, "FAO") -> 7.5 | V32: =AVERAGEIFS('Cover Summary'!H$13:H$156,'Cover Summary'!$F$13:$F$156, "NG4936",'Cover Summary'!$E$13:$E$156, "FAO") -> 13.75 | W32: =AVERAGEIFS('Cover Summary'!I$13:I$156,'Cover Summary'!$F$13:$F$156, "NG4936",'Cover Summary'!$E$13:$E$156, "FAO") -> 19.916667 | X32: =AVERAGEIFS('Cover Summary'!J$13:J$156,'Cover Summary'!$F$13:$F$156, "NG4936",'Cover Summary'!$E$13:$E$156, "FAO") -> 38.083333 | Y32: =AVERAGEIFS('Cover Summary'!K$13:K$156,'Cover Summary'!$F$13:$F$156, "NG4936",'Cover Summary'!$E$13:$E$156, "FAO") -> 51.916667 | Z32: =AVERAGEIFS('Cover Summary'!L$13:L$156,'Cover Summary'!$F$13:$F$156, "NG4936",'Cover Summary'!$E$13:$E$156, "FAO") -> 64.916667 | AA32: =AVERAGEIFS('Cover Summary'!M$13:M$156,'Cover Summary'!$F$13:$F$156, "NG4936",'Cover Summary'!$E$13:$E$156, "FAO") -> 73.916667 | AB32: =AVERAGEIFS('Cover Summary'!N$13:N$156,'Cover Summary'!$F$13:$F$156, "NG4936",'Cover Summary'!$E$13:$E$156, "FAO") -> 88.272727 | ... AF32: =AVERAGEIFS('Cover Summary'!R$13:R$156,'Cover Summary'!$F$13:$F$156, "NG4936",'Cover Summary'!$E$13:$E$156, "FAO") -> 88.5
B34: FAO-N | D34: #VALUE! | E34: #VALUE! | F34: =AVERAGEIFS('Cover Summary'!G$13:G$156,'Cover Summary'!$F$13:$F$156, "NG3195",'Cover Summary'!$E$13:$E$156, "FAO-N") -> 12.833333 | G34: =AVERAGEIFS('Cover Summary'!H$13:H$156,'Cover Summary'!$F$13:$F$156, "NG3195",'Cover Summary'!$E$13:$E$156, "FAO-N") -> 19 | H34: =AVERAGEIFS('Cover Summary'!I$13:I$156,'Cover Summary'!$F$13:$F$156, "NG3195",'Cover Summary'!$E$13:$E$156, "FAO-N") -> 25.75 | I34: =AVERAGEIFS('Cover Summary'!J$13:J$156,'Cover Summary'!$F$13:$F$156, "NG3195",'Cover Summary'!$E$13:$E$156, "FAO-N") -> 51.5 | J34: =AVERAGEIFS('Cover Summary'!K$13:K$156,'Cover Summary'!$F$13:$F$156, "NG3195",'Cover Summary'!$E$13:$E$156, "FAO-N") -> 62.916667 | K34: =AVERAGEIFS('Cover Summary'!L$13:L$156,'Cover Summary'!$F$13:$F$156, "NG3195",'Cover Summary'!$E$13:$E$156, "FAO-N") -> 72.333333 | L34: =AVERAGEIFS('Cover Summary'!M$13:M$156,'Cover Summary'!$F$13:$F$156, "NG3195",'Cover Summary'!$E$13:$E$156, "FAO-N") -> 77.916667 | M34: =AVERAGEIFS('Cover Summary'!N$13:N$156,'Cover Summary'!$F$13:$F$156, "NG3195",'Cover Summary'!$E$13:$E$156, "FAO-N") -> 83.8 | ... Q34: =AVERAGEIFS('Cover Summary'!R$13:R$156,'Cover Summary'!$F$13:$F$156, "NG3195",'Cover Summary'!$E$13:$E$156, "FAO-N") -> 89.285714 | T34: FAO-N | U34: =AVERAGEIFS('Cover Summary'!G$13:G$156,'Cover Summary'!$F$13:$F$156, "NG4936",'Cover Summary'!$E$13:$E$156, "FAO-N") -> 7 | V34: =AVERAGEIFS('Cover Summary'!H$13:H$156,'Cover Summary'!$F$13:$F$156, "NG4936",'Cover Summary'!$E$13:$E$156, "FAO-N") -> 13.5 | W34: =AVERAGEIFS('Cover Summary'!I$13:I$156,'Cover Summary'!$F$13:$F$156, "NG4936",'Cover Summary'!$E$13:$E$156, "FAO-N") -> 18.333333 | X34: =AVERAGEIFS('Cover Summary'!J$13:J$156,'Cover Summary'!$F$13:$F$156, "NG4936",'Cover Summary'!$E$13:$E$156, "FAO-N") -> 39.333333 | Y34: =AVERAGEIFS('Cover Summary'!K$13:K$156,'Cover Summary'!$F$13:$F$156, "NG4936",'Cover Summary'!$E$13:$E$156, "FAO-N") -> 51.75 | Z34: =AVERAGEIFS('Cover Summary'!L$13:L$156,'Cover Summary'!$F$13:$F$156, "NG4936",'Cover Summary'!$E$13:$E$156, "FAO-N") -> 62.25 | AA34: =AVERAGEIFS('Cover Summary'!M$13:M$156,'Cover Summary'!$F$13:$F$156, "NG4936",'Cover Summary'!$E$13:$E$156, "FAO-N") -> 69.416667 | AB34: =AVERAGEIFS('Cover Summary'!N$13:N$156,'Cover Summary'!$F$13:$F$156, "NG4936",'Cover Summary'!$E$13:$E$156, "FAO-N") -> 74.818182 | ... AF34: =AVERAGEIFS('Cover Summary'!R$13:R$156,'Cover Summary'!$F$13:$F$156, "NG4936",'Cover Summary'!$E$13:$E$156, "FAO-N") -> 86.222222
C44: Average Canopy Widths
C46: ='Cover Summary'!F9 -> 0

Sheet Emergence
A1: 2022 | C1: Cotton | E1: Emergence & 1st true leaf
A4: Emergence counts taken at the center flag placed in each plot for canopy measurements (1 row West of neutron tubes).
A6: Counting emerged plants 1 meter from North of the flag.
E10: # plants per 1 meter (1 meter North of each flag)
C11: Date: | D11: 44680 | E11: 44683 | G11: 44684 | I11: 44685 | K11: 44686 | M11: 44690 | P11: 44691 | S11: 44694 | V11: 44697 | Y11: 44700 | AB11: 44704 | AE11: 44707
C12: DOY: | D12: 119 | E12: 122 | G12: 123 | I12: 124 | K12: 125 | M12: 129 | P12: 130 | S12: 133 | V12: 136 | Y12: 139 | AB12: 143 | AE12: 146
C13: by: | D13: KRT | E13: SMM | G13: SMM | I13: SMM | K13: SMM | M13: SMM | P13: SMM | S13: SMM | V13: SMM | Y13: SMM | AB13: SMM | AE13: SMM | AH13: SMM
B15: Plot | E15: plants/1 m | F15: plants starting to emerge | G15: plants/1 m | H15: plants starting to emerge | I15: plants/1 m | J15: plants starting to emerge | K15: plants/1 m | L15: plants starting to emerge | M15: plants/1 m | N15: plants starting to emerge | O15: plants w/ 1st leaf | P15: plants/1 m | Q15: plants starting to emerge | R15: plants w/ 1st leaf | S15: plants/1 m | T15: plants starting to emerge | U15: plants w/ 1st leaf | V15: plants/1 m | W15: plants starting to emerge | X15: plants w/ 1st leaf | Y15: plants/1 m | Z15: plants starting to emerge | AA15: plants w/ 1st leaf | AB15: plants/1 m | AC15: plants starting to emerge | AD15: plants w/ 1st leaf | AE15: plants/1 m | AF15: plants starting to emerge | AG15: plants w/ 1st leaf | AH15: plants/1 m | AI15: plants starting to emerge | AJ15: plants w/ 1st leaf
B16: 01-1 | C16: NG4936 | D16: From an email from KRT: "Some plant up for the NG3195 variety today" | E16: 4 | F16: 1 | G16: 4 | H16: 2 | I16: 4 | J16: 3 | K16: 6 | L16: 3 | M16: 9 | N16: 0 | O16: 0 | P16: 9 | R16: 1 | S16: 9 | T16: 1 | U16: 3 | V16: 9 | X16: 7 | Y16: 9 | AA16: 7 | AB16: 9 | AD16: 8 | AE16: 9 | AG16: 9
B17: 01-2 | C17: NG4936 | E17: 3 | F17: 0 | G17: 4 | H17: 0 | I17: 4 | J17: 1 | K17: 4 | L17: 1 | M17: 7 | N17: 0 | O17: 0 | P17: 7 | R17: 0 | S17: 7 | U17: 3 | V17: 7 | X17: 5 | Y17: 7 | AA17: 5 | AB17: 7 | AD17: 5 | AE17: 7 | AG17: 7
B18: 01-3 | C18: NG4936 | E18: 3 | F18: 2 | G18: 4 | H18: 3 | I18: 4 | J18: 4 | K18: 9 | L18: 0 | M18: 9 | N18: 0 | O18: 0 | P18: 9 | R18: 0 | S18: 9 | U18: 2 | V18: 9 | X18: 5 | Y18: 9 | AA18: 7 | AB18: 9 | AD18: 7 | AE18: 9 | AG18: 8
B19: 01-4 | C19: NG4936 | E19: 1 | F19: 3 | G19: 4 | H19: 2 | I19: 5 | J19: 1 | K19: 8 | L19: 0 | M19: 8 | N19: 0 | O19: 0 | P19: 8 | R19: 1 | S19: 8 | U19: 3 | V19: 8 | X19: 7 | Y19: 8 | AA19: 8 | AB19: 8 | AD19: 7 | AE19: 8 | AG19: 8
B20: 02-4 | C20: NG3195 | E20: 6 | F20: 1 | G20: 6 | H20: 1 | I20: 6 | J20: 1 | K20: 7 | L20: 1 | M20: 8 | N20: 0 | O20: 1 | P20: 8 | R20: 2 | S20: 8 | U20: 5 | V20: 8 | X20: 6 | Y20: 8 | AA20: 6 | AB20: 8 | AD20: 6 | AE20: 8 | AG20: 8
B21: 02-3 | C21: NG3195 | E21: 7 | F21: 0 | G21: 7 | H21: 1 | I21: 7 | J21: 2 | K21: 8 | L21: 1 | M21: 9 | N21: 0 | O21: 2 | P21: 9 | R21: 3 | S21: 9 | U21: 6 | V21: 8 | X21: 8 | Y21: 8 | AA21: 8 | AB21: 8 | AD21: 8 | AE21: 8 | AG21: 8
B22: 02-2 | C22: NG3195 | E22: 4 | F22: 1 | G22: 5 | H22: 0 | I22: 5 | J22: 1 | K22: 5 | L22: 1 | M22: 6 | N22: 0 | O22: 0 | P22: 6 | R22: 1 | S22: 6 | U22: 3 | V22: 6 | X22: 5 | Y22: 6 | AA22: 6 | AB22: 6 | AD22: 6 | AE22: 6 | AG22: 6
