Workbook

Sheet Height
A1: CCID | B1: DOY144 | C1: DOY151 | D1: DOY156 | E1: DOY163 | F1: DOY170 | G1: DOY177 | H1: DOY184 | I1: DOY191 | J1: DOY198 | K1: DOY206 | L1: DOY212 | M1: DOY220 | N1: DOY227 | O1: DOY233 | P1: DOY240 | Q1: DOY248 | R1: DOY255
A2: 01-1A | B2: 13 | C2: 18 | D2: 26 | E2: 32 | F2: 42 | G2: 56 | H2: 64 | I2: 85 | J2: 85 | K2: 103 | L2: 113 | M2: 132 | N2: 146 | O2: 153 | P2: 156 | Q2: 156 | R2: 158
A3: 01-1B | B3: 13 | C3: 18 | D3: 27 | E3: 32 | F3: 45 | G3: 49 | H3: 58 | I3: 68 | J3: 76 | K3: 89 | L3: 95 | M3: 111 | N3: 118 | O3: 130 | P3: 131 | Q3: 134 | R3: 142
A4: 01-1C | B4: 11 | C4: 15 | D4: 22 | E4: 27 | F4: 31 | G4: 36 | H4: 51 | I4: 51 | J4: 63 | K4: 69 | L4: 68 | M4: 72 | N4: 90 | O4: 99 | P4: 102 | Q4: 110 | R4: 117
A5: 01-2A | B5: 12 | C5: 22 | D5: 24 | E5: 34 | F5: 48 | G5: 56 | H5: 69 | I5: 75 | J5: 72 | K5: 95 | L5: 110 | M5: 125 | N5: 126 | O5: 136 | P5: 135 | Q5: 141 | R5: 141
A6: 01-2B | B6: 13 | C6: 20 | D6: 25 | E6: 31 | F6: 40 | G6: 52 | H6: 57 | I6: 65 | J6: 58 | K6: 83 | L6: 96 | M6: 119 | N6: 132 | O6: 141 | P6: 142 | Q6: 153 | R6: 153
A7: 01-2C | B7: 9 | C7: 18 | D7: 23 | E7: 26 | F7: 37 | G7: 47 | H7: 53 | I7: 58 | J7: 71 | K7: 85 | L7: 101 | M7: 114 | N7: 122 | O7: 130 | P7: 124 | Q7: 139 | R7: 139
A8: 01-3A | B8: 13 | C8: 19 | D8: 26 | E8: 21 | F8: 42 | G8: 50 | H8: 57 | I8: 76 | J8: 72 | K8: 84 | L8: 93 | M8: 106 | N8: 118 | O8: 119 | P8: 116 | Q8: 126 | R8: 127
A9: 01-3B | B9: 11 | C9: 15 | D9: 24 | E9: 27 | F9: 38 | G9: 47 | H9: 58 | I9: 70 | J9: 85 | K9: 79 | L9: 96 | M9: 110 | N9: 122 | O9: 128 | P9: 132 | Q9: 139 | R9: 137
A10: 01-3C | B10: 12 | C10: 14 | D10: 24 | E10: 27 | F10: 39 | G10: 50 | H10: 61 | I10: 71 | J10: 94 | K10: 82 | L10: 92 | M10: 103 | N10: 116 | O10: 124 | P10: 118 | Q10: 128 | R10: 131
A11: 01-4A | B11: 10 | C11: 13 | D11: 23 | E11: 20 | F11: 37 | G11: 41 | H11: 44 | I11: 44 | J11: 84 | K11: 55 | L11: 58 | M11: 66 | N11: 70 | O11: 73 | P11: 68 | Q11: 72 | R11: 73
A12: 01-4B | B12: 9 | C12: 16 | D12: 21 | E12: 28 | F12: 31 | G12: 33 | H12: 36 | I12: 42 | J12: 84 | K12: 55 | L12: 38 | M12: 51 | N12: 52 | O12: 49 | P12: 49 | Q12: 54 | R12: 55
A13: 01-4C | B13: 12 | C13: 14 | D13: 25 | E13: 24 | F13: 36 | G13: 38 | H13: 46 | I13: 50 | J13: 74 | K13: 66 | L13: 68 | M13: 73 | N13: 78 | O13: 78 | P13: 73 | Q13: 75 | R13: 73
... A193: 16-4C | B193: 9 | C193: 14 | D193: 21 | E193: 30 | F193: 37 | G193: 48 | H193: 66 | I193: 79 | J193: 85 | K193: 111 | L193: 122 | M193: 133 | N193: 146 | O193: 159 | P193: 168 | Q193: 177 | R193: 166

Sheet Width
A1: CCID | B1: DOY144 | C1: DOY151 | D1: DOY156 | E1: DOY163 | F1: DOY170 | G1: DOY177 | H1: DOY184 | I1: DOY191 | J1: DOY198 | K1: DOY206 | L1: DOY212 | M1: DOY220 | N1: DOY227 | O1: DOY233 | P1: DOY240 | Q1: DOY248 | R1: DOY255
A2: 01-1A | B2: 12 | C2: 12 | D2: 23 | E2: 23 | F2: 40 | G2: 42 | H2: 62 | I2: 76 | J2: 75 | K2: 97 | L2: 102 | M2: 102 | N2: 102 | O2: 102 | P2: 102 | Q2: 102 | R2: 102
A3: 01-1B | B3: 13 | C3: 17 | D3: 25 | E3: 30 | F3: 40 | G3: 44 | H3: 57 | I3: 65 | J3: 59 | K3: 80 | L3: 90 | M3: 97 | N3: 102 | O3: 102 | P3: 102 | Q3: 102 | R3: 102
A4: 01-1C | B4: 9 | C4: 15 | D4: 22 | E4: 21 | F4: 29 | G4: 33 | H4: 39 | I4: 40 | J4: 59 | K4: 53 | L4: 49 | M4: 74 | N4: 76 | O4: 102 | P4: 102 | Q4: 102 | R4: 102
A5: 01-2A | B5: 11 | C5: 18 | D5: 25 | E5: 28 | F5: 42 | G5: 52 | H5: 61 | I5: 67 | J5: 60 | K5: 91 | L5: 100 | M5: 102 | N5: 102 | O5: 102 | P5: 102 | Q5: 102 | R5: 102
A6: 01-2B | B6: 12 | C6: 19 | D6: 22 | E6: 20 | F6: 32 | G6: 44 | H6: 43 | I6: 51 | J6: 38 | K6: 69 | L6: 78 | M6: 102 | N6: 102 | O6: 102 | P6: 102 | Q6: 102 | R6: 102
A7: 01-2C | B7: 8 | C7: 15 | D7: 19 | E7: 27 | F7: 30 | G7: 39 | H7: 47 | I7: 51 | J7: 66 | K7: 70 | L7: 89 | M7: 102 | N7: 102 | O7: 102 | P7: 102 | Q7: 102 | R7: 102
A8: 01-3A | B8: 12 | C8: 15 | D8: 24 | E8: 16 | F8: 39 | G8: 43 | H8: 50 | I8: 62 | J8: 65 | K8: 79 | L8: 77 | M8: 94 | N8: 102 | O8: 102 | P8: 102 | Q8: 102 | R8: 102
A9: 01-3B | B9: 8 | C9: 13 | D9: 22 | E9: 19 | F9: 33 | G9: 39 | H9: 47 | I9: 58 | J9: 75 | K9: 74 | L9: 85 | M9: 95 | N9: 102 | O9: 102 | P9: 102 | Q9: 102 | R9: 102
A10: 01-3C | B10: 11 | C10: 12 | D10: 21 | E10: 17 | F10: 31 | G10: 45 | H10: 56 | I10: 63 | J10: 72 | K10: 76 | L10: 90 | M10: 101 | N10: 102 | O10: 102 | P10: 102 | Q10: 102 | R10: 102
A11: 01-4A | B11: 7 | C11: 10 | D11: 22 | E11: 15 | F11: 30 | G11: 32 | H11: 37 | I11: 38 | J11: 74 | K11: 53 | L11: 56 | M11: 56 | N11: 59 | O11: 66 | P11: 60 | Q11: 66 | R11: 67
A12: 01-4B | B12: 7 | C12: 13 | D12: 18 | E12: 19 | F12: 28 | G12: 29 | H12: 30 | I12: 33 | J12: 72 | K12: 45 | L12: 28 | M12: 26 | N12: 28 | O12: 26 | P12: 27 | Q12: 32 | R12: 30
A13: 01-4C | B13: 9 | C13: 14 | D13: 23 | E13: 15 | F13: 32 | G13: 34 | H13: 41 | I13: 39 | J13: 66 | K13: 55 | L13: 59 | M13: 54 | N13: 68 | O13: 69 | P13: 65 | Q13: 67 | R13: 71
... A193: 16-4C | B193: 8 | C193: 15 | D193: 22 | E193: 34 | F193: 36 | G193: 50 | H193: 61 | I193: 74 | J193: 63 | K193: 94 | L193: 102 | M193: 102 | N193: 102 | O193: 102 | P193: 102 | Q193: 102 | R193: 102

Sheet Ordering
A1: 1 | B1: 1 | C1: N | D1: A | E1: =_xlfn.CONCAT(TEXT(A1,"00"),"-",TEXT(B1,"0"),D1) -> 01-1A
A2: 1 | B2: 1 | C2: M | D2: B | E2: =_xlfn.CONCAT(TEXT(A2,"00"),"-",TEXT(B2,"0"),D2) -> 01-1B
A3: 1 | B3: 1 | C3: S | D3: C | E3: =_xlfn.CONCAT(TEXT(A3,"00"),"-",TEXT(B3,"0"),D3) -> 01-1C
A4: 1 | B4: 2 | C4: N | D4: A | E4: =_xlfn.CONCAT(TEXT(A4,"00"),"-",TEXT(B4,"0"),D4) -> 01-2A
A5: 1 | B5: 2 | C5: M | D5: B | E5: =_xlfn.CONCAT(TEXT(A5,"00"),"-",TEXT(B5,"0"),D5) -> 01-2B
A6: 1 | B6: 2 | C6: S | D6: C | E6: =_xlfn.CONCAT(TEXT(A6,"00"),"-",TEXT(B6,"0"),D6) -> 01-2C
A7: 1 | B7: 3 | C7: N | D7: A | E7: =_xlfn.CONCAT(TEXT(A7,"00"),"-",TEXT(B7,"0"),D7) -> 01-3A
A8: 1 | B8: 3 | C8: M | D8: B | E8: =_xlfn.CONCAT(TEXT(A8,"00"),"-",TEXT(B8,"0"),D8) -> 01-3B
A9: 1 | B9: 3 | C9: S | D9: C | E9: =_xlfn.CONCAT(TEXT(A9,"00"),"-",TEXT(B9,"0"),D9) -> 01-3C
A10: 1 | B10: 4 | C10: N | D10: A | E10: =_xlfn.CONCAT(TEXT(A10,"00"),"-",TEXT(B10,"0"),D10) -> 01-4A
A11: 1 | B11: 4 | C11: M | D11: B | E11: =_xlfn.CONCAT(TEXT(A11,"00"),"-",TEXT(B11,"0"),D11) -> 01-4B
A12: 1 | B12: 4 | C12: S | D12: C | E12: =_xlfn.CONCAT(TEXT(A12,"00"),"-",TEXT(B12,"0"),D12) -> 01-4C
... A192: 16 | B192: 1 | C192: N | D192: A | E192: =_xlfn.CONCAT(TEXT(A192,"00"),"-",TEXT(B192,"0"),D192) -> 16-1A

Sheet Blank Data Sheet
A1: 2017 | C1: F13b4 | E1: Cotton | I1: date: | L1: doy:
I2: time:
B3: Canopy Heights & Widths | I3: by:
B5: Measuring row 4 (from the West edge of plots).
B6: North and South flags are orange and Middle flag is pink.
B7: Plot | D7: Flag | E7: Canopy Height (cm) | F7: Canopy Width (cm) | G7: NAWF | I7: Plot | K7: Flag | L7: Canopy Height (cm) | M7: Canopy Width (cm) | N7: NAWF
B8: 01- | C8: 1 | D8: North | I8: 03- | J8: 1 | K8: North
D9: Mid | K9: Mid
D10: South | K10: South
B11: 01- | C11: 2 | D11: North | I11: 03- | J11: 2 | K11: North
D12: Mid | K12: Mid
D13: South | K13: South
B14: 01- | C14: 3 | D14: North | I14: 03- | J14: 3 | K14: North
D15: Mid | K15: Mid
D16: South | K16: South
B17: 01- | C17: 4 | D17: North | I17: 03- | J17: 4 | K17: North
D18: Mid | K18: Mid
D19: South | K19: South
B20: 02- | C20: 4 | D20: South | I20: 04- | J20: 4 | K20: South
D21: Mid | K21: Mid
D22: North | K22: North
B23: 02- | C23: 3 | D23: South | I23: 04- | J23: 3 | K23: South
D24: Mid | K24: Mid
D25: North | K25: North
B26: 02- | C26: 2 | D26: South | I26: 04- | J26: 2 | K26: South
D27: Mid | K27: Mid
D28: North | K28: North
B29: 02- | C29: 1 | D29: South | I29: 04- | J29: 1 | K29: South
D30: Mid | K30: Mid
D31: North | K31: North
B33: 05- | C33: 1 | D33: North | I33: 07- | J33: 1 | K33: North
D34: Mid | K34: Mid
D35: South | K35: South
B36: 05- | C36: 2 | D36: North | I36: 07- | J36: 2 | K36: North
D37: Mid | K37: Mid
D38: South | K38: South
B39: 05- | C39: 3 | D39: North | I39: 07- | J39: 3 | K39: North
D40: Mid | K40: Mid
D41: South | K41: South
B42: 05- | C42: 4 | D42: North | I42: 07- | J42: 4 | K42: North
...

Sheet Height Summary
A1: Summary | B1: 2017 | D1: F13b4 | F1: Cotton | H1: Entered by SMM | T1: b
H2: Proofed by MH
B3: Canopy Heights - Summary | H3: Corrections made by SMM
B5: Measuring row 4 (from the West edge of plots).
B7: North and South flags are orange and Middle flag is pink.
D8: Initials: | F8: SMM | G8: Frank | H8: SMM | I8: SH | J8: SMM | K8: SMM | L8: SMM | M8: SMM | N8: SMM | O8: SMM | P8: SMM | Q8: SMM | R8: SMM | S8: SMM | T8: SMM | U8: SMM | V8: SMM
D9: Date: | F9: 42879 | G9: 42886 | H9: 42891 | I9: 42898 | J9: 42905 | K9: 42912 | L9: 42919 | M9: 42926 | N9: 42933 | O9: 42941 | P9: 42947 | Q9: 42955 | R9: 42962 | S9: 42968 | T9: 42975 | U9: 42983 | V9: 42990
D10: DOY: | F10: 144 | G10: 151 | H10: 156 | I10: 163 | J10: 170 | K10: 177 | L10: 184 | M10: 191 | N10: 198 | O10: 206 | P10: 212 | Q10: 220 | R10: 227 | S10: 233 | T10: 240 | U10: 248 | V10: 255 | X10: 144 | Y10: 151 | Z10: 156 | AA10: 163 | AB10: 170 | AC10: 177 | AD10: 184 | AE10: 191 | AF10: 198 | AG10: 206 | AH10: 212 | AI10: 220 | AJ10: 227 | AK10: 233 | AL10: 240 | AM10: 248 | AN10: 255
D11: Time: | F11: 1420-1525h | H11: 0950-1120h | I11: 1024-1207h | J11: 1000-1140h | K11: 0945-1200h | L11: 0945-1215h | M11: 0930-1130h | N11: 1000-1230h | O11: 0930-1230h | P11: 1000-1200h | Q11: 1050-1250h | R11: 1000-1300h | S11: 1000-1200h | T11: 1000-1215h | U11: 1000-1200h | V11: 0930-1200h
B12: Plot | D12: Flag | E12: TRT | F12: Height (cm) | G12: Height (cm) | H12: Height (cm) | I12: Height (cm) | J12: Height (cm) | K12: Height (cm) | L12: Height (cm) | M12: Height (cm) | N12: Height (cm) | O12: Height (cm) | P12: Height (cm) | Q12: Height (cm) | R12: Height (cm) | S12: Height (cm) | T12: Height (cm) | U12: Height (cm) | V12: Height (cm)
B13: 01- | C13: 1 | D13: North | E13: 80-120 | F13: 13 | G13: 18 | H13: 26 | I13: 32 | J13: 42 | K13: 56 | L13: 64 | M13: 85 | N13: 85 | O13: 103 | P13: 113 | Q13: 132 | R13: 146 | S13: 153 | T13: 156 | U13: 156 | V13: 158
D14: Mid | E14: 80-120 | F14: 13 | G14: 18 | H14: 27 | I14: 31.5 | J14: 45 | K14: 49 | L14: 58 | M14: 68 | N14: 76 | O14: 89 | P14: 95 | Q14: 111 | R14: 118 | S14: 130 | T14: 131 | U14: 134 | V14: 142 | X14: =AVERAGE(F13:F15) -> 12.333333 | Y14: =AVERAGE(G13:G15) -> 17 | Z14: =AVERAGE(H13:H15) -> 25 | AA14: =AVERAGE(I13:I15) -> 30.166667 | AB14: =AVERAGE(J13:J15) -> 39.333333 | AC14: =AVERAGE(K13:K15) -> 47 | AD14: =AVERAGE(L13:L15) -> 57.666667 | AE14: =AVERAGE(M13:M15) -> 68 | ... AN14: =AVERAGE(V13:V15) -> 139
D15: South | E15: 80-120 | F15: 11 | G15: 15 | H15: 22 | I15: 27 | J15: 31 | K15: 36 | L15: 51 | M15: 51 | N15: 63 | O15: 69 | P15: 68 | Q15: 72 | R15: 90 | S15: 99 | T15: 102 | U15: 110 | V15: 117
B16: 01- | C16: 2 | D16: North | E16: 100-100 | F16: 12 | G16: 22 | H16: 24 | I16: 34 | J16: 48 | K16: 56 | L16: 69 | M16: 75 | N16: 72 | O16: 95 | P16: 110 | Q16: 125 | R16: 126 | S16: 136 | T16: 135 | U16: 141 | V16: 141
D17: Mid | E17: 100-100 | F17: 13 | G17: 20 | H17: 25 | I17: 31 | J17: 40 | K17: 52 | L17: 57 | M17: 65 | N17: 58 | O17: 83 | P17: 96 | Q17: 119 | R17: 132 | S17: 141 | T17: 142 | U17: 153 | V17: 153 | X17: =AVERAGE(F16:F18) -> 11.333333 | Y17: =AVERAGE(G16:G18) -> 20 | Z17: =AVERAGE(H16:H18) -> 24 | AA17: =AVERAGE(I16:I18) -> 30.333333 | AB17: =AVERAGE(J16:J18) -> 41.666667 | AC17: =AVERAGE(K16:K18) -> 51.666667 | AD17: =AVERAGE(L16:L18) -> 59.666667 | AE17: =AVERAGE(M16:M18) -> 66 | ... AN17: =AVERAGE(V16:V18) -> 144.33333
D18: South | E18: 100-100 | F18: 9 | G18: 18 | H18: 23 | I18: 26 | J18: 37 | K18: 47 | L18: 53 | M18: 58 | N18: 71 | O18: 85 | P18: 101 | Q18: 114 | R18: 122 | S18: 130 | T18: 124 | U18: 139 | V18: 139
B19: 01- | C19: 3 | D19: North | E19: 80-100 | F19: 13 | G19: 19 | H19: 26 | I19: 21 | J19: 42 | K19: 50 | L19: 57 | M19: 76 | N19: 72 | O19: 84 | P19: 93 | Q19: 106 | R19: 118 | S19: 119 | T19: 116 | U19: 126 | V19: 127
D20: Mid | E20: 80-100 | F20: 11 | G20: 15 | H20: 24 | I20: 27 | J20: 38 | K20: 47 | L20: 58 | M20: 70 | N20: 85 | O20: 79 | P20: 96 | Q20: 110 | R20: 122 | S20: 128 | T20: 132 | U20: 139 | V20: 137 | X20: =AVERAGE(F19:F21) -> 12 | Y20: =AVERAGE(G19:G21) -> 16 | Z20: =AVERAGE(H19:H21) -> 24.666667 | AA20: =AVERAGE(I19:I21) -> 24.833333 | AB20: =AVERAGE(J19:J21) -> 39.666667 | AC20: =AVERAGE(K19:K21) -> 49 | AD20: =AVERAGE(L19:L21) -> 58.666667 | AE20: =AVERAGE(M19:M21) -> 72.333333 | ... AN20: =AVERAGE(V19:V21) -> 131.66667
D21: South | E21: 80-100 | F21: 12 | G21: 14 | H21: 24 | I21: 26.5 | J21: 39 | K21: 50 | L21: 61 | M21: 71 | N21: 94 | O21: 82 | P21: 92 | Q21: 103 | R21: 116 | S21: 124 | T21: 118 | U21: 128 | V21: 131
B22: 01- | C22: 4 | D22: North | E22: 60-60 | F22: 10 | G22: 13 | H22: 23 | I22: 20 | J22: 37 | K22: 41 | L22: 44 | M22: 44 | N22: 84 | O22: 55 | P22: 58 | Q22: 66 | R22: 70 | S22: 73 | T22: 68 | U22: 72 | V22: 73
D23: Mid | E23: 60-60 | F23: 9 | G23: 16 | H23: 21 | I23: 27.5 | J23: 31 | K23: 33 | L23: 36 | M23: 42 | N23: 84 | O23: 55 | P23: 38 | Q23: 51 | R23: 52 | S23: 49 | T23: 49 | U23: 54 | V23: 55 | X23: =AVERAGE(F22:F24) -> 10.333333 | Y23: =AVERAGE(G22:G24) -> 14.333333 | Z23: =AVERAGE(H22:H24) -> 23 | AA23: =AVERAGE(I22:I24) -> 23.833333 | AB23: =AVERAGE(J22:J24) -> 34.666667 | AC23: =AVERAGE(K22:K24) -> 37.333333 | AD23: =AVERAGE(L22:L24) -> 42 | AE23: =AVERAGE(M22:M24) -> 45.333333 | ... AN23: =AVERAGE(V22:V24) -> 67
D24: South | E24: 60-60 | F24: 12 | G24: 14 | H24: 25 | I24: 24 | J24: 36 | K24: 38 | L24: 46 | M24: 50 | N24: 74 | O24: 66 | P24: 68 | Q24: 73 | R24: 78 | S24: 78 | T24: 73 | U24: 75 | V24: 73
B25: 02- | C25: 4 | D25: South | E25: 120-120 | F25: 10 | G25: 14 | H25: 23 | I25: 20 | J25: 37 | K25: 43 | L25: 53 | M25: 61 | N25: 66 | O25: 83 | P25: 93 | Q25: 110 | R25: 118 | S25: 124 | T25: 125 | U25: 127 | V25: 127
D26: Mid | E26: 120-120 | F26: 11 | G26: 13 | H26: 23 | I26: 28 | J26: 38 | K26: 52 | L26: 66 | M26: 77 | N26: 90 | O26: 98 | P26: 111 | Q26: 125 | R26: 129 | S26: 132 | T26: 133 | U26: 127 | V26: 125 | X26: =AVERAGE(F25:F27) -> 10.666667 | Y26: =AVERAGE(G25:G27) -> 13.666667 | Z26: =AVERAGE(H25:H27) -> 22 | AA26: =AVERAGE(I25:I27) -> 25 | AB26: =AVERAGE(J25:J27) -> 38.666667 | AC26: =AVERAGE(K25:K27) -> 50.333333 | AD26: =AVERAGE(L25:L27) -> 63.666667 | AE26: =AVERAGE(M25:M27) -> 75 | ... AN26: =AVERAGE(V25:V27) -> 132
D27: North | E27: 120-120 | F27: 11 | G27: 14 | H27: 20 | I27: 27 | J27: 41 | K27: 56 | L27: 72 | M27: 87 | N27: 102 | O27: 114 | P27: 124 | Q27: 128 | R27: 141 | S27: 145 | T27: 142 | U27: 143 | V27: 144
B28: 02- | C28: 3 | D28: South | E28: 100-60 | F28: 11 | G28: 18 | H28: 23 | I28: 34 | J28: 39 | K28: 53 | L28: 66 | M28: 75 | N28: 84 | O28: 92 | P28: 103 | Q28: 115 | R28: 115 | S28: 109 | T28: 105 | U28: 106 | V28: 102
D29: Mid | E29: 100-60 | F29: 10 | G29: 13 | H29: 25 | I29: 29.5 | J29: 43 | K29: 55 | L29: 74 | M29: 83 | N29: 104 | O29: 109 | P29: 116 | Q29: 124 | R29: 130 | S29: 129 | T29: 125 | U29: 125 | V29: 124 | X29: =AVERAGE(F28:F30) -> 10 | Y29: =AVERAGE(G28:G30) -> 16.333333 | Z29: =AVERAGE(H28:H30) -> 23.333333 | AA29: =AVERAGE(I28:I30) -> 33.833333 | AB29: =AVERAGE(J28:J30) -> 41 | AC29: =AVERAGE(K28:K30) -> 52.333333 | AD29: =AVERAGE(L28:L30) -> 67.333333 | AE29: =AVERAGE(M28:M30) -> 74.333333 | ... AN29: =AVERAGE(V28:V30) -> 106.33333
D30: North | E30: 100-60 | F30: 9 | G30: 18 | H30: 22 | I30: 38 | J30: 41 | K30: 49 | L30: 62 | M30: 65 | N30: 72 | O30: 88 | P30: 92 | Q30: 88 | R30: 95 | S30: 89 | T30: 91 | U30: 88 | V30: 93
B31: 02- | C31: 2 | D31: South | E31: 60-120 | F31: 10 | G31: 19 | H31: 24 | I31: 33.5 | J31: 37 | K31: 45 | L31: 51 | M31: 55 | N31: 61 | O31: 70 | P31: 80 | Q31: 97 | R31: 113 | S31: 115 | T31: 133 | U31: 142 | V31: 149
D32: Mid | E32: 60-120 | F32: 10 | G32: 14 | H32: 24 | I32: 25 | J32: 40 | K32: 47 | L32: 52 | M32: 52 | N32: 59 | O32: 64 | P32: 82 | Q32: 98 | R32: 117 | S32: 128 | T32: 136 | U32: 148 | V32: 128 | X32: =AVERAGE(F31:F33) -> 10 | Y32: =AVERAGE(G31:G33) -> 16.333333 | Z32: =AVERAGE(H31:H33) -> 23.333333 | AA32: =AVERAGE(I31:I33) -> 28.5 | AB32: =AVERAGE(J31:J33) -> 37 | AC32: =AVERAGE(K31:K33) -> 43.666667 | AD32: =AVERAGE(L31:L33) -> 49 | AE32: =AVERAGE(M31:M33) -> 51.333333 | ... AN32: =AVERAGE(V31:V33) -> 136.33333
D33: North | E33: 60-120 | F33: 10 | G33: 16 | H33: 22 | I33: 27 | J33: 34 | K33: 39 | L33: 44 | M33: 47 | N33: 54 | O33: 72 | P33: 74 | Q33: 90 | R33: 107 | S33: 119 | T33: 124 | U33: 132 | V33: 132
B34: 02- | C34: 1 | D34: South | E34: 120-80 | F34: 10 | G34: 19 | H34: 24 | I34: 36 | J34: 42 | K34: 56 | L34: 68 | M34: 89 | N34: 96 | O34: 119 | P34: 120 | Q34: 122 | R34: 132 | S34: 127 | T34: 132 | U34: 130 | V34: 126
D35: Mid | E35: 120-80 | F35: 11 | G35: 15 | H35: 24 | I35: 39 | J35: 43 | K35: 57 | L35: 78 | M35: 99 | N35: 104 | O35: 131 | P35: 124 | Q35: 125 | R35: 136 | S35: 132 | T35: 136 | U35: 133 | V35: 131 | X35: =AVERAGE(F34:F36) -> 10.333333 | Y35: =AVERAGE(G34:G36) -> 17.333333 | Z35: =AVERAGE(H34:H36) -> 24 | AA35: =AVERAGE(I34:I36) -> 36.333333 | AB35: =AVERAGE(J34:J36) -> 44 | AC35: =AVERAGE(K34:K36) -> 57.333333 | AD35: =AVERAGE(L34:L36) -> 73.333333 | AE35: =AVERAGE(M34:M36) -> 91 | ... AN35: =AVERAGE(V34:V36) -> 126.33333
D36: North | E36: 120-80 | F36: 10 | G36: 18 | H36: 24 | I36: 34 | J36: 47 | K36: 59 | L36: 74 | M36: 85 | N36: 98 | O36: 121 | P36: 117 | Q36: 120 | R36: 125 | S36: 126 | T36: 129 | U36: 128 | V36: 122
B37: 03- | C37: 1 | D37: North | E37: 120-100 | F37: 9 | G37: 15 | H37: 21 | I37: 33 | J37: 42 | K37: 56 | L37: 68 | M37: 81 | N37: 98 | O37: 123 | P37: 131 | Q37: 143 | R37: 159 | S37: 169 | T37: 173 | U37: 174 | V37: 182
D38: Mid | E38: 120-100 | F38: 10 | G38: 17 | H38: 23 | I38: 31.5 | J38: 45 | K38: 65 | L38: 73 | M38: 91 | N38: 107 | O38: 120 | P38: 130 | Q38: 144 | R38: 158 | S38: 159 | T38: 161 | U38: 169 | V38: 166 | X38: =AVERAGE(F37:F39) -> 10 | Y38: =AVERAGE(G37:G39) -> 17.333333 | Z38: =AVERAGE(H37:H39) -> 22 | AA38: =AVERAGE(I37:I39) -> 32.5 | AB38: =AVERAGE(J37:J39) -> 43.666667 | AC38: =AVERAGE(K37:K39) -> 60.666667 | AD38: =AVERAGE(L37:L39) -> 68.333333 | AE38: =AVERAGE(M37:M39) -> 84.333333 | ... AN38: =AVERAGE(V37:V39) -> 163.66667
D39: South | E39: 120-100 | F39: 11 | G39: 20 | H39: 22 | I39: 33 | J39: 44 | K39: 61 | L39: 64 | M39: 81 | N39: 91 | O39: 102 | P39: 118 | Q39: 130 | R39: 132 | S39: 141 | T39: 139 | U39: 144 | V39: 143
B40: 03- | C40: 2 | D40: North | E40: 60-80 | F40: 10 | G40: 13 | H40: 25 | I40: 28 | J40: 42 | K40: 53 | L40: 59 | M40: 65 | N40: 75 | O40: 82 | P40: 90 | Q40: 104 | R40: 111 | S40: 111 | T40: 120 | U40: 119 | V40: 120
D41: Mid | E41: 60-80 | F41: 13 | G41: 21 | H41: 25 | I41: 36.5 | J41: 39 | K41: 45 | L41: 49 | M41: 52 | N41: 58 | O41: 58 | P41: 76 | Q41: 85 | R41: 102 | S41: 102 | T41: 105 | U41: 109 | V41: 107 | X41: =AVERAGE(F40:F42) -> 11.666667 | Y41: =AVERAGE(G40:G42) -> 17.333333 | Z41: =AVERAGE(H40:H42) -> 24.666667 | AA41: =AVERAGE(I40:I42) -> 31.166667 | AB41: =AVERAGE(J40:J42) -> 38.666667 | AC41: =AVERAGE(K40:K42) -> 45.666667 | AD41: =AVERAGE(L40:L42) -> 50.333333 | AE41: =AVERAGE(M40:M42) -> 55 | ... AN41: =AVERAGE(V40:V42) -> 101
D42: South | E42: 60-80 | F42: 12 | G42: 18 | H42: 24 | I42: 29 | J42: 35 | K42: 39 | L42: 43 | M42: 48 | N42: 54 | O42: 63 | P42: 66 | Q42: 67 | R42: 82 | S42: 85 | T42: 89 | U42: 79 | V42: 76
...

Sheet Cover Summary
A1: Summary | B1: 2017 | D1: F13b4 | F1: Cotton | H1: Entered by SMM
H2: Proofed by MH
B3: Canopy Heights - Summary
B5: Measuring row 4 (from the West edge of plots). Width between row measured between rows 4 & 5.
B6: North and South flags are orange and Middle flag is pink.
D8: Initials: | F8: SMM | G8: Frank | H8: SMM | I8: SH | J8: SMM | K8: SMM | L8: SMM | M8: SMM | N8: SMM | O8: SMM | P8: SMM | Q8: SMM | R8: SMM | S8: SMM | T8: SMM | U8: SMM | V8: SMM
D9: Date: | F9: 42879 | G9: 42886 | H9: 42891 | I9: 42898 | J9: 42905 | K9: 42912 | L9: 42919 | M9: 42926 | N9: 42933 | O9: 42941 | P9: 42947 | Q9: 42955 | R9: 42962 | S9: 42968 | T9: 42975 | U9: 42983 | V9: 42990
D10: DOY: | F10: 144 | G10: 151 | H10: 156 | I10: 163 | J10: 170 | K10: 177 | L10: 184 | M10: 191 | N10: 198 | O10: 206 | P10: 212 | Q10: 220 | R10: 227 | S10: 233 | T10: 240 | U10: 248 | V10: 255
D11: Time: | F11: 1420-1525h | H11: 0950-1120h | I11: 1024-1207h | J11: 1000-1140h | K11: 0945-1200h | L11: 0945-1215h | M11: 0930-1130h | N11: 1000-1230h | O11: 0930-1230h | P11: 1000-1200h | Q11: 1050-1250h | R11: 1000-1300h | S11: 1000-1200h | T11: 1000-1215h | U11: 1000-1200h | V11: 0930-1200h
B12: Plot | D12: Flag | E12: TRT | F12: Canopy Width (cm) | G12: Canopy Width (cm) | H12: Canopy Width (cm) | I12: Canopy Width (cm) | J12: Canopy Width (cm) | K12: Canopy Width (cm) | L12: Canopy Width (cm) | M12: Canopy Width (cm) | N12: Canopy Width (cm) | O12: Canopy Width (cm) | P12: Canopy Width (cm) | Q12: Canopy Width (cm) | R12: Canopy Width (cm) | S12: Canopy Width (cm) | T12: Canopy Width (cm) | U12: Canopy Width (cm) | V12: Canopy Width (cm)
B13: 01- | C13: 1 | D13: North | E13: 80-120 | F13: 12 | G13: 12 | H13: 23 | I13: 23 | J13: 40 | K13: 42 | L13: 62 | M13: 76 | N13: 75 | O13: 97 | P13: 102 | Q13: 102 | R13: 102 | S13: 102 | T13: 102 | U13: 102 | V13: 102
D14: Mid | E14: 80-120 | F14: 13 | G14: 17 | H14: 25 | I14: 30 | J14: 40 | K14: 44 | L14: 57 | M14: 65 | N14: 59 | O14: 80 | P14: 90 | Q14: 97 | R14: 102 | S14: 102 | T14: 102 | U14: 102 | V14: 102
D15: South | E15: 80-120 | F15: 9 | G15: 15 | H15: 22 | I15: 21 | J15: 29 | K15: 33 | L15: 39 | M15: 40 | N15: 59 | O15: 53 | P15: 49 | Q15: 74 | R15: 76 | S15: 102 | T15: 102 | U15: 102 | V15: 102
B16: 01- | C16: 2 | D16: North | E16: 100-100 | F16: 11 | G16: 18 | H16: 25 | I16: 28 | J16: 42 | K16: 52 | L16: 61 | M16: 67 | N16: 60 | O16: 91 | P16: 100 | Q16: 102 | R16: 102 | S16: 102 | T16: 102 | U16: 102 | V16: 102
D17: Mid | E17: 100-100 | F17: 12 | G17: 19 | H17: 22 | I17: 20 | J17: 32 | K17: 44 | L17: 43 | M17: 51 | N17: 38 | O17: 69 | P17: 78 | Q17: 102 | R17: 102 | S17: 102 | T17: 102 | U17: 102 | V17: 102
D18: South | E18: 100-100 | F18: 8 | G18: 15 | H18: 19 | I18: 27 | J18: 30 | K18: 39 | L18: 47 | M18: 51 | N18: 66 | O18: 70 | P18: 89 | Q18: 102 | R18: 102 | S18: 102 | T18: 102 | U18: 102 | V18: 102
B19: 01- | C19: 3 | D19: North | E19: 80-100 | F19: 12 | G19: 15 | H19: 24 | I19: 16 | J19: 39 | K19: 43 | L19: 50 | M19: 62 | N19: 65 | O19: 79 | P19: 77 | Q19: 94 | R19: 102 | S19: 102 | T19: 102 | U19: 102 | V19: 102
D20: Mid | E20: 80-100 | F20: 8 | G20: 13 | H20: 22 | I20: 19 | J20: 33 | K20: 39 | L20: 47 | M20: 58 | N20: 75 | O20: 74 | P20: 85 | Q20: 95 | R20: 102 | S20: 102 | T20: 102 | U20: 102 | V20: 102
D21: South | E21: 80-100 | F21: 11 | G21: 12 | H21: 21 | I21: 17 | J21: 31 | K21: 45 | L21: 56 | M21: 63 | N21: 72 | O21: 76 | P21: 90 | Q21: 101 | R21: 102 | S21: 102 | T21: 102 | U21: 102 | V21: 102
B22: 01- | C22: 4 | D22: North | E22: 60-60 | F22: 7 | G22: 10 | H22: 22 | I22: 15 | J22: 30 | K22: 32 | L22: 37 | M22: 38 | N22: 74 | O22: 53 | P22: 56 | Q22: 56 | R22: 59 | S22: 66 | T22: 60 | U22: 66 | V22: 67
D23: Mid | E23: 60-60 | F23: 7 | G23: 13 | H23: 18 | I23: 19 | J23: 28 | K23: 29 | L23: 30 | M23: 33 | N23: 72 | O23: 45 | P23: 28 | Q23: 26 | R23: 28 | S23: 26 | T23: 27 | U23: 32 | V23: 30
D24: South | E24: 60-60 | F24: 9 | G24: 14 | H24: 23 | I24: 15 | J24: 32 | K24: 34 | L24: 41 | M24: 39 | N24: 66 | O24: 55 | P24: 59 | Q24: 54 | R24: 68 | S24: 69 | T24: 65 | U24: 67 | V24: 71
B25: 02- | C25: 4 | D25: South | E25: 120-120 | F25: 10 | G25: 15 | H25: 20 | I25: 21 | J25: 31 | K25: 35 | L25: 41 | M25: 47 | N25: 60 | O25: 73 | P25: 81 | Q25: 102 | R25: 102 | S25: 102 | T25: 102 | U25: 102 | V25: 102
D26: Mid | E26: 120-120 | F26: 10 | G26: 13 | H26: 21 | I26: 25 | J26: 34 | K26: 47 | L26: 61 | M26: 68 | N26: 82 | O26: 87 | P26: 97 | Q26: 102 | R26: 102 | S26: 102 | T26: 102 | U26: 102 | V26: 102
D27: North | E27: 120-120 | F27: 9 | G27: 12 | H27: 19 | I27: 27 | J27: 38 | K27: 47 | L27: 66 | M27: 76 | N27: 89 | O27: 94 | P27: 102 | Q27: 102 | R27: 102 | S27: 102 | T27: 102 | U27: 102 | V27: 102
B28: 02- | C28: 3 | D28: South | E28: 100-60 | F28: 10 | G28: 16 | H28: 22 | I28: 32 | J28: 36 | K28: 44 | L28: 57 | M28: 66 | N28: 71 | O28: 87 | P28: 96 | Q28: 102 | R28: 102 | S28: 102 | T28: 102 | U28: 102 | V28: 102
D29: Mid | E29: 100-60 | F29: 9 | G29: 9 | H29: 23 | I29: 31 | J29: 37 | K29: 49 | L29: 63 | M29: 78 | N29: 92 | O29: 91 | P29: 100 | Q29: 102 | R29: 102 | S29: 102 | T29: 102 | U29: 102 | V29: 102
D30: North | E30: 100-60 | F30: 7 | G30: 18 | H30: 20 | I30: 33 | J30: 34 | K30: 46 | L30: 54 | M30: 59 | N30: 72 | O30: 82 | P30: 85 | Q30: 83 | R30: 89 | S30: 95 | T30: 102 | U30: 94 | V30: 102
B31: 02- | C31: 2 | D31: South | E31: 60-120 | F31: 9 | G31: 18 | H31: 22 | I31: 28 | J31: 29 | K31: 36 | L31: 39 | M31: 43 | N31: 50 | O31: 64 | P31: 72 | Q31: 96 | R31: 95 | S31: 102 | T31: 102 | U31: 102 | V31: 102
D32: Mid | E32: 60-120 | F32: 9 | G32: 10 | H32: 21 | I32: 21 | J32: 32 | K32: 36 | L32: 38 | M32: 43 | N32: 46 | O32: 59 | P32: 62 | Q32: 91 | R32: 96 | S32: 102 | T32: 102 | U32: 102 | V32: 102
D33: North | E33: 60-120 | F33: 8 | G33: 15 | H33: 18 | I33: 27.5 | J33: 32 | K33: 34 | L33: 33 | M33: 40 | N33: 43 | O33: 63 | P33: 67 | Q33: 79 | R33: 97 | S33: 102 | T33: 102 | U33: 102 | V33: 102
B34: 02- | C34: 1 | D34: South | E34: 120-80 | F34: 10 | G34: 20 | H34: 23 | I34: 40 | J34: 42 | K34: 51 | L34: 67 | M34: 74 | N34: 88 | O34: 102 | P34: 102 | Q34: 102 | R34: 102 | S34: 102 | T34: 102 | U34: 102 | V34: 102
D35: Mid | E35: 120-80 | F35: 10 | G35: 17 | H35: 21 | I35: 38 | J35: 41 | K35: 55 | L35: 69 | M35: 85 | N35: 91 | O35: 102 | P35: 102 | Q35: 102 | R35: 102 | S35: 102 | T35: 102 | U35: 102 | V35: 102
D36: North | E36: 120-80 | F36: 9 | G36: 19 | H36: 23 | I36: 33 | J36: 45 | K36: 50 | L36: 70 | M36: 79 | N36: 90 | O36: 96 | P36: 102 | Q36: 102 | R36: 102 | S36: 102 | T36: 102 | U36: 102 | V36: 102
B37: 03- | C37: 1 | D37: North | E37: 120-100 | F37: 8 | G37: 17 | H37: 18 | I37: 34 | J37: 38 | K37: 50 | L37: 58 | M37: 69 | N37: 83 | O37: 102 | P37: 102 | Q37: 102 | R37: 102 | S37: 102 | T37: 102 | U37: 102 | V37: 102
D38: Mid | E38: 120-100 | F38: 9 | G38: 14 | H38: 20 | I38: 34 | J38: 41 | K38: 62 | L38: 69 | M38: 83 | N38: 97 | O38: 102 | P38: 102 | Q38: 102 | R38: 102 | S38: 102 | T38: 102 | U38: 102 | V38: 102
D39: South | E39: 120-100 | F39: 9 | G39: 16 | H39: 21 | I39: 31 | J39: 40 | K39: 57 | L39: 61 | M39: 74 | N39: 82 | O39: 90 | P39: 102 | Q39: 102 | R39: 102 | S39: 102 | T39: 102 | U39: 102 | V39: 102
B40: 03- | C40: 2 | D40: North | E40: 60-80 | F40: 8 | G40: 11 | H40: 23 | I40: 27 | J40: 37 | K40: 48 | L40: 46 | M40: 57 | N40: 63 | O40: 65 | P40: 77 | Q40: 90 | R40: 102 | S40: 102 | T40: 102 | U40: 102 | V40: 102
D41: Mid | E41: 60-80 | F41: 10 | G41: 24 | H41: 25 | I41: 34 | J41: 33 | K41: 37 | L41: 41 | M41: 42 | N41: 42 | O41: 49 | P41: 76 | Q41: 89 | R41: 96 | S41: 91 | T41: 102 | U41: 102 | V41: 102
D42: South | E42: 60-80 | F42: 11 | G42: 15 | H42: 22 | I42: 31 | J42: 30 | K42: 37 | L42: 40 | M42: 39 | N42: 37 | O42: 46 | P42: 54 | Q42: 56 | R42: 66 | S42: 70 | T42: 70 | U42: 83 | V42: 78
...

Sheet Averages
A1: Averages by treatments
E2: Variable rate irrigation started 1 June 2017 (d152) | M2: Irrigation treatment changed starting the 19th of July
D3: Average Canopy Heights
C5: Date: | D5: ='Height Summary'!F9 -> 42879 | E5: ='Height Summary'!G9 -> 42886 | F5: ='Height Summary'!H9 -> 42891 | G5: ='Height Summary'!I9 -> 42898 | H5: ='Height Summary'!J9 -> 42905 | I5: ='Height Summary'!K9 -> 42912 | J5: ='Height Summary'!L9 -> 42919 | K5: ='Height Summary'!M9 -> 42926 | ... Q5: ='Height Summary'!S9 -> 42968
C6: DOY: | D6: ='Height Summary'!F10 -> 144 | E6: ='Height Summary'!G10 -> 151 | F6: ='Height Summary'!H10 -> 156 | G6: ='Height Summary'!I10 -> 163 | H6: ='Height Summary'!J10 -> 170 | I6: ='Height Summary'!K10 -> 177 | J6: ='Height Summary'!L10 -> 184 | K6: ='Height Summary'!M10 -> 191 | ... Q6: ='Height Summary'!S10 -> 233
B7: Ave of all 60-##: | C7: 60-60 | D7: =AVERAGEIFS('Height Summary'!F$13:F$204,'Height Summary'!$E$13:$E$204, "60-60") -> 11 | E7: =AVERAGEIFS('Height Summary'!G$13:G$204,'Height Summary'!$E$13:$E$204, "60-60") -> 15.916667 | F7: =AVERAGEIFS('Height Summary'!H$13:H$204,'Height Summary'!$E$13:$E$204, "60-60") -> 22.333333 | G7: =AVERAGEIFS('Height Summary'!I$13:I$204,'Height Summary'!$E$13:$E$204, "60-60") -> 27.958333 | H7: =AVERAGEIFS('Height Summary'!J$13:J$204,'Height Summary'!$E$13:$E$204, "60-60") -> 35.25 | I7: =AVERAGEIFS('Height Summary'!K$13:K$204,'Height Summary'!$E$13:$E$204, "60-60") -> 39.333333 | J7: =AVERAGEIFS('Height Summary'!L$13:L$204,'Height Summary'!$E$13:$E$204, "60-60") -> 47.416667 | K7: =AVERAGEIFS('Height Summary'!M$13:M$204,'Height Summary'!$E$13:$E$204, "60-60") -> 50.416667 | ... Q7: =AVERAGEIFS('Height Summary'!S$13:S$204,'Height Summary'!$E$13:$E$204, "60-60") -> 81.75
C8: 60-80 | D8: =AVERAGEIFS('Height Summary'!F$13:F$204,'Height Summary'!$E$13:$E$204, "60-80") -> 10.666667 | E8: =AVERAGEIFS('Height Summary'!G$13:G$204,'Height Summary'!$E$13:$E$204, "60-80") -> 14.833333 | F8: =AVERAGEIFS('Height Summary'!H$13:H$204,'Height Summary'!$E$13:$E$204, "60-80") -> 21.5 | G8: =AVERAGEIFS('Height Summary'!I$13:I$204,'Height Summary'!$E$13:$E$204, "60-80") -> 28.375 | H8: =AVERAGEIFS('Height Summary'!J$13:J$204,'Height Summary'!$E$13:$E$204, "60-80") -> 34.916667 | I8: =AVERAGEIFS('Height Summary'!K$13:K$204,'Height Summary'!$E$13:$E$204, "60-80") -> 39.5 | J8: =AVERAGEIFS('Height Summary'!L$13:L$204,'Height Summary'!$E$13:$E$204, "60-80") -> 44.833333 | K8: =AVERAGEIFS('Height Summary'!M$13:M$204,'Height Summary'!$E$13:$E$204, "60-80") -> 48.25 | ... Q8: =AVERAGEIFS('Height Summary'!S$13:S$204,'Height Summary'!$E$13:$E$204, "60-80") -> 91.583333
C9: 60-100 | D9: =AVERAGEIFS('Height Summary'!F$13:F$204,'Height Summary'!$E$13:$E$204, "60-100") -> 10.833333 | E9: =AVERAGEIFS('Height Summary'!G$13:G$204,'Height Summary'!$E$13:$E$204, "60-100") -> 15.166667 | F9: =AVERAGEIFS('Height Summary'!H$13:H$204,'Height Summary'!$E$13:$E$204, "60-100") -> 20.833333 | G9: =AVERAGEIFS('Height Summary'!I$13:I$204,'Height Summary'!$E$13:$E$204, "60-100") -> 28.833333 | H9: =AVERAGEIFS('Height Summary'!J$13:J$204,'Height Summary'!$E$13:$E$204, "60-100") -> 34.083333 | I9: =AVERAGEIFS('Height Summary'!K$13:K$204,'Height Summary'!$E$13:$E$204, "60-100") -> 39.083333 | J9: =AVERAGEIFS('Height Summary'!L$13:L$204,'Height Summary'!$E$13:$E$204, "60-100") -> 44 | K9: =AVERAGEIFS('Height Summary'!M$13:M$204,'Height Summary'!$E$13:$E$204, "60-100") -> 46.416667 | ... Q9: =AVERAGEIFS('Height Summary'!S$13:S$204,'Height Summary'!$E$13:$E$204, "60-100") -> 113.33333
C10: 60-120 | D10: =AVERAGEIFS('Height Summary'!F$13:F$204,'Height Summary'!$E$13:$E$204, "60-120") -> 10.75 | E10: =AVERAGEIFS('Height Summary'!G$13:G$204,'Height Summary'!$E$13:$E$204, "60-120") -> 15.25 | F10: =AVERAGEIFS('Height Summary'!H$13:H$204,'Height Summary'!$E$13:$E$204, "60-120") -> 22.833333 | G10: =AVERAGEIFS('Height Summary'!I$13:I$204,'Height Summary'!$E$13:$E$204, "60-120") -> 29.916667 | H10: =AVERAGEIFS('Height Summary'!J$13:J$204,'Height Summary'!$E$13:$E$204, "60-120") -> 35.5 | I10: =AVERAGEIFS('Height Summary'!K$13:K$204,'Height Summary'!$E$13:$E$204, "60-120") -> 40.833333 | J10: =AVERAGEIFS('Height Summary'!L$13:L$204,'Height Summary'!$E$13:$E$204, "60-120") -> 47.583333 | K10: =AVERAGEIFS('Height Summary'!M$13:M$204,'Height Summary'!$E$13:$E$204, "60-120") -> 51.333333 | ... Q10: =AVERAGEIFS('Height Summary'!S$13:S$204,'Height Summary'!$E$13:$E$204, "60-120") -> 118.91667
D11: =AVERAGEIFS('Height Summary'!F$13:F$204,'Height Summary'!$E$13:$E$204, "60-*") -> 10.8125 | E11: =AVERAGEIFS('Height Summary'!G$13:G$204,'Height Summary'!$E$13:$E$204, "60-*") -> 15.291667 | F11: =AVERAGEIFS('Height Summary'!H$13:H$204,'Height Summary'!$E$13:$E$204, "60-*") -> 21.875 | G11: =AVERAGEIFS('Height Summary'!I$13:I$204,'Height Summary'!$E$13:$E$204, "60-*") -> 28.770833 | H11: =AVERAGEIFS('Height Summary'!J$13:J$204,'Height Summary'!$E$13:$E$204, "60-*") -> 34.9375 | I11: =AVERAGEIFS('Height Summary'!K$13:K$204,'Height Summary'!$E$13:$E$204, "60-*") -> 39.6875 | J11: =AVERAGEIFS('Height Summary'!L$13:L$204,'Height Summary'!$E$13:$E$204, "60-*") -> 45.958333 | K11: =AVERAGEIFS('Height Summary'!M$13:M$204,'Height Summary'!$E$13:$E$204, "60-*") -> 49.104167 | ... Q11: =AVERAGEIFS('Height Summary'!S$13:S$204,'Height Summary'!$E$13:$E$204, "60-*") -> 101.39583
B12: Ave of all 80-##: | C12: 80-60 | D12: =AVERAGEIFS('Height Summary'!F$13:F$204,'Height Summary'!$E$13:$E$204, "80-60") -> 10.833333 | E12: =AVERAGEIFS('Height Summary'!G$13:G$204,'Height Summary'!$E$13:$E$204, "80-60") -> 15.25 | F12: =AVERAGEIFS('Height Summary'!H$13:H$204,'Height Summary'!$E$13:$E$204, "80-60") -> 21.75 | G12: =AVERAGEIFS('Height Summary'!I$13:I$204,'Height Summary'!$E$13:$E$204, "80-60") -> 30.416667 | H12: =AVERAGEIFS('Height Summary'!J$13:J$204,'Height Summary'!$E$13:$E$204, "80-60") -> 39.833333 | I12: =AVERAGEIFS('Height Summary'!K$13:K$204,'Height Summary'!$E$13:$E$204, "80-60") -> 47.166667 | J12: =AVERAGEIFS('Height Summary'!L$13:L$204,'Height Summary'!$E$13:$E$204, "80-60") -> 56.916667 | K12: =AVERAGEIFS('Height Summary'!M$13:M$204,'Height Summary'!$E$13:$E$204, "80-60") -> 63.833333 | ... Q12: =AVERAGEIFS('Height Summary'!S$13:S$204,'Height Summary'!$E$13:$E$204, "80-60") -> 98.416667
C13: 80-80 | D13: =AVERAGEIFS('Height Summary'!F$13:F$204,'Height Summary'!$E$13:$E$204, "80-80") -> 10.75 | E13: =AVERAGEIFS('Height Summary'!G$13:G$204,'Height Summary'!$E$13:$E$204, "80-80") -> 16.5 | F13: =AVERAGEIFS('Height Summary'!H$13:H$204,'Height Summary'!$E$13:$E$204, "80-80") -> 22.833333 | G13: =AVERAGEIFS('Height Summary'!I$13:I$204,'Height Summary'!$E$13:$E$204, "80-80") -> 32.333333 | H13: =AVERAGEIFS('Height Summary'!J$13:J$204,'Height Summary'!$E$13:$E$204, "80-80") -> 39.916667 | I13: =AVERAGEIFS('Height Summary'!K$13:K$204,'Height Summary'!$E$13:$E$204, "80-80") -> 47.083333 | J13: =AVERAGEIFS('Height Summary'!L$13:L$204,'Height Summary'!$E$13:$E$204, "80-80") -> 55.416667 | K13: =AVERAGEIFS('Height Summary'!M$13:M$204,'Height Summary'!$E$13:$E$204, "80-80") -> 64.5 | ... Q13: =AVERAGEIFS('Height Summary'!S$13:S$204,'Height Summary'!$E$13:$E$204, "80-80") -> 116.91667
C14: 80-100 | D14: =AVERAGEIFS('Height Summary'!F$13:F$204,'Height Summary'!$E$13:$E$204, "80-100") -> 11.833333 | E14: =AVERAGEIFS('Height Summary'!G$13:G$204,'Height Summary'!$E$13:$E$204, "80-100") -> 16.166667 | F14: =AVERAGEIFS('Height Summary'!H$13:H$204,'Height Summary'!$E$13:$E$204, "80-100") -> 23.5 | G14: =AVERAGEIFS('Height Summary'!I$13:I$204,'Height Summary'!$E$13:$E$204, "80-100") -> 30.083333 | H14: =AVERAGEIFS('Height Summary'!J$13:J$204,'Height Summary'!$E$13:$E$204, "80-100") -> 38.333333 | I14: =AVERAGEIFS('Height Summary'!K$13:K$204,'Height Summary'!$E$13:$E$204, "80-100") -> 47 | J14: =AVERAGEIFS('Height Summary'!L$13:L$204,'Height Summary'!$E$13:$E$204, "80-100") -> 55.75 | K14: =AVERAGEIFS('Height Summary'!M$13:M$204,'Height Summary'!$E$13:$E$204, "80-100") -> 65.333333 | ... Q14: =AVERAGEIFS('Height Summary'!S$13:S$204,'Height Summary'!$E$13:$E$204, "80-100") -> 126.41667
C15: 80-120 | D15: =AVERAGEIFS('Height Summary'!F$13:F$204,'Height Summary'!$E$13:$E$204, "80-120") -> 12 | E15: =AVERAGEIFS('Height Summary'!G$13:G$204,'Height Summary'!$E$13:$E$204, "80-120") -> 15.25 | F15: =AVERAGEIFS('Height Summary'!H$13:H$204,'Height Summary'!$E$13:$E$204, "80-120") -> 24.416667 | G15: =AVERAGEIFS('Height Summary'!I$13:I$204,'Height Summary'!$E$13:$E$204, "80-120") -> 29.458333 | H15: =AVERAGEIFS('Height Summary'!J$13:J$204,'Height Summary'!$E$13:$E$204, "80-120") -> 38.5 | I15: =AVERAGEIFS('Height Summary'!K$13:K$204,'Height Summary'!$E$13:$E$204, "80-120") -> 45.416667 | J15: =AVERAGEIFS('Height Summary'!L$13:L$204,'Height Summary'!$E$13:$E$204, "80-120") -> 54.5 | K15: =AVERAGEIFS('Height Summary'!M$13:M$204,'Height Summary'!$E$13:$E$204, "80-120") -> 62.833333 | ... Q15: =AVERAGEIFS('Height Summary'!S$13:S$204,'Height Summary'!$E$13:$E$204, "80-120") -> 133.25
D16: =AVERAGEIFS('Height Summary'!F$13:F$204,'Height Summary'!$E$13:$E$204, "80-*") -> 11.354167 | E16: =AVERAGEIFS('Height Summary'!G$13:G$204,'Height Summary'!$E$13:$E$204, "80-*") -> 15.791667 | F16: =AVERAGEIFS('Height Summary'!H$13:H$204,'Height Summary'!$E$13:$E$204, "80-*") -> 23.125 | G16: =AVERAGEIFS('Height Summary'!I$13:I$204,'Height Summary'!$E$13:$E$204, "80-*") -> 30.572917 | H16: =AVERAGEIFS('Height Summary'!J$13:J$204,'Height Summary'!$E$13:$E$204, "80-*") -> 39.145833 | I16: =AVERAGEIFS('Height Summary'!K$13:K$204,'Height Summary'!$E$13:$E$204, "80-*") -> 46.666667 | J16: =AVERAGEIFS('Height Summary'!L$13:L$204,'Height Summary'!$E$13:$E$204, "80-*") -> 55.645833 | K16: =AVERAGEIFS('Height Summary'!M$13:M$204,'Height Summary'!$E$13:$E$204, "80-*") -> 64.125 | ... Q16: =AVERAGEIFS('Height Summary'!S$13:S$204,'Height Summary'!$E$13:$E$204, "80-*") -> 118.75
B17: Ave of all 100-##: | C17: 100-60 | D17: =AVERAGEIFS('Height Summary'!F$13:F$204,'Height Summary'!$E$13:$E$204, "100-60") -> 10.666667 | E17: =AVERAGEIFS('Height Summary'!G$13:G$204,'Height Summary'!$E$13:$E$204, "100-60") -> 15.416667 | F17: =AVERAGEIFS('Height Summary'!H$13:H$204,'Height Summary'!$E$13:$E$204, "100-60") -> 23 | G17: =AVERAGEIFS('Height Summary'!I$13:I$204,'Height Summary'!$E$13:$E$204, "100-60") -> 32.583333 | H17: =AVERAGEIFS('Height Summary'!J$13:J$204,'Height Summary'!$E$13:$E$204, "100-60") -> 40.916667 | I17: =AVERAGEIFS('Height Summary'!K$13:K$204,'Height Summary'!$E$13:$E$204, "100-60") -> 51.25 | J17: =AVERAGEIFS('Height Summary'!L$13:L$204,'Height Summary'!$E$13:$E$204, "100-60") -> 63.5 | K17: =AVERAGEIFS('Height Summary'!M$13:M$204,'Height Summary'!$E$13:$E$204, "100-60") -> 72.75 | ... Q17: =AVERAGEIFS('Height Summary'!S$13:S$204,'Height Summary'!$E$13:$E$204, "100-60") -> 108
C18: 100-80 | D18: =AVERAGEIFS('Height Summary'!F$13:F$204,'Height Summary'!$E$13:$E$204, "100-80") -> 11.583333 | E18: =AVERAGEIFS('Height Summary'!G$13:G$204,'Height Summary'!$E$13:$E$204, "100-80") -> 14.416667 | F18: =AVERAGEIFS('Height Summary'!H$13:H$204,'Height Summary'!$E$13:$E$204, "100-80") -> 22.333333 | G18: =AVERAGEIFS('Height Summary'!I$13:I$204,'Height Summary'!$E$13:$E$204, "100-80") -> 30.25 | H18: =AVERAGEIFS('Height Summary'!J$13:J$204,'Height Summary'!$E$13:$E$204, "100-80") -> 40.5 | I18: =AVERAGEIFS('Height Summary'!K$13:K$204,'Height Summary'!$E$13:$E$204, "100-80") -> 49.416667 | J18: =AVERAGEIFS('Height Summary'!L$13:L$204,'Height Summary'!$E$13:$E$204, "100-80") -> 58.916667 | K18: =AVERAGEIFS('Height Summary'!M$13:M$204,'Height Summary'!$E$13:$E$204, "100-80") -> 70.333333 | ... Q18: =AVERAGEIFS('Height Summary'!S$13:S$204,'Height Summary'!$E$13:$E$204, "100-80") -> 121.25
C19: 100-100 | D19: =AVERAGEIFS('Height Summary'!F$13:F$204,'Height Summary'!$E$13:$E$204, "100-100") -> 11.333333 | E19: =AVERAGEIFS('Height Summary'!G$13:G$204,'Height Summary'!$E$13:$E$204, "100-100") -> 16.916667 | F19: =AVERAGEIFS('Height Summary'!H$13:H$204,'Height Summary'!$E$13:$E$204, "100-100") -> 24.083333 | G19: =AVERAGEIFS('Height Summary'!I$13:I$204,'Height Summary'!$E$13:$E$204, "100-100") -> 31.375 | H19: =AVERAGEIFS('Height Summary'!J$13:J$204,'Height Summary'!$E$13:$E$204, "100-100") -> 42.416667 | I19: =AVERAGEIFS('Height Summary'!K$13:K$204,'Height Summary'!$E$13:$E$204, "100-100") -> 52.5 | J19: =AVERAGEIFS('Height Summary'!L$13:L$204,'Height Summary'!$E$13:$E$204, "100-100") -> 65.416667 | K19: =AVERAGEIFS('Height Summary'!M$13:M$204,'Height Summary'!$E$13:$E$204, "100-100") -> 75.5 | ... Q19: =AVERAGEIFS('Height Summary'!S$13:S$204,'Height Summary'!$E$13:$E$204, "100-100") -> 150.08333
C20: 100-120 | D20: =AVERAGEIFS('Height Summary'!F$13:F$204,'Height Summary'!$E$13:$E$204, "100-120") -> 11.166667 | E20: =AVERAGEIFS('Height Summary'!G$13:G$204,'Height Summary'!$E$13:$E$204, "100-120") -> 14.75 | F20: =AVERAGEIFS('Height Summary'!H$13:H$204,'Height Summary'!$E$13:$E$204, "100-120") -> 22.333333 | G20: =AVERAGEIFS('Height Summary'!I$13:I$204,'Height Summary'!$E$13:$E$204, "100-120") -> 28.75 | H20: =AVERAGEIFS('Height Summary'!J$13:J$204,'Height Summary'!$E$13:$E$204, "100-120") -> 38.166667 | I20: =AVERAGEIFS('Height Summary'!K$13:K$204,'Height Summary'!$E$13:$E$204, "100-120") -> 47.25 | J20: =AVERAGEIFS('Height Summary'!L$13:L$204,'Height Summary'!$E$13:$E$204, "100-120") -> 60.916667 | K20: =AVERAGEIFS('Height Summary'!M$13:M$204,'Height Summary'!$E$13:$E$204, "100-120") -> 72.666667 | ... Q20: =AVERAGEIFS('Height Summary'!S$13:S$204,'Height Summary'!$E$13:$E$204, "100-120") -> 142.16667
D21: =AVERAGEIFS('Height Summary'!F$13:F$204,'Height Summary'!$E$13:$E$204, "100-*") -> 11.1875 | E21: =AVERAGEIFS('Height Summary'!G$13:G$204,'Height Summary'!$E$13:$E$204, "100-*") -> 15.375 | F21: =AVERAGEIFS('Height Summary'!H$13:H$204,'Height Summary'!$E$13:$E$204, "100-*") -> 22.9375 | G21: =AVERAGEIFS('Height Summary'!I$13:I$204,'Height Summary'!$E$13:$E$204, "100-*") -> 30.739583 | H21: =AVERAGEIFS('Height Summary'!J$13:J$204,'Height Summary'!$E$13:$E$204, "100-*") -> 40.5 | I21: =AVERAGEIFS('Height Summary'!K$13:K$204,'Height Summary'!$E$13:$E$204, "100-*") -> 50.104167 | J21: =AVERAGEIFS('Height Summary'!L$13:L$204,'Height Summary'!$E$13:$E$204, "100-*") -> 62.1875 | K21: =AVERAGEIFS('Height Summary'!M$13:M$204,'Height Summary'!$E$13:$E$204, "100-*") -> 72.8125 | ... Q21: =AVERAGEIFS('Height Summary'!S$13:S$204,'Height Summary'!$E$13:$E$204, "100-*") -> 130.375
B22: Ave of all 120-##: | C22: 120-60 | D22: =AVERAGEIFS('Height Summary'!F$13:F$204,'Height Summary'!$E$13:$E$204, "120-60") -> 10.833333 | E22: =AVERAGEIFS('Height Summary'!G$13:G$204,'Height Summary'!$E$13:$E$204, "120-60") -> 15.166667 | F22: =AVERAGEIFS('Height Summary'!H$13:H$204,'Height Summary'!$E$13:$E$204, "120-60") -> 22.166667 | G22: =AVERAGEIFS('Height Summary'!I$13:I$204,'Height Summary'!$E$13:$E$204, "120-60") -> 29.375 | H22: =AVERAGEIFS('Height Summary'!J$13:J$204,'Height Summary'!$E$13:$E$204, "120-60") -> 40.75 | I22: =AVERAGEIFS('Height Summary'!K$13:K$204,'Height Summary'!$E$13:$E$204, "120-60") -> 50.583333 | J22: =AVERAGEIFS('Height Summary'!L$13:L$204,'Height Summary'!$E$13:$E$204, "120-60") -> 63.5 | K22: =AVERAGEIFS('Height Summary'!M$13:M$204,'Height Summary'!$E$13:$E$204, "120-60") -> 75.416667 | ... Q22: =AVERAGEIFS('Height Summary'!S$13:S$204,'Height Summary'!$E$13:$E$204, "120-60") -> 120
C23: 120-80 | D23: =AVERAGEIFS('Height Summary'!F$13:F$204,'Height Summary'!$E$13:$E$204, "120-80") -> 11.083333 | E23: =AVERAGEIFS('Height Summary'!G$13:G$204,'Height Summary'!$E$13:$E$204, "120-80") -> 15.666667 | F23: =AVERAGEIFS('Height Summary'!H$13:H$204,'Height Summary'!$E$13:$E$204, "120-80") -> 22.833333 | G23: =AVERAGEIFS('Height Summary'!I$13:I$204,'Height Summary'!$E$13:$E$204, "120-80") -> 33.625 | H23: =AVERAGEIFS('Height Summary'!J$13:J$204,'Height Summary'!$E$13:$E$204, "120-80") -> 43.083333 | I23: =AVERAGEIFS('Height Summary'!K$13:K$204,'Height Summary'!$E$13:$E$204, "120-80") -> 55.166667 | J23: =AVERAGEIFS('Height Summary'!L$13:L$204,'Height Summary'!$E$13:$E$204, "120-80") -> 70.666667 | K23: =AVERAGEIFS('Height Summary'!M$13:M$204,'Height Summary'!$E$13:$E$204, "120-80") -> 83.833333 | ... Q23: =AVERAGEIFS('Height Summary'!S$13:S$204,'Height Summary'!$E$13:$E$204, "120-80") -> 139.66667
C24: 120-100 | D24: =AVERAGEIFS('Height Summary'!F$13:F$204,'Height Summary'!$E$13:$E$204, "120-100") -> 10.333333 | E24: =AVERAGEIFS('Height Summary'!G$13:G$204,'Height Summary'!$E$13:$E$204, "120-100") -> 14.166667 | F24: =AVERAGEIFS('Height Summary'!H$13:H$204,'Height Summary'!$E$13:$E$204, "120-100") -> 21.75 | G24: =AVERAGEIFS('Height Summary'!I$13:I$204,'Height Summary'!$E$13:$E$204, "120-100") -> 31.166667 | H24: =AVERAGEIFS('Height Summary'!J$13:J$204,'Height Summary'!$E$13:$E$204, "120-100") -> 41.416667 | I24: =AVERAGEIFS('Height Summary'!K$13:K$204,'Height Summary'!$E$13:$E$204, "120-100") -> 55.25 | J24: =AVERAGEIFS('Height Summary'!L$13:L$204,'Height Summary'!$E$13:$E$204, "120-100") -> 67.5 | K24: =AVERAGEIFS('Height Summary'!M$13:M$204,'Height Summary'!$E$13:$E$204, "120-100") -> 81 | ... Q24: =AVERAGEIFS('Height Summary'!S$13:S$204,'Height Summary'!$E$13:$E$204, "120-100") -> 150.33333
C25: 120-120 | D25: =AVERAGEIFS('Height Summary'!F$13:F$204,'Height Summary'!$E$13:$E$204, "120-120") -> 11.25 | E25: =AVERAGEIFS('Height Summary'!G$13:G$204,'Height Summary'!$E$13:$E$204, "120-120") -> 15.166667 | F25: =AVERAGEIFS('Height Summary'!H$13:H$204,'Height Summary'!$E$13:$E$204, "120-120") -> 22.583333 | G25: =AVERAGEIFS('Height Summary'!I$13:I$204,'Height Summary'!$E$13:$E$204, "120-120") -> 28.5 | H25: =AVERAGEIFS('Height Summary'!J$13:J$204,'Height Summary'!$E$13:$E$204, "120-120") -> 40.083333 | I25: =AVERAGEIFS('Height Summary'!K$13:K$204,'Height Summary'!$E$13:$E$204, "120-120") -> 51.5 | J25: =AVERAGEIFS('Height Summary'!L$13:L$204,'Height Summary'!$E$13:$E$204, "120-120") -> 66.916667 | K25: =AVERAGEIFS('Height Summary'!M$13:M$204,'Height Summary'!$E$13:$E$204, "120-120") -> 78.5 | ... Q25: =AVERAGEIFS('Height Summary'!S$13:S$204,'Height Summary'!$E$13:$E$204, "120-120") -> 153.66667
D26: =AVERAGEIFS('Height Summary'!F$13:F$204,'Height Summary'!$E$13:$E$204, "120-*") -> 10.875 | E26: =AVERAGEIFS('Height Summary'!G$13:G$204,'Height Summary'!$E$13:$E$204, "120-*") -> 15.041667 | F26: =AVERAGEIFS('Height Summary'!H$13:H$204,'Height Summary'!$E$13:$E$204, "120-*") -> 22.333333 | G26: =AVERAGEIFS('Height Summary'!I$13:I$204,'Height Summary'!$E$13:$E$204, "120-*") -> 30.666667 | H26: =AVERAGEIFS('Height Summary'!J$13:J$204,'Height Summary'!$E$13:$E$204, "120-*") -> 41.333333 | I26: =AVERAGEIFS('Height Summary'!K$13:K$204,'Height Summary'!$E$13:$E$204, "120-*") -> 53.125 | J26: =AVERAGEIFS('Height Summary'!L$13:L$204,'Height Summary'!$E$13:$E$204, "120-*") -> 67.145833 | K26: =AVERAGEIFS('Height Summary'!M$13:M$204,'Height Summary'!$E$13:$E$204, "120-*") -> 79.6875 | ... Q26: =AVERAGEIFS('Height Summary'!S$13:S$204,'Height Summary'!$E$13:$E$204, "120-*") -> 140.91667
M28: Irrigation treatment changed starting the 19th of July
D29: Average Canopy Widths
C31: Date: | D31: ='Cover Summary'!F9 -> 42879 | E31: ='Cover Summary'!G9 -> 42886 | F31: ='Cover Summary'!H9 -> 42891 | G31: ='Cover Summary'!I9 -> 42898 | H31: ='Cover Summary'!J9 -> 42905 | I31: ='Cover Summary'!K9 -> 42912 | J31: ='Cover Summary'!L9 -> 42919 | K31: ='Cover Summary'!M9 -> 42926 | ... Q31: ='Cover Summary'!S9 -> 42968
C32: DOY: | D32: ='Cover Summary'!F10 -> 144 | E32: ='Cover Summary'!G10 -> 151 | F32: ='Cover Summary'!H10 -> 156 | G32: ='Cover Summary'!I10 -> 163 | H32: ='Cover Summary'!J10 -> 170 | I32: ='Cover Summary'!K10 -> 177 | J32: ='Cover Summary'!L10 -> 184 | K32: ='Cover Summary'!M10 -> 191 | ... Q32: ='Cover Summary'!S10 -> 233
B33: Ave of all 60-##: | C33: 60-60 | D33: =AVERAGEIFS('Cover Summary'!F$13:F$204,'Cover Summary'!$E$13:$E$204, "60-60") -> 9.25 | E33: =AVERAGEIFS('Cover Summary'!G$13:G$204,'Cover Summary'!$E$13:$E$204, "60-60") -> 15.833333 | F33: =AVERAGEIFS('Cover Summary'!H$13:H$204,'Cover Summary'!$E$13:$E$204, "60-60") -> 20.25 | G33: =AVERAGEIFS('Cover Summary'!I$13:I$204,'Cover Summary'!$E$13:$E$204, "60-60") -> 27.208333 | H33: =AVERAGEIFS('Cover Summary'!J$13:J$204,'Cover Summary'!$E$13:$E$204, "60-60") -> 30.916667 | I33: =AVERAGEIFS('Cover Summary'!K$13:K$204,'Cover Summary'!$E$13:$E$204, "60-60") -> 35.166667 | J33: =AVERAGEIFS('Cover Summary'!L$13:L$204,'Cover Summary'!$E$13:$E$204, "60-60") -> 41.416667 | K33: =AVERAGEIFS('Cover Summary'!M$13:M$204,'Cover Summary'!$E$13:$E$204, "60-60") -> 42.416667 | ... Q33: =AVERAGEIFS('Cover Summary'!S$13:S$204,'Cover Summary'!$E$13:$E$204, "60-60") -> 73.083333
C34: 60-80 | D34: =AVERAGEIFS('Cover Summary'!F$13:F$204,'Cover Summary'!$E$13:$E$204, "60-80") -> 9.1666667 | E34: =AVERAGEIFS('Cover Summary'!G$13:G$204,'Cover Summary'!$E$13:$E$204, "60-80") -> 15.916667 | F34: =AVERAGEIFS('Cover Summary'!H$13:H$204,'Cover Summary'!$E$13:$E$204, "60-80") -> 20.25 | G34: =AVERAGEIFS('Cover Summary'!I$13:I$204,'Cover Summary'!$E$13:$E$204, "60-80") -> 27.833333 | H34: =AVERAGEIFS('Cover Summary'!J$13:J$204,'Cover Summary'!$E$13:$E$204, "60-80") -> 31.083333 | I34: =AVERAGEIFS('Cover Summary'!K$13:K$204,'Cover Summary'!$E$13:$E$204, "60-80") -> 35.833333 | J34: =AVERAGEIFS('Cover Summary'!L$13:L$204,'Cover Summary'!$E$13:$E$204, "60-80") -> 37.5 | K34: =AVERAGEIFS('Cover Summary'!M$13:M$204,'Cover Summary'!$E$13:$E$204, "60-80") -> 40.333333 | ... Q34: =AVERAGEIFS('Cover Summary'!S$13:S$204,'Cover Summary'!$E$13:$E$204, "60-80") -> 80.333333
C35: 60-100 | D35: =AVERAGEIFS('Cover Summary'!F$13:F$204,'Cover Summary'!$E$13:$E$204, "60-100") -> 9.25 | E35: =AVERAGEIFS('Cover Summary'!G$13:G$204,'Cover Summary'!$E$13:$E$204, "60-100") -> 15.166667 | F35: =AVERAGEIFS('Cover Summary'!H$13:H$204,'Cover Summary'!$E$13:$E$204, "60-100") -> 19.166667 | G35: =AVERAGEIFS('Cover Summary'!I$13:I$204,'Cover Summary'!$E$13:$E$204, "60-100") -> 27.083333 | H35: =AVERAGEIFS('Cover Summary'!J$13:J$204,'Cover Summary'!$E$13:$E$204, "60-100") -> 30.916667 | I35: =AVERAGEIFS('Cover Summary'!K$13:K$204,'Cover Summary'!$E$13:$E$204, "60-100") -> 35.083333 | J35: =AVERAGEIFS('Cover Summary'!L$13:L$204,'Cover Summary'!$E$13:$E$204, "60-100") -> 38.083333 | K35: =AVERAGEIFS('Cover Summary'!M$13:M$204,'Cover Summary'!$E$13:$E$204, "60-100") -> 40 | ... Q35: =AVERAGEIFS('Cover Summary'!S$13:S$204,'Cover Summary'!$E$13:$E$204, "60-100") -> 94.916667
C36: 60-120 | D36: =AVERAGEIFS('Cover Summary'!F$13:F$204,'Cover Summary'!$E$13:$E$204, "60-120") -> 9 | E36: =AVERAGEIFS('Cover Summary'!G$13:G$204,'Cover Summary'!$E$13:$E$204, "60-120") -> 16.083333 | F36: =AVERAGEIFS('Cover Summary'!H$13:H$204,'Cover Summary'!$E$13:$E$204, "60-120") -> 21 | G36: =AVERAGEIFS('Cover Summary'!I$13:I$204,'Cover Summary'!$E$13:$E$204, "60-120") -> 28.708333 | H36: =AVERAGEIFS('Cover Summary'!J$13:J$204,'Cover Summary'!$E$13:$E$204, "60-120") -> 30.666667 | I36: =AVERAGEIFS('Cover Summary'!K$13:K$204,'Cover Summary'!$E$13:$E$204, "60-120") -> 36 | J36: =AVERAGEIFS('Cover Summary'!L$13:L$204,'Cover Summary'!$E$13:$E$204, "60-120") -> 39.666667 | K36: =AVERAGEIFS('Cover Summary'!M$13:M$204,'Cover Summary'!$E$13:$E$204, "60-120") -> 44.333333 | ... Q36: =AVERAGEIFS('Cover Summary'!S$13:S$204,'Cover Summary'!$E$13:$E$204, "60-120") -> 100.91667
D37: =AVERAGEIFS('Cover Summary'!F$13:F$204,'Cover Summary'!$E$13:$E$204, "60-*") -> 9.1666667 | E37: =AVERAGEIFS('Cover Summary'!G$13:G$204,'Cover Summary'!$E$13:$E$204, "60-*") -> 15.75 | F37: =AVERAGEIFS('Cover Summary'!H$13:H$204,'Cover Summary'!$E$13:$E$204, "60-*") -> 20.166667 | G37: =AVERAGEIFS('Cover Summary'!I$13:I$204,'Cover Summary'!$E$13:$E$204, "60-*") -> 27.708333 | H37: =AVERAGEIFS('Cover Summary'!J$13:J$204,'Cover Summary'!$E$13:$E$204, "60-*") -> 30.895833 | I37: =AVERAGEIFS('Cover Summary'!K$13:K$204,'Cover Summary'!$E$13:$E$204, "60-*") -> 35.520833 | J37: =AVERAGEIFS('Cover Summary'!L$13:L$204,'Cover Summary'!$E$13:$E$204, "60-*") -> 39.166667 | K37: =AVERAGEIFS('Cover Summary'!M$13:M$204,'Cover Summary'!$E$13:$E$204, "60-*") -> 41.770833 | ... Q37: =AVERAGEIFS('Cover Summary'!S$13:S$204,'Cover Summary'!$E$13:$E$204, "60-*") -> 87.3125
B38: Ave of all 80-##: | C38: 80-60 | D38: =AVERAGEIFS('Cover Summary'!F$13:F$204,'Cover Summary'!$E$13:$E$204, "80-60") -> 9.0833333 | E38: =AVERAGEIFS('Cover Summary'!G$13:G$204,'Cover Summary'!$E$13:$E$204, "80-60") -> 15.75 | F38: =AVERAGEIFS('Cover Summary'!H$13:H$204,'Cover Summary'!$E$13:$E$204, "80-60") -> 20.416667 | G38: =AVERAGEIFS('Cover Summary'!I$13:I$204,'Cover Summary'!$E$13:$E$204, "80-60") -> 31.625 | H38: =AVERAGEIFS('Cover Summary'!J$13:J$204,'Cover Summary'!$E$13:$E$204, "80-60") -> 35.75 | I38: =AVERAGEIFS('Cover Summary'!K$13:K$204,'Cover Summary'!$E$13:$E$204, "80-60") -> 42.083333 | J38: =AVERAGEIFS('Cover Summary'!L$13:L$204,'Cover Summary'!$E$13:$E$204, "80-60") -> 51.5 | K38: =AVERAGEIFS('Cover Summary'!M$13:M$204,'Cover Summary'!$E$13:$E$204, "80-60") -> 55.083333 | ... Q38: =AVERAGEIFS('Cover Summary'!S$13:S$204,'Cover Summary'!$E$13:$E$204, "80-60") -> 89
C39: 80-80 | D39: =AVERAGEIFS('Cover Summary'!F$13:F$204,'Cover Summary'!$E$13:$E$204, "80-80") -> 9.0833333 | E39: =AVERAGEIFS('Cover Summary'!G$13:G$204,'Cover Summary'!$E$13:$E$204, "80-80") -> 16.75 | F39: =AVERAGEIFS('Cover Summary'!H$13:H$204,'Cover Summary'!$E$13:$E$204, "80-80") -> 21.333333 | G39: =AVERAGEIFS('Cover Summary'!I$13:I$204,'Cover Summary'!$E$13:$E$204, "80-80") -> 30.541667 | H39: =AVERAGEIFS('Cover Summary'!J$13:J$204,'Cover Summary'!$E$13:$E$204, "80-80") -> 36.5 | I39: =AVERAGEIFS('Cover Summary'!K$13:K$204,'Cover Summary'!$E$13:$E$204, "80-80") -> 42.333333 | J39: =AVERAGEIFS('Cover Summary'!L$13:L$204,'Cover Summary'!$E$13:$E$204, "80-80") -> 50.833333 | K39: =AVERAGEIFS('Cover Summary'!M$13:M$204,'Cover Summary'!$E$13:$E$204, "80-80") -> 59.083333 | ... Q39: =AVERAGEIFS('Cover Summary'!S$13:S$204,'Cover Summary'!$E$13:$E$204, "80-80") -> 101.08333
C40: 80-100 | D40: =AVERAGEIFS('Cover Summary'!F$13:F$204,'Cover Summary'!$E$13:$E$204, "80-100") -> 10.166667 | E40: =AVERAGEIFS('Cover Summary'!G$13:G$204,'Cover Summary'!$E$13:$E$204, "80-100") -> 16.833333 | F40: =AVERAGEIFS('Cover Summary'!H$13:H$204,'Cover Summary'!$E$13:$E$204, "80-100") -> 21.916667 | G40: =AVERAGEIFS('Cover Summary'!I$13:I$204,'Cover Summary'!$E$13:$E$204, "80-100") -> 27.666667 | H40: =AVERAGEIFS('Cover Summary'!J$13:J$204,'Cover Summary'!$E$13:$E$204, "80-100") -> 33.916667 | I40: =AVERAGEIFS('Cover Summary'!K$13:K$204,'Cover Summary'!$E$13:$E$204, "80-100") -> 41.083333 | J40: =AVERAGEIFS('Cover Summary'!L$13:L$204,'Cover Summary'!$E$13:$E$204, "80-100") -> 49.583333 | K40: =AVERAGEIFS('Cover Summary'!M$13:M$204,'Cover Summary'!$E$13:$E$204, "80-100") -> 56.583333 | ... Q40: =AVERAGEIFS('Cover Summary'!S$13:S$204,'Cover Summary'!$E$13:$E$204, "80-100") -> 100.83333
C41: 80-120 | D41: =AVERAGEIFS('Cover Summary'!F$13:F$204,'Cover Summary'!$E$13:$E$204, "80-120") -> 10.75 | E41: =AVERAGEIFS('Cover Summary'!G$13:G$204,'Cover Summary'!$E$13:$E$204, "80-120") -> 14.916667 | F41: =AVERAGEIFS('Cover Summary'!H$13:H$204,'Cover Summary'!$E$13:$E$204, "80-120") -> 22.75 | G41: =AVERAGEIFS('Cover Summary'!I$13:I$204,'Cover Summary'!$E$13:$E$204, "80-120") -> 27.541667 | H41: =AVERAGEIFS('Cover Summary'!J$13:J$204,'Cover Summary'!$E$13:$E$204, "80-120") -> 35.083333 | I41: =AVERAGEIFS('Cover Summary'!K$13:K$204,'Cover Summary'!$E$13:$E$204, "80-120") -> 38.833333 | J41: =AVERAGEIFS('Cover Summary'!L$13:L$204,'Cover Summary'!$E$13:$E$204, "80-120") -> 47.333333 | K41: =AVERAGEIFS('Cover Summary'!M$13:M$204,'Cover Summary'!$E$13:$E$204, "80-120") -> 54.833333 | ... Q41: =AVERAGEIFS('Cover Summary'!S$13:S$204,'Cover Summary'!$E$13:$E$204, "80-120") -> 101.75
D42: =AVERAGEIFS('Cover Summary'!F$13:F$204,'Cover Summary'!$E$13:$E$204, "80-*") -> 9.7708333 | E42: =AVERAGEIFS('Cover Summary'!G$13:G$204,'Cover Summary'!$E$13:$E$204, "80-*") -> 16.0625 | F42: =AVERAGEIFS('Cover Summary'!H$13:H$204,'Cover Summary'!$E$13:$E$204, "80-*") -> 21.604167 | G42: =AVERAGEIFS('Cover Summary'!I$13:I$204,'Cover Summary'!$E$13:$E$204, "80-*") -> 29.34375 | H42: =AVERAGEIFS('Cover Summary'!J$13:J$204,'Cover Summary'!$E$13:$E$204, "80-*") -> 35.3125 | I42: =AVERAGEIFS('Cover Summary'!K$13:K$204,'Cover Summary'!$E$13:$E$204, "80-*") -> 41.083333 | J42: =AVERAGEIFS('Cover Summary'!L$13:L$204,'Cover Summary'!$E$13:$E$204, "80-*") -> 49.8125 | K42: =AVERAGEIFS('Cover Summary'!M$13:M$204,'Cover Summary'!$E$13:$E$204, "80-*") -> 56.395833 | ... Q42: =AVERAGEIFS('Cover Summary'!S$13:S$204,'Cover Summary'!$E$13:$E$204, "80-*") -> 98.166667
B43: Ave of all 100-##: | C43: 100-60 | D43: =AVERAGEIFS('Cover Summary'!F$13:F$204,'Cover Summary'!$E$13:$E$204, "100-60") -> 9.25 | E43: =AVERAGEIFS('Cover Summary'!G$13:G$204,'Cover Summary'!$E$13:$E$204, "100-60") -> 14.833333 | F43: =AVERAGEIFS('Cover Summary'!H$13:H$204,'Cover Summary'!$E$13:$E$204, "100-60") -> 21.666667 | G43: =AVERAGEIFS('Cover Summary'!I$13:I$204,'Cover Summary'!$E$13:$E$204, "100-60") -> 31.916667 | H43: =AVERAGEIFS('Cover Summary'!J$13:J$204,'Cover Summary'!$E$13:$E$204, "100-60") -> 37.583333 | I43: =AVERAGEIFS('Cover Summary'!K$13:K$204,'Cover Summary'!$E$13:$E$204, "100-60") -> 46.916667 | J43: =AVERAGEIFS('Cover Summary'!L$13:L$204,'Cover Summary'!$E$13:$E$204, "100-60") -> 55.583333 | K43: =AVERAGEIFS('Cover Summary'!M$13:M$204,'Cover Summary'!$E$13:$E$204, "100-60") -> 64.083333 | ... Q43: =AVERAGEIFS('Cover Summary'!S$13:S$204,'Cover Summary'!$E$13:$E$204, "100-60") -> 99.333333
...
