Workbook

Sheet Height
A1: CCID | B1: DOY130 | C1: DOY139 | D1: DOY146 | E1: DOY153 | F1: DOY159 | G1: DOY168 | H1: DOY173 | I1: DOY179 | J1: DOY187 | K1: DOY193 | L1: DOY203 | M1: DOY213 | N1: DOY224 | O1: DOY231
A2: p01-2 | B2: 8 | C2: 16 | D2: 21 | E2: 26 | F2: 38 | G2: 41 | H2: 48 | I2: 63 | J2: 68 | K2: 77 | L2: 85 | M2: 87 | N2: 94 | O2: 107
A3: p01-4 | B3: 8 | C3: 16 | D3: 21 | E3: 24 | F3: 35 | G3: 52 | H3: 55 | I3: 65 | J3: 76 | K3: 89 | L3: 99 | M3: 100 | N3: 100 | O3: 109
A4: p01-6 | B4: 8 | C4: 15 | D4: 19 | E4: 30 | F4: 42 | G4: 57 | H4: 58 | I4: 64 | J4: 85 | K4: 97 | L4: 107 | M4: 113 | N4: 106 | O4: 112
A5: p02-2 | B5: 7 | C5: 15 | D5: 20 | E5: 26 | F5: 40 | G5: 49 | H5: 64 | I5: 78 | K5: 88 | L5: 100 | M5: 105 | N5: 107 | O5: 111
A6: p02-4 | B6: 8 | C6: 16 | D6: 26 | E6: 30 | F6: 43 | G6: 49 | H6: 64 | I6: 69 | K6: 91 | L6: 103 | M6: 110 | N6: 111 | O6: 114
A7: p02-6 | B7: 7 | C7: 17 | D7: 21 | E7: 31 | F7: 41 | G7: 57 | H7: 63 | I7: 80 | K7: 92 | L7: 106 | M7: 110 | N7: 109 | O7: 114
A8: p03-2 | B8: 7 | C8: 15 | D8: 23 | E8: 23 | F8: 38 | H8: 55 | I8: 59 | J8: 71 | K8: 70 | L8: 88 | M8: 93 | N8: 98 | O8: 109
A9: p03-4 | B9: 7 | C9: 14 | D9: 20 | E9: 27 | F9: 35 | H9: 60 | I9: 62 | J9: 69 | K9: 76 | L9: 82 | M9: 97 | N9: 106 | O9: 114
A10: p03-6 | B10: 8 | C10: 14 | D10: 21 | E10: 28 | F10: 39 | H10: 62 | I10: 63 | J10: 69 | K10: 78 | L10: 85 | M10: 98 | N10: 109 | O10: 109
A11: p04-2 | B11: 9 | C11: 16 | D11: 21 | E11: 28 | F11: 37 | G11: 59 | H11: 69 | I11: 79 | K11: 101 | L11: 105 | M11: 110 | N11: 119 | O11: 120
A12: p04-4 | B12: 8 | C12: 16 | D12: 24 | E12: 32 | F12: 39 | G12: 56 | H12: 64 | I12: 82 | K12: 97 | L12: 110 | M12: 115 | N12: 129 | O12: 126
A13: p04-6 | B13: 8 | C13: 17 | D13: 22 | E13: 31 | F13: 38 | G13: 54 | H13: 63 | I13: 81 | K13: 93 | L13: 95 | M13: 109 | N13: 118 | O13: 118
A14: p05-2 | B14: 7 | C14: 14 | D14: 21 | E14: 29 | F14: 36 | G14: 55 | H14: 58 | I14: 74 | J14: 86 | K14: 94 | L14: 98 | M14: 109 | N14: 110 | O14: 114
A15: p05-4 | B15: 5 | C15: 12 | D15: 19 | E15: 28 | F15: 35 | G15: 54 | H15: 55 | I15: 72 | J15: 84 | K15: 96 | L15: 105 | M15: 106 | N15: 113 | O15: 120
A16: p05-6 | B16: 8 | C16: 14 | D16: 23 | E16: 31 | F16: 40 | G16: 52 | H16: 58 | I16: 67 | J16: 76 | K16: 88 | L16: 102 | M16: 109 | N16: 111 | O16: 117
A17: p06-2 | B17: 9 | C17: 15 | D17: 20 | E17: 29 | F17: 38 | G17: 54 | H17: 65 | I17: 73 | J17: 78 | K17: 86 | L17: 93 | M17: 104 | N17: 108 | O17: 109
A18: p06-4 | B18: 5 | C18: 16 | D18: 22 | E18: 26 | F18: 28 | G18: 51 | H18: 62 | I18: 72 | J18: 81 | K18: 90 | L18: 99 | M18: 100 | N18: 115 | O18: 124
A19: p06-6 | B19: 8 | C19: 17 | D19: 23 | E19: 27 | F19: 41 | G19: 47 | H19: 63 | I19: 59 | J19: 71 | K19: 82 | L19: 91 | M19: 101 | N19: 114 | O19: 114
A20: p07-2 | B20: 6 | C20: 12 | D20: 20 | E20: 25 | F20: 35 | G20: 51 | H20: 61 | I20: 77 | J20: 85 | K20: 93 | L20: 102 | M20: 113 | N20: 115 | O20: 126
A21: p07-4 | B21: 7 | C21: 13 | D21: 20 | E21: 28 | F21: 37 | G21: 57 | H21: 68 | I21: 79 | J21: 85 | K21: 101 | L21: 107 | M21: 114 | N21: 124 | O21: 128
A22: p07-6 | B22: 6 | C22: 14 | D22: 19 | E22: 28 | F22: 38 | G22: 61 | H22: 67 | I22: 85 | J22: 87 | K22: 101 | L22: 111 | M22: 115 | N22: 121 | O22: 120
A23: p08-2 | B23: 7 | C23: 14 | D23: 21 | E23: 27 | F23: 38 | G23: 53 | H23: 66 | I23: 85 | K23: 100 | L23: 105 | M23: 111 | N23: 113 | O23: 126
A24: p08-4 | B24: 8 | C24: 17 | D24: 22 | E24: 29 | F24: 41 | G24: 59 | H24: 63 | I24: 81 | K24: 102 | L24: 109 | M24: 115 | N24: 116 | O24: 123
A25: p08-6 | B25: 6 | C25: 14 | D25: 21 | E25: 27 | F25: 38 | G25: 55 | H25: 69 | I25: 82 | K25: 101 | L25: 109 | M25: 111 | N25: 113 | O25: 111
A26: p09-2 | B26: 7 | C26: 13 | D26: 18 | E26: 26 | F26: 37 | G26: 45 | H26: 57 | I26: 66 | J26: 76 | K26: 82 | L26: 88 | M26: 96 | N26: 99 | O26: 104
A27: p09-4 | B27: 8 | C27: 14 | D27: 20 | E27: 29 | F27: 36 | G27: 47 | H27: 57 | I27: 67 | J27: 73 | K27: 85 | L27: 91 | M27: 99 | N27: 105 | O27: 111
A28: p09-6 | B28: 8 | C28: 15 | D28: 21 | E28: 26 | F28: 34 | G28: 49 | H28: 57 | I28: 68 | J28: 75 | K28: 87 | L28: 95 | M28: 100 | N28: 111 | O28: 107
A29: p10-2 | B29: 8 | C29: 15 | D29: 25 | E29: 29 | F29: 38 | G29: 51 | H29: 63 | I29: 79 | K29: 88 | L29: 100 | M29: 100 | N29: 106 | O29: 105
A30: p10-4 | B30: 7 | C30: 14 | D30: 19 | E30: 26 | F30: 36 | G30: 53 | H30: 66 | I30: 84 | K30: 97 | L30: 108 | M30: 115 | N30: 116 | O30: 118
A31: p10-6 | B31: 6 | C31: 13 | D31: 22 | E31: 28 | F31: 39 | G31: 57 | H31: 71 | I31: 76 | K31: 105 | L31: 115 | M31: 124 | N31: 131 | O31: 128
A32: p11-2 | B32: 7 | C32: 14 | D32: 22 | E32: 28 | F32: 38 | G32: 54 | H32: 58 | I32: 71 | J32: 81 | K32: 91 | L32: 102 | M32: 111 | N32: 112 | O32: 117
A33: p11-4 | B33: 8 | C33: 17 | D33: 21 | E33: 29 | F33: 41 | G33: 56 | H33: 59 | I33: 71 | J33: 86 | K33: 92 | L33: 106 | M33: 116 | N33: 119 | O33: 122
A34: p11-6 | B34: 6 | C34: 16 | D34: 19 | E34: 26 | F34: 37 | G34: 52 | H34: 52 | I34: 65 | J34: 75 | K34: 91 | L34: 105 | M34: 115 | N34: 116 | O34: 119
A35: p12-2 | B35: 6 | C35: 15 | D35: 21 | E35: 29 | F35: 41 | G35: 62 | H35: 73 | I35: 92 | J35: 98 | K35: 103 | L35: 118 | M35: 132 | N35: 134 | O35: 139
A36: p12-4 | B36: 8 | C36: 14 | D36: 22 | E36: 28 | F36: 39 | G36: 56 | H36: 68 | I36: 80 | J36: 88 | K36: 93 | L36: 104 | M36: 114 | N36: 134 | O36: 141
A37: p12-6 | B37: 7 | C37: 12 | D37: 21 | E37: 27 | F37: 38 | G37: 57 | H37: 64 | I37: 78 | J37: 89 | K37: 94 | L37: 105 | M37: 116 | N37: 125 | O37: 128
A38: p13-2 | B38: 6 | C38: 14 | D38: 21 | E38: 27 | F38: 34 | G38: 47 | H38: 58 | I38: 62 | J38: 73 | K38: 82 | L38: 97 | M38: 104 | N38: 110 | O38: 114
A39: p13-4 | B39: 7 | C39: 16 | D39: 20 | E39: 27 | F39: 38 | G39: 51 | H39: 60 | I39: 72 | J39: 73 | K39: 83 | L39: 96 | M39: 108 | N39: 111 | O39: 115
A40: p13-6 | B40: 7 | C40: 13 | D40: 21 | E40: 24 | F40: 36 | G40: 47 | H40: 53 | I40: 60 | J40: 71 | K40: 73 | L40: 84 | M40: 95 | N40: 109 | O40: 110
...

Sheet Width
A1: CCID | B1: DOY130 | C1: DOY139 | D1: DOY146 | E1: DOY153 | F1: DOY159 | G1: DOY168 | H1: DOY173 | I1: DOY179 | J1: DOY187 | K1: DOY193 | L1: DOY203 | M1: DOY213 | N1: DOY224 | O1: DOY231
A2: p01-2 | B2: 8 | C2: 12 | D2: 20 | E2: 26 | F2: 32 | G2: 31 | H2: 44 | I2: 44 | J2: 57 | K2: 71 | L2: 81 | M2: 92 | N2: 97 | O2: 98
A3: p01-4 | B3: 6 | C3: 11 | D3: 19 | E3: 23 | F3: 34 | G3: 42 | H3: 48 | I3: 52 | J3: 72 | K3: 82 | L3: 86 | M3: 99 | N3: 93 | O3: 98
A4: p01-6 | B4: 7 | C4: 16 | D4: 20 | E4: 27 | F4: 34 | G4: 38 | H4: 47 | I4: 74 | J4: 86 | K4: 91 | L4: 94 | M4: 102 | N4: 102 | O4: 102
A5: p02-2 | B5: 6 | C5: 13 | D5: 17 | E5: 24 | F5: 38 | G5: 37 | H5: 50 | I5: 61 | K5: 70 | L5: 96 | M5: 102 | N5: 96 | O5: 102
A6: p02-4 | B6: 7 | C6: 12 | D6: 20 | E6: 26 | F6: 36 | G6: 48 | H6: 56 | I6: 61 | K6: 73 | L6: 98 | M6: 102 | N6: 102 | O6: 102
A7: p02-6 | B7: 6 | C7: 12 | D7: 18 | E7: 31 | F7: 35 | G7: 41 | H7: 51 | I7: 58 | K7: 77 | L7: 101 | M7: 102 | N7: 102 | O7: 102
A8: p03-2 | B8: 6 | C8: 12 | D8: 24 | E8: 25 | F8: 38 | H8: 50 | I8: 48 | J8: 59 | K8: 56 | L8: 74 | M8: 86 | N8: 93 | O8: 102
A9: p03-4 | B9: 7 | C9: 11 | D9: 16 | E9: 26 | F9: 35 | H9: 49 | I9: 46 | J9: 50 | K9: 50 | L9: 66 | M9: 89 | N9: 92 | O9: 102
A10: p03-6 | B10: 7 | C10: 13 | D10: 17 | E10: 23 | F10: 38 | H10: 53 | I10: 49 | J10: 60 | K10: 64 | L10: 77 | M10: 96 | N10: 98 | O10: 102
A11: p04-2 | B11: 7 | C11: 13 | D11: 16 | E11: 25 | F11: 35 | G11: 51 | H11: 63 | I11: 63 | K11: 90 | L11: 100 | M11: 102 | N11: 102 | O11: 102
A12: p04-4 | B12: 7 | C12: 12 | D12: 20 | E12: 30 | F12: 37 | G12: 49 | H12: 60 | I12: 67 | K12: 83 | L12: 102 | M12: 102 | N12: 102 | O12: 102
A13: p04-6 | B13: 6 | C13: 14 | D13: 19 | E13: 28 | F13: 34 | G13: 48 | H13: 45 | I13: 67 | K13: 76 | L13: 88 | M13: 102 | N13: 102 | O13: 102
A14: p05-2 | B14: 6 | C14: 13 | D14: 18 | E14: 30 | F14: 34 | G14: 51 | H14: 46 | I14: 51 | J14: 71 | K14: 75 | L14: 93 | M14: 98 | N14: 102 | O14: 102
A15: p05-4 | B15: 4 | C15: 11 | D15: 15 | E15: 26 | F15: 32 | G15: 41 | H15: 43 | I15: 53 | J15: 79 | K15: 83 | L15: 100 | M15: 98 | N15: 102 | O15: 102
A16: p05-6 | B16: 8 | C16: 11 | D16: 22 | E16: 27 | F16: 34 | G16: 40 | H16: 48 | I16: 59 | J16: 62 | K16: 76 | L16: 92 | M16: 89 | N16: 102 | O16: 102
A17: p06-2 | B17: 7 | C17: 14 | D17: 22 | E17: 25 | F17: 35 | G17: 37 | H17: 54 | I17: 55 | J17: 61 | K17: 74 | L17: 86 | M17: 97 | N17: 100 | O17: 102
A18: p06-4 | B18: 4 | C18: 12 | D18: 18 | E18: 22 | F18: 36 | G18: 49 | H18: 49 | I18: 56 | J18: 69 | K18: 77 | L18: 89 | M18: 102 | N18: 102 | O18: 102
A19: p06-6 | B19: 8 | C19: 9 | D19: 20 | E19: 28 | F19: 40 | G19: 39 | H19: 50 | I19: 53 | J19: 63 | K19: 66 | L19: 85 | M19: 99 | N19: 98 | O19: 102
A20: p07-2 | B20: 5 | C20: 11 | D20: 15 | E20: 23 | F20: 33 | G20: 45 | H20: 53 | I20: 58 | J20: 53 | K20: 76 | L20: 88 | M20: 102 | N20: 102 | O20: 102
A21: p07-4 | B21: 5 | C21: 11 | D21: 18 | E21: 28 | F21: 34 | G21: 50 | H21: 61 | I21: 69 | J21: 62 | K21: 78 | L21: 96 | M21: 102 | N21: 102 | O21: 102
A22: p07-6 | B22: 5 | C22: 14 | D22: 15 | E22: 24 | F22: 33 | G22: 45 | H22: 55 | I22: 60 | J22: 68 | K22: 80 | L22: 101 | M22: 102 | N22: 102 | O22: 102
A23: p08-2 | B23: 7 | C23: 12 | D23: 17 | E23: 25 | F23: 37 | G23: 50 | H23: 63 | I23: 72 | K23: 87 | L23: 102 | M23: 102 | N23: 102 | O23: 102
A24: p08-4 | B24: 7 | C24: 12 | D24: 18 | E24: 27 | F24: 35 | G24: 43 | H24: 51 | I24: 75 | K24: 90 | L24: 102 | M24: 102 | N24: 102 | O24: 102
A25: p08-6 | B25: 7 | C25: 10 | D25: 18 | E25: 26 | F25: 33 | G25: 53 | H25: 58 | I25: 65 | K25: 89 | L25: 102 | M25: 102 | N25: 102 | O25: 102
A26: p09-2 | B26: 6 | C26: 11 | D26: 17 | E26: 25 | F26: 34 | G26: 38 | H26: 47 | I26: 43 | J26: 52 | K26: 66 | L26: 84 | M26: 87 | N26: 84 | O26: 92
A27: p09-4 | B27: 7 | C27: 12 | D27: 18 | E27: 29 | F27: 36 | G27: 39 | H27: 47 | I27: 60 | J27: 59 | K27: 65 | L27: 80 | M27: 89 | N27: 92 | O27: 102
A28: p09-6 | B28: 6 | C28: 11 | D28: 21 | E28: 24 | F28: 37 | G28: 39 | H28: 53 | I28: 62 | J28: 48 | K28: 64 | L28: 76 | M28: 92 | N28: 97 | O28: 99
A29: p10-2 | B29: 8 | C29: 11 | D29: 23 | E29: 28 | F29: 34 | G29: 46 | H29: 51 | I29: 63 | K29: 91 | L29: 102 | M29: 102 | N29: 102 | O29: 102
A30: p10-4 | B30: 4 | C30: 10 | D30: 16 | E30: 18 | F30: 34 | G30: 41 | H30: 53 | I30: 68 | K30: 86 | L30: 102 | M30: 102 | N30: 102 | O30: 102
A31: p10-6 | B31: 5 | C31: 10 | D31: 20 | E31: 27 | F31: 31 | G31: 53 | H31: 63 | I31: 70 | K31: 99 | L31: 102 | M31: 102 | N31: 102 | O31: 102
A32: p11-2 | B32: 6 | C32: 13 | D32: 19 | E32: 28 | F32: 38 | G32: 46 | H32: 49 | I32: 53 | J32: 68 | K32: 76 | L32: 81 | M32: 98 | N32: 102 | O32: 102
A33: p11-4 | B33: 6 | C33: 14 | D33: 17 | E33: 27 | F33: 37 | G33: 48 | H33: 55 | I33: 63 | J33: 75 | K33: 82 | L33: 98 | M33: 102 | N33: 102 | O33: 102
A34: p11-6 | B34: 5 | C34: 12 | D34: 15 | E34: 25 | F34: 33 | G34: 46 | H34: 45 | I34: 55 | J34: 66 | K34: 73 | L34: 94 | M34: 94 | N34: 102 | O34: 102
A35: p12-2 | B35: 7 | C35: 13 | D35: 21 | E35: 29 | F35: 37 | G35: 48 | H35: 74 | I35: 70 | J35: 87 | K35: 95 | L35: 102 | M35: 102 | N35: 102 | O35: 102
A36: p12-4 | B36: 7 | C36: 11 | D36: 19 | E36: 24 | F36: 32 | G36: 50 | H36: 60 | I36: 71 | J36: 71 | K36: 81 | L36: 102 | M36: 102 | N36: 102 | O36: 102
A37: p12-6 | B37: 5 | C37: 12 | D37: 16 | E37: 22 | F37: 34 | G37: 47 | H37: 56 | I37: 63 | J37: 62 | K37: 73 | L37: 102 | M37: 102 | N37: 102 | O37: 102
A38: p13-2 | B38: 5 | C38: 10 | D38: 18 | E38: 25 | F38: 31 | G38: 30 | H38: 48 | I38: 51 | J38: 56 | K38: 68 | L38: 93 | M38: 97 | N38: 102 | O38: 102
A39: p13-4 | B39: 6 | C39: 10 | D39: 16 | E39: 25 | F39: 31 | G39: 36 | H39: 49 | I39: 59 | J39: 56 | K39: 72 | L39: 89 | M39: 99 | N39: 96 | O39: 102
A40: p13-6 | B40: 5 | C40: 11 | D40: 17 | E40: 23 | F40: 33 | G40: 35 | H40: 46 | I40: 43 | J40: 56 | K40: 47 | L40: 76 | M40: 81 | N40: 95 | O40: 102
...

Sheet LAImeter
A1: CCID | B1: DOY133 | C1: DOY137 | D1: DOY145 | E1: DOY151 | F1: DOY159 | G1: DOY165 | H1: DOY174 | I1: DOY179 | J1: DOY186 | K1: DOY194 | L1: DOY195 | M1: DOY201 | N1: DOY202 | O1: DOY207 | P1: DOY215 | Q1: DOY221 | R1: DOY227 | S1: DOY228 | T1: DOY243 | U1: DOY244 | V1: DOY245
A2: p01-1 | C2: 0.08 | D2: 0.25 | E2: 0.4 | F2: 0.71 | G2: 0.96 | H2: 1.13 | I2: 1.73 | J2: 2.29 | K2: 2.6 | M2: 2.79 | O2: 2.76 | P2: 2.86 | Q2: 3.21 | R2: 3.7 | T2: 4.95
A3: p01-2 | C3: 0.23 | D3: 0.3 | E3: 0.43 | F3: 0.51 | G3: 0.8 | H3: 0.89 | I3: 1.53 | J3: 2 | K3: 2.15 | M3: 2.57 | O3: 2.69 | P3: 3.08 | Q3: 3.32 | R3: 3.99 | T3: 4.93
A4: p01-3 | C4: 0.12 | D4: 0.31 | E4: 0.28 | F4: 0.49 | G4: 0.66 | H4: 0.87 | I4: 1.35 | J4: 2.16 | K4: 2.82 | M4: 3.49 | O4: 3.79 | P4: 4.2 | Q4: 4.57 | R4: 5.35 | T4: 4.81
A5: p01-4 | C5: 0.11 | D5: 0.2 | E5: 0.32 | F5: 0.64 | G5: 0.76 | H5: 0.94 | I5: 1.5 | J5: 2.19 | K5: 2.7 | M5: 3.57 | O5: 3.7 | P5: 3.95 | Q5: 4.2 | R5: 4.51 | T5: 5.3
A6: p01-5 | C6: 0.06 | D6: 0.25 | E6: 0.35 | F6: 0.68 | G6: 0.88 | H6: 1.13 | I6: 1.75 | J6: 2.45 | K6: 2.91 | M6: 3.43 | O6: 3.75 | P6: 4.12 | Q6: 4.26 | R6: 4.8 | T6: 5.08
A7: p01-6 | C7: 0.04 | D7: 0.15 | E7: 0.23 | F7: 0.61 | G7: 0.89 | H7: 1.28 | I7: 1.96 | J7: 2.49 | K7: 3.13 | M7: 3.62 | O7: 3.91 | P7: 4.31 | Q7: 4.19 | R7: 4.85 | T7: 4.92
A8: p01-7 | C8: 0.11 | D8: 0.14 | E8: 0.29 | F8: 0.56 | G8: 0.98 | H8: 1.08 | I8: 1.47 | J8: 2.06 | K8: 2.71 | M8: 3.06 | O8: 3.33 | P8: 3.43 | Q8: 3.24 | R8: 3.56 | T8: 4.23
A9: p02-1 | C9: 0.17 | D9: 0.2 | E9: 0.26 | F9: 0.62 | G9: 0.96 | H9: 1.85 | I9: 2.45 | J9: 1.86 | K9: 2.08 | M9: 2.52 | O9: 3.11 | P9: 3.83 | R9: 4.64 | T9: 4.67
A10: p02-2 | C10: 0.14 | D10: 0.17 | E10: 0.24 | F10: 0.47 | G10: 0.66 | H10: 1.24 | I10: 1.85 | J10: 1.92 | K10: 2.55 | M10: 3.6 | O10: 4.27 | P10: 4.59 | R10: 5.34 | T10: 5.31
A11: p02-3 | C11: 0.2 | D11: 0.25 | E11: 0.32 | F11: 0.58 | G11: 0.61 | H11: 1.31 | I11: 1.94 | J11: 1.51 | K11: 2.4 | M11: 3.29 | O11: 3.86 | P11: 4.75 | R11: 5.89 | T11: 5.49
A12: p02-4 | C12: 0.22 | D12: 0.29 | E12: 0.5 | F12: 0.61 | G12: 0.89 | H12: 1.44 | I12: 1.91 | J12: 1.87 | K12: 2.53 | M12: 3.65 | O12: 4.26 | P12: 4.96 | R12: 5.9 | T12: 5.58
A13: p02-5 | C13: 0.18 | D13: 0.4 | E13: 0.39 | F13: 0.74 | G13: 0.83 | H13: 1.26 | I13: 1.92 | J13: 2.44 | K13: 2.97 | M13: 3.47 | O13: 4.06 | P13: 4.82 | R13: 5.64 | T13: 5.48
A14: p02-6 | C14: 0.04 | D14: 0.08 | E14: 0.21 | F14: 0.61 | G14: 0.82 | H14: 1.43 | I14: 2.02 | J14: 1.9 | K14: 3.07 | M14: 3.91 | O14: 4.36 | P14: 5.28 | R14: 5.66 | T14: 5.47
A15: p02-7 | C15: 0.11 | D15: 0.27 | E15: 0.34 | F15: 0.58 | G15: 0.5 | H15: 1.23 | I15: 1.34 | J15: 1.17 | K15: 1.84 | M15: 2.7 | O15: 2.83 | P15: 3.52 | R15: 3.91 | T15: 3.59
A16: p03-1 | B16: 0.08 | C16: 0.12 | D16: 0.3 | E16: 0.29 | F16: 0.41 | G16: 0.67 | H16: 1.06 | I16: 1 | J16: 1.51 | K16: 1.73 | M16: 1.88 | P16: 2.41 | Q16: 3.22 | R16: 3.79 | T16: 3.9
A17: p03-2 | B17: 0.08 | C17: 0.17 | D17: 0.21 | E17: 0.43 | F17: 0.46 | G17: 0.69 | H17: 1.16 | I17: 1.43 | J17: 1.89 | K17: 2.16 | M17: 2.95 | P17: 3.58 | Q17: 4.12 | R17: 4.51 | T17: 4.45
A18: p03-3 | B18: 0.06 | C18: 0.19 | D18: 0.22 | E18: 0.24 | F18: 0.51 | G18: 0.68 | H18: 1.26 | I18: 1.2 | J18: 1.55 | K18: 2.02 | M18: 2.43 | P18: 3.31 | Q18: 3.61 | R18: 4.05 | T18: 4.11
A19: p03-4 | B19: 0.09 | C19: 0.21 | D19: 0.21 | E19: 0.35 | F19: 0.51 | G19: 0.64 | H19: 1.24 | I19: 1.28 | J19: 1.44 | K19: 1.89 | M19: 2.44 | P19: 3.57 | Q19: 3.92 | R19: 4.65 | T19: 4.66
A20: p03-5 | B20: 0.08 | C20: 0.16 | D20: 0.28 | E20: 0.27 | F20: 0.7 | G20: 0.92 | H20: 1.06 | I20: 1.27 | J20: 1.61 | K20: 1.91 | M20: 0.64 | P20: 3.29 | Q20: 3.65 | R20: 4.18 | T20: 4.66
A21: p03-6 | B21: 0.05 | C21: 0.13 | D21: 0.23 | E21: 0.2 | F21: 0.56 | G21: 0.78 | H21: 1.4 | I21: 1.54 | J21: 1.61 | K21: 2.07 | M21: 2.47 | P21: 3.63 | Q21: 4.41 | R21: 4.86 | T21: 4.64
A22: p03-7 | B22: 0.13 | C22: 0.13 | D22: 0.13 | E22: 0.32 | F22: 0.47 | G22: 0.64 | H22: 0.86 | I22: 0.87 | J22: 1.13 | K22: 1.36 | M22: 1.74 | P22: 2.41 | Q22: 2.88 | R22: 2.91 | T22: 2.7
A23: p04-1 | C23: 0.1 | D23: 0.33 | E23: 0.33 | F23: 0.77 | G23: 0.91 | H23: 1.64 | I23: 1.74 | J23: 2.09 | K23: 2.18 | M23: 2.69 | O23: 3.15 | P23: 3.93 | Q23: 4.25 | R23: 4.48 | T23: 3.48
A24: p04-2 | C24: 0.15 | D24: 0.23 | E24: 0.32 | F24: 0.72 | G24: 0.89 | H24: 1.62 | I24: 2.28 | J24: 2.57 | K24: 3.2 | M24: 3.73 | O24: 4.44 | P24: 4.91 | Q24: 5.31 | R24: 5.38 | T24: 4.8
A25: p04-3 | C25: 0.16 | D25: 0.25 | E25: 0.32 | F25: 0.55 | G25: 0.93 | H25: 1.69 | I25: 2.11 | J25: 2.48 | K25: 2.97 | M25: 3.6 | O25: 4.05 | P25: 4.78 | Q25: 5.19 | R25: 5.47 | T25: 5.37
A26: p04-4 | C26: 0.2 | D26: 0.24 | E26: 0.22 | F26: 0.61 | G26: 0.88 | H26: 1.66 | I26: 2.04 | J26: 2.61 | K26: 3.27 | M26: 3.55 | O26: 4.37 | P26: 5.12 | Q26: 5.71 | R26: 5.97 | T26: 5.2
A27: p04-5 | C27: 0.08 | D27: 0.22 | E27: 0.39 | F27: 0.52 | G27: 1.08 | H27: 1.59 | I27: 2.23 | J27: 2.55 | K27: 2.94 | M27: 3.58 | O27: 4.24 | P27: 4.9 | Q27: 5.21 | R27: 5.52 | T27: 4.88 | V27: 4.88
A28: p04-6 | C28: 0.12 | D28: 0.31 | E28: 0.39 | F28: 0.81 | G28: 0.96 | H28: 1.52 | I28: 1.97 | J28: 2.2 | K28: 2.56 | M28: 3.16 | O28: 3.5 | P28: 4.27 | Q28: 5.12 | R28: 5.16 | T28: 4.78
A29: p04-7 | C29: 0.12 | D29: 0.23 | E29: 0.34 | F29: 0.71 | G29: 0.98 | H29: 1.41 | I29: 1.81 | J29: 1.82 | K29: 2.03 | M29: 2.59 | O29: 2.89 | P29: 3.36 | Q29: 4.03 | R29: 4.46 | T29: 3.16
A30: p05-1 | B30: 0.12 | C30: 0.19 | D30: 0.28 | E30: 0.35 | F30: 0.56 | G30: 1.06 | H30: 1.28 | I30: 1.8 | J30: 2.48 | K30: 2.62 | M30: 2.69 | O30: 3.14 | P30: 3.4 | Q30: 3.72 | R30: 3.77 | T30: 4.07
A31: p05-2 | B31: 0.04 | C31: 0.12 | D31: 0.21 | E31: 0.3 | F31: 0.71 | G31: 0.96 | H31: 1.19 | I31: 1.73 | J31: 2.32 | K31: 2.89 | M31: 3.33 | O31: 3.68 | P31: 4.28 | Q31: 4.39 | R31: 4.74 | T31: 4.72
A32: p05-3 | B32: 0.03 | C32: 0.15 | D32: 0.29 | E32: 0.35 | F32: 0.71 | G32: 0.86 | H32: 1.01 | I32: 1.63 | J32: 2.11 | K32: 2.56 | M32: 3.31 | O32: 3.82 | P32: 4.28 | Q32: 4.68 | R32: 4.97 | T32: 4.9
A33: p05-4 | B33: 0.1 | C33: 0.14 | D33: 0.27 | E33: 0.39 | F33: 0.57 | G33: 0.84 | H33: 1.18 | I33: 1.68 | J33: 2.21 | K33: 3.02 | M33: 3.49 | O33: 4.35 | P33: 4.57 | Q33: 4.84 | R33: 4.92 | T33: 5.69 | V33: 5.69
A34: p05-5 | B34: 0.13 | C34: 0.15 | D34: 0.19 | E34: 0.23 | F34: 0.51 | G34: 0.57 | H34: 0.96 | I34: 1.49 | J34: 1.93 | K34: 2.41 | M34: 3.14 | O34: 3.39 | P34: 4.09 | Q34: 4.4 | R34: 4.61 | T34: 4.9 | V34: 5.37
A35: p05-6 | B35: 0.08 | C35: 0.11 | D35: 0.32 | E35: 0.35 | F35: 0.75 | G35: 0.8 | H35: 1.13 | I35: 1.5 | J35: 1.92 | K35: 2.44 | M35: 3.24 | O35: 3.64 | P35: 4.04 | Q35: 4.56 | R35: 4.74 | T35: 4.8
A36: p05-7 | B36: 0.06 | C36: 0.12 | D36: 0.21 | E36: 0.41 | F36: 0.5 | G36: 0.63 | H36: 0.82 | I36: 1.21 | J36: 1.68 | K36: 2.1 | M36: 2.92 | O36: 3.24 | P36: 3.4 | Q36: 3.81 | R36: 3.77 | T36: 3.92
A37: p06-1 | B37: 0.05 | C37: 0.2 | D37: 0.2 | E37: 0.24 | F37: 0.53 | G37: 0.77 | H37: 1.07 | I37: 1.2 | J37: 1.38 | K37: 1.38 | M37: 1.8 | P37: 2.25 | Q37: 2.66 | R37: 2.87 | U37: 3.27
A38: p06-2 | B38: 0 | C38: 0.14 | D38: 0.15 | E38: 0.27 | F38: 0.64 | G38: 0.89 | H38: 1.32 | I38: 1.68 | J38: 1.85 | K38: 2.17 | M38: 2.76 | P38: 3.59 | Q38: 3.92 | R38: 4.11 | U38: 4.95
A39: p06-3 | B39: 0.02 | C39: 0.19 | D39: 0.25 | E39: 0.43 | F39: 0.62 | G39: 0.64 | H39: 1.08 | I39: 1.36 | J39: 1.73 | K39: 2.17 | M39: 2.85 | P39: 4.16 | Q39: 4.9 | R39: 4.86 | U39: 4.68
A40: p06-4 | B40: 0.03 | C40: 0.12 | D40: 0.12 | E40: 0.26 | F40: 0.6 | G40: 0.97 | H40: 1.43 | I40: 1.72 | J40: 2.06 | K40: 2.64 | M40: 3.1 | P40: 4.11 | Q40: 4.45 | R40: 4.83 | U40: 5
...

Sheet SPAD
A1: CCID | B1: DOY179 | C1: DOY202
A2: p01-1 | B2: 34.7 | C2: 42.6
A3: p01-2 | B3: 39.3 | C3: 41.5
A4: p01-3 | B4: 38.4 | C4: 38.6
A5: p01-4 | B5: 35.2 | C5: 43.9
A6: p01-5 | B6: 34.2 | C6: 41.6
A7: p01-6 | B7: 39.4 | C7: 45.7
A8: p01-7 | B8: 42.3 | C8: 47.9
A9: p02-1 | B9: 41.7 | C9: 44.7
A10: p02-2 | B10: 38.9 | C10: 45.1
A11: p02-3 | B11: 40.5 | C11: 48.9
A12: p02-4 | B12: 39 | C12: 42.8
A13: p02-5 | B13: 39.4 | C13: 43.8
... A113: p16-7 | B113: 43 | C113: 39.3

Sheet Density
A1: CCID | B1: PLPD
A2: p01-1 | B2: 19.7
A3: p01-2 | B3: 13.8
A4: p01-3 | B4: 11.8
A5: p01-4 | B5: 12.8
A6: p01-5 | B6: 14.8
A7: p01-6 | B7: 17.7
A8: p01-7 | B8: 14.8
A9: p02-1 | B9: 23.6
A10: p02-2 | B10: 11.8
A11: p02-3 | B11: 12.8
A12: p02-4 | B12: 14.8
A13: p02-5 | B13: 15.7
... A113: p16-7 | B113: 17.7

Sheet Develop
A1: CCID | B1: EDATE | C1: PLYRE | D1: PLDOE | E1: ADAT | F1: ADOY | G1: NAWF213
A2: p01-2 | G2: 2
A3: p01-4 | B3: 40658 | C3: 2011 | D3: 115.375 | E3: 40724 | F3: 181 | G3: 4
A4: p01-6 | G4: 3
A5: p02-2 | G5: 4
A6: p02-4 | B6: 40658 | C6: 2011 | D6: 114.5 | E6: 40724 | F6: 181 | G6: 3
A7: p02-6 | G7: 2
A8: p03-2 | G8: 4
A9: p03-4 | B9: 40658 | C9: 2011 | D9: 114.5 | E9: 40724 | F9: 181 | G9: 3
A10: p03-6 | G10: 3
A11: p04-2 | G11: 4
A12: p04-4 | B12: 40659 | C12: 2011 | D12: 115.7 | E12: 40724 | F12: 181 | G12: 4
A13: p04-6 | G13: 3
A14: p05-2 | G14: 2
A15: p05-4 | B15: 40660 | C15: 2011 | D15: 116.5 | E15: 40724 | F15: 181 | G15: 3
A16: p05-6 | G16: 3
A17: p06-2 | G17: 3
A18: p06-4 | B18: 40659 | C18: 2011 | D18: 115.66667 | E18: 40724 | F18: 181 | G18: 3
A19: p06-6 | G19: 4
A20: p07-2 | G20: 3
A21: p07-4 | B21: 40659 | C21: 2011 | D21: 115.5 | E21: 40724 | F21: 181 | G21: 4
A22: p07-6 | G22: 4
A23: p08-2 | G23: 3
A24: p08-4 | B24: 40659 | C24: 2011 | D24: 116.125 | E24: 40724 | F24: 181 | G24: 2
A25: p08-6 | G25: 2
A26: p09-2 | G26: 2
A27: p09-4 | B27: 40658 | C27: 2011 | D27: 115.4 | E27: 40724 | F27: 181 | G27: 3
A28: p09-6 | G28: 3
A29: p10-2 | G29: 3
A30: p10-4 | B30: 40659 | C30: 2011 | D30: 115.66667 | E30: 40724 | F30: 181 | G30: 3
A31: p10-6 | G31: 3
A32: p11-2 | G32: 4
A33: p11-4 | B33: 40658 | C33: 2011 | D33: 115.41667 | E33: 40724 | F33: 181 | G33: 3
A34: p11-6 | G34: 5
A35: p12-2 | G35: 4
A36: p12-4 | B36: 40659 | C36: 2011 | D36: 115.5 | E36: 40724 | F36: 181 | G36: 4
A37: p12-6 | G37: 4
A38: p13-2 | G38: 3
A39: p13-4 | B39: 40658 | C39: 2011 | D39: 115.25 | E39: 40724 | F39: 181 | G39: 2
A40: p13-6 | G40: 4
...

Sheet doy130
A1: FISE2011 -Cotton Plant Cover and Heights
M2: Date: | N2: 40673
A3: Comments: | C3: starting from the N side of the field in plot 1, and zig-zagging | M3: DOY: | N3: 130
B4: thru the plots. | M4: By: | N4: SMM
B5: Across from tubes 2, 4 & 6 (or 6, 4 & 2 depending on the direction I'm travelling)
B7: Plot | D7: Trt. | E7: Irrig. | F7: Pop. | G7: N | H7: Block | I7: Exotech Code | J7: Time | K7: Meas. (in cm) | L7: Point A | M7: Point B | N7: Point C | O7: Comments
L8: In row # 6 of each border - 2 rows west of neutron tubes.
B9: Plot | C9: Acron | D9: Trt | E9: Irr | F9: Pop | G9: Nit | H9: Block | I9: ExotechCode | J9: Time | K9: Meas | L9: 3.25 | M9: 7.25 | N9: 8.25
B10: 1 | C10: N → S | D10: =VLOOKUP($B10,#REF!,3,0) -> #REF! | E10: =VLOOKUP($B10,#REF!,4,0) -> #REF! | F10: =VLOOKUP($B10,#REF!,5,0) -> #REF! | G10: =VLOOKUP($B10,#REF!,6,0) -> #REF! | H10: =VLOOKUP($B10,#REF!,7,0) -> #REF! | I10: =VLOOKUP($B10,#REF!,8,0) -> #REF! | J10: 1015 | K10: Cover | L10: 7 | M10: 6 | N10: 8
D11: =VLOOKUP($B11,#REF!,3,0) -> #REF! | E11: =VLOOKUP($B11,#REF!,4,0) -> #REF! | F11: =VLOOKUP($B11,#REF!,5,0) -> #REF! | G11: =VLOOKUP($B11,#REF!,6,0) -> #REF! | H11: =VLOOKUP($B11,#REF!,7,0) -> #REF! | I11: =VLOOKUP($B11,#REF!,8,0) -> #REF! | K11: Height | L11: 8 | M11: 8 | N11: 8
B12: 2 | C12: S → N | D12: =VLOOKUP($B12,#REF!,3,0) -> #REF! | E12: =VLOOKUP($B12,#REF!,4,0) -> #REF! | F12: =VLOOKUP($B12,#REF!,5,0) -> #REF! | G12: =VLOOKUP($B12,#REF!,6,0) -> #REF! | H12: =VLOOKUP($B12,#REF!,7,0) -> #REF! | I12: =VLOOKUP($B12,#REF!,8,0) -> #REF! | K12: Cover | L12: 6 | M12: 7 | N12: 6
D13: =VLOOKUP($B13,#REF!,3,0) -> #REF! | E13: =VLOOKUP($B13,#REF!,4,0) -> #REF! | F13: =VLOOKUP($B13,#REF!,5,0) -> #REF! | G13: =VLOOKUP($B13,#REF!,6,0) -> #REF! | H13: =VLOOKUP($B13,#REF!,7,0) -> #REF! | I13: =VLOOKUP($B13,#REF!,8,0) -> #REF! | K13: Height | L13: 7 | M13: 8 | N13: 7
B14: 3 | C14: N → S | D14: =VLOOKUP($B14,#REF!,3,0) -> #REF! | E14: =VLOOKUP($B14,#REF!,4,0) -> #REF! | F14: =VLOOKUP($B14,#REF!,5,0) -> #REF! | G14: =VLOOKUP($B14,#REF!,6,0) -> #REF! | H14: =VLOOKUP($B14,#REF!,7,0) -> #REF! | I14: =VLOOKUP($B14,#REF!,8,0) -> #REF! | K14: Cover | L14: 7 | M14: 7 | N14: 6
D15: =VLOOKUP($B15,#REF!,3,0) -> #REF! | E15: =VLOOKUP($B15,#REF!,4,0) -> #REF! | F15: =VLOOKUP($B15,#REF!,5,0) -> #REF! | G15: =VLOOKUP($B15,#REF!,6,0) -> #REF! | H15: =VLOOKUP($B15,#REF!,7,0) -> #REF! | I15: =VLOOKUP($B15,#REF!,8,0) -> #REF! | K15: Height | L15: 8 | M15: 7 | N15: 7
B16: 4 | C16: S → N | D16: =VLOOKUP($B16,#REF!,3,0) -> #REF! | E16: =VLOOKUP($B16,#REF!,4,0) -> #REF! | F16: =VLOOKUP($B16,#REF!,5,0) -> #REF! | G16: =VLOOKUP($B16,#REF!,6,0) -> #REF! | H16: =VLOOKUP($B16,#REF!,7,0) -> #REF! | I16: =VLOOKUP($B16,#REF!,8,0) -> #REF! | K16: Cover | L16: 7 | M16: 7 | N16: 6
D17: =VLOOKUP($B17,#REF!,3,0) -> #REF! | E17: =VLOOKUP($B17,#REF!,4,0) -> #REF! | F17: =VLOOKUP($B17,#REF!,5,0) -> #REF! | G17: =VLOOKUP($B17,#REF!,6,0) -> #REF! | H17: =VLOOKUP($B17,#REF!,7,0) -> #REF! | I17: =VLOOKUP($B17,#REF!,8,0) -> #REF! | K17: Height | L17: 9 | M17: 8 | N17: 8
B18: 5 | C18: N → S | D18: =VLOOKUP($B18,#REF!,3,0) -> #REF! | E18: =VLOOKUP($B18,#REF!,4,0) -> #REF! | F18: =VLOOKUP($B18,#REF!,5,0) -> #REF! | G18: =VLOOKUP($B18,#REF!,6,0) -> #REF! | H18: =VLOOKUP($B18,#REF!,7,0) -> #REF! | I18: =VLOOKUP($B18,#REF!,8,0) -> #REF! | J18: 1034 | K18: Cover | L18: 8 | M18: 4 | N18: 6
D19: =VLOOKUP($B19,#REF!,3,0) -> #REF! | E19: =VLOOKUP($B19,#REF!,4,0) -> #REF! | F19: =VLOOKUP($B19,#REF!,5,0) -> #REF! | G19: =VLOOKUP($B19,#REF!,6,0) -> #REF! | H19: =VLOOKUP($B19,#REF!,7,0) -> #REF! | I19: =VLOOKUP($B19,#REF!,8,0) -> #REF! | K19: Height | L19: 8 | M19: 5 | N19: 7
B20: 6 | C20: S → N | D20: =VLOOKUP($B20,#REF!,3,0) -> #REF! | E20: =VLOOKUP($B20,#REF!,4,0) -> #REF! | F20: =VLOOKUP($B20,#REF!,5,0) -> #REF! | G20: =VLOOKUP($B20,#REF!,6,0) -> #REF! | H20: =VLOOKUP($B20,#REF!,7,0) -> #REF! | I20: =VLOOKUP($B20,#REF!,8,0) -> #REF! | K20: Cover | L20: 7 | M20: 4 | N20: 8
D21: =VLOOKUP($B21,#REF!,3,0) -> #REF! | E21: =VLOOKUP($B21,#REF!,4,0) -> #REF! | F21: =VLOOKUP($B21,#REF!,5,0) -> #REF! | G21: =VLOOKUP($B21,#REF!,6,0) -> #REF! | H21: =VLOOKUP($B21,#REF!,7,0) -> #REF! | I21: =VLOOKUP($B21,#REF!,8,0) -> #REF! | K21: Height | L21: 9 | M21: 5 | N21: 8
B22: 7 | C22: N → S | D22: =VLOOKUP($B22,#REF!,3,0) -> #REF! | E22: =VLOOKUP($B22,#REF!,4,0) -> #REF! | F22: =VLOOKUP($B22,#REF!,5,0) -> #REF! | G22: =VLOOKUP($B22,#REF!,6,0) -> #REF! | H22: =VLOOKUP($B22,#REF!,7,0) -> #REF! | I22: =VLOOKUP($B22,#REF!,8,0) -> #REF! | K22: Cover | L22: 5 | M22: 5 | N22: 5
D23: =VLOOKUP($B23,#REF!,3,0) -> #REF! | E23: =VLOOKUP($B23,#REF!,4,0) -> #REF! | F23: =VLOOKUP($B23,#REF!,5,0) -> #REF! | G23: =VLOOKUP($B23,#REF!,6,0) -> #REF! | H23: =VLOOKUP($B23,#REF!,7,0) -> #REF! | I23: =VLOOKUP($B23,#REF!,8,0) -> #REF! | K23: Height | L23: 6 | M23: 7 | N23: 6
B24: 8 | C24: S → N | D24: =VLOOKUP($B24,#REF!,3,0) -> #REF! | E24: =VLOOKUP($B24,#REF!,4,0) -> #REF! | F24: =VLOOKUP($B24,#REF!,5,0) -> #REF! | G24: =VLOOKUP($B24,#REF!,6,0) -> #REF! | H24: =VLOOKUP($B24,#REF!,7,0) -> #REF! | I24: =VLOOKUP($B24,#REF!,8,0) -> #REF! | K24: Cover | L24: 7 | M24: 7 | N24: 7
D25: =VLOOKUP($B25,#REF!,3,0) -> #REF! | E25: =VLOOKUP($B25,#REF!,4,0) -> #REF! | F25: =VLOOKUP($B25,#REF!,5,0) -> #REF! | G25: =VLOOKUP($B25,#REF!,6,0) -> #REF! | H25: =VLOOKUP($B25,#REF!,7,0) -> #REF! | I25: =VLOOKUP($B25,#REF!,8,0) -> #REF! | K25: Height | L25: 7 | M25: 8 | N25: 6
B26: 9 | C26: N → S | D26: =VLOOKUP($B26,#REF!,3,0) -> #REF! | E26: =VLOOKUP($B26,#REF!,4,0) -> #REF! | F26: =VLOOKUP($B26,#REF!,5,0) -> #REF! | G26: =VLOOKUP($B26,#REF!,6,0) -> #REF! | H26: =VLOOKUP($B26,#REF!,7,0) -> #REF! | I26: =VLOOKUP($B26,#REF!,8,0) -> #REF! | J26: 1050 | K26: Cover | L26: 6 | M26: 7 | N26: 6
D27: =VLOOKUP($B27,#REF!,3,0) -> #REF! | E27: =VLOOKUP($B27,#REF!,4,0) -> #REF! | F27: =VLOOKUP($B27,#REF!,5,0) -> #REF! | G27: =VLOOKUP($B27,#REF!,6,0) -> #REF! | H27: =VLOOKUP($B27,#REF!,7,0) -> #REF! | I27: =VLOOKUP($B27,#REF!,8,0) -> #REF! | K27: Height | L27: 8 | M27: 8 | N27: 7
B28: 10 | C28: S → N | D28: =VLOOKUP($B28,#REF!,3,0) -> #REF! | E28: =VLOOKUP($B28,#REF!,4,0) -> #REF! | F28: =VLOOKUP($B28,#REF!,5,0) -> #REF! | G28: =VLOOKUP($B28,#REF!,6,0) -> #REF! | H28: =VLOOKUP($B28,#REF!,7,0) -> #REF! | I28: =VLOOKUP($B28,#REF!,8,0) -> #REF! | K28: Cover | L28: 8 | M28: 4 | N28: 5
D29: =VLOOKUP($B29,#REF!,3,0) -> #REF! | E29: =VLOOKUP($B29,#REF!,4,0) -> #REF! | F29: =VLOOKUP($B29,#REF!,5,0) -> #REF! | G29: =VLOOKUP($B29,#REF!,6,0) -> #REF! | H29: =VLOOKUP($B29,#REF!,7,0) -> #REF! | I29: =VLOOKUP($B29,#REF!,8,0) -> #REF! | K29: Height | L29: 8 | M29: 7 | N29: 6
B30: 11 | C30: N → S | D30: =VLOOKUP($B30,#REF!,3,0) -> #REF! | E30: =VLOOKUP($B30,#REF!,4,0) -> #REF! | F30: =VLOOKUP($B30,#REF!,5,0) -> #REF! | G30: =VLOOKUP($B30,#REF!,6,0) -> #REF! | H30: =VLOOKUP($B30,#REF!,7,0) -> #REF! | I30: =VLOOKUP($B30,#REF!,8,0) -> #REF! | K30: Cover | L30: 5 | M30: 6 | N30: 6
D31: =VLOOKUP($B31,#REF!,3,0) -> #REF! | E31: =VLOOKUP($B31,#REF!,4,0) -> #REF! | F31: =VLOOKUP($B31,#REF!,5,0) -> #REF! | G31: =VLOOKUP($B31,#REF!,6,0) -> #REF! | H31: =VLOOKUP($B31,#REF!,7,0) -> #REF! | I31: =VLOOKUP($B31,#REF!,8,0) -> #REF! | K31: Height | L31: 6 | M31: 8 | N31: 7
B32: 12 | C32: S → N | D32: =VLOOKUP($B32,#REF!,3,0) -> #REF! | E32: =VLOOKUP($B32,#REF!,4,0) -> #REF! | F32: =VLOOKUP($B32,#REF!,5,0) -> #REF! | G32: =VLOOKUP($B32,#REF!,6,0) -> #REF! | H32: =VLOOKUP($B32,#REF!,7,0) -> #REF! | I32: =VLOOKUP($B32,#REF!,8,0) -> #REF! | K32: Cover | L32: 7 | M32: 7 | N32: 5
D33: =VLOOKUP($B33,#REF!,3,0) -> #REF! | E33: =VLOOKUP($B33,#REF!,4,0) -> #REF! | F33: =VLOOKUP($B33,#REF!,5,0) -> #REF! | G33: =VLOOKUP($B33,#REF!,6,0) -> #REF! | H33: =VLOOKUP($B33,#REF!,7,0) -> #REF! | I33: =VLOOKUP($B33,#REF!,8,0) -> #REF! | K33: Height | L33: 6 | M33: 8 | N33: 7
B34: 13 | C34: N → S | D34: =VLOOKUP($B34,#REF!,3,0) -> #REF! | E34: =VLOOKUP($B34,#REF!,4,0) -> #REF! | F34: =VLOOKUP($B34,#REF!,5,0) -> #REF! | G34: =VLOOKUP($B34,#REF!,6,0) -> #REF! | H34: =VLOOKUP($B34,#REF!,7,0) -> #REF! | I34: =VLOOKUP($B34,#REF!,8,0) -> #REF! | K34: Cover | L34: 5 | M34: 6 | N34: 5
D35: =VLOOKUP($B35,#REF!,3,0) -> #REF! | E35: =VLOOKUP($B35,#REF!,4,0) -> #REF! | F35: =VLOOKUP($B35,#REF!,5,0) -> #REF! | G35: =VLOOKUP($B35,#REF!,6,0) -> #REF! | H35: =VLOOKUP($B35,#REF!,7,0) -> #REF! | I35: =VLOOKUP($B35,#REF!,8,0) -> #REF! | K35: Height | L35: 7 | M35: 7 | N35: 6
B36: 14 | C36: S → N | D36: =VLOOKUP($B36,#REF!,3,0) -> #REF! | E36: =VLOOKUP($B36,#REF!,4,0) -> #REF! | F36: =VLOOKUP($B36,#REF!,5,0) -> #REF! | G36: =VLOOKUP($B36,#REF!,6,0) -> #REF! | H36: =VLOOKUP($B36,#REF!,7,0) -> #REF! | I36: =VLOOKUP($B36,#REF!,8,0) -> #REF! | K36: Cover | L36: 6 | M36: 6 | N36: 5
D37: =VLOOKUP($B37,#REF!,3,0) -> #REF! | E37: =VLOOKUP($B37,#REF!,4,0) -> #REF! | F37: =VLOOKUP($B37,#REF!,5,0) -> #REF! | G37: =VLOOKUP($B37,#REF!,6,0) -> #REF! | H37: =VLOOKUP($B37,#REF!,7,0) -> #REF! | I37: =VLOOKUP($B37,#REF!,8,0) -> #REF! | K37: Height | L37: 6 | M37: 8 | N37: 6
B38: 15 | C38: N → S | D38: =VLOOKUP($B38,#REF!,3,0) -> #REF! | E38: =VLOOKUP($B38,#REF!,4,0) -> #REF! | F38: =VLOOKUP($B38,#REF!,5,0) -> #REF! | G38: =VLOOKUP($B38,#REF!,6,0) -> #REF! | H38: =VLOOKUP($B38,#REF!,7,0) -> #REF! | I38: =VLOOKUP($B38,#REF!,8,0) -> #REF! | K38: Cover | L38: 8 | M38: 5 | N38: 7
D39: =VLOOKUP($B39,#REF!,3,0) -> #REF! | E39: =VLOOKUP($B39,#REF!,4,0) -> #REF! | F39: =VLOOKUP($B39,#REF!,5,0) -> #REF! | G39: =VLOOKUP($B39,#REF!,6,0) -> #REF! | H39: =VLOOKUP($B39,#REF!,7,0) -> #REF! | I39: =VLOOKUP($B39,#REF!,8,0) -> #REF! | K39: Height | L39: 8 | M39: 6 | N39: 8
B40: 16 | C40: S → N | D40: =VLOOKUP($B40,#REF!,3,0) -> #REF! | E40: =VLOOKUP($B40,#REF!,4,0) -> #REF! | F40: =VLOOKUP($B40,#REF!,5,0) -> #REF! | G40: =VLOOKUP($B40,#REF!,6,0) -> #REF! | H40: =VLOOKUP($B40,#REF!,7,0) -> #REF! | I40: =VLOOKUP($B40,#REF!,8,0) -> #REF! | J40: 1115 | K40: Cover | L40: 5 | M40: 6 | N40: 7
D41: =VLOOKUP($B41,#REF!,3,0) -> #REF! | E41: =VLOOKUP($B41,#REF!,4,0) -> #REF! | F41: =VLOOKUP($B41,#REF!,5,0) -> #REF! | G41: =VLOOKUP($B41,#REF!,6,0) -> #REF! | H41: =VLOOKUP($B41,#REF!,7,0) -> #REF! | I41: =VLOOKUP($B41,#REF!,8,0) -> #REF! | K41: Height | L41: 8 | M41: 8 | N41: 9

Sheet doy139
A1: FISE2011 -Cotton Plant Cover and Heights
M2: Date: | N2: 40682
A3: Comments: | C3: Mostly clear. Breezy but plants still easy to measure-- | M3: DOY: | N3: 139
C4: not moving much. | M4: By: | N4: SMM
B7: Plot | D7: Trt. | E7: Irrig. | F7: Pop. | G7: N | H7: Block | I7: Exotech Code | J7: Time | K7: Meas. (in cm) | L7: Point A | M7: Point B | N7: Point C | O7: Comments
L8: In row # 6 of each border - 2 rows west of neutron tubes.
B9: Plot | C9: Acron | D9: Trt | E9: Irr | F9: Pop | G9: Nit | H9: Block | I9: ExotechCode | J9: Time | K9: Meas | L9: 3.25 | M9: 7.25 | N9: 8.25
B10: 1 | C10: N → S | D10: =VLOOKUP($B10,#REF!,3,0) -> #REF! | E10: =VLOOKUP($B10,#REF!,4,0) -> #REF! | F10: =VLOOKUP($B10,#REF!,5,0) -> #REF! | G10: =VLOOKUP($B10,#REF!,6,0) -> #REF! | H10: =VLOOKUP($B10,#REF!,7,0) -> #REF! | I10: =VLOOKUP($B10,#REF!,8,0) -> #REF! | J10: 1315 | K10: Cover | L10: 16 | M10: 11 | N10: 12
D11: =VLOOKUP($B11,#REF!,3,0) -> #REF! | E11: =VLOOKUP($B11,#REF!,4,0) -> #REF! | F11: =VLOOKUP($B11,#REF!,5,0) -> #REF! | G11: =VLOOKUP($B11,#REF!,6,0) -> #REF! | H11: =VLOOKUP($B11,#REF!,7,0) -> #REF! | I11: =VLOOKUP($B11,#REF!,8,0) -> #REF! | K11: Height | L11: 15 | M11: 16 | N11: 16
B12: 2 | C12: S → N | D12: =VLOOKUP($B12,#REF!,3,0) -> #REF! | E12: =VLOOKUP($B12,#REF!,4,0) -> #REF! | F12: =VLOOKUP($B12,#REF!,5,0) -> #REF! | G12: =VLOOKUP($B12,#REF!,6,0) -> #REF! | H12: =VLOOKUP($B12,#REF!,7,0) -> #REF! | I12: =VLOOKUP($B12,#REF!,8,0) -> #REF! | K12: Cover | L12: 13 | M12: 12 | N12: 12
D13: =VLOOKUP($B13,#REF!,3,0) -> #REF! | E13: =VLOOKUP($B13,#REF!,4,0) -> #REF! | F13: =VLOOKUP($B13,#REF!,5,0) -> #REF! | G13: =VLOOKUP($B13,#REF!,6,0) -> #REF! | H13: =VLOOKUP($B13,#REF!,7,0) -> #REF! | I13: =VLOOKUP($B13,#REF!,8,0) -> #REF! | K13: Height | L13: 15 | M13: 16 | N13: 17
B14: 3 | C14: N → S | D14: =VLOOKUP($B14,#REF!,3,0) -> #REF! | E14: =VLOOKUP($B14,#REF!,4,0) -> #REF! | F14: =VLOOKUP($B14,#REF!,5,0) -> #REF! | G14: =VLOOKUP($B14,#REF!,6,0) -> #REF! | H14: =VLOOKUP($B14,#REF!,7,0) -> #REF! | I14: =VLOOKUP($B14,#REF!,8,0) -> #REF! | K14: Cover | L14: 13 | M14: 11 | N14: 12
D15: =VLOOKUP($B15,#REF!,3,0) -> #REF! | E15: =VLOOKUP($B15,#REF!,4,0) -> #REF! | F15: =VLOOKUP($B15,#REF!,5,0) -> #REF! | G15: =VLOOKUP($B15,#REF!,6,0) -> #REF! | H15: =VLOOKUP($B15,#REF!,7,0) -> #REF! | I15: =VLOOKUP($B15,#REF!,8,0) -> #REF! | K15: Height | L15: 14 | M15: 14 | N15: 15
B16: 4 | C16: S → N | D16: =VLOOKUP($B16,#REF!,3,0) -> #REF! | E16: =VLOOKUP($B16,#REF!,4,0) -> #REF! | F16: =VLOOKUP($B16,#REF!,5,0) -> #REF! | G16: =VLOOKUP($B16,#REF!,6,0) -> #REF! | H16: =VLOOKUP($B16,#REF!,7,0) -> #REF! | I16: =VLOOKUP($B16,#REF!,8,0) -> #REF! | K16: Cover | L16: 13 | M16: 12 | N16: 14
D17: =VLOOKUP($B17,#REF!,3,0) -> #REF! | E17: =VLOOKUP($B17,#REF!,4,0) -> #REF! | F17: =VLOOKUP($B17,#REF!,5,0) -> #REF! | G17: =VLOOKUP($B17,#REF!,6,0) -> #REF! | H17: =VLOOKUP($B17,#REF!,7,0) -> #REF! | I17: =VLOOKUP($B17,#REF!,8,0) -> #REF! | K17: Height | L17: 16 | M17: 16 | N17: 17
B18: 5 | C18: N → S | D18: =VLOOKUP($B18,#REF!,3,0) -> #REF! | E18: =VLOOKUP($B18,#REF!,4,0) -> #REF! | F18: =VLOOKUP($B18,#REF!,5,0) -> #REF! | G18: =VLOOKUP($B18,#REF!,6,0) -> #REF! | H18: =VLOOKUP($B18,#REF!,7,0) -> #REF! | I18: =VLOOKUP($B18,#REF!,8,0) -> #REF! | K18: Cover | L18: 11 | M18: 11 | N18: 13
D19: =VLOOKUP($B19,#REF!,3,0) -> #REF! | E19: =VLOOKUP($B19,#REF!,4,0) -> #REF! | F19: =VLOOKUP($B19,#REF!,5,0) -> #REF! | G19: =VLOOKUP($B19,#REF!,6,0) -> #REF! | H19: =VLOOKUP($B19,#REF!,7,0) -> #REF! | I19: =VLOOKUP($B19,#REF!,8,0) -> #REF! | K19: Height | L19: 14 | M19: 12 | N19: 14
B20: 6 | C20: S → N | D20: =VLOOKUP($B20,#REF!,3,0) -> #REF! | E20: =VLOOKUP($B20,#REF!,4,0) -> #REF! | F20: =VLOOKUP($B20,#REF!,5,0) -> #REF! | G20: =VLOOKUP($B20,#REF!,6,0) -> #REF! | H20: =VLOOKUP($B20,#REF!,7,0) -> #REF! | I20: =VLOOKUP($B20,#REF!,8,0) -> #REF! | K20: Cover | L20: 14 | M20: 12 | N20: 9
D21: =VLOOKUP($B21,#REF!,3,0) -> #REF! | E21: =VLOOKUP($B21,#REF!,4,0) -> #REF! | F21: =VLOOKUP($B21,#REF!,5,0) -> #REF! | G21: =VLOOKUP($B21,#REF!,6,0) -> #REF! | H21: =VLOOKUP($B21,#REF!,7,0) -> #REF! | I21: =VLOOKUP($B21,#REF!,8,0) -> #REF! | K21: Height | L21: 15 | M21: 16 | N21: 17
B22: 7 | C22: N → S | D22: =VLOOKUP($B22,#REF!,3,0) -> #REF! | E22: =VLOOKUP($B22,#REF!,4,0) -> #REF! | F22: =VLOOKUP($B22,#REF!,5,0) -> #REF! | G22: =VLOOKUP($B22,#REF!,6,0) -> #REF! | H22: =VLOOKUP($B22,#REF!,7,0) -> #REF! | I22: =VLOOKUP($B22,#REF!,8,0) -> #REF! | K22: Cover | L22: 14 | M22: 11 | N22: 11
D23: =VLOOKUP($B23,#REF!,3,0) -> #REF! | E23: =VLOOKUP($B23,#REF!,4,0) -> #REF! | F23: =VLOOKUP($B23,#REF!,5,0) -> #REF! | G23: =VLOOKUP($B23,#REF!,6,0) -> #REF! | H23: =VLOOKUP($B23,#REF!,7,0) -> #REF! | I23: =VLOOKUP($B23,#REF!,8,0) -> #REF! | K23: Height | L23: 14 | M23: 13 | N23: 12
B24: 8 | C24: S → N | D24: =VLOOKUP($B24,#REF!,3,0) -> #REF! | E24: =VLOOKUP($B24,#REF!,4,0) -> #REF! | F24: =VLOOKUP($B24,#REF!,5,0) -> #REF! | G24: =VLOOKUP($B24,#REF!,6,0) -> #REF! | H24: =VLOOKUP($B24,#REF!,7,0) -> #REF! | I24: =VLOOKUP($B24,#REF!,8,0) -> #REF! | K24: Cover | L24: 12 | M24: 12 | N24: 10
D25: =VLOOKUP($B25,#REF!,3,0) -> #REF! | E25: =VLOOKUP($B25,#REF!,4,0) -> #REF! | F25: =VLOOKUP($B25,#REF!,5,0) -> #REF! | G25: =VLOOKUP($B25,#REF!,6,0) -> #REF! | H25: =VLOOKUP($B25,#REF!,7,0) -> #REF! | I25: =VLOOKUP($B25,#REF!,8,0) -> #REF! | K25: Height | L25: 14 | M25: 17 | N25: 14
B26: 9 | C26: N → S | D26: =VLOOKUP($B26,#REF!,3,0) -> #REF! | E26: =VLOOKUP($B26,#REF!,4,0) -> #REF! | F26: =VLOOKUP($B26,#REF!,5,0) -> #REF! | G26: =VLOOKUP($B26,#REF!,6,0) -> #REF! | H26: =VLOOKUP($B26,#REF!,7,0) -> #REF! | I26: =VLOOKUP($B26,#REF!,8,0) -> #REF! | J26: 1340 | K26: Cover | L26: 11 | M26: 12 | N26: 11
D27: =VLOOKUP($B27,#REF!,3,0) -> #REF! | E27: =VLOOKUP($B27,#REF!,4,0) -> #REF! | F27: =VLOOKUP($B27,#REF!,5,0) -> #REF! | G27: =VLOOKUP($B27,#REF!,6,0) -> #REF! | H27: =VLOOKUP($B27,#REF!,7,0) -> #REF! | I27: =VLOOKUP($B27,#REF!,8,0) -> #REF! | K27: Height | L27: 15 | M27: 14 | N27: 13
B28: 10 | C28: S → N | D28: =VLOOKUP($B28,#REF!,3,0) -> #REF! | E28: =VLOOKUP($B28,#REF!,4,0) -> #REF! | F28: =VLOOKUP($B28,#REF!,5,0) -> #REF! | G28: =VLOOKUP($B28,#REF!,6,0) -> #REF! | H28: =VLOOKUP($B28,#REF!,7,0) -> #REF! | I28: =VLOOKUP($B28,#REF!,8,0) -> #REF! | K28: Cover | L28: 11 | M28: 10 | N28: 10
D29: =VLOOKUP($B29,#REF!,3,0) -> #REF! | E29: =VLOOKUP($B29,#REF!,4,0) -> #REF! | F29: =VLOOKUP($B29,#REF!,5,0) -> #REF! | G29: =VLOOKUP($B29,#REF!,6,0) -> #REF! | H29: =VLOOKUP($B29,#REF!,7,0) -> #REF! | I29: =VLOOKUP($B29,#REF!,8,0) -> #REF! | K29: Height | L29: 15 | M29: 14 | N29: 13
B30: 11 | C30: N → S | D30: =VLOOKUP($B30,#REF!,3,0) -> #REF! | E30: =VLOOKUP($B30,#REF!,4,0) -> #REF! | F30: =VLOOKUP($B30,#REF!,5,0) -> #REF! | G30: =VLOOKUP($B30,#REF!,6,0) -> #REF! | H30: =VLOOKUP($B30,#REF!,7,0) -> #REF! | I30: =VLOOKUP($B30,#REF!,8,0) -> #REF! | K30: Cover | L30: 12 | M30: 14 | N30: 13
D31: =VLOOKUP($B31,#REF!,3,0) -> #REF! | E31: =VLOOKUP($B31,#REF!,4,0) -> #REF! | F31: =VLOOKUP($B31,#REF!,5,0) -> #REF! | G31: =VLOOKUP($B31,#REF!,6,0) -> #REF! | H31: =VLOOKUP($B31,#REF!,7,0) -> #REF! | I31: =VLOOKUP($B31,#REF!,8,0) -> #REF! | K31: Height | L31: 16 | M31: 17 | N31: 14
B32: 12 | C32: S → N | D32: =VLOOKUP($B32,#REF!,3,0) -> #REF! | E32: =VLOOKUP($B32,#REF!,4,0) -> #REF! | F32: =VLOOKUP($B32,#REF!,5,0) -> #REF! | G32: =VLOOKUP($B32,#REF!,6,0) -> #REF! | H32: =VLOOKUP($B32,#REF!,7,0) -> #REF! | I32: =VLOOKUP($B32,#REF!,8,0) -> #REF! | K32: Cover | L32: 13 | M32: 11 | N32: 12
D33: =VLOOKUP($B33,#REF!,3,0) -> #REF! | E33: =VLOOKUP($B33,#REF!,4,0) -> #REF! | F33: =VLOOKUP($B33,#REF!,5,0) -> #REF! | G33: =VLOOKUP($B33,#REF!,6,0) -> #REF! | H33: =VLOOKUP($B33,#REF!,7,0) -> #REF! | I33: =VLOOKUP($B33,#REF!,8,0) -> #REF! | K33: Height | L33: 15 | M33: 14 | N33: 12
B34: 13 | C34: N → S | D34: =VLOOKUP($B34,#REF!,3,0) -> #REF! | E34: =VLOOKUP($B34,#REF!,4,0) -> #REF! | F34: =VLOOKUP($B34,#REF!,5,0) -> #REF! | G34: =VLOOKUP($B34,#REF!,6,0) -> #REF! | H34: =VLOOKUP($B34,#REF!,7,0) -> #REF! | I34: =VLOOKUP($B34,#REF!,8,0) -> #REF! | K34: Cover | L34: 11 | M34: 10 | N34: 10
D35: =VLOOKUP($B35,#REF!,3,0) -> #REF! | E35: =VLOOKUP($B35,#REF!,4,0) -> #REF! | F35: =VLOOKUP($B35,#REF!,5,0) -> #REF! | G35: =VLOOKUP($B35,#REF!,6,0) -> #REF! | H35: =VLOOKUP($B35,#REF!,7,0) -> #REF! | I35: =VLOOKUP($B35,#REF!,8,0) -> #REF! | K35: Height | L35: 13 | M35: 16 | N35: 14
B36: 14 | C36: S → N | D36: =VLOOKUP($B36,#REF!,3,0) -> #REF! | E36: =VLOOKUP($B36,#REF!,4,0) -> #REF! | F36: =VLOOKUP($B36,#REF!,5,0) -> #REF! | G36: =VLOOKUP($B36,#REF!,6,0) -> #REF! | H36: =VLOOKUP($B36,#REF!,7,0) -> #REF! | I36: =VLOOKUP($B36,#REF!,8,0) -> #REF! | K36: Cover | L36: 8 | M36: 9 | N36: 12
D37: =VLOOKUP($B37,#REF!,3,0) -> #REF! | E37: =VLOOKUP($B37,#REF!,4,0) -> #REF! | F37: =VLOOKUP($B37,#REF!,5,0) -> #REF! | G37: =VLOOKUP($B37,#REF!,6,0) -> #REF! | H37: =VLOOKUP($B37,#REF!,7,0) -> #REF! | I37: =VLOOKUP($B37,#REF!,8,0) -> #REF! | K37: Height | L37: 15 | M37: 12 | N37: 14
B38: 15 | C38: N → S | D38: =VLOOKUP($B38,#REF!,3,0) -> #REF! | E38: =VLOOKUP($B38,#REF!,4,0) -> #REF! | F38: =VLOOKUP($B38,#REF!,5,0) -> #REF! | G38: =VLOOKUP($B38,#REF!,6,0) -> #REF! | H38: =VLOOKUP($B38,#REF!,7,0) -> #REF! | I38: =VLOOKUP($B38,#REF!,8,0) -> #REF! | K38: Cover | L38: 12 | M38: 9 | N38: 11
D39: =VLOOKUP($B39,#REF!,3,0) -> #REF! | E39: =VLOOKUP($B39,#REF!,4,0) -> #REF! | F39: =VLOOKUP($B39,#REF!,5,0) -> #REF! | G39: =VLOOKUP($B39,#REF!,6,0) -> #REF! | H39: =VLOOKUP($B39,#REF!,7,0) -> #REF! | I39: =VLOOKUP($B39,#REF!,8,0) -> #REF! | K39: Height | L39: 16 | M39: 10 | N39: 14
B40: 16 | C40: S → N | D40: =VLOOKUP($B40,#REF!,3,0) -> #REF! | E40: =VLOOKUP($B40,#REF!,4,0) -> #REF! | F40: =VLOOKUP($B40,#REF!,5,0) -> #REF! | G40: =VLOOKUP($B40,#REF!,6,0) -> #REF! | H40: =VLOOKUP($B40,#REF!,7,0) -> #REF! | I40: =VLOOKUP($B40,#REF!,8,0) -> #REF! | K40: Cover | L40: 10 | M40: 12 | N40: 12
D41: =VLOOKUP($B41,#REF!,3,0) -> #REF! | E41: =VLOOKUP($B41,#REF!,4,0) -> #REF! | F41: =VLOOKUP($B41,#REF!,5,0) -> #REF! | G41: =VLOOKUP($B41,#REF!,6,0) -> #REF! | H41: =VLOOKUP($B41,#REF!,7,0) -> #REF! | I41: =VLOOKUP($B41,#REF!,8,0) -> #REF! | K41: Height | L41: 14 | M41: 14 | N41: 17
B42: 17 | C42: N → S | D42: =VLOOKUP($B42,#REF!,3,0) -> #REF! | E42: =VLOOKUP($B42,#REF!,4,0) -> #REF! | F42: =VLOOKUP($B42,#REF!,5,0) -> #REF! | G42: =VLOOKUP($B42,#REF!,6,0) -> #REF! | H42: =VLOOKUP($B42,#REF!,7,0) -> #REF! | I42: =VLOOKUP($B42,#REF!,8,0) -> #REF! | J42: 1400 | K42: Cover | L42: 9 | M42: 10 | N42: 12
...

Sheet doy146
A1: FISE2011 -Cotton Plant Cover and Heights
M2: Date: | N2: 40689
A3: Comments: | C3: Mostly clear. Light-moderate wind but OK for measuring | M3: DOY: | N3: 146
C4: plants - they're not moving too much. | M4: By: | N4: SMM
B7: Plot | D7: Trt. | E7: Irrig. | F7: Pop. | G7: N | H7: Block | I7: Exotech Code | J7: Time | K7: Meas. (in cm) | L7: Point A | M7: Point B | N7: Point C | O7: Comments
L8: In row # 6 of each border - 2 rows west of neutron tubes.
B9: Plot | C9: Acron | D9: Trt | E9: Irr | F9: Pop | G9: Nit | H9: Block | I9: ExotechCode | J9: Time | K9: Meas | L9: 3.25 | M9: 7.25 | N9: 8.25
B10: 1 | C10: N → S | D10: =VLOOKUP($B10,#REF!,3,0) -> #REF! | E10: =VLOOKUP($B10,#REF!,4,0) -> #REF! | F10: =VLOOKUP($B10,#REF!,5,0) -> #REF! | G10: =VLOOKUP($B10,#REF!,6,0) -> #REF! | H10: =VLOOKUP($B10,#REF!,7,0) -> #REF! | I10: =VLOOKUP($B10,#REF!,8,0) -> #REF! | J10: 1330 | K10: Cover | L10: 20 | M10: 19 | N10: 20
D11: =VLOOKUP($B11,#REF!,3,0) -> #REF! | E11: =VLOOKUP($B11,#REF!,4,0) -> #REF! | F11: =VLOOKUP($B11,#REF!,5,0) -> #REF! | G11: =VLOOKUP($B11,#REF!,6,0) -> #REF! | H11: =VLOOKUP($B11,#REF!,7,0) -> #REF! | I11: =VLOOKUP($B11,#REF!,8,0) -> #REF! | K11: Height | L11: 19 | M11: 21 | N11: 21
B12: 2 | C12: S → N | D12: =VLOOKUP($B12,#REF!,3,0) -> #REF! | E12: =VLOOKUP($B12,#REF!,4,0) -> #REF! | F12: =VLOOKUP($B12,#REF!,5,0) -> #REF! | G12: =VLOOKUP($B12,#REF!,6,0) -> #REF! | H12: =VLOOKUP($B12,#REF!,7,0) -> #REF! | I12: =VLOOKUP($B12,#REF!,8,0) -> #REF! | K12: Cover | L12: 17 | M12: 20 | N12: 18
D13: =VLOOKUP($B13,#REF!,3,0) -> #REF! | E13: =VLOOKUP($B13,#REF!,4,0) -> #REF! | F13: =VLOOKUP($B13,#REF!,5,0) -> #REF! | G13: =VLOOKUP($B13,#REF!,6,0) -> #REF! | H13: =VLOOKUP($B13,#REF!,7,0) -> #REF! | I13: =VLOOKUP($B13,#REF!,8,0) -> #REF! | K13: Height | L13: 20 | M13: 26 | N13: 21
B14: 3 | C14: N → S | D14: =VLOOKUP($B14,#REF!,3,0) -> #REF! | E14: =VLOOKUP($B14,#REF!,4,0) -> #REF! | F14: =VLOOKUP($B14,#REF!,5,0) -> #REF! | G14: =VLOOKUP($B14,#REF!,6,0) -> #REF! | H14: =VLOOKUP($B14,#REF!,7,0) -> #REF! | I14: =VLOOKUP($B14,#REF!,8,0) -> #REF! | K14: Cover | L14: 17 | M14: 16 | N14: 24
D15: =VLOOKUP($B15,#REF!,3,0) -> #REF! | E15: =VLOOKUP($B15,#REF!,4,0) -> #REF! | F15: =VLOOKUP($B15,#REF!,5,0) -> #REF! | G15: =VLOOKUP($B15,#REF!,6,0) -> #REF! | H15: =VLOOKUP($B15,#REF!,7,0) -> #REF! | I15: =VLOOKUP($B15,#REF!,8,0) -> #REF! | K15: Height | L15: 21 | M15: 20 | N15: 23
B16: 4 | C16: S → N | D16: =VLOOKUP($B16,#REF!,3,0) -> #REF! | E16: =VLOOKUP($B16,#REF!,4,0) -> #REF! | F16: =VLOOKUP($B16,#REF!,5,0) -> #REF! | G16: =VLOOKUP($B16,#REF!,6,0) -> #REF! | H16: =VLOOKUP($B16,#REF!,7,0) -> #REF! | I16: =VLOOKUP($B16,#REF!,8,0) -> #REF! | K16: Cover | L16: 16 | M16: 20 | N16: 19
D17: =VLOOKUP($B17,#REF!,3,0) -> #REF! | E17: =VLOOKUP($B17,#REF!,4,0) -> #REF! | F17: =VLOOKUP($B17,#REF!,5,0) -> #REF! | G17: =VLOOKUP($B17,#REF!,6,0) -> #REF! | H17: =VLOOKUP($B17,#REF!,7,0) -> #REF! | I17: =VLOOKUP($B17,#REF!,8,0) -> #REF! | K17: Height | L17: 21 | M17: 24 | N17: 22
B18: 5 | C18: N → S | D18: =VLOOKUP($B18,#REF!,3,0) -> #REF! | E18: =VLOOKUP($B18,#REF!,4,0) -> #REF! | F18: =VLOOKUP($B18,#REF!,5,0) -> #REF! | G18: =VLOOKUP($B18,#REF!,6,0) -> #REF! | H18: =VLOOKUP($B18,#REF!,7,0) -> #REF! | I18: =VLOOKUP($B18,#REF!,8,0) -> #REF! | K18: Cover | L18: 22 | M18: 15 | N18: 18
D19: =VLOOKUP($B19,#REF!,3,0) -> #REF! | E19: =VLOOKUP($B19,#REF!,4,0) -> #REF! | F19: =VLOOKUP($B19,#REF!,5,0) -> #REF! | G19: =VLOOKUP($B19,#REF!,6,0) -> #REF! | H19: =VLOOKUP($B19,#REF!,7,0) -> #REF! | I19: =VLOOKUP($B19,#REF!,8,0) -> #REF! | K19: Height | L19: 23 | M19: 19 | N19: 21
B20: 6 | C20: S → N | D20: =VLOOKUP($B20,#REF!,3,0) -> #REF! | E20: =VLOOKUP($B20,#REF!,4,0) -> #REF! | F20: =VLOOKUP($B20,#REF!,5,0) -> #REF! | G20: =VLOOKUP($B20,#REF!,6,0) -> #REF! | H20: =VLOOKUP($B20,#REF!,7,0) -> #REF! | I20: =VLOOKUP($B20,#REF!,8,0) -> #REF! | K20: Cover | L20: 22 | M20: 18 | N20: 20
D21: =VLOOKUP($B21,#REF!,3,0) -> #REF! | E21: =VLOOKUP($B21,#REF!,4,0) -> #REF! | F21: =VLOOKUP($B21,#REF!,5,0) -> #REF! | G21: =VLOOKUP($B21,#REF!,6,0) -> #REF! | H21: =VLOOKUP($B21,#REF!,7,0) -> #REF! | I21: =VLOOKUP($B21,#REF!,8,0) -> #REF! | K21: Height | L21: 20 | M21: 22 | N21: 23
B22: 7 | C22: N → S | D22: =VLOOKUP($B22,#REF!,3,0) -> #REF! | E22: =VLOOKUP($B22,#REF!,4,0) -> #REF! | F22: =VLOOKUP($B22,#REF!,5,0) -> #REF! | G22: =VLOOKUP($B22,#REF!,6,0) -> #REF! | H22: =VLOOKUP($B22,#REF!,7,0) -> #REF! | I22: =VLOOKUP($B22,#REF!,8,0) -> #REF! | K22: Cover | L22: 15 | M22: 18 | N22: 15
D23: =VLOOKUP($B23,#REF!,3,0) -> #REF! | E23: =VLOOKUP($B23,#REF!,4,0) -> #REF! | F23: =VLOOKUP($B23,#REF!,5,0) -> #REF! | G23: =VLOOKUP($B23,#REF!,6,0) -> #REF! | H23: =VLOOKUP($B23,#REF!,7,0) -> #REF! | I23: =VLOOKUP($B23,#REF!,8,0) -> #REF! | K23: Height | L23: 19 | M23: 20 | N23: 20
B24: 8 | C24: S → N | D24: =VLOOKUP($B24,#REF!,3,0) -> #REF! | E24: =VLOOKUP($B24,#REF!,4,0) -> #REF! | F24: =VLOOKUP($B24,#REF!,5,0) -> #REF! | G24: =VLOOKUP($B24,#REF!,6,0) -> #REF! | H24: =VLOOKUP($B24,#REF!,7,0) -> #REF! | I24: =VLOOKUP($B24,#REF!,8,0) -> #REF! | K24: Cover | L24: 17 | M24: 18 | N24: 18
D25: =VLOOKUP($B25,#REF!,3,0) -> #REF! | E25: =VLOOKUP($B25,#REF!,4,0) -> #REF! | F25: =VLOOKUP($B25,#REF!,5,0) -> #REF! | G25: =VLOOKUP($B25,#REF!,6,0) -> #REF! | H25: =VLOOKUP($B25,#REF!,7,0) -> #REF! | I25: =VLOOKUP($B25,#REF!,8,0) -> #REF! | K25: Height | L25: 21 | M25: 22 | N25: 21
B26: 9 | C26: N → S | D26: =VLOOKUP($B26,#REF!,3,0) -> #REF! | E26: =VLOOKUP($B26,#REF!,4,0) -> #REF! | F26: =VLOOKUP($B26,#REF!,5,0) -> #REF! | G26: =VLOOKUP($B26,#REF!,6,0) -> #REF! | H26: =VLOOKUP($B26,#REF!,7,0) -> #REF! | I26: =VLOOKUP($B26,#REF!,8,0) -> #REF! | K26: Cover | L26: 21 | M26: 18 | N26: 17
D27: =VLOOKUP($B27,#REF!,3,0) -> #REF! | E27: =VLOOKUP($B27,#REF!,4,0) -> #REF! | F27: =VLOOKUP($B27,#REF!,5,0) -> #REF! | G27: =VLOOKUP($B27,#REF!,6,0) -> #REF! | H27: =VLOOKUP($B27,#REF!,7,0) -> #REF! | I27: =VLOOKUP($B27,#REF!,8,0) -> #REF! | K27: Height | L27: 21 | M27: 20 | N27: 18
B28: 10 | C28: S → N | D28: =VLOOKUP($B28,#REF!,3,0) -> #REF! | E28: =VLOOKUP($B28,#REF!,4,0) -> #REF! | F28: =VLOOKUP($B28,#REF!,5,0) -> #REF! | G28: =VLOOKUP($B28,#REF!,6,0) -> #REF! | H28: =VLOOKUP($B28,#REF!,7,0) -> #REF! | I28: =VLOOKUP($B28,#REF!,8,0) -> #REF! | K28: Cover | L28: 23 | M28: 16 | N28: 20
D29: =VLOOKUP($B29,#REF!,3,0) -> #REF! | E29: =VLOOKUP($B29,#REF!,4,0) -> #REF! | F29: =VLOOKUP($B29,#REF!,5,0) -> #REF! | G29: =VLOOKUP($B29,#REF!,6,0) -> #REF! | H29: =VLOOKUP($B29,#REF!,7,0) -> #REF! | I29: =VLOOKUP($B29,#REF!,8,0) -> #REF! | K29: Height | L29: 25 | M29: 19 | N29: 22
B30: 11 | C30: N → S | D30: =VLOOKUP($B30,#REF!,3,0) -> #REF! | E30: =VLOOKUP($B30,#REF!,4,0) -> #REF! | F30: =VLOOKUP($B30,#REF!,5,0) -> #REF! | G30: =VLOOKUP($B30,#REF!,6,0) -> #REF! | H30: =VLOOKUP($B30,#REF!,7,0) -> #REF! | I30: =VLOOKUP($B30,#REF!,8,0) -> #REF! | K30: Cover | L30: 15 | M30: 17 | N30: 19
D31: =VLOOKUP($B31,#REF!,3,0) -> #REF! | E31: =VLOOKUP($B31,#REF!,4,0) -> #REF! | F31: =VLOOKUP($B31,#REF!,5,0) -> #REF! | G31: =VLOOKUP($B31,#REF!,6,0) -> #REF! | H31: =VLOOKUP($B31,#REF!,7,0) -> #REF! | I31: =VLOOKUP($B31,#REF!,8,0) -> #REF! | K31: Height | L31: 19 | M31: 21 | N31: 22
B32: 12 | C32: S → N | D32: =VLOOKUP($B32,#REF!,3,0) -> #REF! | E32: =VLOOKUP($B32,#REF!,4,0) -> #REF! | F32: =VLOOKUP($B32,#REF!,5,0) -> #REF! | G32: =VLOOKUP($B32,#REF!,6,0) -> #REF! | H32: =VLOOKUP($B32,#REF!,7,0) -> #REF! | I32: =VLOOKUP($B32,#REF!,8,0) -> #REF! | K32: Cover | L32: 21 | M32: 19 | N32: 16
D33: =VLOOKUP($B33,#REF!,3,0) -> #REF! | E33: =VLOOKUP($B33,#REF!,4,0) -> #REF! | F33: =VLOOKUP($B33,#REF!,5,0) -> #REF! | G33: =VLOOKUP($B33,#REF!,6,0) -> #REF! | H33: =VLOOKUP($B33,#REF!,7,0) -> #REF! | I33: =VLOOKUP($B33,#REF!,8,0) -> #REF! | K33: Height | L33: 21 | M33: 22 | N33: 21
B34: 13 | C34: N → S | D34: =VLOOKUP($B34,#REF!,3,0) -> #REF! | E34: =VLOOKUP($B34,#REF!,4,0) -> #REF! | F34: =VLOOKUP($B34,#REF!,5,0) -> #REF! | G34: =VLOOKUP($B34,#REF!,6,0) -> #REF! | H34: =VLOOKUP($B34,#REF!,7,0) -> #REF! | I34: =VLOOKUP($B34,#REF!,8,0) -> #REF! | K34: Cover | L34: 17 | M34: 16 | N34: 18
D35: =VLOOKUP($B35,#REF!,3,0) -> #REF! | E35: =VLOOKUP($B35,#REF!,4,0) -> #REF! | F35: =VLOOKUP($B35,#REF!,5,0) -> #REF! | G35: =VLOOKUP($B35,#REF!,6,0) -> #REF! | H35: =VLOOKUP($B35,#REF!,7,0) -> #REF! | I35: =VLOOKUP($B35,#REF!,8,0) -> #REF! | K35: Height | L35: 21 | M35: 20 | N35: 21
B36: 14 | C36: S → N | D36: =VLOOKUP($B36,#REF!,3,0) -> #REF! | E36: =VLOOKUP($B36,#REF!,4,0) -> #REF! | F36: =VLOOKUP($B36,#REF!,5,0) -> #REF! | G36: =VLOOKUP($B36,#REF!,6,0) -> #REF! | H36: =VLOOKUP($B36,#REF!,7,0) -> #REF! | I36: =VLOOKUP($B36,#REF!,8,0) -> #REF! | K36: Cover | L36: 21 | M36: 19 | N36: 18
D37: =VLOOKUP($B37,#REF!,3,0) -> #REF! | E37: =VLOOKUP($B37,#REF!,4,0) -> #REF! | F37: =VLOOKUP($B37,#REF!,5,0) -> #REF! | G37: =VLOOKUP($B37,#REF!,6,0) -> #REF! | H37: =VLOOKUP($B37,#REF!,7,0) -> #REF! | I37: =VLOOKUP($B37,#REF!,8,0) -> #REF! | K37: Height | L37: 22 | M37: 21 | N37: 22
B38: 15 | C38: N → S | D38: =VLOOKUP($B38,#REF!,3,0) -> #REF! | E38: =VLOOKUP($B38,#REF!,4,0) -> #REF! | F38: =VLOOKUP($B38,#REF!,5,0) -> #REF! | G38: =VLOOKUP($B38,#REF!,6,0) -> #REF! | H38: =VLOOKUP($B38,#REF!,7,0) -> #REF! | I38: =VLOOKUP($B38,#REF!,8,0) -> #REF! | K38: Cover | L38: 22 | M38: 19 | N38: 18
D39: =VLOOKUP($B39,#REF!,3,0) -> #REF! | E39: =VLOOKUP($B39,#REF!,4,0) -> #REF! | F39: =VLOOKUP($B39,#REF!,5,0) -> #REF! | G39: =VLOOKUP($B39,#REF!,6,0) -> #REF! | H39: =VLOOKUP($B39,#REF!,7,0) -> #REF! | I39: =VLOOKUP($B39,#REF!,8,0) -> #REF! | K39: Height | L39: 22 | M39: 21 | N39: 22
B40: 16 | C40: S → N | D40: =VLOOKUP($B40,#REF!,3,0) -> #REF! | E40: =VLOOKUP($B40,#REF!,4,0) -> #REF! | F40: =VLOOKUP($B40,#REF!,5,0) -> #REF! | G40: =VLOOKUP($B40,#REF!,6,0) -> #REF! | H40: =VLOOKUP($B40,#REF!,7,0) -> #REF! | I40: =VLOOKUP($B40,#REF!,8,0) -> #REF! | K40: Cover | L40: 23 | M40: 16 | N40: 19
D41: =VLOOKUP($B41,#REF!,3,0) -> #REF! | E41: =VLOOKUP($B41,#REF!,4,0) -> #REF! | F41: =VLOOKUP($B41,#REF!,5,0) -> #REF! | G41: =VLOOKUP($B41,#REF!,6,0) -> #REF! | H41: =VLOOKUP($B41,#REF!,7,0) -> #REF! | I41: =VLOOKUP($B41,#REF!,8,0) -> #REF! | K41: Height | L41: 24 | M41: 22 | N41: 26
B42: 17 | C42: N → S | D42: =VLOOKUP($B42,#REF!,3,0) -> #REF! | E42: =VLOOKUP($B42,#REF!,4,0) -> #REF! | F42: =VLOOKUP($B42,#REF!,5,0) -> #REF! | G42: =VLOOKUP($B42,#REF!,6,0) -> #REF! | H42: =VLOOKUP($B42,#REF!,7,0) -> #REF! | I42: =VLOOKUP($B42,#REF!,8,0) -> #REF! | J42: 1425 end | K42: Cover | L42: 20 | M42: 16 | N42: 18
...

Sheet doy153
A1: FISE2011 -Cotton Plant Cover and Heights
M2: Date: | N2: 40696
A3: Comments: | C3: Mostly clear. Light wind from W with a few gusts | M3: DOY: | N3: 153
B4: (but not enough to make measurements hard). Irrigation today. | M4: By: | N4: SMM
B7: Plot | D7: Trt. | E7: Irrig. | F7: Pop. | G7: N | H7: Block | I7: Exotech Code | J7: Time | K7: Meas. (in cm) | L7: Point A | M7: Point B | N7: Point C | O7: Comments
L8: In row # 6 of each border - 2 rows west of neutron tubes.
B9: Plot | C9: Acron | D9: Trt | E9: Irr | F9: Pop | G9: Nit | H9: Block | I9: ExotechCode | J9: Time | K9: Meas | L9: 3.25 | M9: 7.25 | N9: 8.25
B10: 1 | C10: N → S | D10: =VLOOKUP($B10,#REF!,3,0) -> #REF! | E10: =VLOOKUP($B10,#REF!,4,0) -> #REF! | F10: =VLOOKUP($B10,#REF!,5,0) -> #REF! | G10: =VLOOKUP($B10,#REF!,6,0) -> #REF! | H10: =VLOOKUP($B10,#REF!,7,0) -> #REF! | I10: =VLOOKUP($B10,#REF!,8,0) -> #REF! | J10: 1210 | K10: Cover | L10: 27 | M10: 23 | N10: 26
D11: =VLOOKUP($B11,#REF!,3,0) -> #REF! | E11: =VLOOKUP($B11,#REF!,4,0) -> #REF! | F11: =VLOOKUP($B11,#REF!,5,0) -> #REF! | G11: =VLOOKUP($B11,#REF!,6,0) -> #REF! | H11: =VLOOKUP($B11,#REF!,7,0) -> #REF! | I11: =VLOOKUP($B11,#REF!,8,0) -> #REF! | K11: Height | L11: 30 | M11: 24 | N11: 26
B12: 2 | C12: S → N | D12: =VLOOKUP($B12,#REF!,3,0) -> #REF! | E12: =VLOOKUP($B12,#REF!,4,0) -> #REF! | F12: =VLOOKUP($B12,#REF!,5,0) -> #REF! | G12: =VLOOKUP($B12,#REF!,6,0) -> #REF! | H12: =VLOOKUP($B12,#REF!,7,0) -> #REF! | I12: =VLOOKUP($B12,#REF!,8,0) -> #REF! | K12: Cover | L12: 24 | M12: 26 | N12: 31
D13: =VLOOKUP($B13,#REF!,3,0) -> #REF! | E13: =VLOOKUP($B13,#REF!,4,0) -> #REF! | F13: =VLOOKUP($B13,#REF!,5,0) -> #REF! | G13: =VLOOKUP($B13,#REF!,6,0) -> #REF! | H13: =VLOOKUP($B13,#REF!,7,0) -> #REF! | I13: =VLOOKUP($B13,#REF!,8,0) -> #REF! | K13: Height | L13: 26 | M13: 30 | N13: 31
B14: 3 | C14: N → S | D14: =VLOOKUP($B14,#REF!,3,0) -> #REF! | E14: =VLOOKUP($B14,#REF!,4,0) -> #REF! | F14: =VLOOKUP($B14,#REF!,5,0) -> #REF! | G14: =VLOOKUP($B14,#REF!,6,0) -> #REF! | H14: =VLOOKUP($B14,#REF!,7,0) -> #REF! | I14: =VLOOKUP($B14,#REF!,8,0) -> #REF! | K14: Cover | L14: 23 | M14: 26 | N14: 25
D15: =VLOOKUP($B15,#REF!,3,0) -> #REF! | E15: =VLOOKUP($B15,#REF!,4,0) -> #REF! | F15: =VLOOKUP($B15,#REF!,5,0) -> #REF! | G15: =VLOOKUP($B15,#REF!,6,0) -> #REF! | H15: =VLOOKUP($B15,#REF!,7,0) -> #REF! | I15: =VLOOKUP($B15,#REF!,8,0) -> #REF! | K15: Height | L15: 28 | M15: 27 | N15: 23
B16: 4 | C16: S → N | D16: =VLOOKUP($B16,#REF!,3,0) -> #REF! | E16: =VLOOKUP($B16,#REF!,4,0) -> #REF! | F16: =VLOOKUP($B16,#REF!,5,0) -> #REF! | G16: =VLOOKUP($B16,#REF!,6,0) -> #REF! | H16: =VLOOKUP($B16,#REF!,7,0) -> #REF! | I16: =VLOOKUP($B16,#REF!,8,0) -> #REF! | K16: Cover | L16: 25 | M16: 30 | N16: 28
D17: =VLOOKUP($B17,#REF!,3,0) -> #REF! | E17: =VLOOKUP($B17,#REF!,4,0) -> #REF! | F17: =VLOOKUP($B17,#REF!,5,0) -> #REF! | G17: =VLOOKUP($B17,#REF!,6,0) -> #REF! | H17: =VLOOKUP($B17,#REF!,7,0) -> #REF! | I17: =VLOOKUP($B17,#REF!,8,0) -> #REF! | K17: Height | L17: 28 | M17: 32 | N17: 31
B18: 5 | C18: N → S | D18: =VLOOKUP($B18,#REF!,3,0) -> #REF! | E18: =VLOOKUP($B18,#REF!,4,0) -> #REF! | F18: =VLOOKUP($B18,#REF!,5,0) -> #REF! | G18: =VLOOKUP($B18,#REF!,6,0) -> #REF! | H18: =VLOOKUP($B18,#REF!,7,0) -> #REF! | I18: =VLOOKUP($B18,#REF!,8,0) -> #REF! | K18: Cover | L18: 27 | M18: 26 | N18: 30
D19: =VLOOKUP($B19,#REF!,3,0) -> #REF! | E19: =VLOOKUP($B19,#REF!,4,0) -> #REF! | F19: =VLOOKUP($B19,#REF!,5,0) -> #REF! | G19: =VLOOKUP($B19,#REF!,6,0) -> #REF! | H19: =VLOOKUP($B19,#REF!,7,0) -> #REF! | I19: =VLOOKUP($B19,#REF!,8,0) -> #REF! | K19: Height | L19: 31 | M19: 28 | N19: 29
B20: 6 | C20: S → N | D20: =VLOOKUP($B20,#REF!,3,0) -> #REF! | E20: =VLOOKUP($B20,#REF!,4,0) -> #REF! | F20: =VLOOKUP($B20,#REF!,5,0) -> #REF! | G20: =VLOOKUP($B20,#REF!,6,0) -> #REF! | H20: =VLOOKUP($B20,#REF!,7,0) -> #REF! | I20: =VLOOKUP($B20,#REF!,8,0) -> #REF! | K20: Cover | L20: 25 | M20: 22 | N20: 28
D21: =VLOOKUP($B21,#REF!,3,0) -> #REF! | E21: =VLOOKUP($B21,#REF!,4,0) -> #REF! | F21: =VLOOKUP($B21,#REF!,5,0) -> #REF! | G21: =VLOOKUP($B21,#REF!,6,0) -> #REF! | H21: =VLOOKUP($B21,#REF!,7,0) -> #REF! | I21: =VLOOKUP($B21,#REF!,8,0) -> #REF! | K21: Height | L21: 29 | M21: 26 | N21: 27
B22: 7 | C22: N → S | D22: =VLOOKUP($B22,#REF!,3,0) -> #REF! | E22: =VLOOKUP($B22,#REF!,4,0) -> #REF! | F22: =VLOOKUP($B22,#REF!,5,0) -> #REF! | G22: =VLOOKUP($B22,#REF!,6,0) -> #REF! | H22: =VLOOKUP($B22,#REF!,7,0) -> #REF! | I22: =VLOOKUP($B22,#REF!,8,0) -> #REF! | K22: Cover | L22: 24 | M22: 28 | N22: 23
D23: =VLOOKUP($B23,#REF!,3,0) -> #REF! | E23: =VLOOKUP($B23,#REF!,4,0) -> #REF! | F23: =VLOOKUP($B23,#REF!,5,0) -> #REF! | G23: =VLOOKUP($B23,#REF!,6,0) -> #REF! | H23: =VLOOKUP($B23,#REF!,7,0) -> #REF! | I23: =VLOOKUP($B23,#REF!,8,0) -> #REF! | K23: Height | L23: 28 | M23: 28 | N23: 25
B24: 8 | C24: S → N | D24: =VLOOKUP($B24,#REF!,3,0) -> #REF! | E24: =VLOOKUP($B24,#REF!,4,0) -> #REF! | F24: =VLOOKUP($B24,#REF!,5,0) -> #REF! | G24: =VLOOKUP($B24,#REF!,6,0) -> #REF! | H24: =VLOOKUP($B24,#REF!,7,0) -> #REF! | I24: =VLOOKUP($B24,#REF!,8,0) -> #REF! | K24: Cover | L24: 25 | M24: 27 | N24: 26
D25: =VLOOKUP($B25,#REF!,3,0) -> #REF! | E25: =VLOOKUP($B25,#REF!,4,0) -> #REF! | F25: =VLOOKUP($B25,#REF!,5,0) -> #REF! | G25: =VLOOKUP($B25,#REF!,6,0) -> #REF! | H25: =VLOOKUP($B25,#REF!,7,0) -> #REF! | I25: =VLOOKUP($B25,#REF!,8,0) -> #REF! | K25: Height | L25: 27 | M25: 29 | N25: 27
B26: 9 | C26: N → S | D26: =VLOOKUP($B26,#REF!,3,0) -> #REF! | E26: =VLOOKUP($B26,#REF!,4,0) -> #REF! | F26: =VLOOKUP($B26,#REF!,5,0) -> #REF! | G26: =VLOOKUP($B26,#REF!,6,0) -> #REF! | H26: =VLOOKUP($B26,#REF!,7,0) -> #REF! | I26: =VLOOKUP($B26,#REF!,8,0) -> #REF! | J26: 1237 | K26: Cover | L26: 24 | M26: 29 | N26: 25
D27: =VLOOKUP($B27,#REF!,3,0) -> #REF! | E27: =VLOOKUP($B27,#REF!,4,0) -> #REF! | F27: =VLOOKUP($B27,#REF!,5,0) -> #REF! | G27: =VLOOKUP($B27,#REF!,6,0) -> #REF! | H27: =VLOOKUP($B27,#REF!,7,0) -> #REF! | I27: =VLOOKUP($B27,#REF!,8,0) -> #REF! | K27: Height | L27: 26 | M27: 29 | N27: 26
B28: 10 | C28: S → N | D28: =VLOOKUP($B28,#REF!,3,0) -> #REF! | E28: =VLOOKUP($B28,#REF!,4,0) -> #REF! | F28: =VLOOKUP($B28,#REF!,5,0) -> #REF! | G28: =VLOOKUP($B28,#REF!,6,0) -> #REF! | H28: =VLOOKUP($B28,#REF!,7,0) -> #REF! | I28: =VLOOKUP($B28,#REF!,8,0) -> #REF! | K28: Cover | L28: 28 | M28: 18 | N28: 27
D29: =VLOOKUP($B29,#REF!,3,0) -> #REF! | E29: =VLOOKUP($B29,#REF!,4,0) -> #REF! | F29: =VLOOKUP($B29,#REF!,5,0) -> #REF! | G29: =VLOOKUP($B29,#REF!,6,0) -> #REF! | H29: =VLOOKUP($B29,#REF!,7,0) -> #REF! | I29: =VLOOKUP($B29,#REF!,8,0) -> #REF! | K29: Height | L29: 29 | M29: 26 | N29: 28
