Workbook

Sheet Raw Scale
A1: Column A - ID (ID)
A2: Column B - Harvest Area ID (HID)
A3: Column C - Harvest method (HARM)
A4: Column D - Harvest date (HADAT, mm/dd/yyyy)
A5: Column E - Weight of machine-picked cotton in bag (lbs). Machine harvest 2 rows by 14.476 m into mesh bags. Weigh in field using IQ plus 390-DC scale.
A6: Column F - Wet bulk weight at harvest (fiber + seed + trash) (WBWAH, kg/ha)
A7: Column G - Ginning Date (GNDAT, mm/dd/yyyy). Ginned using the MAC large gin with cleaners.
A8: Column H - Weight of bulk cotton subsample in bag prior to ginning (lbs)
A9: Column I - Weight of combined bulk cotton samples. Material from neighboring harvest areas were combined prior to ginning (1&20,2&19,…9&12,10&11,21&40,22&39,…29&32,30&31) (lbs)
A10: Column J - Weight of fiber in bag after ginning (lbs)
A11: Column K - Weight of fuzzy seed in bin after ginning (lbs)
A12: Column L - Fiber fraction after ginning (FFRAC, g/g)
... A19: Parameters
A20: 1.08 | B20: Weight of a single mesh harvest bag (lbs)
A21: 0.453592 | B21: kg per lb
A22: =2*1.016*14.476 -> 29.415232 | B22: Size of harvest area (2 40-inch rows by 14.476 m, 16 m plot length minus 5 foot buffer mowed out) (m2)
A23: 10000 | B23: m2 per ha
A24: 0.16 | B24: Weight of a single subsample bag (lbs)
A25: 1.04 | B25: Weight of bag for fiber at gin (lbs)
A26: 1.7 | B26: Weight of seed bin at gin (lbs) | S26: Plot-scale calculations | AJ26: Zone-scale calculations
C28: Harvest | D28: Harvest | E28: Harvest | F28: Harvest | G28: Ginning | H28: Ginning | I28: Ginning | J28: Ginning | K28: Ginning | L28: Ginning | M28: Ginning | N28: Ginning | O28: Compute | P28: Compute | Q28: Compute | T28: Harvest | U28: Harvest | V28: Harvest | W28: Harvest | X28: Ginning | Y28: Ginning | Z28: Ginning | AA28: Ginning | AB28: Ginning | AC28: Ginning | AD28: Ginning | AE28: Ginning | AF28: Compute | AG28: Compute | AH28: Compute | AK28: Harvest | AL28: Harvest | AM28: Harvest | AN28: Harvest | AO28: Ginning | AP28: Ginning | AQ28: Ginning | AR28: Ginning | AS28: Ginning | AT28: Ginning | AU28: Ginning | AV28: Ginning | AW28: Compute | AX28: Compute | AY28: Compute
I29: Combined | J29: Combined | K29: Combined | Z29: Combined | AA29: Combined | AB29: Combined | AQ29: Combined | AR29: Combined | AS29: Combined
E30: Field wt | G30: Date | H30: Sample | I30: Sample | J30: Fiber | K30: Seed | V30: Field wt | X30: Date | Y30: Sample | Z30: Sample | AA30: Fiber | AB30: Seed | AM30: Field wt | AO30: Date | AP30: Sample | AQ30: Sample | AR30: Fiber | AS30: Seed
A31: ID | B31: HID | C31: HARM | D31: HADAT | E31: in bag | F31: WBWAH | G31: GNDAT | H31: wt in bag | I31: Weight | J31: wt in bag | K31: wt in bin | L31: FFRAC | M31: SFRAC | N31: TFRAC | O31: WFWAH | P31: WSWAH | Q31: WSCWAH | S31: PID | T31: HARM | U31: HADAT | V31: in bag | W31: WBWAH | X31: GNDAT | Y31: wt in bags | Z31: Weight | AA31: wt in bags | AB31: wt in bins | AC31: FFRAC | AD31: SFRAC | AE31: TFRAC | AF31: WFWAH | AG31: WSWAH | AH31: WSCWAH | AJ31: ZID | AK31: HARM | AL31: HADAT | AM31: in bag | AN31: WBWAH | AO31: GNDAT | AP31: wt in bags | AQ31: Weight | AR31: wt in bags | AS31: wt in bins | AT31: FFRAC | AU31: SFRAC | AV31: TFRAC | AW31: WFWAH | AX31: WSWAH | AY31: WSCWAH
E32: (lbs) | F32: (kg/ha) | H32: (lbs) | I32: (lbs) | J32: (lbs) | K32: (lbs) | L32: (g/g) | M32: (g/g) | N32: (g/g) | O32: (kg/ha) | P32: (kg/ha) | Q32: (kg/ha) | V32: (lbs) | W32: (kg/ha) | Y32: (lbs) | Z32: (lbs) | AA32: (lbs) | AB32: (lbs) | AC32: (g/g) | AD32: (g/g) | AE32: (g/g) | AF32: (kg/ha) | AG32: (kg/ha) | AH32: (kg/ha) | AM32: (lbs) | AN32: (kg/ha) | AP32: (lbs) | AQ32: (lbs) | AR32: (lbs) | AS32: (lbs) | AT32: (g/g) | AU32: (g/g) | AV32: (g/g) | AW32: (kg/ha) | AX32: (kg/ha) | AY32: (kg/ha)
A33: ID | B33: HID | C33: HARM | D33: HADAT | F33: WBWAH | G33: GNDAT | L33: FFRAC | M33: SFRAC | N33: TFRAC | O33: WFWAH | P33: WSWAH | Q33: WSCWAH | S33: PID | T33: HARM | U33: HADAT | W33: WBWAH | X33: GNDAT | AC33: FFRAC | AD33: SFRAC | AE33: TFRAC | AF33: WFWAH | AG33: WSWAH | AH33: WSCWAH | AJ33: ZID | AK33: HARM | AL33: HADAT | AN33: WBWAH | AO33: GNDAT | AT33: FFRAC | AU33: SFRAC | AV33: TFRAC | AW33: WFWAH | AX33: WSWAH | AY33: WSCWAH
A34: 1 | B34: p01-01 | C34: Machine | D34: 40827 | E34: 19 | F34: =(E34-2*$A$20)*$A$21/$A$22*$A$23 -> 2596.7802 | G34: 40200 | H34: 3.02 | I34: =H34+H53-2*$A$24 -> 5.98 | J34: 3.16 | K34: 5.04 | L34: =(J34-$A$25)/I34 -> 0.35451505 | M34: =(K34-$A$26)/I34 -> 0.55852843 | N34: =1-L34-M34 -> 0.086956522 | O34: =F34*L34 -> 920.59767 | P34: =F34*M34 -> 1450.3756 | Q34: =O34+P34 -> 2370.9732 | S34: p01 | T34: Machine | U34: =D34 -> 40827 | V34: =SUM(E34:E73) -> 1130.4 | W34: =(V34-80*$A$20)*$A$21/(40*$A$22)*$A$23 -> 4024.7009 | X34: =G34 -> 40200 | Y34: =SUM(H34:H73) -> 130.32 | Z34: =SUM(I34:I73) -> 247.84 | AA34: =SUM(J34:J73) -> 127.72 | AB34: =SUM(K34:K73) -> 205.96 | AC34: =(AA34-40*$A$25)/Z34 -> 0.34748225 | AD34: =(AB34-40*$A$26)/Z34 -> 0.55664945 | AE34: =1-AC34-AD34 -> 0.095868302 | AF34: =W34*AC34 -> 1398.5121 | AG34: =W34*AD34 -> 2240.3476 | AH34: =AF34+AG34 -> 3638.8597 | AJ34: p0101 | AK34: Machine | AL34: =D43 -> 40827 | AM34: =SUM(E43,E44) -> 53.1 | AN34: =(AM34-4*$A$20)*$A$21/(2*$A$22)*$A$23 -> 3761.0136 | AO34: =G43 -> 40200 | AP34: =SUM(H43,H44) -> 6.62 | AQ34: =SUM(I43,I44) -> 12.6 | AR34: =SUM(J43,J44) -> 6.48 | AS34: =SUM(K43,K44) -> 10.44 | AT34: =(AR34-2*$A$25)/AQ34 -> 0.34920635 | AU34: =(AS34-2*$A$26)/AQ34 -> 0.55873016 | AV34: =1-AT34-AU34 -> 0.092063492 | AW34: =AN34*AT34 -> 1313.3698 | AX34: =AN34*AU34 -> 2101.3917 | AY34: =AW34+AX34 -> 3414.7616
A35: 2 | B35: p01-02 | C35: Machine | D35: 40827 | E35: 22 | F35: =(E35-2*$A$20)*$A$21/$A$22*$A$23 -> 3059.3895 | G35: 40200 | H35: 3.28 | I35: =H35+H52-2*$A$24 -> 6 | J35: 3.14 | K35: 4.98 | L35: =(J35-$A$25)/I35 -> 0.35 | M35: =(K35-$A$26)/I35 -> 0.54666667 | N35: =1-L35-M35 -> 0.10333333 | O35: =F35*L35 -> 1070.7863 | P35: =F35*M35 -> 1672.4663 | Q35: =O35+P35 -> 2743.2526
A36: 3 | B36: p01-03 | C36: Machine | D36: 40827 | E36: 22.7 | F36: =(E36-2*$A$20)*$A$21/$A$22*$A$23 -> 3167.3317 | G36: 40200 | H36: 3.26 | I36: =H36+H51-2*$A$24 -> 6.62 | J36: 3.38 | K36: 5.36 | L36: =(J36-$A$25)/I36 -> 0.35347432 | M36: =(K36-$A$26)/I36 -> 0.55287009 | N36: =1-L36-M36 -> 0.093655589 | O36: =F36*L36 -> 1119.5704 | P36: =F36*M36 -> 1751.123 | Q36: =O36+P36 -> 2870.6934 | AJ36: p0102 | AK36: Machine | AL36: =D42 -> 40827 | AM36: =SUM(E42,E45) -> 48.4 | AN36: =(AM36-4*$A$20)*$A$21/(2*$A$22)*$A$23 -> 3398.6364 | AO36: =G42 -> 40200 | AP36: =SUM(H42,H45) -> 5.98 | AQ36: =SUM(I42,I45) -> 11.32 | AR36: =SUM(J42,J45) -> 5.92 | AS36: =SUM(K42,K45) -> 9.72 | AT36: =(AR36-2*$A$25)/AQ36 -> 0.33922261 | AU36: =(AS36-2*$A$26)/AQ36 -> 0.55830389 | AV36: =1-AT36-AU36 -> 0.1024735 | AW36: =AN36*AT36 -> 1152.8943 | AX36: =AN36*AU36 -> 1897.4719 | AY36: =AW36+AX36 -> 3050.3662
A37: 4 | B37: p01-04 | C37: Machine | D37: 40827 | E37: 26.6 | F37: =(E37-2*$A$20)*$A$21/$A$22*$A$23 -> 3768.7238 | G37: 40200 | H37: 3.02 | I37: =H37+H50-2*$A$24 -> 5.52 | J37: 2.94 | K37: 4.8 | L37: =(J37-$A$25)/I37 -> 0.3442029 | M37: =(K37-$A$26)/I37 -> 0.5615942 | N37: =1-L37-M37 -> 0.094202899 | O37: =F37*L37 -> 1297.2057 | P37: =F37*M37 -> 2116.4934 | Q37: =O37+P37 -> 3413.6991
A38: 5 | B38: p01-05 | C38: Machine | D38: 40827 | E38: 25.6 | F38: =(E38-2*$A$20)*$A$21/$A$22*$A$23 -> 3614.5207 | G38: 40200 | H38: 3.3 | I38: =H38+H49-2*$A$24 -> 5.48 | J38: 2.98 | K38: 4.78 | L38: =(J38-$A$25)/I38 -> 0.3540146 | M38: =(K38-$A$26)/I38 -> 0.5620438 | N38: =1-L38-M38 -> 0.083941606 | O38: =F38*L38 -> 1279.5931 | P38: =F38*M38 -> 2031.5189 | Q38: =O38+P38 -> 3311.112 | AJ38: p0103 | AK38: Machine | AL38: =D41 -> 40827 | AM38: =SUM(E41,E46) -> 55.9 | AN38: =(AM38-4*$A$20)*$A$21/(2*$A$22)*$A$23 -> 3976.898 | AO38: =G41 -> 40200 | AP38: =SUM(H41,H46) -> 6.44 | AQ38: =SUM(I41,I46) -> 12.24 | AR38: =SUM(J41,J46) -> 6.52 | AS38: =SUM(K41,K46) -> 10.24 | AT38: =(AR38-2*$A$25)/AQ38 -> 0.3627451 | AU38: =(AS38-2*$A$26)/AQ38 -> 0.55882353 | AV38: =1-AT38-AU38 -> 0.078431373 | AW38: =AN38*AT38 -> 1442.6002 | AX38: =AN38*AU38 -> 2222.3842 | AY38: =AW38+AX38 -> 3664.9844
A39: 6 | B39: p01-06 | C39: Machine | D39: 40827 | E39: 26.7 | F39: =(E39-2*$A$20)*$A$21/$A$22*$A$23 -> 3784.1441 | G39: 40200 | H39: 3.38 | I39: =H39+H48-2*$A$24 -> 7.08 | J39: 3.54 | K39: 5.64 | L39: =(J39-$A$25)/I39 -> 0.35310734 | M39: =(K39-$A$26)/I39 -> 0.55649718 | N39: =1-L39-M39 -> 0.09039548 | O39: =F39*L39 -> 1336.2091 | P39: =F39*M39 -> 2105.8655 | Q39: =O39+P39 -> 3442.0746
A40: 7 | B40: p01-07 | C40: Machine | D40: 40827 | E40: 27.5 | F40: =(E40-2*$A$20)*$A$21/$A$22*$A$23 -> 3907.5066 | G40: 40200 | H40: 3.18 | I40: =H40+H47-2*$A$24 -> 6.64 | J40: 3.32 | K40: 5.36 | L40: =(J40-$A$25)/I40 -> 0.34337349 | M40: =(K40-$A$26)/I40 -> 0.55120482 | N40: =1-L40-M40 -> 0.10542169 | O40: =F40*L40 -> 1341.7342 | P40: =F40*M40 -> 2153.8365 | Q40: =O40+P40 -> 3495.5707 | AJ40: p0104 | AK40: Machine | AL40: =D40 -> 40827 | AM40: =SUM(E40,E47) -> 60.7 | AN40: =(AM40-4*$A$20)*$A$21/(2*$A$22)*$A$23 -> 4346.9854 | AO40: =G40 -> 40200 | AP40: =SUM(H40,H47) -> 6.96 | AQ40: =SUM(I40,I47) -> 13.28 | AR40: =SUM(J40,J47) -> 6.64 | AS40: =SUM(K40,K47) -> 10.72 | AT40: =(AR40-2*$A$25)/AQ40 -> 0.34337349 | AU40: =(AS40-2*$A$26)/AQ40 -> 0.55120482 | AV40: =1-AT40-AU40 -> 0.10542169 | AW40: =AN40*AT40 -> 1492.6396 | AX40: =AN40*AU40 -> 2396.0793 | AY40: =AW40+AX40 -> 3888.7189
A41: 8 | B41: p01-08 | C41: Machine | D41: 40827 | E41: 26.3 | F41: =(E41-2*$A$20)*$A$21/$A$22*$A$23 -> 3722.4629 | G41: 40200 | H41: 2.9 | I41: =H41+H46-2*$A$24 -> 6.12 | J41: 3.26 | K41: 5.12 | L41: =(J41-$A$25)/I41 -> 0.3627451 | M41: =(K41-$A$26)/I41 -> 0.55882353 | N41: =1-L41-M41 -> 0.078431373 | O41: =F41*L41 -> 1350.3052 | P41: =F41*M41 -> 2080.1998 | Q41: =O41+P41 -> 3430.505
A42: 9 | B42: p01-09 | C42: Machine | D42: 40827 | E42: 21.4 | F42: =(E42-2*$A$20)*$A$21/$A$22*$A$23 -> 2966.8677 | G42: 40200 | H42: 2.86 | I42: =H42+H45-2*$A$24 -> 5.66 | J42: 2.96 | K42: 4.86 | L42: =(J42-$A$25)/I42 -> 0.33922261 | M42: =(K42-$A$26)/I42 -> 0.55830389 | N42: =1-L42-M42 -> 0.1024735 | O42: =F42*L42 -> 1006.4286 | P42: =F42*M42 -> 1656.4138 | Q42: =O42+P42 -> 2662.8424 | AJ42: p0105 | AK42: Machine | AL42: =D39 -> 40827 | AM42: =SUM(E39,E48) -> 58.6 | AN42: =(AM42-4*$A$20)*$A$21/(2*$A$22)*$A$23 -> 4185.0722 | AO42: =G39 -> 40200 | AP42: =SUM(H39,H48) -> 7.4 | AQ42: =SUM(I39,I48) -> 14.16 | AR42: =SUM(J39,J48) -> 7.08 | AS42: =SUM(K39,K48) -> 11.28 | AT42: =(AR42-2*$A$25)/AQ42 -> 0.35310734 | AU42: =(AS42-2*$A$26)/AQ42 -> 0.55649718 | AV42: =1-AT42-AU42 -> 0.09039548 | AW42: =AN42*AT42 -> 1477.7797 | AX42: =AN42*AU42 -> 2328.9808 | AY42: =AW42+AX42 -> 3806.7606
A43: 10 | B43: p01-10 | C43: Machine | D43: 40827 | E43: 22.9 | F43: =(E43-2*$A$20)*$A$21/$A$22*$A$23 -> 3198.1723 | G43: 40200 | H43: 3.68 | I43: =H43+H44-2*$A$24 -> 6.3 | J43: 3.24 | K43: 5.22 | L43: =(J43-$A$25)/I43 -> 0.34920635 | M43: =(K43-$A$26)/I43 -> 0.55873016 | N43: =1-L43-M43 -> 0.092063492 | O43: =F43*L43 -> 1116.8221 | P43: =F43*M43 -> 1786.9153 | Q43: =O43+P43 -> 2903.7374
A44: 11 | B44: p01-11 | C44: Machine | D44: 40827 | E44: 30.2 | F44: =(E44-2*$A$20)*$A$21/$A$22*$A$23 -> 4323.855 | G44: 40200 | H44: 2.94 | I44: =H44+H43-2*$A$24 -> 6.3 | J44: 3.24 | K44: 5.22 | L44: =(J44-$A$25)/I44 -> 0.34920635 | M44: =(K44-$A$26)/I44 -> 0.55873016 | N44: =1-L44-M44 -> 0.092063492 | O44: =F44*L44 -> 1509.9176 | P44: =F44*M44 -> 2415.8682 | Q44: =O44+P44 -> 3925.7858 | AJ44: p0106 | AK44: Machine | AL44: =D38 -> 40827 | AM44: =SUM(E38,E49) -> 55.6 | AN44: =(AM44-4*$A$20)*$A$21/(2*$A$22)*$A$23 -> 3953.7675 | AO44: =G38 -> 40200 | AP44: =SUM(H38,H49) -> 5.8 | AQ44: =SUM(I38,I49) -> 10.96 | AR44: =SUM(J38,J49) -> 5.96 | AS44: =SUM(K38,K49) -> 9.56 | AT44: =(AR44-2*$A$25)/AQ44 -> 0.3540146 | AU44: =(AS44-2*$A$26)/AQ44 -> 0.5620438 | AV44: =1-AT44-AU44 -> 0.083941606 | AW44: =AN44*AT44 -> 1399.6914 | AX44: =AN44*AU44 -> 2222.1905 | AY44: =AW44+AX44 -> 3621.8819
A45: 12 | B45: p01-12 | C45: Machine | D45: 40827 | E45: 27 | F45: =(E45-2*$A$20)*$A$21/$A$22*$A$23 -> 3830.405 | G45: 40200 | H45: 3.12 | I45: =H45+H42-2*$A$24 -> 5.66 | J45: 2.96 | K45: 4.86 | L45: =(J45-$A$25)/I45 -> 0.33922261 | M45: =(K45-$A$26)/I45 -> 0.55830389 | N45: =1-L45-M45 -> 0.1024735 | O45: =F45*L45 -> 1299.36 | P45: =F45*M45 -> 2138.53 | Q45: =O45+P45 -> 3437.89
A46: 13 | B46: p01-13 | C46: Machine | D46: 40827 | E46: 29.6 | F46: =(E46-2*$A$20)*$A$21/$A$22*$A$23 -> 4231.3331 | G46: 40200 | H46: 3.54 | I46: =H46+H41-2*$A$24 -> 6.12 | J46: 3.26 | K46: 5.12 | L46: =(J46-$A$25)/I46 -> 0.3627451 | M46: =(K46-$A$26)/I46 -> 0.55882353 | N46: =1-L46-M46 -> 0.078431373 | O46: =F46*L46 -> 1534.8953 | P46: =F46*M46 -> 2364.5685 | Q46: =O46+P46 -> 3899.4638 | AJ46: p0107 | AK46: Machine | AL46: =D37 -> 40827 | AM46: =SUM(E37,E50) -> 61.2 | AN46: =(AM46-4*$A$20)*$A$21/(2*$A$22)*$A$23 -> 4385.5362 | AO46: =G37 -> 40200 | AP46: =SUM(H37,H50) -> 5.84 | AQ46: =SUM(I37,I50) -> 11.04 | AR46: =SUM(J37,J50) -> 5.88 | AS46: =SUM(K37,K50) -> 9.6 | AT46: =(AR46-2*$A$25)/AQ46 -> 0.3442029 | AU46: =(AS46-2*$A$26)/AQ46 -> 0.5615942 | AV46: =1-AT46-AU46 -> 0.094202899 | AW46: =AN46*AT46 -> 1509.5143 | AX46: =AN46*AU46 -> 2462.8917 | AY46: =AW46+AX46 -> 3972.406
A47: 14 | B47: p01-14 | C47: Machine | D47: 40827 | E47: 33.2 | F47: =(E47-2*$A$20)*$A$21/$A$22*$A$23 -> 4786.4643 | G47: 40200 | H47: 3.78 | I47: =H47+H40-2*$A$24 -> 6.64 | J47: 3.32 | K47: 5.36 | L47: =(J47-$A$25)/I47 -> 0.34337349 | M47: =(K47-$A$26)/I47 -> 0.55120482 | N47: =1-L47-M47 -> 0.10542169 | O47: =F47*L47 -> 1643.545 | P47: =F47*M47 -> 2638.3222 | Q47: =O47+P47 -> 4281.8671
...

Sheet Zone Scale
B1: Harvest | C1: Harvest | D1: Harvest | E1: Harvest | F1: Ginning | G1: Ginning | H1: Ginning | I1: Ginning | J1: Ginning | K1: Ginning | L1: Ginning | M1: Ginning | N1: Compute | O1: Compute | P1: Compute
H2: Combined | I2: Combined | J2: Combined
D3: Field wt | F3: Date | G3: Sample | H3: Sample | I3: Fiber | J3: Seed
A4: ZID | B4: HARM | C4: HADAT | D4: in bag | E4: WBWAH | F4: GNDAT | G4: wt in bags | H4: Weight | I4: wt in bags | J4: wt in bins | K4: FFRAC | L4: SFRAC | M4: TFRAC | N4: WFWAH | O4: WSWAH | P4: WSCWAH
D5: (lbs) | E5: (kg/ha) | G5: (lbs) | H5: (lbs) | I5: (lbs) | J5: (lbs) | K5: (g/g) | L5: (g/g) | M5: (g/g) | N5: (kg/ha) | O5: (kg/ha) | P5: (kg/ha)
A6: ZID | B6: HARM | C6: HADAT | E6: WBWAH | F6: GNDAT | K6: FFRAC | L6: SFRAC | M6: TFRAC | N6: WFWAH | O6: WSWAH | P6: WSCWAH
A7: p0101 | B7: Machine | C7: 40827 | D7: 53.1 | E7: 3761.0136 | F7: 40200 | G7: 6.62 | H7: 12.6 | I7: 6.48 | J7: 10.44 | K7: 0.34920635 | L7: 0.55873016 | M7: 0.092063492 | N7: 1313.3698 | O7: 2101.3917 | P7: 3414.7616
A8: p0102 | B8: Machine | C8: 40827 | D8: 48.4 | E8: 3398.6364 | F8: 40200 | G8: 5.98 | H8: 11.32 | I8: 5.92 | J8: 9.72 | K8: 0.33922261 | L8: 0.55830389 | M8: 0.1024735 | N8: 1152.8943 | O8: 1897.4719 | P8: 3050.3662
A9: p0103 | B9: Machine | C9: 40827 | D9: 55.9 | E9: 3976.898 | F9: 40200 | G9: 6.44 | H9: 12.24 | I9: 6.52 | J9: 10.24 | K9: 0.3627451 | L9: 0.55882353 | M9: 0.078431373 | N9: 1442.6002 | O9: 2222.3842 | P9: 3664.9844
A10: p0104 | B10: Machine | C10: 40827 | D10: 60.7 | E10: 4346.9854 | F10: 40200 | G10: 6.96 | H10: 13.28 | I10: 6.64 | J10: 10.72 | K10: 0.34337349 | L10: 0.55120482 | M10: 0.10542169 | N10: 1492.6396 | O10: 2396.0793 | P10: 3888.7189
A11: p0105 | B11: Machine | C11: 40827 | D11: 58.6 | E11: 4185.0722 | F11: 40200 | G11: 7.4 | H11: 14.16 | I11: 7.08 | J11: 11.28 | K11: 0.35310734 | L11: 0.55649718 | M11: 0.09039548 | N11: 1477.7797 | O11: 2328.9808 | P11: 3806.7606
A12: p0106 | B12: Machine | C12: 40827 | D12: 55.6 | E12: 3953.7675 | F12: 40200 | G12: 5.8 | H12: 10.96 | I12: 5.96 | J12: 9.56 | K12: 0.3540146 | L12: 0.5620438 | M12: 0.083941606 | N12: 1399.6914 | O12: 2222.1905 | P12: 3621.8819
A13: p0107 | B13: Machine | C13: 40827 | D13: 61.2 | E13: 4385.5362 | F13: 40200 | G13: 5.84 | H13: 11.04 | I13: 5.88 | J13: 9.6 | K13: 0.3442029 | L13: 0.5615942 | M13: 0.094202899 | N13: 1509.5143 | O13: 2462.8917 | P13: 3972.406
A14: p0108 | B14: Machine | C14: 40827 | D14: 52.7 | E14: 3730.173 | F14: 40200 | G14: 6.94 | H14: 13.24 | I14: 6.76 | J14: 10.72 | K14: 0.35347432 | L14: 0.55287009 | M14: 0.093655589 | N14: 1318.5204 | O14: 2062.3011 | P14: 3380.8215
A15: p0109 | B15: Machine | C15: 40827 | D15: 49.6 | E15: 3491.1582 | F15: 40200 | G15: 6.32 | H15: 12 | I15: 6.28 | J15: 9.96 | K15: 0.35 | L15: 0.54666667 | M15: 0.10333333 | N15: 1221.9054 | O15: 1908.4998 | P15: 3130.4052
A16: p0110 | B16: Machine | C16: 40827 | D16: 45.9 | E16: 3205.8825 | F16: 40200 | G16: 6.3 | H16: 11.96 | I16: 6.32 | J16: 10.08 | K16: 0.35451505 | L16: 0.55852843 | M16: 0.086956522 | N16: 1136.5336 | O16: 1790.5765 | P16: 2927.1101
A17: p0111 | B17: Machine | C17: 40827 | D17: 55.9 | E17: 3976.898 | F17: 40200 | G17: 6.32 | H17: 12 | I17: 6.2 | J17: 10.24 | K17: 0.34333333 | L17: 0.57 | M17: 0.086666667 | N17: 1365.4016 | O17: 2266.8319 | P17: 3632.2335
A18: p0112 | B18: Machine | C18: 40827 | D18: 58.1 | E18: 4146.5214 | F18: 40200 | G18: 6.82 | H18: 13 | I18: 6.56 | J18: 10.52 | K18: 0.34461538 | L18: 0.54769231 | M18: 0.10769231 | N18: 1428.9551 | O18: 2271.0179 | P18: 3699.9729
... A326: p1620 | B326: Machine | C326: 40830 | D326: 53.91 | E326: 3823.4659 | F326: 40204 | G326: 6.3 | H326: 11.96 | I326: 6.08 | J326: 10.08 | K326: 0.33444816 | L326: 0.55852843 | M326: 0.10702341 | N326: 1278.7511 | O326: 2135.5144 | P326: 3414.2655

Sheet Plot Scale
B1: Harvest | C1: Harvest | D1: Harvest | E1: Harvest | F1: Ginning | G1: Ginning | H1: Ginning | I1: Ginning | J1: Ginning | K1: Ginning | L1: Ginning | M1: Ginning | N1: Compute | O1: Compute | P1: Compute
H2: Combined | I2: Combined | J2: Combined
D3: Field wt | F3: Date | G3: Sample | H3: Sample | I3: Fiber | J3: Seed
A4: PID | B4: HARM | C4: HADAT | D4: in bag | E4: WBWAH | F4: GNDAT | G4: wt in bags | H4: Weight | I4: wt in bags | J4: wt in bins | K4: FFRAC | L4: SFRAC | M4: TFRAC | N4: WFWAH | O4: WSWAH | P4: WSCWAH
D5: (lbs) | E5: (kg/ha) | G5: (lbs) | H5: (lbs) | I5: (lbs) | J5: (lbs) | K5: (g/g) | L5: (g/g) | M5: (g/g) | N5: (kg/ha) | O5: (kg/ha) | P5: (kg/ha)
A6: PID | B6: HARM | C6: HADAT | E6: WBWAH | F6: GNDAT | K6: FFRAC | L6: SFRAC | M6: TFRAC | N6: WFWAH | O6: WSWAH | P6: WSCWAH
A7: p01 | B7: Machine | C7: 40827 | D7: 1130.4 | E7: 4024.7009 | F7: 40200 | G7: 130.32 | H7: 247.84 | I7: 127.72 | J7: 205.96 | K7: 0.34748225 | L7: 0.55664945 | M7: 0.095868302 | N7: 1398.5121 | O7: 2240.3476 | P7: 3638.8597
A8: p02 | B8: Machine | C8: 40827 | D8: 1310.2 | E8: 4717.8439 | F8: 40200 | G8: 142.3 | H8: 271.8 | I8: 131.64 | J8: 224.52 | K8: 0.33127299 | L8: 0.57586461 | M8: 0.092862399 | N8: 1562.8943 | O8: 2716.8393 | P8: 4279.7336
A9: p03 | B9: Machine | C9: 40827 | D9: 1159.9 | E9: 4138.4257 | F9: 40200 | G9: 128.72 | H9: 244.64 | I9: 122.48 | J9: 209.6 | K9: 0.33060824 | L9: 0.57880968 | M9: 0.09058208 | N9: 1368.1977 | O9: 2395.3609 | P9: 3763.5585
A10: p04 | B10: Machine | C10: 40827 | D10: 1420 | E10: 5141.1314 | F10: 40205 | G10: 123.9 | H10: 235 | I10: 118.84 | J10: 202.92 | K10: 0.32868085 | L10: 0.57412766 | M10: 0.097191489 | N10: 1689.7914 | O10: 2951.6657 | P10: 4641.4572
A11: p05 | B11: Machine | C11: 40827 | D11: 1419.1 | E11: 5137.6618 | F11: 40205 | G11: 113.76 | H11: 214.72 | I11: 112.92 | J11: 189.04 | K11: 0.3321535 | L11: 0.56371088 | M11: 0.10413562 | N11: 1706.4924 | O11: 2896.1559 | P11: 4602.6482
A12: p06 | B12: Machine | C12: 40828 | D12: 1336 | E12: 4817.3049 | F12: 40205 | G12: 132.54 | H12: 252.28 | I12: 125.24 | J12: 211.12 | K12: 0.33153639 | L12: 0.56730617 | M12: 0.10115744 | N12: 1597.1119 | O12: 2732.8868 | P12: 4329.9986
A13: p07 | B13: Machine | C13: 40828 | D13: 1410.9 | E13: 5106.0502 | F13: 40204 | G13: 130.86 | H13: 248.92 | I13: 123.08 | J13: 210.04 | K13: 0.32733408 | L13: 0.5706251 | M13: 0.10204082 | N13: 1671.3843 | O13: 2913.6404 | P13: 4585.0247
A14: p08 | B14: Machine | C14: 40828 | D14: 1426.3 | E14: 5165.4184 | F14: 40204 | G14: 128.46 | H14: 244.12 | I14: 124.56 | J14: 205.28 | K14: 0.33983287 | L14: 0.56234639 | M14: 0.097820744 | N14: 1755.379 | O14: 2904.7544 | P14: 4660.1333
A15: p09 | B15: Machine | C15: 40828 | D15: 1201 | E15: 4296.8694 | F15: 40205 | G15: 119.46 | H15: 226.12 | I15: 118.52 | J15: 195.4 | K15: 0.34017336 | L15: 0.56341765 | M15: 0.096408986 | N15: 1461.6805 | O15: 2420.9321 | P15: 3882.6126
A16: p10 | B16: Machine | C16: 40828 | D16: 1597.5 | E16: 5825.4077 | F16: 40204 | G16: 130.68 | H16: 248.56 | I16: 123.68 | J16: 208.8 | K16: 0.33022208 | L16: 0.56646283 | M16: 0.10331509 | N16: 1923.6782 | O16: 3299.8769 | P16: 5223.5551
A17: p11 | B17: Machine | C17: 40829 | D17: 1445.3 | E17: 5238.6649 | F17: 40200 | G17: 145.9 | H17: 279 | I17: 135 | J17: 226.16 | K17: 0.33476703 | L17: 0.56688172 | M17: 0.098351254 | N17: 1753.7323 | O17: 2969.7033 | P17: 4723.4356
A18: p12 | B18: Machine | C18: 40829 | D18: 1189.6 | E18: 4252.9215 | F18: 40200 | G18: 141.56 | H18: 270.32 | I18: 129.48 | J18: 223.2 | K18: 0.32509618 | L18: 0.57413436 | M18: 0.10076946 | N18: 1382.6086 | O18: 2441.7484 | P18: 3824.3569
... A22: p16 | B22: Machine | C22: 40830 | D22: 1047.41 | E22: 3704.7681 | F22: 40204 | G22: 142.04 | H22: 271.28 | I22: 132.96 | J22: 220.92 | K22: 0.33677381 | L22: 0.56369802 | M22: 0.099528163 | N22: 1247.6689 | O22: 2088.3704 | P22: 3336.0393

Sheet Compare
B1: Original | C1: Original
B2: Spreadsheet | C2: Spreadsheet
B4: Lint | C4: Cottonseed | N4: 0
N5: 3500
A6: Plot
A7: 1 | B7: 1398.6065 | C7: 2242.6002
A8: 2 | B8: 1563.1485 | C8: 2718.8598
A9: 3 | B9: 1368.5259 | C9: 2397.7732
A10: 4 | B10: 1692.1451 | C10: 2953.0622
A11: 5 | B11: 1708.5412 | C11: 2897.4369
A12: 6 | B12: 1598.2501 | C12: 2736.6998
A13: 7 | B13: 1671.2312 | C13: 2915.0886
A14: 8 | B14: 1757.1442 | C14: 2906.9077
A15: 9 | B15: 1461.4396 | C15: 2423.1886
A16: 10 | B16: 1923.5403 | C16: 3303.5235
A17: 11 | B17: 1753.7772 | C17: 2971.218
A18: 12 | B18: 1383.6941 | C18: 2442.4122
A19: 13 | B19: 1492.2576 | C19: 2570.5248
A20: 14 | B20: 1443.0983 | C20: 2566.8154 | N20: 0
A21: 15 | B21: 1701.0724 | C21: 2822.4013 | N21: 3500
A22: 16 | B22: 1247.3844 | C22: 2088.1322

Sheet 2011 Cotton harvest
C2: Cotton in field 33 was harvested on these dates
C3: Using a 2-row picker and bagging the samples (in 2 bags) from a 50' strip.
C4: In each of the 17 borders, 40 samples were collected.
C6: Two rows on the East and 2 rows on the West were buffer rows, and not harvested.
D7: There was also a buffer area (?? ') on the North and South ends of the borders.
C9: Problems picking?
C10: Problems processing?
B12: General Plot Map for Harvesting
C13: ↑ | D13: ↓ | E13: ↑ | F13: ↓ | H13: North ↑ | J13: KRT GIS IntraPlot Numbering
C14: Buffer | D14: Buffer | E14: Buffer | F14: Buffer
C15: 40 | D15: 21 | E15: 20 | F15: 1 | J15: 20 | K15: 10
C16: 39 | D16: 22 | E16: 19 | F16: 2 | J16: 19 | K16: 9
C17: 38 | D17: 23 | E17: 18 | F17: 3 | J17: 18 | K17: 8
C18: 37 | D18: 24 | E18: 17 | F18: 4 | J18: 17 | K18: 7
C19: 36 | D19: 25 | E19: 16 | F19: 5 | J19: 16 | K19: 6
C20: 35 | D20: 26 | E20: 15 | F20: 6 | J20: 15 | K20: 5
C21: 34 | D21: 27 | E21: 14 | F21: 7 | J21: 14 | K21: 4
C22: 33 | D22: 28 | E22: 13 | F22: 8 | J22: 13 | K22: 3
C23: 32 | D23: 29 | E23: 12 | F23: 9 | J23: 12 | K23: 2
C24: 31 | D24: 30 | E24: 11 | F24: 10 | J24: 11 | K24: 1
C25: Buffer | D25: Buffer | E25: Buffer | F25: Buffer
B26: 2 row buffer | C26: 2 rows | D26: 2 rows | E26: 2 rows | F26: 2 rows | G26: 2 row buffer
C27: ←Cell width→ | E27: ←Cell width→

Sheet Field Harvest
A1: FISE Cotton 2011 -- Large Field Experiment
A3: Cotton Harvest
A4: Harvested sample weights
B5: Two bags used to collect harvested cotton for each 50' length. Bags "A" and "B" in no particular order. "A" & "B" are not from equal lenths of rows.
B6: Weight is harvested cotton in mesh bag. Using U ofA'a scale (IQ plus 390-DC is listed on digital read-out). Same scale as last time.
B8: Plots highlighted in yellow = the picker driver didn't stop between sample cells and samples are mixed (either mixed a lot, or a little)
B10: Data entered by SMM on 14 Oct
B12: Weights recorded are the harvested cotton and the large mesh bag (not tared). Weighed 2 mesh bags later - 1.06 lb & 1.10 lb
C14: Border # | D14: 1 | E14: MAC | H14: Border # | I14: 2 | J14: NDB | M14: Border # | N14: 3 | O14: FAO | R14: Border # | S14: 4 | T14: NDA | W14: Border # | X14: 5 | Y14: MAC | AB14: Border # | AC14: 6 | AD14: FAO | AG14: Border # | AH14: 7 | AI14: NDA | AL14: Border # | AM14: 8 | AN14: NDB
C15: Harvest Date: | D15: 40827 | H15: Date: | I15: 40827 | M15: Date: | N15: 40827 | R15: Date: | S15: 40827 | W15: Date: | X15: 40827 | AB15: Date: | AC15: 40828 | AG15: Date: | AH15: 40828 | AL15: Date: | AM15: 40828
B18: Samp. # | C18: Weight Bag A (lbs) | D18: Weight Bag B (lbs) | E18: Total Weight (lbs) | G18: Samp. # | H18: Weight Bag A (lbs) | I18: Weight Bag B (lbs) | J18: Total Weight (lbs) | L18: Samp. # | M18: Weight Bag A (lbs) | N18: Weight Bag B (lbs) | O18: Total Weight (lbs) | Q18: Samp. # | R18: Weight Bag A (lbs) | S18: Weight Bag B (lbs) | T18: Total Weight (lbs) | V18: Samp. # | W18: Weight Bag A (lbs) | X18: Weight Bag B (lbs) | Y18: Total Weight (lbs) | AA18: Samp. # | AB18: Weight Bag A (lbs) | AC18: Weight Bag B (lbs) | AD18: Total Weight (lbs) | AF18: Samp. # | AG18: Weight Bag A (lbs) | AH18: Weight Bag B (lbs) | AI18: Total Weight (lbs) | AK18: Samp. # | AL18: Weight Bag A (lbs) | AM18: Weight Bag B (lbs) | AN18: Total Weight (lbs)
B19: 1 | C19: 7.8 | D19: 11.2 | E19: =C19+D19 -> 19 | G19: 1 | H19: 13.7 | I19: 13 | J19: =H19+I19 -> 26.7 | L19: 1 | M19: 7.5 | N19: 10.5 | O19: =M19+N19 -> 18 | Q19: 1 | R19: 12.9 | S19: 14.1 | T19: =R19+S19 -> 27 | V19: 1 | W19: 14.3 | X19: 15.5 | Y19: =W19+X19 -> 29.8 | AA19: 1 | AB19: 16.6 | AC19: 12.4 | AD19: =AB19+AC19 -> 29 | AF19: 1 | AG19: 11.8 | AH19: 18.6 | AI19: =AG19+AH19 -> 30.4 | AK19: 1 | AL19: 12.3 | AM19: 15.8 | AN19: =AL19+AM19 -> 28.1
B20: 2 | C20: 9 | D20: 13 | E20: =C20+D20 -> 22 | G20: 2 | H20: 15.2 | I20: 16.8 | J20: =H20+I20 -> 32 | L20: 2 | M20: 13.9 | N20: 15.7 | O20: =M20+N20 -> 29.6 | Q20: 2 | R20: 17.4 | S20: 17.6 | T20: =R20+S20 -> 35 | V20: 2 | W20: 16.4 | X20: 20.9 | Y20: =W20+X20 -> 37.3 | AA20: 2 | AB20: 15.2 | AC20: 14.6 | AD20: =AB20+AC20 -> 29.8 | AF20: 2 | AG20: 14.8 | AH20: 16.3 | AI20: =AG20+AH20 -> 31.1 | AK20: 2 | AL20: 14.6 | AM20: 17.3 | AN20: =AL20+AM20 -> 31.9
B21: 3 | C21: 10.3 | D21: 12.4 | E21: =C21+D21 -> 22.7 | G21: 3 | H21: 14.9 | I21: 13.9 | J21: =H21+I21 -> 28.8 | L21: 3 | M21: 13.2 | N21: 13.4 | O21: =M21+N21 -> 26.6 | Q21: 3 | R21: 16.5 | S21: 17.2 | T21: =R21+S21 -> 33.7 | V21: 3 | W21: 16.3 | X21: 27.3 | Y21: =W21+X21 -> 43.6 | AA21: 3 | AB21: 14.5 | AC21: 17.5 | AD21: =AB21+AC21 -> 32 | AF21: 3 | AG21: 14.7 | AH21: 18.3 | AI21: =AG21+AH21 -> 33 | AK21: 3 | AL21: 14.3 | AM21: 16.3 | AN21: =AL21+AM21 -> 30.6
B22: 4 | C22: 11.4 | D22: 15.2 | E22: =C22+D22 -> 26.6 | G22: 4 | H22: 14.2 | I22: 15.3 | J22: =H22+I22 -> 29.5 | L22: 4 | M22: 13.5 | N22: 14.1 | O22: =M22+N22 -> 27.6 | Q22: 4 | R22: 17.5 | S22: 18 | T22: =R22+S22 -> 35.5 | V22: 4 | W22: 10.9 | X22: 16.7 | Y22: =W22+X22 -> 27.6 | AA22: 4 | AB22: 13.5 | AC22: 17.6 | AD22: =AB22+AC22 -> 31.1 | AF22: 4 | AG22: 18.1 | AH22: 12.5 | AI22: =AG22+AH22 -> 30.6 | AK22: 4 | AL22: 15.3 | AM22: 17.5 | AN22: =AL22+AM22 -> 32.8
B23: 5 | C23: 12.9 | D23: 12.7 | E23: =C23+D23 -> 25.6 | G23: 5 | H23: 14.8 | I23: 14.7 | J23: =H23+I23 -> 29.5 | L23: 5 | M23: 17.2 | N23: 12.4 | O23: =M23+N23 -> 29.6 | Q23: 5 | R23: 18.6 | S23: 21.2 | T23: =R23+S23 -> 39.8 | V23: 5 | W23: 18.7 | X23: 17.7 | Y23: =W23+X23 -> 36.4 | AA23: 5 | AB23: 16.2 | AC23: 19.5 | AD23: =AB23+AC23 -> 35.7 | AF23: 5 | AG23: 14.7 | AH23: 14.5 | AI23: =AG23+AH23 -> 29.2 | AK23: 5 | AL23: 15.7 | AM23: 18.1 | AN23: =AL23+AM23 -> 33.8
B24: 6 | C24: 13.5 | D24: 13.2 | E24: =C24+D24 -> 26.7 | G24: 6 | H24: 15.3 | I24: 16.7 | J24: =H24+I24 -> 32 | L24: 6 | M24: 13.9 | N24: 13.9 | O24: =M24+N24 -> 27.8 | Q24: 6 | R24: 17.9 | S24: 19.6 | T24: =R24+S24 -> 37.5 | V24: 6 | W24: 18.1 | X24: 19 | Y24: =W24+X24 -> 37.1 | AA24: 6 | AB24: 16.6 | AC24: 20.4 | AD24: =AB24+AC24 -> 37 | AF24: 6 | AG24: 13.6 | AH24: 18.3 | AI24: =AG24+AH24 -> 31.9 | AK24: 6 | AL24: 16.6 | AM24: 23.9 | AN24: =AL24+AM24 -> 40.5
B25: 7 | C25: 13.8 | D25: 13.7 | E25: =C25+D25 -> 27.5 | G25: 7 | H25: 14.4 | I25: 11.8 | J25: =H25+I25 -> 26.2 | L25: 7 | M25: 14.3 | N25: 14.4 | O25: =M25+N25 -> 28.7 | Q25: 7 | R25: 17.9 | S25: 21.7 | T25: =R25+S25 -> 39.6 | V25: 7 | W25: 15.7 | X25: 19.3 | Y25: =W25+X25 -> 35 | AA25: 7 | AB25: 16.2 | AC25: 17.9 | AD25: =AB25+AC25 -> 34.1 | AF25: 7 | AG25: 16.2 | AH25: 19.5 | AI25: =AG25+AH25 -> 35.7 | AK25: 7 | AL25: 18.6 | AM25: 19.4 | AN25: =AL25+AM25 -> 38
B26: 8 | C26: 14.4 | D26: 11.9 | E26: =C26+D26 -> 26.3 | G26: 8 | H26: 17.5 | I26: 11.4 | J26: =H26+I26 -> 28.9 | L26: 8 | M26: 14.3 | N26: 14.5 | O26: =M26+N26 -> 28.8 | Q26: 8 | R26: 18.3 | S26: 17.4 | T26: =R26+S26 -> 35.7 | V26: 8 | W26: 16.9 | X26: 17.6 | Y26: =W26+X26 -> 34.5 | AA26: 8 | AB26: 17.3 | AC26: 17.8 | AD26: =AB26+AC26 -> 35.1 | AF26: 8 | AG26: 16.2 | AH26: 18.8 | AI26: =AG26+AH26 -> 35 | AK26: 8 | AL26: 15.4 | AM26: 19.7 | AN26: =AL26+AM26 -> 35.1
B27: 9 | C27: 10.6 | D27: 10.8 | E27: =C27+D27 -> 21.4 | G27: 9 | H27: 16.6 | I27: 18.2 | J27: =H27+I27 -> 34.8 | L27: 9 | M27: 13.3 | N27: 16.9 | O27: =M27+N27 -> 30.2 | Q27: 9 | R27: 16.7 | S27: 18.5 | T27: =R27+S27 -> 35.2 | V27: 9 | W27: 17.4 | X27: 18.7 | Y27: =W27+X27 -> 36.1 | AA27: 9 | AB27: 14.3 | AC27: 17.5 | AD27: =AB27+AC27 -> 31.8 | AF27: 9 | AG27: 15 | AH27: 17.8 | AI27: =AG27+AH27 -> 32.8 | AK27: 9 | AL27: 17 | AM27: 19.8 | AN27: =AL27+AM27 -> 36.8
B28: 10 | C28: 11.7 | D28: 11.2 | E28: =C28+D28 -> 22.9 | G28: 10 | H28: 17.1 | I28: 14.2 | J28: =H28+I28 -> 31.3 | L28: 10 | M28: 12.1 | N28: 10.3 | O28: =M28+N28 -> 22.4 | Q28: 10 | R28: 14 | S28: 15.4 | T28: =R28+S28 -> 29.4 | V28: 10 | W28: 19.4 | X28: 15.8 | Y28: =W28+X28 -> 35.2 | AA28: 10 | AB28: 13.7 | AC28: 12.3 | AD28: =AB28+AC28 -> 26 | AF28: 10 | AG28: 16.6 | AH28: 16.5 | AI28: =AG28+AH28 -> 33.1 | AK28: 10 | AL28: 16.3 | AM28: 18.3 | AN28: =AL28+AM28 -> 34.6
B29: 11 | C29: 16.1 | D29: 14.1 | E29: =C29+D29 -> 30.2 | G29: 11 | H29: 20.6 | I29: 13.2 | J29: =H29+I29 -> 33.8 | L29: 11 | M29: 11.9 | N29: 17.8 | O29: =M29+N29 -> 29.7 | Q29: 11 | R29: 15.6 | S29: 18.1 | T29: =R29+S29 -> 33.7 | V29: 11 | W29: 16.8 | X29: 19.8 | Y29: =W29+X29 -> 36.6 | AA29: 11 | AB29: 11.1 | AC29: 16.5 | AD29: =AB29+AC29 -> 27.6 | AF29: 11 | AG29: 15.5 | AH29: 20.1 | AI29: =AG29+AH29 -> 35.6 | AK29: 11 | AL29: 16 | AM29: 19.7 | AN29: =AL29+AM29 -> 35.7
B30: 12 | C30: 15.1 | D30: 11.9 | E30: =C30+D30 -> 27 | G30: 12 | H30: 17.5 | I30: 20.3 | J30: =H30+I30 -> 37.8 | L30: 12 | M30: 16.9 | N30: 19 | O30: =M30+N30 -> 35.9 | Q30: 12 | R30: 17.7 | S30: 21 | T30: =R30+S30 -> 38.7 | V30: 12 | W30: 18.9 | X30: 20.3 | Y30: =W30+X30 -> 39.2 | AA30: 12 | AB30: 17.9 | AC30: 19.7 | AD30: =AB30+AC30 -> 37.6 | AF30: 12 | AG30: 16.2 | AH30: 21.2 | AI30: =AG30+AH30 -> 37.4 | AK30: 12 | AL30: 18.9 | AM30: 20 | AN30: =AL30+AM30 -> 38.9
... B58: 40 | C58: 10.7 | D58: 11.5 | E58: =C58+D58 -> 22.2 | G58: 40 | H58: 18.3 | I58: 10.3 | J58: =H58+I58 -> 28.6 | L58: 40 | M58: 10.7 | N58: 7.8 | O58: =M58+N58 -> 18.5 | Q58: 40 | R58: 12.7 | S58: 11.5 | T58: =R58+S58 -> 24.2 | V58: 40 | W58: 15.4 | X58: 15 | Y58: =W58+X58 -> 30.4 | AA58: 40 | AB58: 12.6 | AC58: 14.5 | AD58: =AB58+AC58 -> 27.1 | AF58: 40 | AG58: 16.4 | AH58: 16.2 | AI58: =AG58+AH58 -> 32.6 | AK58: 40 | AL58: 13.7 | AM58: 13 | AN58: =AL58+AM58 -> 26.7
D59: Ave wt. per 50' : | E59: =AVERAGE(E19:E58) -> 28.26 | I59: Ave wt. per 50' : | J59: =AVERAGE(J19:J58) -> 32.755 | N59: Ave wt. per 50' : | O59: =AVERAGE(O19:O58) -> 28.9975 | S59: Ave wt. per 50' : | T59: =AVERAGE(T19:T58) -> 35.5 | X59: Ave wt. per 50' : | Y59: =AVERAGE(Y19:Y58) -> 35.4775 | AC59: Ave wt. per 50' : | AD59: =AVERAGE(AD19:AD58) -> 33.4 | AH59: Ave wt. per 50' : | AI59: =AVERAGE(AI19:AI58) -> 35.2725 | AM59: Ave wt. per 50' : | AN59: =AVERAGE(AN19:AN58) -> 35.6575
A62: GIS Plot# | E62: Wt(lbs) | F62: Wt (kg) | G62: Wt (kg/ha) | J62: Wt(lbs) | K62: Wt (kg) | L62: Wt (kg/ha) | O62: Wt(lbs) | P62: Wt (kg) | Q62: Wt (kg/ha) | T62: Wt(lbs) | U62: Wt (kg) | V62: Wt (kg/ha) | Y62: Wt(lbs) | Z62: Wt (kg) | AA62: Wt (kg/ha) | AD62: Wt(lbs) | AE62: Wt (kg) | AF62: Wt (kg/ha) | AI62: Wt(lbs) | AJ62: Wt (kg) | AK62: Wt (kg/ha) | AN62: Wt(lbs) | AO62: Wt (kg) | AP62: Wt (kg/ha)
A63: 1 | E63: =SUM('Field Harvest'!E28:E29)-2*1.06-2*1.1 -> 48.78 | F63: =E63/2.2046226218 -> 22.126236 | G63: =F63/58.8*10000 -> 3762.9653 | J63: =SUM('Field Harvest'!J28:J29)-2*1.06-2*1.1 -> 60.78 | K63: =J63/2.2046226218 -> 27.569344 | L63: =K63/58.8*10000 -> 4688.664 | O63: =SUM('Field Harvest'!O28:O29)-2*1.06-2*1.1 -> 47.78 | P63: =O63/2.2046226218 -> 21.672643 | Q63: =P63/58.8*10000 -> 3685.8237 | T63: =SUM('Field Harvest'!T28:T29)-2*1.06-2*1.1 -> 58.78 | U63: =T63/2.2046226218 -> 26.66216 | V63: =U63/58.8*10000 -> 4534.3809 | Y63: =SUM('Field Harvest'!Y28:Y29)-2*1.06-2*1.1 -> 67.48 | Z63: =Y63/2.2046226218 -> 30.608413 | AA63: =Z63/58.8*10000 -> 5205.5124 | AD63: =SUM('Field Harvest'!AD28:AD29)-2*1.06-2*1.1 -> 49.28 | AE63: =AD63/2.2046226218 -> 22.353032 | AF63: =AE63/58.8*10000 -> 3801.5361 | AI63: =SUM('Field Harvest'!AI28:AI29)-2*1.06-2*1.1 -> 64.38 | AJ63: =AI63/2.2046226218 -> 29.202277 | AK63: =AJ63/58.8*10000 -> 4966.3736 | AN63: =SUM('Field Harvest'!AN28:AN29)-2*1.06-2*1.1 -> 65.98 | AO63: =AN63/2.2046226218 -> 29.928025 | AP63: =AO63/58.8*10000 -> 5089.8001
A64: 2 | E64: =SUM('Field Harvest'!E30,'Field Harvest'!E27)-2*1.06-2*1.1 -> 44.08 | F64: =E64/2.2046226218 -> 19.994352 | G64: =F64/58.8*10000 -> 3400.3999 | J64: =SUM('Field Harvest'!J30,'Field Harvest'!J27)-2*1.06-2*1.1 -> 68.28 | K64: =J64/2.2046226218 -> 30.971287 | L64: =K64/58.8*10000 -> 5267.2257 | O64: =SUM('Field Harvest'!O30,'Field Harvest'!O27)-2*1.06-2*1.1 -> 61.78 | P64: =O64/2.2046226218 -> 28.022937 | Q64: =P64/58.8*10000 -> 4765.8055 | T64: =SUM('Field Harvest'!T30,'Field Harvest'!T27)-2*1.06-2*1.1 -> 69.58 | U64: =T64/2.2046226218 -> 31.560957 | V64: =U64/58.8*10000 -> 5367.5097 | Y64: =SUM('Field Harvest'!Y30,'Field Harvest'!Y27)-2*1.06-2*1.1 -> 70.98 | Z64: =Y64/2.2046226218 -> 32.195986 | AA64: =Z64/58.8*10000 -> 5475.5079 | AD64: =SUM('Field Harvest'!AD30,'Field Harvest'!AD27)-2*1.06-2*1.1 -> 65.08 | AE64: =AD64/2.2046226218 -> 29.519791 | AF64: =AE64/58.8*10000 -> 5020.3727 | AI64: =SUM('Field Harvest'!AI30,'Field Harvest'!AI27)-2*1.06-2*1.1 -> 65.88 | AJ64: =AI64/2.2046226218 -> 29.882665 | AK64: =AJ64/58.8*10000 -> 5082.0859 | AN64: =SUM('Field Harvest'!AN30,'Field Harvest'!AN27)-2*1.06-2*1.1 -> 71.38 | AO64: =AN64/2.2046226218 -> 32.377423 | AP64: =AO64/58.8*10000 -> 5506.3645
A65: 3 | E65: =SUM(E26,E31)-2*1.06-2*1.1 -> 51.58 | F65: =E65/2.2046226218 -> 23.396294 | G65: =F65/58.8*10000 -> 3978.9616 | J65: =SUM(J26,J31)-2*1.06-2*1.1 -> 58.78 | K65: =J65/2.2046226218 -> 26.66216 | L65: =K65/58.8*10000 -> 4534.3809 | O65: =SUM(O26,O31)-2*1.06-2*1.1 -> 58.38 | P65: =O65/2.2046226218 -> 26.480723 | Q65: =P65/58.8*10000 -> 4503.5242 | T65: =SUM(T26,T31)-2*1.06-2*1.1 -> 69.38 | U65: =T65/2.2046226218 -> 31.470239 | V65: =U65/58.8*10000 -> 5352.0814 | Y65: =SUM(Y26,Y31)-2*1.06-2*1.1 -> 66.78 | Z65: =Y65/2.2046226218 -> 30.290898 | AA65: =Z65/58.8*10000 -> 5151.5133 | AD65: =SUM(AD26,AD31)-2*1.06-2*1.1 -> 69.08 | AE65: =AD65/2.2046226218 -> 31.334161 | AF65: =AE65/58.8*10000 -> 5328.9389 | AI65: =SUM(AI26,AI31)-2*1.06-2*1.1 -> 71.58 | AJ65: =AI65/2.2046226218 -> 32.468142 | AK65: =AJ65/58.8*10000 -> 5521.7928 | AN65: =SUM(AN26,AN31)-2*1.06-2*1.1 -> 70.38 | AO65: =AN65/2.2046226218 -> 31.923831 | AP65: =AO65/58.8*10000 -> 5429.223
A66: 4 | E66: =SUM(E25,E32)-2*1.06-2*1.1 -> 56.38 | F66: =E66/2.2046226218 -> 25.573538 | G66: =F66/58.8*10000 -> 4349.2411 | J66: =SUM(J25,J32)-2*1.06-2*1.1 -> 52.18 | K66: =J66/2.2046226218 -> 23.66845 | L66: =K66/58.8*10000 -> 4025.2466 | O66: =SUM(O25,O32)-2*1.06-2*1.1 -> 58.08 | P66: =O66/2.2046226218 -> 26.344645 | Q66: =P66/58.8*10000 -> 4480.3818 | T66: =SUM(T25,T32)-2*1.06-2*1.1 -> 79.08 | U66: =T66/2.2046226218 -> 35.870085 | V66: =U66/58.8*10000 -> 6100.3545 | Y66: =SUM(Y25,Y32)-2*1.06-2*1.1 -> 65.98 | Z66: =Y66/2.2046226218 -> 29.928025 | AA66: =Z66/58.8*10000 -> 5089.8001 | AD66: =SUM(AD25,AD32)-2*1.06-2*1.1 -> 67.98 | AE66: =AD66/2.2046226218 -> 30.835209 | AF66: =AE66/58.8*10000 -> 5244.0832 | AI66: =SUM(AI25,AI32)-2*1.06-2*1.1 -> 73.88 | AJ66: =AI66/2.2046226218 -> 33.511404 | AK66: =AJ66/58.8*10000 -> 5699.2184 | AN66: =SUM(AN25,AN32)-2*1.06-2*1.1 -> 74.58 | AO66: =AN66/2.2046226218 -> 33.828919 | AP66: =AO66/58.8*10000 -> 5753.2175
A67: 5 | E67: =SUM(E24,E33)-2*1.06-2*1.1 -> 54.28 | F67: =E67/2.2046226218 -> 24.620994 | G67: =F67/58.8*10000 -> 4187.2439 | J67: =SUM(J24,J33)-2*1.06-2*1.1 -> 61.88 | K67: =J67/2.2046226218 -> 28.068296 | L67: =K67/58.8*10000 -> 4773.5197 | O67: =SUM(O24,O33)-2*1.06-2*1.1 -> 51.78 | P67: =O67/2.2046226218 -> 23.487013 | Q67: =P67/58.8*10000 -> 3994.39 | T67: =SUM(T24,T33)-2*1.06-2*1.1 -> 74.08 | U67: =T67/2.2046226218 -> 33.602123 | V67: =U67/58.8*10000 -> 5714.6467 | Y67: =SUM(Y24,Y33)-2*1.06-2*1.1 -> 71.58 | Z67: =Y67/2.2046226218 -> 32.468142 | AA67: =Z67/58.8*10000 -> 5521.7928 | AD67: =SUM(AD24,AD33)-2*1.06-2*1.1 -> 72.68 | AE67: =AD67/2.2046226218 -> 32.967093 | AF67: =AE67/58.8*10000 -> 5606.6485 | AI67: =SUM(AI24,AI33)-2*1.06-2*1.1 -> 66.88 | AJ67: =AI67/2.2046226218 -> 30.336258 | AK67: =AJ67/58.8*10000 -> 5159.2275 | AN67: =SUM(AN24,AN33)-2*1.06-2*1.1 -> 77.78 | AO67: =AN67/2.2046226218 -> 35.280415 | AP67: =AO67/58.8*10000 -> 6000.0705
A68: 6 | E68: =SUM(E23,E34)-2*1.06-2*1.1 -> 51.28 | F68: =E68/2.2046226218 -> 23.260217 | G68: =F68/58.8*10000 -> 3955.8192 | J68: =SUM(J23,J34)-2*1.06-2*1.1 -> 60.78 | K68: =J68/2.2046226218 -> 27.569344 | L68: =K68/58.8*10000 -> 4688.664 | O68: =SUM(O23,O34)-2*1.06-2*1.1 -> 56.98 | P68: =O68/2.2046226218 -> 25.845693 | Q68: =P68/58.8*10000 -> 4395.5261 | T68: =SUM(T23,T34)-2*1.06-2*1.1 -> 74.98 | U68: =T68/2.2046226218 -> 34.010356 | V68: =U68/58.8*10000 -> 5784.0741 | Y68: =SUM(Y23,Y34)-2*1.06-2*1.1 -> 73.48 | Z68: =Y68/2.2046226218 -> 33.329967 | AA68: =Z68/58.8*10000 -> 5668.3618 | AD68: =SUM(AD23,AD34)-2*1.06-2*1.1 -> 71.78 | AE68: =AD68/2.2046226218 -> 32.55886 | AF68: =AE68/58.8*10000 -> 5537.2211 | AI68: =SUM(AI23,AI34)-2*1.06-2*1.1 -> 58.98 | AJ68: =AI68/2.2046226218 -> 26.752878 | AK68: =AJ68/58.8*10000 -> 4549.8092 | AN68: =SUM(AN23,AN34)-2*1.06-2*1.1 -> 66.48 | AO68: =AN68/2.2046226218 -> 30.154821 | AP68: =AO68/58.8*10000 -> 5128.3709
A69: 7 | E69: =SUM(E22,E35)-2*1.06-2*1.1 -> 56.88 | F69: =E69/2.2046226218 -> 25.800334 | G69: =F69/58.8*10000 -> 4387.8119 | J69: =SUM(J22,J35)-2*1.06-2*1.1 -> 59.58 | K69: =J69/2.2046226218 -> 27.025033 | L69: =K69/58.8*10000 -> 4596.0941 | O69: =SUM(O22,O35)-2*1.06-2*1.1 -> 55.38 | P69: =O69/2.2046226218 -> 25.119945 | Q69: =P69/58.8*10000 -> 4272.0996 | T69: =SUM(T22,T35)-2*1.06-2*1.1 -> 69.68 | U69: =T69/2.2046226218 -> 31.606316 | V69: =U69/58.8*10000 -> 5375.2239 | Y69: =SUM(Y22,Y35)-2*1.06-2*1.1 -> 61.18 | Z69: =Y69/2.2046226218 -> 27.750781 | AA69: =Z69/58.8*10000 -> 4719.5206 | AD69: =SUM(AD22,AD35)-2*1.06-2*1.1 -> 64.48 | AE69: =AD69/2.2046226218 -> 29.247636 | AF69: =AE69/58.8*10000 -> 4974.0878 | AI69: =SUM(AI22,AI35)-2*1.06-2*1.1 -> 59.48 | AJ69: =AI69/2.2046226218 -> 26.979674 | AK69: =AJ69/58.8*10000 -> 4588.38 | AN69: =SUM(AN22,AN35)-2*1.06-2*1.1 -> 64.48 | AO69: =AN69/2.2046226218 -> 29.247636 | AP69: =AO69/58.8*10000 -> 4974.0878
A70: 8 | E70: =SUM(E21,E36)-2*1.06-2*1.1 -> 48.38 | F70: =E70/2.2046226218 -> 21.944799 | G70: =F70/58.8*10000 -> 3732.1086 | J70: =SUM(J21,J36)-2*1.06-2*1.1 -> 57.98 | K70: =J70/2.2046226218 -> 26.299286 | L70: =K70/58.8*10000 -> 4472.6676 | O70: =SUM(O21,O36)-2*1.06-2*1.1 -> 50.18 | P70: =O70/2.2046226218 -> 22.761265 | Q70: =P70/58.8*10000 -> 3870.9635 | T70: =SUM(T21,T36)-2*1.06-2*1.1 -> 66.08 | U70: =T70/2.2046226218 -> 29.973384 | V70: =U70/58.8*10000 -> 5097.5143 | Y70: =SUM(Y21,Y36)-2*1.06-2*1.1 -> 73.28 | Z70: =Y70/2.2046226218 -> 33.239249 | AA70: =Z70/58.8*10000 -> 5652.9335 | AD70: =SUM(AD21,AD36)-2*1.06-2*1.1 -> 64.08 | AE70: =AD70/2.2046226218 -> 29.066199 | AF70: =AE70/58.8*10000 -> 4943.2311 | AI70: =SUM(AI21,AI36)-2*1.06-2*1.1 -> 64.28 | AJ70: =AI70/2.2046226218 -> 29.156918 | AK70: =AJ70/58.8*10000 -> 4958.6594 | AN70: =SUM(AN21,AN36)-2*1.06-2*1.1 -> 64.48 | AO70: =AN70/2.2046226218 -> 29.247636 | AP70: =AO70/58.8*10000 -> 4974.0878
A71: 9 | E71: =SUM(E20,E37)-2*1.06-2*1.1 -> 45.28 | F71: =E71/2.2046226218 -> 20.538663 | G71: =F71/58.8*10000 -> 3492.9698 | J71: =SUM(J20,J37)-2*1.06-2*1.1 -> 62.48 | K71: =J71/2.2046226218 -> 28.340451 | L71: =K71/58.8*10000 -> 4819.8046 | O71: =SUM(O20,O37)-2*1.06-2*1.1 -> 58.18 | P71: =O71/2.2046226218 -> 26.390004 | Q71: =P71/58.8*10000 -> 4488.0959 | T71: =SUM(T20,T37)-2*1.06-2*1.1 -> 65.48 | U71: =T71/2.2046226218 -> 29.701228 | V71: =U71/58.8*10000 -> 5051.2293 | Y71: =SUM(Y20,Y37)-2*1.06-2*1.1 -> 68.48 | Z71: =Y71/2.2046226218 -> 31.062005 | AA71: =Z71/58.8*10000 -> 5282.654 | AD71: =SUM(AD20,AD37)-2*1.06-2*1.1 -> 59.08 | AE71: =AD71/2.2046226218 -> 26.798237 | AF71: =AE71/58.8*10000 -> 4557.5233 | AI71: =SUM(AI20,AI37)-2*1.06-2*1.1 -> 62.78 | AJ71: =AI71/2.2046226218 -> 28.476529 | AK71: =AJ71/58.8*10000 -> 4842.9471 | AN71: =SUM(AN20,AN37)-2*1.06-2*1.1 -> 61.78 | AO71: =AN71/2.2046226218 -> 28.022937 | AP71: =AO71/58.8*10000 -> 4765.8055
A72: 10 | E72: =SUM(E19,E38)-2*1.06-2*1.1 -> 41.58 | F72: =E72/2.2046226218 -> 18.860371 | G72: =F72/58.8*10000 -> 3207.546 | J72: =SUM(J19,J38)-2*1.06-2*1.1 -> 52.28 | K72: =J72/2.2046226218 -> 23.713809 | L72: =K72/58.8*10000 -> 4032.9607 | O72: =SUM(O19,O38)-2*1.06-2*1.1 -> 34.48 | P72: =O72/2.2046226218 -> 15.639865 | Q72: =P72/58.8*10000 -> 2659.841 | T72: =SUM(T19,T38)-2*1.06-2*1.1 -> 51.08 | U72: =T72/2.2046226218 -> 23.169498 | V72: =U72/58.8*10000 -> 3940.3909 | Y72: =SUM(Y19,Y38)-2*1.06-2*1.1 -> 57.98 | Z72: =Y72/2.2046226218 -> 26.299286 | AA72: =Z72/58.8*10000 -> 4472.6676 | AD72: =SUM(AD19,AD38)-2*1.06-2*1.1 -> 57.48 | AE72: =AD72/2.2046226218 -> 26.072489 | AF72: =AE72/58.8*10000 -> 4434.0968 | AI72: =SUM(AI19,AI38)-2*1.06-2*1.1 -> 59.98 | AJ72: =AI72/2.2046226218 -> 27.20647 | AK72: =AJ72/58.8*10000 -> 4626.9507 | AN72: =SUM(AN19,AN38)-2*1.06-2*1.1 -> 54.08 | AO72: =AN72/2.2046226218 -> 24.530275 | AP72: =AO72/58.8*10000 -> 4171.8155
A73: 11 | E73: =SUM(E48:E49)-2*1.06-2*1.1 -> 51.58 | F73: =E73/2.2046226218 -> 23.396294 | G73: =F73/58.8*10000 -> 3978.9616 | J73: =SUM(J48:J49)-2*1.06-2*1.1 -> 65.78 | K73: =J73/2.2046226218 -> 29.837306 | L73: =K73/58.8*10000 -> 5074.3718 | O73: =SUM(O48:O49)-2*1.06-2*1.1 -> 50.08 | P73: =O73/2.2046226218 -> 22.715906 | Q73: =P73/58.8*10000 -> 3863.2493 | T73: =SUM(T48:T49)-2*1.06-2*1.1 -> 58.48 | U73: =T73/2.2046226218 -> 26.526082 | V73: =U73/58.8*10000 -> 4511.2384 | Y73: =SUM(Y48:Y49)-2*1.06-2*1.1 -> 64.28 | Z73: =Y73/2.2046226218 -> 29.156918 | AA73: =Z73/58.8*10000 -> 4958.6594 | AD73: =SUM(AD48:AD49)-2*1.06-2*1.1 -> 49.08 | AE73: =AD73/2.2046226218 -> 22.262314 | AF73: =AE73/58.8*10000 -> 3786.1077 | AI73: =SUM(AI48:AI49)-2*1.06-2*1.1 -> 63.78 | AJ73: =AI73/2.2046226218 -> 28.930121 | AK73: =AJ73/58.8*10000 -> 4920.0887 | AN73: =SUM(AN48:AN49)-2*1.06-2*1.1 -> 67.28 | AO73: =AN73/2.2046226218 -> 30.517695 | AP73: =AO73/58.8*10000 -> 5190.0841
A74: 12 | E74: =SUM(E47,E50)-2*1.06-2*1.1 -> 53.78 | F74: =E74/2.2046226218 -> 24.394198 | G74: =F74/58.8*10000 -> 4148.6731 | J74: =SUM(J47,J50)-2*1.06-2*1.1 -> 67.88 | K74: =J74/2.2046226218 -> 30.78985 | L74: =K74/58.8*10000 -> 5236.3691 | O74: =SUM(O47,O50)-2*1.06-2*1.1 -> 59.98 | P74: =O74/2.2046226218 -> 27.20647 | Q74: =P74/58.8*10000 -> 4626.9507 | T74: =SUM(T47,T50)-2*1.06-2*1.1 -> 67.48 | U74: =T74/2.2046226218 -> 30.608413 | V74: =U74/58.8*10000 -> 5205.5124 | Y74: =SUM(Y47,Y50)-2*1.06-2*1.1 -> 66.98 | Z74: =Y74/2.2046226218 -> 30.381617 | AA74: =Z74/58.8*10000 -> 5166.9417 | AD74: =SUM(AD47,AD50)-2*1.06-2*1.1 -> 59.98 | AE74: =AD74/2.2046226218 -> 27.20647 | AF74: =AE74/58.8*10000 -> 4626.9507 | AI74: =SUM(AI47,AI50)-2*1.06-2*1.1 -> 68.98 | AJ74: =AI74/2.2046226218 -> 31.288802 | AK74: =AJ74/58.8*10000 -> 5321.2248 | AN74: =SUM(AN47,AN50)-2*1.06-2*1.1 -> 64.28 | AO74: =AN74/2.2046226218 -> 29.156918 | AP74: =AO74/58.8*10000 -> 4958.6594
A75: 13 | E75: =SUM(E46,E51)-2*1.06-2*1.1 -> 48.08 | F75: =E75/2.2046226218 -> 21.808721 | G75: =F75/58.8*10000 -> 3708.9662 | J75: =SUM(J46,J51)-2*1.06-2*1.1 -> 62.38 | K75: =J75/2.2046226218 -> 28.295092 | L75: =K75/58.8*10000 -> 4812.0905 | O75: =SUM(O46,O51)-2*1.06-2*1.1 -> 59.68 | P75: =O75/2.2046226218 -> 27.070393 | Q75: =P75/58.8*10000 -> 4603.8083 | T75: =SUM(T46,T51)-2*1.06-2*1.1 -> 69.88 | U75: =T75/2.2046226218 -> 31.697035 | V75: =U75/58.8*10000 -> 5390.6522 | Y75: =SUM(Y46,Y51)-2*1.06-2*1.1 -> 65.58 | Z75: =Y75/2.2046226218 -> 29.746588 | AA75: =Z75/58.8*10000 -> 5058.9435 | AD75: =SUM(AD46,AD51)-2*1.06-2*1.1 -> 68.88 | AE75: =AD75/2.2046226218 -> 31.243442 | AF75: =AE75/58.8*10000 -> 5313.5106 | AI75: =SUM(AI46,AI51)-2*1.06-2*1.1 -> 73.88 | AJ75: =AI75/2.2046226218 -> 33.511404 | AK75: =AJ75/58.8*10000 -> 5699.2184 | AN75: =SUM(AN46,AN51)-2*1.06-2*1.1 -> 64.28 | AO75: =AN75/2.2046226218 -> 29.156918 | AP75: =AO75/58.8*10000 -> 4958.6594
A76: 14 | E76: =SUM(E45,E52)-2*1.06-2*1.1 -> 62.68 | F76: =E76/2.2046226218 -> 28.43117 | G76: =F76/58.8*10000 -> 4835.233 | J76: =SUM(J45,J52)-2*1.06-2*1.1 -> 61.08 | K76: =J76/2.2046226218 -> 27.705422 | L76: =K76/58.8*10000 -> 4711.8065 | O76: =SUM(O45,O52)-2*1.06-2*1.1 -> 62.98 | P76: =O76/2.2046226218 -> 28.567247 | Q76: =P76/58.8*10000 -> 4858.3754 | T76: =SUM(T45,T52)-2*1.06-2*1.1 -> 77.38 | U76: =T76/2.2046226218 -> 35.098978 | V76: =U76/58.8*10000 -> 5969.2139 | Y76: =SUM(Y45,Y52)-2*1.06-2*1.1 -> 65.68 | Z76: =Y76/2.2046226218 -> 29.791947 | AA76: =Z76/58.8*10000 -> 5066.6576 | AD76: =SUM(AD45,AD52)-2*1.06-2*1.1 -> 63.88 | AE76: =AD76/2.2046226218 -> 28.975481 | AF76: =AE76/58.8*10000 -> 4927.8028 | AI76: =SUM(AI45,AI52)-2*1.06-2*1.1 -> 75.78 | AJ76: =AI76/2.2046226218 -> 34.37323 | AK76: =AJ76/58.8*10000 -> 5845.7874 | AN76: =SUM(AN45,AN52)-2*1.06-2*1.1 -> 76.48 | AO76: =AN76/2.2046226218 -> 34.690744 | AP76: =AO76/58.8*10000 -> 5899.7865
...

Sheet Subsample weights
B1: FISE Cotton 2011 -- Large Field Experiment | K1: FISE Cotton 2011 -- Large Field Experiment | T1: FISE Cotton 2011 -- Large Field Experiment | AC1: FISE Cotton 2011 -- Large Field Experiment | AL1: FISE Cotton 2011 -- Large Field Experiment | AU1: FISE Cotton 2011 -- Large Field Experiment
B3: Cotton Harvest | K3: Cotton Harvest | T3: Cotton Harvest | AC3: Cotton Harvest | AL3: Cotton Harvest | AU3: Cotton Harvest
B4: Subsample weights | K4: Subsample weights | T4: Subsample weights | AC4: Subsample weights | AL4: Subsample weights | AU4: Subsample weights
B5: Weights are weights of bag and cotton. Weight of bag & 4 staples alone is 0.16 lb
B7: Border # | C7: 1 | E7: Border # | F7: 2 | H7: Border # | I7: 3 | K7: Border # | L7: 4 | N7: Border # | O7: 5 | Q7: Border # | R7: 6 | T7: Border # | U7: 7 | W7: Border # | X7: 8 | Z7: Border # | AA7: 9 | AC7: Border # | AD7: 10 | AF7: Border # | AG7: 11 | AI7: Border # | AJ7: 12 | AL7: Border # | AM7: 13 | AO7: Border # | AP7: 14 | AR7: Border # | AS7: 15 | AU7: Border # | AV7: 16 | AX7: Border # | AY7: 17
B9: Samp. # | C9: Bag & cotton (lbs) | E9: Samp. # | F9: Bag & cotton (lbs) | H9: Samp. # | I9: Bag & cotton (lbs) | K9: Samp. # | L9: Bag & cotton (lbs) | N9: Samp. # | O9: Bag & cotton (lbs) | Q9: Samp. # | R9: Bag & cotton (lbs) | T9: Samp. # | U9: Bag & cotton (lbs) | W9: Samp. # | X9: Bag & cotton (lbs) | Z9: Samp. # | AA9: Bag & cotton (lbs) | AC9: Samp. # | AD9: Bag & cotton (lbs) | AF9: Samp. # | AG9: Bag & cotton (lbs) | AI9: Samp. # | AJ9: Bag & cotton (lbs) | AL9: Samp. # | AM9: Bag & cotton (lbs) | AO9: Samp. # | AP9: Bag & cotton (lbs) | AR9: Samp. # | AS9: Bag & cotton (lbs) | AU9: Samp. # | AV9: Bag & cotton (lbs) | AX9: Samp. # | AY9: Bag & cotton (lbs)
B10: 1 | C10: 3.02 | E10: 1 | F10: 3.36 | H10: 1 | I10: 2.7 | K10: 1 | L10: 2.76 | N10: 1 | O10: 3.12 | Q10: 1 | R10: 4.32 | T10: 1 | U10: 3.36 | W10: 1 | X10: 3.04 | Z10: 1 | AA10: 3.5 | AC10: 1 | AD10: 3.04 | AF10: 1 | AG10: 3.22 | AI10: 1 | AJ10: 3.62 | AL10: 1 | AM10: 3.48 | AO10: 1 | AP10: 2.5 | AR10: 1 | AS10: 3.92 | AU10: 1 | AV10: 3.8 | AX10: 1 | AY10: 3.98
B11: 2 | C11: 3.28 | E11: 2 | F11: 3.32 | H11: 2 | I11: 3.34 | K11: 2 | L11: 3.34 | N11: 2 | O11: 2.54 | Q11: 2 | R11: 3.06 | T11: 2 | U11: 2.48 | W11: 2 | X11: 3.72 | Z11: 2 | AA11: 4.02 | AC11: 2 | AD11: 2.72 | AF11: 2 | AG11: 3.1 | AI11: 2 | AJ11: 3.46 | AL11: 2 | AM11: 3.22 | AO11: 2 | AP11: 3.26 | AR11: 2 | AS11: 1.74 | AU11: 2 | AV11: 3.52 | AX11: 2 | AY11: 4.34
B12: 3 | C12: 3.26 | E12: 3 | F12: 3.2 | H12: 3 | I12: 3.3 | K12: 3 | L12: 3.56 | N12: 3 | O12: 3.54 | Q12: 3 | R12: 2.92 | T12: 3 | U12: 3.14 | W12: 3 | X12: 3.64 | Z12: 3 | AA12: 2.98 | AC12: 3 | AD12: 2.66 | AF12: 3 | AG12: 4.16 | AI12: 3 | AJ12: 3.42 | AL12: 3 | AM12: 3.46 | AO12: 3 | AP12: 4.22 | AR12: 3 | AS12: 4.24 | AU12: 3 | AV12: 3.9 | AX12: 3 | AY12: 4.48
B13: 4 | C13: 3.02 | E13: 4 | F13: 3.42 | H13: 4 | I13: 3.46 | K13: 4 | L13: 3.82 | N13: 4 | O13: 3.16 | Q13: 4 | R13: 3.3 | T13: 4 | U13: 2.68 | W13: 4 | X13: 3.5 | Z13: 4 | AA13: 3.72 | AC13: 4 | AD13: 2.84 | AF13: 4 | AG13: 3.14 | AI13: 4 | AJ13: 3.34 | AL13: 4 | AM13: 4.02 | AO13: 4 | AP13: 4.4 | AR13: 4 | AS13: 5.08 | AU13: 4 | AV13: 3.92 | AX13: 4 | AY13: 3.24
B14: 5 | C14: 3.3 | E14: 5 | F14: 3.58 | H14: 5 | I14: 3.26 | K14: 5 | L14: 3.28 | N14: 5 | O14: 2.96 | Q14: 5 | R14: 3 | T14: 5 | U14: 2.38 | W14: 5 | X14: 3.3 | Z14: 5 | AA14: 2.66 | AC14: 5 | AD14: 3.2 | AF14: 5 | AG14: 4.34 | AI14: 5 | AJ14: 2.66 | AL14: 5 | AM14: 2.86 | AO14: 5 | AP14: 3.92 | AR14: 5 | AS14: 3.58 | AU14: 5 | AV14: 3.94 | AX14: 5 | AY14: 3.2
B15: 6 | C15: 3.38 | E15: 6 | F15: 3.28 | H15: 6 | I15: 3.56 | K15: 6 | L15: 3.08 | N15: 6 | O15: 2.88 | Q15: 6 | R15: 2.9 | T15: 6 | U15: 3.46 | W15: 6 | X15: 3.12 | Z15: 6 | AA15: 3.08 | AC15: 6 | AD15: 2.54 | AF15: 6 | AG15: 3.74 | AI15: 6 | AJ15: 3.76 | AL15: 6 | AM15: 4.32 | AO15: 6 | AP15: 3.08 | AR15: 6 | AS15: 3.58 | AU15: 6 | AV15: 3.9 | AX15: 6 | AY15: 2.98
B16: 7 | C16: 3.18 | E16: 7 | F16: 3.14 | H16: 7 | I16: 2.96 | K16: 7 | L16: 2.72 | N16: 7 | O16: 2.6 | Q16: 7 | R16: 3.22 | T16: 7 | U16: 2.52 | W16: 7 | X16: 3.52 | Z16: 7 | AA16: 3.04 | AC16: 7 | AD16: 3.4 | AF16: 7 | AG16: 3.66 | AI16: 7 | AJ16: 2.86 | AL16: 7 | AM16: 3.58 | AO16: 7 | AP16: 3.6 | AR16: 7 | AS16: 3.5 | AU16: 7 | AV16: 3.82 | AX16: 7 | AY16: 3.82
B17: 8 | C17: 2.9 | E17: 8 | F17: 3.6 | H17: 8 | I17: 2.92 | K17: 8 | L17: 2.62 | N17: 8 | O17: 2.44 | Q17: 8 | R17: 3.04 | T17: 8 | U17: 2.44 | W17: 8 | X17: 2.76 | Z17: 8 | AA17: 2.9 | AC17: 8 | AD17: 3.02 | AF17: 8 | AG17: 3.26 | AI17: 8 | AJ17: 4.02 | AL17: 8 | AM17: 3.7 | AO17: 8 | AP17: 3.36 | AR17: 8 | AS17: 4.34 | AU17: 8 | AV17: 4.08 | AX17: 8 | AY17: 3.36
B18: 9 | C18: 2.86 | E18: 9 | F18: 3.62 | H18: 9 | I18: 3.2 | K18: 9 | L18: 2.64 | N18: 9 | O18: 2.88 | Q18: 9 | R18: 4.2 | T18: 9 | U18: 3.52 | W18: 9 | X18: 3.74 | Z18: 9 | AA18: 2.76 | AC18: 9 | AD18: 3.18 | AF18: 9 | AG18: 3.52 | AI18: 9 | AJ18: 2.9 | AL18: 9 | AM18: 3.74 | AO18: 9 | AP18: 3.84 | AR18: 9 | AS18: 4.9 | AU18: 9 | AV18: 3.94 | AX18: 9 | AY18: 3.94
B19: 10 | C19: 3.68 | E19: 10 | F19: 3.94 | H19: 10 | I19: 3.56 | K19: 10 | L19: 3.46 | N19: 10 | O19: 2.68 | Q19: 10 | R19: 3.7 | T19: 10 | U19: 3.92 | W19: 10 | X19: 3.84 | Z19: 10 | AA19: 3.26 | AC19: 10 | AD19: 3.12 | AF19: 10 | AG19: 4.14 | AI19: 10 | AJ19: 3.84 | AL19: 10 | AM19: 3.58 | AO19: 10 | AP19: 2.9 | AR19: 10 | AS19: 4.5 | AU19: 10 | AV19: 3.7 | AX19: 10 | AY19: 3.98
B20: 11 | C20: 2.94 | E20: 11 | F20: 3.94 | H20: 11 | I20: 3.24 | K20: 11 | L20: 2.82 | N20: 11 | O20: 3.08 | Q20: 11 | R20: 4.16 | T20: 11 | U20: 3.74 | W20: 11 | X20: 3.8 | Z20: 11 | AA20: 3 | AC20: 11 | AD20: 3.4 | AF20: 11 | AG20: 3.18 | AI20: 11 | AJ20: 3.54 | AL20: 11 | AM20: 3.56 | AO20: 11 | AP20: 3.62 | AR20: 11 | AS20: 4.24 | AU20: 11 | AV20: 3.4 | AX20: 11 | AY20: 3.5
B21: 12 | C21: 3.12 | E21: 12 | F21: 3.66 | H21: 12 | I21: 3.22 | K21: 12 | L21: 3.06 | N21: 12 | O21: 2.7 | Q21: 12 | R21: 3.5 | T21: 12 | U21: 3.64 | W21: 12 | X21: 3.82 | Z21: 12 | AA21: 3.16 | AC21: 12 | AD21: 3.08 | AF21: 12 | AG21: 3.6 | AI21: 12 | AJ21: 2.74 | AL21: 12 | AM21: 3.58 | AO21: 12 | AP21: 4.22 | AR21: 12 | AS21: 3.82 | AU21: 12 | AV21: 3.78 | AX21: 12 | AY21: 2.8
... B30: 21 | C30: 3.66 | E30: 21 | F30: 3.66 | H30: 21 | I30: 2.72 | K30: 21 | L30: 2.9 | N30: 21 | O30: 2.48 | Q30: 21 | R30: 3.46 | T30: 21 | U30: 2.84 | W30: 21 | X30: 3.32 | Z30: 21 | AA30: 2.62 | AC30: 21 | AD30: 3.34 | AF30: 21 | AG30: 3.68 | AI30: 21 | AJ30: 3.54 | AL30: 21 | AM30: 4.24 | AO30: 21 | AP30: 4.7 | AR30: 21 | AS30: 3.76 | AU30: 21 | AV30: 3.8 | AX30: 21 | AY30: 3.3
B31: 22 | C31: 3.48 | E31: 22 | F31: 3.94 | H31: 22 | I31: 3.24 | K31: 22 | L31: 3.24 | N31: 22 | O31: 2.72 | Q31: 22 | R31: 3.68 | T31: 22 | U31: 3.52 | W31: 22 | X31: 3.26 | Z31: 22 | AA31: 2.42 | AC31: 22 | AD31: 3.54 | AF31: 22 | AG31: 3 | AI31: 22 | AJ31: 3.74 | AL31: 22 | AM31: 3.38 | AO31: 22 | AQ31: oops- no sample collected | AR31: 22 | AS31: 3.36 | AU31: 22 | AV31: 3.74 | AX31: 22 | AY31: 2.86
B32: 23 | C32: 2.88 | E32: 23 | F32: 4.48 | H32: 23 | I32: 3.18 | K32: 23 | L32: 2.52 | N32: 23 | O32: 2.6 | Q32: 23 | R32: 2.82 | T32: 23 | U32: 3.56 | W32: 23 | X32: 2.4 | Z32: 23 | AA32: 2.5 | AC32: 23 | AD32: 2.84 | AF32: 23 | AG32: 3.9 | AI32: 23 | AJ32: 4.26 | AL32: 23 | AM32: 4.02 | AO32: 23 | AP32: 3.22 | AR32: 23 | AS32: 3.42 | AU32: 23 | AV32: 3.6 | AX32: 23 | AY32: 3.48
B33: 24 | C33: 2.58 | E33: 24 | F33: 3.7 | H33: 24 | I33: 3.24 | K33: 24 | L33: 3.28 | N33: 24 | O33: 2.32 | Q33: 24 | R33: 3.34 | T33: 24 | U33: 2.8 | W33: 24 | X33: 3.38 | Z33: 24 | AA33: 3.56 | AC33: 24 | AD33: 4.06 | AF33: 24 | AG33: 3.5 | AI33: 24 | AJ33: 2.74 | AL33: 24 | AM33: 4.18 | AO33: 24 | AP33: 3.1 | AR33: 24 | AS33: 4.26 | AU33: 24 | AV33: 3.9 | AX33: 24 | AY33: 2.92
B34: 25 | C34: 3.5 | E34: 25 | F34: 3.76 | H34: 25 | I34: 3.66 | K34: 25 | L34: 3.1 | N34: 25 | O34: 2.52 | Q34: 25 | R34: 3.64 | T34: 25 | U34: 3.02 | W34: 25 | X34: 3.48 | Z34: 25 | AA34: 3.38 | AC34: 25 | AD34: 3.64 | AF34: 25 | AG34: 3.5 | AI34: 25 | AJ34: 3.8 | AL34: 25 | AM34: 3.14 | AO34: 25 | AP34: 3.46 | AR34: 25 | AS34: 3.88 | AU34: 25 | AV34: 3.9 | AX34: 25 | AY34: 3.68
B35: 26 | C35: 3.48 | E35: 26 | F35: 2.9 | H35: 26 | I35: 3.16 | K35: 26 | L35: 2.94 | N35: 26 | O35: 2.58 | Q35: 26 | R35: 2.88 | T35: 26 | U35: 3.16 | W35: 26 | X35: 2.84 | Z35: 26 | AA35: 2.42 | AC35: 26 | AD35: 4.02 | AF35: 26 | AG35: 3.18 | AI35: 26 | AJ35: 4.42 | AL35: 26 | AM35: 3.92 | AO35: 26 | AP35: 2.84 | AR35: 26 | AS35: 4.28 | AU35: 26 | AV35: 3.24 | AX35: 26 | AY35: 3.68
B36: 27 | C36: 3.36 | E36: 27 | F36: 4.1 | H36: 27 | I36: 3.18 | K36: 27 | L36: 3.14 | N36: 27 | O36: 2.44 | Q36: 27 | R36: 2.84 | T36: 27 | U36: 3.88 | W36: 27 | X36: 3.26 | Z36: 27 | AA36: 2.72 | AC36: 27 | AD36: 3.38 | AF36: 27 | AG36: 3.46 | AI36: 27 | AJ36: 3.66 | AL36: 27 | AM36: 3.5 | AO36: 27 | AP36: 3.94 | AR36: 27 | AS36: 3.72 | AU36: 27 | AV36: 2.8 | AX36: 27 | AY36: 4.12
B37: 28 | C37: 2.92 | E37: 28 | F37: 3.48 | H37: 28 | I37: 2.76 | K37: 28 | L37: 3.34 | N37: 28 | O37: 2.72 | Q37: 28 | R37: 3.34 | T37: 28 | U37: 2.92 | W37: 28 | X37: 3.44 | Z37: 28 | AA37: 1.98 | AC37: 28 | AD37: 3.48 | AF37: 28 | AG37: 4.44 | AI37: 28 | AJ37: 3.46 | AL37: 28 | AM37: 3.5 | AO37: 28 | AP37: 3.64 | AR37: 28 | AS37: 3.82 | AU37: 28 | AV37: 3.64 | AX37: 28 | AY37: 3.68
B38: 29 | C38: 3.4 | E38: 29 | F38: 3.62 | H38: 29 | I38: 3.4 | K38: 29 | L38: 3.1 | N38: 29 | O38: 2.24 | Q38: 29 | R38: 3.08 | T38: 29 | U38: 3.48 | W38: 29 | X38: 3.04 | Z38: 29 | AA38: 2.32 | AC38: 29 | AD38: 3.62 | AF38: 29 | AG38: 2.88 | AI38: 29 | AJ38: 3.8 | AL38: 29 | AM38: 2.86 | AO38: 29 | AP38: 3.7 | AR38: 29 | AS38: 3.66 | AU38: 29 | AV38: 2.6 | AX38: 29 | AY38: 3.14
B39: 30 | C39: 3.02 | E39: 30 | F39: 3.84 | H39: 30 | I39: 3.36 | K39: 30 | L39: 3 | N39: 30 | O39: 2.48 | Q39: 30 | R39: 3.6 | T39: 30 | U39: 3.56 | W39: 30 | X39: 2.64 | Z39: 30 | AA39: 3.32 | AC39: 30 | AD39: 3.56 | AF39: 30 | AG39: 3.24 | AI39: 30 | AJ39: 3.08 | AL39: 30 | AM39: 4.38 | AO39: 30 | AP39: 2.96 | AR39: 30 | AS39: 3.54 | AU39: 30 | AV39: 4.24 | AX39: 30 | AY39: 3.82
B40: 31 | C40: 3.3 | E40: 31 | F40: 3.48 | H40: 31 | I40: 3.38 | K40: 31 | L40: 3.02 | N40: 31 | O40: 3.72 | Q40: 31 | R40: 2.94 | T40: 31 | U40: 3.52 | W40: 31 | X40: 3.42 | Z40: 31 | AA40: 3.16 | AC40: 31 | AD40: 3.5 | AF40: 31 | AG40: 3.12 | AI40: 31 | AJ40: 3.02 | AL40: 31 | AM40: 3.12 | AO40: 31 | AP40: 3.84 | AR40: 31 | AS40: 4.12 | AU40: 31 | AV40: 3.44 | AX40: 31 | AY40: 3.74
B41: 32 | C41: 3.42 | E41: 32 | F41: 2.9 | H41: 32 | I41: 3.14 | K41: 32 | L41: 2.8 | N41: 32 | O41: 3.26 | Q41: 32 | R41: 3.64 | T41: 32 | U41: 3.28 | W41: 32 | X41: 2.88 | Z41: 32 | AA41: 3.66 | AC41: 32 | AD41: 4.36 | AF41: 32 | AG41: 3.14 | AI41: 32 | AJ41: 4.14 | AL41: 32 | AM41: 4 | AO41: 32 | AP41: 2.6 | AR41: 32 | AS41: 2.7 | AU41: 32 | AV41: 2.6 | AX41: 32 | AY41: 3.28
B42: 33 | C42: 3.34 | E42: 33 | F42: 3.38 | H42: 33 | I42: 3.06 | K42: 33 | L42: 2.58 | N42: 33 | O42: 3 | Q42: 33 | R42: 3.1 | T42: 33 | U42: 3.08 | W42: 33 | X42: 2.6 | Z42: 33 | AA42: 2.52 | AC42: 33 | AD42: 4.04 | AF42: 33 | AG42: 4.06 | AI42: 33 | AJ42: 3.5 | AL42: 33 | AM42: 3.86 | AO42: 33 | AP42: 2.86 | AR42: 33 | AS42: 3.06 | AU42: 33 | AV42: 3.92 | AX42: 33 | AY42: 4.04
B43: 34 | C43: 2.94 | E43: 34 | F43: 3.18 | H43: 34 | I43: 3.98 | K43: 34 | L43: 2.96 | N43: 34 | O43: 2.8 | Q43: 34 | R43: 3.38 | T43: 34 | U43: 3.06 | W43: 34 | X43: 2.36 | Z43: 34 | AA43: 2.32 | AC43: 34 | AD43: 3.04 | AF43: 34 | AG43: 3.44 | AI43: 34 | AJ43: 3.58 | AL43: 34 | AM43: 3.4 | AO43: 34 | AP43: 3.7 | AR43: 34 | AS43: 4.08 | AU43: 34 | AV43: 2.76 | AX43: 34 | AY43: 3.22
... B49: 40 | C49: 3.32 | E49: 40 | F49: 3.42 | H49: 40 | I49: 3.66 | K49: 40 | L49: 3.42 | N49: 40 | O49: 2.9 | Q49: 40 | R49: 2.88 | T49: 40 | U49: 3.6 | W49: 40 | X49: 2.86 | Z49: 40 | AA49: 2.36 | AC49: 40 | AD49: 3.5 | AF49: 40 | AG49: 4.38 | AI49: 40 | AJ49: 3.72 | AL49: 40 | AM49: 3.76 | AO49: 40 | AP49: 3.94 | AR49: 40 | AS49: 3.98 | AU49: 40 | AV49: 2.5 | AX49: 40 | AY49: 3.18
B51: Cell # | C51: Total raw cotton/cell (lb) | E51: Cell # | F51: Total raw cotton/cell (lb) | H51: Cell # | I51: Total raw cotton/cell (lb) | K51: Cell # | L51: Total raw cotton/cell (lb) | N51: Cell # | O51: Total raw cotton/cell (lb) | Q51: Cell # | R51: Total raw cotton/cell (lb) | T51: Cell # | U51: Total raw cotton/cell (lb) | W51: Cell # | X51: Total raw cotton/cell (lb) | Z51: Cell # | AA51: Total raw cotton/cell (lb) | AC51: Cell # | AD51: Total raw cotton/cell (lb) | AF51: Cell # | AG51: Total raw cotton/cell (lb) | AI51: Cell # | AJ51: Total raw cotton/cell (lb) | AL51: Cell # | AM51: Total raw cotton/cell (lb) | AO51: Cell # | AP51: Total raw cotton/cell (lb) | AR51: Cell # | AS51: Total raw cotton/cell (lb) | AU51: Cell # | AV51: Total raw cotton/cell (lb) | AX51: Cell # | AY51: Total raw cotton/cell (lb)
