Workbook

Sheet Height
A1: CCID | B1: DOY156 | C1: DOY163 | D1: DOY171 | E1: DOY177 | F1: DOY184 | G1: DOY194 | H1: DOY201 | I1: DOY208 | J1: DOY215 | K1: DOY236
A2: p01-01 | B2: 13 | C2: 20 | D2: 28 | E2: 42 | F2: 55 | G2: 65 | H2: 76 | I2: 85 | J2: 98 | K2: 102
A3: p01-02 | B3: 15 | C3: 22 | D3: 32 | E3: 53 | F3: 77 | G3: 89 | H3: 100 | I3: 115 | J3: 125 | K3: 129
A4: p01-03 | B4: 13 | C4: 21 | D4: 31 | E4: 51 | F4: 74 | G4: 84 | H4: 92 | I4: 101 | J4: 112 | K4: 117
A5: p01-04 | B5: 9 | C5: 15 | D5: 25 | E5: 50 | F5: 77 | G5: 88 | H5: 99 | I5: 110 | J5: 122 | K5: 127
A6: p01-05 | B6: 9 | C6: 16 | D6: 26 | E6: 43 | F6: 66 | G6: 77 | H6: 89 | I6: 102 | J6: 113 | K6: 119
A7: p01-06 | B7: 12 | C7: 20 | D7: 29 | E7: 45 | F7: 67 | G7: 86 | H7: 107 | I7: 134 | J7: 148 | K7: 154
A8: p01-07 | B8: 10 | C8: 18 | D8: 28 | E8: 40 | F8: 58 | G8: 67 | H8: 76 | I8: 85 | J8: 100 | K8: 98
A9: p01-08 | B9: 20 | C9: 26 | D9: 35 | E9: 54 | F9: 80 | G9: 93 | H9: 105 | I9: 115 | J9: 131 | K9: 138
A10: p01-09 | B10: 18 | C10: 24 | D10: 32 | E10: 53 | F10: 80 | G10: 90 | H10: 97 | I10: 107 | J10: 118 | K10: 121
A11: p01-10 | B11: 13 | C11: 20 | D11: 29 | E11: 51 | F11: 81 | G11: 90 | H11: 98 | I11: 108 | J11: 117 | K11: 122
A12: p01-11 | B12: 15 | C12: 21 | D12: 30 | E12: 50 | F12: 64 | G12: 76 | H12: 88 | I12: 101 | J12: 116 | K12: 123
A13: p01-12 | B13: 14 | C13: 20 | D13: 29 | E13: 52 | F13: 67 | G13: 77 | H13: 86 | I13: 95 | J13: 107 | K13: 113
... A181: p12-15 | B181: 9 | C181: 16 | D181: 26 | E181: 49 | F181: 67 | G181: 76 | H181: 86 | I181: 96 | J181: 107 | K181: 110

Sheet Width
A1: CCID | B1: DOY156 | C1: DOY163 | D1: DOY171 | E1: DOY177 | F1: DOY184 | G1: DOY194 | H1: DOY201 | I1: DOY208 | J1: DOY215 | K1: DOY236
A2: p01-01 | B2: 13 | C2: 21 | D2: 26 | E2: 40 | F2: 55 | G2: 90 | H2: 72 | I2: 84 | J2: 85 | K2: 89
A3: p01-02 | B3: 15 | C3: 22 | D3: 28 | E3: 54 | F3: 73 | G3: 85 | H3: 96 | I3: 102 | J3: 102 | K3: 102
A4: p01-03 | B4: 14 | C4: 22 | D4: 31 | E4: 50 | F4: 71 | G4: 81 | H4: 89 | I4: 87 | J4: 102 | K4: 102
A5: p01-04 | B5: 10 | C5: 20 | D5: 34 | E5: 52 | F5: 77 | G5: 84 | H5: 94 | I5: 102 | J5: 102 | K5: 102
A6: p01-05 | B6: 12 | C6: 19 | D6: 28 | E6: 47 | F6: 67 | G6: 75 | H6: 83 | I6: 96 | J6: 102 | K6: 102
A7: p01-06 | B7: 13 | C7: 19 | D7: 26 | E7: 42 | F7: 61 | G7: 83 | H7: 95 | I7: 102 | J7: 102 | K7: 102
A8: p01-07 | B8: 12 | C8: 20 | D8: 27 | E8: 53 | F8: 61 | G8: 66 | H8: 73 | I8: 83 | J8: 84 | K8: 87
A9: p01-08 | B9: 19 | C9: 25 | D9: 31 | E9: 55 | F9: 81 | G9: 89 | H9: 100 | I9: 102 | J9: 102 | K9: 102
A10: p01-09 | B10: 18 | C10: 24 | D10: 29 | E10: 50 | F10: 68 | G10: 81 | H10: 94 | I10: 102 | J10: 102 | K10: 102
A11: p01-10 | B11: 14 | C11: 21 | D11: 27 | E11: 52 | F11: 76 | G11: 86 | H11: 96 | I11: 102 | J11: 102 | K11: 102
A12: p01-11 | B12: 16 | C12: 21 | D12: 28 | E12: 49 | F12: 63 | G12: 72 | H12: 84 | I12: 100 | J12: 102 | K12: 102
A13: p01-12 | B13: 16 | C13: 20 | D13: 25 | E13: 52 | F13: 64 | G13: 74 | H13: 83 | I13: 96 | J13: 102 | K13: 102
... A181: p12-15 | B181: 10 | C181: 19 | D181: 26 | E181: 46 | F181: 65 | G181: 71 | H181: 78 | I181: 85 | J181: 89 | K181: 91

Sheet Density
A1: CCID | B1: PLAPD
A2: p01-01 | B2: 8.3114611
A3: p01-02 | B3: 8.5301837
A4: p01-03 | B4: 6.7804024
A5: p01-04 | B5: 7.2178478
A6: p01-05 | B6: 8.0927384
A7: p01-06 | B7: 8.5301837
A8: p01-07 | B8: 7.8740157
A9: p01-08 | B9: 8.967629
A10: p01-09 | B10: 6.9991251
A11: p01-10 | B11: 6.9991251
A12: p01-11 | B12: 8.967629
A13: p01-12 | B13: 8.3114611
... A181: p12-15 | B181: 9.4050744

Sheet Develop
A1: CCID | B1: EDATE | C1: PLYRE | D1: PLDOE | E1: LF1D | F1: ADAT | G1: ADOY
A2: p01-01 | B2: 45052 | C2: 2023 | D2: 125.5 | E2: 45060 | F2: 45107 | G2: 181.2
A3: p01-02 | B3: 45052 | C3: 2023 | D3: 126 | E3: 45060 | F3: 45109 | G3: 182.6
A4: p01-03 | B4: 45049 | C4: 2023 | D4: 123.25 | E4: 45062 | F4: 45108 | G4: 181.66667
A5: p01-04 | B5: 45049 | C5: 2023 | D5: 123.2 | E5: 45061 | F5: 45108 | G5: 182
A6: p01-05 | B6: 45049 | C6: 2023 | D6: 123 | E6: 45060 | F6: 45109 | G6: 182.83333
A7: p01-06 | B7: 45050 | C7: 2023 | D7: 124 | E7: 45062 | F7: 45110 | G7: 184
A8: p01-07 | B8: 45052 | C8: 2023 | D8: 126 | E8: 45060 | F8: 45110 | G8: 184
A9: p01-08 | B9: 45050 | C9: 2023 | D9: 123.5 | E9: 45060 | F9: 45108 | G9: 181.66667
A10: p01-09 | B10: 45050 | C10: 2023 | D10: 123.5 | E10: 45062 | F10: 45109 | G10: 182.83333
A11: p01-10 | B11: 45050 | C11: 2023 | D11: 124 | E11: 45062 | F11: 45108 | G11: 182
A12: p01-11 | B12: 45051 | C12: 2023 | D12: 125.2 | E12: 45061 | F12: 45108 | G12: 181.66667
A13: p01-12 | B13: 45051 | C13: 2023 | D13: 124.66667 | E13: 45061 | F13: 45108 | G13: 181.66667
... A181: p12-15 | B181: 45050 | C181: 2023 | D181: 124 | E181: 45062 | F181: 45109 | G181: 182.83333

Sheet PlotDevelop
A1: Plot | B1: EDATE | C1: PLYRE | D1: PLDOE | E1: LF1D | F1: ADAT | G1: ADOY | H1: NAWF184 | I1: NAWF194 | J1: NAWF201 | K1: NAWF208 | L1: NAWF215 | M1: NAWF236
A2: p01 | B2: 45050 | C2: 2023 | D2: 124 | E2: 45061 | F2: 45108 | G2: 182.32955 | H2: 6.2727273 | I2: 5.9090909 | J2: 4.7272727 | K2: 3.0909091 | L2: 2.3636364 | M2: 1.0909091
A3: p02 | B3: 45049 | C3: 2023 | D3: 123 | E3: 45061 | F3: 45109 | G3: 183.1358 | H3: 7.1818182 | I3: 6.8181818 | J3: 5.0909091 | K3: 3.6363636 | L3: 3.0909091 | M3: 2
A4: p03 | B4: 45048 | C4: 2023 | D4: 122 | E4: 45060 | F4: 45109 | G4: 182.86047 | H4: 7.2727273 | I4: 6.7272727 | J4: 5.2727273 | K4: 3.6363636 | L4: 3.1818182 | M4: 1.6363636
A5: p04 | B5: 45050 | C5: 2023 | D5: 124 | E5: 45062 | F5: 45108 | G5: 181.89247 | H5: 6.6363636 | I5: 5.8181818 | J5: 4.3636364 | K5: 2.5454545 | L5: 2.0909091 | M5: 0.81818182
A6: p05 | B6: 45049 | C6: 2023 | D6: 123 | E6: 45061 | F6: 45109 | G6: 182.86047 | H6: 7.1818182 | I6: 6.6363636 | J6: 5.1818182 | K6: 4.0909091 | L6: 3.2727273 | M6: 1.9090909
A7: p06 | B7: 45050 | C7: 2023 | D7: 124 | E7: 45061 | F7: 45108 | G7: 182.32955 | H7: 6.7272727 | I7: 5.6363636 | J7: 4.1818182 | K7: 2.6363636 | L7: 2 | M7: 1
A8: p07 | B8: 45050 | C8: 2023 | D8: 124 | E8: 45063 | F8: 45110 | G8: 183.55696 | H8: 6.2727273 | I8: 5.3636364 | J8: 3.6363636 | K8: 2.0909091 | L8: 1.3636364 | M8: 0.81818182
A9: p08 | B9: 45049 | C9: 2023 | D9: 123 | E9: 45063 | F9: 45109 | G9: 183 | H9: 6.8181818 | I9: 5.8181818 | J9: 4.0909091 | K9: 2.8181818 | L9: 2.2727273 | M9: 1.3636364
A10: p09 | B10: 45050 | C10: 2023 | D10: 124 | E10: 45062 | F10: 45108 | G10: 182.3908 | H10: 6.6363636 | I10: 6.0909091 | J10: 4.3636364 | K10: 3 | L10: 2.0909091 | M10: 1.5454545
A11: p10 | B11: 45051 | C11: 2023 | D11: 125 | E11: 45063 | F11: 45109 | G11: 183.2125 | H11: 6.0909091 | I11: 5.5454545 | J11: 3.9090909 | K11: 2.2727273 | L11: 1.8181818 | M11: 1
A12: p11 | B12: 45049 | C12: 2023 | D12: 123 | E12: 45063 | F12: 45108 | G12: 182 | H12: 6.7272727 | I12: 6.1818182 | J12: 4.4545455 | K12: 2.7272727 | L12: 2 | M12: 1.4545455
A13: p12 | B13: 45050 | C13: 2023 | D13: 124 | E13: 45063 | F13: 45108 | G13: 182.46154 | H13: 6.2727273 | I13: 5.7272727 | J13: 4 | K13: 2.1818182 | L13: 1.6363636 | M13: 0.90909091

Sheet Blank Data Sheet
A1: 2023 | B1: F13b4 | C1: Cotton
A2: Canopy Measurements & NAWF | J2: Date: | L2: Time:
A3: Cotton planted 24 April. Watered 25 April. | J3: DOY: | L3: by:
A5: Plot | B5: Height (cm) | C5: Width (cm) | D5: NAWF | E5: NAWF | F5: NAWF | G5: NAWF | H5: NAWF | J5: Plot | K5: Height (cm) | L5: Width (cm) | M5: NAWF | N5: NAWF | O5: NAWF | P5: NAWF | Q5: NAWF | T5: Plot | U5: Height (cm) | V5: Width (cm) | W5: NAWF | X5: NAWF | Y5: NAWF | Z5: NAWF | AA5: NAWF | AD5: Plot | AE5: Height (cm) | AF5: Width (cm) | AG5: NAWF | AH5: NAWF | AI5: NAWF | AJ5: NAWF | AK5: NAWF
A6: 01-01 | J6: 02-15 | T6: 03-01 | AD6: 04-15
A7: 01-02 | J7: 02-14 | T7: 03-02 | AD7: 04-14
A8: 01-03 | J8: 02-13 | T8: 03-03 | AD8: 04-13
A9: 01-04 | J9: 02-12 | T9: 03-04 | AD9: 04-12
A10: 01-05 | J10: 02-11 | T10: 03-05 | AD10: 04-11
A11: 01-06 | J11: 02-10 | T11: 03-06 | AD11: 04-10
A12: 01-07 | J12: 02-9 | T12: 03-07 | AD12: 04-9
A13: 01-08 | J13: 02-8 | T13: 03-08 | AD13: 04-8
A14: 01-09 | J14: 02-7 | T14: 03-09 | AD14: 04-7
A15: 01-10 | J15: 02-6 | T15: 03-10 | AD15: 04-6
A16: 01-11 | J16: 02-5 | T16: 03-11 | AD16: 04-5
A17: 01-12 | J17: 02-4 | T17: 03-12 | AD17: 04-4
... A20: 01-15 | J20: 02-1 | T20: 01-15 | AD20: 04-1
A22: Plot | B22: Height (cm) | C22: Width (cm) | D22: NAWF | E22: NAWF | F22: NAWF | G22: NAWF | H22: NAWF | J22: Plot | K22: Height (cm) | L22: Width (cm) | M22: NAWF | N22: NAWF | O22: NAWF | P22: NAWF | Q22: NAWF | T22: Plot | U22: Height (cm) | V22: Width (cm) | W22: NAWF | X22: NAWF | Y22: NAWF | Z22: NAWF | AA22: NAWF | AD22: Plot | AE22: Height (cm) | AF22: Width (cm) | AG22: NAWF | AH22: NAWF | AI22: NAWF | AJ22: NAWF | AK22: NAWF
A23: 05-01 | J23: 06-15 | T23: 07-01 | AD23: 08-15
A24: 05-02 | J24: 06-14 | T24: 07-02 | AD24: 08-14
A25: 05-03 | J25: 06-13 | T25: 07-03 | AD25: 08-13
A26: 05-04 | J26: 06-12 | T26: 07-04 | AD26: 08-12
A27: 05-05 | J27: 06-11 | T27: 07-05 | AD27: 08-11
A28: 05-06 | J28: 06-10 | T28: 07-06 | AD28: 08-10
A29: 05-07 | J29: 06-9 | T29: 07-07 | AD29: 08-9
A30: 05-08 | J30: 06-8 | T30: 07-08 | AD30: 08-8
A31: 05-09 | J31: 06-7 | T31: 07-09 | AD31: 08-7
A32: 05-10 | J32: 06-6 | T32: 07-10 | AD32: 08-6
A33: 05-11 | J33: 06-5 | T33: 07-11 | AD33: 08-5
A34: 05-12 | J34: 06-4 | T34: 07-12 | AD34: 08-4
... A37: 05-15 | J37: 06-1 | T37: 07-15 | AD37: 08-1
A39: Plot | B39: Height (cm) | C39: Width (cm) | D39: NAWF | E39: NAWF | F39: NAWF | G39: NAWF | H39: NAWF | J39: Plot | K39: Height (cm) | L39: Width (cm) | M39: NAWF | N39: NAWF | O39: NAWF | P39: NAWF | Q39: NAWF | T39: Plot | U39: Height (cm) | V39: Width (cm) | W39: NAWF | X39: NAWF | Y39: NAWF | Z39: NAWF | AA39: NAWF | AD39: Plot | AE39: Height (cm) | AF39: Width (cm) | AG39: NAWF | AH39: NAWF | AI39: NAWF | AJ39: NAWF | AK39: NAWF
A40: 09-01 | J40: 10-15 | T40: 11-01 | AD40: 12-15
A41: 09-02 | J41: 10-14 | T41: 11-02 | AD41: 12-14
A42: 09-03 | J42: 10-13 | T42: 11-03 | AD42: 12-13
A43: 09-04 | J43: 10-12 | T43: 11-04 | AD43: 12-12
A44: 09-05 | J44: 10-11 | T44: 11-05 | AD44: 12-11
A45: 09-06 | J45: 10-10 | T45: 11-06 | AD45: 12-10
A46: 09-07 | J46: 10-9 | T46: 11-07 | AD46: 12-9
A47: 09-08 | J47: 10-8 | T47: 11-08 | AD47: 12-8
...

Sheet Height Summary
A1: Summary | B1: 2023 | D1: F13b4 | F1: Cotton
D2: spans 4-6
B3: Canopy Heights - Summary
D8: Initials: | E8: SMM | F8: SMM | G8: SMM | H8: SMM | I8: SMM | J8: SMM | K8: SMM | L8: SMM | M8: SMM | N8: SMM
D9: Date: | E9: 45082 | F9: 45089 | G9: 45097 | H9: 45103 | I9: 45110 | J9: 45120 | K9: 45127 | L9: 45134 | M9: 45141 | N9: 45162
D10: DOY: | E10: 156 | F10: 163 | G10: 171 | H10: 177 | I10: 184 | J10: 194 | K10: 201 | L10: 208 | M10: 215 | N10: 236
D11: Time: | E11: 0915-1200 | F11: 0900-1130 | G11: 0900-1145 | H11: 0830-1130 | I11: 0845-1200 | J11: 0900-1200 | K11: 0830-1200 | L11: 0815-1215 | M11: 0830-1300 | N11: 0815-1430
B12: Plot | D12: TRT | E12: Height (cm) | F12: Height (cm) | G12: Height (cm) | H12: Height (cm) | I12: Height (cm) | J12: Height (cm) | K12: Height (cm) | L12: Height (cm) | M12: Height (cm) | N12: Height (cm)
B13: 01- | C13: 1 | D13: STRIP | E13: 13 | F13: 20 | G13: 28 | H13: 42 | I13: 55 | J13: 65 | K13: 76 | L13: 85 | M13: 98 | N13: 102
B14: 01- | C14: 2 | D14: STRIP | E14: 15 | F14: 22 | G14: 32 | H14: 53 | I14: 77 | J14: 89 | K14: 100 | L14: 115 | M14: 125 | N14: 129
B15: 01- | C15: 3 | D15: STRIP | E15: 13 | F15: 21 | G15: 31 | H15: 51 | I15: 74 | J15: 84 | K15: 92 | L15: 101 | M15: 112 | N15: 117
B16: 01- | C16: 4 | D16: STRIP | E16: 9 | F16: 15 | G16: 25 | H16: 50 | I16: 77 | J16: 88 | K16: 99 | L16: 110 | M16: 122 | N16: 127
B17: 01- | C17: 5 | D17: STRIP | E17: 9 | F17: 16 | G17: 26 | H17: 43 | I17: 66 | J17: 77 | K17: 89 | L17: 102 | M17: 113 | N17: 119
B18: 01- | C18: 6 | D18: STRIP | E18: 12 | F18: 20 | G18: 29 | H18: 45 | I18: 67 | J18: 86 | K18: 107 | L18: 134 | M18: 148 | N18: 154
B19: 01- | C19: 7 | D19: STRIP | E19: 10 | F19: 18 | G19: 28 | H19: 40 | I19: 58 | J19: 67 | K19: 76 | L19: 85 | M19: 100 | N19: 98
B20: 01- | C20: 8 | D20: STRIP | E20: 20 | F20: 26 | G20: 35 | H20: 54 | I20: 80 | J20: 93 | K20: 105 | L20: 115 | M20: 131 | N20: 138
B21: 01- | C21: 9 | D21: STRIP | E21: 18 | F21: 24 | G21: 32 | H21: 53 | I21: 80 | J21: 90 | K21: 97 | L21: 107 | M21: 118 | N21: 121
B22: 01- | C22: 10 | D22: STRIP | E22: 13 | F22: 20 | G22: 29 | H22: 51 | I22: 81 | J22: 90 | K22: 98 | L22: 108 | M22: 117 | N22: 122
B23: 01- | C23: 11 | D23: STRIP | E23: 15 | F23: 21 | G23: 30 | H23: 50 | I23: 64 | J23: 76 | K23: 88 | L23: 101 | M23: 116 | N23: 123
B24: 01- | C24: 12 | D24: STRIP | E24: 14 | F24: 20 | G24: 29 | H24: 52 | I24: 67 | J24: 77 | K24: 86 | L24: 95 | M24: 107 | N24: 113
... B102: 06- | C102: 1 | D102: STRIP | E102: 18 | F102: 26 | G102: 35 | H102: 55 | I102: 81 | J102: 91 | K102: 100 | L102: 108 | M102: 124 | N102: 126
B103: 7 | C103: 1 | D103: BEDS | E103: 15 | F103: 26 | G103: 31 | H103: 51 | I103: 74 | J103: 82 | K103: 91 | L103: 99 | M103: 117 | N103: 114
B104: 7 | C104: 2 | D104: BEDS | E104: 13 | F104: 23 | G104: 29 | H104: 48 | I104: 68 | J104: 78 | K104: 88 | L104: 98 | M104: 120 | N104: 116
B105: 7 | C105: 3 | D105: BEDS | E105: 7 | F105: 13 | G105: 25 | H105: 45 | I105: 83 | J105: 89 | K105: 95 | L105: 102 | M105: 118 | N105: 109
B106: 7 | C106: 4 | D106: BEDS | E106: 10 | F106: 18 | G106: 27 | H106: 48 | I106: 67 | J106: 77 | K106: 90 | L106: 101 | M106: 117 | N106: 118
B107: 7 | C107: 5 | D107: BEDS | E107: 18 | F107: 25 | G107: 33 | H107: 53 | I107: 71 | J107: 83 | K107: 95 | L107: 107 | M107: 120 | N107: 126
B108: 7 | C108: 6 | D108: BEDS | E108: 8 | F108: 14 | G108: 24 | H108: 45 | I108: 65 | J108: 76 | K108: 86 | L108: 95 | M108: 112 | N108: 114
B109: 7 | C109: 7 | D109: BEDS | E109: 11 | F109: 19 | G109: 26 | H109: 45 | I109: 65 | J109: 75 | K109: 85 | L109: 94 | M109: 107 | N109: 112
B110: 7 | C110: 8 | D110: BEDS | E110: 2 | F110: 8 | G110: 15 | H110: 38 | I110: 58 | J110: 69 | K110: 83 | L110: 95 | M110: 109 | N110: 114
B111: 7 | C111: 9 | D111: BEDS | E111: 4 | F111: 11 | G111: 21 | H111: 46 | I111: 68 | J111: 83 | K111: 94 | L111: 113 | M111: 135 | N111: 138
B112: 7 | C112: 10 | D112: BEDS | E112: 6 | F112: 13 | G112: 23 | H112: 48 | I112: 68 | J112: 81 | K112: 92 | L112: 110 | M112: 120 | N112: 126
B113: 7 | C113: 11 | D113: BEDS | E113: 11 | F113: 17 | G113: 26 | H113: 47 | I113: 67 | J113: 78 | K113: 89 | L113: 98 | M113: 116 | N113: 121
B114: 7 | C114: 12 | D114: BEDS | E114: 10 | F114: 17 | G114: 25 | H114: 43 | I114: 62 | J114: 74 | K114: 86 | L114: 105 | M114: 129 | N114: 132
... B192: 12 | C192: 1 | D192: BEDS | E192: 11 | F192: 19 | G192: 27 | H192: 50 | I192: 66 | J192: 76 | K192: 86 | L192: 97 | M192: 108 | N192: 112

Sheet Cover Summary
A1: Summary | B1: 2023 | D1: F13b4 | F1: Cotton
D2: spans 4-6
B3: Canopy Heights - Summary | F3: "--" = closed canopy
D8: Initials: | E8: SMM | F8: SMM | G8: SMM | H8: SMM | I8: SMM | J8: SMM | K8: SMM | L8: SMM | M8: SMM | N8: SMM
D9: Date: | E9: 45082 | F9: 45089 | G9: 45097 | H9: 45103 | I9: 45110 | J9: 45120 | K9: 45127 | L9: 45134 | M9: 45141 | N9: 45162
D10: DOY: | E10: 156 | F10: 163 | G10: 171 | H10: 177 | I10: 184 | J10: 194 | K10: 201 | L10: 208 | M10: 215 | N10: 236
D11: Time: | G11: 0900-1145
B12: Plot | D12: Flag | E12: Width (cm) | F12: Width (cm) | G12: Width (cm) | H12: Width (cm) | I12: Width (cm) | J12: Width (cm) | K12: Width (cm) | L12: Width (cm) | M12: Width (cm) | N12: Width (cm)
B13: 01- | C13: 1 | D13: STRIP | E13: 13 | F13: 21 | G13: 26 | H13: 40 | I13: 55 | J13: 90 | K13: 72 | L13: 84 | M13: 85 | N13: 89
B14: 01- | C14: 2 | D14: STRIP | E14: 15 | F14: 22 | G14: 28 | H14: 54 | I14: 73 | J14: 85 | K14: 96 | L14: -- | M14: -- | N14: --
B15: 01- | C15: 3 | D15: STRIP | E15: 14 | F15: 22 | G15: 31 | H15: 50 | I15: 71 | J15: 81 | K15: 89 | L15: 87 | M15: -- | N15: --
B16: 01- | C16: 4 | D16: STRIP | E16: 10 | F16: 20 | G16: 34 | H16: 52 | I16: 77 | J16: 84 | K16: 94 | L16: -- | M16: -- | N16: --
B17: 01- | C17: 5 | D17: STRIP | E17: 12 | F17: 19 | G17: 28 | H17: 47 | I17: 67 | J17: 75 | K17: 83 | L17: 96 | M17: -- | N17: --
B18: 01- | C18: 6 | D18: STRIP | E18: 13 | F18: 19 | G18: 26 | H18: 42 | I18: 61 | J18: 83 | K18: 95 | L18: -- | M18: -- | N18: --
B19: 01- | C19: 7 | D19: STRIP | E19: 12 | F19: 20 | G19: 27 | H19: 53 | I19: 61 | J19: 66 | K19: 73 | L19: 83 | M19: 84 | N19: 87
B20: 01- | C20: 8 | D20: STRIP | E20: 19 | F20: 25 | G20: 31 | H20: 55 | I20: 81 | J20: 89 | K20: 100 | L20: -- | M20: -- | N20: --
B21: 01- | C21: 9 | D21: STRIP | E21: 18 | F21: 24 | G21: 29 | H21: 50 | I21: 68 | J21: 81 | K21: 94 | L21: -- | M21: -- | N21: --
B22: 01- | C22: 10 | D22: STRIP | E22: 14 | F22: 21 | G22: 27 | H22: 52 | I22: 76 | J22: 86 | K22: 96 | L22: -- | M22: -- | N22: --
B23: 01- | C23: 11 | D23: STRIP | E23: 16 | F23: 21 | G23: 28 | H23: 49 | I23: 63 | J23: 72 | K23: 84 | L23: 100 | M23: -- | N23: --
B24: 01- | C24: 12 | D24: STRIP | E24: 16 | F24: 20 | G24: 25 | H24: 52 | I24: 64 | J24: 74 | K24: 83 | L24: 96 | M24: -- | N24: --
B25: 01- | C25: 13 | D25: STRIP | E25: 12 | F25: 17 | G25: 24 | H25: 39 | I25: 53 | J25: 60 | K25: 71 | L25: 84 | M25: 94 | N25: 97
B26: 01- | C26: 14 | D26: STRIP | E26: 14 | F26: 18 | G26: 26 | H26: 50 | I26: 75 | J26: 82 | K26: 93 | L26: -- | M26: -- | N26: --
B27: 01- | C27: 15 | D27: STRIP | E27: 14 | F27: 19 | G27: 28 | H27: =AVERAGE(G27,I27) -> 46 | I27: 64 | J27: 77 | K27: 88 | L27: 94 | M27: -- | N27: --
B28: 02- | C28: 15 | D28: NO TILL | E28: 19 | F28: 26 | G28: 33 | H28: 48 | I28: 62 | J28: 74 | K28: 83 | L28: 92 | M28: 102 | N28: --
B29: 02- | C29: 14 | D29: NO TILL | E29: 17 | F29: 22 | G29: 28 | H29: 53 | I29: 78 | J29: 89 | K29: 97 | L29: -- | M29: -- | N29: --
B30: 02- | C30: 13 | D30: NO TILL | E30: 20 | F30: 24 | G30: 30 | H30: 49 | I30: 65 | J30: 77 | K30: 88 | L30: 99 | M30: -- | N30: --
B31: 02- | C31: 12 | D31: NO TILL | E31: 21 | F31: 28 | G31: 34 | H31: 55 | I31: 81 | J31: 90 | K31: 101 | L31: -- | M31: -- | N31: --
B32: 02- | C32: 11 | D32: NO TILL | E32: 18 | F32: 27 | G32: 33 | H32: 52 | I32: 68 | J32: 76 | K32: 84 | L32: 97 | M32: -- | N32: --
B33: 02- | C33: 10 | D33: NO TILL | E33: 21 | F33: 29 | G33: 35 | H33: 51 | I33: 58 | J33: 69 | K33: 75 | L33: 91 | M33: 97 | N33: --
B34: 02- | C34: 9 | D34: NO TILL | E34: 15 | F34: 20 | G34: 29 | H34: 55 | I34: 78 | J34: 92 | K34: 101 | L34: -- | M34: -- | N34: --
B35: 02- | C35: 8 | D35: NO TILL | E35: 20 | F35: 27 | G35: 33 | H35: 55 | I35: 77 | J35: 91 | K35: 102 | L35: -- | M35: -- | N35: --
B36: 02- | C36: 7 | D36: NO TILL | E36: 20 | F36: 28 | G36: 35 | H36: 56 | I36: 82 | J36: 94 | K36: -- | L36: -- | M36: -- | N36: --
B37: 02- | C37: 6 | D37: NO TILL | E37: 13 | F37: 19 | G37: 23 | H37: 42 | I37: 56 | J37: 68 | K37: 79 | L37: 91 | N37: --
B38: 02- | C38: 5 | D38: NO TILL | E38: 17 | F38: 25 | G38: 32 | H38: 51 | I38: 71 | J38: 82 | K38: 94 | L38: -- | M38: -- | N38: --
B39: 02- | C39: 4 | D39: NO TILL | E39: 24 | F39: 31 | G39: 36 | H39: 60 | I39: 86 | J39: 98 | K39: -- | L39: -- | M39: -- | N39: --
B40: 02- | C40: 3 | D40: NO TILL | E40: 24 | F40: 32 | G40: 37 | H40: 62 | I40: 86 | J40: 97 | K40: -- | L40: -- | M40: -- | N40: --
B41: 02- | C41: 2 | D41: NO TILL | E41: 17 | F41: 33 | G41: 40 | H41: 65 | I41: 87 | J41: 99 | K41: -- | L41: -- | M41: -- | N41: --
B42: 02- | C42: 1 | D42: NO TILL | E42: 16 | F42: 31 | G42: 39 | H42: 54 | I42: 71 | J42: 84 | K42: 97 | L42: -- | M42: -- | N42: --
B43: 03- | C43: 1 | D43: NO TILL | E43: 20 | F43: 30 | G43: 39 | H43: 56 | I43: 76 | J43: 87 | K43: 99 | L43: -- | M43: -- | N43: --
B44: 03- | C44: 2 | D44: NO TILL | E44: 16 | F44: 26 | G44: 34 | H44: 60 | I44: 83 | J44: 94 | K44: 101 | L44: -- | M44: -- | N44: --
...

Sheet Averages
A1: 2023 - Averages by treatments
A4: Average Canopy Heights
C6: ='Height Summary'!E$9 -> 45082 | D6: ='Height Summary'!F$9 -> 45089 | E6: ='Height Summary'!G$9 -> 45097 | F6: ='Height Summary'!H$9 -> 45103 | G6: ='Height Summary'!I$9 -> 45110 | H6: ='Height Summary'!J$9 -> 45120 | I6: ='Height Summary'!K$9 -> 45127 | J6: ='Height Summary'!L$9 -> 45134 | ... L6: ='Height Summary'!N$9 -> 45162
C7: ='Height Summary'!E$10 -> 156 | D7: ='Height Summary'!F$10 -> 163 | E7: ='Height Summary'!G$10 -> 171 | F7: ='Height Summary'!H$10 -> 177 | G7: ='Height Summary'!I$10 -> 184 | H7: ='Height Summary'!J$10 -> 194 | I7: ='Height Summary'!K$10 -> 201 | J7: ='Height Summary'!L$10 -> 208 | ... L7: ='Height Summary'!N$10 -> 236
A8: STRIP | C8: =AVERAGEIFS('Height Summary'!E$13:E$192,'Height Summary'!$D$13:$D$192, "STRIP") -> 12.622222 | D8: =AVERAGEIFS('Height Summary'!F$13:F$192,'Height Summary'!$D$13:$D$192, "STRIP") -> 19.955556 | E8: =AVERAGEIFS('Height Summary'!G$13:G$192,'Height Summary'!$D$13:$D$192, "STRIP") -> 29.155556 | F8: =AVERAGEIFS('Height Summary'!H$13:H$192,'Height Summary'!$D$13:$D$192, "STRIP") -> 49.288889 | G8: =AVERAGEIFS('Height Summary'!I$13:I$192,'Height Summary'!$D$13:$D$192, "STRIP") -> 72.933333 | H8: =AVERAGEIFS('Height Summary'!J$13:J$192,'Height Summary'!$D$13:$D$192, "STRIP") -> 84.222222 | I8: =AVERAGEIFS('Height Summary'!K$13:K$192,'Height Summary'!$D$13:$D$192, "STRIP") -> 95.4 | J8: =AVERAGEIFS('Height Summary'!L$13:L$192,'Height Summary'!$D$13:$D$192, "STRIP") -> 106.77778 | ... L8: =AVERAGEIFS('Height Summary'!N$13:N$192,'Height Summary'!$D$13:$D$192, "STRIP") -> 125.4
A10: NO TILL | C10: =AVERAGEIFS('Height Summary'!E$13:E$192,'Height Summary'!$D$13:$D$192, "NO TILL") -> 20.488889 | D10: =AVERAGEIFS('Height Summary'!F$13:F$192,'Height Summary'!$D$13:$D$192, "NO TILL") -> 27.6 | E10: =AVERAGEIFS('Height Summary'!G$13:G$192,'Height Summary'!$D$13:$D$192, "NO TILL") -> 36.622222 | F10: =AVERAGEIFS('Height Summary'!H$13:H$192,'Height Summary'!$D$13:$D$192, "NO TILL") -> 58.711111 | G10: =AVERAGEIFS('Height Summary'!I$13:I$192,'Height Summary'!$D$13:$D$192, "NO TILL") -> 84.044444 | H10: =AVERAGEIFS('Height Summary'!J$13:J$192,'Height Summary'!$D$13:$D$192, "NO TILL") -> 93.733333 | I10: =AVERAGEIFS('Height Summary'!K$13:K$192,'Height Summary'!$D$13:$D$192, "NO TILL") -> 102.77778 | J10: =AVERAGEIFS('Height Summary'!L$13:L$192,'Height Summary'!$D$13:$D$192, "NO TILL") -> 112.2 | ... L10: =AVERAGEIFS('Height Summary'!N$13:N$192,'Height Summary'!$D$13:$D$192, "NO TILL") -> 127.31111
A12: BEDS | C12: =AVERAGEIFS('Height Summary'!E$13:E$192,'Height Summary'!$D$13:$D$192, "BEDS") -> 9.3333333 | D12: =AVERAGEIFS('Height Summary'!F$13:F$192,'Height Summary'!$D$13:$D$192, "BEDS") -> 16.6 | E12: =AVERAGEIFS('Height Summary'!G$13:G$192,'Height Summary'!$D$13:$D$192, "BEDS") -> 25.266667 | F12: =AVERAGEIFS('Height Summary'!H$13:H$192,'Height Summary'!$D$13:$D$192, "BEDS") -> 47.755556 | G12: =AVERAGEIFS('Height Summary'!I$13:I$192,'Height Summary'!$D$13:$D$192, "BEDS") -> 66.933333 | H12: =AVERAGEIFS('Height Summary'!J$13:J$192,'Height Summary'!$D$13:$D$192, "BEDS") -> 77.711111 | I12: =AVERAGEIFS('Height Summary'!K$13:K$192,'Height Summary'!$D$13:$D$192, "BEDS") -> 88.577778 | J12: =AVERAGEIFS('Height Summary'!L$13:L$192,'Height Summary'!$D$13:$D$192, "BEDS") -> 99.222222 | ... L12: =AVERAGEIFS('Height Summary'!N$13:N$192,'Height Summary'!$D$13:$D$192, "BEDS") -> 117.93333
A14: FLAT | C14: =AVERAGEIFS('Height Summary'!E$13:E$192,'Height Summary'!$D$13:$D$192, "FLAT") -> 12.422222 | D14: =AVERAGEIFS('Height Summary'!F$13:F$192,'Height Summary'!$D$13:$D$192, "FLAT") -> 19.977778 | E14: =AVERAGEIFS('Height Summary'!G$13:G$192,'Height Summary'!$D$13:$D$192, "FLAT") -> 28.311111 | F14: =AVERAGEIFS('Height Summary'!H$13:H$192,'Height Summary'!$D$13:$D$192, "FLAT") -> 51.688889 | G14: =AVERAGEIFS('Height Summary'!I$13:I$192,'Height Summary'!$D$13:$D$192, "FLAT") -> 74.8 | H14: =AVERAGEIFS('Height Summary'!J$13:J$192,'Height Summary'!$D$13:$D$192, "FLAT") -> 84.333333 | I14: =AVERAGEIFS('Height Summary'!K$13:K$192,'Height Summary'!$D$13:$D$192, "FLAT") -> 93.6 | J14: =AVERAGEIFS('Height Summary'!L$13:L$192,'Height Summary'!$D$13:$D$192, "FLAT") -> 102.77778 | ... L14: =AVERAGEIFS('Height Summary'!N$13:N$192,'Height Summary'!$D$13:$D$192, "FLAT") -> 118.82222
A17: Average Canopy Widths
C19: ='Cover Summary'!E9 -> 45082 | D19: ='Cover Summary'!F9 -> 45089 | E19: ='Cover Summary'!G9 -> 45097 | F19: ='Cover Summary'!H9 -> 45103 | G19: ='Cover Summary'!I9 -> 45110 | H19: ='Cover Summary'!J9 -> 45120 | I19: ='Cover Summary'!K9 -> 45127 | J19: ='Cover Summary'!L9 -> 45134 | ... L19: ='Cover Summary'!N9 -> 45162
C20: ='Cover Summary'!E10 -> 156 | D20: ='Cover Summary'!F10 -> 163 | E20: ='Cover Summary'!G10 -> 171 | F20: ='Cover Summary'!H10 -> 177 | G20: ='Cover Summary'!I10 -> 184 | H20: ='Cover Summary'!J10 -> 194 | I20: ='Cover Summary'!K10 -> 201 | J20: ='Cover Summary'!L10 -> 208 | ... L20: ='Cover Summary'!N10 -> 236
A21: STRIP | C21: =AVERAGEIFS('Cover Summary'!E$13:E$192,'Cover Summary'!$D$13:$D$192, "STRIP") -> 13.977778 | D21: =AVERAGEIFS('Cover Summary'!F$13:F$192,'Cover Summary'!$D$13:$D$192, "STRIP") -> 21.022222 | E21: =AVERAGEIFS('Cover Summary'!G$13:G$192,'Cover Summary'!$D$13:$D$192, "STRIP") -> 28.177778 | F21: =AVERAGEIFS('Cover Summary'!H$13:H$192,'Cover Summary'!$D$13:$D$192, "STRIP") -> 49.688889 | G21: =AVERAGEIFS('Cover Summary'!I$13:I$192,'Cover Summary'!$D$13:$D$192, "STRIP") -> 70.488889 | H21: =AVERAGEIFS('Cover Summary'!J$13:J$192,'Cover Summary'!$D$13:$D$192, "STRIP") -> 80.577778 | I21: =AVERAGEIFS('Cover Summary'!K$13:K$192,'Cover Summary'!$D$13:$D$192, "STRIP") -> 90.090909 | J21: =AVERAGEIFS('Cover Summary'!L$13:L$192,'Cover Summary'!$D$13:$D$192, "STRIP") -> 94.85 | ... L21: =AVERAGEIFS('Cover Summary'!N$13:N$192,'Cover Summary'!$D$13:$D$192, "STRIP") -> 92.5
A23: NO TILL | C23: =AVERAGEIFS('Cover Summary'!E$13:E$192,'Cover Summary'!$D$13:$D$192, "NO TILL") -> 19.222222 | D23: =AVERAGEIFS('Cover Summary'!F$13:F$192,'Cover Summary'!$D$13:$D$192, "NO TILL") -> 28.022222 | E23: =AVERAGEIFS('Cover Summary'!G$13:G$192,'Cover Summary'!$D$13:$D$192, "NO TILL") -> 34.977778 | F23: =AVERAGEIFS('Cover Summary'!H$13:H$192,'Cover Summary'!$D$13:$D$192, "NO TILL") -> 56.977778 | G23: =AVERAGEIFS('Cover Summary'!I$13:I$192,'Cover Summary'!$D$13:$D$192, "NO TILL") -> 79.422222 | H23: =AVERAGEIFS('Cover Summary'!J$13:J$192,'Cover Summary'!$D$13:$D$192, "NO TILL") -> 89.431818 | I23: =AVERAGEIFS('Cover Summary'!K$13:K$192,'Cover Summary'!$D$13:$D$192, "NO TILL") -> 95 | J23: =AVERAGEIFS('Cover Summary'!L$13:L$192,'Cover Summary'!$D$13:$D$192, "NO TILL") -> 95.333333 | ... L23: =AVERAGEIFS('Cover Summary'!N$13:N$192,'Cover Summary'!$D$13:$D$192, "NO TILL") -> #DIV/0!
A25: BEDS | C25: =AVERAGEIFS('Cover Summary'!E$13:E$192,'Cover Summary'!$D$13:$D$192, "BEDS") -> 10.533333 | D25: =AVERAGEIFS('Cover Summary'!F$13:F$192,'Cover Summary'!$D$13:$D$192, "BEDS") -> 17.533333 | E25: =AVERAGEIFS('Cover Summary'!G$13:G$192,'Cover Summary'!$D$13:$D$192, "BEDS") -> 24.622222 | F25: =AVERAGEIFS('Cover Summary'!H$13:H$192,'Cover Summary'!$D$13:$D$192, "BEDS") -> 46.955556 | G25: =AVERAGEIFS('Cover Summary'!I$13:I$192,'Cover Summary'!$D$13:$D$192, "BEDS") -> 64.422222 | H25: =AVERAGEIFS('Cover Summary'!J$13:J$192,'Cover Summary'!$D$13:$D$192, "BEDS") -> 72.666667 | I25: =AVERAGEIFS('Cover Summary'!K$13:K$192,'Cover Summary'!$D$13:$D$192, "BEDS") -> 82.488889 | J25: =AVERAGEIFS('Cover Summary'!L$13:L$192,'Cover Summary'!$D$13:$D$192, "BEDS") -> 92.348837 | ... L25: =AVERAGEIFS('Cover Summary'!N$13:N$192,'Cover Summary'!$D$13:$D$192, "BEDS") -> 95
A27: FLAT | C27: =AVERAGEIFS('Cover Summary'!E$13:E$192,'Cover Summary'!$D$13:$D$192, "FLAT") -> 12.822222 | D27: =AVERAGEIFS('Cover Summary'!F$13:F$192,'Cover Summary'!$D$13:$D$192, "FLAT") -> 20.911111 | E27: =AVERAGEIFS('Cover Summary'!G$13:G$192,'Cover Summary'!$D$13:$D$192, "FLAT") -> 27.266667 | F27: =AVERAGEIFS('Cover Summary'!H$13:H$192,'Cover Summary'!$D$13:$D$192, "FLAT") -> 49.844444 | G27: =AVERAGEIFS('Cover Summary'!I$13:I$192,'Cover Summary'!$D$13:$D$192, "FLAT") -> 71.044444 | H27: =AVERAGEIFS('Cover Summary'!J$13:J$192,'Cover Summary'!$D$13:$D$192, "FLAT") -> 79.4 | I27: =AVERAGEIFS('Cover Summary'!K$13:K$192,'Cover Summary'!$D$13:$D$192, "FLAT") -> 88.8 | J27: =AVERAGEIFS('Cover Summary'!L$13:L$192,'Cover Summary'!$D$13:$D$192, "FLAT") -> 94.290323 | ... L27: =AVERAGEIFS('Cover Summary'!N$13:N$192,'Cover Summary'!$D$13:$D$192, "FLAT") -> 94.642857

Sheet Counts
B1: 2023 | C1: F13b4 | D1: Cotton | F1: Final density counts
F2: Cotton planted 24 April. Watered 25 April.
H3: Date: | I3: various | L3: SMM
H4: DOY:
B5: Counted plants in 1.5 meter North of each canopy height flag & same relative location in the rows to the East and West of the flagged row. Where neutron tubes are located in the row to the East, the final density count in that row may be shifted North a bit.
C6: 1 row East of flag | E6: 1 row West of flag | I6: 1 row East of flag | K6: 1 row West of flag
B7: Plot | C7: # plants /1.5 m | D7: # plants /1.5 m | E7: # plants /1.5 m | F7: Notes | H7: Plot | I7: # plants /1.5 m | J7: # plants /1.5 m | K7: # plants /1.5 m | L7: Notes
B8: 01-01 | C8: 13 | D8: 13 | E8: 12 | H8: 03-01 | I8: 15 | J8: 17 | K8: 16
B9: 01-02 | C9: 12 | D9: 13 | E9: 14 | H9: 03-02 | I9: 14 | J9: 11 | K9: 12
B10: 01-03 | C10: 8 | D10: 11 | E10: 12 | H10: 03-03 | I10: 8 | J10: 5 | K10: 14
B11: 01-04 | C11: 10 | D11: 12 | E11: 11 | H11: 03-04 | I11: 14 | J11: 14 | K11: 13
B12: 01-05 | C12: 11 | D12: 14 | E12: 12 | H12: 03-05 | I12: 11 | J12: 10 | K12: 12
B13: 01-06 | C13: 13 | D13: 12 | E13: 14 | H13: 03-06 | I13: 11 | J13: 15 | K13: 14
B14: 01-07 | C14: 10 | D14: 13 | E14: 13 | H14: 03-07 | I14: 6 | J14: 8 | K14: 11
B15: 01-08 | C15: 15 | D15: 14 | E15: 12 | H15: 03-08 | I15: 10 | J15: 14 | K15: 9
B16: 01-09 | C16: 9 | D16: 10 | E16: 13 | H16: 03-09 | I16: 15 | J16: 11 | K16: 14
B17: 01-10 | C17: 11 | D17: 10 | E17: 11 | H17: 03-10 | I17: 14 | J17: 12 | K17: 15
B18: 01-11 | C18: 15 | D18: 12 | E18: 14 | H18: 03-11 | I18: 9 | J18: 10 | K18: 11
B19: 01-12 | C19: 13 | D19: 11 | E19: 14 | H19: 03-12 | I19: 14 | J19: 13 | K19: 13
... B37: 02-1 | C37: 10 | D37: 8 | E37: 12 | H37: 04-1 | I37: 13 | J37: 17 | K37: 14
C39: 1 row East of flag | E39: 1 row West of flag | I39: 1 row East of flag | K39: 1 row West of flag
B40: Plot | C40: # plants /1.5 m | D40: # plants /1.5 m | E40: # plants /1.5 m | F40: Notes | H40: Plot | I40: # plants /1.5 m | J40: # plants /1.5 m | K40: # plants /1.5 m | L40: Notes
B41: 05-01 | C41: 9 | D41: 6 | E41: 11 | H41: 07-01 | I41: 10 | J41: 14 | K41: 12
B42: 05-02 | C42: 8 | D42: 9 | E42: 12 | H42: 07-02 | I42: 14 | J42: 10 | K42: 11
B43: 05-03 | C43: 13 | D43: 11 | E43: 10 | H43: 07-03 | I43: 13 | J43: 11 | K43: 13
B44: 05-04 | C44: 14 | D44: 12 | E44: 13 | H44: 07-04 | I44: 12 | J44: 13 | K44: 14
B45: 05-05 | C45: 11 | D45: 10 | E45: 16 | H45: 07-05 | I45: 12 | J45: 15 | K45: 16
B46: 05-06 | C46: 12 | D46: 11 | E46: 12 | H46: 07-06 | I46: 16 | J46: 12 | K46: 15
B47: 05-07 | C47: 16 | D47: 13 | E47: 14 | H47: 07-07 | I47: 15 | J47: 14 | K47: 12
B48: 05-08 | C48: 14 | D48: 14 | E48: 13 | H48: 07-08 | I48: 11 | J48: 9 | K48: 11
B49: 05-09 | C49: 8 | D49: 8 | E49: 13 | H49: 07-09 | I49: 17 | J49: 13 | K49: 12
B50: 05-10 | C50: 15 | D50: 12 | E50: 13 | H50: 07-10 | I50: 16 | J50: 14 | K50: 13
B51: 05-11 | C51: 13 | D51: 13 | E51: 13 | H51: 07-11 | I51: 18 | J51: 16 | K51: 15
B52: 05-12 | C52: 14 | D52: 13 | E52: 15 | H52: 07-12 | I52: 14 | J52: 16 | K52: 19
... B70: 06-1 | C70: 15 | D70: 13 | E70: 11 | H70: 08-1 | I70: 13 | J70: 12 | K70: 11
C72: 1 row East of flag | E72: 1 row West of flag | I72: 1 row East of flag | K72: 1 row West of flag
B73: Plot | C73: # plants /1.5 m | D73: # plants /1.5 m | E73: # plants /1.5 m | F73: Notes | H73: Plot | I73: # plants /1.5 m | J73: # plants /1.5 m | K73: # plants /1.5 m | L73: Notes
B74: 09-01 | C74: 14 | D74: 17 | E74: 15 | H74: 11-01 | I74: 13 | J74: 12 | K74: 9
B75: 09-02 | C75: 18 | D75: 11 | E75: 13 | H75: 11-02 | I75: 12 | J75: 15 | K75: 13
B76: 09-03 | C76: 15 | D76: 14 | E76: 14 | H76: 11-03 | I76: 11 | J76: 14 | K76: 13
...

Sheet Counts2
F1: PLAPD
A2: 01-01 | B2: 13 | C2: 13 | D2: 12 | F2: =SUM(B2:D2)/(1.5*1.016*3) -> 8.3114611
A3: 01-02 | B3: 12 | C3: 13 | D3: 14 | F3: =SUM(B3:D3)/(1.5*1.016*3) -> 8.5301837
A4: 01-03 | B4: 8 | C4: 11 | D4: 12 | F4: =SUM(B4:D4)/(1.5*1.016*3) -> 6.7804024
A5: 01-04 | B5: 10 | C5: 12 | D5: 11 | F5: =SUM(B5:D5)/(1.5*1.016*3) -> 7.2178478
A6: 01-05 | B6: 11 | C6: 14 | D6: 12 | F6: =SUM(B6:D6)/(1.5*1.016*3) -> 8.0927384
A7: 01-06 | B7: 13 | C7: 12 | D7: 14 | F7: =SUM(B7:D7)/(1.5*1.016*3) -> 8.5301837
A8: 01-07 | B8: 10 | C8: 13 | D8: 13 | F8: =SUM(B8:D8)/(1.5*1.016*3) -> 7.8740157
A9: 01-08 | B9: 15 | C9: 14 | D9: 12 | F9: =SUM(B9:D9)/(1.5*1.016*3) -> 8.967629
A10: 01-09 | B10: 9 | C10: 10 | D10: 13 | F10: =SUM(B10:D10)/(1.5*1.016*3) -> 6.9991251
A11: 01-10 | B11: 11 | C11: 10 | D11: 11 | F11: =SUM(B11:D11)/(1.5*1.016*3) -> 6.9991251
A12: 01-11 | B12: 15 | C12: 12 | D12: 14 | F12: =SUM(B12:D12)/(1.5*1.016*3) -> 8.967629
A13: 01-12 | B13: 13 | C13: 11 | D13: 14 | F13: =SUM(B13:D13)/(1.5*1.016*3) -> 8.3114611
... A181: 12-15 | B181: 13 | C181: 17 | D181: 13 | F181: =SUM(B181:D181)/(1.5*1.016*3) -> 9.4050744

Sheet Emergence1
A1: 2023 | C1: Cotton | D1: Emergence & 1st true leaf
A4: Emergence counts taken at the center flag placed in each plot for canopy measurements
A6: Counting emerged plants 1 meter from North of the flag.
F7: ***"Plants starting to emerge" may not be accurate in plots due to stubble remaining in the planting swath.
G8: But this was just a count I started a few years back to get an idea of emergence over weekends or other times I couldn't get into the field for a few days.
G9: It also gives a little insight into seedling mortality.
C10: # plants per 1 meter (1 meter North of each flag)
B11: Date: | C11: Date: | D11: 45048 | F11: 45050 | H11: 45054 | J11: 45057 | M11: 45061 | P11: 45064
B12: DOY: | C12: DOY: | D12: 122 | F12: 124 | H12: 128 | J12: 131 | M12: 135 | P12: 138
B13: Time: | C13: by: | D13: 1215-1345h | F13: 1015-1140h | H13: 1000-1125h | J13: 1300-1440h | M13: 1000-1145h | P13: 1030-1215h
B15: Plot | D15: plants/1 m | F15: plants/1 m | G15: plants starting to emerge | H15: plants/1 m | I15: plants starting to emerge | J15: plants/1 m | K15: plants starting to emerge | L15: 1st true leaf | M15: plants/1 m | N15: plants starting to emerge | O15: 1st true leaf | P15: plants/1 m | Q15: plants starting to emerge | R15: 1st true leaf
B16: 01-01 | C16: NG4936 | D16: 0 | F16: 3 | G16: 1 | H16: 7 | J16: 9 | M16: 9 | O16: 7 | P16: 9 | R16: 9
B17: 01-02 | C17: NG4936 | D17: 1 | F17: 2 | G17: 3 | H17: 6 | I17: 1 | J17: 8 | M17: 8 | O17: 5 | P17: 8 | R17: 8
B18: 01-03 | C18: NG4936 | D18: 1 | E18: 1 | F18: 5 | H18: 7 | J18: 7 | M18: 7 | O18: 3 | P18: 7 | R18: 6
B19: 01-04 | C19: NG4936 | D19: 1 | F19: 6 | H19: 8 | J19: 8 | M19: 8 | O19: 4 | P19: 8 | R19: 8
B20: 01-05 | C20: NG3195 | D20: 1 | E20: 3 | F20: 9 | H20: 9 | J20: 10 | M20: 10 | O20: 6 | P20: 10 | R20: 10
B21: 01-06 | C21: NG3195 | D21: 0 | F21: 3 | G21: 2 | H21: 6 | J21: 6 | M21: 6 | O21: 2 | P21: 6 | R21: 6
B22: 01-07 | C22: NG3195 | D22: 0 | F22: 2 | G22: 2 | H22: 6 | I22: 1 | J22: 8 | M22: 8 | O22: 6 | P22: 8 | R22: 8
B23: 01-08 | C23: NG3195 | D23: 0 | F23: 6 | G23: 2 | H23: 9 | J23: 9 | M23: 9 | O23: 6 | P23: 9 | R23: 9
B24: 01-09 | C24: NG4936 | D24: 0 | F24: 4 | H24: 6 | J24: 6 | M24: 6 | O24: 2 | P24: 6 | R24: 6
B25: 01-10 | C25: NG4936 | D25: 0 | E25: 1 | F25: 3 | G25: 2 | H25: 5 | I25: 1 | J25: 6 | L25: 1 | M25: 6 | O25: 2 | P25: 6 | R25: 5
B26: 01-11 | C26: NG4936 | D26: 0 | E26: 1 | F26: 2 | G26: 1 | H26: 7 | I26: 1 | J26: 7 | M26: 7 | O26: 4 | P26: 7 | R26: 7
B27: 01-12 | C27: NG4936 | D27: 0 | E27: 1 | F27: 3 | G27: 1 | H27: 6 | J27: 6 | K27: 1 | M27: 7 | O27: 3 | P27: 7 | R27: 7
B28: 01-13 | C28: NG3195 | D28: 0 | F28: 3 | H28: 5 | I28: 2 | J28: 8 | K28: 1 | L28: 1 | M28: 9 | O28: 5 | P28: 9 | R28: 9
B29: 01-14 | C29: NG3195 | D29: 0 | E29: 1 | F29: 3 | G29: 2 | H29: 7 | I29: 1 | J29: 8 | M29: 8 | O29: 5 | P29: 8 | R29: 8
B30: 01-15 | C30: NG3195 | D30: 1 | E30: 1 | F30: 4 | H30: 5 | I30: 1 | J30: 7 | K30: 1 | M30: 8 | O30: 4 | P30: 8 | R30: 8
B31: 02-15 | C31: NG3195 | D31: 3 | E31: 1 | F31: 5 | G31: 1 | H31: 5 | I31: 1 | J31: 6 | L31: 2 | M31: 6 | O31: 5 | P31: 6 | R31: 6
B32: 02-14 | C32: NG3195 | D32: 0 | E32: 2 | F32: 6 | G32: 1 | H32: 8 | I32: 2 | J32: 12 | L32: 1 | M32: 12 | O32: 9 | P32: 12 | R32: 10
B33: 02-13 | C33: NG3195 | D33: 1 | E33: 0 | F33: 3 | G33: 1 | H33: 3 | J33: 3 | L33: 1 | M33: 3 | O33: 2 | P33: 3 | R33: 3
B34: 02-12 | C34: NG3195 | D34: 3 | E34: 1 | F34: 7 | G34: 1 | H34: 10 | J34: 10 | K34: 1 | L34: 1 | M34: 11 | O34: 5 | P34: 11 | R34: 10
B35: 02-11 | C35: NG3195 | D35: 3 | E35: 0 | F35: 4 | H35: 6 | J35: 6 | M35: 6 | O35: 2 | P35: 6 | R35: 6
B36: 02-10 | C36: NG4936 | D36: 2 | E36: 0 | F36: 3 | H36: 3 | J36: 4 | L36: 1 | M36: 4 | O36: 3 | P36: 4 | R36: 4
B37: 02-9 | C37: NG4936 | D37: 1 | E37: 1 | F37: 5 | H37: 6 | J37: 5 | K37: 2 | M37: 7 | O37: 3 | P37: 7 | R37: 7
B38: 02-8 | C38: NG4936 | D38: 0 | E38: 2 | F38: 3 | H38: 4 | J38: 4 | M38: 4 | O38: 2 | P38: 4 | R38: 4
B39: 02-7 | C39: NG4936 | D39: 4 | E39: 1 | F39: 5 | H39: 6 | J39: 6 | K39: 1 | L39: 1 | M39: 7 | O39: 5 | P39: 7 | R39: 7
B40: 02-6 | C40: NG3195 | D40: 0 | E40: 0 | F40: 2 | G40: 1 | H40: 3 | J40: 3 | M40: 3 | O40: 1 | P40: 3 | R40: 3
B41: 02-5 | C41: NG3195 | D41: 3 | E41: 1 | F41: 6 | H41: 8 | I41: 1 | J41: 9 | M41: 9 | O41: 5 | P41: 9 | R41: 9
B42: 02-4 | C42: NG3195 | D42: 5 | E42: 2 | F42: 8 | G42: 1 | H42: 8 | J42: 8 | M42: 8 | O42: 3 | P42: 8 | R42: 8
B43: 02-3 | C43: NG3195 | D43: 4 | E43: 3 | F43: 7 | G43: 2 | H43: 9 | J43: 10 | L43: 1 | M43: 10 | O43: 6 | P43: 10 | R43: 10
B44: 02-2 | C44: NG4936 | D44: 4 | E44: 1 | F44: 8 | H44: 9 | J44: 9 | M44: 9 | O44: 4 | P44: 9 | R44: 9
...

Sheet Emergence2
C1: Emergence | L1: First Leaf
C2: 122 | D2: 124 | E2: 128 | F2: 131 | G2: 135 | H2: 138 | I2: 0.5 | J2: 50% DOY | L2: 131 | M2: 135 | N2: 138 | O2: 50% DOY
A3: 01-01 | B3: NG4936 | C3: 0 | D3: 3 | E3: 7 | F3: 9 | G3: 9 | H3: 9 | I3: =H3/2 -> 4.5 | J3: =D$2+(I3-D3)/(E3-D3)*(E$2-D$2) -> 125.5 | L3: 0 | M3: 7 | N3: 9 | O3: =L$2+(I3-L3)/(M3-L3)*(M$2-L$2) -> 133.57143
A4: 01-02 | B4: NG4936 | C4: 1 | D4: 2 | E4: 6 | F4: 8 | G4: 8 | H4: 8 | I4: =H4/2 -> 4 | J4: =D$2+(I4-D4)/(E4-D4)*(E$2-D$2) -> 126 | L4: 0 | M4: 5 | N4: 8 | O4: =L$2+(I4-L4)/(M4-L4)*(M$2-L$2) -> 134.2
A5: 01-03 | B5: NG4936 | C5: 1 | D5: 5 | E5: 7 | F5: 7 | G5: 7 | H5: 7 | I5: =H5/2 -> 3.5 | J5: =C$2+(I5-C5)/(D5-C5)*(D$2-C$2) -> 123.25 | L5: 0 | M5: 3 | N5: 6 | O5: =M$2+(I5-M5)/(N5-M5)*(N$2-M$2) -> 135.5
A6: 01-04 | B6: NG4936 | C6: 1 | D6: 6 | E6: 8 | F6: 8 | G6: 8 | H6: 8 | I6: =H6/2 -> 4 | J6: =C$2+(I6-C6)/(D6-C6)*(D$2-C$2) -> 123.2 | L6: 0 | M6: 4 | N6: 8 | O6: =M$2+(I6-M6)/(N6-M6)*(N$2-M$2) -> 135
A7: 01-05 | B7: NG3195 | C7: 1 | D7: 9 | E7: 9 | F7: 10 | G7: 10 | H7: 10 | I7: =H7/2 -> 5 | J7: =C$2+(I7-C7)/(D7-C7)*(D$2-C$2) -> 123 | L7: 0 | M7: 6 | N7: 10 | O7: =L$2+(I7-L7)/(M7-L7)*(M$2-L$2) -> 134.33333
A8: 01-06 | B8: NG3195 | C8: 0 | D8: 3 | E8: 6 | F8: 6 | G8: 6 | H8: 6 | I8: =H8/2 -> 3 | J8: =D$2+(I8-D8)/(E8-D8)*(E$2-D$2) -> 124 | L8: 0 | M8: 2 | N8: 6 | O8: =M$2+(I8-M8)/(N8-M8)*(N$2-M$2) -> 135.75
A9: 01-07 | B9: NG3195 | C9: 0 | D9: 2 | E9: 6 | F9: 8 | G9: 8 | H9: 8 | I9: =H9/2 -> 4 | J9: =D$2+(I9-D9)/(E9-D9)*(E$2-D$2) -> 126 | L9: 0 | M9: 6 | N9: 8 | O9: =L$2+(I9-L9)/(M9-L9)*(M$2-L$2) -> 133.66667
A10: 01-08 | B10: NG3195 | C10: 0 | D10: 6 | E10: 9 | F10: 9 | G10: 9 | H10: 9 | I10: =H10/2 -> 4.5 | J10: =C$2+(I10-C10)/(D10-C10)*(D$2-C$2) -> 123.5 | L10: 0 | M10: 6 | N10: 9 | O10: =L$2+(I10-L10)/(M10-L10)*(M$2-L$2) -> 134
A11: 01-09 | B11: NG4936 | C11: 0 | D11: 4 | E11: 6 | F11: 6 | G11: 6 | H11: 6 | I11: =H11/2 -> 3 | J11: =C$2+(I11-C11)/(D11-C11)*(D$2-C$2) -> 123.5 | L11: 0 | M11: 2 | N11: 6 | O11: =M$2+(I11-M11)/(N11-M11)*(N$2-M$2) -> 135.75
A12: 01-10 | B12: NG4936 | C12: 0 | D12: 3 | E12: 5 | F12: 6 | G12: 6 | H12: 6 | I12: =H12/2 -> 3 | J12: =D$2+(I12-D12)/(E12-D12)*(E$2-D$2) -> 124 | L12: 1 | M12: 2 | N12: 5 | O12: =M$2+(I12-M12)/(N12-M12)*(N$2-M$2) -> 136
A13: 01-11 | B13: NG4936 | C13: 0 | D13: 2 | E13: 7 | F13: 7 | G13: 7 | H13: 7 | I13: =H13/2 -> 3.5 | J13: =D$2+(I13-D13)/(E13-D13)*(E$2-D$2) -> 125.2 | L13: 0 | M13: 4 | N13: 7 | O13: =L$2+(I13-L13)/(M13-L13)*(M$2-L$2) -> 134.5
A14: 01-12 | B14: NG4936 | C14: 0 | D14: 3 | E14: 6 | F14: 6 | G14: 7 | H14: 7 | I14: =H14/2 -> 3.5 | J14: =D$2+(I14-D14)/(E14-D14)*(E$2-D$2) -> 124.66667 | L14: 0 | M14: 3 | N14: 7 | O14: =M$2+(I14-M14)/(N14-M14)*(N$2-M$2) -> 135.375
A15: 01-13 | B15: NG3195 | C15: 0 | D15: 3 | E15: 5 | F15: 8 | G15: 9 | H15: 9 | I15: =H15/2 -> 4.5 | J15: =D$2+(I15-D15)/(E15-D15)*(E$2-D$2) -> 127 | L15: 1 | M15: 5 | N15: 9 | O15: =L$2+(I15-L15)/(M15-L15)*(M$2-L$2) -> 134.5
A16: 01-14 | B16: NG3195 | C16: 0 | D16: 3 | E16: 7 | F16: 8 | G16: 8 | H16: 8 | I16: =H16/2 -> 4 | J16: =D$2+(I16-D16)/(E16-D16)*(E$2-D$2) -> 125 | L16: 0 | M16: 5 | N16: 8 | O16: =M$2+(I16-M16)/(N16-M16)*(N$2-M$2) -> 134
A17: 01-15 | B17: NG3195 | C17: 1 | D17: 4 | E17: 5 | F17: 7 | G17: 8 | H17: 8 | I17: =H17/2 -> 4 | J17: =D$2+(I17-D17)/(E17-D17)*(E$2-D$2) -> 124 | L17: 0 | M17: 4 | N17: 8 | O17: =M$2+(I17-M17)/(N17-M17)*(N$2-M$2) -> 135
A18: 02-1 | B18: NG4936 | C18: 2 | D18: 4 | E18: 3 | F18: 4 | G18: 4 | H18: 4 | I18: =H18/2 -> 2 | J18: =C$2+(I18-C18)/(D18-C18)*(D$2-C$2) -> 122 | L18: 0 | M18: 1 | N18: 3 | O18: =M$2+(I18-M18)/(N18-M18)*(N$2-M$2) -> 136.5
A19: 02-2 | B19: NG4936 | C19: 4 | D19: 8 | E19: 9 | F19: 9 | G19: 9 | H19: 9 | I19: =H19/2 -> 4.5 | J19: =C$2+(I19-C19)/(D19-C19)*(D$2-C$2) -> 122.25 | L19: 0 | M19: 4 | N19: 9 | O19: =M$2+(I19-M19)/(N19-M19)*(N$2-M$2) -> 135.3
A20: 02-3 | B20: NG3195 | C20: 4 | D20: 7 | E20: 9 | F20: 10 | G20: 10 | H20: 10 | I20: =H20/2 -> 5 | J20: =C$2+(I20-C20)/(D20-C20)*(D$2-C$2) -> 122.66667 | L20: 1 | M20: 6 | N20: 10 | O20: =L$2+(I20-L20)/(M20-L20)*(M$2-L$2) -> 134.2
A21: 02-4 | B21: NG3195 | C21: 5 | D21: 8 | E21: 8 | F21: 8 | G21: 8 | H21: 8 | I21: =H21/2 -> 4 | J21: =C$2+(I21-C21)/(D21-C21)*(D$2-C$2) -> 121.33333 | L21: 0 | M21: 3 | N21: 8 | O21: =M$2+(I21-M21)/(N21-M21)*(N$2-M$2) -> 135.6
A22: 02-5 | B22: NG3195 | C22: 3 | D22: 6 | E22: 8 | F22: 9 | G22: 9 | H22: 9 | I22: =H22/2 -> 4.5 | J22: =C$2+(I22-C22)/(D22-C22)*(D$2-C$2) -> 123 | L22: 0 | M22: 5 | N22: 9 | O22: =L$2+(I22-L22)/(M22-L22)*(M$2-L$2) -> 134.6
A23: 02-6 | B23: NG3195 | C23: 0 | D23: 2 | E23: 3 | F23: 3 | G23: 3 | H23: 3 | I23: =H23/2 -> 1.5 | J23: =C$2+(I23-C23)/(D23-C23)*(D$2-C$2) -> 123.5 | L23: 0 | M23: 1 | N23: 3 | O23: =M$2+(I23-M23)/(N23-M23)*(N$2-M$2) -> 135.75
A24: 02-7 | B24: NG4936 | C24: 4 | D24: 5 | E24: 6 | F24: 6 | G24: 7 | H24: 7 | I24: =H24/2 -> 3.5 | J24: =C$2+(I24-C24)/(D24-C24)*(D$2-C$2) -> 121 | L24: 1 | M24: 5 | N24: 7 | O24: =L$2+(I24-L24)/(M24-L24)*(M$2-L$2) -> 133.5
A25: 02-8 | B25: NG4936 | C25: 0 | D25: 3 | E25: 4 | F25: 4 | G25: 4 | H25: 4 | I25: =H25/2 -> 2 | J25: =C$2+(I25-C25)/(D25-C25)*(D$2-C$2) -> 123.33333 | L25: 0 | M25: 2 | N25: 4 | O25: =M$2+(I25-M25)/(N25-M25)*(N$2-M$2) -> 135
A26: 02-9 | B26: NG4936 | C26: 1 | D26: 5 | E26: 6 | F26: 5 | G26: 7 | H26: 7 | I26: =H26/2 -> 3.5 | J26: =C$2+(I26-C26)/(D26-C26)*(D$2-C$2) -> 123.25 | L26: 0 | M26: 3 | N26: 7 | O26: =M$2+(I26-M26)/(N26-M26)*(N$2-M$2) -> 135.375
A27: 02-10 | B27: NG4936 | C27: 2 | D27: 3 | E27: 3 | F27: 4 | G27: 4 | H27: 4 | I27: =H27/2 -> 2 | J27: =C$2+(I27-C27)/(D27-C27)*(D$2-C$2) -> 122 | L27: 1 | M27: 3 | N27: 4 | O27: =L$2+(I27-L27)/(M27-L27)*(M$2-L$2) -> 133
A28: 02-11 | B28: NG3195 | C28: 3 | D28: 4 | E28: 6 | F28: 6 | G28: 6 | H28: 6 | I28: =H28/2 -> 3 | J28: =C$2+(I28-C28)/(D28-C28)*(D$2-C$2) -> 122 | L28: 0 | M28: 2 | N28: 6 | O28: =M$2+(I28-M28)/(N28-M28)*(N$2-M$2) -> 135.75
A29: 02-12 | B29: NG3195 | C29: 3 | D29: 7 | E29: 10 | F29: 10 | G29: 11 | H29: 11 | I29: =H29/2 -> 5.5 | J29: =C$2+(I29-C29)/(D29-C29)*(D$2-C$2) -> 123.25 | L29: 1 | M29: 5 | N29: 10 | O29: =M$2+(I29-M29)/(N29-M29)*(N$2-M$2) -> 135.3
A30: 02-13 | B30: NG3195 | C30: 1 | D30: 3 | E30: 3 | F30: 3 | G30: 3 | H30: 3 | I30: =H30/2 -> 1.5 | J30: =C$2+(I30-C30)/(D30-C30)*(D$2-C$2) -> 122.5 | L30: 1 | M30: 2 | N30: 3 | O30: =L$2+(I30-L30)/(M30-L30)*(M$2-L$2) -> 133
A31: 02-14 | B31: NG3195 | C31: 0 | D31: 6 | E31: 8 | F31: 12 | G31: 12 | H31: 12 | I31: =H31/2 -> 6 | J31: =D$2+(I31-D31)/(E31-D31)*(E$2-D$2) -> 124 | L31: 1 | M31: 9 | N31: 10 | O31: =L$2+(I31-L31)/(M31-L31)*(M$2-L$2) -> 133.5
A32: 02-15 | B32: NG3195 | C32: 3 | D32: 5 | E32: 5 | F32: 6 | G32: 6 | H32: 6 | I32: =H32/2 -> 3 | J32: =C$2+(I32-C32)/(D32-C32)*(D$2-C$2) -> 122 | L32: 2 | M32: 5 | N32: 6 | O32: =L$2+(I32-L32)/(M32-L32)*(M$2-L$2) -> 132.33333
A33: 03-01 | B33: NG4936 | C33: 8 | D33: 10 | E33: 11 | F33: 11 | G33: 11 | H33: 11 | I33: =H33/2 -> 5.5 | J33: =C$2+(I33-C33)/(D33-C33)*(D$2-C$2) -> 119.5 | L33: 2 | M33: 8 | N33: 10 | O33: =L$2+(I33-L33)/(M33-L33)*(M$2-L$2) -> 133.33333
A34: 03-02 | B34: NG4936 | C34: 2 | D34: 4 | E34: 6 | F34: 6 | G34: 6 | H34: 6 | I34: =H34/2 -> 3 | J34: =C$2+(I34-C34)/(D34-C34)*(D$2-C$2) -> 123 | L34: 1 | M34: 4 | N34: 6 | O34: =L$2+(I34-L34)/(M34-L34)*(M$2-L$2) -> 133.66667
A35: 03-03 | B35: NG4936 | C35: 1 | D35: 1 | E35: 1 | F35: 1 | G35: 1 | H35: 1 | I35: =H35/2 -> 0.5 | J35: 122 | L35: 0 | M35: 0 | N35: 0 | O35: 135
A36: 03-04 | B36: NG4936 | C36: 6 | D36: 8 | E36: 8 | F36: 8 | G36: 8 | H36: 8 | I36: =H36/2 -> 4 | J36: =C$2+(I36-C36)/(D36-C36)*(D$2-C$2) -> 120 | L36: 1 | M36: 5 | N36: 5 | O36: =L$2+(I36-L36)/(M36-L36)*(M$2-L$2) -> 134
A37: 03-05 | B37: NG4936 | C37: 4 | D37: 5 | E37: 6 | F37: 6 | G37: 6 | H37: 6 | I37: =H37/2 -> 3 | J37: =C$2+(I37-C37)/(D37-C37)*(D$2-C$2) -> 120 | L37: 1 | M37: 4 | N37: 6 | O37: =L$2+(I37-L37)/(M37-L37)*(M$2-L$2) -> 133.66667
A38: 03-06 | B38: NG4936 | C38: 6 | D38: 10 | E38: 10 | F38: 10 | G38: 10 | H38: 10 | I38: =H38/2 -> 5 | J38: =C$2+(I38-C38)/(D38-C38)*(D$2-C$2) -> 121.5 | L38: 2 | M38: 7 | N38: 10 | O38: =L$2+(I38-L38)/(M38-L38)*(M$2-L$2) -> 133.4
A39: 03-07 | B39: NG3195 | C39: 0 | D39: 1 | E39: 2 | F39: 2 | G39: 2 | H39: 2 | I39: =H39/2 -> 1 | J39: =D$2+(I39-D39)/(E39-D39)*(E$2-D$2) -> 124 | L39: 0 | N39: 1 | O39: =L$2+(I39-L39)/(N39-L39)*(N$2-L$2) -> 138
A40: 03-08 | B40: NG3195 | C40: 6 | D40: 9 | E40: 10 | F40: 10 | G40: 10 | H40: 10 | I40: =H40/2 -> 5 | J40: =C$2+(I40-C40)/(D40-C40)*(D$2-C$2) -> 121.33333 | L40: 1 | M40: 5 | N40: 10 | O40: =M$2+(I40-M40)/(N40-M40)*(N$2-M$2) -> 135
...

Sheet Anthesis
A1: 2023 | D1: F1b4 | F1: Cotton
B3: Flowering
B5: Number of plants out of 10 that are flowering. Taken at the flags for canopy measurements.
B7: Date: | C7: 45133 | D7: 45110 | E7: 45120
B8: DOY: | C8: 177 | D8: 184 | E8: 194
B9: Time: | C9: 0830-1130 | D9: 0845-1200 | E9: 0900-1200
B11: Plot | C11: # flowering plants/10 plants | D11: # flowering plants/10 plants | E11: # flowering plants/10 plants | F11: # flowering plants/10 plants | G11: # flowering plants/10 plants | H11: # flowering plants/10 plants | J11: 50% flowering
B12: 01-01 | C12: 2 | D12: 7 | E12: 10 | J12: =C$8+(5-C12)/(D12-C12)*(D$8-C$8) -> 181.2
B13: 01-02 | C13: 1 | D13: 6 | E13: 10 | J13: =C$8+(5-C13)/(D13-C13)*(D$8-C$8) -> 182.6
B14: 01-03 | C14: 1 | D14: 7 | E14: 10 | J14: =C$8+(5-C14)/(D14-C14)*(D$8-C$8) -> 181.66667
B15: 01-04 | C15: 0 | D15: 7 | E15: 10 | J15: =C$8+(5-C15)/(D15-C15)*(D$8-C$8) -> 182
B16: 01-05 | C16: 0 | D16: 6 | E16: 10 | J16: =C$8+(5-C16)/(D16-C16)*(D$8-C$8) -> 182.83333
B17: 01-06 | C17: 0 | D17: 5 | E17: 10 | J17: =C$8+(5-C17)/(D17-C17)*(D$8-C$8) -> 184
B18: 01-07 | C18: 0 | D18: 5 | E18: 10 | J18: =C$8+(5-C18)/(D18-C18)*(D$8-C$8) -> 184
B19: 01-08 | C19: 1 | D19: 7 | E19: 10 | J19: =C$8+(5-C19)/(D19-C19)*(D$8-C$8) -> 181.66667
B20: 01-09 | C20: 0 | D20: 6 | E20: 10 | J20: =C$8+(5-C20)/(D20-C20)*(D$8-C$8) -> 182.83333
B21: 01-10 | C21: 0 | D21: 7 | E21: 10 | J21: =C$8+(5-C21)/(D21-C21)*(D$8-C$8) -> 182
B22: 01-11 | C22: 1 | D22: 7 | E22: 10 | J22: =C$8+(5-C22)/(D22-C22)*(D$8-C$8) -> 181.66667
B23: 01-12 | C23: 1 | D23: 7 | E23: 10 | J23: =C$8+(5-C23)/(D23-C23)*(D$8-C$8) -> 181.66667
... B26: 01-15 | C26: 1 | D26: 7 | E26: 10 | J26: =C$8+(5-C26)/(D26-C26)*(D$8-C$8) -> 181.66667
B27: 02-15 | C27: 0 | D27: 4 | E27: 8 | J27: =D$8+(5-D27)/(E27-D27)*(E$8-D$8) -> 186.5
B28: 02-14 | C28: 1 | D28: 7 | E28: 10 | J28: =C$8+(5-C28)/(D28-C28)*(D$8-C$8) -> 181.66667
B29: 02-13 | C29: 1 | D29: 6 | E29: 10 | J29: =C$8+(5-C29)/(D29-C29)*(D$8-C$8) -> 182.6
B30: 02-12 | C30: 0 | D30: 5 | E30: 10 | J30: =C$8+(5-C30)/(D30-C30)*(D$8-C$8) -> 184
B31: 02-11 | C31: 0 | D31: 5 | E31: 10 | J31: =C$8+(5-C31)/(D31-C31)*(D$8-C$8) -> 184
B32: 02-10 | C32: 0 | D32: 4 | E32: 9 | J32: =D$8+(5-D32)/(E32-D32)*(E$8-D$8) -> 186
B33: 02-9 | C33: 1 | D33: 7 | E33: 10 | J33: =C$8+(5-C33)/(D33-C33)*(D$8-C$8) -> 181.66667
B34: 02-8 | C34: 0 | D34: 6 | E34: 10 | J34: =C$8+(5-C34)/(D34-C34)*(D$8-C$8) -> 182.83333
B35: 02-7 | C35: 0 | D35: 6 | E35: 10 | J35: =C$8+(5-C35)/(D35-C35)*(D$8-C$8) -> 182.83333
B36: 02-6 | C36: 0 | D36: 5 | E36: 10 | J36: =C$8+(5-C36)/(D36-C36)*(D$8-C$8) -> 184
B37: 02-5 | C37: 0 | D37: 5 | E37: 9 | J37: =C$8+(5-C37)/(D37-C37)*(D$8-C$8) -> 184
B38: 02-4 | C38: 0 | D38: 6 | E38: 10 | J38: =C$8+(5-C38)/(D38-C38)*(D$8-C$8) -> 182.83333
B39: 02-3 | C39: 0 | D39: 6 | E39: 10 | J39: =C$8+(5-C39)/(D39-C39)*(D$8-C$8) -> 182.83333
B40: 02-2 | C40: 0 | D40: 6 | E40: 10 | J40: =C$8+(5-C40)/(D40-C40)*(D$8-C$8) -> 182.83333
B41: 02-1 | C41: 1 | D41: 7 | E41: 10 | J41: =C$8+(5-C41)/(D41-C41)*(D$8-C$8) -> 181.66667
B42: 03-01 | C42: 0 | D42: 6 | E42: 10 | J42: =C$8+(5-C42)/(D42-C42)*(D$8-C$8) -> 182.83333
B43: 03-02 | C43: 0 | D43: 5 | E43: 10 | J43: =C$8+(5-C43)/(D43-C43)*(D$8-C$8) -> 184
B44: 03-03 | C44: 1 | D44: 7 | E44: 10 | J44: =C$8+(5-C44)/(D44-C44)*(D$8-C$8) -> 181.66667
... B108: 07-07 | C108: 0 | D108: 5 | E108: 9 | J108: =C$8+(5-C108)/(D108-C108)*(D$8-C$8) -> 184
B109: 07-08 | C109: 0 | D109: 4 | E109: 10 | J109: =D$8+(5-D109)/(E109-D109)*(E$8-D$8) -> 185.66667
...

Sheet NAWFd184
A1: 2023 | B1: F13b4 | C1: Cotton | E1: date: | F1: 45110
B3: Nodes Above White Flower | E3: by: | F3: SMM
B4: Counting the nodes of the upermost white flower in the 1st position of ~11 plants per plot - between the 12 flags that mark the location for the plant heights in a plot.
B6: Plot | C6: NAWF | D6: NAWF | E6: NAWF | F6: NAWF | G6: NAWF | H6: NAWF | I6: NAWF | J6: NAWF | K6: NAWF | L6: NAWF | M6: NAWF | N6: Average
A7: strip | B7: 1 | C7: 6 | D7: 6 | E7: 6 | F7: 7 | G7: 6 | H7: 8 | I7: 7 | J7: 6 | K7: 6 | L7: 6 | M7: 5 | N7: =AVERAGE(C7:M7) -> 6.2727273
A8: no till | B8: 2 | C8: 6 | D8: 7 | E8: 7 | F8: 7 | G8: 8 | H8: 7 | I8: 7 | J8: 8 | K8: 8 | L8: 7 | M8: 7 | N8: =AVERAGE(C8:M8) -> 7.1818182
A9: no till | B9: 3 | C9: 7 | D9: 8 | E9: 8 | F9: 9 | G9: 7 | H9: 7 | I9: 8 | J9: 7 | K9: 7 | L9: 6 | M9: 6 | N9: =AVERAGE(C9:M9) -> 7.2727273
A10: stri | B10: 4 | C10: 5 | D10: 5 | E10: 6 | F10: 9 | G10: 7 | H10: 7 | I10: 7 | J10: 8 | K10: 7 | L10: 6 | M10: 6 | N10: =AVERAGE(C10:M10) -> 6.6363636
A11: no till | B11: 5 | C11: 8 | D11: 7 | E11: 7 | F11: 8 | G11: 7 | H11: 8 | I11: 8 | J11: 7 | K11: 6 | L11: 7 | M11: 6 | N11: =AVERAGE(C11:M11) -> 7.1818182
A12: strip | B12: 6 | C12: 6 | D12: 5 | E12: 6 | F12: 6 | G12: 7 | H12: 7 | I12: 8 | J12: 7 | K12: 8 | L12: 7 | M12: 7 | N12: =AVERAGE(C12:M12) -> 6.7272727
A13: beds | B13: 7 | C13: 6 | D13: 7 | E13: 6 | F13: 6 | G13: 6 | H13: 7 | I13: 7 | J13: 6 | K13: 6 | L13: 7 | M13: 5 | N13: =AVERAGE(C13:M13) -> 6.2727273
A14: flat | B14: 8 | C14: 6 | D14: 6 | E14: 8 | F14: 7 | G14: 7 | H14: 8 | I14: 7 | J14: 6 | K14: 6 | L14: 7 | M14: 7 | N14: =AVERAGE(C14:M14) -> 6.8181818
A15: flat | B15: 9 | C15: 6 | D15: 7 | E15: 8 | F15: 6 | G15: 7 | H15: 8 | I15: 7 | J15: 6 | K15: 7 | L15: 6 | M15: 5 | N15: =AVERAGE(C15:M15) -> 6.6363636
A16: beds | B16: 10 | C16: 4 | D16: 6 | E16: 6 | F16: 7 | G16: 7 | H16: 6 | I16: 6 | J16: 7 | K16: 6 | L16: 6 | M16: 6 | N16: =AVERAGE(C16:M16) -> 6.0909091
A17: flat | B17: 11 | C17: 6 | D17: 6 | E17: 7 | F17: 8 | G17: 8 | H17: 7 | I17: 6 | J17: 6 | K17: 7 | L17: 6 | M17: 7 | N17: =AVERAGE(C17:M17) -> 6.7272727
A18: beds | B18: 12 | C18: 5 | D18: 5 | E18: 6 | F18: 6 | G18: 7 | H18: 7 | I18: 6 | J18: 7 | K18: 6 | L18: 8 | M18: 6 | N18: =AVERAGE(C18:M18) -> 6.2727273

Sheet NAWFd194
A1: 2023 | B1: F13b4 | C1: Cotton | E1: date: | F1: 45120
B3: Nodes Above White Flower | E3: by: | F3: SMM
B4: Counting the nodes of the upermost white flower in the 1st position of ~11 plants per plot - between the 12 flags that mark the location for the plant heights in a plot.
B6: Plot | C6: NAWF | D6: NAWF | E6: NAWF | F6: NAWF | G6: NAWF | H6: NAWF | I6: NAWF | J6: NAWF | K6: NAWF | L6: NAWF | M6: NAWF | N6: Average
A7: strip | B7: 1 | C7: 6 | D7: 6 | E7: 6 | F7: 5 | G7: 7 | H7: 7 | I7: 6 | J7: 5 | K7: 6 | L7: 6 | M7: 5 | N7: =AVERAGE(C7:M7) -> 5.9090909
A8: no till | B8: 2 | C8: 6 | D8: 5 | E8: 7 | F8: 7 | G8: 8 | H8: 7 | I8: 6 | J8: 7 | K8: 7 | L8: 8 | M8: 7 | N8: =AVERAGE(C8:M8) -> 6.8181818
A9: no till | B9: 3 | C9: 7 | D9: 7 | E9: 6 | F9: 8 | G9: 8 | H9: 7 | I9: 5 | J9: 6 | K9: 6 | L9: 7 | M9: 7 | N9: =AVERAGE(C9:M9) -> 6.7272727
A10: stri | B10: 4 | C10: 5 | D10: 5 | E10: 6 | F10: 6 | G10: 6 | H10: 7 | I10: 6 | J10: 6 | K10: 5 | L10: 6 | M10: 6 | N10: =AVERAGE(C10:M10) -> 5.8181818
A11: no till | B11: 5 | C11: 7 | D11: 6 | E11: 7 | F11: 6 | G11: 7 | H11: 6 | I11: 7 | J11: 8 | K11: 6 | L11: 7 | M11: 6 | N11: =AVERAGE(C11:M11) -> 6.6363636
A12: strip | B12: 6 | C12: 4 | D12: 6 | E12: 6 | F12: 7 | G12: 6 | H12: 6 | I12: 5 | J12: 5 | K12: 6 | L12: 6 | M12: 5 | N12: =AVERAGE(C12:M12) -> 5.6363636
A13: beds | B13: 7 | C13: 5 | D13: 5 | E13: 6 | F13: 6 | G13: 7 | H13: 6 | I13: 5 | J13: 6 | K13: 5 | L13: 4 | M13: 4 | N13: =AVERAGE(C13:M13) -> 5.3636364
A14: flat | B14: 8 | C14: 5 | D14: 6 | E14: 6 | F14: 7 | G14: 7 | H14: 7 | I14: 6 | J14: 5 | K14: 5 | L14: 5 | M14: 5 | N14: =AVERAGE(C14:M14) -> 5.8181818
A15: flat | B15: 9 | C15: 6 | D15: 5 | E15: 7 | F15: 6 | G15: 6 | H15: 7 | I15: 8 | J15: 7 | K15: 6 | L15: 5 | M15: 4 | N15: =AVERAGE(C15:M15) -> 6.0909091
A16: beds | B16: 10 | C16: 4 | D16: 4 | E16: 6 | F16: 5 | G16: 6 | H16: 6 | I16: 7 | J16: 6 | K16: 6 | L16: 5 | M16: 6 | N16: =AVERAGE(C16:M16) -> 5.5454545
A17: flat | B17: 11 | C17: 6 | D17: 7 | E17: 6 | F17: 5 | G17: 6 | H17: 7 | I17: 6 | J17: 6 | K17: 6 | L17: 7 | M17: 6 | N17: =AVERAGE(C17:M17) -> 6.1818182
A18: beds | B18: 12 | C18: 3 | D18: 4 | E18: 6 | F18: 6 | G18: 6 | H18: 7 | I18: 6 | J18: 6 | K18: 7 | L18: 6 | M18: 6 | N18: =AVERAGE(C18:M18) -> 5.7272727

Sheet NAWFd201
A1: 2023 | B1: F13b4 | C1: Cotton | E1: date: | F1: 45127
B3: Nodes Above White Flower | E3: by: | F3: SMM
B4: Counting the nodes of the upermost white flower in the 1st position of ~11 plants per plot - between the 12 flags that mark the location for the plant heights in a plot.
B6: Plot | C6: NAWF | D6: NAWF | E6: NAWF | F6: NAWF | G6: NAWF | H6: NAWF | I6: NAWF | J6: NAWF | K6: NAWF | L6: NAWF | M6: NAWF | N6: Average
A7: strip | B7: 1 | C7: 4 | D7: 5 | E7: 4 | F7: 5 | G7: 6 | H7: 5 | I7: 5 | J7: 5 | K7: 4 | L7: 5 | M7: 4 | N7: =AVERAGE(C7:M7) -> 4.7272727
A8: no till | B8: 2 | C8: 3 | D8: 4 | E8: 5 | F8: 5 | G8: 6 | H8: 7 | I8: 5 | J8: 6 | K8: 5 | L8: 5 | M8: 5 | N8: =AVERAGE(C8:M8) -> 5.0909091
A9: no till | B9: 3 | C9: 4 | D9: 5 | E9: 5 | F9: 7 | G9: 5 | H9: 6 | I9: 5 | J9: 6 | K9: 6 | L9: 5 | M9: 4 | N9: =AVERAGE(C9:M9) -> 5.2727273
A10: stri | B10: 4 | C10: 4 | D10: 4 | E10: 4 | F10: 5 | G10: 5 | H10: 4 | I10: 5 | J10: 5 | K10: 5 | L10: 4 | M10: 3 | N10: =AVERAGE(C10:M10) -> 4.3636364
A11: no till | B11: 5 | C11: 5 | D11: 5 | E11: 4 | F11: 5 | G11: 7 | H11: 6 | I11: 6 | J11: 5 | K11: 5 | L11: 4 | M11: 5 | N11: =AVERAGE(C11:M11) -> 5.1818182
A12: strip | B12: 6 | C12: 3 | D12: 3 | E12: 4 | F12: 4 | G12: 5 | H12: 5 | I12: 4 | J12: 5 | K12: 4 | L12: 5 | M12: 4 | N12: =AVERAGE(C12:M12) -> 4.1818182
A13: beds | B13: 7 | C13: 3 | D13: 4 | E13: 3 | F13: 3 | G13: 4 | H13: 5 | I13: 3 | J13: 4 | K13: 4 | L13: 4 | M13: 3 | N13: =AVERAGE(C13:M13) -> 3.6363636
A14: flat | B14: 8 | C14: 3 | D14: 4 | E14: 5 | F14: 4 | G14: 5 | H14: 6 | I14: 4 | J14: 3 | K14: 4 | L14: 3 | M14: 4 | N14: =AVERAGE(C14:M14) -> 4.0909091
A15: flat | B15: 9 | C15: 4 | D15: 3 | E15: 4 | F15: 7 | G15: 5 | H15: 6 | I15: 5 | J15: 5 | K15: 4 | L15: 3 | M15: 2 | N15: =AVERAGE(C15:M15) -> 4.3636364
A16: beds | B16: 10 | C16: 2 | D16: 3 | E16: 4 | F16: 5 | G16: 4 | H16: 5 | I16: 4 | J16: 5 | K16: 5 | L16: 3 | M16: 3 | N16: =AVERAGE(C16:M16) -> 3.9090909
A17: flat | B17: 11 | C17: 4 | D17: 3 | E17: 4 | F17: 5 | G17: 5 | H17: 4 | I17: 6 | J17: 6 | K17: 5 | L17: 4 | M17: 3 | N17: =AVERAGE(C17:M17) -> 4.4545455
A18: beds | B18: 12 | C18: 3 | D18: 3 | E18: 3 | F18: 4 | G18: 4 | H18: 5 | I18: 5 | J18: 4 | K18: 5 | L18: 4 | M18: 4 | N18: =AVERAGE(C18:M18) -> 4

Sheet NAWFd208
A1: 2023 | B1: F13b4 | C1: Cotton | E1: date: | F1: 45134
B3: Nodes Above White Flower | E3: by: | F3: SMM
B4: Counting the nodes of the upermost white flower in the 1st position of ~11 plants per plot - between the 12 flags that mark the location for the plant heights in a plot.
B6: Plot | C6: NAWF | D6: NAWF | E6: NAWF | F6: NAWF | G6: NAWF | H6: NAWF | I6: NAWF | J6: NAWF | K6: NAWF | L6: NAWF | M6: NAWF | N6: Average
A7: strip | B7: 1 | C7: 2 | D7: 3 | E7: 3 | F7: 5 | G7: 4 | H7: 3 | I7: 4 | J7: 3 | K7: 3 | L7: 2 | M7: 2 | N7: =AVERAGE(C7:M7) -> 3.0909091
A8: no till | B8: 2 | C8: 3 | D8: 4 | E8: 3 | F8: 3 | G8: 4 | H8: 3 | I8: 3 | J8: 4 | K8: 5 | L8: 4 | M8: 4 | N8: =AVERAGE(C8:M8) -> 3.6363636
A9: no till | B9: 3 | C9: 3 | D9: 3 | E9: 5 | F9: 4 | G9: 4 | H9: 4 | I9: 4 | J9: 4 | K9: 3 | L9: 3 | M9: 3 | N9: =AVERAGE(C9:M9) -> 3.6363636
A10: stri | B10: 4 | C10: 3 | D10: 2 | E10: 3 | F10: 1 | G10: 2 | H10: 3 | I10: 3 | J10: 3 | K10: 3 | L10: 3 | M10: 2 | N10: =AVERAGE(C10:M10) -> 2.5454545
A11: no till | B11: 5 | C11: 3 | D11: 4 | E11: 5 | F11: 4 | G11: 3 | H11: 4 | I11: 4 | J11: 5 | K11: 5 | L11: 5 | M11: 3 | N11: =AVERAGE(C11:M11) -> 4.0909091
A12: strip | B12: 6 | C12: 3 | D12: 3 | E12: 2 | F12: 3 | G12: 3 | H12: 3 | I12: 2 | J12: 3 | K12: 3 | L12: 2 | M12: 2 | N12: =AVERAGE(C12:M12) -> 2.6363636
A13: beds | B13: 7 | C13: 2 | D13: 2 | E13: 2 | F13: 3 | G13: 3 | H13: 2 | I13: 2 | J13: 1 | K13: 2 | L13: 2 | M13: 2 | N13: =AVERAGE(C13:M13) -> 2.0909091
A14: flat | B14: 8 | C14: 2 | D14: 4 | E14: 4 | F14: 3 | G14: 3 | H14: 4 | I14: 2 | J14: 2 | K14: 3 | L14: 2 | M14: 2 | N14: =AVERAGE(C14:M14) -> 2.8181818
A15: flat | B15: 9 | C15: 2 | D15: 3 | E15: 3 | F15: 4 | G15: 3 | H15: 2 | I15: 4 | J15: 2 | K15: 3 | L15: 4 | M15: 3 | N15: =AVERAGE(C15:M15) -> 3
A16: beds | B16: 10 | C16: 1 | D16: 2 | E16: 2 | F16: 3 | G16: 3 | H16: 3 | I16: 2 | J16: 2 | K16: 3 | L16: 2 | M16: 2 | N16: =AVERAGE(C16:M16) -> 2.2727273
A17: flat | B17: 11 | C17: 2 | D17: 3 | E17: 3 | F17: 2 | G17: 4 | H17: 3 | I17: 3 | J17: 2 | K17: 4 | L17: 2 | M17: 2 | N17: =AVERAGE(C17:M17) -> 2.7272727
A18: beds | B18: 12 | C18: 2 | D18: 2 | E18: 1 | F18: 3 | G18: 2 | H18: 2 | I18: 3 | J18: 2 | K18: 3 | L18: 2 | M18: 2 | N18: =AVERAGE(C18:M18) -> 2.1818182

Sheet NAWFd215
A1: 2023 | B1: F13b4 | C1: Cotton | E1: date: | F1: 45141
B3: Nodes Above White Flower | E3: by: | F3: SMM
B4: Counting the nodes of the upermost white flower in the 1st position of ~11 plants per plot - between the 12 flags that mark the location for the plant heights in a plot.
B6: Plot | C6: NAWF | D6: NAWF | E6: NAWF | F6: NAWF | G6: NAWF | H6: NAWF | I6: NAWF | J6: NAWF | K6: NAWF | L6: NAWF | M6: NAWF | N6: Average
A7: strip | B7: 1 | C7: 1 | D7: 1 | E7: 2 | F7: 4 | G7: 3 | H7: 3 | I7: 3 | J7: 3 | K7: 2 | L7: 2 | M7: 2 | N7: =AVERAGE(C7:M7) -> 2.3636364
A8: no till | B8: 2 | C8: 2 | D8: 3 | E8: 3 | F8: 4 | G8: 3 | H8: 4 | I8: 4 | J8: 3 | K8: 3 | L8: 3 | M8: 2 | N8: =AVERAGE(C8:M8) -> 3.0909091
A9: no till | B9: 3 | C9: 2 | D9: 2 | E9: 3 | F9: 3 | G9: 4 | H9: 5 | I9: 3 | J9: 4 | K9: 3 | L9: 3 | M9: 3 | N9: =AVERAGE(C9:M9) -> 3.1818182
