Workbook

Sheet EXNDVI
A1: Plot | B1: DOY152 | C1: DOY157 | D1: DOY163 | E1: DOY166 | F1: DOY169 | G1: DOY172 | H1: DOY176 | I1: DOY178 | J1: DOY180 | K1: DOY183 | L1: DOY187 | M1: DOY190 | N1: DOY192 | O1: DOY194 | P1: DOY200 | Q1: DOY204 | R1: DOY206 | S1: DOY208 | T1: DOY211 | U1: DOY213 | V1: DOY214 | W1: DOY219 | X1: DOY222 | Y1: DOY225 | Z1: DOY227 | AA1: DOY232 | AB1: DOY234 | AC1: DOY236 | AD1: DOY242 | AE1: DOY247 | AF1: DOY253 | AG1: DOY260 | AH1: DOY263 | AI1: DOY267 | AJ1: DOY269 | AK1: DOY276
A2: Panel 100.1 | B2: =(('Band 4'!B3-'Band 3'!B3)/('Band 3'!B3+'Band 4'!B3)) -> -0.0001 | C2: =(('Band 4'!C3-'Band 3'!C3)/('Band 3'!C3+'Band 4'!C3)) -> -9.9700897e-05 | D2: =(('Band 4'!D3-'Band 3'!D3)/('Band 3'!D3+'Band 4'!D3)) -> -9.9700897e-05 | E2: =(('Band 4'!E3-'Band 3'!E3)/('Band 3'!E3+'Band 4'!E3)) -> -0.00010009008 | F2: =(('Band 4'!F3-'Band 3'!F3)/('Band 3'!F3+'Band 4'!F3)) -> -0.00015074619 | G2: =(('Band 4'!G3-'Band 3'!G3)/('Band 3'!G3+'Band 4'!G3)) -> -9.9850225e-05 | H2: =(('Band 4'!H3-'Band 3'!H3)/('Band 3'!H3+'Band 4'!H3)) -> -0.0001005935 | I2: =(('Band 4'!I3-'Band 3'!I3)/('Band 3'!I3+'Band 4'!I3)) -> -0.00010033109 | ... AK2: =(('Band 4'!AK3-'Band 3'!AK3)/('Band 3'!AK3+'Band 4'!AK3)) -> -0.00015181418
A3: Panel 70.1 | B3: =(('Band 4'!B4-'Band 3'!B4)/('Band 3'!B4+'Band 4'!B4)) -> 0.73281135 | C3: =(('Band 4'!C4-'Band 3'!C4)/('Band 3'!C4+'Band 4'!C4)) -> 0.65139371 | D3: =(('Band 4'!D4-'Band 3'!D4)/('Band 3'!D4+'Band 4'!D4)) -> 0.65158028 | E3: =(('Band 4'!E4-'Band 3'!E4)/('Band 3'!E4+'Band 4'!E4)) -> 0.6520184 | F3: =(('Band 4'!F4-'Band 3'!F4)/('Band 3'!F4+'Band 4'!F4)) -> 0.65236271 | G3: =(('Band 4'!G4-'Band 3'!G4)/('Band 3'!G4+'Band 4'!G4)) -> 0.65158831 | H3: =(('Band 4'!H4-'Band 3'!H4)/('Band 3'!H4+'Band 4'!H4)) -> 0.6518509 | I3: =(('Band 4'!I4-'Band 3'!I4)/('Band 3'!I4+'Band 4'!I4)) -> 0.65257376 | ... AK3: =(('Band 4'!AK4-'Band 3'!AK4)/('Band 3'!AK4+'Band 4'!AK4)) -> 0.65320911
A4: p41 | B4: =(('Band 4'!B5-'Band 3'!B5)/('Band 3'!B5+'Band 4'!B5)) -> 0.14820497 | C4: =(('Band 4'!C5-'Band 3'!C5)/('Band 3'!C5+'Band 4'!C5)) -> 0.18913707 | D4: =(('Band 4'!D5-'Band 3'!D5)/('Band 3'!D5+'Band 4'!D5)) -> 0.21889401 | E4: =(('Band 4'!E5-'Band 3'!E5)/('Band 3'!E5+'Band 4'!E5)) -> 0.26540173 | F4: =(('Band 4'!F5-'Band 3'!F5)/('Band 3'!F5+'Band 4'!F5)) -> 0.28585961 | G4: =(('Band 4'!G5-'Band 3'!G5)/('Band 3'!G5+'Band 4'!G5)) -> 0.29610984 | H4: =(('Band 4'!H5-'Band 3'!H5)/('Band 3'!H5+'Band 4'!H5)) -> 0.35919283 | I4: =(('Band 4'!I5-'Band 3'!I5)/('Band 3'!I5+'Band 4'!I5)) -> 0.41515082 | ... AK4: =(('Band 4'!AK5-'Band 3'!AK5)/('Band 3'!AK5+'Band 4'!AK5)) -> 0.67364991
A5: p42 | B5: =(('Band 4'!B6-'Band 3'!B6)/('Band 3'!B6+'Band 4'!B6)) -> 0.13571211 | C5: =(('Band 4'!C6-'Band 3'!C6)/('Band 3'!C6+'Band 4'!C6)) -> 0.16143565 | D5: =(('Band 4'!D6-'Band 3'!D6)/('Band 3'!D6+'Band 4'!D6)) -> 0.16804889 | E5: =(('Band 4'!E6-'Band 3'!E6)/('Band 3'!E6+'Band 4'!E6)) -> 0.20883251 | F5: =(('Band 4'!F6-'Band 3'!F6)/('Band 3'!F6+'Band 4'!F6)) -> 0.23560976 | G5: =(('Band 4'!G6-'Band 3'!G6)/('Band 3'!G6+'Band 4'!G6)) -> 0.27305936 | H5: =(('Band 4'!H6-'Band 3'!H6)/('Band 3'!H6+'Band 4'!H6)) -> 0.3257719 | I5: =(('Band 4'!I6-'Band 3'!I6)/('Band 3'!I6+'Band 4'!I6)) -> 0.39855381 | ... AK5: =(('Band 4'!AK6-'Band 3'!AK6)/('Band 3'!AK6+'Band 4'!AK6)) -> 0.75305006
A6: p43 | B6: =(('Band 4'!B7-'Band 3'!B7)/('Band 3'!B7+'Band 4'!B7)) -> 0.13840457 | C6: =(('Band 4'!C7-'Band 3'!C7)/('Band 3'!C7+'Band 4'!C7)) -> 0.15839809 | D6: =(('Band 4'!D7-'Band 3'!D7)/('Band 3'!D7+'Band 4'!D7)) -> 0.17348019 | E6: =(('Band 4'!E7-'Band 3'!E7)/('Band 3'!E7+'Band 4'!E7)) -> 0.19663315 | F6: =(('Band 4'!F7-'Band 3'!F7)/('Band 3'!F7+'Band 4'!F7)) -> 0.22257053 | G6: =(('Band 4'!G7-'Band 3'!G7)/('Band 3'!G7+'Band 4'!G7)) -> 0.27294285 | H6: =(('Band 4'!H7-'Band 3'!H7)/('Band 3'!H7+'Band 4'!H7)) -> 0.29201331 | I6: =(('Band 4'!I7-'Band 3'!I7)/('Band 3'!I7+'Band 4'!I7)) -> 0.33462616 | ... AK6: =(('Band 4'!AK7-'Band 3'!AK7)/('Band 3'!AK7+'Band 4'!AK7)) -> 0.59413854
A7: p44 | B7: =(('Band 4'!B8-'Band 3'!B8)/('Band 3'!B8+'Band 4'!B8)) -> 0.14441502 | C7: =(('Band 4'!C8-'Band 3'!C8)/('Band 3'!C8+'Band 4'!C8)) -> 0.1635876 | D7: =(('Band 4'!D8-'Band 3'!D8)/('Band 3'!D8+'Band 4'!D8)) -> 0.17040261 | E7: =(('Band 4'!E8-'Band 3'!E8)/('Band 3'!E8+'Band 4'!E8)) -> 0.17870722 | F7: =(('Band 4'!F8-'Band 3'!F8)/('Band 3'!F8+'Band 4'!F8)) -> 0.18765192 | G7: =(('Band 4'!G8-'Band 3'!G8)/('Band 3'!G8+'Band 4'!G8)) -> 0.22884013 | H7: =(('Band 4'!H8-'Band 3'!H8)/('Band 3'!H8+'Band 4'!H8)) -> 0.25345069 | I7: =(('Band 4'!I8-'Band 3'!I8)/('Band 3'!I8+'Band 4'!I8)) -> 0.27295703 | ... AK7: =(('Band 4'!AK8-'Band 3'!AK8)/('Band 3'!AK8+'Band 4'!AK8)) -> 0.68960935
A8: p45 | B8: =(('Band 4'!B9-'Band 3'!B9)/('Band 3'!B9+'Band 4'!B9)) -> 0.16169943 | C8: =(('Band 4'!C9-'Band 3'!C9)/('Band 3'!C9+'Band 4'!C9)) -> 0.18031746 | D8: =(('Band 4'!D9-'Band 3'!D9)/('Band 3'!D9+'Band 4'!D9)) -> 0.19148936 | E8: =(('Band 4'!E9-'Band 3'!E9)/('Band 3'!E9+'Band 4'!E9)) -> 0.23589395 | F8: =(('Band 4'!F9-'Band 3'!F9)/('Band 3'!F9+'Band 4'!F9)) -> 0.26699463 | G8: =(('Band 4'!G9-'Band 3'!G9)/('Band 3'!G9+'Band 4'!G9)) -> 0.25657895 | H8: =(('Band 4'!H9-'Band 3'!H9)/('Band 3'!H9+'Band 4'!H9)) -> 0.32302937 | I8: =(('Band 4'!I9-'Band 3'!I9)/('Band 3'!I9+'Band 4'!I9)) -> 0.36726967 | ... AK8: =(('Band 4'!AK9-'Band 3'!AK9)/('Band 3'!AK9+'Band 4'!AK9)) -> 0.71684817
A9: p46 | B9: =(('Band 4'!B10-'Band 3'!B10)/('Band 3'!B10+'Band 4'!B10)) -> 0.14517363 | C9: =(('Band 4'!C10-'Band 3'!C10)/('Band 3'!C10+'Band 4'!C10)) -> 0.19691703 | D9: =(('Band 4'!D10-'Band 3'!D10)/('Band 3'!D10+'Band 4'!D10)) -> 0.22038981 | E9: =(('Band 4'!E10-'Band 3'!E10)/('Band 3'!E10+'Band 4'!E10)) -> 0.29021559 | F9: =(('Band 4'!F10-'Band 3'!F10)/('Band 3'!F10+'Band 4'!F10)) -> 0.31823657 | G9: =(('Band 4'!G10-'Band 3'!G10)/('Band 3'!G10+'Band 4'!G10)) -> 0.36670459 | H9: =(('Band 4'!H10-'Band 3'!H10)/('Band 3'!H10+'Band 4'!H10)) -> 0.47990868 | I9: =(('Band 4'!I10-'Band 3'!I10)/('Band 3'!I10+'Band 4'!I10)) -> 0.51185138 | ... AK9: =(('Band 4'!AK10-'Band 3'!AK10)/('Band 3'!AK10+'Band 4'!AK10)) -> 0.73905579
A10: p47 | B10: =(('Band 4'!B11-'Band 3'!B11)/('Band 3'!B11+'Band 4'!B11)) -> 0.14890354 | C10: =(('Band 4'!C11-'Band 3'!C11)/('Band 3'!C11+'Band 4'!C11)) -> 0.17430065 | D10: =(('Band 4'!D11-'Band 3'!D11)/('Band 3'!D11+'Band 4'!D11)) -> 0.2049948 | E10: =(('Band 4'!E11-'Band 3'!E11)/('Band 3'!E11+'Band 4'!E11)) -> 0.25332721 | F10: =(('Band 4'!F11-'Band 3'!F11)/('Band 3'!F11+'Band 4'!F11)) -> 0.27355989 | G10: =(('Band 4'!G11-'Band 3'!G11)/('Band 3'!G11+'Band 4'!G11)) -> 0.33140826 | H10: =(('Band 4'!H11-'Band 3'!H11)/('Band 3'!H11+'Band 4'!H11)) -> 0.41443486 | I10: =(('Band 4'!I11-'Band 3'!I11)/('Band 3'!I11+'Band 4'!I11)) -> 0.4097178 | ... AK10: =(('Band 4'!AK11-'Band 3'!AK11)/('Band 3'!AK11+'Band 4'!AK11)) -> 0.66617367
A11: p48 | B11: =(('Band 4'!B12-'Band 3'!B12)/('Band 3'!B12+'Band 4'!B12)) -> 0.13716545 | C11: =(('Band 4'!C12-'Band 3'!C12)/('Band 3'!C12+'Band 4'!C12)) -> 0.14808986 | D11: =(('Band 4'!D12-'Band 3'!D12)/('Band 3'!D12+'Band 4'!D12)) -> 0.18451121 | E11: =(('Band 4'!E12-'Band 3'!E12)/('Band 3'!E12+'Band 4'!E12)) -> 0.22143865 | F11: =(('Band 4'!F12-'Band 3'!F12)/('Band 3'!F12+'Band 4'!F12)) -> 0.23715415 | G11: =(('Band 4'!G12-'Band 3'!G12)/('Band 3'!G12+'Band 4'!G12)) -> 0.25515174 | H11: =(('Band 4'!H12-'Band 3'!H12)/('Band 3'!H12+'Band 4'!H12)) -> 0.34008176 | I11: =(('Band 4'!I12-'Band 3'!I12)/('Band 3'!I12+'Band 4'!I12)) -> 0.4043573 | ... AK11: =(('Band 4'!AK12-'Band 3'!AK12)/('Band 3'!AK12+'Band 4'!AK12)) -> 0.68268839
A12: p38 | B12: =(('Band 4'!B13-'Band 3'!B13)/('Band 3'!B13+'Band 4'!B13)) -> 0.14204787 | C12: =(('Band 4'!C13-'Band 3'!C13)/('Band 3'!C13+'Band 4'!C13)) -> 0.18513458 | D12: =(('Band 4'!D13-'Band 3'!D13)/('Band 3'!D13+'Band 4'!D13)) -> 0.20244399 | E12: =(('Band 4'!E13-'Band 3'!E13)/('Band 3'!E13+'Band 4'!E13)) -> 0.25468717 | F12: =(('Band 4'!F13-'Band 3'!F13)/('Band 3'!F13+'Band 4'!F13)) -> 0.27285068 | G12: =(('Band 4'!G13-'Band 3'!G13)/('Band 3'!G13+'Band 4'!G13)) -> 0.30042194 | H12: =(('Band 4'!H13-'Band 3'!H13)/('Band 3'!H13+'Band 4'!H13)) -> 0.35591944 | I12: =(('Band 4'!I13-'Band 3'!I13)/('Band 3'!I13+'Band 4'!I13)) -> 0.41445428 | ... AK12: =(('Band 4'!AK13-'Band 3'!AK13)/('Band 3'!AK13+'Band 4'!AK13)) -> 0.62450962
A13: p37 | B13: =(('Band 4'!B14-'Band 3'!B14)/('Band 3'!B14+'Band 4'!B14)) -> 0.13073005 | C13: =(('Band 4'!C14-'Band 3'!C14)/('Band 3'!C14+'Band 4'!C14)) -> 0.15256496 | D13: =(('Band 4'!D14-'Band 3'!D14)/('Band 3'!D14+'Band 4'!D14)) -> 0.18365019 | E13: =(('Band 4'!E14-'Band 3'!E14)/('Band 3'!E14+'Band 4'!E14)) -> 0.19686888 | F13: =(('Band 4'!F14-'Band 3'!F14)/('Band 3'!F14+'Band 4'!F14)) -> 0.22259136 | G13: =(('Band 4'!G14-'Band 3'!G14)/('Band 3'!G14+'Band 4'!G14)) -> 0.22733964 | H13: =(('Band 4'!H14-'Band 3'!H14)/('Band 3'!H14+'Band 4'!H14)) -> 0.26681957 | I13: =(('Band 4'!I14-'Band 3'!I14)/('Band 3'!I14+'Band 4'!I14)) -> 0.31434109 | ... AK13: =(('Band 4'!AK14-'Band 3'!AK14)/('Band 3'!AK14+'Band 4'!AK14)) -> 0.74825432
... A46: Panel 100.3 | B46: =(('Band 4'!B47-'Band 3'!B47)/('Band 3'!B47+'Band 4'!B47)) -> 0 | C46: =(('Band 4'!C47-'Band 3'!C47)/('Band 3'!C47+'Band 4'!C47)) -> 0 | D46: =(('Band 4'!D47-'Band 3'!D47)/('Band 3'!D47+'Band 4'!D47)) -> 4.872582e-05 | E46: =(('Band 4'!E47-'Band 3'!E47)/('Band 3'!E47+'Band 4'!E47)) -> -4.9360778e-05 | F46: =(('Band 4'!F47-'Band 3'!F47)/('Band 3'!F47+'Band 4'!F47)) -> -9.9098206e-05 | G46: =(('Band 4'!G47-'Band 3'!G47)/('Band 3'!G47+'Band 4'!G47)) -> 0 | H46: =(('Band 4'!H47-'Band 3'!H47)/('Band 3'!H47+'Band 4'!H47)) -> -9.9088387e-05 | I46: =(('Band 4'!I47-'Band 3'!I47)/('Band 3'!I47+'Band 4'!I47)) -> -4.9433981e-05 | ... AK46: =(('Band 4'!AK47-'Band 3'!AK47)/('Band 3'!AK47+'Band 4'!AK47)) -> -0.00014985764
A47: Quality | B47: 2 | C47: 3 | D47: 3 | E47: 2 | F47: 2 | G47: 0 | H47: 1 | I47: 2 | J47: 3 | K47: 2 | L47: 2 | M47: 2 | N47: 3 | O47: 3 | P47: 2 | Q47: 5 | R47: 4 | S47: 4 | T47: 4 | U47: 3 | V47: 2 | W47: 3 | X47: 2 | Y47: 3 | Z47: 3 | AA47: 2 | AB47: 2 | AC47: 2 | AD47: 2 | AE47: 3 | AF47: 2 | AG47: 2 | AH47: 2 | AI47: 2 | AJ47: 1 | AK47: 2

Sheet NDVI
B1: DOY
A2: Plot | B2: 152 | C2: 157 | D2: 163 | E2: 166 | F2: 169 | G2: 172 | H2: 176 | I2: 178 | J2: 180 | K2: 183 | L2: 187 | M2: 190 | N2: 192 | O2: 194 | P2: 200 | Q2: 204 | R2: 206 | S2: 208 | T2: 211 | U2: 213 | V2: 214 | W2: 219 | X2: 222 | Y2: 225 | Z2: 227 | AA2: 232 | AB2: 234 | AC2: 236 | AD2: 242 | AE2: 247 | AF2: 253 | AG2: 260 | AH2: 263 | AI2: 267 | AJ2: 269 | AK2: 276
A3: Panel 100.1 | B3: =(('Band 4'!B3-'Band 3'!B3)/('Band 3'!B3+'Band 4'!B3)) -> -0.0001 | C3: =(('Band 4'!C3-'Band 3'!C3)/('Band 3'!C3+'Band 4'!C3)) -> -9.9700897e-05 | D3: =(('Band 4'!D3-'Band 3'!D3)/('Band 3'!D3+'Band 4'!D3)) -> -9.9700897e-05 | E3: =(('Band 4'!E3-'Band 3'!E3)/('Band 3'!E3+'Band 4'!E3)) -> -0.00010009008 | F3: =(('Band 4'!F3-'Band 3'!F3)/('Band 3'!F3+'Band 4'!F3)) -> -0.00015074619 | G3: =(('Band 4'!G3-'Band 3'!G3)/('Band 3'!G3+'Band 4'!G3)) -> -9.9850225e-05 | H3: =(('Band 4'!H3-'Band 3'!H3)/('Band 3'!H3+'Band 4'!H3)) -> -0.0001005935 | I3: =(('Band 4'!I3-'Band 3'!I3)/('Band 3'!I3+'Band 4'!I3)) -> -0.00010033109 | ... AK3: =(('Band 4'!AK3-'Band 3'!AK3)/('Band 3'!AK3+'Band 4'!AK3)) -> -0.00015181418
A4: Panel 70.1 | B4: =(('Band 4'!B4-'Band 3'!B4)/('Band 3'!B4+'Band 4'!B4)) -> 0.73281135 | C4: =(('Band 4'!C4-'Band 3'!C4)/('Band 3'!C4+'Band 4'!C4)) -> 0.65139371 | D4: =(('Band 4'!D4-'Band 3'!D4)/('Band 3'!D4+'Band 4'!D4)) -> 0.65158028 | E4: =(('Band 4'!E4-'Band 3'!E4)/('Band 3'!E4+'Band 4'!E4)) -> 0.6520184 | F4: =(('Band 4'!F4-'Band 3'!F4)/('Band 3'!F4+'Band 4'!F4)) -> 0.65236271 | G4: =(('Band 4'!G4-'Band 3'!G4)/('Band 3'!G4+'Band 4'!G4)) -> 0.65158831 | H4: =(('Band 4'!H4-'Band 3'!H4)/('Band 3'!H4+'Band 4'!H4)) -> 0.6518509 | I4: =(('Band 4'!I4-'Band 3'!I4)/('Band 3'!I4+'Band 4'!I4)) -> 0.65257376 | ... AK4: =(('Band 4'!AK4-'Band 3'!AK4)/('Band 3'!AK4+'Band 4'!AK4)) -> 0.65320911
A5: 41 | B5: =(('Band 4'!B5-'Band 3'!B5)/('Band 3'!B5+'Band 4'!B5)) -> 0.14820497 | C5: =(('Band 4'!C5-'Band 3'!C5)/('Band 3'!C5+'Band 4'!C5)) -> 0.18913707 | D5: =(('Band 4'!D5-'Band 3'!D5)/('Band 3'!D5+'Band 4'!D5)) -> 0.21889401 | E5: =(('Band 4'!E5-'Band 3'!E5)/('Band 3'!E5+'Band 4'!E5)) -> 0.26540173 | F5: =(('Band 4'!F5-'Band 3'!F5)/('Band 3'!F5+'Band 4'!F5)) -> 0.28585961 | G5: =(('Band 4'!G5-'Band 3'!G5)/('Band 3'!G5+'Band 4'!G5)) -> 0.29610984 | H5: =(('Band 4'!H5-'Band 3'!H5)/('Band 3'!H5+'Band 4'!H5)) -> 0.35919283 | I5: =(('Band 4'!I5-'Band 3'!I5)/('Band 3'!I5+'Band 4'!I5)) -> 0.41515082 | ... AK5: =(('Band 4'!AK5-'Band 3'!AK5)/('Band 3'!AK5+'Band 4'!AK5)) -> 0.67364991
A6: 42 | B6: =(('Band 4'!B6-'Band 3'!B6)/('Band 3'!B6+'Band 4'!B6)) -> 0.13571211 | C6: =(('Band 4'!C6-'Band 3'!C6)/('Band 3'!C6+'Band 4'!C6)) -> 0.16143565 | D6: =(('Band 4'!D6-'Band 3'!D6)/('Band 3'!D6+'Band 4'!D6)) -> 0.16804889 | E6: =(('Band 4'!E6-'Band 3'!E6)/('Band 3'!E6+'Band 4'!E6)) -> 0.20883251 | F6: =(('Band 4'!F6-'Band 3'!F6)/('Band 3'!F6+'Band 4'!F6)) -> 0.23560976 | G6: =(('Band 4'!G6-'Band 3'!G6)/('Band 3'!G6+'Band 4'!G6)) -> 0.27305936 | H6: =(('Band 4'!H6-'Band 3'!H6)/('Band 3'!H6+'Band 4'!H6)) -> 0.3257719 | I6: =(('Band 4'!I6-'Band 3'!I6)/('Band 3'!I6+'Band 4'!I6)) -> 0.39855381 | ... AK6: =(('Band 4'!AK6-'Band 3'!AK6)/('Band 3'!AK6+'Band 4'!AK6)) -> 0.75305006
A7: 43 | B7: =(('Band 4'!B7-'Band 3'!B7)/('Band 3'!B7+'Band 4'!B7)) -> 0.13840457 | C7: =(('Band 4'!C7-'Band 3'!C7)/('Band 3'!C7+'Band 4'!C7)) -> 0.15839809 | D7: =(('Band 4'!D7-'Band 3'!D7)/('Band 3'!D7+'Band 4'!D7)) -> 0.17348019 | E7: =(('Band 4'!E7-'Band 3'!E7)/('Band 3'!E7+'Band 4'!E7)) -> 0.19663315 | F7: =(('Band 4'!F7-'Band 3'!F7)/('Band 3'!F7+'Band 4'!F7)) -> 0.22257053 | G7: =(('Band 4'!G7-'Band 3'!G7)/('Band 3'!G7+'Band 4'!G7)) -> 0.27294285 | H7: =(('Band 4'!H7-'Band 3'!H7)/('Band 3'!H7+'Band 4'!H7)) -> 0.29201331 | I7: =(('Band 4'!I7-'Band 3'!I7)/('Band 3'!I7+'Band 4'!I7)) -> 0.33462616 | ... AK7: =(('Band 4'!AK7-'Band 3'!AK7)/('Band 3'!AK7+'Band 4'!AK7)) -> 0.59413854
A8: 44 | B8: =(('Band 4'!B8-'Band 3'!B8)/('Band 3'!B8+'Band 4'!B8)) -> 0.14441502 | C8: =(('Band 4'!C8-'Band 3'!C8)/('Band 3'!C8+'Band 4'!C8)) -> 0.1635876 | D8: =(('Band 4'!D8-'Band 3'!D8)/('Band 3'!D8+'Band 4'!D8)) -> 0.17040261 | E8: =(('Band 4'!E8-'Band 3'!E8)/('Band 3'!E8+'Band 4'!E8)) -> 0.17870722 | F8: =(('Band 4'!F8-'Band 3'!F8)/('Band 3'!F8+'Band 4'!F8)) -> 0.18765192 | G8: =(('Band 4'!G8-'Band 3'!G8)/('Band 3'!G8+'Band 4'!G8)) -> 0.22884013 | H8: =(('Band 4'!H8-'Band 3'!H8)/('Band 3'!H8+'Band 4'!H8)) -> 0.25345069 | I8: =(('Band 4'!I8-'Band 3'!I8)/('Band 3'!I8+'Band 4'!I8)) -> 0.27295703 | ... AK8: =(('Band 4'!AK8-'Band 3'!AK8)/('Band 3'!AK8+'Band 4'!AK8)) -> 0.68960935
A9: 45 | B9: =(('Band 4'!B9-'Band 3'!B9)/('Band 3'!B9+'Band 4'!B9)) -> 0.16169943 | C9: =(('Band 4'!C9-'Band 3'!C9)/('Band 3'!C9+'Band 4'!C9)) -> 0.18031746 | D9: =(('Band 4'!D9-'Band 3'!D9)/('Band 3'!D9+'Band 4'!D9)) -> 0.19148936 | E9: =(('Band 4'!E9-'Band 3'!E9)/('Band 3'!E9+'Band 4'!E9)) -> 0.23589395 | F9: =(('Band 4'!F9-'Band 3'!F9)/('Band 3'!F9+'Band 4'!F9)) -> 0.26699463 | G9: =(('Band 4'!G9-'Band 3'!G9)/('Band 3'!G9+'Band 4'!G9)) -> 0.25657895 | H9: =(('Band 4'!H9-'Band 3'!H9)/('Band 3'!H9+'Band 4'!H9)) -> 0.32302937 | I9: =(('Band 4'!I9-'Band 3'!I9)/('Band 3'!I9+'Band 4'!I9)) -> 0.36726967 | ... AK9: =(('Band 4'!AK9-'Band 3'!AK9)/('Band 3'!AK9+'Band 4'!AK9)) -> 0.71684817
A10: 46 | B10: =(('Band 4'!B10-'Band 3'!B10)/('Band 3'!B10+'Band 4'!B10)) -> 0.14517363 | C10: =(('Band 4'!C10-'Band 3'!C10)/('Band 3'!C10+'Band 4'!C10)) -> 0.19691703 | D10: =(('Band 4'!D10-'Band 3'!D10)/('Band 3'!D10+'Band 4'!D10)) -> 0.22038981 | E10: =(('Band 4'!E10-'Band 3'!E10)/('Band 3'!E10+'Band 4'!E10)) -> 0.29021559 | F10: =(('Band 4'!F10-'Band 3'!F10)/('Band 3'!F10+'Band 4'!F10)) -> 0.31823657 | G10: =(('Band 4'!G10-'Band 3'!G10)/('Band 3'!G10+'Band 4'!G10)) -> 0.36670459 | H10: =(('Band 4'!H10-'Band 3'!H10)/('Band 3'!H10+'Band 4'!H10)) -> 0.47990868 | I10: =(('Band 4'!I10-'Band 3'!I10)/('Band 3'!I10+'Band 4'!I10)) -> 0.51185138 | ... AK10: =(('Band 4'!AK10-'Band 3'!AK10)/('Band 3'!AK10+'Band 4'!AK10)) -> 0.73905579
A11: 47 | B11: =(('Band 4'!B11-'Band 3'!B11)/('Band 3'!B11+'Band 4'!B11)) -> 0.14890354 | C11: =(('Band 4'!C11-'Band 3'!C11)/('Band 3'!C11+'Band 4'!C11)) -> 0.17430065 | D11: =(('Band 4'!D11-'Band 3'!D11)/('Band 3'!D11+'Band 4'!D11)) -> 0.2049948 | E11: =(('Band 4'!E11-'Band 3'!E11)/('Band 3'!E11+'Band 4'!E11)) -> 0.25332721 | F11: =(('Band 4'!F11-'Band 3'!F11)/('Band 3'!F11+'Band 4'!F11)) -> 0.27355989 | G11: =(('Band 4'!G11-'Band 3'!G11)/('Band 3'!G11+'Band 4'!G11)) -> 0.33140826 | H11: =(('Band 4'!H11-'Band 3'!H11)/('Band 3'!H11+'Band 4'!H11)) -> 0.41443486 | I11: =(('Band 4'!I11-'Band 3'!I11)/('Band 3'!I11+'Band 4'!I11)) -> 0.4097178 | ... AK11: =(('Band 4'!AK11-'Band 3'!AK11)/('Band 3'!AK11+'Band 4'!AK11)) -> 0.66617367
A12: 48 | B12: =(('Band 4'!B12-'Band 3'!B12)/('Band 3'!B12+'Band 4'!B12)) -> 0.13716545 | C12: =(('Band 4'!C12-'Band 3'!C12)/('Band 3'!C12+'Band 4'!C12)) -> 0.14808986 | D12: =(('Band 4'!D12-'Band 3'!D12)/('Band 3'!D12+'Band 4'!D12)) -> 0.18451121 | E12: =(('Band 4'!E12-'Band 3'!E12)/('Band 3'!E12+'Band 4'!E12)) -> 0.22143865 | F12: =(('Band 4'!F12-'Band 3'!F12)/('Band 3'!F12+'Band 4'!F12)) -> 0.23715415 | G12: =(('Band 4'!G12-'Band 3'!G12)/('Band 3'!G12+'Band 4'!G12)) -> 0.25515174 | H12: =(('Band 4'!H12-'Band 3'!H12)/('Band 3'!H12+'Band 4'!H12)) -> 0.34008176 | I12: =(('Band 4'!I12-'Band 3'!I12)/('Band 3'!I12+'Band 4'!I12)) -> 0.4043573 | ... AK12: =(('Band 4'!AK12-'Band 3'!AK12)/('Band 3'!AK12+'Band 4'!AK12)) -> 0.68268839
A13: 38 | B13: =(('Band 4'!B13-'Band 3'!B13)/('Band 3'!B13+'Band 4'!B13)) -> 0.14204787 | C13: =(('Band 4'!C13-'Band 3'!C13)/('Band 3'!C13+'Band 4'!C13)) -> 0.18513458 | D13: =(('Band 4'!D13-'Band 3'!D13)/('Band 3'!D13+'Band 4'!D13)) -> 0.20244399 | E13: =(('Band 4'!E13-'Band 3'!E13)/('Band 3'!E13+'Band 4'!E13)) -> 0.25468717 | F13: =(('Band 4'!F13-'Band 3'!F13)/('Band 3'!F13+'Band 4'!F13)) -> 0.27285068 | G13: =(('Band 4'!G13-'Band 3'!G13)/('Band 3'!G13+'Band 4'!G13)) -> 0.30042194 | H13: =(('Band 4'!H13-'Band 3'!H13)/('Band 3'!H13+'Band 4'!H13)) -> 0.35591944 | I13: =(('Band 4'!I13-'Band 3'!I13)/('Band 3'!I13+'Band 4'!I13)) -> 0.41445428 | ... AK13: =(('Band 4'!AK13-'Band 3'!AK13)/('Band 3'!AK13+'Band 4'!AK13)) -> 0.62450962
A14: 37 | B14: =(('Band 4'!B14-'Band 3'!B14)/('Band 3'!B14+'Band 4'!B14)) -> 0.13073005 | C14: =(('Band 4'!C14-'Band 3'!C14)/('Band 3'!C14+'Band 4'!C14)) -> 0.15256496 | D14: =(('Band 4'!D14-'Band 3'!D14)/('Band 3'!D14+'Band 4'!D14)) -> 0.18365019 | E14: =(('Band 4'!E14-'Band 3'!E14)/('Band 3'!E14+'Band 4'!E14)) -> 0.19686888 | F14: =(('Band 4'!F14-'Band 3'!F14)/('Band 3'!F14+'Band 4'!F14)) -> 0.22259136 | G14: =(('Band 4'!G14-'Band 3'!G14)/('Band 3'!G14+'Band 4'!G14)) -> 0.22733964 | H14: =(('Band 4'!H14-'Band 3'!H14)/('Band 3'!H14+'Band 4'!H14)) -> 0.26681957 | I14: =(('Band 4'!I14-'Band 3'!I14)/('Band 3'!I14+'Band 4'!I14)) -> 0.31434109 | ... AK14: =(('Band 4'!AK14-'Band 3'!AK14)/('Band 3'!AK14+'Band 4'!AK14)) -> 0.74825432
A15: 36 | B15: =(('Band 4'!B15-'Band 3'!B15)/('Band 3'!B15+'Band 4'!B15)) -> 0.13532079 | C15: =(('Band 4'!C15-'Band 3'!C15)/('Band 3'!C15+'Band 4'!C15)) -> 0.16183476 | D15: =(('Band 4'!D15-'Band 3'!D15)/('Band 3'!D15+'Band 4'!D15)) -> 0.18331754 | E15: =(('Band 4'!E15-'Band 3'!E15)/('Band 3'!E15+'Band 4'!E15)) -> 0.20208117 | F15: =(('Band 4'!F15-'Band 3'!F15)/('Band 3'!F15+'Band 4'!F15)) -> 0.23311093 | G15: =(('Band 4'!G15-'Band 3'!G15)/('Band 3'!G15+'Band 4'!G15)) -> 0.26010326 | H15: =(('Band 4'!H15-'Band 3'!H15)/('Band 3'!H15+'Band 4'!H15)) -> 0.28787615 | I15: =(('Band 4'!I15-'Band 3'!I15)/('Band 3'!I15+'Band 4'!I15)) -> 0.3288803 | ... AK15: =(('Band 4'!AK15-'Band 3'!AK15)/('Band 3'!AK15+'Band 4'!AK15)) -> 0.80473588
A16: 35 | B16: =(('Band 4'!B16-'Band 3'!B16)/('Band 3'!B16+'Band 4'!B16)) -> 0.12183522 | C16: =(('Band 4'!C16-'Band 3'!C16)/('Band 3'!C16+'Band 4'!C16)) -> 0.13646416 | D16: =(('Band 4'!D16-'Band 3'!D16)/('Band 3'!D16+'Band 4'!D16)) -> 0.14636486 | E16: =(('Band 4'!E16-'Band 3'!E16)/('Band 3'!E16+'Band 4'!E16)) -> 0.16454674 | F16: =(('Band 4'!F16-'Band 3'!F16)/('Band 3'!F16+'Band 4'!F16)) -> 0.18724158 | G16: =(('Band 4'!G16-'Band 3'!G16)/('Band 3'!G16+'Band 4'!G16)) -> 0.19814062 | H16: =(('Band 4'!H16-'Band 3'!H16)/('Band 3'!H16+'Band 4'!H16)) -> 0.21231131 | I16: =(('Band 4'!I16-'Band 3'!I16)/('Band 3'!I16+'Band 4'!I16)) -> 0.23677858 | ... AK16: =(('Band 4'!AK16-'Band 3'!AK16)/('Band 3'!AK16+'Band 4'!AK16)) -> 0.75267841
... A20: 31 | B20: =(('Band 4'!B20-'Band 3'!B20)/('Band 3'!B20+'Band 4'!B20)) -> 0.13806564 | C20: =(('Band 4'!C20-'Band 3'!C20)/('Band 3'!C20+'Band 4'!C20)) -> 0.17963895 | D20: =(('Band 4'!D20-'Band 3'!D20)/('Band 3'!D20+'Band 4'!D20)) -> 0.23852093 | E20: =(('Band 4'!E20-'Band 3'!E20)/('Band 3'!E20+'Band 4'!E20)) -> 0.25566882 | F20: =(('Band 4'!F20-'Band 3'!F20)/('Band 3'!F20+'Band 4'!F20)) -> 0.30637838 | G20: =(('Band 4'!G20-'Band 3'!G20)/('Band 3'!G20+'Band 4'!G20)) -> 0.3113069 | H20: =(('Band 4'!H20-'Band 3'!H20)/('Band 3'!H20+'Band 4'!H20)) -> 0.38986317 | I20: =(('Band 4'!I20-'Band 3'!I20)/('Band 3'!I20+'Band 4'!I20)) -> 0.45526983 | ... AK20: =(('Band 4'!AK20-'Band 3'!AK20)/('Band 3'!AK20+'Band 4'!AK20)) -> 0.82808717
A21: Panel 100.2 | B21: =(('Band 4'!B21-'Band 3'!B21)/('Band 3'!B21+'Band 4'!B21)) -> -9.9186669e-05 | C21: =(('Band 4'!C21-'Band 3'!C21)/('Band 3'!C21+'Band 4'!C21)) -> -4.9487801e-05 | D21: =(('Band 4'!D21-'Band 3'!D21)/('Band 3'!D21+'Band 4'!D21)) -> 0 | E21: =(('Band 4'!E21-'Band 3'!E21)/('Band 3'!E21+'Band 4'!E21)) -> -4.9753719e-05 | F21: =(('Band 4'!F21-'Band 3'!F21)/('Band 3'!F21+'Band 4'!F21)) -> -0.00014984267 | G21: =(('Band 4'!G21-'Band 3'!G21)/('Band 3'!G21+'Band 4'!G21)) -> -4.9625329e-05 | H21: =(('Band 4'!H21-'Band 3'!H21)/('Band 3'!H21+'Band 4'!H21)) -> -9.9910081e-05 | I21: =(('Band 4'!I21-'Band 3'!I21)/('Band 3'!I21+'Band 4'!I21)) -> -9.9681021e-05 | ... AK21: =(('Band 4'!AK21-'Band 3'!AK21)/('Band 3'!AK21+'Band 4'!AK21)) -> -0.00015086749
A22: Soil Tray | B22: =(('Band 4'!B22-'Band 3'!B22)/('Band 3'!B22+'Band 4'!B22)) -> 0.12696682 | C22: =(('Band 4'!C22-'Band 3'!C22)/('Band 3'!C22+'Band 4'!C22)) -> 0.11779969 | D22: =(('Band 4'!D22-'Band 3'!D22)/('Band 3'!D22+'Band 4'!D22)) -> 0.12252702 | E22: =(('Band 4'!E22-'Band 3'!E22)/('Band 3'!E22+'Band 4'!E22)) -> 0.11828315 | F22: =(('Band 4'!F22-'Band 3'!F22)/('Band 3'!F22+'Band 4'!F22)) -> 0.12008073 | G22: =(('Band 4'!G22-'Band 3'!G22)/('Band 3'!G22+'Band 4'!G22)) -> 0.11690918 | H22: =(('Band 4'!H22-'Band 3'!H22)/('Band 3'!H22+'Band 4'!H22)) -> 0.12977357 | I22: =(('Band 4'!I22-'Band 3'!I22)/('Band 3'!I22+'Band 4'!I22)) -> 0.12136579 | ... AK22: =(('Band 4'!AK22-'Band 3'!AK22)/('Band 3'!AK22+'Band 4'!AK22)) -> 0.12010706
A23: 1 | B23: =(('Band 4'!B23-'Band 3'!B23)/('Band 3'!B23+'Band 4'!B23)) -> 0.13117149 | C23: =(('Band 4'!C23-'Band 3'!C23)/('Band 3'!C23+'Band 4'!C23)) -> 0.12573735 | D23: =(('Band 4'!D23-'Band 3'!D23)/('Band 3'!D23+'Band 4'!D23)) -> 0.12284656 | E23: =(('Band 4'!E23-'Band 3'!E23)/('Band 3'!E23+'Band 4'!E23)) -> 0.12257222 | F23: =(('Band 4'!F23-'Band 3'!F23)/('Band 3'!F23+'Band 4'!F23)) -> 0.12251274 | G23: =(('Band 4'!G23-'Band 3'!G23)/('Band 3'!G23+'Band 4'!G23)) -> 0.12026251 | H23: =(('Band 4'!H23-'Band 3'!H23)/('Band 3'!H23+'Band 4'!H23)) -> 0.12235725 | I23: =(('Band 4'!I23-'Band 3'!I23)/('Band 3'!I23+'Band 4'!I23)) -> 0.12160371 | ... AK23: =(('Band 4'!AK23-'Band 3'!AK23)/('Band 3'!AK23+'Band 4'!AK23)) -> 0.093243998
A24: 2 | B24: =(('Band 4'!B24-'Band 3'!B24)/('Band 3'!B24+'Band 4'!B24)) -> 0.15251223 | C24: =(('Band 4'!C24-'Band 3'!C24)/('Band 3'!C24+'Band 4'!C24)) -> 0.17612874 | D24: =(('Band 4'!D24-'Band 3'!D24)/('Band 3'!D24+'Band 4'!D24)) -> 0.21354034 | E24: =(('Band 4'!E24-'Band 3'!E24)/('Band 3'!E24+'Band 4'!E24)) -> 0.29659965 | F24: =(('Band 4'!F24-'Band 3'!F24)/('Band 3'!F24+'Band 4'!F24)) -> 0.32333244 | G24: =(('Band 4'!G24-'Band 3'!G24)/('Band 3'!G24+'Band 4'!G24)) -> 0.41999491 | H24: =(('Band 4'!H24-'Band 3'!H24)/('Band 3'!H24+'Band 4'!H24)) -> 0.47458017 | I24: =(('Band 4'!I24-'Band 3'!I24)/('Band 3'!I24+'Band 4'!I24)) -> 0.53449782 | ... AK24: =(('Band 4'!AK24-'Band 3'!AK24)/('Band 3'!AK24+'Band 4'!AK24)) -> 0.77370285
A25: 3 | B25: =(('Band 4'!B25-'Band 3'!B25)/('Band 3'!B25+'Band 4'!B25)) -> 0.13987392 | C25: =(('Band 4'!C25-'Band 3'!C25)/('Band 3'!C25+'Band 4'!C25)) -> 0.15312765 | D25: =(('Band 4'!D25-'Band 3'!D25)/('Band 3'!D25+'Band 4'!D25)) -> 0.11376657 | E25: =(('Band 4'!E25-'Band 3'!E25)/('Band 3'!E25+'Band 4'!E25)) -> 0.13768485 | F25: =(('Band 4'!F25-'Band 3'!F25)/('Band 3'!F25+'Band 4'!F25)) -> 0.13716814 | G25: =(('Band 4'!G25-'Band 3'!G25)/('Band 3'!G25+'Band 4'!G25)) -> 0.13075237 | H25: =(('Band 4'!H25-'Band 3'!H25)/('Band 3'!H25+'Band 4'!H25)) -> 0.10352941 | I25: =(('Band 4'!I25-'Band 3'!I25)/('Band 3'!I25+'Band 4'!I25)) -> 0.11260504 | ... AK25: =(('Band 4'!AK25-'Band 3'!AK25)/('Band 3'!AK25+'Band 4'!AK25)) -> 0.11235294
A26: 4 | B26: =(('Band 4'!B26-'Band 3'!B26)/('Band 3'!B26+'Band 4'!B26)) -> 0.14399067 | C26: =(('Band 4'!C26-'Band 3'!C26)/('Band 3'!C26+'Band 4'!C26)) -> 0.15796641 | D26: =(('Band 4'!D26-'Band 3'!D26)/('Band 3'!D26+'Band 4'!D26)) -> 0.17972129 | E26: =(('Band 4'!E26-'Band 3'!E26)/('Band 3'!E26+'Band 4'!E26)) -> 0.20955042 | F26: =(('Band 4'!F26-'Band 3'!F26)/('Band 3'!F26+'Band 4'!F26)) -> 0.23069307 | G26: =(('Band 4'!G26-'Band 3'!G26)/('Band 3'!G26+'Band 4'!G26)) -> 0.29109415 | H26: =(('Band 4'!H26-'Band 3'!H26)/('Band 3'!H26+'Band 4'!H26)) -> 0.29186847 | I26: =(('Band 4'!I26-'Band 3'!I26)/('Band 3'!I26+'Band 4'!I26)) -> 0.29025424 | ... AK26: =(('Band 4'!AK26-'Band 3'!AK26)/('Band 3'!AK26+'Band 4'!AK26)) -> 0.77005025
A27: 5 | B27: =(('Band 4'!B27-'Band 3'!B27)/('Band 3'!B27+'Band 4'!B27)) -> 0.14615562 | C27: =(('Band 4'!C27-'Band 3'!C27)/('Band 3'!C27+'Band 4'!C27)) -> 0.15410274 | D27: =(('Band 4'!D27-'Band 3'!D27)/('Band 3'!D27+'Band 4'!D27)) -> 0.18745406 | E27: =(('Band 4'!E27-'Band 3'!E27)/('Band 3'!E27+'Band 4'!E27)) -> 0.21296758 | F27: =(('Band 4'!F27-'Band 3'!F27)/('Band 3'!F27+'Band 4'!F27)) -> 0.25282113 | G27: =(('Band 4'!G27-'Band 3'!G27)/('Band 3'!G27+'Band 4'!G27)) -> 0.27145709 | H27: =(('Band 4'!H27-'Band 3'!H27)/('Band 3'!H27+'Band 4'!H27)) -> 0.30966685 | I27: =(('Band 4'!I27-'Band 3'!I27)/('Band 3'!I27+'Band 4'!I27)) -> 0.34290753 | ... AK27: =(('Band 4'!AK27-'Band 3'!AK27)/('Band 3'!AK27+'Band 4'!AK27)) -> 0.73361034
A28: 6 | B28: =(('Band 4'!B28-'Band 3'!B28)/('Band 3'!B28+'Band 4'!B28)) -> 0.14825046 | C28: =(('Band 4'!C28-'Band 3'!C28)/('Band 3'!C28+'Band 4'!C28)) -> 0.16183137 | D28: =(('Band 4'!D28-'Band 3'!D28)/('Band 3'!D28+'Band 4'!D28)) -> 0.19690939 | E28: =(('Band 4'!E28-'Band 3'!E28)/('Band 3'!E28+'Band 4'!E28)) -> 0.23405311 | F28: =(('Band 4'!F28-'Band 3'!F28)/('Band 3'!F28+'Band 4'!F28)) -> 0.26708362 | G28: =(('Band 4'!G28-'Band 3'!G28)/('Band 3'!G28+'Band 4'!G28)) -> 0.36980948 | H28: =(('Band 4'!H28-'Band 3'!H28)/('Band 3'!H28+'Band 4'!H28)) -> 0.34775304 | I28: =(('Band 4'!I28-'Band 3'!I28)/('Band 3'!I28+'Band 4'!I28)) -> 0.41274123 | ... AK28: =(('Band 4'!AK28-'Band 3'!AK28)/('Band 3'!AK28+'Band 4'!AK28)) -> 0.77273665
A29: 7 | B29: =(('Band 4'!B29-'Band 3'!B29)/('Band 3'!B29+'Band 4'!B29)) -> 0.15056285 | C29: =(('Band 4'!C29-'Band 3'!C29)/('Band 3'!C29+'Band 4'!C29)) -> 0.16167665 | D29: =(('Band 4'!D29-'Band 3'!D29)/('Band 3'!D29+'Band 4'!D29)) -> 0.19400049 | E29: =(('Band 4'!E29-'Band 3'!E29)/('Band 3'!E29+'Band 4'!E29)) -> 0.25367922 | F29: =(('Band 4'!F29-'Band 3'!F29)/('Band 3'!F29+'Band 4'!F29)) -> 0.27984052 | G29: =(('Band 4'!G29-'Band 3'!G29)/('Band 3'!G29+'Band 4'!G29)) -> 0.37835052 | H29: =(('Band 4'!H29-'Band 3'!H29)/('Band 3'!H29+'Band 4'!H29)) -> 0.38923829 | I29: =(('Band 4'!I29-'Band 3'!I29)/('Band 3'!I29+'Band 4'!I29)) -> 0.47267997 | ... AK29: =(('Band 4'!AK29-'Band 3'!AK29)/('Band 3'!AK29+'Band 4'!AK29)) -> 0.73804659
A30: 8 | B30: =(('Band 4'!B30-'Band 3'!B30)/('Band 3'!B30+'Band 4'!B30)) -> 0.1535478 | C30: =(('Band 4'!C30-'Band 3'!C30)/('Band 3'!C30+'Band 4'!C30)) -> 0.18220874 | D30: =(('Band 4'!D30-'Band 3'!D30)/('Band 3'!D30+'Band 4'!D30)) -> 0.21559074 | E30: =(('Band 4'!E30-'Band 3'!E30)/('Band 3'!E30+'Band 4'!E30)) -> 0.28355995 | F30: =(('Band 4'!F30-'Band 3'!F30)/('Band 3'!F30+'Band 4'!F30)) -> 0.29038855 | G30: =(('Band 4'!G30-'Band 3'!G30)/('Band 3'!G30+'Band 4'!G30)) -> 0.34506693 | H30: =(('Band 4'!H30-'Band 3'!H30)/('Band 3'!H30+'Band 4'!H30)) -> 0.33385013 | I30: =(('Band 4'!I30-'Band 3'!I30)/('Band 3'!I30+'Band 4'!I30)) -> 0.36585366 | ... AK30: =(('Band 4'!AK30-'Band 3'!AK30)/('Band 3'!AK30+'Band 4'!AK30)) -> 0.71120593
A31: 18 | B31: =(('Band 4'!B31-'Band 3'!B31)/('Band 3'!B31+'Band 4'!B31)) -> 0.1297774 | C31: =(('Band 4'!C31-'Band 3'!C31)/('Band 3'!C31+'Band 4'!C31)) -> 0.15193798 | D31: =(('Band 4'!D31-'Band 3'!D31)/('Band 3'!D31+'Band 4'!D31)) -> 0.18872196 | E31: =(('Band 4'!E31-'Band 3'!E31)/('Band 3'!E31+'Band 4'!E31)) -> 0.21431476 | F31: =(('Band 4'!F31-'Band 3'!F31)/('Band 3'!F31+'Band 4'!F31)) -> 0.25976725 | G31: =(('Band 4'!G31-'Band 3'!G31)/('Band 3'!G31+'Band 4'!G31)) -> 0.25960561 | H31: =(('Band 4'!H31-'Band 3'!H31)/('Band 3'!H31+'Band 4'!H31)) -> 0.33751088 | I31: =(('Band 4'!I31-'Band 3'!I31)/('Band 3'!I31+'Band 4'!I31)) -> 0.3343442 | ... AK31: =(('Band 4'!AK31-'Band 3'!AK31)/('Band 3'!AK31+'Band 4'!AK31)) -> 0.71645065
A32: 17 | B32: =(('Band 4'!B32-'Band 3'!B32)/('Band 3'!B32+'Band 4'!B32)) -> 0.1230982 | C32: =(('Band 4'!C32-'Band 3'!C32)/('Band 3'!C32+'Band 4'!C32)) -> 0.14369321 | D32: =(('Band 4'!D32-'Band 3'!D32)/('Band 3'!D32+'Band 4'!D32)) -> 0.17734784 | E32: =(('Band 4'!E32-'Band 3'!E32)/('Band 3'!E32+'Band 4'!E32)) -> 0.19415073 | F32: =(('Band 4'!F32-'Band 3'!F32)/('Band 3'!F32+'Band 4'!F32)) -> 0.21515735 | G32: =(('Band 4'!G32-'Band 3'!G32)/('Band 3'!G32+'Band 4'!G32)) -> 0.22127216 | H32: =(('Band 4'!H32-'Band 3'!H32)/('Band 3'!H32+'Band 4'!H32)) -> 0.29567673 | I32: =(('Band 4'!I32-'Band 3'!I32)/('Band 3'!I32+'Band 4'!I32)) -> 0.31699422 | ... AK32: =(('Band 4'!AK32-'Band 3'!AK32)/('Band 3'!AK32+'Band 4'!AK32)) -> 0.70233091
A33: 16 | B33: =(('Band 4'!B33-'Band 3'!B33)/('Band 3'!B33+'Band 4'!B33)) -> 0.13163512 | C33: =(('Band 4'!C33-'Band 3'!C33)/('Band 3'!C33+'Band 4'!C33)) -> 0.15595758 | D33: =(('Band 4'!D33-'Band 3'!D33)/('Band 3'!D33+'Band 4'!D33)) -> 0.18869459 | E33: =(('Band 4'!E33-'Band 3'!E33)/('Band 3'!E33+'Band 4'!E33)) -> 0.22328042 | F33: =(('Band 4'!F33-'Band 3'!F33)/('Band 3'!F33+'Band 4'!F33)) -> 0.25907173 | G33: =(('Band 4'!G33-'Band 3'!G33)/('Band 3'!G33+'Band 4'!G33)) -> 0.28652274 | H33: =(('Band 4'!H33-'Band 3'!H33)/('Band 3'!H33+'Band 4'!H33)) -> 0.27575703 | I33: =(('Band 4'!I33-'Band 3'!I33)/('Band 3'!I33+'Band 4'!I33)) -> 0.33961915 | ... AK33: =(('Band 4'!AK33-'Band 3'!AK33)/('Band 3'!AK33+'Band 4'!AK33)) -> 0.77974684
A34: 15 | B34: =(('Band 4'!B34-'Band 3'!B34)/('Band 3'!B34+'Band 4'!B34)) -> 0.12357994 | C34: =(('Band 4'!C34-'Band 3'!C34)/('Band 3'!C34+'Band 4'!C34)) -> 0.14135315 | D34: =(('Band 4'!D34-'Band 3'!D34)/('Band 3'!D34+'Band 4'!D34)) -> 0.166632 | E34: =(('Band 4'!E34-'Band 3'!E34)/('Band 3'!E34+'Band 4'!E34)) -> 0.1824229 | F34: =(('Band 4'!F34-'Band 3'!F34)/('Band 3'!F34+'Band 4'!F34)) -> 0.2060343 | G34: =(('Band 4'!G34-'Band 3'!G34)/('Band 3'!G34+'Band 4'!G34)) -> 0.23589655 | H34: =(('Band 4'!H34-'Band 3'!H34)/('Band 3'!H34+'Band 4'!H34)) -> 0.26390533 | I34: =(('Band 4'!I34-'Band 3'!I34)/('Band 3'!I34+'Band 4'!I34)) -> 0.28975717 | ... AK34: =(('Band 4'!AK34-'Band 3'!AK34)/('Band 3'!AK34+'Band 4'!AK34)) -> 0.76701967
... A46: 28 | B46: =(('Band 4'!B46-'Band 3'!B46)/('Band 3'!B46+'Band 4'!B46)) -> 0.14247151 | C46: =(('Band 4'!C46-'Band 3'!C46)/('Band 3'!C46+'Band 4'!C46)) -> 0.1667493 | D46: =(('Band 4'!D46-'Band 3'!D46)/('Band 3'!D46+'Band 4'!D46)) -> 0.22192893 | E46: =(('Band 4'!E46-'Band 3'!E46)/('Band 3'!E46+'Band 4'!E46)) -> 0.24960254 | F46: =(('Band 4'!F46-'Band 3'!F46)/('Band 3'!F46+'Band 4'!F46)) -> 0.31451434 | G46: =(('Band 4'!G46-'Band 3'!G46)/('Band 3'!G46+'Band 4'!G46)) -> 0.3286484 | H46: =(('Band 4'!H46-'Band 3'!H46)/('Band 3'!H46+'Band 4'!H46)) -> 0.37004119 | I46: =(('Band 4'!I46-'Band 3'!I46)/('Band 3'!I46+'Band 4'!I46)) -> 0.43518133 | ... AK46: =(('Band 4'!AK46-'Band 3'!AK46)/('Band 3'!AK46+'Band 4'!AK46)) -> 0.68733274
A47: Panel 100.3 | B47: =(('Band 4'!B47-'Band 3'!B47)/('Band 3'!B47+'Band 4'!B47)) -> 0 | C47: =(('Band 4'!C47-'Band 3'!C47)/('Band 3'!C47+'Band 4'!C47)) -> 0 | D47: =(('Band 4'!D47-'Band 3'!D47)/('Band 3'!D47+'Band 4'!D47)) -> 4.872582e-05 | E47: =(('Band 4'!E47-'Band 3'!E47)/('Band 3'!E47+'Band 4'!E47)) -> -4.9360778e-05 | F47: =(('Band 4'!F47-'Band 3'!F47)/('Band 3'!F47+'Band 4'!F47)) -> -9.9098206e-05 | G47: =(('Band 4'!G47-'Band 3'!G47)/('Band 3'!G47+'Band 4'!G47)) -> 0 | H47: =(('Band 4'!H47-'Band 3'!H47)/('Band 3'!H47+'Band 4'!H47)) -> -9.9088387e-05 | I47: =(('Band 4'!I47-'Band 3'!I47)/('Band 3'!I47+'Band 4'!I47)) -> -4.9433981e-05 | ... AK47: =(('Band 4'!AK47-'Band 3'!AK47)/('Band 3'!AK47+'Band 4'!AK47)) -> -0.00014985764
A48: Quality | B48: 2 | C48: 3 | D48: 3 | E48: 2 | F48: 2 | G48: 0 | H48: 1 | I48: 2 | J48: 3 | K48: 2 | L48: 2 | M48: 2 | N48: 3 | O48: 3 | P48: 2 | Q48: 5 | R48: 4 | S48: 4 | T48: 4 | U48: 3 | V48: 2 | W48: 3 | X48: 2 | Y48: 3 | Z48: 3 | AA48: 2 | AB48: 2 | AC48: 2 | AD48: 2 | AE48: 3 | AF48: 2 | AG48: 2 | AH48: 2 | AI48: 2 | AJ48: 1 | AK48: 2

Sheet Band 1
B1: DOY
A2: Plot | B2: 152 | C2: 157 | D2: 163 | E2: 166 | F2: 169 | G2: 172 | H2: 176 | I2: 178 | J2: 180 | K2: 183 | L2: 187 | M2: 190 | N2: 192 | O2: 194 | P2: 200 | Q2: 204 | R2: 206 | S2: 208 | T2: 211 | U2: 213 | V2: 214 | W2: 219 | X2: 222 | Y2: 225 | Z2: 227 | AA2: 232 | AB2: 234 | AC2: 236 | AD2: 242 | AE2: 247 | AF2: 253 | AG2: 260 | AH2: 263 | AI2: 267 | AJ2: 269 | AK2: 276
A3: Panel 100.1 | B3: ='DOY152'!AB2 -> 1.0001 | C3: ='DOY157'!AB2 -> 1.0031 | D3: ='DOY163'!AB2 -> 1.0031 | E3: ='DOY166'!AB2 -> 0.9992 | F3: ='DOY169'!AB2 -> 0.9952 | G3: ='DOY172'!AB2 -> 1.0016 | H3: ='DOY176'!AB2 -> 0.9942 | I3: ='DOY178'!AB2 -> 0.9968 | J3: ='DOY180'!AB2 -> 0.9932 | K3: ='DOY183'!AB2 -> 0.9927 | L3: ='DOY187'!AB2 -> 0.9982 | M3: ='DOY190'!AB2 -> 0.9932 | N3: ='DOY192'!AB2 -> 0.9919 | O3: ='DOY194'!AB2 -> 0.9878 | P3: ='DOY200'!AB2 -> 0.9946 | Q3: ='DOY204'!AB2 -> 0.9928 | R3: ='DOY206'!AB2 -> 0.9922 | S3: ='DOY208'!AB2 -> 0.9928 | T3: ='DOY211'!AB2 -> 1.0002 | U3: ='DOY213'!AB2 -> 0.9946 | V3: ='DOY214'!AB2 -> 0.9931 | W3: ='DOY219'!AB2 -> 0.9952 | X3: ='DOY222'!AB2 -> 0.9984 | Y3: ='DOY225'!AB2 -> 0.9913 | Z3: ='DOY227'!AB2 -> 0.993 | AA3: ='DOY232'!AB2 -> 0.9921 | AB3: ='DOY234'!AB2 -> 0.9951 | AC3: ='DOY236'!AB2 -> 0.9906 | AD3: ='DOY242'!AB2 -> 0.9948 | AE3: ='DOY247'!AB2 -> 0.9839 | AF3: ='DOY253'!AB2 -> 0.9859 | AG3: ='DOY260'!AB2 -> 0.9861 | AH3: ='DOY263'!AB2 -> 0.9949 | AI3: ='DOY267'!AB2 -> 0.989 | AJ3: ='DOY269'!AB2 -> 0.9933 | AK3: ='DOY276'!AB2 -> 0.9882
A4: Panel 70.1 | B4: ='DOY152'!AB3 -> 0.0555 | C4: ='DOY157'!AB3 -> 0.1458 | D4: ='DOY163'!AB3 -> 0.1376 | E4: ='DOY166'!AB3 -> 0.136 | F4: ='DOY169'!AB3 -> 0.1362 | G4: ='DOY172'!AB3 -> 0.1371 | H4: ='DOY176'!AB3 -> 0.1358 | I4: ='DOY178'!AB3 -> 0.1362 | J4: ='DOY180'!AB3 -> 0.1352 | K4: ='DOY183'!AB3 -> 0.1345 | L4: ='DOY187'!AB3 -> 0.1351 | M4: ='DOY190'!AB3 -> 0.1351 | N4: ='DOY192'!AB3 -> 0.1345 | O4: ='DOY194'!AB3 -> 0.1721 | P4: ='DOY200'!AB3 -> 0.1372 | Q4: ='DOY204'!AB3 -> 0.1295 | R4: ='DOY206'!AB3 -> 0.1363 | S4: ='DOY208'!AB3 -> 0.1977 | T4: ='DOY211'!AB3 -> 0.1343 | U4: ='DOY213'!AB3 -> 0.1446 | V4: ='DOY214'!AB3 -> 0.0697 | W4: ='DOY219'!AB3 -> 0.1508 | X4: ='DOY222'!AB3 -> 0.1348 | Y4: ='DOY225'!AB3 -> 0.117 | Z4: ='DOY227'!AB3 -> 0.1341 | AA4: ='DOY232'!AB3 -> 0.1352 | AB4: ='DOY234'!AB3 -> 0.1346 | AC4: ='DOY236'!AB3 -> 0.1341 | AD4: ='DOY242'!AB3 -> 0.1344 | AE4: ='DOY247'!AB3 -> 0.1339 | AF4: ='DOY253'!AB3 -> 0.1332 | AG4: ='DOY260'!AB3 -> 0.1349 | AH4: ='DOY263'!AB3 -> 0.1352 | AI4: ='DOY267'!AB3 -> 0.1351 | AJ4: ='DOY269'!AB3 -> 0.1337 | AK4: ='DOY276'!AB3 -> 0.1338
A5: 41 | B5: ='DOY152'!AB4 -> 0.2828 | C5: ='DOY157'!AB4 -> 0.2556 | D5: ='DOY163'!AB4 -> 0.1724 | E5: ='DOY166'!AB4 -> 0.1596 | F5: ='DOY169'!AB4 -> 0.1441 | G5: ='DOY172'!AB4 -> 0.1583 | H5: ='DOY176'!AB4 -> 0.1439 | I5: ='DOY178'!AB4 -> 0.1286 | J5: ='DOY180'!AB4 -> 0.1283 | K5: ='DOY183'!AB4 -> 0.1198 | L5: ='DOY187'!AB4 -> 0.0862 | M5: ='DOY190'!AB4 -> 0.0773 | N5: ='DOY192'!AB4 -> 0.0633 | O5: ='DOY194'!AB4 -> 0.0673 | P5: ='DOY200'!AB4 -> 0.0548 | Q5: ='DOY204'!AB4 -> 0.0709 | R5: ='DOY206'!AB4 -> 0.0919 | S5: ='DOY208'!AB4 -> 0.0359 | T5: ='DOY211'!AB4 -> 0.0296 | U5: ='DOY213'!AB4 -> 0.0478 | V5: ='DOY214'!AB4 -> 0.0244 | W5: ='DOY219'!AB4 -> 0.0297 | X5: ='DOY222'!AB4 -> 0.0267 | Y5: ='DOY225'!AB4 -> 0.0221 | Z5: ='DOY227'!AB4 -> 0.0273 | AA5: ='DOY232'!AB4 -> 0.0362 | AB5: ='DOY234'!AB4 -> 0.0274 | AC5: ='DOY236'!AB4 -> 0.0264 | AD5: ='DOY242'!AB4 -> 0.0276 | AE5: ='DOY247'!AB4 -> 0.0392 | AF5: ='DOY253'!AB4 -> 0.0284 | AG5: ='DOY260'!AB4 -> 0.0314 | AH5: ='DOY263'!AB4 -> 0.0388 | AI5: ='DOY267'!AB4 -> 0.0443 | AJ5: ='DOY269'!AB4 -> 0.0513 | AK5: ='DOY276'!AB4 -> 0.0701
A6: 42 | B6: ='DOY152'!AB5 -> 0.2922 | C6: ='DOY157'!AB5 -> 0.2835 | D6: ='DOY163'!AB5 -> 0.1925 | E6: ='DOY166'!AB5 -> 0.1725 | F6: ='DOY169'!AB5 -> 0.1587 | G6: ='DOY172'!AB5 -> 0.1625 | H6: ='DOY176'!AB5 -> 0.16 | I6: ='DOY178'!AB5 -> 0.144 | J6: ='DOY180'!AB5 -> 0.1254 | K6: ='DOY183'!AB5 -> 0.1189 | L6: ='DOY187'!AB5 -> 0.0907 | M6: ='DOY190'!AB5 -> 0.0771 | N6: ='DOY192'!AB5 -> 0.0661 | O6: ='DOY194'!AB5 -> 0.0665 | P6: ='DOY200'!AB5 -> 0.0427 | Q6: ='DOY204'!AB5 -> 0.0564 | R6: ='DOY206'!AB5 -> 0.0785 | S6: ='DOY208'!AB5 -> 0.0315 | T6: ='DOY211'!AB5 -> 0.0228 | U6: ='DOY213'!AB5 -> 0.0372 | V6: ='DOY214'!AB5 -> 0.0248 | W6: ='DOY219'!AB5 -> 0.0283 | X6: ='DOY222'!AB5 -> 0.0251 | Y6: ='DOY225'!AB5 -> 0.0225 | Z6: ='DOY227'!AB5 -> 0.0273 | AA6: ='DOY232'!AB5 -> 0.0344 | AB6: ='DOY234'!AB5 -> 0.0274 | AC6: ='DOY236'!AB5 -> 0.0291 | AD6: ='DOY242'!AB5 -> 0.0306 | AE6: ='DOY247'!AB5 -> 0.041 | AF6: ='DOY253'!AB5 -> 0.0347 | AG6: ='DOY260'!AB5 -> 0.0344 | AH6: ='DOY263'!AB5 -> 0.0426 | AI6: ='DOY267'!AB5 -> 0.0475 | AJ6: ='DOY269'!AB5 -> 0.0522 | AK6: ='DOY276'!AB5 -> 0.0576
A7: 43 | B7: ='DOY152'!AB6 -> 0.2864 | C7: ='DOY157'!AB6 -> 0.2874 | D7: ='DOY163'!AB6 -> 0.1962 | E7: ='DOY166'!AB6 -> 0.176 | F7: ='DOY169'!AB6 -> 0.1651 | G7: ='DOY172'!AB6 -> 0.1576 | H7: ='DOY176'!AB6 -> 0.1739 | I7: ='DOY178'!AB6 -> 0.1583 | J7: ='DOY180'!AB6 -> 0.1554 | K7: ='DOY183'!AB6 -> 0.1378 | L7: ='DOY187'!AB6 -> 0.124 | M7: ='DOY190'!AB6 -> 0.0869 | N7: ='DOY192'!AB6 -> 0.0747 | O7: ='DOY194'!AB6 -> 0.0615 | P7: ='DOY200'!AB6 -> 0.0486 | Q7: ='DOY204'!AB6 -> 0.0531 | R7: ='DOY206'!AB6 -> 0.0567 | S7: ='DOY208'!AB6 -> 0.0269 | T7: ='DOY211'!AB6 -> 0.0209 | U7: ='DOY213'!AB6 -> 0.0287 | V7: ='DOY214'!AB6 -> 0.0246 | W7: ='DOY219'!AB6 -> 0.0267 | X7: ='DOY222'!AB6 -> 0.0264 | Y7: ='DOY225'!AB6 -> 0.0355 | Z7: ='DOY227'!AB6 -> 0.0266 | AA7: ='DOY232'!AB6 -> 0.0311 | AB7: ='DOY234'!AB6 -> 0.029 | AC7: ='DOY236'!AB6 -> 0.0288 | AD7: ='DOY242'!AB6 -> 0.0275 | AE7: ='DOY247'!AB6 -> 0.0252 | AF7: ='DOY253'!AB6 -> 0.0298 | AG7: ='DOY260'!AB6 -> 0.038 | AH7: ='DOY263'!AB6 -> 0.0428 | AI7: ='DOY267'!AB6 -> 0.0521 | AJ7: ='DOY269'!AB6 -> 0.0597 | AK7: ='DOY276'!AB6 -> 0.0917
A8: 44 | B8: ='DOY152'!AB7 -> 0.2809 | C8: ='DOY157'!AB7 -> 0.2853 | D8: ='DOY163'!AB7 -> 0.194 | E8: ='DOY166'!AB7 -> 0.1885 | F8: ='DOY169'!AB7 -> 0.1702 | G8: ='DOY172'!AB7 -> 0.1641 | H8: ='DOY176'!AB7 -> 0.1902 | I8: ='DOY178'!AB7 -> 0.1753 | J8: ='DOY180'!AB7 -> 0.172 | K8: ='DOY183'!AB7 -> 0.1594 | L8: ='DOY187'!AB7 -> 0.1547 | M8: ='DOY190'!AB7 -> 0.1255 | N8: ='DOY192'!AB7 -> 0.115 | O8: ='DOY194'!AB7 -> 0.1017 | P8: ='DOY200'!AB7 -> 0.0964 | Q8: ='DOY204'!AB7 -> 0.0745 | R8: ='DOY206'!AB7 -> 0.0662 | S8: ='DOY208'!AB7 -> 0.0358 | T8: ='DOY211'!AB7 -> 0.0273 | U8: ='DOY213'!AB7 -> 0.0345 | V8: ='DOY214'!AB7 -> 0.0318 | W8: ='DOY219'!AB7 -> 0.0284 | X8: ='DOY222'!AB7 -> 0.0334 | Y8: ='DOY225'!AB7 -> 0.0362 | Z8: ='DOY227'!AB7 -> 0.0246 | AA8: ='DOY232'!AB7 -> 0.0262 | AB8: ='DOY234'!AB7 -> 0.0254 | AC8: ='DOY236'!AB7 -> 0.0253 | AD8: ='DOY242'!AB7 -> 0.0235 | AE8: ='DOY247'!AB7 -> 0.0244 | AF8: ='DOY253'!AB7 -> 0.0246 | AG8: ='DOY260'!AB7 -> 0.0287 | AH8: ='DOY263'!AB7 -> 0.0342 | AI8: ='DOY267'!AB7 -> 0.0359 | AJ8: ='DOY269'!AB7 -> 0.0375 | AK8: ='DOY276'!AB7 -> 0.0581
A9: 45 | B9: ='DOY152'!AB8 -> 0.2689 | C9: ='DOY157'!AB8 -> 0.2618 | D9: ='DOY163'!AB8 -> 0.1901 | E9: ='DOY166'!AB8 -> 0.1717 | F9: ='DOY169'!AB8 -> 0.1691 | G9: ='DOY172'!AB8 -> 0.1595 | H9: ='DOY176'!AB8 -> 0.1547 | I9: ='DOY178'!AB8 -> 0.1504 | J9: ='DOY180'!AB8 -> 0.1476 | K9: ='DOY183'!AB8 -> 0.1202 | L9: ='DOY187'!AB8 -> 0.0955 | M9: ='DOY190'!AB8 -> 0.0578 | N9: ='DOY192'!AB8 -> 0.0465 | O9: ='DOY194'!AB8 -> 0.0459 | P9: ='DOY200'!AB8 -> 0.0301 | Q9: ='DOY204'!AB8 -> 0.0374 | R9: ='DOY206'!AB8 -> 0.0351 | S9: ='DOY208'!AB8 -> 0.0244 | T9: ='DOY211'!AB8 -> 0.0142 | U9: ='DOY213'!AB8 -> 0.0235 | V9: ='DOY214'!AB8 -> 0.023 | W9: ='DOY219'!AB8 -> 0.0206 | X9: ='DOY222'!AB8 -> 0.0246 | Y9: ='DOY225'!AB8 -> 0.0287 | Z9: ='DOY227'!AB8 -> 0.0281 | AA9: ='DOY232'!AB8 -> 0.0302 | AB9: ='DOY234'!AB8 -> 0.0279 | AC9: ='DOY236'!AB8 -> 0.0289 | AD9: ='DOY242'!AB8 -> 0.0254 | AE9: ='DOY247'!AB8 -> 0.0299 | AF9: ='DOY253'!AB8 -> 0.028 | AG9: ='DOY260'!AB8 -> 0.0379 | AH9: ='DOY263'!AB8 -> 0.0396 | AI9: ='DOY267'!AB8 -> 0.04 | AJ9: ='DOY269'!AB8 -> 0.0452 | AK9: ='DOY276'!AB8 -> 0.0651
A10: 46 | B10: ='DOY152'!AB9 -> 0.2847 | C10: ='DOY157'!AB9 -> 0.2672 | D10: ='DOY163'!AB9 -> 0.1856 | E10: ='DOY166'!AB9 -> 0.1532 | F10: ='DOY169'!AB9 -> 0.1447 | G10: ='DOY172'!AB9 -> 0.1731 | H10: ='DOY176'!AB9 -> 0.1118 | I10: ='DOY178'!AB9 -> 0.1161 | J10: ='DOY180'!AB9 -> 0.1069 | K10: ='DOY183'!AB9 -> 0.0669 | L10: ='DOY187'!AB9 -> 0.0644 | M10: ='DOY190'!AB9 -> 0.0525 | N10: ='DOY192'!AB9 -> 0.0301 | O10: ='DOY194'!AB9 -> 0.0464 | P10: ='DOY200'!AB9 -> 0.0301 | Q10: ='DOY204'!AB9 -> 0.0486 | R10: ='DOY206'!AB9 -> 0.0363 | S10: ='DOY208'!AB9 -> 0.0258 | T10: ='DOY211'!AB9 -> 0.0163 | U10: ='DOY213'!AB9 -> 0.0307 | V10: ='DOY214'!AB9 -> 0.0255 | W10: ='DOY219'!AB9 -> 0.0244 | X10: ='DOY222'!AB9 -> 0.0271 | Y10: ='DOY225'!AB9 -> 0.0307 | Z10: ='DOY227'!AB9 -> 0.0279 | AA10: ='DOY232'!AB9 -> 0.0311 | AB10: ='DOY234'!AB9 -> 0.029 | AC10: ='DOY236'!AB9 -> 0.029 | AD10: ='DOY242'!AB9 -> 0.0256 | AE10: ='DOY247'!AB9 -> 0.0319 | AF10: ='DOY253'!AB9 -> 0.03 | AG10: ='DOY260'!AB9 -> 0.0369 | AH10: ='DOY263'!AB9 -> 0.0425 | AI10: ='DOY267'!AB9 -> 0.0434 | AJ10: ='DOY269'!AB9 -> 0.0446 | AK10: ='DOY276'!AB9 -> 0.0598
A11: 47 | B11: ='DOY152'!AB10 -> 0.2834 | C11: ='DOY157'!AB10 -> 0.2752 | D11: ='DOY163'!AB10 -> 0.1945 | E11: ='DOY166'!AB10 -> 0.1664 | F11: ='DOY169'!AB10 -> 0.1524 | G11: ='DOY172'!AB10 -> 0.1545 | H11: ='DOY176'!AB10 -> 0.1299 | I11: ='DOY178'!AB10 -> 0.1395 | J11: ='DOY180'!AB10 -> 0.122 | K11: ='DOY183'!AB10 -> 0.12 | L11: ='DOY187'!AB10 -> 0.1164 | M11: ='DOY190'!AB10 -> 0.0812 | N11: ='DOY192'!AB10 -> 0.0773 | O11: ='DOY194'!AB10 -> 0.0628 | P11: ='DOY200'!AB10 -> 0.0452 | Q11: ='DOY204'!AB10 -> 0.0885 | R11: ='DOY206'!AB10 -> 0.0804 | S11: ='DOY208'!AB10 -> 0.0371 | T11: ='DOY211'!AB10 -> 0.0235 | U11: ='DOY213'!AB10 -> 0.0506 | V11: ='DOY214'!AB10 -> 0.03 | W11: ='DOY219'!AB10 -> 0.0304 | X11: ='DOY222'!AB10 -> 0.0342 | Y11: ='DOY225'!AB10 -> 0.0337 | Z11: ='DOY227'!AB10 -> 0.0323 | AA11: ='DOY232'!AB10 -> 0.0383 | AB11: ='DOY234'!AB10 -> 0.0295 | AC11: ='DOY236'!AB10 -> 0.0304 | AD11: ='DOY242'!AB10 -> 0.0316 | AE11: ='DOY247'!AB10 -> 0.0356 | AF11: ='DOY253'!AB10 -> 0.034 | AG11: ='DOY260'!AB10 -> 0.0384 | AH11: ='DOY263'!AB10 -> 0.0446 | AI11: ='DOY267'!AB10 -> 0.0513 | AJ11: ='DOY269'!AB10 -> 0.0565 | AK11: ='DOY276'!AB10 -> 0.0788
A12: 48 | B12: ='DOY152'!AB11 -> 0.2895 | C12: ='DOY157'!AB11 -> 0.3011 | D12: ='DOY163'!AB11 -> 0.1935 | E12: ='DOY166'!AB11 -> 0.1686 | F12: ='DOY169'!AB11 -> 0.1561 | G12: ='DOY172'!AB11 -> 0.2037 | H12: ='DOY176'!AB11 -> 0.1716 | I12: ='DOY178'!AB11 -> 0.1369 | J12: ='DOY180'!AB11 -> 0.1369 | K12: ='DOY183'!AB11 -> 0.1125 | L12: ='DOY187'!AB11 -> 0.0891 | M12: ='DOY190'!AB11 -> 0.0876 | N12: ='DOY192'!AB11 -> 0.0481 | O12: ='DOY194'!AB11 -> 0.0589 | P12: ='DOY200'!AB11 -> 0.0464 | Q12: ='DOY204'!AB11 -> 0.0714 | R12: ='DOY206'!AB11 -> 0.0425 | S12: ='DOY208'!AB11 -> 0.027 | T12: ='DOY211'!AB11 -> 0.0168 | U12: ='DOY213'!AB11 -> 0.04 | V12: ='DOY214'!AB11 -> 0.0245 | W12: ='DOY219'!AB11 -> 0.0216 | X12: ='DOY222'!AB11 -> 0.0275 | Y12: ='DOY225'!AB11 -> 0.0281 | Z12: ='DOY227'!AB11 -> 0.0273 | AA12: ='DOY232'!AB11 -> 0.03 | AB12: ='DOY234'!AB11 -> 0.0281 | AC12: ='DOY236'!AB11 -> 0.028 | AD12: ='DOY242'!AB11 -> 0.0277 | AE12: ='DOY247'!AB11 -> 0.0246 | AF12: ='DOY253'!AB11 -> 0.0303 | AG12: ='DOY260'!AB11 -> 0.0388 | AH12: ='DOY263'!AB11 -> 0.0441 | AI12: ='DOY267'!AB11 -> 0.0496 | AJ12: ='DOY269'!AB11 -> 0.0523 | AK12: ='DOY276'!AB11 -> 0.0786
A13: 38 | B13: ='DOY152'!AB12 -> 0.3105 | C13: ='DOY157'!AB12 -> 0.3 | D13: ='DOY163'!AB12 -> 0.1994 | E13: ='DOY166'!AB12 -> 0.1783 | F13: ='DOY169'!AB12 -> 0.1617 | G13: ='DOY172'!AB12 -> 0.1668 | H13: ='DOY176'!AB12 -> 0.1759 | I13: ='DOY178'!AB12 -> 0.1591 | J13: ='DOY180'!AB12 -> 0.164 | K13: ='DOY183'!AB12 -> 0.1377 | L13: ='DOY187'!AB12 -> 0.1118 | M13: ='DOY190'!AB12 -> 0.0786 | N13: ='DOY192'!AB12 -> 0.0648 | O13: ='DOY194'!AB12 -> 0.0485 | P13: ='DOY200'!AB12 -> 0.0324 | Q13: ='DOY204'!AB12 -> 0.0501 | R13: ='DOY206'!AB12 -> 0.0455 | S13: ='DOY208'!AB12 -> 0.0284 | T13: ='DOY211'!AB12 -> 0.0203 | U13: ='DOY213'!AB12 -> 0.0406 | V13: ='DOY214'!AB12 -> 0.0245 | W13: ='DOY219'!AB12 -> 0.0269 | X13: ='DOY222'!AB12 -> 0.0287 | Y13: ='DOY225'!AB12 -> 0.0353 | Z13: ='DOY227'!AB12 -> 0.0313 | AA13: ='DOY232'!AB12 -> 0.0328 | AB13: ='DOY234'!AB12 -> 0.0305 | AC13: ='DOY236'!AB12 -> 0.0328 | AD13: ='DOY242'!AB12 -> 0.0316 | AE13: ='DOY247'!AB12 -> 0.0285 | AF13: ='DOY253'!AB12 -> 0.0375 | AG13: ='DOY260'!AB12 -> 0.0445 | AH13: ='DOY263'!AB12 -> 0.0517 | AI13: ='DOY267'!AB12 -> 0.058 | AJ13: ='DOY269'!AB12 -> 0.0671 | AK13: ='DOY276'!AB12 -> 0.0997
A14: 37 | B14: ='DOY152'!AB13 -> 0.3126 | C14: ='DOY157'!AB13 -> 0.3195 | D14: ='DOY163'!AB13 -> 0.2198 | E14: ='DOY166'!AB13 -> 0.2093 | F14: ='DOY169'!AB13 -> 0.1903 | G14: ='DOY172'!AB13 -> 0.1885 | H14: ='DOY176'!AB13 -> 0.1974 | I14: ='DOY178'!AB13 -> 0.1817 | J14: ='DOY180'!AB13 -> 0.1839 | K14: ='DOY183'!AB13 -> 0.1677 | L14: ='DOY187'!AB13 -> 0.1439 | M14: ='DOY190'!AB13 -> 0.1309 | N14: ='DOY192'!AB13 -> 0.1181 | O14: ='DOY194'!AB13 -> 0.0768 | P14: ='DOY200'!AB13 -> 0.0725 | Q14: ='DOY204'!AB13 -> 0.0805 | R14: ='DOY206'!AB13 -> 0.0731 | S14: ='DOY208'!AB13 -> 0.0483 | T14: ='DOY211'!AB13 -> 0.032 | U14: ='DOY213'!AB13 -> 0.0703 | V14: ='DOY214'!AB13 -> 0.031 | W14: ='DOY219'!AB13 -> 0.0371 | X14: ='DOY222'!AB13 -> 0.0346 | Y14: ='DOY225'!AB13 -> 0.0313 | Z14: ='DOY227'!AB13 -> 0.0312 | AA14: ='DOY232'!AB13 -> 0.0315 | AB14: ='DOY234'!AB13 -> 0.0286 | AC14: ='DOY236'!AB13 -> 0.0286 | AD14: ='DOY242'!AB13 -> 0.0305 | AE14: ='DOY247'!AB13 -> 0.0346 | AF14: ='DOY253'!AB13 -> 0.0338 | AG14: ='DOY260'!AB13 -> 0.0374 | AH14: ='DOY263'!AB13 -> 0.0447 | AI14: ='DOY267'!AB13 -> 0.0466 | AJ14: ='DOY269'!AB13 -> 0.0516 | AK14: ='DOY276'!AB13 -> 0.0666
A15: 36 | B15: ='DOY152'!AB14 -> 0.3196 | C15: ='DOY157'!AB14 -> 0.3143 | D15: ='DOY163'!AB14 -> 0.2199 | E15: ='DOY166'!AB14 -> 0.1946 | F15: ='DOY169'!AB14 -> 0.1873 | G15: ='DOY172'!AB14 -> 0.2115 | H15: ='DOY176'!AB14 -> 0.2056 | I15: ='DOY178'!AB14 -> 0.1952 | J15: ='DOY180'!AB14 -> 0.192 | K15: ='DOY183'!AB14 -> 0.1549 | L15: ='DOY187'!AB14 -> 0.1453 | M15: ='DOY190'!AB14 -> 0.0869 | N15: ='DOY192'!AB14 -> 0.0647 | O15: ='DOY194'!AB14 -> 0.0732 | P15: ='DOY200'!AB14 -> 0.051 | Q15: ='DOY204'!AB14 -> 0.0579 | R15: ='DOY206'!AB14 -> 0.0488 | S15: ='DOY208'!AB14 -> 0.0268 | T15: ='DOY211'!AB14 -> 0.0188 | U15: ='DOY213'!AB14 -> 0.0412 | V15: ='DOY214'!AB14 -> 0.0253 | W15: ='DOY219'!AB14 -> 0.0278 | X15: ='DOY222'!AB14 -> 0.0281 | Y15: ='DOY225'!AB14 -> 0.0286 | Z15: ='DOY227'!AB14 -> 0.0288 | AA15: ='DOY232'!AB14 -> 0.0318 | AB15: ='DOY234'!AB14 -> 0.0292 | AC15: ='DOY236'!AB14 -> 0.0303 | AD15: ='DOY242'!AB14 -> 0.0279 | AE15: ='DOY247'!AB14 -> 0.0307 | AF15: ='DOY253'!AB14 -> 0.0298 | AG15: ='DOY260'!AB14 -> 0.034 | AH15: ='DOY263'!AB14 -> 0.0414 | AI15: ='DOY267'!AB14 -> 0.0435 | AJ15: ='DOY269'!AB14 -> 0.0444 | AK15: ='DOY276'!AB14 -> 0.0534
A16: 35 | B16: ='DOY152'!AB15 -> 0.3219 | C16: ='DOY157'!AB15 -> 0.336 | D16: ='DOY163'!AB15 -> 0.225 | E16: ='DOY166'!AB15 -> 0.2113 | F16: ='DOY169'!AB15 -> 0.2111 | G16: ='DOY172'!AB15 -> 0.2141 | H16: ='DOY176'!AB15 -> 0.2051 | I16: ='DOY178'!AB15 -> 0.1732 | J16: ='DOY180'!AB15 -> 0.2134 | K16: ='DOY183'!AB15 -> 0.2102 | L16: ='DOY187'!AB15 -> 0.1182 | M16: ='DOY190'!AB15 -> 0.1792 | N16: ='DOY192'!AB15 -> 0.1553 | O16: ='DOY194'!AB15 -> 0.1653 | P16: ='DOY200'!AB15 -> 0.143 | Q16: ='DOY204'!AB15 -> 0.0683 | R16: ='DOY206'!AB15 -> 0.0706 | S16: ='DOY208'!AB15 -> 0.0791 | T16: ='DOY211'!AB15 -> 0.0376 | U16: ='DOY213'!AB15 -> 0.0801 | V16: ='DOY214'!AB15 -> 0.0447 | W16: ='DOY219'!AB15 -> 0.0393 | X16: ='DOY222'!AB15 -> 0.036 | Y16: ='DOY225'!AB15 -> 0.0337 | Z16: ='DOY227'!AB15 -> 0.032 | AA16: ='DOY232'!AB15 -> 0.0348 | AB16: ='DOY234'!AB15 -> 0.0353 | AC16: ='DOY236'!AB15 -> 0.0314 | AD16: ='DOY242'!AB15 -> 0.0284 | AE16: ='DOY247'!AB15 -> 0.0283 | AF16: ='DOY253'!AB15 -> 0.0301 | AG16: ='DOY260'!AB15 -> 0.0367 | AH16: ='DOY263'!AB15 -> 0.0436 | AI16: ='DOY267'!AB15 -> 0.0475 | AJ16: ='DOY269'!AB15 -> 0.0514 | AK16: ='DOY276'!AB15 -> 0.0657
... A20: 31 | B20: ='DOY152'!AB19 -> 0.3022 | C20: ='DOY157'!AB19 -> 0.2824 | D20: ='DOY163'!AB19 -> 0.1925 | E20: ='DOY166'!AB19 -> 0.1817 | F20: ='DOY169'!AB19 -> 0.1653 | G20: ='DOY172'!AB19 -> 0.1878 | H20: ='DOY176'!AB19 -> 0.1579 | I20: ='DOY178'!AB19 -> 0.1553 | J20: ='DOY180'!AB19 -> 0.087 | K20: ='DOY183'!AB19 -> 0.108 | L20: ='DOY187'!AB19 -> 0.0876 | M20: ='DOY190'!AB19 -> 0.0688 | N20: ='DOY192'!AB19 -> 0.0407 | O20: ='DOY194'!AB19 -> 0.038 | P20: ='DOY200'!AB19 -> 0.0327 | Q20: ='DOY204'!AB19 -> 0.045 | R20: ='DOY206'!AB19 -> 0.043 | S20: ='DOY208'!AB19 -> 0.0259 | T20: ='DOY211'!AB19 -> 0.0215 | U20: ='DOY213'!AB19 -> 0.0286 | V20: ='DOY214'!AB19 -> 0.0247 | W20: ='DOY219'!AB19 -> 0.0254 | X20: ='DOY222'!AB19 -> 0.0272 | Y20: ='DOY225'!AB19 -> 0.0283 | Z20: ='DOY227'!AB19 -> 0.029 | AA20: ='DOY232'!AB19 -> 0.0318 | AB20: ='DOY234'!AB19 -> 0.0296 | AC20: ='DOY236'!AB19 -> 0.0294 | AD20: ='DOY242'!AB19 -> 0.03 | AE20: ='DOY247'!AB19 -> 0.0319 | AF20: ='DOY253'!AB19 -> 0.032 | AG20: ='DOY260'!AB19 -> 0.0346 | AH20: ='DOY263'!AB19 -> 0.0407 | AI20: ='DOY267'!AB19 -> 0.0439 | AJ20: ='DOY269'!AB19 -> 0.0459 | AK20: ='DOY276'!AB19 -> 0.0466
A21: Panel 100.2 | B21: ='DOY152'!AB20 -> 1.0083 | C21: ='DOY157'!AB20 -> 1.0104 | D21: ='DOY163'!AB20 -> 1.0167 | E21: ='DOY166'!AB20 -> 1.005 | F21: ='DOY169'!AB20 -> 1.0012 | G21: ='DOY172'!AB20 -> 1.0076 | H21: ='DOY176'!AB20 -> 1.001 | I21: ='DOY178'!AB20 -> 1.0033 | J21: ='DOY180'!AB20 -> 1 | K21: ='DOY183'!AB20 -> 1 | L21: ='DOY187'!AB20 -> 1.0056 | M21: ='DOY190'!AB20 -> 1.0002 | N21: ='DOY192'!AB20 -> 0.9988 | O21: ='DOY194'!AB20 -> 0.9949 | P21: ='DOY200'!AB20 -> 1.0023 | Q21: ='DOY204'!AB20 -> 0.9999 | R21: ='DOY206'!AB20 -> 0.9997 | S21: ='DOY208'!AB20 -> 1 | T21: ='DOY211'!AB20 -> 1.0075 | U21: ='DOY213'!AB20 -> 1.0012 | V21: ='DOY214'!AB20 -> 1.0006 | W21: ='DOY219'!AB20 -> 1.0024 | X21: ='DOY222'!AB20 -> 1.0067 | Y21: ='DOY225'!AB20 -> 1.0005 | Z21: ='DOY227'!AB20 -> 1.0007 | AA21: ='DOY232'!AB20 -> 0.999 | AB21: ='DOY234'!AB20 -> 1.0022 | AC21: ='DOY236'!AB20 -> 0.9986 | AD21: ='DOY242'!AB20 -> 1.0013 | AE21: ='DOY247'!AB20 -> 0.9915 | AF21: ='DOY253'!AB20 -> 0.9939 | AG21: ='DOY260'!AB20 -> 0.9929 | AH21: ='DOY263'!AB20 -> 1.0014 | AI21: ='DOY267'!AB20 -> 0.9953 | AJ21: ='DOY269'!AB20 -> 0.999 | AK21: ='DOY276'!AB20 -> 0.9944
A22: Soil Tray | B22: ='DOY152'!AB21 -> 0.2842 | C22: ='DOY157'!AB21 -> 0.2581 | D22: ='DOY163'!AB21 -> 0.2672 | E22: ='DOY166'!AB21 -> 0.2688 | F22: ='DOY169'!AB21 -> 0.2662 | G22: ='DOY172'!AB21 -> 0.2671 | H22: ='DOY176'!AB21 -> 0.2652 | I22: ='DOY178'!AB21 -> 0.2666 | J22: ='DOY180'!AB21 -> 0.2639 | K22: ='DOY183'!AB21 -> 0.2665 | L22: ='DOY187'!AB21 -> 0.2694 | M22: ='DOY190'!AB21 -> 0.2654 | N22: ='DOY192'!AB21 -> 0.2652 | O22: ='DOY194'!AB21 -> 0.2672 | P22: ='DOY200'!AB21 -> 0.2662 | Q22: ='DOY204'!AB21 -> 0.2532 | R22: ='DOY206'!AB21 -> 0.2632 | S22: ='DOY208'!AB21 -> 0.2595 | T22: ='DOY211'!AB21 -> 0.2844 | U22: ='DOY213'!AB21 -> 0.2643 | V22: ='DOY214'!AB21 -> 0.2602 | W22: ='DOY219'!AB21 -> 0.2392 | X22: ='DOY222'!AB21 -> 0.2708 | Y22: ='DOY225'!AB21 -> 0.2667 | Z22: ='DOY227'!AB21 -> 0.2629 | AA22: ='DOY232'!AB21 -> 0.2707 | AB22: ='DOY234'!AB21 -> 0.2667 | AC22: ='DOY236'!AB21 -> 0.2666 | AD22: ='DOY242'!AB21 -> 0.2661 | AE22: ='DOY247'!AB21 -> 0.2638 | AF22: ='DOY253'!AB21 -> 0.266 | AG22: ='DOY260'!AB21 -> 0.2634 | AH22: ='DOY263'!AB21 -> 0.2705 | AI22: ='DOY267'!AB21 -> 0.2655 | AJ22: ='DOY269'!AB21 -> 0.2663 | AK22: ='DOY276'!AB21 -> 0.2671
A23: 1 | B23: ='DOY152'!AB22 -> 0.3052 | C23: ='DOY157'!AB22 -> 0.289 | D23: ='DOY163'!AB22 -> 0.2794 | E23: ='DOY166'!AB22 -> 0.2754 | F23: ='DOY169'!AB22 -> 0.2735 | G23: ='DOY172'!AB22 -> 0.2744 | H23: ='DOY176'!AB22 -> 0.27 | I23: ='DOY178'!AB22 -> 0.2719 | J23: ='DOY180'!AB22 -> 0.2707 | K23: ='DOY183'!AB22 -> 0.2739 | L23: ='DOY187'!AB22 -> 0.2753 | M23: ='DOY190'!AB22 -> 0.2694 | N23: ='DOY192'!AB22 -> 0.2304 | O23: ='DOY194'!AB22 -> 0.2355 | P23: ='DOY200'!AB22 -> 0.3199 | Q23: ='DOY204'!AB22 -> 0.2953 | R23: ='DOY206'!AB22 -> 0.3179 | S23: ='DOY208'!AB22 -> 0.3114 | T23: ='DOY211'!AB22 -> 0.2781 | U23: ='DOY213'!AB22 -> 0.3445 | V23: ='DOY214'!AB22 -> 0.2547 | W23: ='DOY219'!AB22 -> 0.3553 | X23: ='DOY222'!AB22 -> 0.3226 | Y23: ='DOY225'!AB22 -> 0.3204 | Z23: ='DOY227'!AB22 -> 0.3221 | AA23: ='DOY232'!AB22 -> 0.3279 | AB23: ='DOY234'!AB22 -> 0.3282 | AC23: ='DOY236'!AB22 -> 0.3301 | AD23: ='DOY242'!AB22 -> 0.3178 | AE23: ='DOY247'!AB22 -> 0.3181 | AF23: ='DOY253'!AB22 -> 0.3224 | AG23: ='DOY260'!AB22 -> 0.3173 | AH23: ='DOY263'!AB22 -> 0.3286 | AI23: ='DOY267'!AB22 -> 0.333 | AJ23: ='DOY269'!AB22 -> 0.3343 | AK23: ='DOY276'!AB22 -> 0.33
A24: 2 | B24: ='DOY152'!AB23 -> 0.1967 | C24: ='DOY157'!AB23 -> 0.1898 | D24: ='DOY163'!AB23 -> 0.1579 | E24: ='DOY166'!AB23 -> 0.1471 | F24: ='DOY169'!AB23 -> 0.1288 | G24: ='DOY172'!AB23 -> 0.1164 | H24: ='DOY176'!AB23 -> 0.1144 | I24: ='DOY178'!AB23 -> 0.1076 | J24: ='DOY180'!AB23 -> 0.062 | K24: ='DOY183'!AB23 -> 0.0623 | L24: ='DOY187'!AB23 -> 0.0585 | M24: ='DOY190'!AB23 -> 0.0492 | N24: ='DOY192'!AB23 -> 0.032 | O24: ='DOY194'!AB23 -> 0.0297 | P24: ='DOY200'!AB23 -> 0.0266 | Q24: ='DOY204'!AB23 -> 0.0381 | R24: ='DOY206'!AB23 -> 0.0414 | S24: ='DOY208'!AB23 -> 0.0272 | T24: ='DOY211'!AB23 -> 0.0254 | U24: ='DOY213'!AB23 -> 0.0357 | V24: ='DOY214'!AB23 -> 0.0258 | W24: ='DOY219'!AB23 -> 0.0291 | X24: ='DOY222'!AB23 -> 0.0234 | Y24: ='DOY225'!AB23 -> 0.0253 | Z24: ='DOY227'!AB23 -> 0.0271 | AA24: ='DOY232'!AB23 -> 0.0347 | AB24: ='DOY234'!AB23 -> 0.0299 | AC24: ='DOY236'!AB23 -> 0.028 | AD24: ='DOY242'!AB23 -> 0.0276 | AE24: ='DOY247'!AB23 -> 0.0278 | AF24: ='DOY253'!AB23 -> 0.0292 | AG24: ='DOY260'!AB23 -> 0.0346 | AH24: ='DOY263'!AB23 -> 0.0398 | AI24: ='DOY267'!AB23 -> 0.0428 | AJ24: ='DOY269'!AB23 -> 0.0463 | AK24: ='DOY276'!AB23 -> 0.0525
A25: 3 | B25: ='DOY152'!AB24 -> 0.2245 | C25: ='DOY157'!AB24 -> 0.1541 | D25: ='DOY163'!AB24 -> 0.277 | E25: ='DOY166'!AB24 -> 0.1736 | F25: ='DOY169'!AB24 -> 0.1803 | G25: ='DOY172'!AB24 -> 0.1826 | H25: ='DOY176'!AB24 -> 0.3105 | I25: ='DOY178'!AB24 -> 0.1622 | J25: ='DOY180'!AB24 -> 0.3001 | K25: ='DOY183'!AB24 -> 0.1871 | L25: ='DOY187'!AB24 -> 0.1834 | M25: ='DOY190'!AB24 -> 0.1839 | N25: ='DOY192'!AB24 -> 0.2816 | O25: ='DOY194'!AB24 -> 0.1799 | P25: ='DOY200'!AB24 -> 0.1654 | Q25: ='DOY204'!AB24 -> 0.1611 | R25: ='DOY206'!AB24 -> 0.1796 | S25: ='DOY208'!AB24 -> 0.1991 | T25: ='DOY211'!AB24 -> 0.1049 | U25: ='DOY213'!AB24 -> 0.1815 | V25: ='DOY214'!AB24 -> 0.1941 | W25: ='DOY219'!AB24 -> 0.1936 | X25: ='DOY222'!AB24 -> 0.1777 | Y25: ='DOY225'!AB24 -> 0.1746 | Z25: ='DOY227'!AB24 -> 0.3131 | AA25: ='DOY232'!AB24 -> 0.1525 | AB25: ='DOY234'!AB24 -> 0.1715 | AC25: ='DOY236'!AB24 -> 0.3062 | AD25: ='DOY242'!AB24 -> 0.3137 | AE25: ='DOY247'!AB24 -> 0.1487 | AF25: ='DOY253'!AB24 -> 0.1659 | AG25: ='DOY260'!AB24 -> 0.2823 | AH25: ='DOY263'!AB24 -> 0.1714 | AI25: ='DOY267'!AB24 -> 0.2984 | AJ25: ='DOY269'!AB24 -> 0.3033 | AK25: ='DOY276'!AB24 -> 0.305
A26: 4 | B26: ='DOY152'!AB25 -> 0.1887 | C26: ='DOY157'!AB25 -> 0.1896 | D26: ='DOY163'!AB25 -> 0.1742 | E26: ='DOY166'!AB25 -> 0.1597 | F26: ='DOY169'!AB25 -> 0.1585 | G26: ='DOY172'!AB25 -> 0.1438 | H26: ='DOY176'!AB25 -> 0.1436 | I26: ='DOY178'!AB25 -> 0.1378 | J26: ='DOY180'!AB25 -> 0.1138 | K26: ='DOY183'!AB25 -> 0.1574 | L26: ='DOY187'!AB25 -> 0.1382 | M26: ='DOY190'!AB25 -> 0.1278 | N26: ='DOY192'!AB25 -> 0.1025 | O26: ='DOY194'!AB25 -> 0.1017 | P26: ='DOY200'!AB25 -> 0.1116 | Q26: ='DOY204'!AB25 -> 0.0559 | R26: ='DOY206'!AB25 -> 0.0597 | S26: ='DOY208'!AB25 -> 0.031 | T26: ='DOY211'!AB25 -> 0.023 | U26: ='DOY213'!AB25 -> 0.0326 | V26: ='DOY214'!AB25 -> 0.0246 | W26: ='DOY219'!AB25 -> 0.0322 | X26: ='DOY222'!AB25 -> 0.0252 | Y26: ='DOY225'!AB25 -> 0.0254 | Z26: ='DOY227'!AB25 -> 0.0261 | AA26: ='DOY232'!AB25 -> 0.0283 | AB26: ='DOY234'!AB25 -> 0.0258 | AC26: ='DOY236'!AB25 -> 0.027 | AD26: ='DOY242'!AB25 -> 0.0248 | AE26: ='DOY247'!AB25 -> 0.0212 | AF26: ='DOY253'!AB25 -> 0.0316 | AG26: ='DOY260'!AB25 -> 0.0375 | AH26: ='DOY263'!AB25 -> 0.0389 | AI26: ='DOY267'!AB25 -> 0.0397 | AJ26: ='DOY269'!AB25 -> 0.0415 | AK26: ='DOY276'!AB25 -> 0.0551
A27: 5 | B27: ='DOY152'!AB26 -> 0.191 | C27: ='DOY157'!AB26 -> 0.1956 | D27: ='DOY163'!AB26 -> 0.1683 | E27: ='DOY166'!AB26 -> 0.1621 | F27: ='DOY169'!AB26 -> 0.1586 | G27: ='DOY172'!AB26 -> 0.1476 | H27: ='DOY176'!AB26 -> 0.1278 | I27: ='DOY178'!AB26 -> 0.1332 | J27: ='DOY180'!AB26 -> 0.1 | K27: ='DOY183'!AB26 -> 0.128 | L27: ='DOY187'!AB26 -> 0.1075 | M27: ='DOY190'!AB26 -> 0.0915 | N27: ='DOY192'!AB26 -> 0.0821 | O27: ='DOY194'!AB26 -> 0.0797 | P27: ='DOY200'!AB26 -> 0.0903 | Q27: ='DOY204'!AB26 -> 0.0538 | R27: ='DOY206'!AB26 -> 0.0598 | S27: ='DOY208'!AB26 -> 0.0375 | T27: ='DOY211'!AB26 -> 0.018 | U27: ='DOY213'!AB26 -> 0.0352 | V27: ='DOY214'!AB26 -> 0.0249 | W27: ='DOY219'!AB26 -> 0.0301 | X27: ='DOY222'!AB26 -> 0.0246 | Y27: ='DOY225'!AB26 -> 0.0236 | Z27: ='DOY227'!AB26 -> 0.0258 | AA27: ='DOY232'!AB26 -> 0.0304 | AB27: ='DOY234'!AB26 -> 0.0259 | AC27: ='DOY236'!AB26 -> 0.0276 | AD27: ='DOY242'!AB26 -> 0.0291 | AE27: ='DOY247'!AB26 -> 0.0224 | AF27: ='DOY253'!AB26 -> 0.0309 | AG27: ='DOY260'!AB26 -> 0.0346 | AH27: ='DOY263'!AB26 -> 0.0379 | AI27: ='DOY267'!AB26 -> 0.0372 | AJ27: ='DOY269'!AB26 -> 0.0404 | AK27: ='DOY276'!AB26 -> 0.0582
