Workbook
Name SWC: [1]A!$T$1:$AQ$10

Sheet Summary
A1: Year | B1: DOY | C1: Experiment | D1: Tube | E1: d290cm | F1: d270cm | G1: d250cm | H1: d230cm | I1: d210cm | J1: d190cm | K1: d170cm | L1: d150cm | M1: d130cm | N1: d110cm | O1: d090cm | P1: d070cm | Q1: d050cm | R1: d030cm
A2: 2007 | B2: 122 | C2: ISM | D2: p11 | E2: 0.133 | F2: 0.13 | G2: 0.119 | H2: 0.13 | I2: 0.147 | J2: 0.155 | K2: 0.197 | L2: 0.171 | M2: 0.198 | N2: 0.175 | O2: 0.164 | P2: 0.138 | Q2: 0.121 | R2: 0.079
A3: 2007 | B3: 122 | C3: ISM | D3: p12 | E3: 0.125 | F3: 0.123 | G3: 0.14 | H3: 0.161 | I3: 0.199 | J3: 0.133 | K3: 0.183 | L3: 0.177 | M3: 0.108 | N3: 0.076 | O3: 0.076 | P3: 0.091 | Q3: 0.116 | R3: 0.069
A4: 2007 | B4: 122 | C4: ISM | D4: p13 | E4: 0.147 | F4: 0.151 | G4: 0.15 | H4: 0.164 | I4: 0.145 | J4: 0.134 | K4: 0.105 | L4: 0.096 | M4: 0.072 | N4: 0.065 | O4: 0.066 | P4: 0.08 | Q4: 0.101 | R4: 0.068
A5: 2007 | B5: 122 | C5: ISM | D5: p14 | E5: 0.05 | F5: 0.093 | G5: 0.095 | H5: 0.111 | I5: 0.116 | J5: 0.191 | K5: 0.209 | L5: 0.21 | M5: 0.2 | N5: 0.161 | O5: 0.149 | P5: 0.111 | Q5: 0.099 | R5: 0.067
A6: 2007 | B6: 122 | C6: ISM | D6: p15 | E6: 0.11 | F6: 0.125 | G6: 0.123 | H6: 0.141 | I6: 0.193 | J6: 0.197 | K6: 0.148 | L6: 0.136 | M6: 0.113 | N6: 0.091 | O6: 0.079 | P6: 0.082 | Q6: 0.098 | R6: 0.065
A7: 2007 | B7: 122 | C7: ISM | D7: p16 | E7: 0.141 | F7: 0.134 | G7: 0.138 | H7: 0.166 | I7: 0.213 | J7: 0.204 | K7: 0.124 | L7: 0.098 | M7: 0.081 | N7: 0.078 | O7: 0.075 | P7: 0.072 | Q7: 0.085 | R7: 0.093
A8: 2007 | B8: 122 | C8: ISM | D8: p17 | E8: 0.19 | F8: 0.196 | G8: 0.156 | H8: 0.161 | I8: 0.165 | J8: 0.14 | K8: 0.135 | L8: 0.176 | M8: 0.129 | N8: 0.097 | O8: 0.086 | P8: 0.075 | Q8: 0.082 | R8: 0.074
A9: 2007 | B9: 122 | C9: ISM | D9: p18 | E9: 0.279 | F9: 0.277 | G9: 0.26 | H9: 0.177 | I9: 0.122 | J9: 0.13 | K9: 0.163 | L9: 0.171 | M9: 0.16 | N9: 0.163 | O9: 0.157 | P9: 0.159 | Q9: 0.116 | R9: 0.075
A10: 2007 | B10: 122 | C10: ISM | D10: p21 | E10: 0.282 | F10: 0.179 | G10: 0.166 | H10: 0.163 | I10: 0.221 | J10: 0.223 | K10: 0.183 | L10: 0.188 | M10: 0.166 | N10: 0.178 | O10: 0.178 | P10: 0.115 | Q10: 0.125 | R10: 0.09
A11: 2007 | B11: 122 | C11: ISM | D11: p22 | E11: 0.14 | F11: 0.126 | G11: 0.136 | H11: 0.127 | I11: 0.137 | J11: 0.181 | K11: 0.169 | L11: 0.199 | M11: 0.185 | N11: 0.164 | O11: 0.155 | P11: 0.135 | Q11: 0.118 | R11: 0.071
A12: 2007 | B12: 122 | C12: ISM | D12: p23 | E12: 0.145 | F12: 0.18 | G12: 0.155 | H12: 0.163 | I12: 0.17 | J12: 0.183 | K12: 0.139 | L12: 0.097 | M12: 0.082 | N12: 0.074 | O12: 0.073 | P12: 0.081 | Q12: 0.107 | R12: 0.081
A13: 2007 | B13: 122 | C13: ISM | D13: p24 | E13: 0.08 | F13: 0.066 | G13: 0.07 | H13: 0.091 | I13: 0.105 | J13: 0.142 | K13: 0.157 | L13: 0.208 | M13: 0.179 | N13: 0.186 | O13: 0.196 | P13: 0.177 | Q13: 0.129 | R13: 0.118
... A36: 2007 | B36: 152 | C36: ISM | D36: p05 | E36: 0.112 | F36: 0.103 | G36: 0.114 | H36: 0.131 | I36: 0.151 | J36: 0.215 | K36: 0.232 | L36: 0.238 | M36: 0.245 | N36: 0.25 | O36: 0.214 | P36: 0.187 | Q36: 0.192 | R36: 0.147
A37: 2007 | B37: 152 | C37: ISM | D37: p06 | H37: 0.144 | I37: 0.16 | J37: 0.164 | K37: 0.173 | L37: 0.184 | M37: 0.201 | N37: 0.2 | O37: 0.173 | P37: 0.178 | Q37: 0.183 | R37: 0.13
A38: 2007 | B38: 152 | C38: ISM | D38: p07 | H38: 0.178 | I38: 0.192 | J38: 0.186 | K38: 0.238 | L38: 0.265 | M38: 0.271 | N38: 0.255 | O38: 0.245 | P38: 0.214 | Q38: 0.197 | R38: 0.138
A39: 2007 | B39: 152 | C39: ISM | D39: p08 | E39: 0.21 | F39: 0.22 | G39: 0.236 | H39: 0.164 | I39: 0.15 | J39: 0.184 | K39: 0.161 | L39: 0.143 | M39: 0.147 | N39: 0.18 | O39: 0.218 | P39: 0.213 | Q39: 0.188 | R39: 0.13
A40: 2007 | B40: 152 | C40: ISM | D40: p10 | E40: 0.165 | F40: 0.151 | G40: 0.153 | H40: 0.164 | I40: 0.157 | J40: 0.154 | K40: 0.157 | L40: 0.151 | M40: 0.153 | N40: 0.146 | O40: 0.144 | P40: 0.151 | Q40: 0.168 | R40: 0.136
A41: 2007 | B41: 152 | C41: ISM | D41: p11 | E41: 0.133 | F41: 0.132 | G41: 0.121 | H41: 0.132 | I41: 0.15 | J41: 0.16 | K41: 0.201 | L41: 0.176 | M41: 0.263 | N41: 0.283 | O41: 0.258 | P41: 0.219 | Q41: 0.206 | R41: 0.148
A42: 2007 | B42: 152 | C42: ISM | D42: p12 | E42: 0.138 | F42: 0.135 | G42: 0.151 | H42: 0.173 | I42: 0.208 | J42: 0.198 | K42: 0.197 | L42: 0.195 | M42: 0.174 | N42: 0.162 | O42: 0.148 | P42: 0.174 | Q42: 0.199 | R42: 0.161
A43: 2007 | B43: 152 | C43: ISM | D43: p13 | E43: 0.151 | F43: 0.153 | G43: 0.151 | H43: 0.17 | I43: 0.154 | J43: 0.152 | K43: 0.146 | L43: 0.143 | M43: 0.141 | N43: 0.134 | O43: 0.13 | P43: 0.166 | Q43: 0.196 | R43: 0.161
A44: 2007 | B44: 152 | C44: ISM | D44: p14 | E44: 0.051 | F44: 0.094 | G44: 0.1 | H44: 0.112 | I44: 0.12 | J44: 0.199 | K44: 0.23 | L44: 0.24 | M44: 0.264 | N44: 0.273 | O44: 0.268 | P44: 0.209 | Q44: 0.187 | R44: 0.169
A45: 2007 | B45: 152 | C45: ISM | D45: p15 | E45: 0.109 | F45: 0.125 | G45: 0.124 | H45: 0.14 | I45: 0.197 | J45: 0.203 | K45: 0.208 | L45: 0.224 | M45: 0.232 | N45: 0.175 | O45: 0.152 | P45: 0.156 | Q45: 0.169 | R45: 0.125
A46: 2007 | B46: 152 | C46: ISM | D46: p16 | E46: 0.141 | F46: 0.135 | G46: 0.138 | H46: 0.165 | I46: 0.216 | J46: 0.247 | K46: 0.209 | L46: 0.172 | M46: 0.177 | N46: 0.169 | O46: 0.163 | P46: 0.159 | Q46: 0.173 | R46: 0.15
A47: 2007 | B47: 152 | C47: ISM | D47: p17 | E47: 0.191 | F47: 0.196 | G47: 0.16 | H47: 0.168 | I47: 0.17 | J47: 0.169 | K47: 0.188 | L47: 0.237 | M47: 0.243 | N47: 0.187 | O47: 0.174 | P47: 0.164 | Q47: 0.17 | R47: 0.132
A48: 2007 | B48: 152 | C48: ISM | D48: p18 | E48: 0.279 | F48: 0.279 | G48: 0.263 | H48: 0.182 | I48: 0.128 | J48: 0.151 | K48: 0.195 | L48: 0.227 | M48: 0.221 | N48: 0.247 | O48: 0.264 | P48: 0.277 | Q48: 0.228 | R48: 0.161
A49: 2007 | B49: 152 | C49: ISM | D49: p21 | E49: 0.275 | F49: 0.179 | G49: 0.166 | H49: 0.163 | I49: 0.211 | J49: 0.257 | K49: 0.23 | L49: 0.24 | M49: 0.237 | N49: 0.27 | O49: 0.271 | P49: 0.211 | Q49: 0.212 | R49: 0.171
A50: 2007 | B50: 152 | C50: ISM | D50: p22 | E50: 0.144 | F50: 0.126 | G50: 0.135 | H50: 0.13 | I50: 0.137 | J50: 0.182 | K50: 0.234 | L50: 0.24 | M50: 0.264 | N50: 0.271 | O50: 0.274 | P50: 0.218 | Q50: 0.195 | R50: 0.164
... A75: 2007 | B75: 158 | C75: ISM | D75: p05 | E75: 0.114 | F75: 0.106 | G75: 0.115 | H75: 0.126 | I75: 0.144 | J75: 0.207 | K75: 0.234 | L75: 0.229 | M75: 0.245 | N75: 0.25 | O75: 0.219 | P75: 0.193 | Q75: 0.208 | R75: 0.201
A76: 2007 | B76: 158 | C76: ISM | D76: p06 | H76: 0.144 | I76: 0.16 | J76: 0.176 | K76: 0.17 | L76: 0.178 | M76: 0.198 | N76: 0.197 | O76: 0.166 | P76: 0.176 | Q76: 0.197 | R76: 0.185
A77: 2007 | B77: 158 | C77: ISM | D77: p07 | H77: 0.173 | I77: 0.183 | J77: 0.18 | K77: 0.235 | L77: 0.253 | M77: 0.262 | N77: 0.252 | O77: 0.241 | P77: 0.218 | Q77: 0.214 | R77: 0.199
A78: 2007 | B78: 158 | C78: ISM | D78: p08 | E78: 0.203 | F78: 0.218 | G78: 0.223 | H78: 0.156 | I78: 0.145 | J78: 0.184 | K78: 0.161 | L78: 0.139 | M78: 0.15 | N78: 0.177 | O78: 0.211 | P78: 0.206 | Q78: 0.205 | R78: 0.185
A79: 2007 | B79: 158 | C79: ISM | D79: p10 | E79: 0.16 | F79: 0.146 | G79: 0.151 | H79: 0.162 | I79: 0.156 | J79: 0.155 | K79: 0.155 | L79: 0.149 | M79: 0.153 | N79: 0.147 | O79: 0.154 | P79: 0.162 | Q79: 0.194 | R79: 0.194
A80: 2007 | B80: 158 | C80: ISM | D80: p11 | E80: 0.128 | F80: 0.128 | G80: 0.121 | H80: 0.125 | I80: 0.148 | J80: 0.157 | K80: 0.199 | L80: 0.183 | M80: 0.263 | N80: 0.273 | O80: 0.262 | P80: 0.22 | Q80: 0.224 | R80: 0.211
A81: 2007 | B81: 158 | C81: ISM | D81: p12 | E81: 0.133 | F81: 0.14 | G81: 0.146 | H81: 0.165 | I81: 0.205 | J81: 0.196 | K81: 0.192 | L81: 0.195 | M81: 0.178 | N81: 0.155 | O81: 0.151 | P81: 0.176 | Q81: 0.213 | R81: 0.229
A82: 2007 | B82: 158 | C82: ISM | D82: p13 | E82: 0.15 | F82: 0.146 | G82: 0.15 | H82: 0.167 | I82: 0.153 | J82: 0.146 | K82: 0.142 | L82: 0.139 | M82: 0.141 | N82: 0.134 | O82: 0.139 | P82: 0.174 | Q82: 0.215 | R82: 0.222
A83: 2007 | B83: 158 | C83: ISM | D83: p14 | E83: 0.052 | F83: 0.092 | G83: 0.102 | H83: 0.112 | I83: 0.12 | J83: 0.2 | K83: 0.226 | L83: 0.239 | M83: 0.261 | N83: 0.274 | O83: 0.266 | P83: 0.212 | Q83: 0.198 | R83: 0.23
A84: 2007 | B84: 158 | C84: ISM | D84: p15 | E84: 0.107 | F84: 0.119 | G84: 0.12 | H84: 0.14 | I84: 0.192 | J84: 0.198 | K84: 0.206 | L84: 0.219 | M84: 0.235 | N84: 0.175 | O84: 0.154 | P84: 0.168 | Q84: 0.187 | R84: 0.186
A85: 2007 | B85: 158 | C85: ISM | D85: p16 | E85: 0.14 | F85: 0.136 | G85: 0.144 | H85: 0.169 | I85: 0.215 | J85: 0.247 | K85: 0.205 | L85: 0.17 | M85: 0.175 | N85: 0.168 | O85: 0.167 | P85: 0.168 | Q85: 0.194 | R85: 0.203
A86: 2007 | B86: 158 | C86: ISM | D86: p17 | E86: 0.185 | F86: 0.196 | G86: 0.157 | H86: 0.157 | I86: 0.172 | J86: 0.164 | K86: 0.182 | L86: 0.233 | M86: 0.239 | N86: 0.183 | O86: 0.173 | P86: 0.169 | Q86: 0.188 | R86: 0.212
...

Sheet A
A1: DOY (Julian) | F1: 122 | H1: DOY (Julian) | M1: 152 | U1: 158 | AC1: 164 | AK1: 169 | AS1: 170 | BA1: 172 | BI1: 173 | BQ1: 176 | BY1: 179 | CG1: 183 | CO1: 186 | CW1: 190 | DE1: 193 | DM1: 194 | DU1: 197 | EC1: 200 | EK1: 204 | ES1: 207 | FA1: 211 | FI1: 214 | FQ1: 218 | FY1: 220 | GG1: 221 | GO1: 225 | GW1: 228 | HE1: 229 | HM1: 232
A2: Cotton 2007 | C2: Neutron/TDR readings | H2: Cotton 2007 | J2: Neutron/TDR readings | P2: Cotton 2007 | R2: Neutron/TDR readings | X2: Cotton 2007 | Z2: Neutron/TDR readings | AF2: Cotton 2007 | AH2: Neutron/TDR readings | AN2: Cotton 2007 | AP2: Neutron/TDR readings | AV2: Cotton 2007 | AX2: Neutron/TDR readings | BD2: Cotton 2007 | BF2: Neutron/TDR readings | BL2: Cotton 2007 | BN2: Neutron/TDR readings | BT2: Cotton 2007 | BV2: Neutron/TDR readings | CB2: Cotton 2007 | CD2: Neutron/TDR readings | CJ2: Cotton 2007 | CL2: Neutron/TDR readings | CR2: Cotton 2007 | CT2: Neutron/TDR readings | CZ2: Cotton 2007 | DB2: Neutron/TDR readings | DH2: Cotton 2007 | DJ2: Neutron/TDR readings | DP2: Cotton 2007 | DR2: Neutron/TDR readings | DX2: Cotton 2007 | DZ2: Neutron/TDR readings | EF2: Cotton 2007 | EH2: Neutron/TDR readings | EN2: Cotton 2007 | EP2: Neutron/TDR readings | EV2: Cotton 2007 | EX2: Neutron/TDR readings | FD2: Cotton 2007 | FF2: Neutron/TDR readings | FL2: Cotton 2007 | FN2: Neutron/TDR readings | FT2: Cotton 2007 | FV2: Neutron/TDR readings | GB2: Cotton 2007 | GD2: Neutron/TDR readings | GJ2: Cotton 2007 | GL2: Neutron/TDR readings | GR2: Cotton 2007 | GT2: Neutron/TDR readings | GZ2: Cotton 2007 | HB2: Neutron/TDR readings | HH2: Cotton 2007 | HJ2: Neutron/TDR readings
A3: Treatment summary | C3: 0-290 cm depth | H3: Treatment summary | J3: 0-290 cm depth | P3: Treatment summary | R3: 0-190 cm depth | X3: Treatment summary | Z3: 0-190 cm depth | AF3: Treatment summary | AH3: 0-190 cm depth | AN3: Treatment summary | AP3: 0-190 cm depth | AV3: Treatment summary | AX3: 0-190 cm depth | BD3: Treatment summary | BF3: 0-190 cm depth | BL3: Treatment summary | BN3: 0-190 cm depth | BT3: Treatment summary | BV3: 0-190 cm depth | CB3: Treatment summary | CD3: 0-190 cm depth | CJ3: Treatment summary | CL3: 0-190 cm depth | CR3: Treatment summary | CT3: 0-190 cm depth | CZ3: Treatment summary | DB3: 0-190 cm depth | DH3: Treatment summary | DJ3: 0-190 cm depth | DP3: Treatment summary | DR3: 0-190 cm depth | DX3: Treatment summary | DZ3: 0-190 cm depth | EF3: Treatment summary | EH3: 0-190 cm depth | EN3: Treatment summary | EP3: 0-190 cm depth | EV3: Treatment summary | EX3: 0-190 cm depth | FD3: Treatment summary | FF3: 0-190 cm depth | FL3: Treatment summary | FN3: 0-190 cm depth | FT3: Treatment summary | FV3: 0-190 cm depth | GB3: Treatment summary | GD3: 0-190 cm depth | GJ3: Treatment summary | GL3: 0-190 cm depth | GR3: Treatment summary | GT3: 0-190 cm depth | GZ3: Treatment summary | HB3: 0-190 cm depth | HH3: Treatment summary | HJ3: 0-190 cm depth
A4: Date: 2-May-07 | C4: File name: | D4: CT15207.xls | F4: Cum | H4: Date: 1-Jun-07 | J4: File name: | K4: CT15207.xls | M4: Cum | N4: Accum. | P4: Date: 7-Jun-07 | R4: File name: | S4: CT15807.xls | U4: Cum | V4: Accum. | X4: Date: 13-Jun-07 | Z4: File name: | AA4: CT16407.xls | AC4: Cum | AD4: Accum. | AF4: Date: 18-Jun-07 | AH4: File name: | AI4: CT16907.xls | AK4: Cum | AL4: Accum. | AN4: Date: 19-Jun-07 | AP4: File name: | AQ4: CT17007.xls | AS4: Cum | AT4: Accum. | AV4: Date: 21-Jun-07 | AX4: File name: | AY4: CT17207.xls | BA4: Cum | BB4: Accum. | BD4: Date: 22-Jun-07 | BF4: File name: | BG4: CT17307.xls | BI4: Cum | BJ4: Accum. | BL4: Date: 25-Jun-07 | BN4: File name: | BO4: CT17607.xls | BQ4: Cum | BR4: Accum. | BT4: Date: 28-Jun-07 | BV4: File name: | BW4: CT17907.xls | BY4: Cum | BZ4: Accum. | CB4: Date: 2-Jul-07 | CD4: File name: | CE4: CT18307.xls | CG4: Cum | CH4: Accum. | CJ4: Date: 5-Jul-07 | CL4: File name: | CM4: CT18607.xls | CO4: Cum | CP4: Accum. | CR4: Date: 9-Jul-07 | CT4: File name: | CU4: CT19007.xls | CW4: Cum | CX4: Accum. | CZ4: Date: 12-Jul-07 | DB4: File name: | DC4: CT19307.xls | DE4: Cum | DF4: Accum. | DH4: Date: 13-Jul-07 | DJ4: File name: | DK4: CT19407.xls | DM4: Cum | DN4: Accum. | DP4: Date: 16-Jul-07 | DR4: File name: | DS4: CT19707.xls | DU4: Cum | DV4: Accum. | DX4: Date: 19-Jul-07 | DZ4: File name: | EA4: CT20007.xls | EC4: Cum | ED4: Accum. | EF4: Date: 23-Jul-07 | EH4: File name: | EI4: CT20407.xls | EK4: Cum | EL4: Accum. | EN4: Date: 26-Jul-07 | EP4: File name: | EQ4: CT20707.xls | ES4: Cum | ET4: Accum. | EV4: Date: 30-Jul-07 | EX4: File name: | EY4: CT21107.xls | FA4: Cum | FB4: Accum. | FD4: Date: 2-Aug-07 | FF4: File name: | FG4: CT21407.xls | FI4: Cum | FJ4: Accum. | FL4: Date: 6-Aug-07 | FN4: File name: | FO4: CT21807.xls | FQ4: Cum | FR4: Accum. | FT4: Date: 8-Aug-07 | FV4: File name: | FW4: CT22007.xls | FY4: Cum | FZ4: Accum. | GB4: Date: 9-Aug-07 | GD4: File name: | GE4: CT22107.xls | GG4: Cum | GH4: Accum. | GJ4: Date: 13-Aug-07 | GL4: File name: | GM4: CT22507.xls | GO4: Cum | GP4: Accum. | GR4: Date: 16-Aug-07 | GT4: File name: | GU4: CT22807.xls | GW4: Cum | GX4: Accum. | GZ4: Date: 17-Aug-07 | HB4: File name: | HC4: CT22907.xls | HE4: Cum | HF4: Accum. | HH4: Date: 20-Aug-07 | HJ4: File name: | HK4: CT23207.xls | HM4: Cum | HN4: Accum.
F5: Storage | M5: Storage | N5: diff | U5: Storage | V5: diff | AC5: Storage | AD5: diff | AK5: Storage | AL5: diff | AS5: Storage | AT5: diff | BA5: Storage | BB5: diff | BI5: Storage | BJ5: diff | BQ5: Storage | BR5: diff | BY5: Storage | BZ5: diff | CG5: Storage | CH5: diff | CO5: Storage | CP5: diff | CW5: Storage | CX5: diff | DE5: Storage | DF5: diff | DM5: Storage | DN5: diff | DU5: Storage | DV5: diff | EC5: Storage | ED5: diff | EK5: Storage | EL5: diff | ES5: Storage | ET5: diff | FA5: Storage | FB5: diff | FI5: Storage | FJ5: diff | FQ5: Storage | FR5: diff | FY5: Storage | FZ5: diff | GG5: Storage | GH5: diff | GO5: Storage | GP5: diff | GW5: Storage | GX5: diff | HE5: Storage | HF5: diff | HM5: Storage | HN5: diff | HQ5: MAX-A | HR5: MAX-B | HS5: MAX | HY5: Min-A | HZ5: Min-B | IA5: MIN
A6: Tube no. | B6: Trt/Rep | C6: Depth cm | D6: % H2O | E6: H2O cm | F6: cm | H6: Tube no. | I6: Trt/Rep | J6: Depth cm | K6: % H2O | L6: H2O cm | M6: cm | N6: cm | P6: Tube no. | Q6: Trt/Rep | R6: Depth cm | S6: % H2O | T6: H2O cm | U6: cm | V6: cm | X6: Tube no. | Y6: Trt/Rep | Z6: Depth cm | AA6: % H2O | AB6: H2O cm | AC6: cm | AD6: cm | AF6: Tube no. | AG6: Trt/Rep | AH6: Depth cm | AI6: % H2O | AJ6: H2O cm | AK6: cm | AL6: cm | AN6: Tube no. | AO6: Trt/Rep | AP6: Depth cm | AQ6: % H2O | AR6: H2O cm | AS6: cm | AT6: cm | AV6: Tube no. | AW6: Trt/Rep | AX6: Depth cm | AY6: % H2O | AZ6: H2O cm | BA6: cm | BB6: cm | BD6: Tube no. | BE6: Trt/Rep | BF6: Depth cm | BG6: % H2O | BH6: H2O cm | BI6: cm | BJ6: cm | BL6: Tube no. | BM6: Trt/Rep | BN6: Depth cm | BO6: % H2O | BP6: H2O cm | BQ6: cm | BR6: cm | BT6: Tube no. | BU6: Trt/Rep | BV6: Depth cm | BW6: % H2O | BX6: H2O cm | BY6: cm | BZ6: cm | CB6: Tube no. | CC6: Trt/Rep | CD6: Depth cm | CE6: % H2O | CF6: H2O cm | CG6: cm | CH6: cm | CJ6: Tube no. | CK6: Trt/Rep | CL6: Depth cm | CM6: % H2O | CN6: H2O cm | CO6: cm | CP6: cm | CR6: Tube no. | CS6: Trt/Rep | CT6: Depth cm | CU6: % H2O | CV6: H2O cm | CW6: cm | CX6: cm | CZ6: Tube no. | DA6: Trt/Rep | DB6: Depth cm | DC6: % H2O | DD6: H2O cm | DE6: cm | DF6: cm | DH6: Tube no. | DI6: Trt/Rep | DJ6: Depth cm | DK6: % H2O | DL6: H2O cm | DM6: cm | DN6: cm | DP6: Tube no. | DQ6: Trt/Rep | DR6: Depth cm | DS6: % H2O | DT6: H2O cm | DU6: cm | DV6: cm | DX6: Tube no. | DY6: Trt/Rep | DZ6: Depth cm | EA6: % H2O | EB6: H2O cm | EC6: cm | ED6: cm | EF6: Tube no. | EG6: Trt/Rep | EH6: Depth cm | EI6: % H2O | EJ6: H2O cm | EK6: cm | EL6: cm | EN6: Tube no. | EO6: Trt/Rep | EP6: Depth cm | EQ6: % H2O | ER6: H2O cm | ES6: cm | ET6: cm | EV6: Tube no. | EW6: Trt/Rep | EX6: Depth cm | EY6: % H2O | EZ6: H2O cm | FA6: cm | FB6: cm | FD6: Tube no. | FE6: Trt/Rep | FF6: Depth cm | FG6: % H2O | FH6: H2O cm | FI6: cm | FJ6: cm | FL6: Tube no. | FM6: Trt/Rep | FN6: Depth cm | FO6: % H2O | FP6: H2O cm | FQ6: cm | FR6: cm | FT6: Tube no. | FU6: Trt/Rep | FV6: Depth cm | FW6: % H2O | FX6: H2O cm | FY6: cm | FZ6: cm | GB6: Tube no. | GC6: Trt/Rep | GD6: Depth cm | GE6: % H2O | GF6: H2O cm | GG6: cm | GH6: cm | GJ6: Tube no. | GK6: Trt/Rep | GL6: Depth cm | GM6: % H2O | GN6: H2O cm | GO6: cm | GP6: cm | GR6: Tube no. | GS6: Trt/Rep | GT6: Depth cm | GU6: % H2O | GV6: H2O cm | GW6: cm | GX6: cm | GZ6: Tube no. | HA6: Trt/Rep | HB6: Depth cm | HC6: % H2O | HD6: H2O cm | HE6: cm | HF6: cm | HH6: Tube no. | HI6: Trt/Rep | HJ6: Depth cm | HK6: % H2O | HL6: H2O cm | HM6: cm | HN6: cm
A7: 2 | H7: 2 | I7: STR1 | J7: 30 | K7: 0.166 | L7: =K7*30 -> 4.98 | M7: =L7 -> 4.98 | N7: =F7-M7 -> -4.98 | P7: =A7 -> 2 | Q7: =B7 -> 0 | R7: 30 | S7: 0.193 | T7: =S7*30 -> 5.79 | U7: =T7 -> 5.79 | V7: =M7-U7 -> -0.81 | X7: =P7 -> 2 | Y7: =Q7 -> 0 | Z7: 30 | AA7: 0.16 | AB7: =AA7*30 -> 4.8 | AC7: =AB7 -> 4.8 | AD7: =U7-AC7 -> 0.99 | AF7: =X7 -> 2 | AG7: =Y7 -> 0 | AH7: 30 | AI7: #N/A | AJ7: =AI7*30 -> #N/A | AK7: =AJ7 -> #N/A | AL7: =AC7-AK7 -> #N/A | AN7: =AF7 -> 2 | AO7: =AG7 -> 0 | AP7: 30 | AQ7: 0.127 | AR7: =AQ7*30 -> 3.81 | AS7: =AR7 -> 3.81 | AT7: =AC7-AS7 -> 0.99 | AV7: =AN7 -> 2 | AW7: =AO7 -> 0 | AX7: 30 | AY7: #N/A | AZ7: =AY7*30 -> #N/A | BA7: =AZ7 -> #N/A | BB7: =AK7-BA7 -> #N/A | BD7: =AV7 -> 2 | BE7: =AW7 -> 0 | BF7: 30 | BG7: 0.181 | BH7: =BG7*30 -> 5.43 | BI7: =BH7 -> 5.43 | BJ7: =AS7-BI7 -> -1.62 | BL7: =BD7 -> 2 | BM7: =BE7 -> 0 | BN7: 30 | BO7: 0.151 | BP7: =BO7*30 -> 4.53 | BQ7: =BP7 -> 4.53 | BR7: =BI7-BQ7 -> 0.9 | BT7: =BL7 -> 2 | BU7: =BM7 -> 0 | BV7: 30 | BW7: 0.12 | BX7: =BW7*30 -> 3.6 | BY7: =BX7 -> 3.6 | BZ7: =BQ7-BY7 -> 0.93 | CB7: =BT7 -> 2 | CC7: =BU7 -> 0 | CD7: 30 | CE7: 0.155 | CF7: =CE7*30 -> 4.65 | CG7: =CF7 -> 4.65 | CH7: =BY7-CG7 -> -1.05 | CJ7: =CB7 -> 2 | CK7: =CC7 -> 0 | CL7: 30 | CM7: 0.119 | CN7: =CM7*30 -> 3.57 | CO7: =CN7 -> 3.57 | CP7: =CG7-CO7 -> 1.08 | CR7: =CJ7 -> 2 | CS7: =CK7 -> 0 | CT7: 30 | CU7: 0.092 | CV7: =CU7*30 -> 2.76 | CW7: =CV7 -> 2.76 | CX7: =CO7-CW7 -> 0.81 | CZ7: =CR7 -> 2 | DA7: =CS7 -> 0 | DB7: 30 | DC7: #N/A | DD7: =DC7*30 -> #N/A | DE7: =DD7 -> #N/A | DF7: =CW7-DE7 -> #N/A | DH7: =CZ7 -> 2 | DI7: =DA7 -> 0 | DJ7: 30 | DK7: 0.185 | DL7: =DK7*30 -> 5.55 | DM7: =DL7 -> 5.55 | DN7: =CW7-DM7 -> -2.79 | DP7: =DH7 -> 2 | DQ7: =DI7 -> 0 | DR7: 30 | DS7: #N/A | DT7: =DS7*30 -> #N/A | DU7: =DT7 -> #N/A | DV7: =DE7-DU7 -> #N/A | DX7: =DP7 -> 2 | DY7: =DQ7 -> 0 | DZ7: 30 | EA7: 0.124 | EB7: =EA7*30 -> 3.72 | EC7: =EB7 -> 3.72 | ED7: =DM7-EC7 -> 1.83 | EF7: =DX7 -> 2 | EG7: =DY7 -> 0 | EH7: 30 | EI7: #N/A | EJ7: =EI7*30 -> #N/A | EK7: =EJ7 -> #N/A | EL7: =DU7-EK7 -> #N/A | EN7: =EF7 -> 2 | EO7: =EG7 -> 0 | EP7: 30 | EQ7: 0.105 | ER7: =EQ7*30 -> 3.15 | ES7: =ER7 -> 3.15 | ET7: =EC7-ES7 -> 0.57 | EV7: =EN7 -> 2 | EW7: =EO7 -> 0 | EX7: 30 | EY7: #N/A | EZ7: =EY7*30 -> #N/A | FA7: =EZ7 -> #N/A | FB7: =EK7-FA7 -> #N/A | FD7: =EV7 -> 2 | FE7: =EW7 -> 0 | FF7: 30 | FG7: 0.099 | FH7: =FG7*30 -> 2.97 | FI7: =FH7 -> 2.97 | FJ7: =ES7-FI7 -> 0.18 | FL7: =FD7 -> 2 | FM7: =FE7 -> 0 | FN7: 30 | FO7: 0.174 | FP7: =FO7*30 -> 5.22 | FQ7: =FP7 -> 5.22 | FR7: =FI7-FQ7 -> -2.25 | FT7: =FL7 -> 2 | FU7: =FM7 -> 0 | FV7: 30 | FW7: #N/A | FX7: =FW7*30 -> #N/A | FY7: =FX7 -> #N/A | FZ7: =FQ7-FY7 -> #N/A | GB7: =FT7 -> 2 | GC7: =FU7 -> 0 | GD7: 30 | GE7: #N/A | GF7: =GE7*30 -> #N/A | GG7: =GF7 -> #N/A | GH7: =FY7-GG7 -> #N/A | GJ7: =GB7 -> 2 | GK7: =GC7 -> 0 | GL7: 30 | GM7: 0.12 | GN7: =GM7*30 -> 3.6 | GO7: =GN7 -> 3.6 | GP7: =FQ7-GO7 -> 1.62 | GR7: =GJ7 -> 2 | GS7: =GK7 -> 0 | GT7: 30 | GU7: #N/A | GV7: =GU7*30 -> #N/A | GW7: =GV7 -> #N/A | GX7: =FY7-GW7 -> #N/A | GZ7: =GR7 -> 2 | HA7: =GS7 -> 0 | HB7: 30 | HC7: #N/A | HD7: =HC7*30 -> #N/A | HE7: =HD7 -> #N/A | HF7: =GG7-HE7 -> #N/A | HH7: =GZ7 -> 2 | HI7: =HA7 -> 0 | HJ7: 30 | HK7: 0.091 | HL7: =HK7*30 -> 2.73 | HM7: =HL7 -> 2.73 | HN7: =GO7-HM7 -> 0.87 | HP7: 30 | HQ7: =MAX(D7,S7,AA7,AQ7, BG7, BO7, BW7, CE7, CM7, CU7, DK7,EA7,EQ7,FG7,FO7, GM7,HK7) -> 0.193 | HR7: 0.233 | HS7: =MAX(HQ7,HR7) -> 0.233 | HT7: =HS7*30 -> 6.99 | HU7: =HT7 -> 6.99 | HV7: =HH7 -> 2 | HX7: 30 | HY7: =MIN(D7,S7,AA7,AQ7,BG7, BO7, BW7, CE7, CM7, CU7, DK7, EA7,EQ7,FG7,FO7,GM7,HK7) -> 0.091 | HZ7: 0.071 | IA7: =MIN(HY7,HZ7) -> 0.071 | IB7: =IA7*30 -> 2.13 | IC7: =IB7 -> 2.13
J8: 50 | K8: 0.191 | L8: =K8*20 -> 3.82 | M8: =M7+L8 -> 8.8 | N8: =F8-M8 -> -8.8 | R8: 50 | S8: 0.208 | T8: =S8*20 -> 4.16 | U8: =U7+T8 -> 9.95 | V8: =M8-U8 -> -1.15 | Z8: 50 | AA8: 0.189 | AB8: =AA8*20 -> 3.78 | AC8: =AC7+AB8 -> 8.58 | AD8: =U8-AC8 -> 1.37 | AH8: 50 | AI8: #N/A | AJ8: =AI8*20 -> #N/A | AK8: =AK7+AJ8 -> #N/A | AL8: =AC8-AK8 -> #N/A | AP8: 50 | AQ8: 0.172 | AR8: =AQ8*20 -> 3.44 | AS8: =AS7+AR8 -> 7.25 | AT8: =AC8-AS8 -> 1.33 | AX8: 50 | AY8: #N/A | AZ8: =AY8*20 -> #N/A | BA8: =BA7+AZ8 -> #N/A | BB8: =AK8-BA8 -> #N/A | BF8: 50 | BG8: 0.206 | BH8: =BG8*20 -> 4.12 | BI8: =BI7+BH8 -> 9.55 | BJ8: =AS8-BI8 -> -2.3 | BN8: 50 | BO8: 0.181 | BP8: =BO8*20 -> 3.62 | BQ8: =BQ7+BP8 -> 8.15 | BR8: =BI8-BQ8 -> 1.4 | BV8: 50 | BW8: 0.153 | BX8: =BW8*20 -> 3.06 | BY8: =BY7+BX8 -> 6.66 | BZ8: =BQ8-BY8 -> 1.49 | CD8: 50 | CE8: 0.188 | CF8: =CE8*20 -> 3.76 | CG8: =CG7+CF8 -> 8.41 | CH8: =BY8-CG8 -> -1.75 | CL8: 50 | CM8: 0.147 | CN8: =CM8*20 -> 2.94 | CO8: =CO7+CN8 -> 6.51 | CP8: =CG8-CO8 -> 1.9 | CT8: 50 | CU8: 0.128 | CV8: =CU8*20 -> 2.56 | CW8: =CW7+CV8 -> 5.32 | CX8: =CO8-CW8 -> 1.19 | DB8: 50 | DC8: #N/A | DD8: =DC8*20 -> #N/A | DE8: =DE7+DD8 -> #N/A | DF8: =CW8-DE8 -> #N/A | DJ8: 50 | DK8: 0.204 | DL8: =DK8*20 -> 4.08 | DM8: =DM7+DL8 -> 9.63 | DN8: =CW8-DM8 -> -4.31 | DR8: 50 | DS8: #N/A | DT8: =DS8*20 -> #N/A | DU8: =DU7+DT8 -> #N/A | DV8: =DE8-DU8 -> #N/A | DZ8: 50 | EA8: 0.142 | EB8: =EA8*20 -> 2.84 | EC8: =EC7+EB8 -> 6.56 | ED8: =DM8-EC8 -> 3.07 | EH8: 50 | EI8: #N/A | EJ8: =EI8*20 -> #N/A | EK8: =EK7+EJ8 -> #N/A | EL8: =DU8-EK8 -> #N/A | EP8: 50 | EQ8: 0.127 | ER8: =EQ8*20 -> 2.54 | ES8: =ES7+ER8 -> 5.69 | ET8: =EC8-ES8 -> 0.87 | EX8: 50 | EY8: #N/A | EZ8: =EY8*20 -> #N/A | FA8: =FA7+EZ8 -> #N/A | FB8: =EK8-FA8 -> #N/A | FF8: 50 | FG8: 0.118 | FH8: =FG8*20 -> 2.36 | FI8: =FI7+FH8 -> 5.33 | FJ8: =ES8-FI8 -> 0.36 | FN8: 50 | FO8: 0.202 | FP8: =FO8*20 -> 4.04 | FQ8: =FQ7+FP8 -> 9.26 | FR8: =FI8-FQ8 -> -3.93 | FV8: 50 | FW8: #N/A | FX8: =FW8*20 -> #N/A | FY8: =FY7+FX8 -> #N/A | FZ8: =FQ8-FY8 -> #N/A | GD8: 50 | GE8: #N/A | GF8: =GE8*20 -> #N/A | GG8: =GG7+GF8 -> #N/A | GH8: =FY8-GG8 -> #N/A | GL8: 50 | GM8: 0.155 | GN8: =GM8*20 -> 3.1 | GO8: =GO7+GN8 -> 6.7 | GP8: =FQ8-GO8 -> 2.56 | GT8: 50 | GU8: #N/A | GV8: =GU8*20 -> #N/A | GW8: =GW7+GV8 -> #N/A | GX8: =FY8-GW8 -> #N/A | HB8: 50 | HC8: #N/A | HD8: =HC8*20 -> #N/A | HE8: =HE7+HD8 -> #N/A | HF8: =GG8-HE8 -> #N/A | HJ8: 50 | HK8: 0.125 | HL8: =HK8*20 -> 2.5 | HM8: =HM7+HL8 -> 5.23 | HN8: =GO8-HM8 -> 1.47 | HP8: 50 | HQ8: =MAX(D8,S8,AA8,AQ8, BG8, BO8, BW8, CE8, CM8, CU8, DK8,EA8,EQ8,FG8,FO8, GM8,HK8) -> 0.208 | HR8: 0.209 | HS8: =MAX(HQ8,HR8) -> 0.209 | HT8: =HS8*20 -> 4.18 | HU8: =HU7+HT8 -> 11.17 | HX8: 50 | HY8: =MIN(D8,S8,AA8,AQ8,BG8, BO8, BW8, CE8, CM8, CU8, DK8, EA8,EQ8,FG8,FO8,GM8,HK8) -> 0.118 | HZ8: 0.111 | IA8: =MIN(HY8,HZ8) -> 0.111 | IB8: =IA8*20 -> 2.22 | IC8: =IC7+IB8 -> 4.35
J9: 70 | K9: 0.169 | L9: =K9*20 -> 3.38 | M9: =M8+L9 -> 12.18 | N9: =F9-M9 -> -12.18 | R9: 70 | S9: 0.169 | T9: =S9*20 -> 3.38 | U9: =U8+T9 -> 13.33 | V9: =M9-U9 -> -1.15 | Z9: 70 | AA9: 0.173 | AB9: =AA9*20 -> 3.46 | AC9: =AC8+AB9 -> 12.04 | AD9: =U9-AC9 -> 1.29 | AH9: 70 | AI9: #N/A | AJ9: =AI9*20 -> #N/A | AK9: =AK8+AJ9 -> #N/A | AL9: =AC9-AK9 -> #N/A | AP9: 70 | AQ9: 0.168 | AR9: =AQ9*20 -> 3.36 | AS9: =AS8+AR9 -> 10.61 | AT9: =AC9-AS9 -> 1.43 | AX9: 70 | AY9: #N/A | AZ9: =AY9*20 -> #N/A | BA9: =BA8+AZ9 -> #N/A | BB9: =AK9-BA9 -> #N/A | BF9: 70 | BG9: 0.186 | BH9: =BG9*20 -> 3.72 | BI9: =BI8+BH9 -> 13.27 | BJ9: =AS9-BI9 -> -2.66 | BN9: 70 | BO9: 0.172 | BP9: =BO9*20 -> 3.44 | BQ9: =BQ8+BP9 -> 11.59 | BR9: =BI9-BQ9 -> 1.68 | BV9: 70 | BW9: 0.159 | BX9: =BW9*20 -> 3.18 | BY9: =BY8+BX9 -> 9.84 | BZ9: =BQ9-BY9 -> 1.75 | CD9: 70 | CE9: 0.171 | CF9: =CE9*20 -> 3.42 | CG9: =CG8+CF9 -> 11.83 | CH9: =BY9-CG9 -> -1.99 | CL9: 70 | CM9: 0.156 | CN9: =CM9*20 -> 3.12 | CO9: =CO8+CN9 -> 9.63 | CP9: =CG9-CO9 -> 2.2 | CT9: 70 | CU9: 0.132 | CV9: =CU9*20 -> 2.64 | CW9: =CW8+CV9 -> 7.96 | CX9: =CO9-CW9 -> 1.67 | DB9: 70 | DC9: #N/A | DD9: =DC9*20 -> #N/A | DE9: =DE8+DD9 -> #N/A | DF9: =CW9-DE9 -> #N/A | DJ9: 70 | DK9: 0.191 | DL9: =DK9*20 -> 3.82 | DM9: =DM8+DL9 -> 13.45 | DN9: =CW9-DM9 -> -5.49 | DR9: 70 | DS9: #N/A | DT9: =DS9*20 -> #N/A | DU9: =DU8+DT9 -> #N/A | DV9: =DE9-DU9 -> #N/A | DZ9: 70 | EA9: 0.144 | EB9: =EA9*20 -> 2.88 | EC9: =EC8+EB9 -> 9.44 | ED9: =DM9-EC9 -> 4.01 | EH9: 70 | EI9: #N/A | EJ9: =EI9*20 -> #N/A | EK9: =EK8+EJ9 -> #N/A | EL9: =DU9-EK9 -> #N/A | EP9: 70 | EQ9: 0.126 | ER9: =EQ9*20 -> 2.52 | ES9: =ES8+ER9 -> 8.21 | ET9: =EC9-ES9 -> 1.23 | EX9: 70 | EY9: #N/A | EZ9: =EY9*20 -> #N/A | FA9: =FA8+EZ9 -> #N/A | FB9: =EK9-FA9 -> #N/A | FF9: 70 | FG9: 0.114 | FH9: =FG9*20 -> 2.28 | FI9: =FI8+FH9 -> 7.61 | FJ9: =ES9-FI9 -> 0.6 | FN9: 70 | FO9: 0.183 | FP9: =FO9*20 -> 3.66 | FQ9: =FQ8+FP9 -> 12.92 | FR9: =FI9-FQ9 -> -5.31 | FV9: 70 | FW9: #N/A | FX9: =FW9*20 -> #N/A | FY9: =FY8+FX9 -> #N/A | FZ9: =FQ9-FY9 -> #N/A | GD9: 70 | GE9: #N/A | GF9: =GE9*20 -> #N/A | GG9: =GG8+GF9 -> #N/A | GH9: =FY9-GG9 -> #N/A | GL9: 70 | GM9: 0.148 | GN9: =GM9*20 -> 2.96 | GO9: =GO8+GN9 -> 9.66 | GP9: =FQ9-GO9 -> 3.26 | GT9: 70 | GU9: #N/A | GV9: =GU9*20 -> #N/A | GW9: =GW8+GV9 -> #N/A | GX9: =FY9-GW9 -> #N/A | HB9: 70 | HC9: #N/A | HD9: =HC9*20 -> #N/A | HE9: =HE8+HD9 -> #N/A | HF9: =GG9-HE9 -> #N/A | HJ9: 70 | HK9: 0.121 | HL9: =HK9*20 -> 2.42 | HM9: =HM8+HL9 -> 7.65 | HN9: =GO9-HM9 -> 2.01 | HP9: 70 | HQ9: =MAX(D9,S9,AA9,AQ9, BG9, BO9, BW9, CE9, CM9, CU9, DK9,EA9,EQ9,FG9,FO9, GM9,HK9) -> 0.191 | HR9: 0.184 | HS9: =MAX(HQ9,HR9) -> 0.191 | HT9: =HS9*20 -> 3.82 | HU9: =HU8+HT9 -> 14.99 | HX9: 70 | HY9: =MIN(D9,S9,AA9,AQ9,BG9, BO9, BW9, CE9, CM9, CU9, DK9, EA9,EQ9,FG9,FO9,GM9,HK9) -> 0.114 | HZ9: 0.102 | IA9: =MIN(HY9,HZ9) -> 0.102 | IB9: =IA9*20 -> 2.04 | IC9: =IC8+IB9 -> 6.39
J10: 90 | K10: 0.156 | L10: =K10*20 -> 3.12 | M10: =M9+L10 -> 15.3 | N10: =F10-M10 -> -15.3 | R10: 90 | S10: 0.156 | T10: =S10*20 -> 3.12 | U10: =U9+T10 -> 16.45 | V10: =M10-U10 -> -1.15 | Z10: 90 | AA10: 0.145 | AB10: =AA10*20 -> 2.9 | AC10: =AC9+AB10 -> 14.94 | AD10: =U10-AC10 -> 1.51 | AH10: 90 | AI10: #N/A | AJ10: =AI10*20 -> #N/A | AK10: =AK9+AJ10 -> #N/A | AL10: =AC10-AK10 -> #N/A | AP10: 90 | AQ10: 0.142 | AR10: =AQ10*20 -> 2.84 | AS10: =AS9+AR10 -> 13.45 | AT10: =AC10-AS10 -> 1.49 | AX10: 90 | AY10: #N/A | AZ10: =AY10*20 -> #N/A | BA10: =BA9+AZ10 -> #N/A | BB10: =AK10-BA10 -> #N/A | BF10: 90 | BG10: 0.147 | BH10: =BG10*20 -> 2.94 | BI10: =BI9+BH10 -> 16.21 | BJ10: =AS10-BI10 -> -2.76 | BN10: 90 | BO10: 0.144 | BP10: =BO10*20 -> 2.88 | BQ10: =BQ9+BP10 -> 14.47 | BR10: =BI10-BQ10 -> 1.74 | BV10: 90 | BW10: 0.144 | BX10: =BW10*20 -> 2.88 | BY10: =BY9+BX10 -> 12.72 | BZ10: =BQ10-BY10 -> 1.75 | CD10: 90 | CE10: 0.138 | CF10: =CE10*20 -> 2.76 | CG10: =CG9+CF10 -> 14.59 | CH10: =BY10-CG10 -> -1.87 | CL10: 90 | CM10: 0.137 | CN10: =CM10*20 -> 2.74 | CO10: =CO9+CN10 -> 12.37 | CP10: =CG10-CO10 -> 2.22 | CT10: 90 | CU10: 0.116 | CV10: =CU10*20 -> 2.32 | CW10: =CW9+CV10 -> 10.28 | CX10: =CO10-CW10 -> 2.09 | DB10: 90 | DC10: #N/A | DD10: =DC10*20 -> #N/A | DE10: =DE9+DD10 -> #N/A | DF10: =CW10-DE10 -> #N/A | DJ10: 90 | DK10: 0.159 | DL10: =DK10*20 -> 3.18 | DM10: =DM9+DL10 -> 16.63 | DN10: =CW10-DM10 -> -6.35 | DR10: 90 | DS10: #N/A | DT10: =DS10*20 -> #N/A | DU10: =DU9+DT10 -> #N/A | DV10: =DE10-DU10 -> #N/A | DZ10: 90 | EA10: 0.116 | EB10: =EA10*20 -> 2.32 | EC10: =EC9+EB10 -> 11.76 | ED10: =DM10-EC10 -> 4.87 | EH10: 90 | EI10: #N/A | EJ10: =EI10*20 -> #N/A | EK10: =EK9+EJ10 -> #N/A | EL10: =DU10-EK10 -> #N/A | EP10: 90 | EQ10: 0.096 | ER10: =EQ10*20 -> 1.92 | ES10: =ES9+ER10 -> 10.13 | ET10: =EC10-ES10 -> 1.63 | EX10: 90 | EY10: #N/A | EZ10: =EY10*20 -> #N/A | FA10: =FA9+EZ10 -> #N/A | FB10: =EK10-FA10 -> #N/A | FF10: 90 | FG10: 0.083 | FH10: =FG10*20 -> 1.66 | FI10: =FI9+FH10 -> 9.27 | FJ10: =ES10-FI10 -> 0.86 | FN10: 90 | FO10: 0.155 | FP10: =FO10*20 -> 3.1 | FQ10: =FQ9+FP10 -> 16.02 | FR10: =FI10-FQ10 -> -6.75 | FV10: 90 | FW10: #N/A | FX10: =FW10*20 -> #N/A | FY10: =FY9+FX10 -> #N/A | FZ10: =FQ10-FY10 -> #N/A | GD10: 90 | GE10: #N/A | GF10: =GE10*20 -> #N/A | GG10: =GG9+GF10 -> #N/A | GH10: =FY10-GG10 -> #N/A | GL10: 90 | GM10: 0.116 | GN10: =GM10*20 -> 2.32 | GO10: =GO9+GN10 -> 11.98 | GP10: =FQ10-GO10 -> 4.04 | GT10: 90 | GU10: #N/A | GV10: =GU10*20 -> #N/A | GW10: =GW9+GV10 -> #N/A | GX10: =FY10-GW10 -> #N/A | HB10: 90 | HC10: #N/A | HD10: =HC10*20 -> #N/A | HE10: =HE9+HD10 -> #N/A | HF10: =GG10-HE10 -> #N/A | HJ10: 90 | HK10: 0.086 | HL10: =HK10*20 -> 1.72 | HM10: =HM9+HL10 -> 9.37 | HN10: =GO10-HM10 -> 2.61 | HP10: 90 | HQ10: =MAX(D10,S10,AA10,AQ10, BG10, BO10, BW10, CE10, CM10, CU10, DK10,EA10,EQ10,FG10,FO10, GM10,HK10) -> 0.159 | HR10: 0.141 | HS10: =MAX(HQ10,HR10) -> 0.159 | HT10: =HS10*20 -> 3.18 | HU10: =HU9+HT10 -> 18.17 | HX10: 90 | HY10: =MIN(D10,S10,AA10,AQ10,BG10, BO10, BW10, CE10, CM10, CU10, DK10, EA10,EQ10,FG10,FO10,GM10,HK10) -> 0.083 | HZ10: 0.075 | IA10: =MIN(HY10,HZ10) -> 0.075 | IB10: =IA10*20 -> 1.5 | IC10: =IC9+IB10 -> 7.89
J11: 110 | K11: 0.198 | L11: =K11*20 -> 3.96 | M11: =M10+L11 -> 19.26 | N11: =F11-M11 -> -19.26 | R11: 110 | S11: 0.19 | T11: =S11*20 -> 3.8 | U11: =U10+T11 -> 20.25 | V11: =M11-U11 -> -0.99 | Z11: 110 | AA11: 0.173 | AB11: =AA11*20 -> 3.46 | AC11: =AC10+AB11 -> 18.4 | AD11: =U11-AC11 -> 1.85 | AH11: 110 | AI11: #N/A | AJ11: =AI11*20 -> #N/A | AK11: =AK10+AJ11 -> #N/A | AL11: =AC11-AK11 -> #N/A | AP11: 110 | AQ11: 0.175 | AR11: =AQ11*20 -> 3.5 | AS11: =AS10+AR11 -> 16.95 | AT11: =AC11-AS11 -> 1.45 | AX11: 110 | AY11: #N/A | AZ11: =AY11*20 -> #N/A | BA11: =BA10+AZ11 -> #N/A | BB11: =AK11-BA11 -> #N/A | BF11: 110 | BG11: 0.177 | BH11: =BG11*20 -> 3.54 | BI11: =BI10+BH11 -> 19.75 | BJ11: =AS11-BI11 -> -2.8 | BN11: 110 | BO11: 0.178 | BP11: =BO11*20 -> 3.56 | BQ11: =BQ10+BP11 -> 18.03 | BR11: =BI11-BQ11 -> 1.72 | BV11: 110 | BW11: 0.175 | BX11: =BW11*20 -> 3.5 | BY11: =BY10+BX11 -> 16.22 | BZ11: =BQ11-BY11 -> 1.81 | CD11: 110 | CE11: 0.176 | CF11: =CE11*20 -> 3.52 | CG11: =CG10+CF11 -> 18.11 | CH11: =BY11-CG11 -> -1.89 | CL11: 110 | CM11: 0.175 | CN11: =CM11*20 -> 3.5 | CO11: =CO10+CN11 -> 15.87 | CP11: =CG11-CO11 -> 2.24 | CT11: 110 | CU11: 0.157 | CV11: =CU11*20 -> 3.14 | CW11: =CW10+CV11 -> 13.42 | CX11: =CO11-CW11 -> 2.45 | DB11: 110 | DC11: #N/A | DD11: =DC11*20 -> #N/A | DE11: =DE10+DD11 -> #N/A | DF11: =CW11-DE11 -> #N/A | DJ11: 110 | DK11: 0.179 | DL11: =DK11*20 -> 3.58 | DM11: =DM10+DL11 -> 20.21 | DN11: =CW11-DM11 -> -6.79 | DR11: 110 | DS11: #N/A | DT11: =DS11*20 -> #N/A | DU11: =DU10+DT11 -> #N/A | DV11: =DE11-DU11 -> #N/A | DZ11: 110 | EA11: 0.151 | EB11: =EA11*20 -> 3.02 | EC11: =EC10+EB11 -> 14.78 | ED11: =DM11-EC11 -> 5.43 | EH11: 110 | EI11: #N/A | EJ11: =EI11*20 -> #N/A | EK11: =EK10+EJ11 -> #N/A | EL11: =DU11-EK11 -> #N/A | EP11: 110 | EQ11: 0.12 | ER11: =EQ11*20 -> 2.4 | ES11: =ES10+ER11 -> 12.53 | ET11: =EC11-ES11 -> 2.25 | EX11: 110 | EY11: #N/A | EZ11: =EY11*20 -> #N/A | FA11: =FA10+EZ11 -> #N/A | FB11: =EK11-FA11 -> #N/A | FF11: 110 | FG11: 0.1 | FH11: =FG11*20 -> 2 | FI11: =FI10+FH11 -> 11.27 | FJ11: =ES11-FI11 -> 1.26 | FN11: 110 | FO11: 0.178 | FP11: =FO11*20 -> 3.56 | FQ11: =FQ10+FP11 -> 19.58 | FR11: =FI11-FQ11 -> -8.31 | FV11: 110 | FW11: #N/A | FX11: =FW11*20 -> #N/A | FY11: =FY10+FX11 -> #N/A | FZ11: =FQ11-FY11 -> #N/A | GD11: 110 | GE11: #N/A | GF11: =GE11*20 -> #N/A | GG11: =GG10+GF11 -> #N/A | GH11: =FY11-GG11 -> #N/A | GL11: 110 | GM11: 0.144 | GN11: =GM11*20 -> 2.88 | GO11: =GO10+GN11 -> 14.86 | GP11: =FQ11-GO11 -> 4.72 | GT11: 110 | GU11: #N/A | GV11: =GU11*20 -> #N/A | GW11: =GW10+GV11 -> #N/A | GX11: =FY11-GW11 -> #N/A | HB11: 110 | HC11: #N/A | HD11: =HC11*20 -> #N/A | HE11: =HE10+HD11 -> #N/A | HF11: =GG11-HE11 -> #N/A | HJ11: 110 | HK11: 0.107 | HL11: =HK11*20 -> 2.14 | HM11: =HM10+HL11 -> 11.51 | HN11: =GO11-HM11 -> 3.35 | HP11: 110 | HQ11: =MAX(D11,S11,AA11,AQ11, BG11, BO11, BW11, CE11, CM11, CU11, DK11,EA11,EQ11,FG11,FO11, GM11,HK11) -> 0.19 | HR11: 0.137 | HS11: =MAX(HQ11,HR11) -> 0.19 | HT11: =HS11*20 -> 3.8 | HU11: =HU10+HT11 -> 21.97 | HX11: 110 | HY11: =MIN(D11,S11,AA11,AQ11,BG11, BO11, BW11, CE11, CM11, CU11, DK11, EA11,EQ11,FG11,FO11,GM11,HK11) -> 0.1 | HZ11: 0.085 | IA11: =MIN(HY11,HZ11) -> 0.085 | IB11: =IA11*20 -> 1.7 | IC11: =IC10+IB11 -> 9.59
J12: 130 | K12: 0.227 | L12: =K12*20 -> 4.54 | M12: =M11+L12 -> 23.8 | N12: =F12-M12 -> -23.8 | R12: 130 | S12: 0.22 | T12: =S12*20 -> 4.4 | U12: =U11+T12 -> 24.65 | V12: =M12-U12 -> -0.85 | Z12: 130 | AA12: 0.205 | AB12: =AA12*20 -> 4.1 | AC12: =AC11+AB12 -> 22.5 | AD12: =U12-AC12 -> 2.15 | AH12: 130 | AI12: #N/A | AJ12: =AI12*20 -> #N/A | AK12: =AK11+AJ12 -> #N/A | AL12: =AC12-AK12 -> #N/A | AP12: 130 | AQ12: 0.212 | AR12: =AQ12*20 -> 4.24 | AS12: =AS11+AR12 -> 21.19 | AT12: =AC12-AS12 -> 1.31 | AX12: 130 | AY12: #N/A | AZ12: =AY12*20 -> #N/A | BA12: =BA11+AZ12 -> #N/A | BB12: =AK12-BA12 -> #N/A | BF12: 130 | BG12: 0.214 | BH12: =BG12*20 -> 4.28 | BI12: =BI11+BH12 -> 24.03 | BJ12: =AS12-BI12 -> -2.84 | BN12: 130 | BO12: 0.209 | BP12: =BO12*20 -> 4.18 | BQ12: =BQ11+BP12 -> 22.21 | BR12: =BI12-BQ12 -> 1.82 | BV12: 130 | BW12: 0.213 | BX12: =BW12*20 -> 4.26 | BY12: =BY11+BX12 -> 20.48 | BZ12: =BQ12-BY12 -> 1.73 | CD12: 130 | CE12: 0.208 | CF12: =CE12*20 -> 4.16 | CG12: =CG11+CF12 -> 22.27 | CH12: =BY12-CG12 -> -1.79 | CL12: 130 | CM12: 0.208 | CN12: =CM12*20 -> 4.16 | CO12: =CO11+CN12 -> 20.03 | CP12: =CG12-CO12 -> 2.24 | CT12: 130 | CU12: 0.201 | CV12: =CU12*20 -> 4.02 | CW12: =CW11+CV12 -> 17.44 | CX12: =CO12-CW12 -> 2.59 | DB12: 130 | DC12: #N/A | DD12: =DC12*20 -> #N/A | DE12: =DE11+DD12 -> #N/A | DF12: =CW12-DE12 -> #N/A | DJ12: 130 | DK12: 0.204 | DL12: =DK12*20 -> 4.08 | DM12: =DM11+DL12 -> 24.29 | DN12: =CW12-DM12 -> -6.85 | DR12: 130 | DS12: #N/A | DT12: =DS12*20 -> #N/A | DU12: =DU11+DT12 -> #N/A | DV12: =DE12-DU12 -> #N/A | DZ12: 130 | EA12: 0.187 | EB12: =EA12*20 -> 3.74 | EC12: =EC11+EB12 -> 18.52 | ED12: =DM12-EC12 -> 5.77 | EH12: 130 | EI12: #N/A | EJ12: =EI12*20 -> #N/A | EK12: =EK11+EJ12 -> #N/A | EL12: =DU12-EK12 -> #N/A | EP12: 130 | EQ12: 0.144 | ER12: =EQ12*20 -> 2.88 | ES12: =ES11+ER12 -> 15.41 | ET12: =EC12-ES12 -> 3.11 | EX12: 130 | EY12: #N/A | EZ12: =EY12*20 -> #N/A | FA12: =FA11+EZ12 -> #N/A | FB12: =EK12-FA12 -> #N/A | FF12: 130 | FG12: 0.118 | FH12: =FG12*20 -> 2.36 | FI12: =FI11+FH12 -> 13.63 | FJ12: =ES12-FI12 -> 1.78 | FN12: 130 | FO12: 0.192 | FP12: =FO12*20 -> 3.84 | FQ12: =FQ11+FP12 -> 23.42 | FR12: =FI12-FQ12 -> -9.79 | FV12: 130 | FW12: #N/A | FX12: =FW12*20 -> #N/A | FY12: =FY11+FX12 -> #N/A | FZ12: =FQ12-FY12 -> #N/A | GD12: 130 | GE12: #N/A | GF12: =GE12*20 -> #N/A | GG12: =GG11+GF12 -> #N/A | GH12: =FY12-GG12 -> #N/A | GL12: 130 | GM12: 0.165 | GN12: =GM12*20 -> 3.3 | GO12: =GO11+GN12 -> 18.16 | GP12: =FQ12-GO12 -> 5.26 | GT12: 130 | GU12: #N/A | GV12: =GU12*20 -> #N/A | GW12: =GW11+GV12 -> #N/A | GX12: =FY12-GW12 -> #N/A | HB12: 130 | HC12: #N/A | HD12: =HC12*20 -> #N/A | HE12: =HE11+HD12 -> #N/A | HF12: =GG12-HE12 -> #N/A | HJ12: 130 | HK12: 0.12 | HL12: =HK12*20 -> 2.4 | HM12: =HM11+HL12 -> 13.91 | HN12: =GO12-HM12 -> 4.25 | HP12: 130 | HQ12: =MAX(D12,S12,AA12,AQ12, BG12, BO12, BW12, CE12, CM12, CU12, DK12,EA12,EQ12,FG12,FO12, GM12,HK12) -> 0.22 | HR12: 0.12 | HS12: =MAX(HQ12,HR12) -> 0.22 | HT12: =HS12*20 -> 4.4 | HU12: =HU11+HT12 -> 26.37 | HX12: 130 | HY12: =MIN(D12,S12,AA12,AQ12,BG12, BO12, BW12, CE12, CM12, CU12, DK12, EA12,EQ12,FG12,FO12,GM12,HK12) -> 0.118 | HZ12: 0.102 | IA12: =MIN(HY12,HZ12) -> 0.102 | IB12: =IA12*20 -> 2.04 | IC12: =IC11+IB12 -> 11.63
J13: 150 | K13: 0.221 | L13: =K13*20 -> 4.42 | M13: =M12+L13 -> 28.22 | N13: =F13-M13 -> -28.22 | R13: 150 | S13: 0.213 | T13: =S13*20 -> 4.26 | U13: =U12+T13 -> 28.91 | V13: =M13-U13 -> -0.69 | Z13: 150 | AA13: 0.214 | AB13: =AA13*20 -> 4.28 | AC13: =AC12+AB13 -> 26.78 | AD13: =U13-AC13 -> 2.13 | AH13: 150 | AI13: #N/A | AJ13: =AI13*20 -> #N/A | AK13: =AK12+AJ13 -> #N/A | AL13: =AC13-AK13 -> #N/A | AP13: 150 | AQ13: 0.215 | AR13: =AQ13*20 -> 4.3 | AS13: =AS12+AR13 -> 25.49 | AT13: =AC13-AS13 -> 1.29 | AX13: 150 | AY13: #N/A | AZ13: =AY13*20 -> #N/A | BA13: =BA12+AZ13 -> #N/A | BB13: =AK13-BA13 -> #N/A | BF13: 150 | BG13: 0.213 | BH13: =BG13*20 -> 4.26 | BI13: =BI12+BH13 -> 28.29 | BJ13: =AS13-BI13 -> -2.8 | BN13: 150 | BO13: 0.217 | BP13: =BO13*20 -> 4.34 | BQ13: =BQ12+BP13 -> 26.55 | BR13: =BI13-BQ13 -> 1.74 | BV13: 150 | BW13: 0.218 | BX13: =BW13*20 -> 4.36 | BY13: =BY12+BX13 -> 24.84 | BZ13: =BQ13-BY13 -> 1.71 | CD13: 150 | CE13: 0.219 | CF13: =CE13*20 -> 4.38 | CG13: =CG12+CF13 -> 26.65 | CH13: =BY13-CG13 -> -1.81 | CL13: 150 | CM13: 0.217 | CN13: =CM13*20 -> 4.34 | CO13: =CO12+CN13 -> 24.37 | CP13: =CG13-CO13 -> 2.28 | CT13: 150 | CU13: 0.211 | CV13: =CU13*20 -> 4.22 | CW13: =CW12+CV13 -> 21.66 | CX13: =CO13-CW13 -> 2.71 | DB13: 150 | DC13: #N/A | DD13: =DC13*20 -> #N/A | DE13: =DE12+DD13 -> #N/A | DF13: =CW13-DE13 -> #N/A | DJ13: 150 | DK13: 0.211 | DL13: =DK13*20 -> 4.22 | DM13: =DM12+DL13 -> 28.51 | DN13: =CW13-DM13 -> -6.85 | DR13: 150 | DS13: #N/A | DT13: =DS13*20 -> #N/A | DU13: =DU12+DT13 -> #N/A | DV13: =DE13-DU13 -> #N/A | DZ13: 150 | EA13: 0.202 | EB13: =EA13*20 -> 4.04 | EC13: =EC12+EB13 -> 22.56 | ED13: =DM13-EC13 -> 5.95 | EH13: 150 | EI13: #N/A | EJ13: =EI13*20 -> #N/A | EK13: =EK12+EJ13 -> #N/A | EL13: =DU13-EK13 -> #N/A | EP13: 150 | EQ13: 0.173 | ER13: =EQ13*20 -> 3.46 | ES13: =ES12+ER13 -> 18.87 | ET13: =EC13-ES13 -> 3.69 | EX13: 150 | EY13: #N/A | EZ13: =EY13*20 -> #N/A | FA13: =FA12+EZ13 -> #N/A | FB13: =EK13-FA13 -> #N/A | FF13: 150 | FG13: 0.146 | FH13: =FG13*20 -> 2.92 | FI13: =FI12+FH13 -> 16.55 | FJ13: =ES13-FI13 -> 2.32 | FN13: 150 | FO13: 0.163 | FP13: =FO13*20 -> 3.26 | FQ13: =FQ12+FP13 -> 26.68 | FR13: =FI13-FQ13 -> -10.13 | FV13: 150 | FW13: #N/A | FX13: =FW13*20 -> #N/A | FY13: =FY12+FX13 -> #N/A | FZ13: =FQ13-FY13 -> #N/A | GD13: 150 | GE13: #N/A | GF13: =GE13*20 -> #N/A | GG13: =GG12+GF13 -> #N/A | GH13: =FY13-GG13 -> #N/A | GL13: 150 | GM13: 0.166 | GN13: =GM13*20 -> 3.32 | GO13: =GO12+GN13 -> 21.48 | GP13: =FQ13-GO13 -> 5.2 | GT13: 150 | GU13: #N/A | GV13: =GU13*20 -> #N/A | GW13: =GW12+GV13 -> #N/A | GX13: =FY13-GW13 -> #N/A | HB13: 150 | HC13: #N/A | HD13: =HC13*20 -> #N/A | HE13: =HE12+HD13 -> #N/A | HF13: =GG13-HE13 -> #N/A | HJ13: 150 | HK13: 0.137 | HL13: =HK13*20 -> 2.74 | HM13: =HM12+HL13 -> 16.65 | HN13: =GO13-HM13 -> 4.83 | HP13: 150 | HQ13: =MAX(D13,S13,AA13,AQ13, BG13, BO13, BW13, CE13, CM13, CU13, DK13,EA13,EQ13,FG13,FO13, GM13,HK13) -> 0.219 | HR13: 0.128 | HS13: =MAX(HQ13,HR13) -> 0.219 | HT13: =HS13*20 -> 4.38 | HU13: =HU12+HT13 -> 30.75 | HX13: 150 | HY13: =MIN(D13,S13,AA13,AQ13,BG13, BO13, BW13, CE13, CM13, CU13, DK13, EA13,EQ13,FG13,FO13,GM13,HK13) -> 0.137 | HZ13: 0.105 | IA13: =MIN(HY13,HZ13) -> 0.105 | IB13: =IA13*20 -> 2.1 | IC13: =IC12+IB13 -> 13.73
J14: 170 | K14: 0.232 | L14: =K14*20 -> 4.64 | M14: =M13+L14 -> 32.86 | N14: =F14-M14 -> -32.86 | R14: 170 | S14: 0.226 | T14: =S14*20 -> 4.52 | U14: =U13+T14 -> 33.43 | V14: =M14-U14 -> -0.57 | Z14: 170 | AA14: 0.205 | AB14: =AA14*20 -> 4.1 | AC14: =AC13+AB14 -> 30.88 | AD14: =U14-AC14 -> 2.55 | AH14: 170 | AI14: #N/A | AJ14: =AI14*20 -> #N/A | AK14: =AK13+AJ14 -> #N/A | AL14: =AC14-AK14 -> #N/A | AP14: 170 | AQ14: 0.211 | AR14: =AQ14*20 -> 4.22 | AS14: =AS13+AR14 -> 29.71 | AT14: =AC14-AS14 -> 1.17 | AX14: 170 | AY14: #N/A | AZ14: =AY14*20 -> #N/A | BA14: =BA13+AZ14 -> #N/A | BB14: =AK14-BA14 -> #N/A | BF14: 170 | BG14: 0.21 | BH14: =BG14*20 -> 4.2 | BI14: =BI13+BH14 -> 32.49 | BJ14: =AS14-BI14 -> -2.78 | BN14: 170 | BO14: 0.214 | BP14: =BO14*20 -> 4.28 | BQ14: =BQ13+BP14 -> 30.83 | BR14: =BI14-BQ14 -> 1.66 | BV14: 170 | BW14: 0.211 | BX14: =BW14*20 -> 4.22 | BY14: =BY13+BX14 -> 29.06 | BZ14: =BQ14-BY14 -> 1.77 | CD14: 170 | CE14: 0.213 | CF14: =CE14*20 -> 4.26 | CG14: =CG13+CF14 -> 30.91 | CH14: =BY14-CG14 -> -1.85 | CL14: 170 | CM14: 0.215 | CN14: =CM14*20 -> 4.3 | CO14: =CO13+CN14 -> 28.67 | CP14: =CG14-CO14 -> 2.24 | CT14: 170 | CU14: 0.21 | CV14: =CU14*20 -> 4.2 | CW14: =CW13+CV14 -> 25.86 | CX14: =CO14-CW14 -> 2.81 | DB14: 170 | DC14: #N/A | DD14: =DC14*20 -> #N/A | DE14: =DE13+DD14 -> #N/A | DF14: =CW14-DE14 -> #N/A | DJ14: 170 | DK14: 0.216 | DL14: =DK14*20 -> 4.32 | DM14: =DM13+DL14 -> 32.83 | DN14: =CW14-DM14 -> -6.97 | DR14: 170 | DS14: #N/A | DT14: =DS14*20 -> #N/A | DU14: =DU13+DT14 -> #N/A | DV14: =DE14-DU14 -> #N/A | DZ14: 170 | EA14: 0.202 | EB14: =EA14*20 -> 4.04 | EC14: =EC13+EB14 -> 26.6 | ED14: =DM14-EC14 -> 6.23 | EH14: 170 | EI14: #N/A | EJ14: =EI14*20 -> #N/A | EK14: =EK13+EJ14 -> #N/A | EL14: =DU14-EK14 -> #N/A | EP14: 170 | EQ14: 0.195 | ER14: =EQ14*20 -> 3.9 | ES14: =ES13+ER14 -> 22.77 | ET14: =EC14-ES14 -> 3.83 | EX14: 170 | EY14: #N/A | EZ14: =EY14*20 -> #N/A | FA14: =FA13+EZ14 -> #N/A | FB14: =EK14-FA14 -> #N/A | FF14: 170 | FG14: 0.178 | FH14: =FG14*20 -> 3.56 | FI14: =FI13+FH14 -> 20.11 | FJ14: =ES14-FI14 -> 2.66 | FN14: 170 | FO14: 0.18 | FP14: =FO14*20 -> 3.6 | FQ14: =FQ13+FP14 -> 30.28 | FR14: =FI14-FQ14 -> -10.17 | FV14: 170 | FW14: #N/A | FX14: =FW14*20 -> #N/A | FY14: =FY13+FX14 -> #N/A | FZ14: =FQ14-FY14 -> #N/A | GD14: 170 | GE14: #N/A | GF14: =GE14*20 -> #N/A | GG14: =GG13+GF14 -> #N/A | GH14: =FY14-GG14 -> #N/A | GL14: 170 | GM14: 0.178 | GN14: =GM14*20 -> 3.56 | GO14: =GO13+GN14 -> 25.04 | GP14: =FQ14-GO14 -> 5.24 | GT14: 170 | GU14: #N/A | GV14: =GU14*20 -> #N/A | GW14: =GW13+GV14 -> #N/A | GX14: =FY14-GW14 -> #N/A | HB14: 170 | HC14: #N/A | HD14: =HC14*20 -> #N/A | HE14: =HE13+HD14 -> #N/A | HF14: =GG14-HE14 -> #N/A | HJ14: 170 | HK14: 0.146 | HL14: =HK14*20 -> 2.92 | HM14: =HM13+HL14 -> 19.57 | HN14: =GO14-HM14 -> 5.47 | HP14: 170 | HQ14: =MAX(D14,S14,AA14,AQ14, BG14, BO14, BW14, CE14, CM14, CU14, DK14,EA14,EQ14,FG14,FO14, GM14,HK14) -> 0.226 | HR14: 0.14 | HS14: =MAX(HQ14,HR14) -> 0.226 | HT14: =HS14*20 -> 4.52 | HU14: =HU13+HT14 -> 35.27 | HX14: 170 | HY14: =MIN(D14,S14,AA14,AQ14,BG14, BO14, BW14, CE14, CM14, CU14, DK14, EA14,EQ14,FG14,FO14,GM14,HK14) -> 0.146 | HZ14: 0.111 | IA14: =MIN(HY14,HZ14) -> 0.111 | IB14: =IA14*20 -> 2.22 | IC14: =IC13+IB14 -> 15.95
J15: 190 | K15: 0.243 | L15: =K15*20 -> 4.86 | M15: =M14+L15 -> 37.72 | N15: =F15-M15 -> -37.72 | R15: 190 | S15: 0.237 | T15: =S15*20 -> 4.74 | U15: =U14+T15 -> 38.17 | V15: =M15-U15 -> -0.45 | Z15: 190 | AA15: 0.234 | AB15: =AA15*20 -> 4.68 | AC15: =AC14+AB15 -> 35.56 | AD15: =U15-AC15 -> 2.61 | AH15: 190 | AI15: #N/A | AJ15: =AI15*20 -> #N/A | AK15: =AK14+AJ15 -> #N/A | AL15: =AC15-AK15 -> #N/A | AP15: 190 | AQ15: 0.234 | AR15: =AQ15*20 -> 4.68 | AS15: =AS14+AR15 -> 34.39 | AT15: =AC15-AS15 -> 1.17 | AX15: 190 | AY15: #N/A | AZ15: =AY15*20 -> #N/A | BA15: =BA14+AZ15 -> #N/A | BB15: =AK15-BA15 -> #N/A | BF15: 190 | BG15: 0.239 | BH15: =BG15*20 -> 4.78 | BI15: =BI14+BH15 -> 37.27 | BJ15: =AS15-BI15 -> -2.88 | BN15: 190 | BO15: 0.239 | BP15: =BO15*20 -> 4.78 | BQ15: =BQ14+BP15 -> 35.61 | BR15: =BI15-BQ15 -> 1.66 | BV15: 190 | BW15: 0.241 | BX15: =BW15*20 -> 4.82 | BY15: =BY14+BX15 -> 33.88 | BZ15: =BQ15-BY15 -> 1.73 | CD15: 190 | CE15: 0.242 | CF15: =CE15*20 -> 4.84 | CG15: =CG14+CF15 -> 35.75 | CH15: =BY15-CG15 -> -1.87 | CL15: 190 | CM15: 0.239 | CN15: =CM15*20 -> 4.78 | CO15: =CO14+CN15 -> 33.45 | CP15: =CG15-CO15 -> 2.3 | CT15: 190 | CU15: 0.241 | CV15: =CU15*20 -> 4.82 | CW15: =CW14+CV15 -> 30.68 | CX15: =CO15-CW15 -> 2.77 | DB15: 190 | DC15: #N/A | DD15: =DC15*20 -> #N/A | DE15: =DE14+DD15 -> #N/A | DF15: =CW15-DE15 -> #N/A | DJ15: 190 | DK15: 0.244 | DL15: =DK15*20 -> 4.88 | DM15: =DM14+DL15 -> 37.71 | DN15: =CW15-DM15 -> -7.03 | DR15: 190 | DS15: #N/A | DT15: =DS15*20 -> #N/A | DU15: =DU14+DT15 -> #N/A | DV15: =DE15-DU15 -> #N/A | DZ15: 190 | EA15: 0.24 | EB15: =EA15*20 -> 4.8 | EC15: =EC14+EB15 -> 31.4 | ED15: =DM15-EC15 -> 6.31 | EH15: 190 | EI15: #N/A | EJ15: =EI15*20 -> #N/A | EK15: =EK14+EJ15 -> #N/A | EL15: =DU15-EK15 -> #N/A | EP15: 190 | EQ15: 0.232 | ER15: =EQ15*20 -> 4.64 | ES15: =ES14+ER15 -> 27.41 | ET15: =EC15-ES15 -> 3.99 | EX15: 190 | EY15: #N/A | EZ15: =EY15*20 -> #N/A | FA15: =FA14+EZ15 -> #N/A | FB15: =EK15-FA15 -> #N/A | FF15: 190 | FG15: 0.222 | FH15: =FG15*20 -> 4.44 | FI15: =FI14+FH15 -> 24.55 | FJ15: =ES15-FI15 -> 2.86 | FN15: 190 | FO15: 0.226 | FP15: =FO15*20 -> 4.52 | FQ15: =FQ14+FP15 -> 34.8 | FR15: =FI15-FQ15 -> -10.25 | FV15: 190 | FW15: #N/A | FX15: =FW15*20 -> #N/A | FY15: =FY14+FX15 -> #N/A | FZ15: =FQ15-FY15 -> #N/A | GD15: 190 | GE15: #N/A | GF15: =GE15*20 -> #N/A | GG15: =GG14+GF15 -> #N/A | GH15: =FY15-GG15 -> #N/A | GL15: 190 | GM15: 0.226 | GN15: =GM15*20 -> 4.52 | GO15: =GO14+GN15 -> 29.56 | GP15: =FQ15-GO15 -> 5.24 | GT15: 190 | GU15: #N/A | GV15: =GU15*20 -> #N/A | GW15: =GW14+GV15 -> #N/A | GX15: =FY15-GW15 -> #N/A | HB15: 190 | HC15: #N/A | HD15: =HC15*20 -> #N/A | HE15: =HE14+HD15 -> #N/A | HF15: =GG15-HE15 -> #N/A | HJ15: 190 | HK15: 0.211 | HL15: =HK15*20 -> 4.22 | HM15: =HM14+HL15 -> 23.79 | HN15: =GO15-HM15 -> 5.77 | HP15: 190 | HQ15: =MAX(D15,S15,AA15,AQ15, BG15, BO15, BW15, CE15, CM15, CU15, DK15,EA15,EQ15,FG15,FO15, GM15,HK15) -> 0.244 | HR15: 0.205 | HS15: =MAX(HQ15,HR15) -> 0.244 | HT15: =HS15*20 -> 4.88 | HU15: =HU14+HT15 -> 40.15 | HX15: 190 | HY15: =MIN(D15,S15,AA15,AQ15,BG15, BO15, BW15, CE15, CM15, CU15, DK15, EA15,EQ15,FG15,FO15,GM15,HK15) -> 0.211 | HZ15: 0.139 | IA15: =MIN(HY15,HZ15) -> 0.139 | IB15: =IA15*20 -> 2.78 | IC15: =IC14+IB15 -> 18.73
J16: 210 | K16: 0.223 | L16: =K16*20 -> 4.46 | M16: =M15+L16 -> 42.18 | N16: =F16-M16 -> -42.18 | R16: 210 | S16: 0.219 | T16: =S16*20 -> 4.38 | U16: =U15+T16 -> 42.55 | V16: =M16-U16 -> -0.37 | Z16: 210 | AA16: 0.22 | AB16: =AA16*20 -> 4.4 | AC16: =AC15+AB16 -> 39.96 | AD16: =U16-AC16 -> 2.59 | AH16: 210 | AI16: #N/A | AJ16: =AI16*20 -> #N/A | AK16: =AK15+AJ16 -> #N/A | AL16: =AC16-AK16 -> #N/A | AP16: 210 | AQ16: 0.221 | AR16: =AQ16*20 -> 4.42 | AS16: =AS15+AR16 -> 38.81 | AT16: =AC16-AS16 -> 1.15 | AX16: 210 | AY16: #N/A | AZ16: =AY16*20 -> #N/A | BA16: =BA15+AZ16 -> #N/A | BB16: =AK16-BA16 -> #N/A | BF16: 210 | BG16: 0.228 | BH16: =BG16*20 -> 4.56 | BI16: =BI15+BH16 -> 41.83 | BJ16: =AS16-BI16 -> -3.02 | BN16: 210 | BO16: 0.224 | BP16: =BO16*20 -> 4.48 | BQ16: =BQ15+BP16 -> 40.09 | BR16: =BI16-BQ16 -> 1.74 | BV16: 210 | BW16: 0.222 | BX16: =BW16*20 -> 4.44 | BY16: =BY15+BX16 -> 38.32 | BZ16: =BQ16-BY16 -> 1.77 | CD16: 210 | CE16: 0.222 | CF16: =CE16*20 -> 4.44 | CG16: =CG15+CF16 -> 40.19 | CH16: =BY16-CG16 -> -1.87 | CL16: 210 | CM16: 0.228 | CN16: =CM16*20 -> 4.56 | CO16: =CO15+CN16 -> 38.01 | CP16: =CG16-CO16 -> 2.18 | CT16: 210 | CU16: 0.224 | CV16: =CU16*20 -> 4.48 | CW16: =CW15+CV16 -> 35.16 | CX16: =CO16-CW16 -> 2.85 | DB16: 210 | DC16: #N/A | DD16: =DC16*20 -> #N/A | DE16: =DE15+DD16 -> #N/A | DF16: =CW16-DE16 -> #N/A | DJ16: 210 | DK16: 0.23 | DL16: =DK16*20 -> 4.6 | DM16: =DM15+DL16 -> 42.31 | DN16: =CW16-DM16 -> -7.15 | DR16: 210 | DS16: #N/A | DT16: =DS16*20 -> #N/A | DU16: =DU15+DT16 -> #N/A | DV16: =DE16-DU16 -> #N/A | DZ16: 210 | EA16: 0.223 | EB16: =EA16*20 -> 4.46 | EC16: =EC15+EB16 -> 35.86 | ED16: =DM16-EC16 -> 6.45 | EH16: 210 | EI16: #N/A | EJ16: =EI16*20 -> #N/A | EK16: =EK15+EJ16 -> #N/A | EL16: =DU16-EK16 -> #N/A | EP16: 210 | EQ16: 0.223 | ER16: =EQ16*20 -> 4.46 | ES16: =ES15+ER16 -> 31.87 | ET16: =EC16-ES16 -> 3.99 | EX16: 210 | EY16: #N/A | EZ16: =EY16*20 -> #N/A | FA16: =FA15+EZ16 -> #N/A | FB16: =EK16-FA16 -> #N/A | FF16: 210 | FG16: 0.211 | FH16: =FG16*20 -> 4.22 | FI16: =FI15+FH16 -> 28.77 | FJ16: =ES16-FI16 -> 3.1 | FN16: 210 | FO16: 0.209 | FP16: =FO16*20 -> 4.18 | FQ16: =FQ15+FP16 -> 38.98 | FR16: =FI16-FQ16 -> -10.21 | FV16: 210 | FW16: #N/A | FX16: =FW16*20 -> #N/A | FY16: =FY15+FX16 -> #N/A | FZ16: =FQ16-FY16 -> #N/A | GD16: 210 | GE16: #N/A | GF16: =GE16*20 -> #N/A | GG16: =GG15+GF16 -> #N/A | GH16: =FY16-GG16 -> #N/A | GL16: 210 | GM16: 0.21 | GN16: =GM16*20 -> 4.2 | GO16: =GO15+GN16 -> 33.76 | GP16: =FQ16-GO16 -> 5.22 | GT16: 210 | GU16: #N/A | GV16: =GU16*20 -> #N/A | GW16: =GW15+GV16 -> #N/A | GX16: =FY16-GW16 -> #N/A | HB16: 210 | HC16: #N/A | HD16: =HC16*20 -> #N/A | HE16: =HE15+HD16 -> #N/A | HF16: =GG16-HE16 -> #N/A | HJ16: 210 | HK16: 0.205 | HL16: =HK16*20 -> 4.1 | HM16: =HM15+HL16 -> 27.89 | HN16: =GO16-HM16 -> 5.87 | HP16: 210 | HQ16: =MAX(D16,S16,AA16,AQ16, BG16, BO16, BW16, CE16, CM16, CU16, DK16,EA16,EQ16,FG16,FO16, GM16,HK16) -> 0.23 | HR16: 0.198 | HS16: =MAX(HQ16,HR16) -> 0.23 | HT16: =HS16*20 -> 4.6 | HU16: =HU15+HT16 -> 44.75 | HX16: 210 | HY16: =MIN(D16,S16,AA16,AQ16,BG16, BO16, BW16, CE16, CM16, CU16, DK16, EA16,EQ16,FG16,FO16,GM16,HK16) -> 0.205 | HZ16: 0.142 | IA16: =MIN(HY16,HZ16) -> 0.142 | IB16: =IA16*20 -> 2.84 | IC16: =IC15+IB16 -> 21.57
J17: 230 | K17: 0.184 | L17: =K17*20 -> 3.68 | M17: =M16+L17 -> 45.86 | N17: =F17-M17 -> -45.86 | R17: 230 | S17: 0.179 | T17: =S17*20 -> 3.58 | U17: =U16+T17 -> 46.13 | V17: =M17-U17 -> -0.27 | Z17: 230 | AA17: 0.179 | AB17: =AA17*20 -> 3.58 | AC17: =AC16+AB17 -> 43.54 | AD17: =U17-AC17 -> 2.59 | AH17: 230 | AI17: #N/A | AJ17: =AI17*20 -> #N/A | AK17: =AK16+AJ17 -> #N/A | AL17: =AC17-AK17 -> #N/A | AP17: 230 | AQ17: 0.178 | AR17: =AQ17*20 -> 3.56 | AS17: =AS16+AR17 -> 42.37 | AT17: =AC17-AS17 -> 1.17 | AX17: 230 | AY17: #N/A | AZ17: =AY17*20 -> #N/A | BA17: =BA16+AZ17 -> #N/A | BB17: =AK17-BA17 -> #N/A | BF17: 230 | BG17: 0.187 | BH17: =BG17*20 -> 3.74 | BI17: =BI16+BH17 -> 45.57 | BJ17: =AS17-BI17 -> -3.2 | BN17: 230 | BO17: 0.183 | BP17: =BO17*20 -> 3.66 | BQ17: =BQ16+BP17 -> 43.75 | BR17: =BI17-BQ17 -> 1.82 | BV17: 230 | BW17: 0.184 | BX17: =BW17*20 -> 3.68 | BY17: =BY16+BX17 -> 42 | BZ17: =BQ17-BY17 -> 1.75 | CD17: 230 | CE17: 0.182 | CF17: =CE17*20 -> 3.64 | CG17: =CG16+CF17 -> 43.83 | CH17: =BY17-CG17 -> -1.83 | CL17: 230 | CM17: 0.187 | CN17: =CM17*20 -> 3.74 | CO17: =CO16+CN17 -> 41.75 | CP17: =CG17-CO17 -> 2.08 | CT17: 230 | CU17: 0.181 | CV17: =CU17*20 -> 3.62 | CW17: =CW16+CV17 -> 38.78 | CX17: =CO17-CW17 -> 2.97 | DB17: 230 | DC17: #N/A | DD17: =DC17*20 -> #N/A | DE17: =DE16+DD17 -> #N/A | DF17: =CW17-DE17 -> #N/A | DJ17: 230 | DK17: 0.19 | DL17: =DK17*20 -> 3.8 | DM17: =DM16+DL17 -> 46.11 | DN17: =CW17-DM17 -> -7.33 | DR17: 230 | DS17: #N/A | DT17: =DS17*20 -> #N/A | DU17: =DU16+DT17 -> #N/A | DV17: =DE17-DU17 -> #N/A | DZ17: 230 | EA17: 0.179 | EB17: =EA17*20 -> 3.58 | EC17: =EC16+EB17 -> 39.44 | ED17: =DM17-EC17 -> 6.67 | EH17: 230 | EI17: #N/A | EJ17: =EI17*20 -> #N/A | EK17: =EK16+EJ17 -> #N/A | EL17: =DU17-EK17 -> #N/A | EP17: 230 | EQ17: 0.176 | ER17: =EQ17*20 -> 3.52 | ES17: =ES16+ER17 -> 35.39 | ET17: =EC17-ES17 -> 4.05 | EX17: 230 | EY17: #N/A | EZ17: =EY17*20 -> #N/A | FA17: =FA16+EZ17 -> #N/A | FB17: =EK17-FA17 -> #N/A | FF17: 230 | FG17: 0.165 | FH17: =FG17*20 -> 3.3 | FI17: =FI16+FH17 -> 32.07 | FJ17: =ES17-FI17 -> 3.32 | FN17: 230 | FO17: 0.164 | FP17: =FO17*20 -> 3.28 | FQ17: =FQ16+FP17 -> 42.26 | FR17: =FI17-FQ17 -> -10.19 | FV17: 230 | FW17: #N/A | FX17: =FW17*20 -> #N/A | FY17: =FY16+FX17 -> #N/A | FZ17: =FQ17-FY17 -> #N/A | GD17: 230 | GE17: #N/A | GF17: =GE17*20 -> #N/A | GG17: =GG16+GF17 -> #N/A | GH17: =FY17-GG17 -> #N/A | GL17: 230 | GM17: 0.166 | GN17: =GM17*20 -> 3.32 | GO17: =GO16+GN17 -> 37.08 | GP17: =FQ17-GO17 -> 5.18 | GT17: 230 | GU17: #N/A | GV17: =GU17*20 -> #N/A | GW17: =GW16+GV17 -> #N/A | GX17: =FY17-GW17 -> #N/A | HB17: 230 | HC17: #N/A | HD17: =HC17*20 -> #N/A | HE17: =HE16+HD17 -> #N/A | HF17: =GG17-HE17 -> #N/A | HJ17: 230 | HK17: 0.163 | HL17: =HK17*20 -> 3.26 | HM17: =HM16+HL17 -> 31.15 | HN17: =GO17-HM17 -> 5.93 | HP17: 230 | HQ17: =MAX(D17,S17,AA17,AQ17, BG17, BO17, BW17, CE17, CM17, CU17, DK17,EA17,EQ17,FG17,FO17, GM17,HK17) -> 0.19 | HR17: 0.16 | HS17: =MAX(HQ17,HR17) -> 0.19 | HT17: =HS17*20 -> 3.8 | HU17: =HU16+HT17 -> 48.55 | HX17: 230 | HY17: =MIN(D17,S17,AA17,AQ17,BG17, BO17, BW17, CE17, CM17, CU17, DK17, EA17,EQ17,FG17,FO17,GM17,HK17) -> 0.163 | HZ17: 0.118 | IA17: =MIN(HY17,HZ17) -> 0.118 | IB17: =IA17*20 -> 2.36 | IC17: =IC16+IB17 -> 23.93
J18: 250 | K18: 0.159 | L18: =K18*20 -> 3.18 | M18: =M17+L18 -> 49.04 | N18: =F18-M18 -> -49.04 | R18: 250 | S18: 0.156 | T18: =S18*20 -> 3.12 | U18: =U17+T18 -> 49.25 | V18: =M18-U18 -> -0.21 | Z18: 250 | AA18: 0.159 | AB18: =AA18*20 -> 3.18 | AC18: =AC17+AB18 -> 46.72 | AD18: =U18-AC18 -> 2.53 | AH18: 250 | AI18: #N/A | AJ18: =AI18*20 -> #N/A | AK18: =AK17+AJ18 -> #N/A | AL18: =AC18-AK18 -> #N/A | AP18: 250 | AQ18: 0.155 | AR18: =AQ18*20 -> 3.1 | AS18: =AS17+AR18 -> 45.47 | AT18: =AC18-AS18 -> 1.25 | AX18: 250 | AY18: #N/A | AZ18: =AY18*20 -> #N/A | BA18: =BA17+AZ18 -> #N/A | BB18: =AK18-BA18 -> #N/A | BF18: 250 | BG18: 0.156 | BH18: =BG18*20 -> 3.12 | BI18: =BI17+BH18 -> 48.69 | BJ18: =AS18-BI18 -> -3.22 | BN18: 250 | BO18: 0.158 | BP18: =BO18*20 -> 3.16 | BQ18: =BQ17+BP18 -> 46.91 | BR18: =BI18-BQ18 -> 1.78 | BV18: 250 | BW18: 0.155 | BX18: =BW18*20 -> 3.1 | BY18: =BY17+BX18 -> 45.1 | BZ18: =BQ18-BY18 -> 1.81 | CD18: 250 | CE18: 0.154 | CF18: =CE18*20 -> 3.08 | CG18: =CG17+CF18 -> 46.91 | CH18: =BY18-CG18 -> -1.81 | CL18: 250 | CM18: 0.159 | CN18: =CM18*20 -> 3.18 | CO18: =CO17+CN18 -> 44.93 | CP18: =CG18-CO18 -> 1.98 | CT18: 250 | CU18: 0.157 | CV18: =CU18*20 -> 3.14 | CW18: =CW17+CV18 -> 41.92 | CX18: =CO18-CW18 -> 3.01 | DB18: 250 | DC18: #N/A | DD18: =DC18*20 -> #N/A | DE18: =DE17+DD18 -> #N/A | DF18: =CW18-DE18 -> #N/A | DJ18: 250 | DK18: 0.159 | DL18: =DK18*20 -> 3.18 | DM18: =DM17+DL18 -> 49.29 | DN18: =CW18-DM18 -> -7.37 | DR18: 250 | DS18: #N/A | DT18: =DS18*20 -> #N/A | DU18: =DU17+DT18 -> #N/A | DV18: =DE18-DU18 -> #N/A | DZ18: 250 | EA18: 0.151 | EB18: =EA18*20 -> 3.02 | EC18: =EC17+EB18 -> 42.46 | ED18: =DM18-EC18 -> 6.83 | EH18: 250 | EI18: #N/A | EJ18: =EI18*20 -> #N/A | EK18: =EK17+EJ18 -> #N/A | EL18: =DU18-EK18 -> #N/A | EP18: 250 | EQ18: 0.149 | ER18: =EQ18*20 -> 2.98 | ES18: =ES17+ER18 -> 38.37 | ET18: =EC18-ES18 -> 4.09 | EX18: 250 | EY18: #N/A | EZ18: =EY18*20 -> #N/A | FA18: =FA17+EZ18 -> #N/A | FB18: =EK18-FA18 -> #N/A | FF18: 250 | FG18: 0.144 | FH18: =FG18*20 -> 2.88 | FI18: =FI17+FH18 -> 34.95 | FJ18: =ES18-FI18 -> 3.42 | FN18: 250 | FO18: 0.139 | FP18: =FO18*20 -> 2.78 | FQ18: =FQ17+FP18 -> 45.04 | FR18: =FI18-FQ18 -> -10.09 | FV18: 250 | FW18: #N/A | FX18: =FW18*20 -> #N/A | FY18: =FY17+FX18 -> #N/A | FZ18: =FQ18-FY18 -> #N/A | GD18: 250 | GE18: #N/A | GF18: =GE18*20 -> #N/A | GG18: =GG17+GF18 -> #N/A | GH18: =FY18-GG18 -> #N/A | GL18: 250 | GM18: 0.137 | GN18: =GM18*20 -> 2.74 | GO18: =GO17+GN18 -> 39.82 | GP18: =FQ18-GO18 -> 5.22 | GT18: 250 | GU18: #N/A | GV18: =GU18*20 -> #N/A | GW18: =GW17+GV18 -> #N/A | GX18: =FY18-GW18 -> #N/A | HB18: 250 | HC18: #N/A | HD18: =HC18*20 -> #N/A | HE18: =HE17+HD18 -> #N/A | HF18: =GG18-HE18 -> #N/A | HJ18: 250 | HK18: 0.136 | HL18: =HK18*20 -> 2.72 | HM18: =HM17+HL18 -> 33.87 | HN18: =GO18-HM18 -> 5.95 | HP18: 250 | HQ18: =MAX(D18,S18,AA18,AQ18, BG18, BO18, BW18, CE18, CM18, CU18, DK18,EA18,EQ18,FG18,FO18, GM18,HK18) -> 0.159 | HR18: 0.134 | HS18: =MAX(HQ18,HR18) -> 0.159 | HT18: =HS18*20 -> 3.18 | HU18: =HU17+HT18 -> 51.73 | HX18: 250 | HY18: =MIN(D18,S18,AA18,AQ18,BG18, BO18, BW18, CE18, CM18, CU18, DK18, EA18,EQ18,FG18,FO18,GM18,HK18) -> 0.136 | HZ18: 0.107 | IA18: =MIN(HY18,HZ18) -> 0.107 | IB18: =IA18*20 -> 2.14 | IC18: =IC17+IB18 -> 26.07
J19: 270 | K19: 0.144 | L19: =K19*20 -> 2.88 | M19: =M18+L19 -> 51.92 | N19: =F19-M19 -> -51.92 | R19: 270 | S19: 0.134 | T19: =S19*20 -> 2.68 | U19: =U18+T19 -> 51.93 | V19: =M19-U19 -> -0.01 | Z19: 270 | AA19: 0.138 | AB19: =AA19*20 -> 2.76 | AC19: =AC18+AB19 -> 49.48 | AD19: =U19-AC19 -> 2.45 | AH19: 270 | AI19: #N/A | AJ19: =AI19*20 -> #N/A | AK19: =AK18+AJ19 -> #N/A | AL19: =AC19-AK19 -> #N/A | AP19: 270 | AQ19: 0.136 | AR19: =AQ19*20 -> 2.72 | AS19: =AS18+AR19 -> 48.19 | AT19: =AC19-AS19 -> 1.29 | AX19: 270 | AY19: #N/A | AZ19: =AY19*20 -> #N/A | BA19: =BA18+AZ19 -> #N/A | BB19: =AK19-BA19 -> #N/A | BF19: 270 | BG19: 0.137 | BH19: =BG19*20 -> 2.74 | BI19: =BI18+BH19 -> 51.43 | BJ19: =AS19-BI19 -> -3.24 | BN19: 270 | BO19: 0.141 | BP19: =BO19*20 -> 2.82 | BQ19: =BQ18+BP19 -> 49.73 | BR19: =BI19-BQ19 -> 1.7 | BV19: 270 | BW19: 0.139 | BX19: =BW19*20 -> 2.78 | BY19: =BY18+BX19 -> 47.88 | BZ19: =BQ19-BY19 -> 1.85 | CD19: 270 | CE19: 0.137 | CF19: =CE19*20 -> 2.74 | CG19: =CG18+CF19 -> 49.65 | CH19: =BY19-CG19 -> -1.77 | CL19: 270 | CM19: 0.137 | CN19: =CM19*20 -> 2.74 | CO19: =CO18+CN19 -> 47.67 | CP19: =CG19-CO19 -> 1.98 | CT19: 270 | CU19: 0.136 | CV19: =CU19*20 -> 2.72 | CW19: =CW18+CV19 -> 44.64 | CX19: =CO19-CW19 -> 3.03 | DB19: 270 | DC19: #N/A | DD19: =DC19*20 -> #N/A | DE19: =DE18+DD19 -> #N/A | DF19: =CW19-DE19 -> #N/A | DJ19: 270 | DK19: 0.139 | DL19: =DK19*20 -> 2.78 | DM19: =DM18+DL19 -> 52.07 | DN19: =CW19-DM19 -> -7.43 | DR19: 270 | DS19: #N/A | DT19: =DS19*20 -> #N/A | DU19: =DU18+DT19 -> #N/A | DV19: =DE19-DU19 -> #N/A | DZ19: 270 | EA19: 0.136 | EB19: =EA19*20 -> 2.72 | EC19: =EC18+EB19 -> 45.18 | ED19: =DM19-EC19 -> 6.89 | EH19: 270 | EI19: #N/A | EJ19: =EI19*20 -> #N/A | EK19: =EK18+EJ19 -> #N/A | EL19: =DU19-EK19 -> #N/A | EP19: 270 | EQ19: 0.126 | ER19: =EQ19*20 -> 2.52 | ES19: =ES18+ER19 -> 40.89 | ET19: =EC19-ES19 -> 4.29 | EX19: 270 | EY19: #N/A | EZ19: =EY19*20 -> #N/A | FA19: =FA18+EZ19 -> #N/A | FB19: =EK19-FA19 -> #N/A | FF19: 270 | FG19: 0.124 | FH19: =FG19*20 -> 2.48 | FI19: =FI18+FH19 -> 37.43 | FJ19: =ES19-FI19 -> 3.46 | FN19: 270 | FO19: 0.119 | FP19: =FO19*20 -> 2.38 | FQ19: =FQ18+FP19 -> 47.42 | FR19: =FI19-FQ19 -> -9.99 | FV19: 270 | FW19: #N/A | FX19: =FW19*20 -> #N/A | FY19: =FY18+FX19 -> #N/A | FZ19: =FQ19-FY19 -> #N/A | GD19: 270 | GE19: #N/A | GF19: =GE19*20 -> #N/A | GG19: =GG18+GF19 -> #N/A | GH19: =FY19-GG19 -> #N/A | GL19: 270 | GM19: 0.12 | GN19: =GM19*20 -> 2.4 | GO19: =GO18+GN19 -> 42.22 | GP19: =FQ19-GO19 -> 5.2 | GT19: 270 | GU19: #N/A | GV19: =GU19*20 -> #N/A | GW19: =GW18+GV19 -> #N/A | GX19: =FY19-GW19 -> #N/A | HB19: 270 | HC19: #N/A | HD19: =HC19*20 -> #N/A | HE19: =HE18+HD19 -> #N/A | HF19: =GG19-HE19 -> #N/A | HJ19: 270 | HK19: 0.115 | HL19: =HK19*20 -> 2.3 | HM19: =HM18+HL19 -> 36.17 | HN19: =GO19-HM19 -> 6.05 | HP19: 270 | HQ19: =MAX(D19,S19,AA19,AQ19, BG19, BO19, BW19, CE19, CM19, CU19, DK19,EA19,EQ19,FG19,FO19, GM19,HK19) -> 0.141 | HR19: 0.115 | HS19: =MAX(HQ19,HR19) -> 0.141 | HT19: =HS19*20 -> 2.82 | HU19: =HU18+HT19 -> 54.55 | HX19: 270 | HY19: =MIN(D19,S19,AA19,AQ19,BG19, BO19, BW19, CE19, CM19, CU19, DK19, EA19,EQ19,FG19,FO19,GM19,HK19) -> 0.115 | HZ19: 0.1 | IA19: =MIN(HY19,HZ19) -> 0.1 | IB19: =IA19*20 -> 2 | IC19: =IC18+IB19 -> 28.07
