Workbook

Sheet Height
A1: CCID | B1: DOY152 | C1: DOY158 | D1: DOY168 | E1: DOY175 | F1: DOY182 | G1: DOY194 | H1: DOY200 | I1: DOY217 | J1: DOY224 | K1: DOY231 | L1: DOY250
A2: p01-1N | B2: 18 | C2: 23 | D2: 31 | E2: 37 | F2: 53 | G2: 85 | H2: 100 | I2: 118 | K2: 162 | L2: 170
A3: p01-1M | B3: 17 | C3: 25 | D3: 32 | E3: 43 | F3: 61 | G3: 95 | H3: 113 | I3: 130 | J3: 139 | K3: 147
A4: p01-1S | B4: 12 | C4: 17 | D4: 22 | E4: 30 | F4: 43 | G4: 70 | H4: 93 | I4: 114 | J4: 138 | K4: 155
A5: p01-2N | B5: 12 | C5: 19 | D5: 25 | E5: 36 | F5: 42 | G5: 52 | H5: 70 | I5: 88 | J5: 114 | K5: 136
A6: p01-2M | B6: 10 | C6: 19 | D6: 26 | E6: 38 | F6: 41 | G6: 46 | H6: 68 | I6: 89 | J6: 119 | K6: 142
A7: p01-2S | B7: 9 | C7: 14 | D7: 21 | E7: 28 | F7: 34 | G7: 45 | H7: 55 | I7: 68 | J7: 84 | K7: 100
A8: p01-3N | B8: 12 | C8: 18 | D8: 26 | E8: 33 | F8: 38 | G8: 53 | H8: 68 | I8: 82 | J8: 105 | K8: 126
A9: p01-3M | B9: 12 | C9: 22 | D9: 33 | E9: 45 | F9: 53 | G9: 71 | H9: 87 | I9: 103 | J9: 131 | K9: 154
A10: p01-3S | B10: 13 | C10: 19 | D10: 26 | E10: 31 | F10: 42 | G10: 67 | H10: 79 | I10: 90 | J10: 113 | K10: 134
A11: p01-4N | B11: 9 | C11: 12 | D11: 15 | E11: 20 | F11: 30 | G11: 48 | H11: 63 | I11: 80 | J11: 102 | K11: 119
A12: p01-4M | B12: 10 | C12: 14 | D12: 17 | E12: 23 | F12: 38 | G12: 70 | H12: 85 | I12: 101 | J12: 125 | K12: 144
A13: p01-4S | B13: 15 | C13: 23 | D13: 31 | E13: 42 | F13: 64 | G13: 103 | H13: 121 | I13: 137 | J13: 153 | K13: 169 | L13: 193
A14: p02-1N | B14: 18 | C14: 28 | D14: 41 | E14: 52 | F14: 68 | G14: 97 | H14: 115 | I14: 133 | J14: 160 | K14: 185 | L14: 97
A15: p02-1M | B15: 17 | C15: 26 | D15: 35 | E15: 48 | F15: 58 | G15: 78 | H15: 91 | I15: 106 | J15: 141 | K15: 167 | L15: 186
A16: p02-1S | B16: 19 | C16: 30 | D16: 43 | E16: 56 | F16: 68 | G16: 95 | H16: 113 | I16: 130 | J16: 160 | K16: 184 | L16: 196
A17: p02-2N | B17: 21 | C17: 33 | D17: 45 | E17: 58 | F17: 68 | G17: 86 | H17: 101 | I17: 117 | J17: 140 | K17: 159 | L17: 179
A18: p02-2M | B18: 23 | C18: 32 | D18: 42 | E18: 55 | F18: 62 | G18: 76 | H18: 97 | I18: 117 | J18: 142 | K18: 165 | L18: 184
A19: p02-2S | B19: 18 | C19: 28 | D19: 40 | E19: 53 | F19: 59 | G19: 70 | H19: 84 | I19: 98 | J19: 122 | K19: 141
A20: p02-3N | B20: 17 | C20: 26 | D20: 32 | E20: 40 | F20: 51 | G20: 73 | H20: 88 | I20: 102 | J20: 130 | K20: 151
A21: p02-3M | B21: 17 | C21: 24 | D21: 30 | E21: 37 | F21: 49 | G21: 74 | H21: 91 | I21: 105 | J21: 126 | K21: 143
A22: p02-3S | B22: 15 | C22: 23 | D22: 30 | E22: 38 | F22: 50 | G22: 71 | H22: 86 | I22: 99 | J22: 128 | K22: 152
A23: p02-4N | B23: 15 | C23: 22 | D23: 30 | E23: 41 | F23: 56 | G23: 89 | H23: 100 | I23: 115 | J23: 142 | K23: 162 | L23: 182
A24: p02-4M | B24: 16 | C24: 23 | D24: 32 | E24: 42 | F24: 60 | G24: 97 | H24: 111 | I24: 133 | J24: 156 | K24: 175 | L24: 183
A25: p02-4S | B25: 16 | C25: 26 | D25: 37 | E25: 48 | F25: 63 | G25: 99 | H25: 114 | I25: 131 | J25: 151 | K25: 167 | L25: 187
A26: p03-1N | B26: 23 | C26: 34 | D26: 48 | E26: 63 | F26: 73 | G26: 96 | H26: 113 | I26: 129 | J26: 151 | K26: 171 | L26: 191
A27: p03-1M | B27: 15 | C27: 25 | D27: 37 | E27: 51 | F27: 62 | G27: 79 | H27: 95 | I27: 111 | J27: 136 | K27: 157 | L27: 178
A28: p03-1S | B28: 18 | C28: 30 | D28: 44 | E28: 59 | F28: 71 | G28: 99 | H28: 122 | I28: 143 | J28: 160 | K28: 174 | L28: 190
A29: p03-2N | B29: 21 | C29: 21 | D29: 21 | E29: 58 | F29: 73 | G29: 100 | H29: 139 | I29: 159 | J29: 183 | K29: 203 | L29: 200
A30: p03-2M | B30: 20 | C30: 32 | D30: 44 | E30: 54 | F30: 69 | G30: 98 | H30: 115 | I30: 132 | J30: 169 | K30: 197 | L30: 201
A31: p03-2S | B31: 22 | C31: 35 | D31: 49 | E31: 62 | F31: 75 | G31: 103 | H31: 118 | I31: 133 | J31: 165 | K31: 191 | L31: 193
A32: p03-3N | B32: 19 | C32: 29 | D32: 38 | E32: 48 | F32: 62 | G32: 92 | H32: 104 | I32: 117 | J32: 165 | K32: 205 | L32: 195
A33: p03-3M | B33: 19 | C33: 29 | D33: 42 | E33: 51 | F33: 68 | G33: 104 | H33: 125 | I33: 147 | J33: 173 | K33: 197 | L33: 194
A34: p03-3S | B34: 19 | C34: 31 | D34: 43 | E34: 54 | F34: 69 | G34: 103 | H34: 125 | I34: 146 | J34: 172 | K34: 195 | L34: 201
A35: p03-4N | B35: 18 | C35: 18 | D35: 39 | E35: 48 | F35: 62 | G35: 91 | H35: 102 | I35: 114 | J35: 144 | K35: 170 | L35: 185
A36: p03-4M | B36: 13 | C36: 17 | D36: 25 | E36: 32 | F36: 41 | G36: 63 | H36: 79 | I36: 95 | J36: 118 | K36: 132
A37: p03-4S | B37: 16 | C37: 26 | D37: 39 | E37: 52 | F37: 67 | G37: 98 | H37: 119 | I37: 137 | J37: 163 | K37: 185 | L37: 198
A38: p04-1N | B38: 15 | C38: 23 | D38: 33 | E38: 45 | F38: 61 | G38: 92 | H38: 116 | I38: 143 | J38: 174 | K38: 200 | L38: 192
A39: p04-1M | B39: 11 | C39: 21 | D39: 30 | E39: 40 | F39: 57 | G39: 91 | H39: 109 | I39: 126 | J39: 163 | K39: 196 | L39: 199
A40: p04-1S | B40: 11 | C40: 11 | D40: 11 | E40: 38 | F40: 54 | G40: 83 | H40: 106 | I40: 129 | J40: 163 | K40: 191 | L40: 200
...

Sheet Width
A1: CCID | B1: DOY152 | C1: DOY158 | D1: DOY168 | E1: DOY175 | F1: DOY182 | G1: DOY194 | H1: DOY200 | I1: DOY217 | J1: DOY224 | K1: DOY231 | L1: DOY250
A2: p01-1N | B2: 14 | C2: 22 | D2: 32 | E2: 40 | F2: 54 | G2: 76 | H2: 81 | I2: 89 | J2: 102 | K2: 102 | L2: 102
A3: p01-1M | B3: 12 | C3: 23 | D3: 36 | E3: 46 | F3: 61 | G3: 83 | H3: 87 | I3: 95 | J3: 102 | K3: 102 | L3: 102
A4: p01-1S | B4: 10 | C4: 17 | D4: 25 | E4: 33 | F4: 47 | G4: 68 | H4: 81 | I4: 80 | J4: 98 | K4: 102 | L4: 102
A5: p01-2N | B5: 11 | C5: 18 | D5: 26 | E5: 33 | F5: 38 | G5: 46 | H5: 57 | I5: 77 | J5: 86 | K5: 102 | L5: 102
A6: p01-2M | B6: 10 | C6: 18 | D6: 27 | E6: 35 | F6: 37 | G6: 41 | H6: 56 | I6: 82 | J6: 93 | K6: 102 | L6: 102
A7: p01-2S | B7: 7 | C7: 14 | D7: 21 | E7: 26 | F7: 31 | G7: 41 | H7: 48 | I7: 64 | J7: 86 | K7: 91 | L7: 102
A8: p01-3N | B8: 9 | C8: 18 | D8: 29 | E8: 38 | F8: 44 | G8: 52 | H8: 58 | I8: 73 | J8: 81 | K8: 94 | L8: 102
A9: p01-3M | B9: 12 | C9: 19 | D9: 28 | E9: 35 | F9: 46 | G9: 63 | H9: 72 | I9: 88 | J9: 102 | K9: 102 | L9: 102
A10: p01-3S | B10: 12 | C10: 19 | D10: 29 | E10: 36 | F10: 45 | G10: 59 | H10: 62 | I10: 74 | J10: 83 | K10: 102 | L10: 102
A11: p01-4N | B11: 9 | C11: 13 | D11: 17 | E11: 21 | F11: 30 | G11: 43 | H11: 51 | I11: 65 | J11: 77 | K11: 102 | L11: 102
A12: p01-4M | B12: 9 | C12: 14 | D12: 23 | E12: 30 | F12: 11 | G12: 67 | H12: 73 | I12: 84 | J12: 90 | K12: 102 | L12: 102
A13: p01-4S | B13: 14 | C13: 25 | D13: 38 | E13: 50 | F13: 62 | G13: 80 | H13: 87 | I13: 95 | J13: 102 | K13: 102 | L13: 102
... A145: p12-4S | B145: 11 | C145: 22 | D145: 35 | E145: 45 | F145: 57 | G145: 76 | H145: 70 | I145: 60 | J145: 63 | K145: 92 | L145: 102

Sheet Density
A1: CCID | B1: PLPD
A2: p01-1M | B2: 8.0927384
A3: p01-2M | B3: 8.967629
A4: p01-3M | B4: 7.2178478
A5: p01-4M | B5: 7.4365704
A6: p02-1M | B6: 8.0927384
A7: p02-2M | B7: 7.8740157
A8: p02-3M | B8: 9.8425197
A9: p02-4M | B9: 9.1863517
A10: p03-1M | B10: 10.498688
A11: p03-2M | B11: 10.061242
A12: p03-3M | B12: 9.4050744
A13: p03-4M | B13: 8.5301837
... A49: p12-4M | B49: 6.7804024

Sheet Develop
A1: CCID | B1: EDATE | C1: PLYRE | D1: PLDOE | E1: LF1D | F1: ADAT | G1: ADOY | H1: NAWF182 | I1: NAWF194 | J1: NAWF200 | K1: NAWF217 | L1: NAWF224 | M1: NAWF238 | N1: NAWF250
A2: p01-1E | B2: 44317 | C2: 2021 | D2: 120.8 | E2: 44332
A3: p01-1M | F3: 44377 | G3: 180.5 | H3: 8.375 | I3: 6.5555556 | J3: 4.4444444 | K3: 4.6666667 | L3: 4.8888889 | M3: 6.1111111 | N3: 2.7777778
A4: p01-2E | B4: 44318 | C4: 2021 | D4: 122 | E4: 44330
A5: p01-2M | F5: 44374 | G5: 178 | H5: 8 | I5: 4.4444444 | J5: 5.2222222 | K5: 5.4444444 | L5: 5.7777778 | M5: 5.8888889 | N5: 3.1111111
A6: p01-3E | B6: 44317 | C6: 2021 | D6: 120.8 | E6: 44331
A7: p01-3M | F7: 44375 | G7: 179 | H7: 8.5555556 | I7: 4.8888889 | J7: 5.6666667 | K7: 5.3333333 | L7: 5.2222222 | M7: 4.4444444 | N7: 3
A8: p01-4E | B8: 44318 | C8: 2021 | D8: 121.625 | E8: 44331
A9: p01-4M | F9: 44377 | G9: 181.25 | H9: 8.5555556 | I9: 5.8888889 | J9: 5.5555556 | K9: 5.5555556 | L9: 5.4444444 | M9: 5.1111111 | N9: 3.6666667
A10: p02-1E | B10: 44317 | C10: 2021 | D10: 120.5 | E10: 44330
A11: p02-1M | F11: 44376 | G11: 180 | H11: 8.7777778 | I11: 5.4444444 | J11: 6 | K11: 5.4444444 | L11: 5.2222222 | M11: 5.4444444 | N11: 3.6666667
A12: p02-2E | B12: 44317 | C12: 2021 | D12: 120.5 | E12: 44331
A13: p02-2M | F13: 44378 | G13: 182 | H13: 8.2222222 | I13: 4.7777778 | J13: 5.6666667 | K13: 6 | L13: 5.3333333 | M13: 4.8888889 | N13: 3.2222222
A14: p02-3E | B14: 44316 | C14: 2021 | D14: 120.2 | E14: 44331
A15: p02-3M | F15: 44376 | G15: 180 | H15: 8 | I15: 4.3333333 | J15: 5.3333333 | K15: 5.1111111 | L15: 5.6666667 | M15: 4.6666667 | N15: 3.4444444
A16: p02-4E | B16: 44317 | C16: 2021 | D16: 121.1 | E16: 44330
A17: p02-4M | F17: 44375 | G17: 179 | H17: 8.3333333 | I17: 6.2222222 | J17: 5 | K17: 5.6666667 | L17: 5.3333333 | M17: 4.3333333 | N17: 3
A18: p03-1E | B18: 44317 | C18: 2021 | D18: 120.92857 | E18: 44331
A19: p03-1M | F19: 44377 | G19: 181 | H19: 7.8888889 | I19: 5.5555556 | J19: 5.7777778 | K19: 5.6666667 | L19: 5.5555556 | M19: 5.2222222 | N19: 3.7777778
A20: p03-2E | B20: 44317 | C20: 2021 | D20: 121 | E20: 44331
A21: p03-2M | F21: 44377 | G21: 181 | H21: 8.7777778 | I21: 6.5555556 | J21: 5.2222222 | K21: 5.6666667 | L21: 5.2222222 | M21: 5 | N21: 3.5555556
A22: p03-3E | B22: 44317 | C22: 2021 | D22: 121.14286 | E22: 44331
A23: p03-3M | F23: 44377 | G23: 180.8 | H23: 8.7777778 | I23: 6.6666667 | J23: 5.4444444 | K23: 6.2222222 | L23: 4.8888889 | M23: 4.6666667 | N23: 3.1111111
A24: p03-4E | B24: 44317 | C24: 2021 | D24: 121 | E24: 44331
A25: p03-4M | F25: 44375 | G25: 179 | H25: 7.7777778 | I25: 5.5555556 | J25: 5 | K25: 4.8888889 | L25: 5.1111111 | M25: 4.8888889 | N25: 3.1111111
A26: p04-1E | B26: 44317 | C26: 2021 | D26: 120.75 | E26: 44332
A27: p04-1M | F27: 44376 | G27: 180 | H27: 8.2222222 | I27: 6.8888889 | J27: 5.5555556 | K27: 6.3333333 | L27: 5.2222222 | M27: 5.2222222 | N27: 3.6666667
A28: p04-2E | B28: 44318 | C28: 2021 | D28: 122 | E28: 44331
A29: p04-2M | F29: 44377 | G29: 180.5 | H29: 8.3333333 | I29: 7.1111111 | J29: 5.6666667 | K29: 6 | L29: 5.1111111 | M29: 4.8888889 | N29: 3.6666667
A30: p04-3E | B30: 44319 | C30: 2021 | D30: 122.5 | E30: 44333
A31: p04-3M | F31: 44372 | G31: 176 | H31: 8.7777778 | I31: 7.2222222 | J31: 6 | K31: 5.6666667 | L31: 4.6666667 | M31: 4.1111111 | N31: 2.6666667
A32: p04-4E | B32: 44319 | C32: 2021 | D32: 123.4 | E32: 44332
A33: p04-4M | F33: 44377 | G33: 181 | H33: 8.4444444 | I33: 6.6666667 | J33: 5.2222222 | K33: 4.8888889 | L33: 4.6666667 | M33: 3.3333333 | N33: 3
A34: p05-1E | B34: 44317 | C34: 2021 | D34: 121.1 | E34: 44330
A35: p05-1M | F35: 44377 | G35: 181 | H35: 8.1111111 | I35: 6.2222222 | J35: 5.6666667 | K35: 5.7777778 | L35: 4.7777778 | M35: 4.2222222 | N35: 2.8888889
A36: p05-2E | B36: 44318 | C36: 2021 | D36: 121.75 | E36: 44331
A37: p05-2M | F37: 44378 | G37: 182 | H37: 8.4444444 | I37: 6.6666667 | J37: 5.6666667 | K37: 6.1111111 | L37: 5.1111111 | M37: 4.5555556 | N37: 3
A38: p05-3E | B38: 44318 | C38: 2021 | D38: 121.625 | E38: 44332
A39: p05-3M | F39: 44377 | G39: 180.5 | H39: 8.6666667 | I39: 5.6666667 | J39: 6.4444444 | K39: 5 | L39: 5.3333333 | M39: 4.8888889 | N39: 3.1111111
A40: p05-4E | B40: 44317 | C40: 2021 | D40: 120.5 | E40: 44330
...

Sheet Ordering
A1: 1 | B1: 1 | C1: N | D1: =_xlfn.CONCAT("p",TEXT(A1,"00"),"-",TEXT(B1,"0"),C1) -> p01-1N | F1: 1
A2: 1 | B2: 1 | C2: M | D2: =_xlfn.CONCAT("p",TEXT(A2,"00"),"-",TEXT(B2,"0"),C2) -> p01-1M | F2: 2
A3: 1 | B3: 1 | C3: S | D3: =_xlfn.CONCAT("p",TEXT(A3,"00"),"-",TEXT(B3,"0"),C3) -> p01-1S | F3: 3
A4: 1 | B4: 2 | C4: N | D4: =_xlfn.CONCAT("p",TEXT(A4,"00"),"-",TEXT(B4,"0"),C4) -> p01-2N | F4: 4
A5: 1 | B5: 2 | C5: M | D5: =_xlfn.CONCAT("p",TEXT(A5,"00"),"-",TEXT(B5,"0"),C5) -> p01-2M | F5: 5
A6: 1 | B6: 2 | C6: S | D6: =_xlfn.CONCAT("p",TEXT(A6,"00"),"-",TEXT(B6,"0"),C6) -> p01-2S | F6: 6
A7: 1 | B7: 3 | C7: N | D7: =_xlfn.CONCAT("p",TEXT(A7,"00"),"-",TEXT(B7,"0"),C7) -> p01-3N | F7: 7
A8: 1 | B8: 3 | C8: M | D8: =_xlfn.CONCAT("p",TEXT(A8,"00"),"-",TEXT(B8,"0"),C8) -> p01-3M | F8: 8
A9: 1 | B9: 3 | C9: S | D9: =_xlfn.CONCAT("p",TEXT(A9,"00"),"-",TEXT(B9,"0"),C9) -> p01-3S | F9: 9
A10: 1 | B10: 4 | C10: N | D10: =_xlfn.CONCAT("p",TEXT(A10,"00"),"-",TEXT(B10,"0"),C10) -> p01-4N | F10: 10
A11: 1 | B11: 4 | C11: M | D11: =_xlfn.CONCAT("p",TEXT(A11,"00"),"-",TEXT(B11,"0"),C11) -> p01-4M | F11: 11
A12: 1 | B12: 4 | C12: S | D12: =_xlfn.CONCAT("p",TEXT(A12,"00"),"-",TEXT(B12,"0"),C12) -> p01-4S | F12: 12
... A144: 12 | B144: 1 | C144: N | D144: =_xlfn.CONCAT("p",TEXT(A144,"00"),"-",TEXT(B144,"0"),C144) -> p12-1N | F144: 133

Sheet Blank Data Sheet
A1: 2022 | B1: F13b4 | E1: date: | I1: doy:
B2: Cotton | F2: time:
A3: Canopy Heights & Widths | F3: by:
B5: Canopy Heights/LAI in row 5. Three measurements per plot.
B6: At both the Canopy Measurement points and the LAI measurement point.
B7: Canopy Height & LAI flags may not be exactly at the GPS points - I adjusted depending on skips in rows. SMM
B8: Plot | D8: Flag | E8: Canopy Height (cm) | F8: Canopy Width (cm) | G8: NAWF | H8: NAWF | I8: NAWF
B9: 01- | C9: 1 | D9: North
D10: Mid
D11: South
B12: 01- | C12: 2 | D12: North
D13: Mid
D14: South
B15: 01- | C15: 3 | D15: North
D16: Mid
D17: South
B18: 01- | C18: 4 | D18: North
D19: Mid
D20: South
B21: 02- | C21: 4 | D21: South
D22: Mid
D23: North
B24: 02- | C24: 3 | D24: South
D25: Mid
D26: North
B27: 02- | C27: 2 | D27: South
D28: Mid
D29: North
B30: 02- | C30: 1 | D30: South
D31: Mid
D32: North
B33: 03- | C33: 1 | D33: North
D34: Mid
D35: South
B36: 03- | C36: 2 | D36: North
D37: Mid
D38: South
B39: 03- | C39: 3 | D39: North
D40: Mid
D41: South
...

Sheet Height Summary
A1: Summary | B1: 2021 | D1: F13b4 | O1: Removed
O2: calculated
B3: Canopy Heights - Summary | O3: data 9/18/2024
D8: Initials: | G8: SMM | H8: SMM | I8: SMM | J8: SMM | K8: SMM | L8: SMM | M8: SMM | N8: SMM | O8: SMM | P8: SMM | Q8: SMM
D9: Date: | G9: 44348 | H9: 44354 | I9: 44364 | J9: 44371 | K9: 44378 | L9: 44390 | M9: 44396 | N9: 44413 | O9: 44420 | P9: 44427 | Q9: 44446
D10: DOY: | G10: 152 | H10: 158 | I10: 168 | J10: 175 | K10: 182 | L10: 194 | M10: 200 | N10: 217 | O10: 224 | P10: 238 | Q10: 250
D11: Time: | G11: 1430-1600 | H11: 1000-1130 | I11: 0945-1145 | J11: 1130-1245 | K11: 1015-1130 | L11: 1000-1245 | M11: 0930-1230 | N11: 1000-1315 | O11: 0930-1245 | P11: 0915-1300 | Q11: 0900-1330
B12: Plot | D12: Flag | E12: TRT | F12: Variety | G12: Height (cm) | H12: Height (cm) | I12: Height (cm) | J12: Height (cm) | K12: Height (cm) | L12: Height (cm) | M12: Height (cm) | N12: Height (cm) | O12: Height (cm) | P12: Height (cm) | Q12: Height (cm) | R12: Height (cm) | S12: Height (cm) | T12: Height (cm) | U12: Height (cm) | V12: Height (cm) | W12: Height (cm) | X12: Height (cm)
B13: 01- | C13: 1 | D13: North | E13: FAO | F13: NG4936 | G13: 18 | H13: 23 | I13: 31 | J13: 37 | K13: 53 | L13: 85 | M13: 100 | N13: 118 | P13: 162 | Q13: 170
D14: Mid | E14: FAO | F14: NG4936 | G14: 17 | H14: 25 | I14: 32 | J14: 43 | K14: 61 | L14: 95 | M14: 113 | N14: 130 | O14: 139 | P14: 147
D15: South | E15: FAO | F15: NG4936 | G15: 12 | H15: 17 | I15: 22 | J15: 30 | K15: 43 | L15: 70 | M15: 93 | N15: 114 | O15: 138 | P15: 155
B16: 01- | C16: 2 | D16: North | E16: CSM-N | F16: NG4936 | G16: 12 | H16: 19 | I16: 25 | J16: 36 | K16: 42 | L16: 52 | M16: 70 | N16: 88 | O16: 114 | P16: 136
D17: Mid | E17: CSM-N | F17: NG4936 | G17: 10 | H17: 19 | I17: 26 | J17: 38 | K17: 41 | L17: 46 | M17: 68 | N17: 89 | O17: 119 | P17: 142
D18: South | E18: CSM-N | F18: NG4936 | G18: 9 | H18: 14 | I18: 21 | J18: 28 | K18: 34 | L18: 45 | M18: 55 | N18: 68 | O18: 84 | P18: 100
B19: 01- | C19: 3 | D19: North | E19: AQC-N | F19: NG4936 | G19: 12 | H19: 18 | I19: 26 | J19: 33 | K19: 38 | L19: 53 | M19: 68 | N19: 82 | O19: 105 | P19: 126
D20: Mid | E20: AQC-N | F20: NG4936 | G20: 12 | H20: 22 | I20: 33 | J20: 45 | K20: 53 | L20: 71 | M20: 87 | N20: 103 | O20: 131 | P20: 154
D21: South | E21: AQC-N | F21: NG4936 | G21: 13 | H21: 19 | I21: 26 | J21: 31 | K21: 42 | L21: 67 | M21: 79 | N21: 90 | O21: 113 | P21: 134
B22: 01- | C22: 4 | D22: North | E22: AQC | F22: NG4936 | G22: 9 | H22: 12 | I22: 15 | J22: 20 | K22: 30 | L22: 48 | M22: 63 | N22: 80 | O22: 102 | P22: 119
D23: Mid | E23: AQC | F23: NG4936 | G23: 10 | H23: 14 | I23: 17 | J23: 23 | K23: 38 | L23: 70 | M23: 85 | N23: 101 | O23: 125 | P23: 144
D24: South | E24: AQC | F24: NG4936 | G24: 15 | H24: 23 | I24: 31 | J24: 42 | K24: 64 | L24: 103 | M24: 121 | N24: 137 | O24: 153 | P24: 169 | Q24: 193
B25: 02- | C25: 4 | D25: South | E25: AQC | F25: NG3195 | G25: 16 | H25: 26 | I25: 37 | J25: 48 | K25: 63 | L25: 99 | M25: 114 | N25: 131 | O25: 151 | P25: 167 | Q25: 187
D26: Mid | E26: AQC | F26: NG3195 | G26: 16 | H26: 23 | I26: 32 | J26: 42 | K26: 60 | L26: 97 | M26: 111 | N26: 133 | O26: 156 | P26: 175 | Q26: 183
D27: North | E27: AQC | F27: NG3195 | G27: 15 | H27: 22 | I27: 30 | J27: 41 | K27: 56 | L27: 89 | M27: 100 | N27: 115 | O27: 142 | P27: 162 | Q27: 182
B28: 02- | C28: 3 | D28: South | E28: AQC-N | F28: NG3195 | G28: 15 | H28: 23 | I28: 30 | J28: 38 | K28: 50 | L28: 71 | M28: 86 | N28: 99 | O28: 128 | P28: 152
D29: Mid | E29: AQC-N | F29: NG3195 | G29: 17 | H29: 24 | I29: 30 | J29: 37 | K29: 49 | L29: 74 | M29: 91 | N29: 105 | O29: 126 | P29: 143
D30: North | E30: AQC-N | F30: NG3195 | G30: 17 | H30: 26 | I30: 32 | J30: 40 | K30: 51 | L30: 73 | M30: 88 | N30: 102 | O30: 130 | P30: 151
B31: 02- | C31: 2 | D31: South | E31: CSM-N | F31: NG3195 | G31: 18 | H31: 28 | I31: 40 | J31: 53 | K31: 59 | L31: 70 | M31: 84 | N31: 98 | O31: 122 | P31: 141
D32: Mid | E32: CSM-N | F32: NG3195 | G32: 23 | H32: 32 | I32: 42 | J32: 55 | K32: 62 | L32: 76 | M32: 97 | N32: 117 | O32: 142 | P32: 165 | Q32: 184
D33: North | E33: CSM-N | F33: NG3195 | G33: 21 | H33: 33 | I33: 45 | J33: 58 | K33: 68 | L33: 86 | M33: 101 | N33: 117 | O33: 140 | P33: 159 | Q33: 179
B34: 02- | C34: 1 | D34: South | E34: FAO | F34: NG3195 | G34: 19 | H34: 30 | I34: 43 | J34: 56 | K34: 68 | L34: 95 | M34: 113 | N34: 130 | O34: 160 | P34: 184 | Q34: 196
D35: Mid | E35: FAO | F35: NG3195 | G35: 17 | H35: 26 | I35: 35 | J35: 48 | K35: 58 | L35: 78 | M35: 91 | N35: 106 | O35: 141 | P35: 167 | Q35: 186
D36: North | E36: FAO | F36: NG3195 | G36: 18 | H36: 28 | I36: 41 | J36: 52 | K36: 68 | L36: 97 | M36: 115 | N36: 133 | O36: 160 | P36: 185 | Q36: 97
B37: 03- | C37: 1 | D37: North | E37: AQC-N | F37: NG3195 | G37: 23 | H37: 34 | I37: 48 | J37: 63 | K37: 73 | L37: 96 | M37: 113 | N37: 129 | O37: 151 | P37: 171 | Q37: 191
D38: Mid | E38: AQC-N | F38: NG3195 | G38: 15 | H38: 25 | I38: 37 | J38: 51 | K38: 62 | L38: 79 | M38: 95 | N38: 111 | O38: 136 | P38: 157 | Q38: 178
D39: South | E39: AQC-N | F39: NG3195 | G39: 18 | H39: 30 | I39: 44 | J39: 59 | K39: 71 | L39: 99 | M39: 122 | N39: 143 | O39: 160 | P39: 174 | Q39: 190
B40: 03- | C40: 2 | D40: North | E40: FAO-N | F40: NG3195 | G40: 21 | H40: 21 | I40: 21 | J40: 58 | K40: 73 | L40: 100 | M40: 139 | N40: 159 | O40: 183 | P40: 203 | Q40: 200
D41: Mid | E41: FAO-N | F41: NG3195 | G41: 20 | H41: 32 | I41: 44 | J41: 54 | K41: 69 | L41: 98 | M41: 115 | N41: 132 | O41: 169 | P41: 197 | Q41: 201
D42: South | E42: FAO-N | F42: NG3195 | G42: 22 | H42: 35 | I42: 49 | J42: 62 | K42: 75 | L42: 103 | M42: 118 | N42: 133 | O42: 165 | P42: 191 | Q42: 193
B43: 03- | C43: 3 | D43: North | E43: CSM | F43: NG3195 | G43: 19 | H43: 29 | I43: 38 | J43: 48 | K43: 62 | L43: 92 | M43: 104 | N43: 117 | O43: 165 | P43: 205 | Q43: 195
D44: Mid | E44: CSM | F44: NG3195 | G44: 19 | H44: 29 | I44: 42 | J44: 51 | K44: 68 | L44: 104 | M44: 125 | N44: 147 | O44: 173 | P44: 197 | Q44: 194
...

Sheet Cover Summary
A1: Summary | B1: 2021 | D1: F13b4 | H1: Cotton
B3: Canopy Heights - Summary | J3: "--" = closed canopy
D8: Initials: | G8: SMM | H8: SMM | I8: SMM | J8: SMM | K8: SMM | L8: SMM | M8: SMM | N8: SMM | O8: SMM | P8: SMM | Q8: SMM
D9: Date: | G9: 44348 | H9: 44354 | I9: 44364 | J9: 44371 | K9: 44378 | L9: 44390 | M9: 44396 | N9: 44413 | O9: 44420 | P9: 44427 | Q9: 44446
D10: DOY: | G10: 152 | H10: 158 | I10: 168 | J10: 175 | K10: 182 | L10: 194 | M10: 200 | N10: 217 | O10: 224 | P10: 238 | Q10: 250
D11: Time: | G11: 1430-1600 | H11: 1030-1200 | I11: 1000-1115 | J11: 1130-1245 | K11: 1015-1130 | L11: 1000-1245 | M11: 0930-1230 | N11: 1000-1315 | O11: 0930-1245 | P11: 0915-1300 | Q11: 0900-1330
B12: Plot | D12: Flag | E12: TRT | F12: Variety | G12: Canopy Width (cm) | H12: Canopy Width (cm) | I12: Canopy Width (cm) | J12: Canopy Width (cm) | K12: Canopy Width (cm) | L12: Canopy Width (cm) | M12: Canopy Width (cm) | N12: Canopy Width (cm) | O12: Canopy Width (cm) | P12: Canopy Width (cm) | Q12: Canopy Width (cm) | R12: Canopy Width (cm) | S12: Canopy Width (cm) | T12: Canopy Width (cm)
B13: 01- | C13: 1 | D13: North | E13: FAO | F13: NG4936 | G13: 14 | H13: 22 | I13: 32 | J13: 40 | K13: 54 | L13: 76 | M13: 81 | N13: 89 | O13: -- | P13: -- | Q13: --
D14: Mid | E14: FAO | F14: NG4936 | G14: 12 | H14: 23 | I14: 36 | J14: 46 | K14: 61 | L14: 83 | M14: 87 | N14: 95 | O14: -- | P14: -- | Q14: --
D15: South | E15: FAO | F15: NG4936 | G15: 10 | H15: 17 | I15: 25 | J15: 33 | K15: 47 | L15: 68 | M15: 81 | N15: 80 | O15: 98 | P15: -- | Q15: --
B16: 01- | C16: 2 | D16: North | E16: CSM-N | F16: NG4936 | G16: 11 | H16: 18 | I16: 26 | J16: 33 | K16: 38 | L16: 46 | M16: 57 | N16: 77 | O16: 86 | P16: -- | Q16: --
D17: Mid | E17: CSM-N | F17: NG4936 | G17: 10 | H17: 18 | I17: 27 | J17: 35 | K17: 37 | L17: 41 | M17: 56 | N17: 82 | O17: 93 | P17: -- | Q17: --
D18: South | E18: CSM-N | F18: NG4936 | G18: 7 | H18: 14 | I18: 21 | J18: 26 | K18: 31 | L18: 41 | M18: 48 | N18: 64 | O18: 86 | P18: 91 | Q18: --
B19: 01- | C19: 3 | D19: North | E19: AQC-N | F19: NG4936 | G19: 9 | H19: 18 | I19: 29 | J19: 38 | K19: 44 | L19: 52 | M19: 58 | N19: 73 | O19: 81 | P19: 94 | Q19: --
D20: Mid | E20: AQC-N | F20: NG4936 | G20: 12 | H20: 19 | I20: 28 | J20: 35 | K20: 46 | L20: 63 | M20: 72 | N20: 88 | O20: -- | P20: -- | Q20: --
D21: South | E21: AQC-N | F21: NG4936 | G21: 12 | H21: 19 | I21: 29 | J21: 36 | K21: 45 | L21: 59 | M21: 62 | N21: 74 | O21: 83 | P21: -- | Q21: --
B22: 01- | C22: 4 | D22: North | E22: AQC | F22: NG4936 | G22: 9 | H22: 13 | I22: 17 | J22: 21 | K22: 30 | L22: 43 | M22: 51 | N22: 65 | O22: 77 | P22: -- | Q22: --
D23: Mid | E23: AQC | F23: NG4936 | G23: 9 | H23: 14 | I23: 23 | J23: 30 | K23: 11 | L23: 67 | M23: 73 | N23: 84 | O23: 90 | P23: -- | Q23: --
D24: South | E24: AQC | F24: NG4936 | G24: 14 | H24: 25 | I24: 38 | J24: 50 | K24: 62 | L24: 80 | M24: 87 | N24: 95 | O24: -- | P24: -- | Q24: --
B25: 02- | C25: 4 | D25: South | E25: AQC | F25: NG3195 | G25: 15 | H25: 26 | I25: 39 | J25: 49 | K25: 58 | L25: 72 | M25: 79 | N25: 93 | O25: -- | P25: -- | Q25: --
D26: Mid | E26: AQC | F26: NG3195 | G26: 14 | H26: 24 | I26: 35 | J26: 46 | K26: 56 | L26: 72 | M26: 80 | N26: 95 | O26: -- | P26: -- | Q26: --
D27: North | E27: AQC | F27: NG3195 | G27: 13 | H27: 23 | I27: 34 | J27: 45 | K27: 55 | L27: 71 | M27: 79 | N27: 93 | O27: -- | P27: -- | Q27: --
B28: 02- | C28: 3 | D28: South | E28: AQC-N | F28: NG3195 | G28: 15 | H28: 21 | I28: 29 | J28: 35 | K28: 43 | L28: 56 | M28: 65 | N28: 84 | O28: 93 | P28: -- | Q28: --
D29: Mid | E29: AQC-N | F29: NG3195 | G29: 15 | H29: 21 | I29: 30 | J29: 37 | K29: 46 | L29: 63 | M29: 70 | N29: 83 | O29: 91 | P29: -- | Q29: --
D30: North | E30: AQC-N | F30: NG3195 | G30: 16 | H30: 21 | I30: 27 | J30: 33 | K30: 43 | L30: 59 | M30: 66 | N30: 82 | O30: 90 | P30: -- | Q30: --
B31: 02- | C31: 2 | D31: South | E31: CSM-N | F31: NG3195 | G31: 19 | H31: 24 | I31: 30 | J31: 35 | K31: 44 | L31: 57 | M31: 65 | N31: 81 | O31: 90 | P31: -- | Q31: --
D32: Mid | E32: CSM-N | F32: NG3195 | G32: 21 | H32: 27 | I32: 33 | J32: 40 | K32: 50 | L32: 66 | M32: 74 | N32: 90 | O32: 99 | P32: -- | Q32: --
D33: North | E33: CSM-N | F33: NG3195 | G33: 20 | H33: 27 | I33: 33 | J33: 42 | K33: 51 | L33: 67 | M33: 78 | N33: 98 | O33: -- | P33: -- | Q33: --
B34: 02- | C34: 1 | D34: South | E34: FAO | F34: NG3195 | G34: 17 | H34: 27 | I34: 40 | J34: 50 | K34: 59 | L34: 72 | M34: 83 | N34: -- | O34: -- | P34: -- | Q34: --
D35: Mid | E35: FAO | F35: NG3195 | G35: 15 | H35: 24 | I35: 36 | J35: 45 | K35: 55 | L35: 70 | M35: 81 | N35: -- | O35: -- | P35: -- | Q35: --
D36: North | E36: FAO | F36: NG3195 | G36: 18 | H36: 26 | I36: 35 | J36: 44 | K36: 57 | L36: 77 | M36: 86 | N36: -- | O36: -- | P36: -- | Q36: --
B37: 03- | C37: 1 | D37: North | E37: AQC-N | F37: NG3195 | G37: 20 | H37: 33 | I37: 48 | J37: 61 | K37: 69 | L37: 82 | M37: 88 | N37: -- | O37: -- | P37: -- | Q37: --
D38: Mid | E38: AQC-N | F38: NG3195 | G38: 14 | H38: 22 | I38: 34 | J38: 44 | K38: 55 | L38: 72 | M38: 79 | N38: 91 | O38: -- | P38: -- | Q38: --
D39: South | E39: AQC-N | F39: NG3195 | G39: 16 | H39: 28 | I39: 43 | J39: 54 | K39: 68 | L39: 85 | M39: 91 | N39: -- | O39: -- | P39: -- | Q39: --
B40: 03- | C40: 2 | D40: North | E40: FAO-N | F40: NG3195 | G40: 18 | H40: 30 | I40: 44 | J40: 56 | K40: 66 | L40: 82 | M40: 87 | N40: -- | O40: -- | P40: -- | Q40: --
D41: Mid | E41: FAO-N | F41: NG3195 | G41: 17 | H41: 29 | I41: 44 | J41: 56 | K41: 66 | L41: 81 | M41: 86 | N41: -- | O41: -- | P41: -- | Q41: --
D42: South | E42: FAO-N | F42: NG3195 | G42: 18 | H42: 30 | I42: 46 | J42: 59 | K42: 73 | L42: 93 | M42: -- | N42: -- | O42: -- | P42: -- | Q42: --
B43: 03- | C43: 3 | D43: North | E43: CSM | F43: NG3195 | G43: 17 | H43: 27 | I43: 39 | J43: 49 | K43: 60 | L43: 77 | M43: 85 | N43: -- | O43: -- | P43: -- | Q43: --
D44: Mid | E44: CSM | F44: NG3195 | G44: 17 | H44: 27 | I44: 39 | J44: 48 | K44: 52 | L44: 81 | M44: 89 | N44: -- | O44: -- | P44: -- | Q44: --
D45: South | E45: CSM | F45: NG3195 | G45: 18 | H45: 30 | I45: 44 | J45: 55 | K45: 70 | L45: 92 | M45: 86 | N45: -- | O45: -- | P45: -- | Q45: --
...

Sheet Averages
A1: Averages by treatments | E1: 2021
A4: Average Canopy Heights | P4: Average Canopy Heights
D5: ='Height Summary'!G9 -> 44348 | E5: ='Height Summary'!H9 -> 44354 | F5: ='Height Summary'!I9 -> 44364 | G5: ='Height Summary'!J9 -> 44371 | H5: ='Height Summary'!K9 -> 44378 | I5: ='Height Summary'!L9 -> 44390 | J5: ='Height Summary'!M9 -> 44396 | K5: ='Height Summary'!N9 -> 44413 | ... N5: ='Height Summary'!Q9 -> 44446 | S5: ='Height Summary'!G9 -> 44348 | T5: ='Height Summary'!H9 -> 44354 | U5: ='Height Summary'!I9 -> 44364 | V5: ='Height Summary'!J9 -> 44371 | W5: ='Height Summary'!K9 -> 44378 | X5: ='Height Summary'!L9 -> 44390 | Y5: ='Height Summary'!M9 -> 44396 | Z5: ='Height Summary'!N9 -> 44413 | ... AC5: ='Height Summary'!Q9 -> 44446
A6: NG3195 | D6: ='Height Summary'!G10 -> 152 | E6: ='Height Summary'!H10 -> 158 | F6: ='Height Summary'!I10 -> 168 | G6: ='Height Summary'!J10 -> 175 | H6: ='Height Summary'!K10 -> 182 | I6: ='Height Summary'!L10 -> 194 | J6: ='Height Summary'!M10 -> 200 | K6: ='Height Summary'!N10 -> 217 | ... N6: ='Height Summary'!Q10 -> 250 | P6: NG4936 | S6: ='Height Summary'!G10 -> 152 | T6: ='Height Summary'!H10 -> 158 | U6: ='Height Summary'!I10 -> 168 | V6: ='Height Summary'!J10 -> 175 | W6: ='Height Summary'!K10 -> 182 | X6: ='Height Summary'!L10 -> 194 | Y6: ='Height Summary'!M10 -> 200 | Z6: ='Height Summary'!N10 -> 217 | ... AC6: ='Height Summary'!Q10 -> 250
B7: AQC | D7: =AVERAGEIFS('Height Summary'!G$13:G$156,'Height Summary'!$F$13:$F$156, "NG3195",'Height Summary'!$E$13:$E$156, "AQC") -> 16.666667 | E7: =AVERAGEIFS('Height Summary'!H$13:H$156,'Height Summary'!$F$13:$F$156, "NG3195",'Height Summary'!$E$13:$E$156, "AQC") -> 26.083333 | F7: =AVERAGEIFS('Height Summary'!I$13:I$156,'Height Summary'!$F$13:$F$156, "NG3195",'Height Summary'!$E$13:$E$156, "AQC") -> 36.916667 | G7: =AVERAGEIFS('Height Summary'!J$13:J$156,'Height Summary'!$F$13:$F$156, "NG3195",'Height Summary'!$E$13:$E$156, "AQC") -> 47.833333 | H7: =AVERAGEIFS('Height Summary'!K$13:K$156,'Height Summary'!$F$13:$F$156, "NG3195",'Height Summary'!$E$13:$E$156, "AQC") -> 64 | I7: =AVERAGEIFS('Height Summary'!L$13:L$156,'Height Summary'!$F$13:$F$156, "NG3195",'Height Summary'!$E$13:$E$156, "AQC") -> 95 | J7: =AVERAGEIFS('Height Summary'!M$13:M$156,'Height Summary'!$F$13:$F$156, "NG3195",'Height Summary'!$E$13:$E$156, "AQC") -> 110.41667 | K7: =AVERAGEIFS('Height Summary'!N$13:N$156,'Height Summary'!$F$13:$F$156, "NG3195",'Height Summary'!$E$13:$E$156, "AQC") -> 127.16667 | ... N7: =AVERAGEIFS('Height Summary'!Q$13:Q$156,'Height Summary'!$F$13:$F$156, "NG3195",'Height Summary'!$E$13:$E$156, "AQC") -> 180.375 | Q7: AQC | S7: =AVERAGEIFS('Height Summary'!G$13:G$156,'Height Summary'!$F$13:$F$156, "NG4936",'Height Summary'!$E$13:$E$156, "AQC") -> 12.166667 | T7: =AVERAGEIFS('Height Summary'!H$13:H$156,'Height Summary'!$F$13:$F$156, "NG4936",'Height Summary'!$E$13:$E$156, "AQC") -> 20.083333 | U7: =AVERAGEIFS('Height Summary'!I$13:I$156,'Height Summary'!$F$13:$F$156, "NG4936",'Height Summary'!$E$13:$E$156, "AQC") -> 28.75 | V7: =AVERAGEIFS('Height Summary'!J$13:J$156,'Height Summary'!$F$13:$F$156, "NG4936",'Height Summary'!$E$13:$E$156, "AQC") -> 37.916667 | W7: =AVERAGEIFS('Height Summary'!K$13:K$156,'Height Summary'!$F$13:$F$156, "NG4936",'Height Summary'!$E$13:$E$156, "AQC") -> 53.916667 | X7: =AVERAGEIFS('Height Summary'!L$13:L$156,'Height Summary'!$F$13:$F$156, "NG4936",'Height Summary'!$E$13:$E$156, "AQC") -> 86.416667 | Y7: =AVERAGEIFS('Height Summary'!M$13:M$156,'Height Summary'!$F$13:$F$156, "NG4936",'Height Summary'!$E$13:$E$156, "AQC") -> 105.25 | Z7: =AVERAGEIFS('Height Summary'!N$13:N$156,'Height Summary'!$F$13:$F$156, "NG4936",'Height Summary'!$E$13:$E$156, "AQC") -> 124.16667 | ... AC7: =AVERAGEIFS('Height Summary'!Q$13:Q$156,'Height Summary'!$F$13:$F$156, "NG4936",'Height Summary'!$E$13:$E$156, "AQC") -> 187.66667
B9: AQC-N | D9: =AVERAGEIFS('Height Summary'!G$13:G$156,'Height Summary'!$F$13:$F$156, "NG3195",'Height Summary'!$E$13:$E$156, "AQC-N") -> 16 | E9: =AVERAGEIFS('Height Summary'!H$13:H$156,'Height Summary'!$F$13:$F$156, "NG3195",'Height Summary'!$E$13:$E$156, "AQC-N") -> 26.083333 | F9: =AVERAGEIFS('Height Summary'!I$13:I$156,'Height Summary'!$F$13:$F$156, "NG3195",'Height Summary'!$E$13:$E$156, "AQC-N") -> 36.083333 | G9: =AVERAGEIFS('Height Summary'!J$13:J$156,'Height Summary'!$F$13:$F$156, "NG3195",'Height Summary'!$E$13:$E$156, "AQC-N") -> 47.166667 | H9: =AVERAGEIFS('Height Summary'!K$13:K$156,'Height Summary'!$F$13:$F$156, "NG3195",'Height Summary'!$E$13:$E$156, "AQC-N") -> 59.25 | I9: =AVERAGEIFS('Height Summary'!L$13:L$156,'Height Summary'!$F$13:$F$156, "NG3195",'Height Summary'!$E$13:$E$156, "AQC-N") -> 83.75 | J9: =AVERAGEIFS('Height Summary'!M$13:M$156,'Height Summary'!$F$13:$F$156, "NG3195",'Height Summary'!$E$13:$E$156, "AQC-N") -> 98.333333 | K9: =AVERAGEIFS('Height Summary'!N$13:N$156,'Height Summary'!$F$13:$F$156, "NG3195",'Height Summary'!$E$13:$E$156, "AQC-N") -> 112.75 | ... N9: =AVERAGEIFS('Height Summary'!Q$13:Q$156,'Height Summary'!$F$13:$F$156, "NG3195",'Height Summary'!$E$13:$E$156, "AQC-N") -> 175 | Q9: AQC-N | S9: =AVERAGEIFS('Height Summary'!G$13:G$156,'Height Summary'!$F$13:$F$156, "NG4936",'Height Summary'!$E$13:$E$156, "AQC-N") -> 11.583333 | T9: =AVERAGEIFS('Height Summary'!H$13:H$156,'Height Summary'!$F$13:$F$156, "NG4936",'Height Summary'!$E$13:$E$156, "AQC-N") -> 17.833333 | U9: =AVERAGEIFS('Height Summary'!I$13:I$156,'Height Summary'!$F$13:$F$156, "NG4936",'Height Summary'!$E$13:$E$156, "AQC-N") -> 25.416667 | V9: =AVERAGEIFS('Height Summary'!J$13:J$156,'Height Summary'!$F$13:$F$156, "NG4936",'Height Summary'!$E$13:$E$156, "AQC-N") -> 35.25 | W9: =AVERAGEIFS('Height Summary'!K$13:K$156,'Height Summary'!$F$13:$F$156, "NG4936",'Height Summary'!$E$13:$E$156, "AQC-N") -> 48.5 | X9: =AVERAGEIFS('Height Summary'!L$13:L$156,'Height Summary'!$F$13:$F$156, "NG4936",'Height Summary'!$E$13:$E$156, "AQC-N") -> 75.75 | Y9: =AVERAGEIFS('Height Summary'!M$13:M$156,'Height Summary'!$F$13:$F$156, "NG4936",'Height Summary'!$E$13:$E$156, "AQC-N") -> 92.333333 | Z9: =AVERAGEIFS('Height Summary'!N$13:N$156,'Height Summary'!$F$13:$F$156, "NG4936",'Height Summary'!$E$13:$E$156, "AQC-N") -> 108.66667 | ... AC9: =AVERAGEIFS('Height Summary'!Q$13:Q$156,'Height Summary'!$F$13:$F$156, "NG4936",'Height Summary'!$E$13:$E$156, "AQC-N") -> 173.4
B11: CSM | D11: =AVERAGEIFS('Height Summary'!G$13:G$156,'Height Summary'!$F$13:$F$156, "NG3195",'Height Summary'!$E$13:$E$156, "CSM") -> 18.25 | E11: =AVERAGEIFS('Height Summary'!H$13:H$156,'Height Summary'!$F$13:$F$156, "NG3195",'Height Summary'!$E$13:$E$156, "CSM") -> 28.5 | F11: =AVERAGEIFS('Height Summary'!I$13:I$156,'Height Summary'!$F$13:$F$156, "NG3195",'Height Summary'!$E$13:$E$156, "CSM") -> 38.75 | G11: =AVERAGEIFS('Height Summary'!J$13:J$156,'Height Summary'!$F$13:$F$156, "NG3195",'Height Summary'!$E$13:$E$156, "CSM") -> 48.916667 | H11: =AVERAGEIFS('Height Summary'!K$13:K$156,'Height Summary'!$F$13:$F$156, "NG3195",'Height Summary'!$E$13:$E$156, "CSM") -> 62.583333 | I11: =AVERAGEIFS('Height Summary'!L$13:L$156,'Height Summary'!$F$13:$F$156, "NG3195",'Height Summary'!$E$13:$E$156, "CSM") -> 90.833333 | J11: =AVERAGEIFS('Height Summary'!M$13:M$156,'Height Summary'!$F$13:$F$156, "NG3195",'Height Summary'!$E$13:$E$156, "CSM") -> 108.91667 | K11: =AVERAGEIFS('Height Summary'!N$13:N$156,'Height Summary'!$F$13:$F$156, "NG3195",'Height Summary'!$E$13:$E$156, "CSM") -> 126.5 | ... N11: =AVERAGEIFS('Height Summary'!Q$13:Q$156,'Height Summary'!$F$13:$F$156, "NG3195",'Height Summary'!$E$13:$E$156, "CSM") -> 187.66667 | Q11: CSM | S11: =AVERAGEIFS('Height Summary'!G$13:G$156,'Height Summary'!$F$13:$F$156, "NG4936",'Height Summary'!$E$13:$E$156, "CSM") -> 11.416667 | T11: =AVERAGEIFS('Height Summary'!H$13:H$156,'Height Summary'!$F$13:$F$156, "NG4936",'Height Summary'!$E$13:$E$156, "CSM") -> 17.583333 | U11: =AVERAGEIFS('Height Summary'!I$13:I$156,'Height Summary'!$F$13:$F$156, "NG4936",'Height Summary'!$E$13:$E$156, "CSM") -> 25.5 | V11: =AVERAGEIFS('Height Summary'!J$13:J$156,'Height Summary'!$F$13:$F$156, "NG4936",'Height Summary'!$E$13:$E$156, "CSM") -> 34.75 | W11: =AVERAGEIFS('Height Summary'!K$13:K$156,'Height Summary'!$F$13:$F$156, "NG4936",'Height Summary'!$E$13:$E$156, "CSM") -> 52.583333 | X11: =AVERAGEIFS('Height Summary'!L$13:L$156,'Height Summary'!$F$13:$F$156, "NG4936",'Height Summary'!$E$13:$E$156, "CSM") -> 80.666667 | Y11: =AVERAGEIFS('Height Summary'!M$13:M$156,'Height Summary'!$F$13:$F$156, "NG4936",'Height Summary'!$E$13:$E$156, "CSM") -> 97.25 | Z11: =AVERAGEIFS('Height Summary'!N$13:N$156,'Height Summary'!$F$13:$F$156, "NG4936",'Height Summary'!$E$13:$E$156, "CSM") -> 114.08333 | ... AC11: =AVERAGEIFS('Height Summary'!Q$13:Q$156,'Height Summary'!$F$13:$F$156, "NG4936",'Height Summary'!$E$13:$E$156, "CSM") -> 177
B13: CSM-N | D13: =AVERAGEIFS('Height Summary'!G$13:G$156,'Height Summary'!$F$13:$F$156, "NG3195",'Height Summary'!$E$13:$E$156, "CSM-N") -> 16.583333 | E13: =AVERAGEIFS('Height Summary'!H$13:H$156,'Height Summary'!$F$13:$F$156, "NG3195",'Height Summary'!$E$13:$E$156, "CSM-N") -> 26 | F13: =AVERAGEIFS('Height Summary'!I$13:I$156,'Height Summary'!$F$13:$F$156, "NG3195",'Height Summary'!$E$13:$E$156, "CSM-N") -> 35.833333 | G13: =AVERAGEIFS('Height Summary'!J$13:J$156,'Height Summary'!$F$13:$F$156, "NG3195",'Height Summary'!$E$13:$E$156, "CSM-N") -> 49.166667 | H13: =AVERAGEIFS('Height Summary'!K$13:K$156,'Height Summary'!$F$13:$F$156, "NG3195",'Height Summary'!$E$13:$E$156, "CSM-N") -> 59 | I13: =AVERAGEIFS('Height Summary'!L$13:L$156,'Height Summary'!$F$13:$F$156, "NG3195",'Height Summary'!$E$13:$E$156, "CSM-N") -> 77.583333 | J13: =AVERAGEIFS('Height Summary'!M$13:M$156,'Height Summary'!$F$13:$F$156, "NG3195",'Height Summary'!$E$13:$E$156, "CSM-N") -> 92.833333 | K13: =AVERAGEIFS('Height Summary'!N$13:N$156,'Height Summary'!$F$13:$F$156, "NG3195",'Height Summary'!$E$13:$E$156, "CSM-N") -> 108.25 | ... N13: =AVERAGEIFS('Height Summary'!Q$13:Q$156,'Height Summary'!$F$13:$F$156, "NG3195",'Height Summary'!$E$13:$E$156, "CSM-N") -> 162 | Q13: CSM-N | S13: =AVERAGEIFS('Height Summary'!G$13:G$156,'Height Summary'!$F$13:$F$156, "NG4936",'Height Summary'!$E$13:$E$156, "CSM-N") -> 11.75 | T13: =AVERAGEIFS('Height Summary'!H$13:H$156,'Height Summary'!$F$13:$F$156, "NG4936",'Height Summary'!$E$13:$E$156, "CSM-N") -> 20.75 | U13: =AVERAGEIFS('Height Summary'!I$13:I$156,'Height Summary'!$F$13:$F$156, "NG4936",'Height Summary'!$E$13:$E$156, "CSM-N") -> 30.166667 | V13: =AVERAGEIFS('Height Summary'!J$13:J$156,'Height Summary'!$F$13:$F$156, "NG4936",'Height Summary'!$E$13:$E$156, "CSM-N") -> 40.583333 | W13: =AVERAGEIFS('Height Summary'!K$13:K$156,'Height Summary'!$F$13:$F$156, "NG4936",'Height Summary'!$E$13:$E$156, "CSM-N") -> 51.25 | X13: =AVERAGEIFS('Height Summary'!L$13:L$156,'Height Summary'!$F$13:$F$156, "NG4936",'Height Summary'!$E$13:$E$156, "CSM-N") -> 72.083333 | Y13: =AVERAGEIFS('Height Summary'!M$13:M$156,'Height Summary'!$F$13:$F$156, "NG4936",'Height Summary'!$E$13:$E$156, "CSM-N") -> 87.333333 | Z13: =AVERAGEIFS('Height Summary'!N$13:N$156,'Height Summary'!$F$13:$F$156, "NG4936",'Height Summary'!$E$13:$E$156, "CSM-N") -> 102.66667 | ... AC13: =AVERAGEIFS('Height Summary'!Q$13:Q$156,'Height Summary'!$F$13:$F$156, "NG4936",'Height Summary'!$E$13:$E$156, "CSM-N") -> 189
B15: FAO | D15: =AVERAGEIFS('Height Summary'!G$13:G$156,'Height Summary'!$F$13:$F$156, "NG3195",'Height Summary'!$E$13:$E$156, "FAO") -> 16.166667 | E15: =AVERAGEIFS('Height Summary'!H$13:H$156,'Height Summary'!$F$13:$F$156, "NG3195",'Height Summary'!$E$13:$E$156, "FAO") -> 25 | F15: =AVERAGEIFS('Height Summary'!I$13:I$156,'Height Summary'!$F$13:$F$156, "NG3195",'Height Summary'!$E$13:$E$156, "FAO") -> 37.083333 | G15: =AVERAGEIFS('Height Summary'!J$13:J$156,'Height Summary'!$F$13:$F$156, "NG3195",'Height Summary'!$E$13:$E$156, "FAO") -> 48.083333 | H15: =AVERAGEIFS('Height Summary'!K$13:K$156,'Height Summary'!$F$13:$F$156, "NG3195",'Height Summary'!$E$13:$E$156, "FAO") -> 61.25 | I15: =AVERAGEIFS('Height Summary'!L$13:L$156,'Height Summary'!$F$13:$F$156, "NG3195",'Height Summary'!$E$13:$E$156, "FAO") -> 88.833333 | J15: =AVERAGEIFS('Height Summary'!M$13:M$156,'Height Summary'!$F$13:$F$156, "NG3195",'Height Summary'!$E$13:$E$156, "FAO") -> 106.08333 | K15: =AVERAGEIFS('Height Summary'!N$13:N$156,'Height Summary'!$F$13:$F$156, "NG3195",'Height Summary'!$E$13:$E$156, "FAO") -> 123.25 | ... N15: =AVERAGEIFS('Height Summary'!Q$13:Q$156,'Height Summary'!$F$13:$F$156, "NG3195",'Height Summary'!$E$13:$E$156, "FAO") -> 175.22222 | Q15: FAO | S15: =AVERAGEIFS('Height Summary'!G$13:G$156,'Height Summary'!$F$13:$F$156, "NG4936",'Height Summary'!$E$13:$E$156, "FAO") -> 14.333333 | T15: =AVERAGEIFS('Height Summary'!H$13:H$156,'Height Summary'!$F$13:$F$156, "NG4936",'Height Summary'!$E$13:$E$156, "FAO") -> 21.666667 | U15: =AVERAGEIFS('Height Summary'!I$13:I$156,'Height Summary'!$F$13:$F$156, "NG4936",'Height Summary'!$E$13:$E$156, "FAO") -> 29.25 | V15: =AVERAGEIFS('Height Summary'!J$13:J$156,'Height Summary'!$F$13:$F$156, "NG4936",'Height Summary'!$E$13:$E$156, "FAO") -> 37.833333 | W15: =AVERAGEIFS('Height Summary'!K$13:K$156,'Height Summary'!$F$13:$F$156, "NG4936",'Height Summary'!$E$13:$E$156, "FAO") -> 54.666667 | X15: =AVERAGEIFS('Height Summary'!L$13:L$156,'Height Summary'!$F$13:$F$156, "NG4936",'Height Summary'!$E$13:$E$156, "FAO") -> 87.5 | Y15: =AVERAGEIFS('Height Summary'!M$13:M$156,'Height Summary'!$F$13:$F$156, "NG4936",'Height Summary'!$E$13:$E$156, "FAO") -> 106.91667 | Z15: =AVERAGEIFS('Height Summary'!N$13:N$156,'Height Summary'!$F$13:$F$156, "NG4936",'Height Summary'!$E$13:$E$156, "FAO") -> 125.33333 | ... AC15: =AVERAGEIFS('Height Summary'!Q$13:Q$156,'Height Summary'!$F$13:$F$156, "NG4936",'Height Summary'!$E$13:$E$156, "FAO") -> 177
B17: FAO-N | D17: =AVERAGEIFS('Height Summary'!G$13:G$156,'Height Summary'!$F$13:$F$156, "NG3195",'Height Summary'!$E$13:$E$156, "FAO-N") -> 16.666667 | E17: =AVERAGEIFS('Height Summary'!H$13:H$156,'Height Summary'!$F$13:$F$156, "NG3195",'Height Summary'!$E$13:$E$156, "FAO-N") -> 25.833333 | F17: =AVERAGEIFS('Height Summary'!I$13:I$156,'Height Summary'!$F$13:$F$156, "NG3195",'Height Summary'!$E$13:$E$156, "FAO-N") -> 34.583333 | G17: =AVERAGEIFS('Height Summary'!J$13:J$156,'Height Summary'!$F$13:$F$156, "NG3195",'Height Summary'!$E$13:$E$156, "FAO-N") -> 48.5 | H17: =AVERAGEIFS('Height Summary'!K$13:K$156,'Height Summary'!$F$13:$F$156, "NG3195",'Height Summary'!$E$13:$E$156, "FAO-N") -> 60.916667 | I17: =AVERAGEIFS('Height Summary'!L$13:L$156,'Height Summary'!$F$13:$F$156, "NG3195",'Height Summary'!$E$13:$E$156, "FAO-N") -> 86.083333 | J17: =AVERAGEIFS('Height Summary'!M$13:M$156,'Height Summary'!$F$13:$F$156, "NG3195",'Height Summary'!$E$13:$E$156, "FAO-N") -> 103.33333 | K17: =AVERAGEIFS('Height Summary'!N$13:N$156,'Height Summary'!$F$13:$F$156, "NG3195",'Height Summary'!$E$13:$E$156, "FAO-N") -> 119.41667 | ... N17: =AVERAGEIFS('Height Summary'!Q$13:Q$156,'Height Summary'!$F$13:$F$156, "NG3195",'Height Summary'!$E$13:$E$156, "FAO-N") -> 194.5 | Q17: FAO-N | S17: =AVERAGEIFS('Height Summary'!G$13:G$156,'Height Summary'!$F$13:$F$156, "NG4936",'Height Summary'!$E$13:$E$156, "FAO-N") -> 12 | T17: =AVERAGEIFS('Height Summary'!H$13:H$156,'Height Summary'!$F$13:$F$156, "NG4936",'Height Summary'!$E$13:$E$156, "FAO-N") -> 18.416667 | U17: =AVERAGEIFS('Height Summary'!I$13:I$156,'Height Summary'!$F$13:$F$156, "NG4936",'Height Summary'!$E$13:$E$156, "FAO-N") -> 25.166667 | V17: =AVERAGEIFS('Height Summary'!J$13:J$156,'Height Summary'!$F$13:$F$156, "NG4936",'Height Summary'!$E$13:$E$156, "FAO-N") -> 36.25 | W17: =AVERAGEIFS('Height Summary'!K$13:K$156,'Height Summary'!$F$13:$F$156, "NG4936",'Height Summary'!$E$13:$E$156, "FAO-N") -> 51.5 | X17: =AVERAGEIFS('Height Summary'!L$13:L$156,'Height Summary'!$F$13:$F$156, "NG4936",'Height Summary'!$E$13:$E$156, "FAO-N") -> 80.833333 | Y17: =AVERAGEIFS('Height Summary'!M$13:M$156,'Height Summary'!$F$13:$F$156, "NG4936",'Height Summary'!$E$13:$E$156, "FAO-N") -> 100.16667 | Z17: =AVERAGEIFS('Height Summary'!N$13:N$156,'Height Summary'!$F$13:$F$156, "NG4936",'Height Summary'!$E$13:$E$156, "FAO-N") -> 119.41667 | ... AC17: =AVERAGEIFS('Height Summary'!Q$13:Q$156,'Height Summary'!$F$13:$F$156, "NG4936",'Height Summary'!$E$13:$E$156, "FAO-N") -> 188.16667
A20: Average Canopy Widths | P20: Average Canopy Widths
D22: ='Cover Summary'!G9 -> 44348 | E22: ='Cover Summary'!H9 -> 44354 | F22: ='Cover Summary'!I9 -> 44364 | G22: ='Cover Summary'!J9 -> 44371 | H22: ='Cover Summary'!K9 -> 44378 | I22: ='Cover Summary'!L9 -> 44390 | J22: ='Cover Summary'!M9 -> 44396 | K22: ='Cover Summary'!N9 -> 44413 | ... N22: ='Cover Summary'!Q9 -> 44446 | S22: ='Cover Summary'!G9 -> 44348 | T22: ='Cover Summary'!H9 -> 44354 | U22: ='Cover Summary'!I9 -> 44364 | V22: ='Cover Summary'!J9 -> 44371 | W22: ='Cover Summary'!K9 -> 44378 | X22: ='Cover Summary'!L9 -> 44390 | Y22: ='Cover Summary'!M9 -> 44396 | Z22: ='Cover Summary'!N9 -> 44413 | ... AC22: ='Cover Summary'!Q9 -> 44446
A23: NG3195 | D23: ='Cover Summary'!G10 -> 152 | E23: ='Cover Summary'!H10 -> 158 | F23: ='Cover Summary'!I10 -> 168 | G23: ='Cover Summary'!J10 -> 175 | H23: ='Cover Summary'!K10 -> 182 | I23: ='Cover Summary'!L10 -> 194 | J23: ='Cover Summary'!M10 -> 200 | K23: ='Cover Summary'!N10 -> 217 | ... N23: ='Cover Summary'!Q10 -> 250 | P23: NG4936 | S23: ='Cover Summary'!G10 -> 152 | T23: ='Cover Summary'!H10 -> 158 | U23: ='Cover Summary'!I10 -> 168 | V23: ='Cover Summary'!J10 -> 175 | W23: ='Cover Summary'!K10 -> 182 | X23: ='Cover Summary'!L10 -> 194 | Y23: ='Cover Summary'!M10 -> 200 | Z23: ='Cover Summary'!N10 -> 217 | ... AC23: ='Cover Summary'!Q10 -> 250
B24: AQC | D24: =AVERAGEIFS('Cover Summary'!G$13:G$156,'Cover Summary'!$F$13:$F$156, "NG3195",'Cover Summary'!$E$13:$E$156, "AQC") -> 15 | E24: =AVERAGEIFS('Cover Summary'!H$13:H$156,'Cover Summary'!$F$13:$F$156, "NG3195",'Cover Summary'!$E$13:$E$156, "AQC") -> 26.083333 | F24: =AVERAGEIFS('Cover Summary'!I$13:I$156,'Cover Summary'!$F$13:$F$156, "NG3195",'Cover Summary'!$E$13:$E$156, "AQC") -> 39.916667 | G24: =AVERAGEIFS('Cover Summary'!J$13:J$156,'Cover Summary'!$F$13:$F$156, "NG3195",'Cover Summary'!$E$13:$E$156, "AQC") -> 51.166667 | H24: =AVERAGEIFS('Cover Summary'!K$13:K$156,'Cover Summary'!$F$13:$F$156, "NG3195",'Cover Summary'!$E$13:$E$156, "AQC") -> 62.5 | I24: =AVERAGEIFS('Cover Summary'!L$13:L$156,'Cover Summary'!$F$13:$F$156, "NG3195",'Cover Summary'!$E$13:$E$156, "AQC") -> 79.75 | J24: =AVERAGEIFS('Cover Summary'!M$13:M$156,'Cover Summary'!$F$13:$F$156, "NG3195",'Cover Summary'!$E$13:$E$156, "AQC") -> 82.333333 | K24: =AVERAGEIFS('Cover Summary'!N$13:N$156,'Cover Summary'!$F$13:$F$156, "NG3195",'Cover Summary'!$E$13:$E$156, "AQC") -> 89.6 | ... N24: =AVERAGEIFS('Cover Summary'!Q$13:Q$156,'Cover Summary'!$F$13:$F$156, "NG3195",'Cover Summary'!$E$13:$E$156, "AQC") -> #DIV/0! | Q24: AQC | S24: =AVERAGEIFS('Cover Summary'!G$13:G$156,'Cover Summary'!$F$13:$F$156, "NG4936",'Cover Summary'!$E$13:$E$156, "AQC") -> 11.333333 | T24: =AVERAGEIFS('Cover Summary'!H$13:H$156,'Cover Summary'!$F$13:$F$156, "NG4936",'Cover Summary'!$E$13:$E$156, "AQC") -> 21.166667 | U24: =AVERAGEIFS('Cover Summary'!I$13:I$156,'Cover Summary'!$F$13:$F$156, "NG4936",'Cover Summary'!$E$13:$E$156, "AQC") -> 33.833333 | V24: =AVERAGEIFS('Cover Summary'!J$13:J$156,'Cover Summary'!$F$13:$F$156, "NG4936",'Cover Summary'!$E$13:$E$156, "AQC") -> 43.75 | W24: =AVERAGEIFS('Cover Summary'!K$13:K$156,'Cover Summary'!$F$13:$F$156, "NG4936",'Cover Summary'!$E$13:$E$156, "AQC") -> 53.083333 | X24: =AVERAGEIFS('Cover Summary'!L$13:L$156,'Cover Summary'!$F$13:$F$156, "NG4936",'Cover Summary'!$E$13:$E$156, "AQC") -> 74.083333 | Y24: =AVERAGEIFS('Cover Summary'!M$13:M$156,'Cover Summary'!$F$13:$F$156, "NG4936",'Cover Summary'!$E$13:$E$156, "AQC") -> 81.75 | Z24: =AVERAGEIFS('Cover Summary'!N$13:N$156,'Cover Summary'!$F$13:$F$156, "NG4936",'Cover Summary'!$E$13:$E$156, "AQC") -> 89.333333 | ... AC24: =AVERAGEIFS('Cover Summary'!Q$13:Q$156,'Cover Summary'!$F$13:$F$156, "NG4936",'Cover Summary'!$E$13:$E$156, "AQC") -> #DIV/0!
B26: AQC-N | D26: =AVERAGEIFS('Cover Summary'!G$13:G$156,'Cover Summary'!$F$13:$F$156, "NG3195",'Cover Summary'!$E$13:$E$156, "AQC-N") -> 14.5 | E26: =AVERAGEIFS('Cover Summary'!H$13:H$156,'Cover Summary'!$F$13:$F$156, "NG3195",'Cover Summary'!$E$13:$E$156, "AQC-N") -> 23.833333 | F26: =AVERAGEIFS('Cover Summary'!I$13:I$156,'Cover Summary'!$F$13:$F$156, "NG3195",'Cover Summary'!$E$13:$E$156, "AQC-N") -> 35.583333 | G26: =AVERAGEIFS('Cover Summary'!J$13:J$156,'Cover Summary'!$F$13:$F$156, "NG3195",'Cover Summary'!$E$13:$E$156, "AQC-N") -> 44.833333 | H26: =AVERAGEIFS('Cover Summary'!K$13:K$156,'Cover Summary'!$F$13:$F$156, "NG3195",'Cover Summary'!$E$13:$E$156, "AQC-N") -> 54.833333 | I26: =AVERAGEIFS('Cover Summary'!L$13:L$156,'Cover Summary'!$F$13:$F$156, "NG3195",'Cover Summary'!$E$13:$E$156, "AQC-N") -> 69.666667 | J26: =AVERAGEIFS('Cover Summary'!M$13:M$156,'Cover Summary'!$F$13:$F$156, "NG3195",'Cover Summary'!$E$13:$E$156, "AQC-N") -> 76.416667 | K26: =AVERAGEIFS('Cover Summary'!N$13:N$156,'Cover Summary'!$F$13:$F$156, "NG3195",'Cover Summary'!$E$13:$E$156, "AQC-N") -> 80.285714 | ... N26: =AVERAGEIFS('Cover Summary'!Q$13:Q$156,'Cover Summary'!$F$13:$F$156, "NG3195",'Cover Summary'!$E$13:$E$156, "AQC-N") -> #DIV/0! | Q26: AQC-N | S26: =AVERAGEIFS('Cover Summary'!G$13:G$156,'Cover Summary'!$F$13:$F$156, "NG4936",'Cover Summary'!$E$13:$E$156, "AQC-N") -> 10.833333 | T26: =AVERAGEIFS('Cover Summary'!H$13:H$156,'Cover Summary'!$F$13:$F$156, "NG4936",'Cover Summary'!$E$13:$E$156, "AQC-N") -> 19.416667 | U26: =AVERAGEIFS('Cover Summary'!I$13:I$156,'Cover Summary'!$F$13:$F$156, "NG4936",'Cover Summary'!$E$13:$E$156, "AQC-N") -> 29.833333 | V26: =AVERAGEIFS('Cover Summary'!J$13:J$156,'Cover Summary'!$F$13:$F$156, "NG4936",'Cover Summary'!$E$13:$E$156, "AQC-N") -> 38.416667 | W26: =AVERAGEIFS('Cover Summary'!K$13:K$156,'Cover Summary'!$F$13:$F$156, "NG4936",'Cover Summary'!$E$13:$E$156, "AQC-N") -> 49.583333 | X26: =AVERAGEIFS('Cover Summary'!L$13:L$156,'Cover Summary'!$F$13:$F$156, "NG4936",'Cover Summary'!$E$13:$E$156, "AQC-N") -> 66.416667 | Y26: =AVERAGEIFS('Cover Summary'!M$13:M$156,'Cover Summary'!$F$13:$F$156, "NG4936",'Cover Summary'!$E$13:$E$156, "AQC-N") -> 72.333333 | Z26: =AVERAGEIFS('Cover Summary'!N$13:N$156,'Cover Summary'!$F$13:$F$156, "NG4936",'Cover Summary'!$E$13:$E$156, "AQC-N") -> 80.2 | ... AC26: =AVERAGEIFS('Cover Summary'!Q$13:Q$156,'Cover Summary'!$F$13:$F$156, "NG4936",'Cover Summary'!$E$13:$E$156, "AQC-N") -> #DIV/0!
B28: CSM | D28: =AVERAGEIFS('Cover Summary'!G$13:G$156,'Cover Summary'!$F$13:$F$156, "NG3195",'Cover Summary'!$E$13:$E$156, "CSM") -> 16.166667 | E28: =AVERAGEIFS('Cover Summary'!H$13:H$156,'Cover Summary'!$F$13:$F$156, "NG3195",'Cover Summary'!$E$13:$E$156, "CSM") -> 26.583333 | F28: =AVERAGEIFS('Cover Summary'!I$13:I$156,'Cover Summary'!$F$13:$F$156, "NG3195",'Cover Summary'!$E$13:$E$156, "CSM") -> 39.166667 | G28: =AVERAGEIFS('Cover Summary'!J$13:J$156,'Cover Summary'!$F$13:$F$156, "NG3195",'Cover Summary'!$E$13:$E$156, "CSM") -> 49.333333 | H28: =AVERAGEIFS('Cover Summary'!K$13:K$156,'Cover Summary'!$F$13:$F$156, "NG3195",'Cover Summary'!$E$13:$E$156, "CSM") -> 60.916667 | I28: =AVERAGEIFS('Cover Summary'!L$13:L$156,'Cover Summary'!$F$13:$F$156, "NG3195",'Cover Summary'!$E$13:$E$156, "CSM") -> 79.833333 | J28: =AVERAGEIFS('Cover Summary'!M$13:M$156,'Cover Summary'!$F$13:$F$156, "NG3195",'Cover Summary'!$E$13:$E$156, "CSM") -> 86 | K28: =AVERAGEIFS('Cover Summary'!N$13:N$156,'Cover Summary'!$F$13:$F$156, "NG3195",'Cover Summary'!$E$13:$E$156, "CSM") -> 94.5 | ... N28: =AVERAGEIFS('Cover Summary'!Q$13:Q$156,'Cover Summary'!$F$13:$F$156, "NG3195",'Cover Summary'!$E$13:$E$156, "CSM") -> #DIV/0! | Q28: CSM | S28: =AVERAGEIFS('Cover Summary'!G$13:G$156,'Cover Summary'!$F$13:$F$156, "NG4936",'Cover Summary'!$E$13:$E$156, "CSM") -> 10.333333 | T28: =AVERAGEIFS('Cover Summary'!H$13:H$156,'Cover Summary'!$F$13:$F$156, "NG4936",'Cover Summary'!$E$13:$E$156, "CSM") -> 18.416667 | U28: =AVERAGEIFS('Cover Summary'!I$13:I$156,'Cover Summary'!$F$13:$F$156, "NG4936",'Cover Summary'!$E$13:$E$156, "CSM") -> 30.916667 | V28: =AVERAGEIFS('Cover Summary'!J$13:J$156,'Cover Summary'!$F$13:$F$156, "NG4936",'Cover Summary'!$E$13:$E$156, "CSM") -> 37.666667 | W28: =AVERAGEIFS('Cover Summary'!K$13:K$156,'Cover Summary'!$F$13:$F$156, "NG4936",'Cover Summary'!$E$13:$E$156, "CSM") -> 49.916667 | X28: =AVERAGEIFS('Cover Summary'!L$13:L$156,'Cover Summary'!$F$13:$F$156, "NG4936",'Cover Summary'!$E$13:$E$156, "CSM") -> 68.75 | Y28: =AVERAGEIFS('Cover Summary'!M$13:M$156,'Cover Summary'!$F$13:$F$156, "NG4936",'Cover Summary'!$E$13:$E$156, "CSM") -> 77.25 | Z28: =AVERAGEIFS('Cover Summary'!N$13:N$156,'Cover Summary'!$F$13:$F$156, "NG4936",'Cover Summary'!$E$13:$E$156, "CSM") -> 87.333333 | ... AC28: =AVERAGEIFS('Cover Summary'!Q$13:Q$156,'Cover Summary'!$F$13:$F$156, "NG4936",'Cover Summary'!$E$13:$E$156, "CSM") -> #DIV/0!
B30: CSM-N | D30: =AVERAGEIFS('Cover Summary'!G$13:G$156,'Cover Summary'!$F$13:$F$156, "NG3195",'Cover Summary'!$E$13:$E$156, "CSM-N") -> 15.083333 | E30: =AVERAGEIFS('Cover Summary'!H$13:H$156,'Cover Summary'!$F$13:$F$156, "NG3195",'Cover Summary'!$E$13:$E$156, "CSM-N") -> 23.583333 | F30: =AVERAGEIFS('Cover Summary'!I$13:I$156,'Cover Summary'!$F$13:$F$156, "NG3195",'Cover Summary'!$E$13:$E$156, "CSM-N") -> 33.583333 | G30: =AVERAGEIFS('Cover Summary'!J$13:J$156,'Cover Summary'!$F$13:$F$156, "NG3195",'Cover Summary'!$E$13:$E$156, "CSM-N") -> 42 | H30: =AVERAGEIFS('Cover Summary'!K$13:K$156,'Cover Summary'!$F$13:$F$156, "NG3195",'Cover Summary'!$E$13:$E$156, "CSM-N") -> 55.166667 | I30: =AVERAGEIFS('Cover Summary'!L$13:L$156,'Cover Summary'!$F$13:$F$156, "NG3195",'Cover Summary'!$E$13:$E$156, "CSM-N") -> 69 | J30: =AVERAGEIFS('Cover Summary'!M$13:M$156,'Cover Summary'!$F$13:$F$156, "NG3195",'Cover Summary'!$E$13:$E$156, "CSM-N") -> 76.083333 | K30: =AVERAGEIFS('Cover Summary'!N$13:N$156,'Cover Summary'!$F$13:$F$156, "NG3195",'Cover Summary'!$E$13:$E$156, "CSM-N") -> 88.545455 | ... N30: =AVERAGEIFS('Cover Summary'!Q$13:Q$156,'Cover Summary'!$F$13:$F$156, "NG3195",'Cover Summary'!$E$13:$E$156, "CSM-N") -> #DIV/0! | Q30: CSM-N | S30: =AVERAGEIFS('Cover Summary'!G$13:G$156,'Cover Summary'!$F$13:$F$156, "NG4936",'Cover Summary'!$E$13:$E$156, "CSM-N") -> 10.75 | T30: =AVERAGEIFS('Cover Summary'!H$13:H$156,'Cover Summary'!$F$13:$F$156, "NG4936",'Cover Summary'!$E$13:$E$156, "CSM-N") -> 19 | U30: =AVERAGEIFS('Cover Summary'!I$13:I$156,'Cover Summary'!$F$13:$F$156, "NG4936",'Cover Summary'!$E$13:$E$156, "CSM-N") -> 29.333333 | V30: =AVERAGEIFS('Cover Summary'!J$13:J$156,'Cover Summary'!$F$13:$F$156, "NG4936",'Cover Summary'!$E$13:$E$156, "CSM-N") -> 37.75 | W30: =AVERAGEIFS('Cover Summary'!K$13:K$156,'Cover Summary'!$F$13:$F$156, "NG4936",'Cover Summary'!$E$13:$E$156, "CSM-N") -> 47.583333 | X30: =AVERAGEIFS('Cover Summary'!L$13:L$156,'Cover Summary'!$F$13:$F$156, "NG4936",'Cover Summary'!$E$13:$E$156, "CSM-N") -> 63.166667 | Y30: =AVERAGEIFS('Cover Summary'!M$13:M$156,'Cover Summary'!$F$13:$F$156, "NG4936",'Cover Summary'!$E$13:$E$156, "CSM-N") -> 69.5 | Z30: =AVERAGEIFS('Cover Summary'!N$13:N$156,'Cover Summary'!$F$13:$F$156, "NG4936",'Cover Summary'!$E$13:$E$156, "CSM-N") -> 82.25 | ... AC30: =AVERAGEIFS('Cover Summary'!Q$13:Q$156,'Cover Summary'!$F$13:$F$156, "NG4936",'Cover Summary'!$E$13:$E$156, "CSM-N") -> #DIV/0!
B32: FAO | D32: =AVERAGEIFS('Cover Summary'!G$13:G$156,'Cover Summary'!$F$13:$F$156, "NG3195",'Cover Summary'!$E$13:$E$156, "FAO") -> 14.5 | E32: =AVERAGEIFS('Cover Summary'!H$13:H$156,'Cover Summary'!$F$13:$F$156, "NG3195",'Cover Summary'!$E$13:$E$156, "FAO") -> 23.833333 | F32: =AVERAGEIFS('Cover Summary'!I$13:I$156,'Cover Summary'!$F$13:$F$156, "NG3195",'Cover Summary'!$E$13:$E$156, "FAO") -> 36 | G32: =AVERAGEIFS('Cover Summary'!J$13:J$156,'Cover Summary'!$F$13:$F$156, "NG3195",'Cover Summary'!$E$13:$E$156, "FAO") -> 45.833333 | H32: =AVERAGEIFS('Cover Summary'!K$13:K$156,'Cover Summary'!$F$13:$F$156, "NG3195",'Cover Summary'!$E$13:$E$156, "FAO") -> 57.416667 | I32: =AVERAGEIFS('Cover Summary'!L$13:L$156,'Cover Summary'!$F$13:$F$156, "NG3195",'Cover Summary'!$E$13:$E$156, "FAO") -> 75.416667 | J32: =AVERAGEIFS('Cover Summary'!M$13:M$156,'Cover Summary'!$F$13:$F$156, "NG3195",'Cover Summary'!$E$13:$E$156, "FAO") -> 82.454545 | K32: =AVERAGEIFS('Cover Summary'!N$13:N$156,'Cover Summary'!$F$13:$F$156, "NG3195",'Cover Summary'!$E$13:$E$156, "FAO") -> 91.25 | ... N32: =AVERAGEIFS('Cover Summary'!Q$13:Q$156,'Cover Summary'!$F$13:$F$156, "NG3195",'Cover Summary'!$E$13:$E$156, "FAO") -> #DIV/0! | Q32: FAO | S32: =AVERAGEIFS('Cover Summary'!G$13:G$156,'Cover Summary'!$F$13:$F$156, "NG4936",'Cover Summary'!$E$13:$E$156, "FAO") -> 12.166667 | T32: =AVERAGEIFS('Cover Summary'!H$13:H$156,'Cover Summary'!$F$13:$F$156, "NG4936",'Cover Summary'!$E$13:$E$156, "FAO") -> 20.833333 | U32: =AVERAGEIFS('Cover Summary'!I$13:I$156,'Cover Summary'!$F$13:$F$156, "NG4936",'Cover Summary'!$E$13:$E$156, "FAO") -> 31.75 | V32: =AVERAGEIFS('Cover Summary'!J$13:J$156,'Cover Summary'!$F$13:$F$156, "NG4936",'Cover Summary'!$E$13:$E$156, "FAO") -> 40.166667 | W32: =AVERAGEIFS('Cover Summary'!K$13:K$156,'Cover Summary'!$F$13:$F$156, "NG4936",'Cover Summary'!$E$13:$E$156, "FAO") -> 53.5 | X32: =AVERAGEIFS('Cover Summary'!L$13:L$156,'Cover Summary'!$F$13:$F$156, "NG4936",'Cover Summary'!$E$13:$E$156, "FAO") -> 74.833333 | Y32: =AVERAGEIFS('Cover Summary'!M$13:M$156,'Cover Summary'!$F$13:$F$156, "NG4936",'Cover Summary'!$E$13:$E$156, "FAO") -> 83.416667 | Z32: =AVERAGEIFS('Cover Summary'!N$13:N$156,'Cover Summary'!$F$13:$F$156, "NG4936",'Cover Summary'!$E$13:$E$156, "FAO") -> 91.571429 | ... AC32: =AVERAGEIFS('Cover Summary'!Q$13:Q$156,'Cover Summary'!$F$13:$F$156, "NG4936",'Cover Summary'!$E$13:$E$156, "FAO") -> #DIV/0!
B34: FAO-N | D34: =AVERAGEIFS('Cover Summary'!G$13:G$156,'Cover Summary'!$F$13:$F$156, "NG3195",'Cover Summary'!$E$13:$E$156, "FAO-N") -> 14.666667 | E34: =AVERAGEIFS('Cover Summary'!H$13:H$156,'Cover Summary'!$F$13:$F$156, "NG3195",'Cover Summary'!$E$13:$E$156, "FAO-N") -> 25.083333 | F34: =AVERAGEIFS('Cover Summary'!I$13:I$156,'Cover Summary'!$F$13:$F$156, "NG3195",'Cover Summary'!$E$13:$E$156, "FAO-N") -> 38 | G34: =AVERAGEIFS('Cover Summary'!J$13:J$156,'Cover Summary'!$F$13:$F$156, "NG3195",'Cover Summary'!$E$13:$E$156, "FAO-N") -> 48.25 | H34: =AVERAGEIFS('Cover Summary'!K$13:K$156,'Cover Summary'!$F$13:$F$156, "NG3195",'Cover Summary'!$E$13:$E$156, "FAO-N") -> 59.583333 | I34: =AVERAGEIFS('Cover Summary'!L$13:L$156,'Cover Summary'!$F$13:$F$156, "NG3195",'Cover Summary'!$E$13:$E$156, "FAO-N") -> 76.666667 | J34: =AVERAGEIFS('Cover Summary'!M$13:M$156,'Cover Summary'!$F$13:$F$156, "NG3195",'Cover Summary'!$E$13:$E$156, "FAO-N") -> 80.2 | K34: =AVERAGEIFS('Cover Summary'!N$13:N$156,'Cover Summary'!$F$13:$F$156, "NG3195",'Cover Summary'!$E$13:$E$156, "FAO-N") -> 89.5 | ... N34: =AVERAGEIFS('Cover Summary'!Q$13:Q$156,'Cover Summary'!$F$13:$F$156, "NG3195",'Cover Summary'!$E$13:$E$156, "FAO-N") -> #DIV/0! | Q34: FAO-N | S34: =AVERAGEIFS('Cover Summary'!G$13:G$156,'Cover Summary'!$F$13:$F$156, "NG4936",'Cover Summary'!$E$13:$E$156, "FAO-N") -> 11.666667 | T34: =AVERAGEIFS('Cover Summary'!H$13:H$156,'Cover Summary'!$F$13:$F$156, "NG4936",'Cover Summary'!$E$13:$E$156, "FAO-N") -> 20.666667 | U34: =AVERAGEIFS('Cover Summary'!I$13:I$156,'Cover Summary'!$F$13:$F$156, "NG4936",'Cover Summary'!$E$13:$E$156, "FAO-N") -> 32.083333 | V34: =AVERAGEIFS('Cover Summary'!J$13:J$156,'Cover Summary'!$F$13:$F$156, "NG4936",'Cover Summary'!$E$13:$E$156, "FAO-N") -> 41.25 | W34: =AVERAGEIFS('Cover Summary'!K$13:K$156,'Cover Summary'!$F$13:$F$156, "NG4936",'Cover Summary'!$E$13:$E$156, "FAO-N") -> 53.333333 | X34: =AVERAGEIFS('Cover Summary'!L$13:L$156,'Cover Summary'!$F$13:$F$156, "NG4936",'Cover Summary'!$E$13:$E$156, "FAO-N") -> 71.083333 | Y34: =AVERAGEIFS('Cover Summary'!M$13:M$156,'Cover Summary'!$F$13:$F$156, "NG4936",'Cover Summary'!$E$13:$E$156, "FAO-N") -> 78.916667 | Z34: =AVERAGEIFS('Cover Summary'!N$13:N$156,'Cover Summary'!$F$13:$F$156, "NG4936",'Cover Summary'!$E$13:$E$156, "FAO-N") -> 85.333333 | ... AC34: =AVERAGEIFS('Cover Summary'!Q$13:Q$156,'Cover Summary'!$F$13:$F$156, "NG4936",'Cover Summary'!$E$13:$E$156, "FAO-N") -> #DIV/0!

Sheet Emergence
A1: 2021 | B1: F13 b4 | D1: Cotton
B3: Emergence
A4: Emergence counts taken at a flag placed in each plot for emergence.
A5: Flags placed 1 row East of the neutron tubes, and 1.5-2 meters North of the tube.
A6: Counting emerged plants 1 fro North of the flag.
A8: Flags zig-zag through the field.
E10: # plants per 1 meter (1 meter North of each flag) | K10: out sick 5 May
B11: Date: | E11: Th 29 April | G11: Sun 2 May | I11: 44319 | K11: 44323 | M11: 44326 | N11: 44328 | O11: 44333
B12: DOY: | E12: 119 | G12: 122 | I12: 123 | K12: 127 | M12: 130 | N12: 132 | O12: 137
B13: by: | E13: SMM | G13: SMM | I13: SMM | K13: SMM | M13: SMM | N13: SMM | O13: SMM
B14: flag point | E14: 1000-1100h | G14: 1000-1030h | I14: 0955-1030h | K14: 0930-1000h | M14: 1000-1030 | N14: 1100-11300 | O14: 1320-1355
A15: "a" = West "b" = East | C15: Plot | E15: plants/1 m | F15: plants starting to emerge | G15: plants/1 m | H15: plants starting to emerge | I15: plants/1 m | J15: plants starting to emerge | K15: plants/1 m | L15: plants starting to emerge | M15: plants/1 m | N15: plants/1 m | O15: plants/1 m
A16: Northwest corner span 6 | B16: 1a | C16: 01-1 | D16: NG4936 | E16: 0 | F16: 0 | G16: 5 | H16: 0 | I16: 5 | J16: 1 | K16: 6 | L16: 1 | M16: 6 | N16: 6 | O16: 6
B17: 1b | C17: 02-1 | D17: NG3195 | E17: 0 | F17: 2 | G17: 10 | H17: 0 | I17: 10 | J17: 0 | K17: 11 | L17: 0 | M17: 11 | N17: 11 | O17: 10
B18: 2b | C18: 02-2 | D18: NG3195 | E18: 0 | F18: 0 | G18: 5 | H18: 1 | I18: 5 | J18: 1 | K18: 6 | L18: 0 | M18: 6 | N18: 6 | O18: 5
B19: 2a | C19: 01-2 | D19: NG4936 | E19: 0 | F19: 1 | G19: 4 | H19: 2 | I19: 5 | J19: 1 | K19: 8 | L19: 0 | M19: 8 | N19: 8 | O19: 8
