Workbook

Sheet Height
A1: CCID | B1: DOY141 | C1: DOY148 | D1: DOY154 | E1: DOY162 | F1: DOY168 | G1: DOY176 | H1: DOY182 | I1: DOY189 | J1: DOY196 | K1: DOY203 | L1: DOY211 | M1: DOY217 | N1: DOY225 | O1: DOY232 | P1: DOY238 | Q1: DOY246 | R1: DOY259
A2: 11N | B2: 10 | C2: 14 | D2: 15 | E2: 23 | F2: 32 | G2: 38 | H2: 56 | I2: 71 | J2: 83 | K2: 91 | L2: 104 | M2: 113 | N2: 109 | O2: 111 | P2: 109 | Q2: 107 | R2: 101
A3: 11S | B3: 10 | C3: 15 | D3: 18 | E3: 31 | F3: 44 | G3: 53 | H3: 64 | I3: 73 | J3: 84 | K3: 96 | L3: 94 | M3: 102 | N3: 98 | O3: 100 | P3: 102 | Q3: 104 | R3: 109
A4: 12N | B4: 11 | C4: 14 | D4: 19 | E4: 27 | F4: 41 | G4: 54 | H4: 67 | I4: 73 | J4: 82 | K4: 93 | L4: 97 | M4: 105 | N4: 94 | O4: 80 | P4: 89 | Q4: 95 | R4: 114
A5: 12S | B5: 12 | C5: 14 | D5: 19 | E5: 31 | F5: 43 | G5: 60 | H5: 75 | I5: 91 | J5: 98 | K5: 108 | L5: 113 | M5: 119 | N5: 113 | O5: 110 | P5: 107 | Q5: 117 | R5: 109
A6: 13N | B6: 12 | C6: 15 | D6: 22 | E6: 34 | F6: 40 | G6: 47 | H6: 61 | I6: 68 | J6: 73 | K6: 76 | L6: 77 | M6: 85 | N6: 86 | O6: 91 | P6: 95 | Q6: 101 | R6: 109
A7: 13S | B7: 9 | C7: 12 | D7: 18 | E7: 25 | F7: 34 | G7: 48 | H7: 61 | I7: 74 | J7: 86 | K7: 97 | L7: 102 | M7: 109 | N7: 107 | O7: 106 | P7: 106 | Q7: 107 | R7: 108
A8: 14N | B8: 9 | C8: 13 | D8: 15 | E8: 25 | F8: 33 | G8: 47 | H8: 58 | I8: 74 | J8: 85 | K8: 92 | L8: 100 | M8: 107 | N8: 95 | O8: 96 | P8: 95 | Q8: 87 | R8: 88
A9: 14S | B9: 11 | C9: 13 | D9: 17 | E9: 28 | F9: 36 | G9: 49 | H9: 66 | I9: 79 | J9: 86 | K9: 98 | L9: 98 | M9: 105 | N9: 94 | O9: 98 | P9: 106 | Q9: 108 | R9: 114
A10: 21N | B10: 10 | C10: 12 | D10: 20 | E10: 29 | F10: 38 | G10: 53 | H10: 70 | I10: 85 | J10: 97 | K10: 106 | L10: 112 | M10: 120 | N10: 106 | O10: 107 | P10: 108 | Q10: 107 | R10: 104
A11: 21S | B11: 10 | C11: 13 | D11: 20 | E11: 29 | F11: 42 | G11: 59 | H11: 68 | I11: 86 | J11: 97 | K11: 102 | L11: 108 | M11: 116 | N11: 100 | O11: 102 | P11: 109 | Q11: 110 | R11: 108
A12: 22N | B12: 10 | C12: 14 | D12: 20 | E12: 30 | F12: 42 | G12: 62 | H12: 77 | I12: 95 | J12: 108 | K12: 119 | L12: 122 | M12: 127 | N12: 103 | O12: 111 | P12: 119 | Q12: 124 | R12: 127
A13: 22S | B13: 10 | C13: 13 | D13: 20 | E13: 29 | F13: 43 | G13: 54 | H13: 72 | I13: 89 | J13: 101 | K13: 107 | L13: 116 | M13: 120 | N13: 105 | O13: 111 | P13: 118 | Q13: 121 | R13: 126
... A49: 64S | B49: 10 | C49: 12 | D49: 19 | E49: 30 | F49: 39 | G49: 51 | H49: 58 | I49: 67 | J49: 69 | K49: 72 | L49: 72 | M49: 78 | N49: 76 | O49: 79 | P49: 83 | Q49: 70 | R49: 68

Sheet Width
A1: CCID | B1: DOY141 | C1: DOY148 | D1: DOY154 | E1: DOY162 | F1: DOY168 | G1: DOY176 | H1: DOY182 | I1: DOY189 | J1: DOY196 | K1: DOY203 | L1: DOY211 | M1: DOY217 | N1: DOY225 | O1: DOY232 | P1: DOY238 | Q1: DOY246 | R1: DOY259
A2: 11N | B2: 6 | C2: 9 | D2: 12 | E2: 21 | F2: 30 | G2: 37 | H2: 54 | I2: 72 | J2: 79 | K2: 83 | L2: 93 | M2: 102 | N2: 102 | O2: 102 | P2: 102 | Q2: 102 | R2: 102
A3: 11S | B3: 6 | C3: 11 | D3: 15 | E3: 27 | F3: 39 | G3: 47 | H3: 57 | I3: 66 | J3: 80 | K3: 94 | L3: 90 | M3: 99 | N3: 102 | O3: 102 | P3: 102 | Q3: 102 | R3: 102
A4: 12N | B4: 7 | C4: 11 | D4: 18 | E4: 23 | F4: 36 | G4: 50 | H4: 63 | I4: 67 | J4: 78 | K4: 86 | L4: 100 | M4: 102 | N4: 102 | O4: 102 | P4: 102 | Q4: 102 | R4: 102
A5: 12S | B5: 8 | C5: 9 | D5: 17 | E5: 29 | F5: 40 | G5: 54 | H5: 64 | I5: 80 | J5: 88 | K5: 89 | L5: 102 | M5: 102 | N5: 102 | O5: 102 | P5: 102 | Q5: 102 | R5: 102
A6: 13N | B6: 8 | C6: 12 | D6: 20 | E6: 32 | F6: 42 | G6: 46 | H6: 56 | I6: 62 | J6: 71 | K6: 73 | L6: 81 | M6: 95 | N6: 94 | O6: 102 | P6: 102 | Q6: 102 | R6: 102
A7: 13S | B7: 6 | C7: 9 | D7: 18 | E7: 26 | F7: 36 | G7: 48 | H7: 62 | I7: 71 | J7: 82 | K7: 92 | L7: 97 | M7: 102 | N7: 102 | O7: 102 | P7: 102 | Q7: 102 | R7: 102
A8: 14N | B8: 7 | C8: 9 | D8: 14 | E8: 25 | F8: 31 | G8: 44 | H8: 57 | I8: 65 | J8: 77 | K8: 83 | L8: 91 | M8: 102 | N8: 102 | O8: 102 | P8: 102 | Q8: 102 | R8: 102
A9: 14S | B9: 10 | C9: 10 | D9: 15 | E9: 25 | F9: 38 | G9: 51 | H9: 60 | I9: 67 | J9: 71 | K9: 80 | L9: 99 | M9: 102 | N9: 102 | O9: 102 | P9: 102 | Q9: 102 | R9: 102
A10: 21N | B10: 7 | C10: 10 | D10: 17 | E10: 27 | F10: 36 | G10: 50 | H10: 62 | I10: 75 | J10: 95 | K10: 101 | L10: 102 | M10: 102 | N10: 102 | O10: 102 | P10: 102 | Q10: 102 | R10: 102
A11: 21S | B11: 8 | C11: 10 | D11: 19 | E11: 28 | F11: 41 | G11: 58 | H11: 69 | I11: 75 | J11: 85 | K11: 89 | L11: 102 | M11: 102 | N11: 102 | O11: 102 | P11: 102 | Q11: 102 | R11: 102
A12: 22N | B12: 7 | C12: 11 | D12: 17 | E12: 28 | F12: 38 | G12: 56 | H12: 71 | I12: 78 | J12: 89 | K12: 96 | L12: 102 | M12: 102 | N12: 102 | O12: 102 | P12: 102 | Q12: 102 | R12: 102
A13: 22S | B13: 7 | C13: 10 | D13: 17 | E13: 29 | F13: 38 | G13: 50 | H13: 64 | I13: 71 | J13: 87 | K13: 93 | L13: 102 | M13: 102 | N13: 102 | O13: 102 | P13: 102 | Q13: 102 | R13: 102
... A49: 64S | B49: 7 | C49: 10 | D49: 16 | E49: 28 | F49: 39 | G49: 48 | H49: 52 | I49: 56 | J49: 60 | K49: 65 | L49: 69 | M49: 80 | N49: 85 | O49: 102 | P49: 102 | Q49: 102 | R49: 102

Sheet LAImeter
A1: CCID | B1: DOY142 | C1: DOY154 | D1: DOY155 | E1: DOY161 | F1: DOY168 | G1: DOY177 | H1: DOY183 | I1: DOY190
A2: 11M | B2: 0.06 | C2: 0.16 | E2: 0.51 | F2: 0.72 | G2: 1.11 | H2: 1.32 | I2: 1.74
A3: 12M | B3: 0.11 | C3: 0.43 | E3: 0.38 | F3: 0.67 | G3: 1 | H3: 1.19 | I3: 2.13
A4: 13M | B4: 0.07 | C4: 0.31 | E4: 0.55 | F4: 1.74 | G4: 0.75 | H4: 1.34 | I4: 2.14
A5: 14M | B5: 0.08 | C5: 0.35 | E5: 0.41 | F5: 0.96 | G5: 0.65 | H5: 1.08 | I5: 1.74
A6: 21M | B6: 0.07 | C6: 0.36 | E6: 0.69 | F6: 1.1 | G6: 1.11 | H6: 1.57 | I6: 2.95
A7: 22M | B7: 0.05 | C7: 0.43 | E7: 0.59 | F7: 1.19 | G7: 1.52 | H7: 1.69 | I7: 2.2
A8: 23M | B8: 0.04 | C8: 0.18 | E8: 0.88 | F8: 1.56 | G8: 0.84 | H8: 1.1 | I8: 1.55
A9: 24M | B9: 0 | C9: 0.56 | E9: 0.21 | F9: 0.6 | G9: 1.07 | H9: 1.4 | I9: 2.06
A10: 31M | B10: 0 | C10: 0.52 | D10: 0.36 | E10: 0.24 | F10: 0.82 | G10: 0.94 | H10: 1.3 | I10: 1.95
A11: 32M | B11: 0.09 | C11: 0.21 | D11: 0.29 | E11: 0.14 | F11: 0.23 | G11: 0.67 | H11: 1.23 | I11: 1.83
A12: 33M | B12: 0.06 | C12: 0.35 | D12: 0.41 | E12: 1.18 | F12: 0.82 | G12: 1.01 | H12: 1.99 | I12: 2.32
A13: 34M | B13: 0.08 | D13: 0.35 | E13: 0.81 | F13: 1.04 | G13: 0.81 | H13: 1.46 | I13: 1.97
A14: 41M | B14: 0 | D14: 0.48 | E14: 0.32 | F14: 0.58 | G14: 0.89 | H14: 1.43 | I14: 1.61
A15: 42M | B15: 0.04 | D15: 0 | E15: 0.07 | F15: 0.61 | G15: 0.8 | H15: 1.11 | I15: 1.72
A16: 43M | B16: 0.09 | D16: 0.51 | E16: 0.91 | F16: 1.71 | G16: 1.17 | H16: 2.05 | I16: 2.26
A17: 44M | B17: 0.03 | D17: 0.69 | E17: 0.43 | F17: 0.9 | G17: 0.75 | H17: 0.85 | I17: 0.97
A18: 51M | B18: 0.11 | D18: 0.57 | E18: 0.15 | F18: 0.77 | G18: 0.84 | H18: 1.79 | I18: 2.07
A19: 52M | B19: 0.15 | D19: 0.35 | E19: 0.61 | F19: 0.66 | G19: 1.41 | H19: 1.89 | I19: 2.84
A20: 53M | B20: 0.05 | D20: 0.33 | E20: 0.57 | F20: 0.82 | G20: 1.02 | H20: 1.66 | I20: 2.45
A21: 54M | B21: 0.03 | D21: 0.74 | E21: 0.44 | F21: 0.52 | G21: 0.76 | H21: 0.98 | I21: 0.83
A22: 61M | B22: 0 | D22: 0.1 | E22: 0.68 | F22: 0.42 | G22: 0.78 | H22: 1.27 | I22: 1.77
A23: 62M | B23: 0.08 | D23: 0.19 | E23: 0.17 | F23: 0.5 | G23: 0.74 | H23: 1.17 | I23: 1.34
A24: 63M | B24: 0.06 | D24: 0.52 | E24: 0.58 | F24: 0.93 | G24: 1.15 | H24: 1.3 | I24: 1.17
A25: 64M | B25: 0 | D25: 0.39 | E25: 0.3 | F25: 0.47 | G25: 0.86 | H25: 1.45 | I25: 1.78

Sheet Density
A1: CCID | B1: PLPD
A2: 11M | B2: 6.5616798
A3: 12M | B3: 6.7804024
A4: 13M | B4: 6.5616798
A5: 14M | B5: 7.2178478
A6: 21M | B6: 7.8740157
A7: 22M | B7: 6.1242345
A8: 23M | B8: 8.5301837
A9: 24M | B9: 7.4365704
A10: 31M | B10: 8.5301837
A11: 32M | B11: 7.6552931
A12: 33M | B12: 7.6552931
A13: 34M | B13: 7.2178478
... A25: 64M | B25: 7.4365704

Sheet Develop
A1: CCID | B1: EDATE | C1: PLYRE | D1: PLDOE | E1: LF1D | F1: ADAT | G1: ADOY | H1: NAWF176 | I1: NAWF182 | J1: NAWF189 | K1: NAWF196 | L1: NAWF203 | M1: NAWF211 | N1: NAWF217 | O1: NAWF225 | P1: NAWF232 | Q1: NAWF238 | R1: NAWF246 | S1: NAWF259
A2: 11N
A3: 11M | H3: 7 | I3: 8 | J3: 7.1666667 | K3: 5.6666667 | L3: 4.3333333 | M3: 3 | N3: 2.1666667 | O3: 1.8333333 | P3: 1.1666667 | Q3: 1 | R3: 0.66666667
A4: 11S
A5: 11E | B5: 43580 | C5: 2019 | D5: 115.4 | E5: 43590
A6: 12N | F6: 45837 | G6: 180.33333
A7: 12M | H7: 7.6 | I7: 7.5 | J7: 5 | K7: 4.3333333 | L7: 3.5 | M7: 2.5 | N7: 1.3333333 | O7: 2.6666667 | P7: 2 | Q7: 1.3333333 | R7: 1.25 | S7: 1.6666667
A8: 12S | F8: 43647 | G8: 182
A9: 12E | B9: 43580 | C9: 2019 | D9: 115.25 | E9: 43591
A10: 13N | F10: 45837 | G10: 180.33333
A11: 13M | H11: 7 | I11: 6.1666667 | J11: 5 | K11: 4.1666667 | L11: 3.1666667 | M11: 2.5 | N11: 1.5 | O11: 1.1666667 | P11: 1 | Q11: 0.5 | R11: 0.75 | S11: 0.5
A12: 13S | F12: 43646 | G12: 181
A13: 13E | B13: 43579 | C13: 2019 | D13: 114.33333 | E13: 43590
A14: 14N | F14: 43646 | G14: 181
A15: 14M | I15: 7.3333333 | J15: 6 | K15: 5.1666667 | L15: 4.1666667 | M15: 2.5 | N15: 1.8333333 | O15: 1.6666667 | P15: 1 | Q15: 0.66666667 | R15: 0.25 | S15: 1
A16: 14S | F16: 45837 | G16: 180
A17: 14E | B17: 43580 | C17: 2019 | D17: 114.75 | E17: 43591
A18: 21N | F18: 43646 | G18: 180.75
A19: 21M | H19: 8 | I19: 8 | J19: 5.8333333 | K19: 4.8333333 | L19: 3.3333333 | M19: 2.8333333 | N19: 2.5 | O19: 2 | P19: 1 | Q19: 0.83333333 | R19: 0.33333333 | S19: 2
A20: 21S | F20: 43647 | G20: 182
A21: 21E | B21: 43580 | C21: 2019 | D21: 114.5 | E21: 43591
A22: 22N | F22: 43644 | G22: 178.66667
A23: 22M | H23: 8.5 | I23: 8.5 | J23: 6.1666667 | K23: 5.3333333 | L23: 3.8333333 | M23: 3.1666667 | N23: 2.1666667 | O23: 1.8333333 | P23: 0.83333333 | Q23: 0.5 | R23: 0.33333333
A24: 22S | F24: 43644 | G24: 178.66667
A25: 22E | B25: 43580 | C25: 2019 | D25: 115.375 | E25: 43591
A26: 23N | F26: 45837 | G26: 179.5
A27: 23M | H27: 8.75 | I27: 7.5 | J27: 5.8333333 | K27: 4.3333333 | L27: 3.1666667 | M27: 2 | N27: 0.83333333 | O27: 1.5 | P27: 1 | Q27: 0.6 | R27: 0.33333333 | S27: 1
A28: 23S | F28: 45837 | G28: 179.5
A29: 23E | B29: 43580 | C29: 2019 | D29: 114.83333 | E29: 43594
A30: 24N | F30: 43643 | G30: 178.25
A31: 24M | H31: 8.25 | I31: 8 | J31: 6.5 | K31: 5.3333333 | L31: 2.6666667 | M31: 1.8333333 | N31: 0.83333333 | O31: 2.5 | P31: 2 | Q31: 1.3333333 | R31: 0.66666667 | S31: 1.5
A32: 24S | F32: 45837 | G32: 180
A33: 24E | B33: 43580 | C33: 2019 | D33: 115.2 | E33: 43591
A34: 31N | F34: 45837 | G34: 180.33333
A35: 31M | I35: 7.8333333 | J35: 7.5 | K35: 5.6666667 | L35: 5 | M35: 3.5 | N35: 2.6666667 | O35: 2.8333333 | P35: 2 | Q35: 1.3333333 | R35: 0.83333333
A36: 31S | F36: 43646 | G36: 180.75
A37: 31E | B37: 43580 | C37: 2019 | D37: 115.375 | E37: 43591
A38: 32N | F38: 43647 | G38: 182
A39: 32M | H39: 8.5 | I39: 7.5 | J39: 7.1666667 | K39: 4.8333333 | L39: 5 | M39: 3.5 | N39: 2.5 | O39: 2.5 | P39: 1.8333333 | Q39: 1.3333333 | R39: 0.83333333
A40: 32S | F40: 43646 | G40: 181.16667
...

Sheet Ordering
A1: 1 | B1: 1 | C1: N | D1: =_xlfn.CONCAT("p",TEXT(A1,"00"),"-",TEXT(B1,"0"),C1) -> p01-1N
A2: 1 | B2: 1 | C2: S | D2: =_xlfn.CONCAT("p",TEXT(A2,"00"),"-",TEXT(B2,"0"),C2) -> p01-1S
A3: 1 | B3: 2 | C3: N | D3: =_xlfn.CONCAT("p",TEXT(A3,"00"),"-",TEXT(B3,"0"),C3) -> p01-2N
A4: 1 | B4: 2 | C4: S | D4: =_xlfn.CONCAT("p",TEXT(A4,"00"),"-",TEXT(B4,"0"),C4) -> p01-2S
A5: 1 | B5: 3 | C5: N | D5: =_xlfn.CONCAT("p",TEXT(A5,"00"),"-",TEXT(B5,"0"),C5) -> p01-3N
A6: 1 | B6: 3 | C6: S | D6: =_xlfn.CONCAT("p",TEXT(A6,"00"),"-",TEXT(B6,"0"),C6) -> p01-3S
A7: 1 | B7: 4 | C7: N | D7: =_xlfn.CONCAT("p",TEXT(A7,"00"),"-",TEXT(B7,"0"),C7) -> p01-4N
A8: 1 | B8: 4 | C8: S | D8: =_xlfn.CONCAT("p",TEXT(A8,"00"),"-",TEXT(B8,"0"),C8) -> p01-4S
A9: 2 | B9: 4 | C9: S | D9: =_xlfn.CONCAT("p",TEXT(A9,"00"),"-",TEXT(B9,"0"),C9) -> p02-4S
A10: 2 | B10: 4 | C10: N | D10: =_xlfn.CONCAT("p",TEXT(A10,"00"),"-",TEXT(B10,"0"),C10) -> p02-4N
A11: 2 | B11: 3 | C11: S | D11: =_xlfn.CONCAT("p",TEXT(A11,"00"),"-",TEXT(B11,"0"),C11) -> p02-3S
A12: 2 | B12: 3 | C12: N | D12: =_xlfn.CONCAT("p",TEXT(A12,"00"),"-",TEXT(B12,"0"),C12) -> p02-3N
... A48: 6 | B48: 1 | C48: N | D48: =_xlfn.CONCAT("p",TEXT(A48,"00"),"-",TEXT(B48,"0"),C48) -> p06-1N

Sheet Blank Data Sheet
A1: 2019 | C1: F13b4 | E1: Cotton | F1: date: | J1: doy:
F2: time:
B3: Canopy Heights & Widths | F3: by:
B5: Canopy Heights flags are Pink and in row 11. Two measurements per plot.
B6: Canopy Measurement points are separate from the LAI measurement point.
B7: Canopy Height & LAI flags may not be exactly at the GPS points - I adjusted depending on skips in rows. SMM
B8: Plot | D8: Flag | E8: Canopy Height (cm) | F8: Canopy Width (cm) | G8: NAWF | H8: NAWF | I8: NAWF
B9: 01- | C9: 1 | D9: North
D10: South
B11: 01- | C11: 2 | D11: North
D12: South
B13: 01- | C13: 3 | D13: North
D14: South
B15: 01- | C15: 4 | D15: North
D16: South
B17: 02- | C17: 4 | D17: South
D18: North
B19: 02- | C19: 3 | D19: South
D20: North
B21: 02- | C21: 2 | D21: South
D22: North
B23: 02- | C23: 1 | D23: South
D24: North
B25: 03- | C25: 1 | D25: North
D26: South
B27: 03- | C27: 2 | D27: North
D28: South
B29: 03- | C29: 3 | D29: North
D30: South
B31: 03- | C31: 4 | D31: North
D32: South
B33: 04- | C33: 4 | D33: South
D34: North
B35: 04- | C35: 3 | D35: South
D36: North
B37: 04- | C37: 2 | D37: South
D38: North
B39: 04- | C39: 1 | D39: South
D40: North
B41: 05- | C41: 1 | D41: North
...

Sheet Height Summary
A1: Summary | B1: 2019 | D1: F13b4 | F1: Cotton
B3: Canopy Heights - Summary
I7: VRI trt began 7 June 2019
D8: Initials: | F8: SMM | G8: SMM | H8: SMM | I8: SMM | J8: SMM | K8: SMM | L8: SMM | M8: SMM | N8: SMM | O8: SMM | P8: SMM | Q8: SMM | R8: SMM | S8: SMM | T8: SMM | U8: SMM | V8: SMM
D9: Date: | F9: 43606 | G9: 43613 | H9: 43619 | I9: 43627 | J9: 43633 | K9: 43641 | L9: 43647 | M9: 43654 | N9: 43661 | O9: 43668 | P9: 43676 | Q9: 43682 | R9: 43690 | S9: 43697 | T9: 43703 | U9: 43711 | V9: 43724
D10: DOY: | F10: 141 | G10: 148 | H10: 154 | I10: 162 | J10: 168 | K10: 176 | L10: 182 | M10: 189 | N10: 196 | O10: 203 | P10: 211 | Q10: 217 | R10: d225 | S10: d232 | T10: d238 | U10: d246 | V10: d259
D11: Time: | F11: 1000-1025h | G11: 1020-1055h | H11: 0915-1015h | I11: 1050-1115h | J11: 1035-1110h | K11: 1140-1240h | L11: 1000-1140h | M11: 1005-1105h | N11: 0945-1050h | O11: 0930-1030h | P11: 0915-1040h | Q11: 0930-1030h | R11: 0920-1105h | S11: 0900-1030h | T11: 1015-1215h | U11: 0930-1110h | V11: 1015-1200h
B12: Plot | D12: Flag | E12: TRT | F12: Height (cm) | G12: Height (cm) | H12: Height (cm) | I12: Height (cm) | J12: Height (cm) | K12: Height (cm) | L12: Height (cm) | M12: Height (cm) | N12: Height (cm) | O12: Height (cm) | P12: Height (cm) | Q12: Height (cm) | R12: Height (cm) | S12: Height (cm) | T12: Height (cm) | U12: Height (cm) | V12: Height (cm)
B13: 01- | C13: 1 | D13: North | E13: DRN | F13: 10 | G13: 14 | H13: 15 | I13: 23 | J13: 32 | K13: 38 | L13: 56 | M13: 71 | N13: 83 | O13: 91 | P13: 104 | Q13: 113 | R13: 109 | S13: 111 | T13: 109 | U13: 107 | V13: 101
D14: South | E14: DRN | F14: 10 | G14: 15 | H14: 18 | I14: 31 | J14: 44 | K14: 53 | L14: 64 | M14: 73 | N14: 84 | O14: 96 | P14: 94 | Q14: 102 | R14: 98 | S14: 100 | T14: 102 | U14: 104 | V14: 109
B15: 01- | C15: 2 | D15: North | E15: VRI | F15: 11 | G15: 14 | H15: 19 | I15: 27 | J15: 41 | K15: 54 | L15: 67 | M15: 73 | N15: 82 | O15: 93 | P15: 97 | Q15: 105 | R15: 94 | S15: 80 | T15: 89 | U15: 95 | V15: 114
D16: South | E16: VRI | F16: 12 | G16: 14 | H16: 19 | I16: 31 | J16: 43 | K16: 60 | L16: 75 | M16: 91 | N16: 98 | O16: 108 | P16: 113 | Q16: 119 | R16: 113 | S16: 110 | T16: 107 | U16: 117 | V16: 109
B17: 01- | C17: 3 | D17: North | E17: DRN | F17: 12 | G17: 15 | H17: 22 | I17: 34 | J17: 40 | K17: 47 | L17: 61 | M17: 68 | N17: 73 | O17: 76 | P17: 77 | Q17: 85 | R17: 86 | S17: 91 | T17: 95 | U17: 101 | V17: 109
D18: South | E18: DRN | F18: 9 | G18: 12 | H18: 18 | I18: 25 | J18: 34 | K18: 48 | L18: 61 | M18: 74 | N18: 86 | O18: 97 | P18: 102 | Q18: 109 | R18: 107 | S18: 106 | T18: 106 | U18: 107 | V18: 108
B19: 01- | C19: 4 | D19: North | E19: SOL | F19: 9 | G19: 13 | H19: 15 | I19: 25 | J19: 33 | K19: 47 | L19: 58 | M19: 74 | N19: 85 | O19: 92 | P19: 100 | Q19: 107 | R19: 95 | S19: 96 | T19: 95 | U19: 87 | V19: 88
D20: South | E20: SOL | F20: 11 | G20: 13 | H20: 17 | I20: 28 | J20: 36 | K20: 49 | L20: 66 | M20: 79 | N20: 86 | O20: 98 | P20: 98 | Q20: 105 | R20: 94 | S20: 98 | T20: 106 | U20: 108 | V20: 114
B21: 02- | C21: 4 | D21: South | E21: MDL | F21: 10 | G21: 12 | H21: 18 | I21: 29 | J21: 37 | K21: 53 | L21: 67 | M21: 77 | N21: 83 | O21: 87 | P21: 89 | Q21: 94 | R21: 87 | S21: 94 | T21: 98 | U21: 108 | V21: 110
D22: North | E22: MDL | F22: 11 | G22: 14 | H22: 20 | I22: 32 | J22: 41 | K22: 58 | L22: 68 | M22: 80 | N22: 88 | O22: 94 | P22: 97 | Q22: 103 | R22: 90 | S22: 96 | T22: 99 | U22: 111 | V22: 114
B23: 02- | C23: 3 | D23: South | E23: VRI | F23: 10 | G23: 12 | H23: 18 | I23: 27 | J23: 35 | K23: 47 | L23: 59 | M23: 69 | N23: 75 | O23: 78 | P23: 86 | Q23: 91 | R23: 87 | S23: 95 | T23: 101 | U23: 109 | V23: 115
D24: North | E24: VRI | F24: 9 | G24: 14 | H24: 20 | I24: 29 | J24: 40 | K24: 61 | L24: 70 | M24: 90 | N24: 101 | O24: 107 | P24: 102 | Q24: 110 | R24: 102 | S24: 107 | T24: 114 | U24: 120 | V24: 125
B25: 02- | C25: 2 | D25: South | E25: SOL | F25: 10 | G25: 13 | H25: 20 | I25: 29 | J25: 43 | K25: 54 | L25: 72 | M25: 89 | N25: 101 | O25: 107 | P25: 116 | Q25: 120 | R25: 105 | S25: 111 | T25: 118 | U25: 121 | V25: 126
D26: North | E26: SOL | F26: 10 | G26: 14 | H26: 20 | I26: 30 | J26: 42 | K26: 62 | L26: 77 | M26: 95 | N26: 108 | O26: 119 | P26: 122 | Q26: 127 | R26: 103 | S26: 111 | T26: 119 | U26: 124 | V26: 127
B27: 02- | C27: 1 | D27: South | E27: MDL | F27: 10 | G27: 13 | H27: 20 | I27: 29 | J27: 42 | K27: 59 | L27: 68 | M27: 86 | N27: 97 | O27: 102 | P27: 108 | Q27: 116 | R27: 100 | S27: 102 | T27: 109 | U27: 110 | V27: 108
D28: North | E28: MDL | F28: 10 | G28: 12 | H28: 20 | I28: 29 | J28: 38 | K28: 53 | L28: 70 | M28: 85 | N28: 97 | O28: 106 | P28: 112 | Q28: 120 | R28: 106 | S28: 107 | T28: 108 | U28: 107 | V28: 104
B29: 03- | C29: 1 | D29: North | E29: MDL | F29: 9 | G29: 13 | H29: 19 | I29: 27 | J29: 34 | K29: 53 | L29: 61 | M29: 78 | N29: 93 | O29: 106 | P29: 116 | Q29: 121 | R29: 113 | S29: 112 | T29: 110 | U29: 111 | V29: 111
D30: South | E30: MDL | F30: 11 | G30: 12 | H30: 17 | I30: 24 | J30: 32 | K30: 45 | L30: 61 | M30: 77 | N30: 91 | O30: 98 | P30: 108 | Q30: 114 | R30: 105 | S30: 107 | T30: 109 | U30: 97 | V30: 99
B31: 03- | C31: 2 | D31: North | E31: SOL | F31: 10 | G31: 12 | H31: 17 | I31: 25 | J31: 32 | K31: 43 | L31: 56 | M31: 71 | N31: 87 | O31: 96 | P31: 107 | Q31: 114 | R31: 112 | S31: 111 | T31: 112 | U31: 111 | V31: 113
D32: South | E32: SOL | F32: 10 | G32: 15 | H32: 25 | I32: 35 | J32: 49 | K32: 64 | L32: 82 | M32: 93 | N32: 107 | O32: 117 | P32: 118 | Q32: 123 | R32: 113 | S32: 116 | T32: 120 | U32: 119 | V32: 118
B33: 03- | C33: 3 | D33: North | E33: DRN | F33: 10 | G33: 15 | H33: 19 | I33: 32 | J33: 41 | K33: 56 | L33: 74 | M33: 78 | N33: 89 | O33: 97 | P33: 105 | Q33: 113 | R33: 99 | S33: 105 | T33: 111 | U33: 118 | V33: 123
D34: South | E34: DRN | F34: 10 | G34: 14 | H34: 18 | I34: 28 | J34: 36 | K34: 47 | L34: 62 | M34: 76 | N34: 87 | O34: 92 | P34: 93 | Q34: 100 | R34: 97 | S34: 100 | T34: 106 | U34: 110 | V34: 117
B35: 03- | C35: 4 | D35: North | E35: SOL | F35: 10 | G35: 14 | H35: 23 | I35: 38 | J35: 46 | K35: 62 | L35: 77 | M35: 91 | N35: 102 | O35: 109 | P35: 106 | Q35: 118 | R35: 96 | S35: 100 | T35: 105 | U35: 113 | V35: 121
D36: South | E36: SOL | F36: 11 | G36: 14 | H36: 19 | I36: 31 | J36: 41 | K36: 56 | L36: 69 | M36: 83 | N36: 92 | O36: 100 | P36: 109 | Q36: 121 | R36: 102 | S36: 107 | T36: 106 | U36: 107 | V36: 109
B37: 04- | C37: 4 | D37: South | E37: VRI | F37: 11 | G37: 15 | H37: 18 | I37: 33 | J37: 44 | K37: 61 | L37: 74 | M37: 82 | N37: 88 | O37: 92 | P37: 95 | Q37: 101 | R37: 89 | S37: 95 | T37: 101 | U37: 108 | V37: 115
D38: North | E38: VRI | F38: 11 | G38: 14 | H38: 20 | I38: 33 | J38: 40 | K38: 52 | L38: 65 | M38: 76 | N38: 85 | O38: 89 | P38: 87 | Q38: 95 | R38: 85 | S38: 89 | T38: 94 | U38: 95 | V38: 88
B39: 04- | C39: 3 | D39: South | E39: MDL | F39: 11 | G39: 14 | H39: 23 | I39: 34 | J39: 46 | K39: 58 | L39: 64 | M39: 78 | N39: 87 | O39: 95 | P39: 93 | Q39: 100 | R39: 91 | S39: 97 | T39: 100 | U39: 101 | V39: 104
D40: North | E40: MDL | F40: 12 | G40: 16 | H40: 25 | I40: 38 | J40: 51 | K40: 73 | L40: 86 | M40: 101 | N40: 105 | O40: 109 | P40: 105 | Q40: 111 | R40: 84 | S40: 90 | T40: 98 | U40: 106 | V40: 114
B41: 04- | C41: 2 | D41: South | E41: VRI | F41: 11 | G41: 14 | H41: 21 | I41: 29 | J41: 35 | K41: 51 | L41: 65 | M41: 81 | N41: 90 | O41: 98 | P41: 96 | Q41: 101 | R41: 83 | S41: 90 | T41: 93 | U41: 97 | V41: 102
D42: North | E42: VRI | F42: 10 | G42: 12 | H42: 20 | I42: 27 | J42: 37 | K42: 51 | L42: 66 | M42: 82 | N42: 88 | O42: 96 | P42: 107 | Q42: 115 | R42: 98 | S42: 106 | T42: 108 | U42: 110 | V42: 111
B43: 04- | C43: 1 | D43: South | E43: DRN | F43: 12 | G43: 15 | H43: 19 | I43: 31 | J43: 40 | K43: 57 | L43: 71 | M43: 83 | N43: 89 | O43: 96 | P43: 97 | Q43: 105 | R43: 94 | S43: 96 | T43: 100 | U43: 106 | V43: 111
D44: North | E44: DRN | F44: 12 | G44: 14 | H44: 21 | I44: 34 | J44: 42 | K44: 58 | L44: 70 | M44: 83 | N44: 89 | O44: 95 | P44: 94 | Q44: 101 | R44: 96 | S44: 99 | T44: 102 | U44: 103 | V44: 101
...

Sheet Cover Summary
A1: Summary | B1: 2019 | D1: F13b4 | F1: Cotton
B3: Canopy Heights - Summary | H3: "--" = closed canopy
I7: VRI trt began 7 June 2019
D8: Initials: | F8: SMM | G8: SMM | H8: SMM | I8: SMM | J8: SMM | K8: SMM | L8: SMM | M8: SMM | N8: SMM | O8: SMM | P8: SMM | Q8: SMM | R8: SMM | S8: SMM | T8: SMM | U8: SMM | V8: SMM
D9: Date: | F9: 43606 | G9: 43613 | H9: 43619 | I9: 43627 | J9: 43633 | K9: 43641 | L9: 43647 | M9: 43654 | N9: 43661 | O9: 43668 | P9: 43676 | Q9: 43682 | R9: 43690 | S9: 43697 | T9: 43703 | U9: 43711 | V9: 43724
D10: DOY: | F10: 141 | G10: 148 | H10: 154 | I10: 162 | J10: 168 | K10: 176 | L10: 182 | M10: 189 | N10: 196 | O10: 203 | P10: 211 | Q10: 217 | R10: d225 | S10: d232 | T10: d238 | U10: d246 | V10: d259
D11: Time: | F11: 1000-1025h | G11: 1020-1055h | H11: 0915-1015h | I11: 1050-1115h | J11: 1035-1110h | K11: 1140-1240h | L11: 1000-1140h | M11: 1005-1105h | N11: 0945-1050h | O11: 0930-1030h | P11: 0915-1040h | Q11: 0930-1030h | R11: 0920-1105h | S11: 0900-1030h | T11: 1015-1215h | U11: 0930-1110h | V11: 1015-1200h
B12: Plot | D12: Flag | E12: TRT | F12: Canopy Width (cm) | G12: Canopy Width (cm) | H12: Canopy Width (cm) | I12: Canopy Width (cm) | J12: Canopy Width (cm) | K12: Canopy Width (cm) | L12: Canopy Width (cm) | M12: Canopy Width (cm) | N12: Canopy Width (cm) | O12: Canopy Width (cm) | P12: Canopy Width (cm) | Q12: Height (cm) | R12: Canopy Width (cm) | S12: Canopy Width (cm) | T12: Canopy Width (cm) | U12: Canopy Width (cm) | V12: Canopy Width (cm)
B13: 01- | C13: 1 | D13: North | E13: DRN | F13: 6 | G13: 9 | H13: 12 | I13: 21 | J13: 30 | K13: 37 | L13: 54 | M13: 72 | N13: 79 | O13: 83 | P13: 93 | Q13: -- | R13: -- | S13: -- | T13: -- | U13: -- | V13: --
D14: South | E14: DRN | F14: 6 | G14: 11 | H14: 15 | I14: 27 | J14: 39 | K14: 47 | L14: 57 | M14: 66 | N14: 80 | O14: 94 | P14: 90 | Q14: 99 | R14: -- | S14: -- | T14: -- | U14: -- | V14: --
B15: 01- | C15: 2 | D15: North | E15: VRI | F15: 7 | G15: 11 | H15: 18 | I15: 23 | J15: 36 | K15: 50 | L15: 63 | M15: 67 | N15: 78 | O15: 86 | P15: 100 | Q15: -- | R15: -- | S15: -- | T15: -- | U15: -- | V15: --
D16: South | E16: VRI | F16: 8 | G16: 9 | H16: 17 | I16: 29 | J16: 40 | K16: 54 | L16: 64 | M16: 80 | N16: 88 | O16: 89 | P16: -- | Q16: -- | R16: -- | S16: -- | T16: -- | U16: -- | V16: --
B17: 01- | C17: 3 | D17: North | E17: DRN | F17: 8 | G17: 12 | H17: 20 | I17: 32 | J17: 42 | K17: 46 | L17: 56 | M17: 62 | N17: 71 | O17: 73 | P17: 81 | Q17: 95 | R17: 94 | S17: -- | T17: -- | U17: -- | V17: --
D18: South | E18: DRN | F18: 6 | G18: 9 | H18: 18 | I18: 26 | J18: 36 | K18: 48 | L18: 62 | M18: 71 | N18: 82 | O18: 92 | P18: 97 | Q18: -- | R18: -- | S18: -- | T18: -- | U18: -- | V18: --
B19: 01- | C19: 4 | D19: North | E19: SOL | F19: 7 | G19: 9 | H19: 14 | I19: 25 | J19: 31 | K19: 44 | L19: 57 | M19: 65 | N19: 77 | O19: 83 | P19: 91 | Q19: -- | R19: -- | S19: -- | T19: -- | U19: -- | V19: --
D20: South | E20: SOL | F20: 10 | G20: 10 | H20: 15 | I20: 25 | J20: 38 | K20: 51 | L20: 60 | M20: 67 | N20: 71 | O20: 80 | P20: 99 | Q20: -- | R20: -- | S20: -- | T20: -- | U20: -- | V20: --
B21: 02- | C21: 4 | D21: South | E21: MDL | F21: 6 | G21: 8 | H21: 15 | I21: 26 | J21: 37 | K21: 50 | L21: 65 | M21: 79 | N21: 82 | O21: 88 | P21: -- | Q21: -- | R21: -- | S21: -- | T21: -- | U21: -- | V21: --
D22: North | E22: MDL | F22: 9 | G22: 12 | H22: 18 | I22: 28 | J22: 40 | K22: 52 | L22: 63 | M22: 67 | N22: 78 | O22: 81 | P22: 92 | Q22: -- | R22: -- | S22: -- | T22: -- | U22: -- | V22: --
B23: 02- | C23: 3 | D23: South | E23: VRI | F23: 8 | G23: 10 | H23: 17 | I23: 26 | J23: 34 | K23: 43 | L23: 55 | M23: 66 | N23: 71 | O23: 75 | P23: 81 | Q23: 95 | R23: 93 | S23: -- | T23: -- | U23: -- | V23: --
D24: North | E24: VRI | F24: 7 | G24: 11 | H24: 18 | I24: 30 | J24: 37 | K24: 54 | L24: 64 | M24: 72 | N24: 89 | O24: 94 | P24: -- | Q24: -- | R24: -- | S24: -- | T24: -- | U24: -- | V24: --
B25: 02- | C25: 2 | D25: South | E25: SOL | F25: 7 | G25: 10 | H25: 17 | I25: 29 | J25: 38 | K25: 50 | L25: 64 | M25: 71 | N25: 87 | O25: 93 | P25: -- | Q25: -- | R25: -- | S25: -- | T25: -- | U25: -- | V25: --
D26: North | E26: SOL | F26: 7 | G26: 11 | H26: 17 | I26: 28 | J26: 38 | K26: 56 | L26: 71 | M26: 78 | N26: 89 | O26: 96 | P26: -- | Q26: -- | R26: -- | S26: -- | T26: -- | U26: -- | V26: --
B27: 02- | C27: 1 | D27: South | E27: MDL | F27: 8 | G27: 10 | H27: 19 | I27: 28 | J27: 41 | K27: 58 | L27: 69 | M27: 75 | N27: 85 | O27: 89 | P27: -- | Q27: -- | R27: -- | S27: -- | T27: -- | U27: -- | V27: --
D28: North | E28: MDL | F28: 7 | G28: 10 | H28: 17 | I28: 27 | J28: 36 | K28: 50 | L28: 62 | M28: 75 | N28: 95 | O28: 101 | P28: -- | Q28: -- | R28: -- | S28: -- | T28: -- | U28: -- | V28: --
B29: 03- | C29: 1 | D29: North | E29: MDL | F29: 6 | G29: 10 | H29: 18 | I29: 26 | J29: 31 | K29: 54 | L29: 59 | M29: 70 | N29: 84 | O29: 93 | P29: -- | Q29: -- | R29: -- | S29: -- | T29: -- | U29: -- | V29: --
D30: South | E30: MDL | F30: 10 | G30: 9 | H30: 14 | I30: 23 | J30: 30 | K30: 44 | L30: 57 | M30: 71 | N30: 85 | O30: 92 | P30: 100 | Q30: -- | R30: -- | S30: -- | T30: -- | U30: -- | V30: --
B31: 03- | C31: 2 | D31: North | E31: SOL | F31: 6 | G31: 8 | H31: 13 | I31: 22 | J31: 31 | K31: 40 | L31: 56 | M31: 67 | N31: 79 | O31: 85 | P31: 100 | Q31: -- | R31: -- | S31: -- | T31: -- | U31: -- | V31: --
D32: South | E32: SOL | F32: 7 | G32: 12 | H32: 22 | I32: 31 | J32: 45 | K32: 57 | L32: 75 | M32: 84 | N32: 92 | O32: 97 | P32: -- | Q32: -- | R32: -- | S32: -- | T32: -- | U32: -- | V32: --
B33: 03- | C33: 3 | D33: North | E33: DRN | F33: 7 | G33: 10 | H33: 17 | I33: 28 | J33: 38 | K33: 52 | L33: 62 | M33: 64 | N33: 76 | O33: 87 | P33: 98 | Q33: -- | R33: -- | S33: -- | T33: -- | U33: -- | V33: --
D34: South | E34: DRN | F34: 7 | G34: 10 | H34: 15 | I34: 24 | J34: 34 | K34: 44 | L34: 56 | M34: 74 | N34: 84 | O34: 90 | P34: 95 | Q34: -- | R34: -- | S34: -- | T34: -- | U34: -- | V34: --
B35: 03- | C35: 4 | D35: North | E35: SOL | F35: 7 | G35: 12 | H35: 22 | I35: 34 | J35: 44 | K35: 60 | L35: 71 | M35: 76 | N35: 90 | O35: 97 | P35: -- | Q35: -- | R35: -- | S35: -- | T35: -- | U35: -- | V35: --
D36: South | E36: SOL | F36: 8 | G36: 12 | H36: 17 | I36: 29 | J36: 40 | K36: 57 | L36: 66 | M36: 76 | N36: 98 | O36: 95 | P36: -- | Q36: -- | R36: -- | S36: -- | T36: -- | U36: -- | V36: --
B37: 04- | C37: 4 | D37: South | E37: VRI | F37: 9 | G37: 12 | H37: 18 | I37: 29 | J37: 44 | K37: 57 | L37: 65 | M37: 74 | N37: 79 | O37: 88 | P37: 97 | Q37: -- | R37: -- | S37: -- | T37: -- | U37: -- | V37: --
D38: North | E38: VRI | F38: 8 | G38: 11 | H38: 18 | I38: 30 | J38: 37 | K38: 46 | L38: 57 | M38: 62 | N38: 69 | O38: 72 | P38: 80 | Q38: 98 | R38: -- | S38: -- | T38: -- | U38: -- | V38: --
B39: 04- | C39: 3 | D39: South | E39: MDL | F39: 10 | G39: 12 | H39: 22 | I39: 29 | J39: 39 | K39: 49 | L39: 56 | M39: 61 | N39: 69 | O39: 71 | P39: 79 | Q39: 87 | R39: -- | S39: -- | T39: -- | U39: -- | V39: --
D40: North | E40: MDL | F40: 10 | G40: 13 | H40: 23 | I40: 34 | J40: 46 | K40: 62 | L40: 73 | M40: 81 | N40: 91 | O40: 97 | P40: -- | Q40: -- | R40: -- | S40: -- | T40: -- | U40: -- | V40: --
B41: 04- | C41: 2 | D41: South | E41: VRI | F41: 7 | G41: 10 | H41: 16 | I41: 28 | J41: 36 | K41: 47 | L41: 58 | M41: 64 | N41: 72 | O41: 80 | P41: 91 | Q41: -- | R41: -- | S41: -- | T41: -- | U41: -- | V41: --
D42: North | E42: VRI | F42: 8 | G42: 10 | H42: 19 | I42: 24 | J42: 35 | K42: 50 | L42: 63 | M42: 73 | N42: 80 | O42: 89 | P42: -- | Q42: -- | R42: -- | S42: -- | T42: -- | U42: -- | V42: --
B43: 04- | C43: 1 | D43: South | E43: DRN | F43: 10 | G43: 11 | H43: 18 | I43: 26 | J43: 38 | K43: 46 | L43: 63 | M43: 72 | N43: 77 | O43: 83 | P43: 94 | Q43: -- | R43: -- | S43: -- | T43: -- | U43: -- | V43: --
D44: North | E44: DRN | F44: 9 | G44: 12 | H44: 19 | I44: 30 | J44: 40 | K44: 51 | L44: 61 | M44: 69 | N44: 73 | O44: 74 | P44: 97 | Q44: -- | R44: -- | S44: -- | T44: -- | U44: -- | V44: --
...

Sheet Averages
A1: Averages by treatments
C3: Average Canopy Heights
C5: ='Height Summary'!F9 -> 43606 | D5: ='Height Summary'!G9 -> 43613 | E5: ='Height Summary'!H9 -> 43619 | F5: ='Height Summary'!I9 -> 43627 | G5: ='Height Summary'!J9 -> 43633 | H5: ='Height Summary'!K9 -> 43641 | I5: ='Height Summary'!L9 -> 43647 | J5: ='Height Summary'!M9 -> 43654 | ... L5: ='Height Summary'!O9 -> 43668 | M5: ='Height Summary'!R9 -> 43690 | N5: ='Height Summary'!S9 -> 43697 | O5: ='Height Summary'!T9 -> 43703 | P5: ='Height Summary'!U9 -> 43711 | Q5: ='Height Summary'!V9 -> 43724
C6: ='Height Summary'!F10 -> 141 | D6: ='Height Summary'!G10 -> 148 | E6: ='Height Summary'!H10 -> 154 | F6: ='Height Summary'!I10 -> 162 | G6: ='Height Summary'!J10 -> 168 | H6: ='Height Summary'!K10 -> 176 | I6: ='Height Summary'!L10 -> 182 | J6: ='Height Summary'!M10 -> 189 | ... L6: ='Height Summary'!O10 -> 203 | M6: ='Height Summary'!R10 -> d225 | N6: ='Height Summary'!S10 -> d232 | O6: ='Height Summary'!T10 -> d238 | P6: ='Height Summary'!U10 -> d246 | Q6: ='Height Summary'!V10 -> d259
B7: Ave of all MDL: | C7: =AVERAGEIFS('Height Summary'!F$13:F$60,'Height Summary'!$E$13:$E$60, "MDL") -> 10.333333 | D7: =AVERAGEIFS('Height Summary'!G$13:G$60,'Height Summary'!$E$13:$E$60, "MDL") -> 13.333333 | E7: =AVERAGEIFS('Height Summary'!H$13:H$60,'Height Summary'!$E$13:$E$60, "MDL") -> 20.25 | F7: =AVERAGEIFS('Height Summary'!I$13:I$60,'Height Summary'!$E$13:$E$60, "MDL") -> 30.833333 | G7: =AVERAGEIFS('Height Summary'!J$13:J$60,'Height Summary'!$E$13:$E$60, "MDL") -> 40.333333 | H7: =AVERAGEIFS('Height Summary'!K$13:K$60,'Height Summary'!$E$13:$E$60, "MDL") -> 56.916667 | I7: =AVERAGEIFS('Height Summary'!L$13:L$60,'Height Summary'!$E$13:$E$60, "MDL") -> 68.75 | J7: =AVERAGEIFS('Height Summary'!M$13:M$60,'Height Summary'!$E$13:$E$60, "MDL") -> 83.083333 | ... L7: =AVERAGEIFS('Height Summary'!O$13:O$60,'Height Summary'!$E$13:$E$60, "MDL") -> 100.16667 | M7: =AVERAGEIFS('Height Summary'!R$13:R$60,'Height Summary'!$E$13:$E$60, "MDL") -> 96.75 | N7: =AVERAGEIFS('Height Summary'!S$13:S$60,'Height Summary'!$E$13:$E$60, "MDL") -> 100.08333 | O7: =AVERAGEIFS('Height Summary'!T$13:T$60,'Height Summary'!$E$13:$E$60, "MDL") -> 103 | P7: =AVERAGEIFS('Height Summary'!U$13:U$60,'Height Summary'!$E$13:$E$60, "MDL") -> 105.66667 | Q7: =AVERAGEIFS('Height Summary'!V$13:V$60,'Height Summary'!$E$13:$E$60, "MDL") -> 108
B9: Ave of all SOL: | C9: =AVERAGEIFS('Height Summary'!F$13:F$60,'Height Summary'!$E$13:$E$60, "SOL") -> 10 | D9: =AVERAGEIFS('Height Summary'!G$13:G$60,'Height Summary'!$E$13:$E$60, "SOL") -> 13.5 | E9: =AVERAGEIFS('Height Summary'!H$13:H$60,'Height Summary'!$E$13:$E$60, "SOL") -> 19.666667 | F9: =AVERAGEIFS('Height Summary'!I$13:I$60,'Height Summary'!$E$13:$E$60, "SOL") -> 30.25 | G9: =AVERAGEIFS('Height Summary'!J$13:J$60,'Height Summary'!$E$13:$E$60, "SOL") -> 40 | H9: =AVERAGEIFS('Height Summary'!K$13:K$60,'Height Summary'!$E$13:$E$60, "SOL") -> 54.166667 | I9: =AVERAGEIFS('Height Summary'!L$13:L$60,'Height Summary'!$E$13:$E$60, "SOL") -> 68.75 | J9: =AVERAGEIFS('Height Summary'!M$13:M$60,'Height Summary'!$E$13:$E$60, "SOL") -> 82.083333 | ... L9: =AVERAGEIFS('Height Summary'!O$13:O$60,'Height Summary'!$E$13:$E$60, "SOL") -> 100.83333 | M9: =AVERAGEIFS('Height Summary'!R$13:R$60,'Height Summary'!$E$13:$E$60, "SOL") -> 99.166667 | N9: =AVERAGEIFS('Height Summary'!S$13:S$60,'Height Summary'!$E$13:$E$60, "SOL") -> 103.25 | O9: =AVERAGEIFS('Height Summary'!T$13:T$60,'Height Summary'!$E$13:$E$60, "SOL") -> 107.16667 | P9: =AVERAGEIFS('Height Summary'!U$13:U$60,'Height Summary'!$E$13:$E$60, "SOL") -> 109.08333 | Q9: =AVERAGEIFS('Height Summary'!V$13:V$60,'Height Summary'!$E$13:$E$60, "SOL") -> 113.58333
B11: Ave of all DRN: | C11: =AVERAGEIFS('Height Summary'!F$13:F$60,'Height Summary'!$E$13:$E$60, "DRN") -> 10.833333 | D11: =AVERAGEIFS('Height Summary'!G$13:G$60,'Height Summary'!$E$13:$E$60, "DRN") -> 14.5 | E11: =AVERAGEIFS('Height Summary'!H$13:H$60,'Height Summary'!$E$13:$E$60, "DRN") -> 19.416667 | F11: =AVERAGEIFS('Height Summary'!I$13:I$60,'Height Summary'!$E$13:$E$60, "DRN") -> 30.5 | G11: =AVERAGEIFS('Height Summary'!J$13:J$60,'Height Summary'!$E$13:$E$60, "DRN") -> 39.75 | H11: =AVERAGEIFS('Height Summary'!K$13:K$60,'Height Summary'!$E$13:$E$60, "DRN") -> 52.75 | I11: =AVERAGEIFS('Height Summary'!L$13:L$60,'Height Summary'!$E$13:$E$60, "DRN") -> 67.166667 | J11: =AVERAGEIFS('Height Summary'!M$13:M$60,'Height Summary'!$E$13:$E$60, "DRN") -> 78 | ... L11: =AVERAGEIFS('Height Summary'!O$13:O$60,'Height Summary'!$E$13:$E$60, "DRN") -> 93.333333 | M11: =AVERAGEIFS('Height Summary'!R$13:R$60,'Height Summary'!$E$13:$E$60, "DRN") -> 94.25 | N11: =AVERAGEIFS('Height Summary'!S$13:S$60,'Height Summary'!$E$13:$E$60, "DRN") -> 97.5 | O11: =AVERAGEIFS('Height Summary'!T$13:T$60,'Height Summary'!$E$13:$E$60, "DRN") -> 101.58333 | P11: =AVERAGEIFS('Height Summary'!U$13:U$60,'Height Summary'!$E$13:$E$60, "DRN") -> 105.5 | Q11: =AVERAGEIFS('Height Summary'!V$13:V$60,'Height Summary'!$E$13:$E$60, "DRN") -> 109.41667
B13: Ave of all VRI: | C13: =AVERAGEIFS('Height Summary'!F$13:F$60,'Height Summary'!$E$13:$E$60, "VRI") -> 10.583333 | D13: =AVERAGEIFS('Height Summary'!G$13:G$60,'Height Summary'!$E$13:$E$60, "VRI") -> 13.666667 | E13: =AVERAGEIFS('Height Summary'!H$13:H$60,'Height Summary'!$E$13:$E$60, "VRI") -> 19.5 | F13: =AVERAGEIFS('Height Summary'!I$13:I$60,'Height Summary'!$E$13:$E$60, "VRI") -> 30 | G13: =AVERAGEIFS('Height Summary'!J$13:J$60,'Height Summary'!$E$13:$E$60, "VRI") -> 40.083333 | H13: =AVERAGEIFS('Height Summary'!K$13:K$60,'Height Summary'!$E$13:$E$60, "VRI") -> 54.666667 | I13: =AVERAGEIFS('Height Summary'!L$13:L$60,'Height Summary'!$E$13:$E$60, "VRI") -> 66.5 | J13: =AVERAGEIFS('Height Summary'!M$13:M$60,'Height Summary'!$E$13:$E$60, "VRI") -> 78.583333 | ... L13: =AVERAGEIFS('Height Summary'!O$13:O$60,'Height Summary'!$E$13:$E$60, "VRI") -> 92 | M13: =AVERAGEIFS('Height Summary'!R$13:R$60,'Height Summary'!$E$13:$E$60, "VRI") -> 91.25 | N13: =AVERAGEIFS('Height Summary'!S$13:S$60,'Height Summary'!$E$13:$E$60, "VRI") -> 94 | O13: =AVERAGEIFS('Height Summary'!T$13:T$60,'Height Summary'!$E$13:$E$60, "VRI") -> 98.666667 | P13: =AVERAGEIFS('Height Summary'!U$13:U$60,'Height Summary'!$E$13:$E$60, "VRI") -> 102.16667 | Q13: =AVERAGEIFS('Height Summary'!V$13:V$60,'Height Summary'!$E$13:$E$60, "VRI") -> 104.66667
C17: Average Canopy Widths
C19: ='Cover Summary'!F9 -> 43606 | D19: ='Cover Summary'!G9 -> 43613 | E19: ='Cover Summary'!H9 -> 43619 | F19: ='Cover Summary'!I9 -> 43627 | G19: ='Cover Summary'!J9 -> 43633 | H19: ='Cover Summary'!K9 -> 43641 | I19: ='Cover Summary'!L9 -> 43647 | J19: ='Cover Summary'!M9 -> 43654 | ... L19: ='Cover Summary'!O9 -> 43668 | M19: ='Cover Summary'!R9 -> 43690 | N19: ='Cover Summary'!S9 -> 43697 | O19: ='Cover Summary'!T9 -> 43703 | P19: ='Cover Summary'!U9 -> 43711 | Q19: ='Cover Summary'!V9 -> 43724
C20: ='Cover Summary'!F10 -> 141 | D20: ='Cover Summary'!G10 -> 148 | E20: ='Cover Summary'!H10 -> 154 | F20: ='Cover Summary'!I10 -> 162 | G20: ='Cover Summary'!J10 -> 168 | H20: ='Cover Summary'!K10 -> 176 | I20: ='Cover Summary'!L10 -> 182 | J20: ='Cover Summary'!M10 -> 189 | ... L20: ='Cover Summary'!O10 -> 203 | M20: ='Cover Summary'!R10 -> d225 | N20: ='Cover Summary'!S10 -> d232 | O20: ='Cover Summary'!T10 -> d238 | P20: ='Cover Summary'!U10 -> d246 | Q20: ='Cover Summary'!V10 -> d259
B21: Ave of all MDL: | C21: =AVERAGEIFS('Cover Summary'!F$13:F$60,'Cover Summary'!$E$13:$E$60, "MDL") -> 8.3333333 | D21: =AVERAGEIFS('Cover Summary'!G$13:G$60,'Cover Summary'!$E$13:$E$60, "MDL") -> 10.75 | E21: =AVERAGEIFS('Cover Summary'!H$13:H$60,'Cover Summary'!$E$13:$E$60, "MDL") -> 18.5 | F21: =AVERAGEIFS('Cover Summary'!I$13:I$60,'Cover Summary'!$E$13:$E$60, "MDL") -> 28.333333 | G21: =AVERAGEIFS('Cover Summary'!J$13:J$60,'Cover Summary'!$E$13:$E$60, "MDL") -> 38.25 | H21: =AVERAGEIFS('Cover Summary'!K$13:K$60,'Cover Summary'!$E$13:$E$60, "MDL") -> 51.583333 | I21: =AVERAGEIFS('Cover Summary'!L$13:L$60,'Cover Summary'!$E$13:$E$60, "MDL") -> 62.666667 | J21: =AVERAGEIFS('Cover Summary'!M$13:M$60,'Cover Summary'!$E$13:$E$60, "MDL") -> 72.25 | ... L21: =AVERAGEIFS('Cover Summary'!O$13:O$60,'Cover Summary'!$E$13:$E$60, "MDL") -> 89.666667 | M21: =AVERAGEIFS('Cover Summary'!R$13:R$60,'Cover Summary'!$E$13:$E$60, "MDL") -> #DIV/0! | N21: =AVERAGEIFS('Cover Summary'!S$13:S$60,'Cover Summary'!$E$13:$E$60, "MDL") -> #DIV/0! | O21: =AVERAGEIFS('Cover Summary'!T$13:T$60,'Cover Summary'!$E$13:$E$60, "MDL") -> #DIV/0! | P21: =AVERAGEIFS('Cover Summary'!U$13:U$60,'Cover Summary'!$E$13:$E$60, "MDL") -> #DIV/0! | Q21: =AVERAGEIFS('Cover Summary'!V$13:V$60,'Cover Summary'!$E$13:$E$60, "MDL") -> #DIV/0!
B23: Ave of all SOL: | C23: =AVERAGEIFS('Cover Summary'!F$13:F$60,'Cover Summary'!$E$13:$E$60, "SOL") -> 7.3333333 | D23: =AVERAGEIFS('Cover Summary'!G$13:G$60,'Cover Summary'!$E$13:$E$60, "SOL") -> 10.75 | E23: =AVERAGEIFS('Cover Summary'!H$13:H$60,'Cover Summary'!$E$13:$E$60, "SOL") -> 17.583333 | F23: =AVERAGEIFS('Cover Summary'!I$13:I$60,'Cover Summary'!$E$13:$E$60, "SOL") -> 28.25 | G23: =AVERAGEIFS('Cover Summary'!J$13:J$60,'Cover Summary'!$E$13:$E$60, "SOL") -> 38.666667 | H23: =AVERAGEIFS('Cover Summary'!K$13:K$60,'Cover Summary'!$E$13:$E$60, "SOL") -> 51 | I23: =AVERAGEIFS('Cover Summary'!L$13:L$60,'Cover Summary'!$E$13:$E$60, "SOL") -> 63.25 | J23: =AVERAGEIFS('Cover Summary'!M$13:M$60,'Cover Summary'!$E$13:$E$60, "SOL") -> 71.166667 | ... L23: =AVERAGEIFS('Cover Summary'!O$13:O$60,'Cover Summary'!$E$13:$E$60, "SOL") -> 89.75 | M23: =AVERAGEIFS('Cover Summary'!R$13:R$60,'Cover Summary'!$E$13:$E$60, "SOL") -> 96 | N23: =AVERAGEIFS('Cover Summary'!S$13:S$60,'Cover Summary'!$E$13:$E$60, "SOL") -> #DIV/0! | O23: =AVERAGEIFS('Cover Summary'!T$13:T$60,'Cover Summary'!$E$13:$E$60, "SOL") -> #DIV/0! | P23: =AVERAGEIFS('Cover Summary'!U$13:U$60,'Cover Summary'!$E$13:$E$60, "SOL") -> #DIV/0! | Q23: =AVERAGEIFS('Cover Summary'!V$13:V$60,'Cover Summary'!$E$13:$E$60, "SOL") -> #DIV/0!
B25: Ave of all DRN: | C25: =AVERAGEIFS('Cover Summary'!F$13:F$60,'Cover Summary'!$E$13:$E$60, "DRN") -> 7.9166667 | D25: =AVERAGEIFS('Cover Summary'!G$13:G$60,'Cover Summary'!$E$13:$E$60, "DRN") -> 10.75 | E25: =AVERAGEIFS('Cover Summary'!H$13:H$60,'Cover Summary'!$E$13:$E$60, "DRN") -> 17.833333 | F25: =AVERAGEIFS('Cover Summary'!I$13:I$60,'Cover Summary'!$E$13:$E$60, "DRN") -> 27.333333 | G25: =AVERAGEIFS('Cover Summary'!J$13:J$60,'Cover Summary'!$E$13:$E$60, "DRN") -> 38.166667 | H25: =AVERAGEIFS('Cover Summary'!K$13:K$60,'Cover Summary'!$E$13:$E$60, "DRN") -> 49.083333 | I25: =AVERAGEIFS('Cover Summary'!L$13:L$60,'Cover Summary'!$E$13:$E$60, "DRN") -> 61.583333 | J25: =AVERAGEIFS('Cover Summary'!M$13:M$60,'Cover Summary'!$E$13:$E$60, "DRN") -> 68.75 | ... L25: =AVERAGEIFS('Cover Summary'!O$13:O$60,'Cover Summary'!$E$13:$E$60, "DRN") -> 84.333333 | M25: =AVERAGEIFS('Cover Summary'!R$13:R$60,'Cover Summary'!$E$13:$E$60, "DRN") -> 93.5 | N25: =AVERAGEIFS('Cover Summary'!S$13:S$60,'Cover Summary'!$E$13:$E$60, "DRN") -> #DIV/0! | O25: =AVERAGEIFS('Cover Summary'!T$13:T$60,'Cover Summary'!$E$13:$E$60, "DRN") -> #DIV/0! | P25: =AVERAGEIFS('Cover Summary'!U$13:U$60,'Cover Summary'!$E$13:$E$60, "DRN") -> #DIV/0! | Q25: =AVERAGEIFS('Cover Summary'!V$13:V$60,'Cover Summary'!$E$13:$E$60, "DRN") -> #DIV/0!
B27: Ave of all VRI: | C27: =AVERAGEIFS('Cover Summary'!F$13:F$60,'Cover Summary'!$E$13:$E$60, "VRI") -> 7.75 | D27: =AVERAGEIFS('Cover Summary'!G$13:G$60,'Cover Summary'!$E$13:$E$60, "VRI") -> 10.75 | E27: =AVERAGEIFS('Cover Summary'!H$13:H$60,'Cover Summary'!$E$13:$E$60, "VRI") -> 17.583333 | F27: =AVERAGEIFS('Cover Summary'!I$13:I$60,'Cover Summary'!$E$13:$E$60, "VRI") -> 28.166667 | G27: =AVERAGEIFS('Cover Summary'!J$13:J$60,'Cover Summary'!$E$13:$E$60, "VRI") -> 38.5 | H27: =AVERAGEIFS('Cover Summary'!K$13:K$60,'Cover Summary'!$E$13:$E$60, "VRI") -> 49.166667 | I27: =AVERAGEIFS('Cover Summary'!L$13:L$60,'Cover Summary'!$E$13:$E$60, "VRI") -> 60 | J27: =AVERAGEIFS('Cover Summary'!M$13:M$60,'Cover Summary'!$E$13:$E$60, "VRI") -> 66.75 | ... L27: =AVERAGEIFS('Cover Summary'!O$13:O$60,'Cover Summary'!$E$13:$E$60, "VRI") -> 80.416667 | M27: =AVERAGEIFS('Cover Summary'!R$13:R$60,'Cover Summary'!$E$13:$E$60, "VRI") -> 88.666667 | N27: =AVERAGEIFS('Cover Summary'!S$13:S$60,'Cover Summary'!$E$13:$E$60, "VRI") -> #DIV/0! | O27: =AVERAGEIFS('Cover Summary'!T$13:T$60,'Cover Summary'!$E$13:$E$60, "VRI") -> #DIV/0! | P27: =AVERAGEIFS('Cover Summary'!U$13:U$60,'Cover Summary'!$E$13:$E$60, "VRI") -> #DIV/0! | Q27: =AVERAGEIFS('Cover Summary'!V$13:V$60,'Cover Summary'!$E$13:$E$60, "VRI") -> #DIV/0!

Sheet Emergence
A1: 2019 | B1: F13 b4 | C1: Cotton
B3: Emergence
A4: Emergence counts taken at the first Plant Sampling flag location in each plot
C8: # plants per 1 meter (1 meter North of each flag)
B9: Date: | C9: 43577 | D9: 43579 | E9: 43580 | F9: 43581 | G9: 43584 | I9: 43586 | K9: 43588 | M9: 43591 | O9: 43592 | Q9: 43593 | S9: 43598
B10: DOY: | C10: 112 | D10: 114 | E10: 115 | F10: 116 | G10: 119 | I10: 121 | K10: 123 | M10: 126 | O10: 127 | Q10: 128 | S10: 133
B11: by: | C11: SMM | D11: SMM | E11: SMM | F11: SMM | G11: SMM | I11: SMM | K11: SMM | M11: SMM | O11: SMM | Q11: SMM | S11: SMM
B12: flag point | D12: 1000-1020h | E12: 1400-1420h | F12: 1015-1035h | G12: 1015-1040h | I12: 1300-1320h | K12: 1300-1320h | M12: 1000-1020h | O12: 1020-1040h | Q12: 1000-1020h | S12: 1000-1020h
A13: Northwest corner span 6 | B13: 1-1 | C13: 0 | D13: 0 | E13: 1 | F13: 6 | G13: 6 | I13: 6 | K13: 6 | M13: 6 | O13: 6 | Q13: 6 | S13: 6
B14: 1-2 | C14: 0 | D14: 0 | E14: 3 | F14: 5 | G14: 6 | I14: 7 | K14: 7 | M14: 7 | O14: 7 | Q14: 7 | S14: 7
B15: 1-3 | C15: 0 | D15: 2 | E15: 5 | F15: 6 | G15: 6 | I15: 6 | K15: 6 | M15: 6 | O15: 6 | Q15: 6 | S15: 6
B16: 1-4 | C16: 0 | D16: 1 | E16: 5 | F16: 7 | G16: 8 | I16: 8 | K16: 8 | M16: 8 | O16: 8 | Q16: 8 | S16: 8
B17: 2-4 | C17: 0 | D17: 0 | E17: 4 | F17: 9 | G17: 10 | I17: 10 | K17: 10 | M17: 10 | O17: 10 | Q17: 10 | S17: 10
B18: 2-3 | C18: 0 | D18: 0 | E18: 3 | F18: 3 | G18: 4 | I18: 5 | K18: 5 | M18: 5 | O18: 5 | Q18: 5 | S18: 5
B19: 2-2 | C19: 0 | D19: 1 | E19: 3 | F19: 7 | G19: 9 | I19: 9 | K19: 9 | M19: 9 | O19: 9 | Q19: 9 | S19: 9
B20: 2-1 | C20: 0 | D20: 0 | E20: 6 | F20: 8 | G20: 10 | I20: 10 | J20: 1 looks bad | K20: 10 | L20: +1 dead | M20: 10 | N20: 1 looks bad | O20: 10 | P20: still alive | Q20: 10 | R20: still alive | S20: 10 | T20: still alive
B21: 3-1 | C21: 0 | D21: 0 | E21: 4 | F21: 8 | G21: 9 | I21: 11 | K21: 11 | M21: 11 | N21: 2 look bad | O21: 11 | Q21: 11 | R21: still alive | S21: 11 | T21: still alive
B22: 3-2 | C22: 0 | D22: 0 | E22: 2 | F22: 5 | G22: 9 | I22: 9 | K22: 9 | M22: 9 | O22: 9 | Q22: 9 | S22: 9
B23: 3-3 | C23: 0 | D23: 0 | E23: 4 | F23: 7 | G23: 8 | I23: 8 | K23: 8 | M23: 8 | O23: 8 | Q23: 8 | S23: 8
B24: 3-4 | C24: 0 | D24: 0 | E24: 7 | F24: 9 | G24: 11 | I24: 10 | J24: +1 dead | K24: 11 | L24: +1 dead | M24: 11 | O24: 11 | P24: 1 looks bad | Q24: 11 | S24: 11
B25: 4-4 | C25: 0 | D25: 0 | E25: 3 | F25: 3 | G25: 5 | H25: +1 dead | I25: 5 | J25: +1 dead | K25: 5 | L25: +1 dead | M25: 5 | O25: 5 | Q25: 5 | S25: 5
B26: 4-3 | C26: 0 | D26: 0 | E26: 3 | F26: 7 | G26: 7 | I26: 7 | K26: 7 | M26: 7 | O26: 7 | Q26: 7 | S26: 7
B27: 4-2 | C27: 0 | D27: 0 | E27: 2 | F27: 2 | G27: 5 | I27: 5 | K27: 6 | M27: 6 | O27: 6 | Q27: 6 | S27: 6
B28: 4-1 | C28: 0 | D28: 1 | E28: 3 | F28: 5 | G28: 5 | H28: +1 dead | I28: 4 | J28: +2 dead | K28: 4 | L28: +2 dead | M28: 4 | O28: 4 | Q28: 4 | S28: 4
B29: 5-1 | C29: 0 | D29: 0 | E29: 2 | F29: 7 | G29: 7 | I29: 7 | K29: 6 | L29: +1 dead | M29: 6 | O29: 6 | P29: 1 looks bad | Q29: 6 | R29: still alive | S29: 5 | T29: + 1 dead
B30: 5-2 | C30: 0 | D30: 0 | E30: 2 | F30: 7 | G30: 10 | I30: 9 | J30: +1 dead | K30: 10 | L30: +1 dead | M30: 10 | O30: 10 | Q30: 10 | S30: 10
B31: 5-3 | C31: 0 | D31: 0 | E31: 4 | F31: 8 | G31: 8 | I31: 7 | J31: +1 dead | K31: 6 | L31: +2 dead | M31: 6 | O31: 6 | Q31: 6 | S31: 6
B32: 5-4 | C32: 0 | D32: 1 | E32: 4 | F32: 8 | G32: 8 | I32: 8 | K32: 8 | M32: 8 | O32: 8 | Q32: 8 | S32: 8
B33: 6-4 | C33: 0 | D33: 0 | E33: 5 | F33: 5 | G33: 7 | H33: +1 dead | I33: 7 | J33: +1 dead | K33: 7 | L33: +1 dead | M33: 7 | O33: 7 | Q33: 7 | S33: 7
B34: 6-3 | C34: 0 | D34: 1 | E34: 2 | F34: 2 | G34: 4 | I34: 5 | K34: 5 | M34: 5 | O34: 5 | Q34: 5 | S34: 5
B35: 6-2 | C35: 0 | D35: 0 | E35: 4 | F35: 5 | G35: 8 | I35: 8 | K35: 8 | M35: 8 | N35: 1 looks bad | O35: 7 | P35: +1 dead | Q35: 7 | S35: 7
A36: Northeast corner span 4 | B36: 6-1 | C36: 0 | D36: 0 | E36: 2 | F36: 6 | G36: 7 | I36: 9 | K36: 8 | L36: +1 dead | M36: 8 | O36: 9 | P36: ! | Q36: 9 | S36: 9
B39: Plot | C39: 112 | D39: 114 | E39: 115 | F39: 116 | G39: 119 | H39: 121 | I39: 123 | J39: 126 | K39: 127 | L39: 128 | M39: 133 | N39: 0.5 | O39: 50% DOY
B40: 1-1 | C40: 0 | D40: 0 | E40: 1 | F40: 6 | G40: 6 | H40: 6 | I40: 6 | J40: 6 | K40: 6 | L40: 6 | M40: 6 | N40: =M40/2 -> 3 | O40: =E$39+(N40-E40)/(F40-E40)*(F$39-E$39) -> 115.4
B41: 1-2 | C41: 0 | D41: 0 | E41: 3 | F41: 5 | G41: 6 | H41: 7 | I41: 7 | J41: 7 | K41: 7 | L41: 7 | M41: 7 | N41: =M41/2 -> 3.5 | O41: =E$39+(N41-E41)/(F41-E41)*(F$39-E$39) -> 115.25
B42: 1-3 | C42: 0 | D42: 2 | E42: 5 | F42: 6 | G42: 6 | H42: 6 | I42: 6 | J42: 6 | K42: 6 | L42: 6 | M42: 6 | N42: =M42/2 -> 3 | O42: =D$39+(N42-D42)/(E42-D42)*(E$39-D$39) -> 114.33333
B43: 1-4 | C43: 0 | D43: 1 | E43: 5 | F43: 7 | G43: 8 | H43: 8 | I43: 8 | J43: 8 | K43: 8 | L43: 8 | M43: 8 | N43: =M43/2 -> 4 | O43: =D$39+(N43-D43)/(E43-D43)*(E$39-D$39) -> 114.75
B44: 2-4 | C44: 0 | D44: 0 | E44: 4 | F44: 9 | G44: 10 | H44: 10 | I44: 10 | J44: 10 | K44: 10 | L44: 10 | M44: 10 | N44: =M44/2 -> 5 | O44: =E$39+(N44-E44)/(F44-E44)*(F$39-E$39) -> 115.2
B45: 2-3 | C45: 0 | D45: 0 | E45: 3 | F45: 3 | G45: 4 | H45: 5 | I45: 5 | J45: 5 | K45: 5 | L45: 5 | M45: 5 | N45: =M45/2 -> 2.5 | O45: =D$39+(N45-D45)/(E45-D45)*(E$39-D$39) -> 114.83333
B46: 2-2 | C46: 0 | D46: 1 | E46: 3 | F46: 7 | G46: 9 | H46: 9 | I46: 9 | J46: 9 | K46: 9 | L46: 9 | M46: 9 | N46: =M46/2 -> 4.5 | O46: =E$39+(N46-E46)/(F46-E46)*(F$39-E$39) -> 115.375
...

Sheet 1stLeaf
A1: 2019 | B1: F13 b4 | D1: Cotton
B3: First true leaf
A4: Flags scattered over field, placed 1 per each of the 16 experimental strips (East to West).
A5: Flags placed in a zig-zag pattern from North to South, with flags placed approx in plot 01-4, then 02-3,
A6: 03-2 and 04-1. Then back from plot 05-1 to 08-4. And repeated again from plots 09-4 to 16-4.
B9: Date: | D9: 43588 | E9: 43591 | F9: 43592 | G9: 43593 | H9: 43598
B10: DOY: | D10: 123 | E10: 126 | F10: 127 | G10: 128 | H10: 133
B11: by: | D11: SMM | E11: SMM | F11: SMM | G11: SMM | H11: SMM
B12: flag point | C12: Total # plants/1 m | D12: 1300-1320 | E12: 1000-1020h | F12: 1010-1040h | G12: 1000-1020h | H12: 1000-1020h | K12: 0.5 | L12: 50% DOY
B13: 1-1 | C13: 6 | D13: 0 | E13: 4 | F13: 4 | G13: 5 | H13: 6 | K13: =H13/2 -> 3 | L13: =D$10+(K13-D13)/(E13-D13)*(E$10-D$10) -> 125.25 | M13: 11E
B14: 1-2 | C14: 7 | D14: 0 | E14: 4 | F14: 5 | G14: 7 | H14: 7 | K14: =H14/2 -> 3.5 | L14: =D$10+(K14-D14)/(E14-D14)*(E$10-D$10) -> 125.625 | M14: 12E
B15: 1-3 | C15: 6 | D15: 0 | E15: 4 | F15: 5 | G15: 6 | H15: 6 | K15: =H15/2 -> 3 | L15: =D$10+(K15-D15)/(E15-D15)*(E$10-D$10) -> 125.25 | M15: 13E
B16: 1-4 | C16: 8 | D16: 0 | E16: 4 | F16: 6 | G16: 8 | H16: 8 | K16: =H16/2 -> 4 | L16: =D$10+(K16-D16)/(E16-D16)*(E$10-D$10) -> 126 | M16: 14E
B17: 2-4 | C17: 10 | D17: 0 | E17: 5 | F17: 7 | G17: 10 | H17: 10 | K17: =H17/2 -> 5 | L17: =D$10+(K17-D17)/(E17-D17)*(E$10-D$10) -> 126 | M17: 24E
B18: 2-3 | C18: 5 | D18: 0 | E18: 1 | F18: 2 | G18: 2 | H18: 5 | K18: =H18/2 -> 2.5 | L18: =G$10+(K18-G18)/(H18-G18)*(H$10-G$10) -> 128.83333 | M18: 23E
B19: 2-2 | C19: 9 | D19: 0 | E19: 5 | F19: 7 | G19: 9 | H19: 9 | K19: =H19/2 -> 4.5 | L19: =D$10+(K19-D19)/(E19-D19)*(E$10-D$10) -> 125.7 | M19: 22E
B20: 2-1 | C20: 10 | D20: 0 | E20: 5 | F20: 8 | G20: 9 | H20: 9 | K20: =H20/2 -> 4.5 | L20: =D$10+(K20-D20)/(E20-D20)*(E$10-D$10) -> 125.7 | M20: 21E
B21: 3-1 | C21: 11 | D21: 0 | E21: 5 | F21: 8 | G21: 9 | H21: 11 | K21: =H21/2 -> 5.5 | L21: =E$10+(K21-E21)/(F21-E21)*(F$10-E$10) -> 126.16667 | M21: 31E
B22: 3-2 | C22: 9 | D22: 0 | E22: 4 | F22: 4 | G22: 7 | H22: 9 | K22: =H22/2 -> 4.5 | L22: =F$10+(K22-F22)/(G22-F22)*(G$10-F$10) -> 127.16667 | M22: 32E
B23: 3-3 | C23: 8 | D23: 0 | E23: 4 | F23: 6 | G23: 7 | H23: 8 | K23: =H23/2 -> 4 | L23: =D$10+(K23-D23)/(E23-D23)*(E$10-D$10) -> 126 | M23: 33E
B24: 3-4 | C24: 11 | D24: 0 | E24: 6 | F24: 9 | G24: 10 | H24: 11 | K24: =H24/2 -> 5.5 | L24: =D$10+(K24-D24)/(E24-D24)*(E$10-D$10) -> 125.75 | M24: 34E
B25: 4-4 | C25: 5 | D25: 0 | E25: 3 | F25: 4 | G25: 5 | H25: 5 | K25: =H25/2 -> 2.5 | L25: =D$10+(K25-D25)/(E25-D25)*(E$10-D$10) -> 125.5 | M25: 44E
B26: 4-3 | C26: 7 | D26: 0 | E26: 4 | F26: 5 | G26: 6 | H26: 7 | K26: =H26/2 -> 3.5 | L26: =D$10+(K26-D26)/(E26-D26)*(E$10-D$10) -> 125.625 | M26: 43E
B27: 4-2 | C27: 6 | D27: 0 | E27: 1 | F27: 2 | G27: 3 | H27: 6 | K27: =H27/2 -> 3 | L27: =F$10+(K27-F27)/(G27-F27)*(G$10-F$10) -> 128 | M27: 42E
B28: 4-1 | C28: 4 | D28: 0 | E28: 1 | F28: 4 | G28: 4 | H28: 4 | K28: =H28/2 -> 2 | L28: =E$10+(K28-E28)/(F28-E28)*(F$10-E$10) -> 126.33333 | M28: 41E
B29: 5-1 | C29: 6-5 | D29: 0 | E29: 4 | F29: 5 | G29: 5 | H29: 5 | K29: =H29/2 -> 2.5 | L29: =D$10+(K29-D29)/(E29-D29)*(E$10-D$10) -> 124.875 | M29: 51E
B30: 5-2 | C30: 10 | D30: 0 | E30: 2 | F30: 6 | G30: 6 | H30: 10 | K30: =H30/2 -> 5 | L30: =E$10+(K30-E30)/(F30-E30)*(F$10-E$10) -> 126.75 | M30: 52E
B31: 5-3 | C31: 6 | D31: 0 | E31: 4 | F31: 6 | G31: 6 | H31: 6 | K31: =H31/2 -> 3 | L31: =D$10+(K31-D31)/(E31-D31)*(E$10-D$10) -> 125.25 | M31: 53E
B32: 5-4 | C32: 8 | D32: 0 | E32: 6 | F32: 8 | G32: 8 | H32: 8 | K32: =H32/2 -> 4 | L32: =D$10+(K32-D32)/(E32-D32)*(E$10-D$10) -> 125 | M32: 54E
B33: 6-4 | C33: 7 | D33: 0 | E33: 5 | F33: 6 | G33: 6 | H33: 7 | K33: =H33/2 -> 3.5 | L33: =D$10+(K33-D33)/(E33-D33)*(E$10-D$10) -> 125.1 | M33: 64E
B34: 6-3 | C34: 5 | D34: 0 | E34: 2 | F34: 3 | G34: 3 | H34: 5 | K34: =H34/2 -> 2.5 | L34: =E$10+(K34-E34)/(F34-E34)*(F$10-E$10) -> 126.5 | M34: 63E
B35: 6-2 | C35: 8 | D35: 0 | E35: 4 | F35: 5 | G35: 6 | H35: 7 | K35: =H35/2 -> 3.5 | L35: =D$10+(K35-D35)/(E35-D35)*(E$10-D$10) -> 125.625 | M35: 62E
B36: 6-1 | C36: 8-9 | D36: 0 | E36: 3 | F36: 5 | G36: 6 | H36: 9 | K36: =H36/2 -> 4.5 | L36: =E$10+(K36-E36)/(F36-E36)*(F$10-E$10) -> 126.75 | M36: 61E
D37: Some true leaves developing, but still small and folded.

Sheet Counts1
A1: 2019 | B1: F13b4 | D1: Cotton | I1: date: | K1: 15 May 2019 | M1: 0945-1030h
B3: Final density counts | I3: by: | J3: SMM
B4: Counted plants in 1.5 meter North of pink "Sampling" flag (& same relative location in the rows to the East and West of the flagged row).
D5: 1 row East of flag | F5: 1 row West of flag | K5: 1 row East of flag | L5: At flag | M5: 1 row West of flag
B6: Plot | D6: # plants /1.5 m | E6: # plants /1.5 m | F6: # plants /1.5 m | G6: Ave plants/meter | I6: Plot | K6: # plants /1.5 m | L6: # plants /1.5 m | M6: # plants /1.5 m | N6: Ave plants/meter
B7: 01- | C7: 1 | D7: 13 | E7: 11 | F7: 6 | G7: =(AVERAGE(D7:F7))/1.5 -> 6.6666667 | I7: 04- | J7: 4 | K7: 12 | L7: 11 | M7: 11 | N7: =(AVERAGE(K7:M7))/1.5 -> 7.5555556
B8: 01- | C8: 2 | D8: 13 | E8: 9 | F8: 9 | G8: =(AVERAGE(D8:F8))/1.5 -> 6.8888889 | I8: 04- | J8: 3 | K8: 15 | L8: 8 | M8: 9 | N8: =(AVERAGE(K8:M8))/1.5 -> 7.1111111
B9: 01- | C9: 3 | D9: 9 | E9: 10 | F9: 11 | G9: =(AVERAGE(D9:F9))/1.5 -> 6.6666667 | I9: 04- | J9: 2 | K9: 10 | L9: 8 | M9: 7 | N9: =(AVERAGE(K9:M9))/1.5 -> 5.5555556
B10: 01- | C10: 4 | D10: 12 | E10: 11 | F10: 10 | G10: =(AVERAGE(D10:F10))/1.5 -> 7.3333333 | I10: 04- | J10: 1 | K10: 12 | L10: 6 | M10: 8 | N10: =(AVERAGE(K10:M10))/1.5 -> 5.7777778
B11: 02- | C11: 4 | D11: 10 | E11: 16 | F11: 10 | G11: =(AVERAGE(D11:F11))/1.5 -> 8 | I11: 05- | J11: 1 | K11: 4 | L11: 9 | M11: 6 | N11: =(AVERAGE(K11:M11))/1.5 -> 4.2222222
B12: 02- | C12: 3 | D12: 11 | E12: 8 | F12: 9 | G12: =(AVERAGE(D12:F12))/1.5 -> 6.2222222 | I12: 05- | J12: 2 | K12: 10 | L12: 14 | M12: 9 | N12: =(AVERAGE(K12:M12))/1.5 -> 7.3333333
B13: 02- | C13: 2 | D13: 12 | E13: 12 | F13: 15 | G13: =(AVERAGE(D13:F13))/1.5 -> 8.6666667 | I13: 05- | J13: 3 | K13: 10 | L13: 11 | M13: 11 | N13: =(AVERAGE(K13:M13))/1.5 -> 7.1111111
B14: 02- | C14: 1 | D14: 8 | E14: 14 | F14: 12 | G14: =(AVERAGE(D14:F14))/1.5 -> 7.5555556 | I14: 05- | J14: 4 | K14: 9 | L14: 10 | M14: 8 | N14: =(AVERAGE(K14:M14))/1.5 -> 6
B15: 03- | C15: 1 | D15: 14 | E15: 16 | F15: 9 | G15: =(AVERAGE(D15:F15))/1.5 -> 8.6666667 | I15: 06- | J15: 4 | K15: 13 | L15: 11 | M15: 12 | N15: =(AVERAGE(K15:M15))/1.5 -> 8
B16: 03- | C16: 2 | D16: 11 | E16: 11 | F16: 13 | G16: =(AVERAGE(D16:F16))/1.5 -> 7.7777778 | I16: 06- | J16: 3 | K16: 7 | L16: 9 | M16: 10 | N16: =(AVERAGE(K16:M16))/1.5 -> 5.7777778
B17: 03- | C17: 3 | D17: 8 | E17: 10 | F17: 17 | G17: =(AVERAGE(D17:F17))/1.5 -> 7.7777778 | I17: 06- | J17: 2 | K17: 7 | L17: 10 | M17: 9 | N17: =(AVERAGE(K17:M17))/1.5 -> 5.7777778
B18: 03- | C18: 4 | D18: 11 | E18: 14 | F18: 8 | G18: =(AVERAGE(D18:F18))/1.5 -> 7.3333333 | I18: 06- | J18: 1 | K18: 10 | L18: 11 | M18: 13 | N18: =(AVERAGE(K18:M18))/1.5 -> 7.5555556
D21: =AVERAGE(D7:F18,K7:M18) -> 10.458333
D22: =AVERAGE(D7:F18,K7:M18)/(1.5*1.016) -> 6.8624234

Sheet Counts2
G2: PLPD
A3: 01- | B3: 1 | C3: 11 | D3: 13 | E3: 11 | F3: 6 | G3: =SUM(D3:F3)/(1.5*1.016*3) -> 6.5616798
A4: 01- | B4: 2 | C4: 12 | D4: 13 | E4: 9 | F4: 9 | G4: =SUM(D4:F4)/(1.5*1.016*3) -> 6.7804024
A5: 01- | B5: 3 | C5: 13 | D5: 9 | E5: 10 | F5: 11 | G5: =SUM(D5:F5)/(1.5*1.016*3) -> 6.5616798
A6: 01- | B6: 4 | C6: 14 | D6: 12 | E6: 11 | F6: 10 | G6: =SUM(D6:F6)/(1.5*1.016*3) -> 7.2178478
A7: 02- | B7: 4 | C7: 24 | D7: 10 | E7: 16 | F7: 10 | G7: =SUM(D7:F7)/(1.5*1.016*3) -> 7.8740157
A8: 02- | B8: 3 | C8: 23 | D8: 11 | E8: 8 | F8: 9 | G8: =SUM(D8:F8)/(1.5*1.016*3) -> 6.1242345
A9: 02- | B9: 2 | C9: 22 | D9: 12 | E9: 12 | F9: 15 | G9: =SUM(D9:F9)/(1.5*1.016*3) -> 8.5301837
A10: 02- | B10: 1 | C10: 21 | D10: 8 | E10: 14 | F10: 12 | G10: =SUM(D10:F10)/(1.5*1.016*3) -> 7.4365704
A11: 03- | B11: 1 | C11: 31 | D11: 14 | E11: 16 | F11: 9 | G11: =SUM(D11:F11)/(1.5*1.016*3) -> 8.5301837
A12: 03- | B12: 2 | C12: 32 | D12: 11 | E12: 11 | F12: 13 | G12: =SUM(D12:F12)/(1.5*1.016*3) -> 7.6552931
A13: 03- | B13: 3 | C13: 33 | D13: 8 | E13: 10 | F13: 17 | G13: =SUM(D13:F13)/(1.5*1.016*3) -> 7.6552931
A14: 03- | B14: 4 | C14: 34 | D14: 11 | E14: 14 | F14: 8 | G14: =SUM(D14:F14)/(1.5*1.016*3) -> 7.2178478
... A26: 06- | B26: 1 | C26: 61 | D26: 10 | E26: 11 | F26: 13 | G26: =SUM(D26:F26)/(1.5*1.016*3) -> 7.4365704

Sheet Flowering
B1: F13 b4 | D1: Cotton
B3: Flowering
A4: Counting 10 plants North from the pink Sampling flag. Counting the number of those plants that are flowering.
B6: Data recorded on Canopy Height & Width data sheets
C9: Date: | D9: 43641 | E9: 43642 | F9: 43647
C10: DOY: | D10: 176 | E10: 177 | F10: 182
C11: by: | D11: SMM | E11: SMM | F11: SMM
A13: plot | D13: # plants flowering/ 10 plants | E13: # plants flowering/ 10 plants | F13: # plants flowering/ 10 plants | G13: # plants flowering/ 10 plants | H13: # plants flowering/ 10 plants | K13: 50% DOY
A14: 01- | B14: 1 | C14: North | D14: 0 | E14: 0 | F14: 1 | J14: 5 | L14: 11N
C15: South | D15: 0 | E15: 0 | F15: 0 | J15: 5 | L15: 11S
A16: 01- | B16: 2 | C16: North | D16: 2 | E16: 3 | F16: 6 | J16: 5 | K16: =E$10+(J16-E16)/(F16-E16)*(F$10-E$10) -> 180.33333 | L16: 12N
C17: South | D17: 1 | E17: 1 | F17: 5 | J17: 5 | K17: =E$10+(J17-E17)/(F17-E17)*(F$10-E$10) -> 182 | L17: 12S
A18: 01- | B18: 3 | C18: North | D18: 2 | E18: 3 | F18: 6 | J18: 5 | K18: =E$10+(J18-E18)/(F18-E18)*(F$10-E$10) -> 180.33333 | L18: 13N
C19: South | D19: 0 | E19: 1 | F19: 6 | J19: 5 | K19: =E$10+(J19-E19)/(F19-E19)*(F$10-E$10) -> 181 | L19: 13S
A20: 01- | B20: 4 | C20: North | D20: 0 | E20: 1 | F20: 6 | J20: 5 | K20: =E$10+(J20-E20)/(F20-E20)*(F$10-E$10) -> 181 | L20: 14N
C21: South | D21: 0 | E21: 2 | F21: 7 | J21: 5 | K21: =E$10+(J21-E21)/(F21-E21)*(F$10-E$10) -> 180 | L21: 14S
A22: 02- | B22: 4 | C22: South | D22: 1 | E22: 2 | F22: 7 | J22: 5 | K22: =E$10+(J22-E22)/(F22-E22)*(F$10-E$10) -> 180 | L22: 24S
C23: North | D23: 2 | E23: 4 | F23: 8 | J23: 5 | K23: =E$10+(J23-E23)/(F23-E23)*(F$10-E$10) -> 178.25 | L23: 24N
A24: 02- | B24: 3 | C24: South | D24: 2 | E24: 3 | F24: 7 | J24: 5 | K24: =E$10+(J24-E24)/(F24-E24)*(F$10-E$10) -> 179.5 | L24: 23S
C25: North | D25: 0 | E25: 2 | F25: 8 | J25: 5 | K25: =E$10+(J25-E25)/(F25-E25)*(F$10-E$10) -> 179.5 | L25: 23N
A26: 02- | B26: 2 | C26: South | D26: 0 | E26: 3 | F26: 9 | J26: 5 | K26: =E$10+(J26-E26)/(F26-E26)*(F$10-E$10) -> 178.66667 | L26: 22S
C27: North | D27: 1 | E27: 4 | F27: 7 | J27: 5 | K27: =E$10+(J27-E27)/(F27-E27)*(F$10-E$10) -> 178.66667 | L27: 22N
A28: 02- | B28: 1 | C28: South | D28: 0 | E28: 3 | F28: 5 | J28: 5 | K28: =E$10+(J28-E28)/(F28-E28)*(F$10-E$10) -> 182 | L28: 21S
C29: North | D29: 1 | E29: 2 | F29: 6 | J29: 5 | K29: =E$10+(J29-E29)/(F29-E29)*(F$10-E$10) -> 180.75 | L29: 21N
A30: 03- | B30: 1 | C30: North | D30: 0 | E30: 1 | F30: 7 | J30: 5 | K30: =E$10+(J30-E30)/(F30-E30)*(F$10-E$10) -> 180.33333 | L30: 31N
C31: South | D31: 0 | E31: 2 | F31: 6 | J31: 5 | K31: =E$10+(J31-E31)/(F31-E31)*(F$10-E$10) -> 180.75 | L31: 31S
A32: 03- | B32: 2 | C32: North | D32: 1 | E32: 2 | F32: 5 | J32: 5 | K32: =E$10+(J32-E32)/(F32-E32)*(F$10-E$10) -> 182 | L32: 32N
C33: South | D33: 0 | E33: 0 | F33: 6 | J33: 5 | K33: =E$10+(J33-E33)/(F33-E33)*(F$10-E$10) -> 181.16667 | L33: 32S
A34: 03- | B34: 3 | C34: North | D34: 1 | E34: 2 | F34: 7 | J34: 5 | K34: =E$10+(J34-E34)/(F34-E34)*(F$10-E$10) -> 180 | L34: 33N
C35: South | D35: 2 | E35: 4 | F35: 8 | J35: 5 | K35: =E$10+(J35-E35)/(F35-E35)*(F$10-E$10) -> 178.25 | L35: 33S
A36: 03- | B36: 4 | C36: North | D36: 1 | E36: 2 | F36: 9 | J36: 5 | K36: =E$10+(J36-E36)/(F36-E36)*(F$10-E$10) -> 179.14286 | L36: 34N
C37: South | D37: 2 | E37: 2 | F37: 7 | J37: 5 | K37: =E$10+(J37-E37)/(F37-E37)*(F$10-E$10) -> 180 | L37: 34S
A38: 04- | B38: 4 | C38: South | D38: 3 | E38: 4 | F38: 9 | J38: 5 | K38: =E$10+(J38-E38)/(F38-E38)*(F$10-E$10) -> 178 | L38: 44S
C39: North | D39: 2 | E39: 4 | F39: 7 | J39: 5 | K39: =E$10+(J39-E39)/(F39-E39)*(F$10-E$10) -> 178.66667 | L39: 44N
A40: 04- | B40: 3 | C40: South | D40: 1 | E40: 4 | F40: 10 | J40: 5 | K40: =E$10+(J40-E40)/(F40-E40)*(F$10-E$10) -> 177.83333 | L40: 43S
C41: North | D41: 1 | E41: 2 | F41: 8 | J41: 5 | K41: =E$10+(J41-E41)/(F41-E41)*(F$10-E$10) -> 179.5 | L41: 43N
A42: 04- | B42: 2 | C42: South | D42: 0 | E42: 2 | F42: 6 | J42: 5 | K42: =E$10+(J42-E42)/(F42-E42)*(F$10-E$10) -> 180.75 | L42: 42S
