Workbook

Sheet Height
A1: CCID | B1: DOY147 | C1: DOY153 | D1: DOY160 | E1: DOY167 | F1: DOY174 | G1: DOY181 | H1: DOY188 | I1: DOY195 | J1: DOY203 | K1: DOY209 | L1: DOY217 | M1: DOY223 | N1: DOY230 | O1: DOY237 | P1: DOY244 | Q1: DOY252
A2: 11N | B2: 11 | C2: 14 | D2: 29 | E2: 38 | F2: 49 | G2: 61 | H2: 76 | I2: 81 | J2: 82 | K2: 86 | L2: 91 | M2: 96 | N2: 98 | O2: 108 | P2: 116 | Q2: 121
A3: 11S | B3: 16 | C3: 21 | D3: 33 | E3: 48 | F3: 58 | G3: 64 | H3: 74 | I3: 80 | J3: 84 | K3: 84 | L3: 88 | M3: 93 | N3: 99 | O3: 113 | P3: 122 | Q3: 127
A4: 12N | B4: 17 | C4: 26 | D4: 39 | E4: 46 | F4: 54 | G4: 61 | H4: 67 | I4: 71 | J4: 64 | K4: 65 | L4: 66 | M4: 69 | N4: 74 | O4: 77 | P4: 79 | Q4: 79
A5: 12S | B5: 12 | C5: 18 | D5: 29 | E5: 36 | F5: 46 | G5: 58 | H5: 65 | I5: 68 | J5: 65 | K5: 61 | L5: 64 | M5: 69 | N5: 72 | O5: 78 | P5: 81 | Q5: 83
A6: 13N | B6: 15 | C6: 23 | D6: 39 | E6: 46 | F6: 51 | G6: 55 | H6: 59 | I6: 65 | J6: 69 | K6: 58 | L6: 63 | M6: 68 | N6: 71 | O6: 80 | P6: 84 | Q6: 88
A7: 13S | B7: 15 | C7: 22 | D7: 31 | E7: 44 | F7: 53 | G7: 58 | H7: 61 | I7: 69 | J7: 76 | K7: 73 | L7: 75 | M7: 79 | N7: 82 | O7: 89 | P7: 91 | Q7: 96
A8: 14N | B8: 15 | C8: 21 | D8: 36 | E8: 45 | F8: 51 | G8: 56 | H8: 60 | I8: 69 | J8: 78 | K8: 76 | L8: 81 | M8: 86 | N8: 92 | O8: 103 | P8: 111 | Q8: 113
A9: 14S | B9: 14 | C9: 19 | D9: 33 | E9: 48 | F9: 55 | G9: 57 | H9: 62 | I9: 73 | J9: 80 | K9: 75 | L9: 80 | M9: 82 | N9: 86 | O9: 91 | P9: 98 | Q9: 102
A10: 21N | B10: 13 | C10: 20 | D10: 32 | E10: 40 | F10: 53 | G10: 58 | H10: 63 | I10: 74 | J10: 79 | K10: 79 | L10: 78 | M10: 82 | N10: 85 | O10: 91 | P10: 96 | Q10: 99
A11: 21S | B11: 12 | C11: 21 | D11: 30 | E11: 39 | F11: 52 | G11: 58 | H11: 62 | I11: 71 | J11: 72 | K11: 70 | L11: 70 | M11: 74 | N11: 79 | O11: 83 | P11: 85 | Q11: 86
A12: 22N | B12: 14 | C12: 21 | D12: 33 | E12: 41 | F12: 55 | G12: 61 | H12: 66 | I12: 75 | J12: 77 | K12: 77 | L12: 79 | M12: 85 | N12: 92 | O12: 104 | P12: 113 | Q12: 119
A13: 22S | B13: 13 | C13: 18 | D13: 33 | E13: 40 | F13: 50 | G13: 56 | H13: 59 | I13: 62 | J13: 68 | K13: 64 | L13: 66 | M13: 70 | N13: 75 | O13: 83 | P13: 91 | Q13: 98
... A49: 64S | B49: 11 | C49: 17 | D49: 29 | E49: 39 | F49: 48 | G49: 51 | H49: 54 | I49: 58 | J49: 62 | K49: 65 | L49: 66 | M49: 68 | N49: 71 | O49: 76 | P49: 82 | Q49: 85

Sheet Width
A1: CCID | B1: DOY147 | C1: DOY153 | D1: DOY160 | E1: DOY167 | F1: DOY174 | G1: DOY181 | H1: DOY188 | I1: DOY195 | J1: DOY203 | K1: DOY209 | L1: DOY217 | M1: DOY223 | N1: DOY230 | O1: DOY237 | P1: DOY252
A2: 11N | B2: 9 | C2: 16 | D2: 29 | E2: 33 | F2: 44 | G2: 50 | H2: 55 | I2: 60 | J2: 73 | K2: 74 | L2: 78 | M2: 83 | N2: 89 | O2: 102 | P2: 102
A3: 11S | B3: 13 | C3: 21 | D3: 30 | E3: 39 | F3: 50 | G3: 56 | H3: 60 | I3: 65 | J3: 77 | K3: 73 | L3: 80 | M3: 84 | N3: 87 | O3: 102 | P3: 102
A4: 12N | B4: 15 | C4: 25 | D4: 32 | E4: 40 | F4: 48 | G4: 53 | H4: 55 | I4: 57 | J4: 57 | K4: 59 | L4: 61 | M4: 62 | N4: 65 | O4: 72 | P4: 71
A5: 12S | B5: 9 | C5: 17 | D5: 24 | E5: 31 | F5: 37 | G5: 41 | H5: 44 | I5: 47 | J5: 53 | K5: 50 | L5: 52 | M5: 55 | N5: 58 | O5: 63 | P5: 72
A6: 13N | B6: 15 | C6: 23 | D6: 32 | E6: 38 | F6: 48 | G6: 53 | H6: 55 | I6: 57 | J6: 58 | K6: 52 | L6: 54 | M6: 53 | N6: 54 | O6: 61 | P6: 73
A7: 13S | B7: 11 | C7: 21 | D7: 32 | E7: 40 | F7: 48 | G7: 53 | H7: 57 | I7: 62 | J7: 71 | K7: 63 | L7: 70 | M7: 72 | N7: 76 | O7: 79 | P7: 84
A8: 14N | B8: 12 | C8: 21 | D8: 28 | E8: 36 | F8: 46 | G8: 52 | H8: 55 | I8: 61 | J8: 74 | K8: 66 | L8: 72 | M8: 75 | N8: 79 | O8: 86 | P8: 102
A9: 14S | B9: 9 | C9: 20 | D9: 26 | E9: 38 | F9: 47 | G9: 55 | H9: 61 | I9: 66 | J9: 68 | K9: 61 | L9: 66 | M9: 71 | N9: 77 | O9: 85 | P9: 91
A10: 21N | B10: 10 | C10: 19 | D10: 29 | E10: 37 | F10: 49 | G10: 58 | H10: 62 | I10: 67 | J10: 73 | K10: 68 | L10: 70 | M10: 74 | N10: 78 | O10: 89 | P10: 102
A11: 21S | B11: 9 | C11: 19 | D11: 27 | E11: 35 | F11: 47 | G11: 49 | H11: 54 | I11: 56 | J11: 64 | K11: 62 | L11: 65 | M11: 69 | N11: 72 | O11: 76 | P11: 85
A12: 22N | B12: 10 | C12: 19 | D12: 31 | E12: 38 | F12: 47 | G12: 53 | H12: 58 | I12: 64 | J12: 71 | K12: 68 | L12: 76 | M12: 83 | N12: 88 | O12: 102 | P12: 102
A13: 22S | B13: 11 | C13: 17 | D13: 29 | E13: 36 | F13: 47 | G13: 50 | H13: 53 | I13: 52 | J13: 56 | K13: 53 | L13: 55 | M13: 59 | N13: 66 | O13: 87 | P13: 102
... A49: 64S | B49: 7 | C49: 18 | D49: 24 | E49: 36 | F49: 42 | G49: 45 | H49: 47 | I49: 43 | J49: 51 | K49: 52 | L49: 53 | M49: 55 | N49: 57 | O49: 67 | P49: 73

Sheet LAImeter
A1: CCID | B1: DOY153 | C1: DOY160 | D1: DOY168 | E1: DOY174 | F1: DOY182 | G1: DOY188 | H1: DOY195 | I1: DOY202 | J1: DOY211 | K1: DOY217
A2: 11M | B2: 0.4 | C2: 0.8 | D2: 0.78 | E2: 0.9 | F2: 1.14 | G2: 1.22 | H2: 1.58 | I2: 1.37 | J2: 1.49 | K2: 2.12
A3: 12M | B3: 0.42 | C3: 0.5 | D3: 0.65 | E3: 0.86 | F3: 1.03 | G3: 1.18 | H3: 1.42 | I3: 1.46 | J3: 1.41 | K3: 1.85
A4: 13M | B4: 0.31 | C4: 1.08 | D4: 0.81 | E4: 0.94 | F4: 1.43 | G4: 1.64 | H4: 2.04 | I4: 2.17 | J4: 2.08 | K4: 2.13
A5: 14M | B5: 0.26 | C5: 0.33 | D5: 0.47 | E5: 0.61 | F5: 0.7 | G5: 0.92 | H5: 1.22 | I5: 1.36 | J5: 1.4 | K5: 2.05
A6: 21M | B6: 0.15 | C6: 1.1 | D6: 0.39 | E6: 0.59 | F6: 0.85 | G6: 0.95 | H6: 1.06 | I6: 1.15 | J6: 1.11 | K6: 1.35
A7: 22M | B7: 0.23 | C7: 1.04 | D7: 0.74 | E7: 0.84 | F7: 1.31 | G7: 1.72 | H7: 1.99 | I7: 2.22 | J7: 2.24 | K7: 3.06
A8: 23M | B8: 0.19 | C8: 0.87 | D8: 0.59 | E8: 0.75 | F8: 1.1 | G8: 1.22 | H8: 1.37 | I8: 1.44 | J8: 1.49 | K8: 1.84
A9: 24M | B9: 0.04 | C9: 0.57 | D9: 0.57 | E9: 0.75 | F9: 1.23 | G9: 1.78 | H9: 2.05 | I9: 2.34 | J9: 2.68 | K9: 2.98
A10: 31M | B10: 0.11 | C10: 0.38 | D10: 0.66 | E10: 0.84 | F10: 1.32 | G10: 1.51 | H10: 2.07 | I10: 2.2 | J10: 2.09 | K10: 2.48
A11: 32M | B11: 1.06 | C11: 0.75 | D11: 0.82 | E11: 1.01 | F11: 1.43 | G11: 1.62 | H11: 2.17 | I11: 2.37 | J11: 3.13 | K11: 2.99
A12: 33M | B12: 0.44 | C12: 0.91 | D12: 0.61 | E12: 1.06 | F12: 1.2 | G12: 1.38 | H12: 2.07 | I12: 2.44 | J12: 2.26 | K12: 2.84
A13: 34M | B13: 0.11 | C13: 0.31 | D13: 0.38 | E13: 0.66 | F13: 0.9 | G13: 1.28 | H13: 1.86 | I13: 1.89 | J13: 2.62 | K13: 2.65
... A25: 64M | B25: 0.05 | C25: 0.27 | D25: 0.44 | E25: 0.62 | F25: 1.09 | G25: 1.48 | H25: 1.91 | I25: 2.14 | J25: 2.44 | K25: 2.56

Sheet Density
A1: CCID | B1: PLPD
A2: 11M | B2: 8.967629
A3: 12M | B3: 10.279965
A4: 13M | B4: 8.7489064
A5: 14M | B5: 9.4050744
A6: 21M | B6: 10.71741
A7: 22M | B7: 9.8425197
A8: 23M | B8: 9.623797
A9: 24M | B9: 9.4050744
A10: 31M | B10: 11.154856
A11: 32M | B11: 11.373578
A12: 33M | B12: 10.936133
A13: 34M | B13: 7.6552931
... A25: 64M | B25: 8.5301837

Sheet Develop
A1: CCID | B1: EDATE | C1: PLYRE | D1: PLDOE | E1: LF1D | F1: ADAT | G1: ADOY | H1: NAWF195 | I1: NAWF203 | J1: NAWF209 | K1: NAWF217 | L1: NAWF223 | M1: NAWF230 | N1: NAWF237 | O1: NAWF244 | P1: NAWF252
A2: 11N | F2: 44006 | G2: 176.33333
A3: 11M | H3: 3.5 | I3: 2.1666667 | J3: 1.8333333 | K3: 2.3333333 | L3: 2.8333333 | M3: 3.1666667 | N3: 3.8333333 | O3: 4.1666667 | P3: 4
A4: 11S | F4: 44004 | G4: 174
A5: 11E | B5: 43950 | C5: 2020 | D5: 120.125 | E5: 43959
A6: 12N | F6: 44006 | G6: 176
A7: 12M | H7: 2.5 | I7: 1.5 | J7: 1.3333333 | K7: 1.6666667 | L7: 1.8333333 | M7: 1.5 | N7: 3.5 | O7: 3 | P7: 3
A8: 12S | F8: 44002 | G8: 172
A9: 12E | B9: 43950 | C9: 2020 | D9: 119.83333 | E9: 43959
A10: 13N | F10: 44001 | G10: 171
A11: 13M | H11: 2.6666667 | I11: 1.3333333 | J11: 1.1666667 | K11: 1.8333333 | L11: 2.5 | M11: 2.3333333 | N11: 4 | O11: 3.1666667 | P11: 3.1666667
A12: 13S | F12: 44002 | G12: 172
A13: 13E | B13: 43950 | C13: 2020 | D13: 120 | E13: 43959
A14: 14N | F14: 44002 | G14: 172
A15: 14M | H15: 3.5 | I15: 1.8333333 | J15: 1.6666667 | K15: 2.1666667 | L15: 3 | M15: 3.1666667 | N15: 4.8333333 | O15: 4.5 | P15: 4.5
A16: 14S | F16: 44001 | G16: 171
A17: 14E | B17: 43950 | C17: 2020 | D17: 120.16667 | E17: 43959
A18: 21N | F18: 44006 | G18: 176
A19: 21M | H19: 3.5 | I19: 1.6666667 | J19: 1.5 | K19: 2.1666667 | L19: 2 | M19: 1.8333333 | N19: 4.3333333 | O19: 3.3333333 | P19: 3.1666667
A20: 21S | F20: 44007 | G20: 176.625
A21: 21E | B21: 43950 | C21: 2020 | D21: 120.4 | E21: 43959
A22: 22N | F22: 44003 | G22: 173
A23: 22M | H23: 3.5 | I23: 1.8333333 | J23: 1.5 | K23: 2 | L23: 2.8333333 | M23: 2.8333333 | N23: 5.1666667 | O23: 5 | P23: 4.8333333
A24: 22S | F24: 44004 | G24: 174
A25: 22E | B25: 43951 | C25: 2020 | D25: 120.5 | E25: 43960
A26: 23N | F26: 44003 | G26: 173
A27: 23M | H27: 3 | I27: 1.5 | J27: 1 | K27: 1.6666667 | L27: 2.8333333 | M27: 2.5 | N27: 3.6666667 | O27: 2.8333333 | P27: 3.1666667
A28: 23S | F28: 44001 | G28: 171
A29: 23E | B29: 43951 | C29: 2020 | D29: 120.5 | E29: 43960
A30: 24N | F30: 44004 | G30: 174
A31: 24M | H31: 3 | I31: 2 | J31: 1.3333333 | K31: 1.8333333 | L31: 2.6666667 | M31: 2.5 | N31: 4.5 | O31: 4 | P31: 4.1666667
A32: 24S | F32: 44004 | G32: 174
A33: 24E | B33: 43951 | C33: 2020 | D33: 120.66667 | E33: 43961
A34: 31N | F34: 44007 | G34: 177.11111
A35: 31M | H35: 3.3333333 | I35: 1.8333333 | J35: 1.3333333 | K35: 2 | L35: 2.5 | M35: 2.3333333 | N35: 4.1666667 | O35: 3.8333333 | P35: 3.6666667
A36: 31S | F36: 44006 | G36: 176.33333
A37: 31E | B37: 43950 | C37: 2020 | D37: 120.41667 | E37: 43961
A38: 32N | F38: 44008 | G38: 177.5
A39: 32M | H39: 3.5 | I39: 2 | J39: 1.5 | K39: 2 | L39: 2.6666667 | M39: 3 | N39: 4.6666667 | O39: 4.6666667 | P39: 4.6666667
A40: 32S | F40: 44007 | G40: 176.625
...

Sheet Ordering
A1: 1 | B1: 1 | C1: N | D1: =_xlfn.CONCAT("p",TEXT(A1,"00"),"-",TEXT(B1,"0"),C1) -> p01-1N
A2: 1 | B2: 1 | C2: S | D2: =_xlfn.CONCAT("p",TEXT(A2,"00"),"-",TEXT(B2,"0"),C2) -> p01-1S
A3: 1 | B3: 2 | C3: N | D3: =_xlfn.CONCAT("p",TEXT(A3,"00"),"-",TEXT(B3,"0"),C3) -> p01-2N
A4: 1 | B4: 2 | C4: S | D4: =_xlfn.CONCAT("p",TEXT(A4,"00"),"-",TEXT(B4,"0"),C4) -> p01-2S
A5: 1 | B5: 3 | C5: N | D5: =_xlfn.CONCAT("p",TEXT(A5,"00"),"-",TEXT(B5,"0"),C5) -> p01-3N
A6: 1 | B6: 3 | C6: S | D6: =_xlfn.CONCAT("p",TEXT(A6,"00"),"-",TEXT(B6,"0"),C6) -> p01-3S
A7: 1 | B7: 4 | C7: N | D7: =_xlfn.CONCAT("p",TEXT(A7,"00"),"-",TEXT(B7,"0"),C7) -> p01-4N
A8: 1 | B8: 4 | C8: S | D8: =_xlfn.CONCAT("p",TEXT(A8,"00"),"-",TEXT(B8,"0"),C8) -> p01-4S
A9: 2 | B9: 4 | C9: S | D9: =_xlfn.CONCAT("p",TEXT(A9,"00"),"-",TEXT(B9,"0"),C9) -> p02-4S
A10: 2 | B10: 4 | C10: N | D10: =_xlfn.CONCAT("p",TEXT(A10,"00"),"-",TEXT(B10,"0"),C10) -> p02-4N
A11: 2 | B11: 3 | C11: S | D11: =_xlfn.CONCAT("p",TEXT(A11,"00"),"-",TEXT(B11,"0"),C11) -> p02-3S
A12: 2 | B12: 3 | C12: N | D12: =_xlfn.CONCAT("p",TEXT(A12,"00"),"-",TEXT(B12,"0"),C12) -> p02-3N
... A48: 6 | B48: 1 | C48: N | D48: =_xlfn.CONCAT("p",TEXT(A48,"00"),"-",TEXT(B48,"0"),C48) -> p06-1N

Sheet Blank Data Sheet
A1: 2020 | C1: F13b4 | E1: Cotton | F1: date: | J1: doy:
F2: time:
B3: Canopy Heights & Widths | F3: by:
B5: Canopy Heights flags are Pink and in row 11. Two measurements per plot.
B6: Canopy Measurement points are separate from the LAI measurement point.
B7: Canopy Height & LAI flags may not be exactly at the GPS points - I adjusted depending on skips in rows. SMM
B8: Plot | D8: Flag | E8: Canopy Height (cm) | F8: Canopy Width (cm) | G8: NAWF | H8: NAWF | I8: NAWF
B9: 01- | C9: 1 | D9: North
D10: South
B11: 01- | C11: 2 | D11: North
D12: South
B13: 01- | C13: 3 | D13: North
D14: South
B15: 01- | C15: 4 | D15: North
D16: South
B17: 02- | C17: 4 | D17: South
D18: North
B19: 02- | C19: 3 | D19: South
D20: North
B21: 02- | C21: 2 | D21: South
D22: North
B23: 02- | C23: 1 | D23: South
D24: North
B25: 03- | C25: 1 | D25: North
D26: South
B27: 03- | C27: 2 | D27: North
D28: South
B29: 03- | C29: 3 | D29: North
D30: South
B31: 03- | C31: 4 | D31: North
D32: South
B33: 04- | C33: 4 | D33: South
D34: North
B35: 04- | C35: 3 | D35: South
D36: North
B37: 04- | C37: 2 | D37: South
D38: North
B39: 04- | C39: 1 | D39: South
D40: North
B41: 05- | C41: 1 | D41: North
...

Sheet Height Summary
A1: Summary | B1: 2020 | D1: F13b4 | F1: Cotton
B3: Canopy Heights - Summary
D8: Initials: | F8: SMM | G8: SMM | H8: SMM | I8: SMM | J8: SMM | K8: SMM | L8: SMM | M8: SMM | N8: SMM | O8: SMM | P8: SMM | Q8: SMM | R8: SMM | S8: SMM | T8: SMM | U8: SMM
D9: Date: | F9: 43977 | G9: 43983 | H9: 43990 | I9: 43997 | J9: 44004 | K9: 44011 | L9: 44018 | M9: 44025 | N9: 44033 | O9: 44039 | P9: 44047 | Q9: 44053 | R9: 44060 | S9: 44432 | T9: 44074 | U9: 44082
D10: DOY: | F10: 147 | G10: 153 | H10: 160 | I10: 167 | J10: 174 | K10: 181 | L10: 188 | M10: 195 | N10: 203 | O10: 209 | P10: 217 | Q10: 223 | R10: 230 | S10: 237 | T10: 244 | U10: 252
D11: Time: | F11: 1030-1125 | G11: 0945-1015 | H11: 1100-1145 | I11: 1015-1100 | J11: 1100-1155 | K11: 1000-1045 | L11: 1015-1100 | M11: 1010-1130 | N11: 0925-1010 | O11: 1030-1115 | P11: 0930-1030 | Q11: 0945-1045 | R11: 1000-1115 | S11: 0930-1045 | T11: 0930-1100 | U11: 1000-1115
B12: Plot | D12: Flag | E12: TRT | F12: Height (cm) | G12: Height (cm) | H12: Height (cm) | I12: Height (cm) | J12: Height (cm) | K12: Height (cm) | L12: Height (cm) | M12: Height (cm) | N12: Height (cm) | O12: Height (cm) | P12: Height (cm) | Q12: Height (cm) | R12: Height (cm) | S12: Height (cm) | T12: Height (cm) | U12: Height (cm) | V12: Height (cm) | W12: Height (cm) | X12: Height (cm) | Y12: Height (cm) | Z12: Height (cm) | AA12: Height (cm) | AB12: Height (cm) | AC12: Height (cm) | AD12: Height (cm)
B13: 01- | C13: 1 | D13: North | E13: MDL | F13: 11 | G13: 14 | H13: 29 | I13: 38 | J13: 49 | K13: 61 | L13: 76 | M13: 81 | N13: 82 | O13: 86 | P13: 91 | Q13: 96 | R13: 98 | S13: 108 | T13: 116 | U13: 121
D14: South | E14: MDL | F14: 16 | G14: 21 | H14: 33 | I14: 48 | J14: 58 | K14: 64 | L14: 74 | M14: 80 | N14: 84 | O14: 84 | P14: 88 | Q14: 93 | R14: 99 | S14: 113 | T14: 122 | U14: 127
B15: 01- | C15: 2 | D15: North | E15: DRN | F15: 17 | G15: 26 | H15: 39 | I15: 46 | J15: 54 | K15: 61 | L15: 67 | M15: 71 | N15: 64 | O15: 65 | P15: 66 | Q15: 69 | R15: 74 | S15: 77 | T15: 79 | U15: 79
D16: South | E16: DRN | F16: 12 | G16: 18 | H16: 29 | I16: 36 | J16: 46 | K16: 58 | L16: 65 | M16: 68 | N16: 65 | O16: 61 | P16: 64 | Q16: 69 | R16: 72 | S16: 78 | T16: 81 | U16: 83
B17: 01- | C17: 3 | D17: North | E17: DRN | F17: 15 | G17: 23 | H17: 39 | I17: 46 | J17: 51 | K17: 55 | L17: 59 | M17: 65 | N17: 69 | O17: 58 | P17: 63 | Q17: 68 | R17: 71 | S17: 80 | T17: 84 | U17: 88
D18: South | E18: DRN | F18: 15 | G18: 22 | H18: 31 | I18: 44 | J18: 53 | K18: 58 | L18: 61 | M18: 69 | N18: 76 | O18: 73 | P18: 75 | Q18: 79 | R18: 82 | S18: 89 | T18: 91 | U18: 96
B19: 01- | C19: 4 | D19: North | E19: MDL | F19: 15 | G19: 21 | H19: 36 | I19: 45 | J19: 51 | K19: 56 | L19: 60 | M19: 69 | N19: 78 | O19: 76 | P19: 81 | Q19: 86 | R19: 92 | S19: 103 | T19: 111 | U19: 113
D20: South | E20: MDL | F20: 14 | G20: 19 | H20: 33 | I20: 48 | J20: 55 | K20: 57 | L20: 62 | M20: 73 | N20: 80 | O20: 75 | P20: 80 | Q20: 82 | R20: 86 | S20: 91 | T20: 98 | U20: 102
B21: 02- | C21: 4 | D21: South | E21: SOL | F21: 12 | G21: 17 | H21: 26 | I21: 35 | J21: 44 | K21: 48 | L21: 50 | M21: 54 | N21: 53 | O21: 51 | P21: 53 | Q21: 56 | R21: 60 | S21: 71 | T21: 79 | U21: 84
D22: North | E22: SOL | F22: 13 | G22: 17 | H22: 31 | I22: 39 | J22: 48 | K22: 53 | L22: 57 | M22: 68 | N22: 74 | O22: 68 | P22: 73 | Q22: 74 | R22: 77 | S22: 84 | T22: 90 | U22: 93
B23: 02- | C23: 3 | D23: South | E23: MDL | F23: 10 | G23: 21 | H23: 32 | I23: 40 | J23: 48 | K23: 54 | L23: 61 | M23: 64 | N23: 65 | O23: 62 | P23: 63 | Q23: 64 | R23: 67 | S23: 70 | T23: 69 | U23: 74
D24: North | E24: MDL | F24: 13 | G24: 19 | H24: 32 | I24: 43 | J24: 52 | K24: 59 | L24: 65 | M24: 76 | N24: 79 | O24: 79 | P24: 81 | Q24: 82 | R24: 86 | S24: 92 | T24: 97 | U24: 101
B25: 02- | C25: 2 | D25: South | E25: SOL | F25: 13 | G25: 18 | H25: 33 | I25: 40 | J25: 50 | K25: 56 | L25: 59 | M25: 62 | N25: 68 | O25: 64 | P25: 66 | Q25: 70 | R25: 75 | S25: 83 | T25: 91 | U25: 98
D26: North | E26: SOL | F26: 14 | G26: 21 | H26: 33 | I26: 41 | J26: 55 | K26: 61 | L26: 66 | M26: 75 | N26: 77 | O26: 77 | P26: 79 | Q26: 85 | R26: 92 | S26: 104 | T26: 113 | U26: 119
B27: 02- | C27: 1 | D27: South | E27: VRI | F27: 12 | G27: 21 | H27: 30 | I27: 39 | J27: 52 | K27: 58 | L27: 62 | M27: 71 | N27: 72 | O27: 70 | P27: 70 | Q27: 74 | R27: 79 | S27: 83 | T27: 85 | U27: 86
D28: North | E28: VRI | F28: 13 | G28: 20 | H28: 32 | I28: 40 | J28: 53 | K28: 58 | L28: 63 | M28: 74 | N28: 79 | O28: 79 | P28: 78 | Q28: 82 | R28: 85 | S28: 91 | T28: 96 | U28: 99
B29: 03- | C29: 1 | D29: North | E29: VRI | F29: 13 | G29: 20 | H29: 28 | I29: 38 | J29: 53 | K29: 62 | L29: 69 | M29: 78 | N29: 78 | O29: 79 | P29: 80 | Q29: 82 | R29: 86 | S29: 94 | T29: 100 | U29: 104
D30: South | E30: VRI | F30: 16 | G30: 20 | H30: 34 | I30: 42 | J30: 57 | K30: 60 | L30: 65 | M30: 71 | N30: 75 | O30: 72 | P30: 75 | Q30: 78 | R30: 82 | S30: 89 | T30: 96 | U30: 99
B31: 03- | C31: 2 | D31: North | E31: SOL | F31: 13 | G31: 17 | H31: 32 | I31: 40 | J31: 54 | K31: 59 | L31: 70 | M31: 80 | N31: 82 | O31: 84 | P31: 86 | Q31: 90 | R31: 95 | S31: 106 | T31: 116 | U31: 120
D32: South | E32: SOL | F32: 13 | G32: 18 | H32: 31 | I32: 38 | J32: 52 | K32: 60 | L32: 72 | M32: 80 | N32: 77 | O32: 75 | P32: 78 | Q32: 83 | R32: 89 | S32: 103 | T32: 112 | U32: 116
B33: 03- | C33: 3 | D33: North | E33: MDL | F33: 15 | G33: 21 | H33: 34 | I33: 39 | J33: 54 | K33: 59 | L33: 65 | M33: 71 | N33: 76 | O33: 71 | P33: 75 | Q33: 80 | R33: 86 | S33: 96 | T33: 107 | U33: 111
D34: South | E34: MDL | F34: 13 | G34: 19 | H34: 28 | I34: 35 | J34: 51 | K34: 57 | L34: 63 | M34: 70 | N34: 76 | O34: 79 | P34: 81 | Q34: 86 | R34: 90 | S34: 103 | T34: 115 | U34: 123
B35: 03- | C35: 4 | D35: North | E35: SOL | F35: 14 | G35: 17 | H35: 29 | I35: 34 | J35: 47 | K35: 54 | L35: 59 | M35: 64 | N35: 65 | O35: 67 | P35: 68 | Q35: 71 | R35: 76 | S35: 84 | T35: 93 | U35: 98
D36: South | E36: SOL | F36: 10 | G36: 15 | H36: 28 | I36: 37 | J36: 50 | K36: 59 | L36: 68 | M36: 78 | N36: 78 | O36: 80 | P36: 82 | Q36: 85 | R36: 92 | S36: 100 | T36: 107 | U36: 111
B37: 04- | C37: 4 | D37: South | E37: VRI | F37: 13 | G37: 19 | H37: 30 | I37: 41 | J37: 56 | K37: 59 | L37: 62 | M37: 65 | N37: 66 | O37: 65 | P37: 65 | Q37: 67 | R37: 70 | S37: 76 | T37: 82 | U37: 86
D38: North | E38: VRI | F38: 16 | G38: 20 | H38: 31 | I38: 38 | J38: 43 | K38: 49 | L38: 54 | M38: 60 | N38: 60 | O38: 58 | P38: 63 | Q38: 65 | R38: 71 | S38: 74 | T38: 80 | U38: 84
B39: 04- | C39: 3 | D39: South | E39: DRN | F39: 16 | G39: 23 | H39: 32 | I39: 40 | J39: 48 | K39: 52 | L39: 57 | M39: 62 | N39: 65 | O39: 64 | P39: 69 | Q39: 73 | R39: 78 | S39: 83 | T39: 87 | U39: 89
D40: North | E40: DRN | F40: 15 | G40: 22 | H40: 32 | I40: 45 | J40: 50 | K40: 54 | L40: 56 | M40: 58 | N40: 64 | O40: 66 | P40: 64 | Q40: 71 | R40: 79 | S40: 88 | T40: 95 | U40: 97
B41: 04- | C41: 2 | D41: South | E41: MDL | F41: 14 | G41: 20 | H41: 30 | I41: 42 | J41: 55 | K41: 62 | L41: 76 | M41: 87 | N41: 88 | O41: 85 | P41: 87 | Q41: 92 | R41: 99 | S41: 109 | T41: 118 | U41: 123
D42: North | E42: MDL | F42: 14 | G42: 20 | H42: 31 | I42: 37 | J42: 52 | K42: 60 | L42: 73 | M42: 81 | N42: 84 | O42: 82 | P42: 85 | Q42: 87 | R42: 93 | S42: 118 | T42: 124 | U42: 129
B43: 04- | C43: 1 | D43: South | E43: DRN | F43: 14 | G43: 23 | H43: 36 | I43: 46 | J43: 57 | K43: 69 | L43: 75 | M43: 79 | N43: 77 | O43: 75 | P43: 77 | Q43: 80 | R43: 82 | S43: 89 | T43: 98 | U43: 105
D44: North | E44: DRN | F44: 16 | G44: 22 | H44: 33 | I44: 43 | J44: 56 | K44: 69 | L44: 76 | M44: 82 | N44: 85 | O44: 85 | P44: 86 | Q44: 88 | R44: 91 | S44: 96 | T44: 102 | U44: 108
B45: 05- | C45: 1 | D45: North | E45: SOL | F45: 16 | G45: 24 | H45: 34 | I45: 44 | J45: 55 | K45: 61 | L45: 68 | M45: 76 | N45: 74 | O45: 75 | P45: 77 | Q45: 82 | R45: 85 | S45: 93 | T45: 100 | U45: 105
...

Sheet Cover Summary
A1: Summary | B1: 2020 | D1: F13b4 | F1: Cotton
B3: Canopy Heights - Summary | H3: "--" = closed canopy
D8: Initials: | F8: SMM | G8: SMM | H8: SMM | I8: SMM | J8: SMM | K8: SMM | L8: SMM | M8: SMM | N8: SMM | O8: SMM | P8: SMM | Q8: SMM | R8: SMM | S8: SMM | T8: SMM
D9: Date: | F9: 43977 | G9: 43983 | H9: 43990 | I9: 43997 | J9: 44004 | K9: 44011 | L9: 44018 | M9: 44025 | N9: 44033 | O9: 44039 | P9: 44047 | Q9: 44053 | R9: 44060 | S9: 44432 | T9: 44082
D10: DOY: | F10: 147 | G10: 153 | H10: 160 | I10: 167 | J10: 174 | K10: 181 | L10: 188 | M10: 195 | N10: 203 | O10: 209 | P10: 217 | Q10: 223 | R10: 230 | S10: 237 | T10: 252
D11: Time: | F11: 1030-1125 | G11: 0945-1015 | H11: 1100-1145 | I11: 1015-1100 | J11: 1100-1155 | K11: 1000-1045 | L11: 1015-1100 | M11: 1010-1130 | N11: 0925-1010 | O11: 1030-1115 | P11: 0930-1030 | Q11: 0945-1045 | R11: 1000-1115 | S11: 0930-1045 | T11: 1000-1115
B12: Plot | D12: Flag | E12: TRT | F12: Canopy Width (cm) | G12: Canopy Width (cm) | H12: Canopy Width (cm) | I12: Canopy Width (cm) | J12: Canopy Width (cm) | K12: Canopy Width (cm) | L12: Canopy Width (cm) | M12: Canopy Width (cm) | N12: Canopy Width (cm) | O12: Canopy Width (cm) | P12: Canopy Width (cm) | Q12: Canopy Width (cm) | R12: Canopy Width (cm) | S12: Canopy Width (cm) | T12: Canopy Width (cm) | U12: Canopy Width (cm) | V12: Canopy Width (cm) | W12: Canopy Width (cm) | X12: Canopy Width (cm) | Y12: Canopy Width (cm) | Z12: Canopy Width (cm) | AA12: Canopy Width (cm) | AB12: Canopy Width (cm) | AC12: Canopy Width (cm)
B13: 01- | C13: 1 | D13: North | E13: MDL | F13: 9 | G13: 16 | H13: 29 | I13: 33 | J13: 44 | K13: 50 | L13: 55 | M13: 60 | N13: 73 | O13: 74 | P13: 78 | Q13: 83 | R13: 89 | S13: -- | T13: --
D14: South | E14: MDL | F14: 13 | G14: 21 | H14: 30 | I14: 39 | J14: 50 | K14: 56 | L14: 60 | M14: 65 | N14: 77 | O14: 73 | P14: 80 | Q14: 84 | R14: 87 | S14: -- | T14: --
B15: 01- | C15: 2 | D15: North | E15: DRN | F15: 15 | G15: 25 | H15: 32 | I15: 40 | J15: 48 | K15: 53 | L15: 55 | M15: 57 | N15: 57 | O15: 59 | P15: 61 | Q15: 62 | R15: 65 | S15: 72 | T15: 71
D16: South | E16: DRN | F16: 9 | G16: 17 | H16: 24 | I16: 31 | J16: 37 | K16: 41 | L16: 44 | M16: 47 | N16: 53 | O16: 50 | P16: 52 | Q16: 55 | R16: 58 | S16: 63 | T16: 72
B17: 01- | C17: 3 | D17: North | E17: DRN | F17: 15 | G17: 23 | H17: 32 | I17: 38 | J17: 48 | K17: 53 | L17: 55 | M17: 57 | N17: 58 | O17: 52 | P17: 54 | Q17: 53 | R17: 54 | S17: 61 | T17: 73
D18: South | E18: DRN | F18: 11 | G18: 21 | H18: 32 | I18: 40 | J18: 48 | K18: 53 | L18: 57 | M18: 62 | N18: 71 | O18: 63 | P18: 70 | Q18: 72 | R18: 76 | S18: 79 | T18: 84
B19: 01- | C19: 4 | D19: North | E19: MDL | F19: 12 | G19: 21 | H19: 28 | I19: 36 | J19: 46 | K19: 52 | L19: 55 | M19: 61 | N19: 74 | O19: 66 | P19: 72 | Q19: 75 | R19: 79 | S19: 86 | T19: --
D20: South | E20: MDL | F20: 9 | G20: 20 | H20: 26 | I20: 38 | J20: 47 | K20: 55 | L20: 61 | M20: 66 | N20: 68 | O20: 61 | P20: 66 | Q20: 71 | R20: 77 | S20: 85 | T20: 91
B21: 02- | C21: 4 | D21: South | E21: SOL | F21: 8 | G21: 16 | H21: 23 | I21: 30 | J21: 38 | K21: 40 | L21: 42 | M21: 42 | N21: 48 | O21: 43 | P21: 45 | Q21: 46 | R21: 44 | S21: 59 | T21: 78
D22: North | E22: SOL | F22: 11 | G22: 14 | H22: 27 | I22: 33 | J22: 43 | K22: 49 | L22: 55 | M22: 54 | N22: 61 | O22: 59 | P22: 60 | Q22: 64 | R22: 68 | S22: 76 | T22: 88
B23: 02- | C23: 3 | D23: South | E23: MDL | F23: 6 | G23: 22 | H23: 27 | I23: 35 | J23: 43 | K23: 44 | L23: 45 | M23: 46 | N23: 52 | O23: 48 | P23: 50 | Q23: 51 | R23: 55 | S23: 62 | T23: 72
D24: North | E24: MDL | F24: 8 | G24: 19 | H24: 29 | I24: 36 | J24: 44 | K24: 53 | L24: 60 | M24: 69 | N24: 66 | O24: 61 | P24: 65 | Q24: 69 | R24: 73 | S24: 83 | T24: 93
B25: 02- | C25: 2 | D25: South | E25: SOL | F25: 11 | G25: 17 | H25: 29 | I25: 36 | J25: 47 | K25: 50 | L25: 53 | M25: 52 | N25: 56 | O25: 53 | P25: 55 | Q25: 59 | R25: 66 | S25: 87 | T25: --
D26: North | E26: SOL | F26: 10 | G26: 19 | H26: 31 | I26: 38 | J26: 47 | K26: 53 | L26: 58 | M26: 64 | N26: 71 | O26: 68 | P26: 76 | Q26: 83 | R26: 88 | S26: -- | T26: --
B27: 02- | C27: 1 | D27: South | E27: VRI | F27: 9 | G27: 19 | H27: 27 | I27: 35 | J27: 47 | K27: 49 | L27: 54 | M27: 56 | N27: 64 | O27: 62 | P27: 65 | Q27: 69 | R27: 72 | S27: 76 | T27: 85
D28: North | E28: VRI | F28: 10 | G28: 19 | H28: 29 | I28: 37 | J28: 49 | K28: 58 | L28: 62 | M28: 67 | N28: 73 | O28: 68 | P28: 70 | Q28: 74 | R28: 78 | S28: 89 | T28: --
B29: 03- | C29: 1 | D29: North | E29: VRI | F29: 11 | G29: 21 | H29: 27 | I29: 40 | J29: 46 | K29: 54 | L29: 61 | M29: 64 | N29: 68 | O29: 68 | P29: 71 | Q29: 77 | R29: 83 | S29: 92 | T29: --
D30: South | E30: VRI | F30: 13 | G30: 21 | H30: 30 | I30: 37 | J30: 51 | K30: 59 | L30: 63 | M30: 66 | N30: 68 | O30: 62 | P30: 64 | Q30: 69 | R30: 73 | S30: 82 | T30: 94
B31: 03- | C31: 2 | D31: North | E31: SOL | F31: 11 | G31: 18 | H31: 27 | I31: 33 | J31: 47 | K31: 55 | L31: 64 | M31: 67 | N31: 75 | O31: 68 | P31: 73 | Q31: 82 | R31: 96 | S31: -- | T31: --
D32: South | E32: SOL | F32: 11 | G32: 18 | H32: 28 | I32: 32 | J32: 47 | K32: 56 | L32: 61 | M32: 66 | N32: 70 | O32: 67 | P32: 71 | Q32: 73 | R32: 75 | S32: 84 | T32: --
B33: 03- | C33: 3 | D33: North | E33: MDL | F33: 12 | G33: 20 | H33: 29 | I33: 35 | J33: 45 | K33: 49 | L33: 50 | M33: 55 | N33: 64 | O33: 63 | P33: 67 | Q33: 73 | R33: 80 | S33: 88 | T33: --
D34: South | E34: MDL | F34: 10 | G34: 18 | H34: 25 | I34: 40 | J34: 47 | K34: 52 | L34: 58 | M34: 60 | N34: 69 | O34: 62 | P34: 67 | Q34: 71 | R34: 78 | T34: --
B35: 03- | C35: 4 | D35: North | E35: SOL | F35: 10 | G35: 14 | H35: 25 | I35: 31 | J35: 39 | K35: 42 | L35: 44 | M35: 47 | N35: 56 | O35: 53 | P35: 59 | Q35: 64 | R35: 73 | S35: 97 | T35: 99
D36: South | E36: SOL | F36: 10 | G36: 17 | H36: 23 | I36: 32 | J36: 40 | K36: 49 | L36: 58 | M36: 69 | N36: 73 | O36: 64 | P36: 71 | Q36: 79 | R36: 87 | S36: -- | T36: --
B37: 04- | C37: 4 | D37: South | E37: VRI | F37: 11 | G37: 21 | H37: 28 | I37: 35 | J37: 43 | K37: 48 | L37: 51 | M37: 53 | N37: 57 | O37: 60 | P37: 62 | Q37: 64 | R37: 65 | S37: 78 | T37: 85
D38: North | E38: VRI | F38: 12 | G38: 18 | H38: 27 | I38: 30 | J38: 38 | K38: 45 | L38: 47 | M38: 46 | N38: 51 | O38: 53 | P38: 56 | Q38: 61 | R38: 66 | S38: 76 | T38: 84
B39: 04- | C39: 3 | D39: South | E39: DRN | F39: 12 | G39: 20 | H39: 27 | I39: 34 | J39: 41 | K39: 43 | L39: 46 | M39: 47 | N39: 59 | O39: 58 | P39: 60 | Q39: 66 | R39: 71 | S39: 85 | T39: --
D40: North | E40: DRN | F40: 11 | G40: 18 | H40: 28 | I40: 37 | J40: 41 | K40: 43 | L40: 45 | M40: 45 | N40: 56 | O40: 55 | P40: 59 | Q40: 63 | R40: 70 | S40: 87 | T40: --
B41: 04- | C41: 2 | D41: South | E41: MDL | F41: 10 | G41: 19 | H41: 27 | I41: 35 | J41: 48 | K41: 58 | L41: 66 | M41: 72 | N41: 79 | O41: 79 | P41: 86 | Q41: 95 | R41: -- | S41: -- | T41: --
D42: North | E42: MDL | F42: 11 | G42: 19 | H42: 27 | I42: 30 | J42: 47 | K42: 57 | L42: 67 | M42: 70 | N42: 72 | O42: 69 | P42: 74 | Q42: 80 | R42: 89 | S42: -- | T42: --
B43: 04- | C43: 1 | D43: South | E43: DRN | F43: 12 | G43: 22 | H43: 33 | I43: 40 | J43: 48 | K43: 55 | L43: 62 | M43: 68 | N43: 73 | O43: 65 | P43: 70 | Q43: 76 | R43: 81 | S43: 92 | T43: --
D44: North | E44: DRN | F44: 12 | G44: 23 | H44: 28 | I44: 35 | J44: 50 | K44: 57 | L44: 61 | M44: 65 | N44: 72 | O44: 67 | P44: 72 | Q44: 77 | R44: 84 | S44: 95 | T44: --
B45: 05- | C45: 1 | D45: North | E45: SOL | F45: 12 | G45: 22 | H45: 32 | I45: 40 | J45: 47 | K45: 53 | L45: 58 | M45: 64 | N45: 69 | O45: 64 | P45: 69 | Q45: 75 | R45: 81 | S45: 90 | T45: --
...

Sheet Averages
A1: Averages by treatments
C3: Average Canopy Heights
C5: 43977 | D5: 43983 | E5: 43990 | F5: 43997 | G5: 44004 | H5: 44011 | I5: 44018 | J5: 44025 | K5: 44033 | L5: 44039 | M5: 44047 | N5: 44053 | O5: 44060 | P5: 44074 | Q5: 44082
C6: 147 | D6: 153 | E6: 160 | F6: 167 | G6: 174 | H6: 181 | I6: 188 | J6: 195 | K6: 203 | L6: 209 | M6: 217 | N6: 223 | O6: 230 | P6: 244 | Q6: 252
B7: Ave of all MDL: | C7: =AVERAGEIFS('Height Summary'!F$13:F$60,'Height Summary'!$E$13:$E$60, "MDL") -> 13.5 | D7: =AVERAGEIFS('Height Summary'!G$13:G$60,'Height Summary'!$E$13:$E$60, "MDL") -> 19.285714 | E7: =AVERAGEIFS('Height Summary'!H$13:H$60,'Height Summary'!$E$13:$E$60, "MDL") -> 31.785714 | F7: =AVERAGEIFS('Height Summary'!I$13:I$60,'Height Summary'!$E$13:$E$60, "MDL") -> 41.714286 | G7: =AVERAGEIFS('Height Summary'!J$13:J$60,'Height Summary'!$E$13:$E$60, "MDL") -> 52.071429 | H7: =AVERAGEIFS('Height Summary'!K$13:K$60,'Height Summary'!$E$13:$E$60, "MDL") -> 58.285714 | I7: =AVERAGEIFS('Height Summary'!L$13:L$60,'Height Summary'!$E$13:$E$60, "MDL") -> 65.928571 | J7: =AVERAGEIFS('Height Summary'!M$13:M$60,'Height Summary'!$E$13:$E$60, "MDL") -> 73.214286 | ... O7: =AVERAGEIFS('Height Summary'!R$13:R$60,'Height Summary'!$E$13:$E$60, "MDL") -> 86.428571 | P7: =AVERAGEIFS('Height Summary'!T$13:T$60,'Height Summary'!$E$13:$E$60, "MDL") -> 103.42857 | Q7: =AVERAGEIFS('Height Summary'!U$13:U$60,'Height Summary'!$E$13:$E$60, "MDL") -> 108.21429
B9: Ave of all SOL: | C9: =AVERAGEIFS('Height Summary'!F$13:F$60,'Height Summary'!$E$13:$E$60, "SOL") -> 12.818182 | D9: =AVERAGEIFS('Height Summary'!G$13:G$60,'Height Summary'!$E$13:$E$60, "SOL") -> 18.181818 | E9: =AVERAGEIFS('Height Summary'!H$13:H$60,'Height Summary'!$E$13:$E$60, "SOL") -> 31.090909 | F9: =AVERAGEIFS('Height Summary'!I$13:I$60,'Height Summary'!$E$13:$E$60, "SOL") -> 39.181818 | G9: =AVERAGEIFS('Height Summary'!J$13:J$60,'Height Summary'!$E$13:$E$60, "SOL") -> 50.818182 | H9: =AVERAGEIFS('Height Summary'!K$13:K$60,'Height Summary'!$E$13:$E$60, "SOL") -> 57.818182 | I9: =AVERAGEIFS('Height Summary'!L$13:L$60,'Height Summary'!$E$13:$E$60, "SOL") -> 64.818182 | J9: =AVERAGEIFS('Height Summary'!M$13:M$60,'Height Summary'!$E$13:$E$60, "SOL") -> 72.818182 | ... O9: =AVERAGEIFS('Height Summary'!R$13:R$60,'Height Summary'!$E$13:$E$60, "SOL") -> 84.363636 | P9: =AVERAGEIFS('Height Summary'!T$13:T$60,'Height Summary'!$E$13:$E$60, "SOL") -> 101.63636 | Q9: =AVERAGEIFS('Height Summary'!U$13:U$60,'Height Summary'!$E$13:$E$60, "SOL") -> 106.09091
B11: Ave of all DRN: | C11: =AVERAGEIFS('Height Summary'!F$13:F$60,'Height Summary'!$E$13:$E$60, "DRN") -> 14.5 | D11: =AVERAGEIFS('Height Summary'!G$13:G$60,'Height Summary'!$E$13:$E$60, "DRN") -> 21.5 | E11: =AVERAGEIFS('Height Summary'!H$13:H$60,'Height Summary'!$E$13:$E$60, "DRN") -> 32.9 | F11: =AVERAGEIFS('Height Summary'!I$13:I$60,'Height Summary'!$E$13:$E$60, "DRN") -> 42.3 | G11: =AVERAGEIFS('Height Summary'!J$13:J$60,'Height Summary'!$E$13:$E$60, "DRN") -> 51 | H11: =AVERAGEIFS('Height Summary'!K$13:K$60,'Height Summary'!$E$13:$E$60, "DRN") -> 58 | I11: =AVERAGEIFS('Height Summary'!L$13:L$60,'Height Summary'!$E$13:$E$60, "DRN") -> 63.2 | J11: =AVERAGEIFS('Height Summary'!M$13:M$60,'Height Summary'!$E$13:$E$60, "DRN") -> 68.3 | ... O11: =AVERAGEIFS('Height Summary'!R$13:R$60,'Height Summary'!$E$13:$E$60, "DRN") -> 77.5 | P11: =AVERAGEIFS('Height Summary'!T$13:T$60,'Height Summary'!$E$13:$E$60, "DRN") -> 88.1 | Q11: =AVERAGEIFS('Height Summary'!U$13:U$60,'Height Summary'!$E$13:$E$60, "DRN") -> 91.5
B13: Ave of all VRI: | C13: =AVERAGEIFS('Height Summary'!F$13:F$60,'Height Summary'!$E$13:$E$60, "VRI") -> 13.8 | D13: =AVERAGEIFS('Height Summary'!G$13:G$60,'Height Summary'!$E$13:$E$60, "VRI") -> 20.4 | E13: =AVERAGEIFS('Height Summary'!H$13:H$60,'Height Summary'!$E$13:$E$60, "VRI") -> 31.4 | F13: =AVERAGEIFS('Height Summary'!I$13:I$60,'Height Summary'!$E$13:$E$60, "VRI") -> 42.3 | G13: =AVERAGEIFS('Height Summary'!J$13:J$60,'Height Summary'!$E$13:$E$60, "VRI") -> 53.6 | H13: =AVERAGEIFS('Height Summary'!K$13:K$60,'Height Summary'!$E$13:$E$60, "VRI") -> 60.1 | I13: =AVERAGEIFS('Height Summary'!L$13:L$60,'Height Summary'!$E$13:$E$60, "VRI") -> 65.7 | J13: =AVERAGEIFS('Height Summary'!M$13:M$60,'Height Summary'!$E$13:$E$60, "VRI") -> 72.111111 | ... O13: =AVERAGEIFS('Height Summary'!R$13:R$60,'Height Summary'!$E$13:$E$60, "VRI") -> 79.8 | P13: =AVERAGEIFS('Height Summary'!T$13:T$60,'Height Summary'!$E$13:$E$60, "VRI") -> 90.9 | Q13: =AVERAGEIFS('Height Summary'!U$13:U$60,'Height Summary'!$E$13:$E$60, "VRI") -> 94.7
C17: Average Canopy Widths
C19: 43977 | D19: 43983 | E19: 43990 | F19: 43997 | G19: 44004 | H19: 44011 | I19: 44018 | J19: 44025 | K19: 44033 | L19: 44039 | M19: 44047 | N19: 44053 | O19: 44060 | P19: 44074 | Q19: 44082
C20: 147 | D20: 153 | E20: 160 | F20: 167 | G20: 174 | H20: 181 | I20: 188 | J20: 195 | K20: 203 | L20: 209 | M20: 217 | N20: 223 | O20: 230 | P20: 244 | Q20: 252
B21: Ave of all MDL: | C21: =AVERAGEIFS('Cover Summary'!F$13:F$60,'Cover Summary'!$E$13:$E$60, "MDL") -> 10.142857 | D21: =AVERAGEIFS('Cover Summary'!G$13:G$60,'Cover Summary'!$E$13:$E$60, "MDL") -> 19.357143 | E21: =AVERAGEIFS('Cover Summary'!H$13:H$60,'Cover Summary'!$E$13:$E$60, "MDL") -> 27.928571 | F21: =AVERAGEIFS('Cover Summary'!I$13:I$60,'Cover Summary'!$E$13:$E$60, "MDL") -> 36.142857 | G21: =AVERAGEIFS('Cover Summary'!J$13:J$60,'Cover Summary'!$E$13:$E$60, "MDL") -> 45.714286 | H21: =AVERAGEIFS('Cover Summary'!K$13:K$60,'Cover Summary'!$E$13:$E$60, "MDL") -> 51.357143 | I21: =AVERAGEIFS('Cover Summary'!L$13:L$60,'Cover Summary'!$E$13:$E$60, "MDL") -> 56.357143 | J21: =AVERAGEIFS('Cover Summary'!M$13:M$60,'Cover Summary'!$E$13:$E$60, "MDL") -> 60.5 | ... Q21: =AVERAGEIFS('Cover Summary'!T$13:T$60,'Cover Summary'!$E$13:$E$60, "MDL") -> 80
B23: Ave of all SOL: | C23: =AVERAGEIFS('Cover Summary'!F$13:F$60,'Cover Summary'!$E$13:$E$60, "SOL") -> 10.090909 | D23: =AVERAGEIFS('Cover Summary'!G$13:G$60,'Cover Summary'!$E$13:$E$60, "SOL") -> 17 | E23: =AVERAGEIFS('Cover Summary'!H$13:H$60,'Cover Summary'!$E$13:$E$60, "SOL") -> 27.363636 | F23: =AVERAGEIFS('Cover Summary'!I$13:I$60,'Cover Summary'!$E$13:$E$60, "SOL") -> 34.454545 | G23: =AVERAGEIFS('Cover Summary'!J$13:J$60,'Cover Summary'!$E$13:$E$60, "SOL") -> 44.181818 | H23: =AVERAGEIFS('Cover Summary'!K$13:K$60,'Cover Summary'!$E$13:$E$60, "SOL") -> 50.636364 | I23: =AVERAGEIFS('Cover Summary'!L$13:L$60,'Cover Summary'!$E$13:$E$60, "SOL") -> 56.636364 | J23: =AVERAGEIFS('Cover Summary'!M$13:M$60,'Cover Summary'!$E$13:$E$60, "SOL") -> 61.090909 | ... Q23: =AVERAGEIFS('Cover Summary'!T$13:T$60,'Cover Summary'!$E$13:$E$60, "SOL") -> 88.333333
B25: Ave of all DRN: | C25: =AVERAGEIFS('Cover Summary'!F$13:F$60,'Cover Summary'!$E$13:$E$60, "DRN") -> 11.6 | D25: =AVERAGEIFS('Cover Summary'!G$13:G$60,'Cover Summary'!$E$13:$E$60, "DRN") -> 20.8 | E25: =AVERAGEIFS('Cover Summary'!H$13:H$60,'Cover Summary'!$E$13:$E$60, "DRN") -> 29 | F25: =AVERAGEIFS('Cover Summary'!I$13:I$60,'Cover Summary'!$E$13:$E$60, "DRN") -> 36.3 | G25: =AVERAGEIFS('Cover Summary'!J$13:J$60,'Cover Summary'!$E$13:$E$60, "DRN") -> 44.1 | H25: =AVERAGEIFS('Cover Summary'!K$13:K$60,'Cover Summary'!$E$13:$E$60, "DRN") -> 48.8 | I25: =AVERAGEIFS('Cover Summary'!L$13:L$60,'Cover Summary'!$E$13:$E$60, "DRN") -> 52.3 | J25: =AVERAGEIFS('Cover Summary'!M$13:M$60,'Cover Summary'!$E$13:$E$60, "DRN") -> 55.5 | ... Q25: =AVERAGEIFS('Cover Summary'!T$13:T$60,'Cover Summary'!$E$13:$E$60, "DRN") -> 76.5
B27: Ave of all VRI: | C27: =AVERAGEIFS('Cover Summary'!F$13:F$60,'Cover Summary'!$E$13:$E$60, "VRI") -> 10.6 | D27: =AVERAGEIFS('Cover Summary'!G$13:G$60,'Cover Summary'!$E$13:$E$60, "VRI") -> 19.8 | E27: =AVERAGEIFS('Cover Summary'!H$13:H$60,'Cover Summary'!$E$13:$E$60, "VRI") -> 28.2 | F27: =AVERAGEIFS('Cover Summary'!I$13:I$60,'Cover Summary'!$E$13:$E$60, "VRI") -> 37.7 | G27: =AVERAGEIFS('Cover Summary'!J$13:J$60,'Cover Summary'!$E$13:$E$60, "VRI") -> 46.2 | H27: =AVERAGEIFS('Cover Summary'!K$13:K$60,'Cover Summary'!$E$13:$E$60, "VRI") -> 53 | I27: =AVERAGEIFS('Cover Summary'!L$13:L$60,'Cover Summary'!$E$13:$E$60, "VRI") -> 58 | J27: =AVERAGEIFS('Cover Summary'!M$13:M$60,'Cover Summary'!$E$13:$E$60, "VRI") -> 61.8 | ... Q27: =AVERAGEIFS('Cover Summary'!T$13:T$60,'Cover Summary'!$E$13:$E$60, "VRI") -> 90.142857

Sheet Emergence
A1: 2020 | B1: F13 b4 | C1: Cotton
B3: Emergence
A4: Emergence counts taken at the first Plant Sampling flag location in each plot
C8: # plants per 1 meter (1 meter North of each flag)
B9: Date: | C9: 43950 | E9: 43951 | F9: 43952 | G9: 43957 | H9: 43960 | I9: 43962
B10: DOY: | C10: 120 | E10: 121 | F10: 122 | G10: 127 | H10: 130 | I10: 132
B11: by: | C11: SMM | E11: SMM | F11: SMM | G11: SMM | H11: SMM | I11: SMM
B12: flag point | C12: 1015-1040h | E12: 0915-0940h | F12: 1200-1220h | G12: 1115-1145h | H12: 1000-1040 | I12: 1115-1200h
C13: plants/1 m | D13: plants w/ dirt on their leaves (recently emerged) | E13: plants/1 m | F13: plants/1 m | G13: plants/1 m | H13: plants/1 m | I13: plants/1 m
A14: Northwest corner span 6 | B14: 1-1 | C14: 5 | D14: 2 | E14: 9 | F14: 9 | G14: 10 | H14: 11 | I14: 11
B15: 1-2 | C15: 6 | D15: 2 | E15: 9 | F15: 9 | G15: 10 | H15: 11 | I15: 11
B16: 1-3 | C16: 5 | D16: 1 | E16: 7 | F16: 9 | G16: 10 | H16: 10 | I16: 10
B17: 1-4 | C17: 3 | D17: 0 | E17: 6 | F17: 6 | G17: 7 | H17: 7 | I17: 7
B18: 2-4 | C18: 3 | D18: 0 | E18: 6 | F18: 8 | G18: 10 | H18: 10 | I18: 10
B19: 2-3 | C19: 4 | D19: 0 | E19: 8 | F19: 9 | G19: 11 | H19: 13 | I19: 12
B20: 2-2 | C20: 3 | D20: 0 | E20: 10 | F20: 11 | G20: 12 | H20: 13 | I20: 13
B21: 2-1 | C21: 5 | D21: 2 | E21: 10 | F21: 12 | G21: 13 | H21: 14 | I21: 14
B22: 3-1 | C22: 3 | D22: 0 | E22: 9 | F22: 10 | G22: 10 | H22: 10 | I22: 11
B23: 3-2 | C23: 5 | D23: 1 | E23: 11 | F23: 14 | G23: 16 | H23: 16 | I23: 16
B24: 3-3 | C24: 2 | D24: 0 | E24: 7 | F24: 7 | G24: 8 | H24: 8 | I24: 8
B25: 3-4 | C25: 1 | D25: 0 | E25: 3 | F25: 3 | G25: 8 | H25: 8 | I25: 8
B26: 4-4 | C26: 7 | D26: 4 | E26: 13 | F26: 15 | G26: 15 | H26: 15 | I26: 15
... B36: 6-2 | C36: 4 | D36: 0 | E36: 8 | F36: 9 | G36: 12 | H36: 12 | I36: 12
A37: Northeast corner span 4 | B37: 6-1 | C37: 7 | D37: 4 | E37: 10 | F37: 12 | G37: 11 | H37: 11 | I37: 11
B40: Plot | C40: 120 | D40: 121 | E40: 122 | F40: 127 | G40: 130 | H40: 132 | I40: 0.5 | J40: 50% DOY
B41: 1-1 | C41: 5 | D41: 9 | E41: 9 | F41: 10 | G41: 11 | H41: 11 | I41: =H41/2 -> 5.5 | J41: =C$40+(I41-C41)/(D41-C41)*(D$40-C$40) -> 120.125
B42: 1-2 | C42: 6 | D42: 9 | E42: 9 | F42: 10 | G42: 11 | H42: 11 | I42: =H42/2 -> 5.5 | J42: =C$40+(I42-C42)/(D42-C42)*(D$40-C$40) -> 119.83333
B43: 1-3 | C43: 5 | D43: 7 | E43: 9 | F43: 10 | G43: 10 | H43: 10 | I43: =H43/2 -> 5 | J43: =C$40+(I43-C43)/(D43-C43)*(D$40-C$40) -> 120
B44: 1-4 | C44: 3 | D44: 6 | E44: 6 | F44: 7 | G44: 7 | H44: 7 | I44: =H44/2 -> 3.5 | J44: =C$40+(I44-C44)/(D44-C44)*(D$40-C$40) -> 120.16667
B45: 2-4 | C45: 3 | D45: 6 | E45: 8 | F45: 10 | G45: 10 | H45: 10 | I45: =H45/2 -> 5 | J45: =C$40+(I45-C45)/(D45-C45)*(D$40-C$40) -> 120.66667
B46: 2-3 | C46: 4 | D46: 8 | E46: 9 | F46: 11 | G46: 13 | H46: 12 | I46: =H46/2 -> 6 | J46: =C$40+(I46-C46)/(D46-C46)*(D$40-C$40) -> 120.5
B47: 2-2 | C47: 3 | D47: 10 | E47: 11 | F47: 12 | G47: 13 | H47: 13 | I47: =H47/2 -> 6.5 | J47: =C$40+(I47-C47)/(D47-C47)*(D$40-C$40) -> 120.5
B48: 2-1 | C48: 5 | D48: 10 | E48: 12 | F48: 13 | G48: 14 | H48: 14 | I48: =H48/2 -> 7 | J48: =C$40+(I48-C48)/(D48-C48)*(D$40-C$40) -> 120.4
B49: 3-1 | C49: 3 | D49: 9 | E49: 10 | F49: 10 | G49: 10 | H49: 11 | I49: =H49/2 -> 5.5 | J49: =C$40+(I49-C49)/(D49-C49)*(D$40-C$40) -> 120.41667
B50: 3-2 | C50: 5 | D50: 11 | E50: 14 | F50: 16 | G50: 16 | H50: 16 | I50: =H50/2 -> 8 | J50: =C$40+(I50-C50)/(D50-C50)*(D$40-C$40) -> 120.5
B51: 3-3 | C51: 2 | D51: 7 | E51: 7 | F51: 8 | G51: 8 | H51: 8 | I51: =H51/2 -> 4 | J51: =C$40+(I51-C51)/(D51-C51)*(D$40-C$40) -> 120.4
B52: 3-4 | C52: 1 | D52: 3 | E52: 3 | F52: 8 | G52: 8 | H52: 8 | I52: =H52/2 -> 4 | J52: =E$40+(I52-E52)/(F52-E52)*(F$40-E$40) -> 123
B53: 4-4 | C53: 7 | D53: 13 | E53: 15 | F53: 15 | G53: 15 | H53: 15 | I53: =H53/2 -> 7.5 | J53: =C$40+(I53-C53)/(D53-C53)*(D$40-C$40) -> 120.08333
B54: 4-3 | C54: 9 | D54: 14 | E54: 17 | F54: 17 | G54: 18 | H54: 18 | I54: =H54/2 -> 9 | J54: =C$40+(I54-C54)/(D54-C54)*(D$40-C$40) -> 120
B55: 4-2 | C55: 6 | D55: 9 | E55: 10 | F55: 10 | G55: 10 | H55: 10 | I55: =H55/2 -> 5 | J55: =C$40+(I55-C55)/(D55-C55)*(D$40-C$40) -> 119.66667
...

Sheet 1stLeaf
A1: 2020 | B1: F13 b4 | D1: Cotton
B3: First true leaf
A4: Flags scattered over field, placed 1 per each of the 16 experimental strips (East to West).
A5: Flags placed in a zig-zag pattern from North to South, with flags placed approx in plot 01-4, then 02-3,
A6: 03-2 and 04-1. Then back from plot 05-1 to 08-4. And repeated again from plots 09-4 to 16-4.
B9: Date: | D9: 43957 | F9: 43960 | G9: 43962
B10: DOY: | D10: 127 | F10: 130 | G10: 132
B11: by: | D11: SMM | F11: SMM | G11: SMM
B12: flag point | C12: Total # plants/1 m | D12: plants w/ 1st true leaf | E12: plants with 1st tru leaf not yet unfurled | F12: plants w/ 1st true leaf | G12: plants w/ 1st true leaf | K12: 0.5 | L12: 50% DOY
B13: 1-1 | C13: 11 | D13: 2 | E13: 3 | F13: 8 | G13: 9 | K13: =C13/2 -> 5.5 | L13: =D$10+(K13-D13)/(F13-D13)*(F$10-D$10) -> 128.75 | M13: 11E
B14: 1-2 | C14: 11 | D14: 1 | E14: 2 | F14: 8 | G14: 10 | K14: =C14/2 -> 5.5 | L14: =D$10+(K14-D14)/(F14-D14)*(F$10-D$10) -> 128.92857 | M14: 12E
B15: 1-3 | C15: 10 | D15: 1 | E15: 2 | F15: 7 | G15: 10 | K15: =C15/2 -> 5 | L15: =D$10+(K15-D15)/(F15-D15)*(F$10-D$10) -> 129 | M15: 13E
B16: 1-4 | C16: 7 | D16: 0 | E16: 3 | F16: 6 | G16: 7 | K16: =C16/2 -> 3.5 | L16: =D$10+(K16-D16)/(F16-D16)*(F$10-D$10) -> 128.75 | M16: 14E
B17: 2-4 | C17: 10 | D17: 0 | E17: 1 | F17: 4 | G17: 7 | K17: =C17/2 -> 5 | L17: =F$10+(K17-F17)/(G17-F17)*(G$10-F$10) -> 130.66667 | M17: 24E
B18: 2-3 | C18: 12 | D18: 1 | E18: 1 | F18: 5 | G18: 10 | K18: =C18/2 -> 6 | L18: =F$10+(K18-F18)/(G18-F18)*(G$10-F$10) -> 130.4 | M18: 23E
B19: 2-2 | C19: 13 | D19: 0 | E19: 2 | F19: 6 | G19: 12 | K19: =C19/2 -> 6.5 | L19: =F$10+(K19-F19)/(G19-F19)*(G$10-F$10) -> 130.16667 | M19: 22E
B20: 2-1 | C20: 14 | D20: 0 | E20: 2 | F20: 9 | G20: 13 | K20: =C20/2 -> 7 | L20: =D$10+(K20-D20)/(F20-D20)*(F$10-D$10) -> 129.33333 | M20: 21E
B21: 3-1 | C21: 11 | D21: 0 | E21: 1 | F21: 4 | G21: 10 | K21: =C21/2 -> 5.5 | L21: =F$10+(K21-F21)/(G21-F21)*(G$10-F$10) -> 130.5 | M21: 31E
B22: 3-2 | C22: 16 | D22: 0 | E22: 3 | F22: 8 | G22: 12 | K22: =C22/2 -> 8 | L22: =D$10+(K22-D22)/(F22-D22)*(F$10-D$10) -> 130 | M22: 32E
B23: 3-3 | C23: 8 | D23: 0 | E23: 2 | F23: 7 | G23: 7 | K23: =C23/2 -> 4 | L23: =D$10+(K23-D23)/(F23-D23)*(F$10-D$10) -> 128.71429 | M23: 33E
B24: 3-4 | C24: 8 | D24: 0 | E24: 0 | F24: 2 | G24: 4 | K24: =C24/2 -> 4 | L24: =F$10+(K24-F24)/(G24-F24)*(G$10-F$10) -> 132 | M24: 34E
B25: 4-4 | C25: 15 | D25: 2 | E25: 3 | F25: 11 | G25: 13 | K25: =C25/2 -> 7.5 | L25: =D$10+(K25-D25)/(F25-D25)*(F$10-D$10) -> 128.83333 | M25: 44E
B26: 4-3 | C26: 18 | D26: 2 | E26: 2 | F26: 11 | G26: 15 | K26: =C26/2 -> 9 | L26: =D$10+(K26-D26)/(F26-D26)*(F$10-D$10) -> 129.33333 | M26: 43E
B27: 4-2 | C27: 10 | D27: 2 | E27: 3 | F27: 8 | G27: 9 | K27: =C27/2 -> 5 | L27: =D$10+(K27-D27)/(F27-D27)*(F$10-D$10) -> 128.5 | M27: 42E
B28: 4-1 | C28: 9 | D28: 1 | E28: 2 | F28: 6 | G28: 8 | K28: =C28/2 -> 4.5 | L28: =D$10+(K28-D28)/(F28-D28)*(F$10-D$10) -> 129.1 | M28: 41E
B29: 5-1 | C29: 13 | D29: 1 | E29: 3 | F29: 9 | G29: 12 | K29: =C29/2 -> 6.5 | L29: =D$10+(K29-D29)/(F29-D29)*(F$10-D$10) -> 129.0625 | M29: 51E
B30: 5-2 | C30: 14 | D30: 2 | E30: 2 | F30: 10 | G30: 14 | K30: =C30/2 -> 7 | L30: =D$10+(K30-D30)/(F30-D30)*(F$10-D$10) -> 128.875 | M30: 52E
B31: 5-3 | C31: 11 | D31: 0 | E31: 3 | F31: 8 | G31: 9 | K31: =C31/2 -> 5.5 | L31: =D$10+(K31-D31)/(F31-D31)*(F$10-D$10) -> 129.0625 | M31: 53E
B32: 5-4 | C32: 11 | D32: 0 | E32: 2 | F32: 8 | G32: 10 | K32: =C32/2 -> 5.5 | L32: =D$10+(K32-D32)/(F32-D32)*(F$10-D$10) -> 129.0625 | M32: 54E
B33: 6-4 | C33: 13 | D33: 0 | E33: 1 | F33: 5 | G33: 9 | K33: =C33/2 -> 6.5 | L33: =F$10+(K33-F33)/(G33-F33)*(G$10-F$10) -> 130.75 | M33: 64E
B34: 6-3 | C34: 12 | D34: 1 | E34: 1 | F34: 5 | G34: 10 | K34: =C34/2 -> 6 | L34: =F$10+(K34-F34)/(G34-F34)*(G$10-F$10) -> 130.4 | M34: 63E
B35: 6-2 | C35: 12 | D35: 0 | E35: 1 | F35: 3 | G35: 8 | K35: =C35/2 -> 6 | L35: =F$10+(K35-F35)/(G35-F35)*(G$10-F$10) -> 131.2 | M35: 62E
B36: 6-1 | C36: 11 | D36: 1 | E36: 0 | F36: 3 | G36: 9 | K36: =C36/2 -> 5.5 | L36: =F$10+(K36-F36)/(G36-F36)*(G$10-F$10) -> 130.83333 | M36: 61E

Sheet Counts1
A1: 2020 | B1: F13b4 | D1: Cotton | I1: date: | K1: 43971
B3: Final density counts | I3: by: | J3: SMM
B4: Counted plants in 1.5 meter North of orange "LAI" flag (& same relative location in the rows to the East and West of the flagged row).
D5: 1 row East of flag | F5: 1 row West of flag | K5: 1 row East of flag | L5: At flag | M5: 1 row West of flag
B6: Plot | D6: # plants /1.5 m | E6: # plants /1.5 m | F6: # plants /1.5 m | G6: Ave plants/meter | I6: Plot | K6: # plants /1.5 m | L6: # plants /1.5 m | M6: # plants /1.5 m | N6: Ave plants/meter
B7: 01- | C7: 1 | D7: 15 | E7: 14 | F7: 12 | G7: =(AVERAGE(D7:F7))/1.5 -> 9.1111111 | I7: 04- | J7: 4 | K7: 16 | L7: 23 | M7: 19 | N7: =(AVERAGE(K7:M7))/1.5 -> 12.888889
B8: 01- | C8: 2 | D8: 14 | E8: 16 | F8: 17 | G8: =(AVERAGE(D8:F8))/1.5 -> 10.444444 | I8: 04- | J8: 3 | K8: 14 | L8: 25 | M8: 15 | N8: =(AVERAGE(K8:M8))/1.5 -> 12
B9: 01- | C9: 3 | D9: 13 | E9: 14 | F9: 13 | G9: =(AVERAGE(D9:F9))/1.5 -> 8.8888889 | I9: 04- | J9: 2 | K9: 14 | L9: 16 | M9: 14 | N9: =(AVERAGE(K9:M9))/1.5 -> 9.7777778
B10: 01- | C10: 4 | D10: 14 | E10: 11 | F10: 18 | G10: =(AVERAGE(D10:F10))/1.5 -> 9.5555556 | I10: 04- | J10: 1 | K10: 14 | L10: 16 | M10: 15 | N10: =(AVERAGE(K10:M10))/1.5 -> 10
B11: 02- | C11: 4 | D11: 16 | E11: 15 | F11: 12 | G11: =(AVERAGE(D11:F11))/1.5 -> 9.5555556 | I11: 05- | J11: 1 | K11: 11 | L11: 17 | M11: 22 | N11: =(AVERAGE(K11:M11))/1.5 -> 11.111111
B12: 02- | C12: 3 | D12: 14 | E12: 18 | F12: 12 | G12: =(AVERAGE(D12:F12))/1.5 -> 9.7777778 | I12: 05- | J12: 2 | K12: 19 | L12: 18 | M12: 19 | N12: =(AVERAGE(K12:M12))/1.5 -> 12.444444
B13: 02- | C13: 2 | D13: 12 | E13: 17 | F13: 16 | G13: =(AVERAGE(D13:F13))/1.5 -> 10 | I13: 05- | J13: 3 | K13: 15 | L13: 15 | M13: 14 | N13: =(AVERAGE(K13:M13))/1.5 -> 9.7777778
B14: 02- | C14: 1 | D14: 13 | E14: 16 | F14: 20 | G14: =(AVERAGE(D14:F14))/1.5 -> 10.888889 | I14: 05- | J14: 4 | K14: 14 | L14: 16 | M14: 2 | N14: =(AVERAGE(K14:M14))/1.5 -> 7.1111111
B15: 03- | C15: 1 | D15: 20 | E15: 15 | F15: 16 | G15: =(AVERAGE(D15:F15))/1.5 -> 11.333333 | I15: 06- | J15: 4 | K15: 13 | L15: 16 | M15: 10 | N15: =(AVERAGE(K15:M15))/1.5 -> 8.6666667
B16: 03- | C16: 2 | D16: 14 | E16: 23 | F16: 15 | G16: =(AVERAGE(D16:F16))/1.5 -> 11.555556 | I16: 06- | J16: 3 | K16: 12 | L16: 15 | M16: 15 | N16: =(AVERAGE(K16:M16))/1.5 -> 9.3333333
B17: 03- | C17: 3 | D17: 23 | E17: 10 | F17: 17 | G17: =(AVERAGE(D17:F17))/1.5 -> 11.111111 | I17: 06- | J17: 2 | K17: 12 | L17: 14 | M17: 16 | N17: =(AVERAGE(K17:M17))/1.5 -> 9.3333333
B18: 03- | C18: 4 | D18: 13 | E18: 12 | F18: 10 | G18: =(AVERAGE(D18:F18))/1.5 -> 7.7777778 | I18: 06- | J18: 1 | K18: 16 | L18: 16 | M18: 19 | N18: =(AVERAGE(K18:M18))/1.5 -> 11.333333
K21: =AVERAGE(D7:F18,K7:M18)/(1.5*1.016) -> 9.9974482

Sheet Counts2
G2: PLPD
A3: 01- | B3: 1 | C3: 11 | D3: 15 | E3: 14 | F3: 12 | G3: =SUM(D3:F3)/(1.5*1.016*3) -> 8.967629
A4: 01- | B4: 2 | C4: 12 | D4: 14 | E4: 16 | F4: 17 | G4: =SUM(D4:F4)/(1.5*1.016*3) -> 10.279965
A5: 01- | B5: 3 | C5: 13 | D5: 13 | E5: 14 | F5: 13 | G5: =SUM(D5:F5)/(1.5*1.016*3) -> 8.7489064
A6: 01- | B6: 4 | C6: 14 | D6: 14 | E6: 11 | F6: 18 | G6: =SUM(D6:F6)/(1.5*1.016*3) -> 9.4050744
A7: 02- | B7: 4 | C7: 24 | D7: 16 | E7: 15 | F7: 12 | G7: =SUM(D7:F7)/(1.5*1.016*3) -> 9.4050744
A8: 02- | B8: 3 | C8: 23 | D8: 14 | E8: 18 | F8: 12 | G8: =SUM(D8:F8)/(1.5*1.016*3) -> 9.623797
A9: 02- | B9: 2 | C9: 22 | D9: 12 | E9: 17 | F9: 16 | G9: =SUM(D9:F9)/(1.5*1.016*3) -> 9.8425197
A10: 02- | B10: 1 | C10: 21 | D10: 13 | E10: 16 | F10: 20 | G10: =SUM(D10:F10)/(1.5*1.016*3) -> 10.71741
A11: 03- | B11: 1 | C11: 31 | D11: 20 | E11: 15 | F11: 16 | G11: =SUM(D11:F11)/(1.5*1.016*3) -> 11.154856
A12: 03- | B12: 2 | C12: 32 | D12: 14 | E12: 23 | F12: 15 | G12: =SUM(D12:F12)/(1.5*1.016*3) -> 11.373578
A13: 03- | B13: 3 | C13: 33 | D13: 23 | E13: 10 | F13: 17 | G13: =SUM(D13:F13)/(1.5*1.016*3) -> 10.936133
A14: 03- | B14: 4 | C14: 34 | D14: 13 | E14: 12 | F14: 10 | G14: =SUM(D14:F14)/(1.5*1.016*3) -> 7.6552931
... A26: 06- | B26: 1 | C26: 61 | D26: 16 | E26: 16 | F26: 19 | G26: =SUM(D26:F26)/(1.5*1.016*3) -> 11.154856

Sheet Flowering
B1: 2020 | D1: F13b4 | F1: Cotton
B3: Flowering
D8: Initials: | F8: SMM | G8: SMM
D9: Date: | F9: 44004 | G9: 29 June 202
D10: DOY: | F10: 174 | G10: 181
D11: Time: | F11: 1100-1155 | G11: 1000-1045
B12: Plot | D12: Flag | E12: TRT | F12: # plants flowering/ 10 plants | G12: # plants flowering/ 10 plants | J12: 50% DOY
B13: 01- | C13: 1 | D13: North | E13: MDL | F13: 3 | G13: 9 | I13: 5 | J13: =IF(F13<=5,F$10+(I13-F13)/(G13-F13)*(G$10-F$10),"") -> 176.33333 | K13: 11N
D14: South | E14: MDL | F14: 5 | G14: 10 | I14: 5 | J14: =IF(F14<=5,F$10+(I14-F14)/(G14-F14)*(G$10-F$10),"") -> 174 | K14: 11S
B15: 01- | C15: 2 | D15: North | E15: DRN | F15: 3 | G15: 10 | I15: 5 | J15: =IF(F15<=5,F$10+(I15-F15)/(G15-F15)*(G$10-F$10),"") -> 176 | K15: 12N
D16: South | E16: DRN | F16: 7 | G16: 10 | I16: 5 | J16: 172 | K16: 12S
B17: 01- | C17: 3 | D17: North | E17: DRN | F17: 8 | G17: 10 | I17: 5 | J17: 171 | K17: 13N
D18: South | E18: DRN | F18: 7 | G18: 10 | I18: 5 | J18: 172 | K18: 13S
B19: 01- | C19: 4 | D19: North | E19: MDL | F19: 7 | G19: 10 | I19: 5 | J19: 172 | K19: 14N
D20: South | E20: MDL | F20: 8 | G20: 10 | I20: 5 | J20: 171 | K20: 14S
B21: 02- | C21: 4 | D21: South | E21: SOL | F21: 5 | G21: 10 | I21: 5 | J21: =IF(F21<=5,F$10+(I21-F21)/(G21-F21)*(G$10-F$10),"") -> 174 | K21: 24S
D22: North | E22: SOL | F22: 5 | G22: 10 | I22: 5 | J22: =IF(F22<=5,F$10+(I22-F22)/(G22-F22)*(G$10-F$10),"") -> 174 | K22: 24N
B23: 02- | C23: 3 | D23: South | E23: MDL | F23: 8 | G23: 10 | I23: 5 | J23: 171 | K23: 23S
D24: North | E24: MDL | F24: 6 | G24: 10 | I24: 5 | J24: 173 | K24: 23N
B25: 02- | C25: 2 | D25: South | E25: SOL | F25: 5 | G25: 10 | I25: 5 | J25: =IF(F25<=5,F$10+(I25-F25)/(G25-F25)*(G$10-F$10),"") -> 174 | K25: 22S
D26: North | E26: SOL | F26: 6 | G26: 10 | I26: 5 | J26: 173 | K26: 22N
B27: 02- | C27: 1 | D27: South | E27: VRI | F27: 2 | G27: 10 | I27: 5 | J27: =IF(F27<=5,F$10+(I27-F27)/(G27-F27)*(G$10-F$10),"") -> 176.625 | K27: 21S
D28: North | E28: VRI | F28: 3 | G28: 10 | I28: 5 | J28: =IF(F28<=5,F$10+(I28-F28)/(G28-F28)*(G$10-F$10),"") -> 176 | K28: 21N
B29: 03- | C29: 1 | D29: North | E29: VRI | F29: 1 | G29: 10 | I29: 5 | J29: =IF(F29<=5,F$10+(I29-F29)/(G29-F29)*(G$10-F$10),"") -> 177.11111 | K29: 31N
D30: South | E30: VRI | F30: 3 | G30: 9 | I30: 5 | J30: =IF(F30<=5,F$10+(I30-F30)/(G30-F30)*(G$10-F$10),"") -> 176.33333 | K30: 31S
B31: 03- | C31: 2 | D31: North | E31: SOL | F31: 1 | G31: 9 | I31: 5 | J31: =IF(F31<=5,F$10+(I31-F31)/(G31-F31)*(G$10-F$10),"") -> 177.5 | K31: 32N
D32: South | E32: SOL | F32: 2 | G32: 10 | I32: 5 | J32: =IF(F32<=5,F$10+(I32-F32)/(G32-F32)*(G$10-F$10),"") -> 176.625 | K32: 32S
B33: 03- | C33: 3 | D33: North | E33: MDL | F33: 0 | G33: 8 | I33: 5 | J33: =IF(F33<=5,F$10+(I33-F33)/(G33-F33)*(G$10-F$10),"") -> 178.375 | K33: 33N
D34: South | E34: MDL | F34: 5 | G34: 10 | I34: 5 | J34: =IF(F34<=5,F$10+(I34-F34)/(G34-F34)*(G$10-F$10),"") -> 174 | K34: 33S
B35: 03- | C35: 4 | D35: North | E35: SOL | F35: 3 | G35: 10 | I35: 5 | J35: =IF(F35<=5,F$10+(I35-F35)/(G35-F35)*(G$10-F$10),"") -> 176 | K35: 34N
D36: South | E36: SOL | F36: 2 | G36: 9 | I36: 5 | J36: =IF(F36<=5,F$10+(I36-F36)/(G36-F36)*(G$10-F$10),"") -> 177 | K36: 34S
B37: 04- | C37: 4 | D37: South | E37: VRI | F37: 7 | G37: 10 | I37: 5 | J37: 172 | K37: 44S
D38: North | E38: VRI | F38: 6 | G38: 10 | I38: 5 | J38: 173 | K38: 44N
B39: 04- | C39: 3 | D39: South | E39: DRN | F39: 2 | G39: 10 | I39: 5 | J39: =IF(F39<=5,F$10+(I39-F39)/(G39-F39)*(G$10-F$10),"") -> 176.625 | K39: 43S
D40: North | E40: DRN | F40: 5 | G40: 10 | I40: 5 | J40: =IF(F40<=5,F$10+(I40-F40)/(G40-F40)*(G$10-F$10),"") -> 174 | K40: 43N
B41: 04- | C41: 2 | D41: South | E41: MDL | F41: 1 | G41: 8 | I41: 5 | J41: =IF(F41<=5,F$10+(I41-F41)/(G41-F41)*(G$10-F$10),"") -> 178 | K41: 42S
D42: North | E42: MDL | F42: 6 | G42: 10 | I42: 5 | J42: 173 | K42: 42N
B43: 04- | C43: 1 | D43: South | E43: DRN | F43: 8 | G43: 10 | I43: 5 | J43: 171 | K43: 41S
D44: North | E44: DRN | F44: 6 | G44: 10 | I44: 5 | J44: 173 | K44: 41N
B45: 05- | C45: 1 | D45: North | E45: SOL | F45: 6 | G45: 10 | I45: 5 | J45: 173 | K45: 51N
...

Sheet NAWFd209
A1: 2020 | B1: F13b4 | D1: Cotton | F1: date: | G1: 44039 | H1: d209
B3: Nodes Above White Flower | F3: by: | G3: SMM
B4: Counting the nodes of the upermost white flower in the 1st position of 6 plants per plot - between the 2 pink flags that mark the location for the Northern and Southern plant heights in a plot.
B6: Plot | D6: NAWF | E6: NAWF | F6: NAWF | G6: NAWF | H6: NAWF | I6: NAWF | J6: Average
B7: 01- | C7: 1 | D7: 1 | E7: 2 | F7: 2 | G7: 2 | H7: 2 | I7: 2 | J7: =AVERAGE(D7:I7) -> 1.8333333
B8: 01- | C8: 2 | D8: 1 | E8: 2 | F8: 1 | G8: 1 | H8: 2 | I8: 1 | J8: =AVERAGE(D8:I8) -> 1.3333333
B9: 01- | C9: 3 | D9: 1 | E9: 2 | F9: 2 | G9: 0 | H9: 1 | I9: 1 | J9: =AVERAGE(D9:I9) -> 1.1666667
B10: 01- | C10: 4 | D10: 2 | E10: 2 | F10: 2 | G10: 2 | H10: 1 | I10: 1 | J10: =AVERAGE(D10:I10) -> 1.6666667
B11: 02- | C11: 4 | D11: 1 | E11: 2 | F11: 1 | G11: 1 | H11: 2 | I11: 1 | J11: =AVERAGE(D11:I11) -> 1.3333333
B12: 02- | C12: 3 | D12: 1 | E12: 1 | F12: 1 | G12: 1 | H12: 1 | I12: 1 | J12: =AVERAGE(D12:I12) -> 1
B13: 02- | C13: 2 | D13: 2 | E13: 1 | F13: 2 | G13: 1 | H13: 2 | I13: 1 | J13: =AVERAGE(D13:I13) -> 1.5
B14: 02- | C14: 1 | D14: 2 | E14: 2 | F14: 2 | G14: 0 | H14: 1 | I14: 2 | J14: =AVERAGE(D14:I14) -> 1.5
B15: 03- | C15: 1 | D15: 1 | E15: 1 | F15: 1 | G15: 2 | H15: 2 | I15: 1 | J15: =AVERAGE(D15:I15) -> 1.3333333
B16: 03- | C16: 2 | D16: 2 | E16: 1 | F16: 2 | G16: 1 | H16: 2 | I16: 1 | J16: =AVERAGE(D16:I16) -> 1.5
B17: 03- | C17: 3 | D17: 2 | E17: 2 | F17: 1 | G17: 2 | H17: 1 | I17: 2 | J17: =AVERAGE(D17:I17) -> 1.6666667
B18: 03- | C18: 4 | D18: 2 | E18: 3 | F18: 3 | G18: 2 | H18: 2 | I18: 3 | J18: =AVERAGE(D18:I18) -> 2.5
... B30: 06- | C30: 1 | D30: 3 | E30: 2 | F30: 1 | G30: 1 | H30: 1 | I30: 1 | J30: =AVERAGE(D30:I30) -> 1.5

Sheet NAWFd217
A1: 2020 | B1: F13b4 | D1: Cotton | F1: date: | G1: 44047 | H1: d232
B3: Nodes Above White Flower | F3: by: | G3: SMM
B4: Counting the nodes of the upermost white flower in the 1st position of 6 plants per plot - between the 2 pink flags that mark the location for the Northern and Southern plant heights in a plot.
B6: Plot | D6: NAWF | E6: NAWF | F6: NAWF | G6: NAWF | H6: NAWF | I6: NAWF | J6: Average
B7: 01- | C7: 1 | D7: 2 | E7: 2 | F7: 3 | G7: 2 | H7: 3 | I7: 2 | J7: =AVERAGE(D7:I7) -> 2.3333333
B8: 01- | C8: 2 | D8: 1 | E8: 2 | F8: 2 | G8: 2 | H8: 1 | I8: 2 | J8: =AVERAGE(D8:I8) -> 1.6666667
B9: 01- | C9: 3 | D9: 2 | E9: 2 | F9: 3 | G9: 1 | H9: 2 | I9: 1 | J9: =AVERAGE(D9:I9) -> 1.8333333
B10: 01- | C10: 4 | D10: 3 | E10: 2 | F10: 2 | G10: 3 | H10: 2 | I10: 1 | J10: =AVERAGE(D10:I10) -> 2.1666667
B11: 02- | C11: 4 | D11: 2 | E11: 3 | F11: 2 | G11: 1 | H11: 2 | I11: 1 | J11: =AVERAGE(D11:I11) -> 1.8333333
B12: 02- | C12: 3 | D12: 1 | E12: 2 | F12: 2 | G12: 1 | H12: 2 | I12: 2 | J12: =AVERAGE(D12:I12) -> 1.6666667
B13: 02- | C13: 2 | D13: 3 | E13: 2 | F13: 2 | G13: 1 | H13: 2 | I13: 2 | J13: =AVERAGE(D13:I13) -> 2
B14: 02- | C14: 1 | D14: 2 | E14: 3 | F14: 2 | G14: 1 | H14: 2 | I14: 3 | J14: =AVERAGE(D14:I14) -> 2.1666667
B15: 03- | C15: 1 | D15: 2 | E15: 2 | F15: 1 | G15: 3 | H15: 2 | I15: 2 | J15: =AVERAGE(D15:I15) -> 2
B16: 03- | C16: 2 | D16: 2 | E16: 2 | F16: 3 | G16: 1 | H16: 2 | I16: 2 | J16: =AVERAGE(D16:I16) -> 2
B17: 03- | C17: 3 | D17: 2 | E17: 2 | F17: 2 | G17: 2 | H17: 2 | I17: 2 | J17: =AVERAGE(D17:I17) -> 2
B18: 03- | C18: 4 | D18: 3 | E18: 3 | F18: 4 | G18: 2 | H18: 3 | I18: 3 | J18: =AVERAGE(D18:I18) -> 3
... B30: 06- | C30: 1 | D30: 3 | E30: 3 | F30: 2 | G30: 3 | H30: 2 | I30: 2 | J30: =AVERAGE(D30:I30) -> 2.5

Sheet NAWFd223
A1: 2020 | B1: F13b4 | D1: Cotton | F1: date: | G1: 44053 | H1: d223
B3: Nodes Above White Flower | F3: by: | G3: SMM
B4: Counting the nodes of the upermost white flower in the 1st position of 6 plants per plot - between the 2 pink flags that mark the location for the Northern and Southern plant heights in a plot.
D5: Starting to have a hard time finding enough white flowers in the 1st position.
B6: Plot | D6: NAWF | E6: NAWF | F6: NAWF | G6: NAWF | H6: NAWF | I6: NAWF | J6: Average
B7: 01- | C7: 1 | D7: 3 | E7: 2 | F7: 4 | G7: 3 | H7: 3 | I7: 2 | J7: =AVERAGE(D7:I7) -> 2.8333333
B8: 01- | C8: 2 | D8: 2 | E8: 2 | F8: 1 | G8: 3 | H8: 2 | I8: 1 | J8: =AVERAGE(D8:I8) -> 1.8333333
B9: 01- | C9: 3 | D9: 2 | E9: 3 | F9: 2 | G9: 3 | H9: 3 | I9: 2 | J9: =AVERAGE(D9:I9) -> 2.5
B10: 01- | C10: 4 | D10: 3 | E10: 4 | F10: 3 | G10: 3 | H10: 2 | I10: 3 | J10: =AVERAGE(D10:I10) -> 3
B11: 02- | C11: 4 | D11: 2 | E11: 3 | F11: 3 | G11: 3 | H11: 2 | I11: 3 | J11: =AVERAGE(D11:I11) -> 2.6666667
B12: 02- | C12: 3 | D12: 2 | E12: 2 | F12: 3 | G12: 3 | H12: 4 | I12: 3 | J12: =AVERAGE(D12:I12) -> 2.8333333
B13: 02- | C13: 2 | D13: 3 | E13: 3 | F13: 2 | G13: 3 | H13: 3 | I13: 3 | J13: =AVERAGE(D13:I13) -> 2.8333333
B14: 02- | C14: 1 | D14: 2 | E14: 2 | F14: 3 | G14: 2 | H14: 1 | I14: 2 | J14: =AVERAGE(D14:I14) -> 2
B15: 03- | C15: 1 | D15: 3 | E15: 2 | F15: 2 | G15: 3 | H15: 2 | I15: 3 | J15: =AVERAGE(D15:I15) -> 2.5
B16: 03- | C16: 2 | D16: 3 | E16: 3 | F16: 2 | G16: 2 | H16: 3 | I16: 3 | J16: =AVERAGE(D16:I16) -> 2.6666667
B17: 03- | C17: 3 | D17: 3 | E17: 3 | F17: 2 | G17: 3 | H17: 2 | I17: 3 | J17: =AVERAGE(D17:I17) -> 2.6666667
B18: 03- | C18: 4 | D18: 3 | E18: 2 | F18: 2 | G18: 3 | H18: 3 | I18: 2 | J18: =AVERAGE(D18:I18) -> 2.5
... B30: 06- | C30: 1 | D30: 2 | E30: 2 | F30: 3 | G30: 2 | H30: 1 | I30: 2 | J30: =AVERAGE(D30:I30) -> 2

Sheet NAWFd230
A1: 2020 | B1: F13b4 | D1: Cotton | F1: date: | G1: 44060 | H1: d230
B3: Nodes Above White Flower | F3: by: | G3: SMM
B4: Counting the nodes of the upermost white flower in the 1st position of 6 plants per plot - between the 2 pink flags that mark the location for the Northern and Southern plant heights in a plot.
B6: Plot | D6: NAWF | E6: NAWF | F6: NAWF | G6: NAWF | H6: NAWF | I6: NAWF | J6: Average
B7: 01- | C7: 1 | D7: 4 | E7: 3 | F7: 3 | G7: 3 | H7: 3 | I7: 3 | J7: =AVERAGE(D7:I7) -> 3.1666667
B8: 01- | C8: 2 | D8: 2 | E8: 1 | F8: 1 | G8: 2 | H8: -- | I8: -- | J8: =AVERAGE(D8:I8) -> 1.5 | K8: "--" = couldn’t find enough white flowers in the 1st position on a branch
B9: 01- | C9: 3 | D9: 2 | E9: 3 | F9: 2 | G9: 3 | H9: 2 | I9: 2 | J9: =AVERAGE(D9:I9) -> 2.3333333
B10: 01- | C10: 4 | D10: 3 | E10: 3 | F10: 4 | G10: 3 | H10: 3 | I10: 3 | J10: =AVERAGE(D10:I10) -> 3.1666667
B11: 02- | C11: 4 | D11: 2 | E11: 2 | F11: 3 | G11: 3 | H11: 3 | I11: 2 | J11: =AVERAGE(D11:I11) -> 2.5
B12: 02- | C12: 3 | D12: 2 | E12: 2 | F12: 3 | G12: 3 | H12: 2 | I12: 3 | J12: =AVERAGE(D12:I12) -> 2.5
B13: 02- | C13: 2 | D13: 4 | E13: 3 | F13: 3 | G13: 3 | H13: 2 | I13: 2 | J13: =AVERAGE(D13:I13) -> 2.8333333
B14: 02- | C14: 1 | D14: 2 | E14: 2 | F14: 2 | G14: 1 | H14: 2 | I14: 2 | J14: =AVERAGE(D14:I14) -> 1.8333333
B15: 03- | C15: 1 | D15: 2 | E15: 3 | F15: 2 | G15: 2 | H15: 3 | I15: 2 | J15: =AVERAGE(D15:I15) -> 2.3333333
B16: 03- | C16: 2 | D16: 4 | E16: 3 | F16: 3 | G16: 3 | H16: 3 | I16: 2 | J16: =AVERAGE(D16:I16) -> 3
B17: 03- | C17: 3 | D17: 3 | E17: 4 | F17: 3 | G17: 2 | H17: 2 | I17: 3 | J17: =AVERAGE(D17:I17) -> 2.8333333
B18: 03- | C18: 4 | D18: 3 | E18: 2 | F18: 3 | G18: 2 | H18: 2 | I18: 3 | J18: =AVERAGE(D18:I18) -> 2.5
B19: 04- | C19: 4 | D19: 1 | E19: 1 | F19: 2 | G19: 2 | H19: 2 | I19: 2 | J19: =AVERAGE(D19:I19) -> 1.6666667
B20: 04- | C20: 3 | D20: 2 | E20: 3 | F20: 3 | G20: 2 | H20: 3 | I20: 3 | J20: =AVERAGE(D20:I20) -> 2.6666667
... B30: 06- | C30: 1 | D30: 1 | E30: 2 | F30: 2 | G30: 1 | H30: 2 | I30: 2 | J30: =AVERAGE(D30:I30) -> 1.6666667

Sheet NAWFd237
A1: 2020 | B1: F13b4 | D1: Cotton | F1: date: | G1: 44067 | H1: d237
B3: Nodes Above White Flower | F3: by: | G3: SMM
B4: Counting the nodes of the upermost white flower in the 1st position of 6 plants per plot - between the 2 pink flags that mark the location for the Northern and Southern plant heights in a plot.
B6: Plot | D6: NAWF | E6: NAWF | F6: NAWF | G6: NAWF | H6: NAWF | I6: NAWF | J6: Average
