Workbook

Sheet PlantDF
A1: Year | B1: DOY | C1: PSDATE | D1: SID | E1: NumPlts | F1: Height | G1: PHTD1 | H1: MSNODE1 | I1: PFNODE1 | J1: FRBNUM1 | K1: ABSNUM | L1: SQRNUM | M1: FLRNUM | N1: GBNUM | O1: MBNUM | P1: LWPD | Q1: SWPD | R1: CWPD | S1: LWAD | T1: SWAD | U1: MBWAD | V1: PWAD | W1: CWAD | X1: LAID_LAB
A2: 2020 | B2: 147 | C2: 43977 | D2: p11-S1 | E2: 1 | F2: 16 | G2: =F2/100 -> 0.16 | H2: 5 | J2: 0 | K2: 0 | L2: 0 | M2: 0 | N2: 0 | O2: 0 | P2: 0.96 | Q2: 0.39 | R2: 1.35 | S2: 96 | T2: 39 | U2: 0 | V2: 0 | W2: =SUM(S2,T2,V2) -> 135 | X2: 0.10037
A3: 2020 | B3: 147 | C3: 43977 | D3: p12-S1 | E3: 1 | F3: 15 | G3: =F3/100 -> 0.15 | H3: 5 | J3: 0 | K3: 0 | L3: 0 | M3: 0 | N3: 0 | O3: 0 | P3: 1.02 | Q3: 0.33 | R3: 1.35 | S3: 102 | T3: 33 | U3: 0 | V3: 0 | W3: =SUM(S3,T3,V3) -> 135 | X3: 0.09822
A4: 2020 | B4: 147 | C4: 43977 | D4: p13-S1 | E4: 1 | F4: 12 | G4: =F4/100 -> 0.12 | H4: 5 | J4: 0 | K4: 0 | L4: 0 | M4: 0 | N4: 0 | O4: 0 | P4: 0.46 | Q4: 0.16 | R4: 0.62 | S4: 46 | T4: 16 | U4: 0 | V4: 0 | W4: =SUM(S4,T4,V4) -> 62 | X4: 0.05279
A5: 2020 | B5: 147 | C5: 43977 | D5: p14-S1 | E5: 1 | F5: 14 | G5: =F5/100 -> 0.14 | H5: 6 | J5: 0 | K5: 0 | L5: 0 | M5: 0 | N5: 0 | O5: 0 | P5: 0.73 | Q5: 0.29 | R5: 1.02 | S5: 73 | T5: 29 | U5: 0 | V5: 0 | W5: =SUM(S5,T5,V5) -> 102 | X5: 0.0876
A6: 2020 | B6: 147 | C6: 43977 | D6: p21-S1 | E6: 1 | F6: 14 | G6: =F6/100 -> 0.14 | H6: 6 | J6: 0 | K6: 0 | L6: 0 | M6: 0 | N6: 0 | O6: 0 | P6: 0.66 | Q6: 0.24 | R6: 0.9 | S6: 66 | T6: 24 | U6: 0 | V6: 0 | W6: =SUM(S6,T6,V6) -> 90 | X6: 0.07044
A7: 2020 | B7: 147 | C7: 43977 | D7: p22-S1 | E7: 1 | F7: 14 | G7: =F7/100 -> 0.14 | H7: 5 | J7: 0 | K7: 0 | L7: 0 | M7: 0 | N7: 0 | O7: 0 | P7: 0.63 | Q7: 0.23 | R7: 0.86 | S7: 63 | T7: 23 | U7: 0 | V7: 0 | W7: =SUM(S7,T7,V7) -> 86 | X7: 0.07278
A8: 2020 | B8: 147 | C8: 43977 | D8: p23-S1 | E8: 1 | F8: 14 | G8: =F8/100 -> 0.14 | H8: 6 | J8: 0 | K8: 0 | L8: 0 | M8: 0 | N8: 0 | O8: 0 | P8: 0.9 | Q8: 0.29 | R8: 1.19 | S8: 90 | T8: 29 | U8: 0 | V8: 0 | W8: =SUM(S8,T8,V8) -> 119 | X8: 0.10442
A9: 2020 | B9: 147 | C9: 43977 | D9: p24-S1 | E9: 1 | F9: 13 | G9: =F9/100 -> 0.13 | H9: 6 | J9: 0 | K9: 0 | L9: 0 | M9: 0 | N9: 0 | O9: 0 | P9: 0.65 | Q9: 0.22 | R9: 0.87 | S9: 65 | T9: 22 | U9: 0 | V9: 0 | W9: =SUM(S9,T9,V9) -> 87 | X9: 0.07513
A10: 2020 | B10: 147 | C10: 43977 | D10: p31-S1 | E10: 1 | F10: 14 | G10: =F10/100 -> 0.14 | H10: 5 | J10: 0 | K10: 0 | L10: 0 | M10: 0 | N10: 0 | O10: 0 | P10: 0.57 | Q10: 0.2 | R10: 0.77 | S10: 57 | T10: 20 | U10: 0 | V10: 0 | W10: =SUM(S10,T10,V10) -> 77 | X10: 0.06676
A11: 2020 | B11: 147 | C11: 43977 | D11: p32-S1 | E11: 1 | F11: 12 | G11: =F11/100 -> 0.12 | H11: 4 | J11: 0 | K11: 0 | L11: 0 | M11: 0 | N11: 0 | O11: 0 | P11: 0.46 | Q11: 0.15 | R11: 0.61 | S11: 46 | T11: 15 | U11: 0 | V11: 0 | W11: =SUM(S11,T11,V11) -> 61 | X11: 0.05408
A12: 2020 | B12: 147 | C12: 43977 | D12: p33-S1 | E12: 1 | F12: 11 | G12: =F12/100 -> 0.11 | H12: 5 | J12: 0 | K12: 0 | L12: 0 | M12: 0 | N12: 0 | O12: 0 | P12: 0.51 | Q12: 0.14 | R12: 0.65 | S12: 51 | T12: 14 | U12: 0 | V12: 0 | W12: =SUM(S12,T12,V12) -> 65 | X12: 0.06145
A13: 2020 | B13: 147 | C13: 43977 | D13: p34-S1 | E13: 1 | F13: 11 | G13: =F13/100 -> 0.11 | H13: 5 | J13: 0 | K13: 0 | L13: 0 | M13: 0 | N13: 0 | O13: 0 | P13: 0.5 | Q13: 0.16 | R13: 0.66 | S13: 50 | T13: 16 | U13: 0 | V13: 0 | W13: =SUM(S13,T13,V13) -> 66 | X13: 0.05794
... A25: 2020 | B25: 147 | C25: 43977 | D25: p64-S1 | E25: 1 | F25: 12 | G25: =F25/100 -> 0.12 | H25: 5 | J25: 0 | K25: 0 | L25: 0 | M25: 0 | N25: 0 | O25: 0 | P25: 0.41 | Q25: 0.15 | R25: 0.56 | S25: 41 | T25: 15 | U25: 0 | V25: 0 | W25: =SUM(S25,T25,V25) -> 56 | X25: 0.04771
A26: 2020 | B26: 160 | C26: 43990 | D26: p11-S2 | E26: 1 | F26: 27 | G26: =F26/100 -> 0.27 | H26: 11 | I26: 6 | J26: 5 | K26: 2 | L26: 3 | M26: 0 | N26: 0 | O26: 0 | P26: 3.1 | Q26: 1.69 | R26: 4.8 | S26: 310 | T26: 169 | U26: 0 | V26: 1 | W26: =SUM(S26,T26,V26) -> 480 | X26: 0.43294
A27: 2020 | B27: 160 | C27: 43990 | D27: p12-S2 | E27: 1 | F27: 31 | G27: =F27/100 -> 0.31 | H27: 10 | I27: 5 | J27: 5 | K27: 3 | L27: 5 | M27: 0 | N27: 0 | O27: 0 | P27: 3.59 | Q27: 2.3 | R27: 5.96 | S27: 359 | T27: 230 | U27: 0 | V27: 7 | W27: =SUM(S27,T27,V27) -> 596 | X27: 0.51278
A28: 2020 | B28: 160 | C28: 43990 | D28: p13-S2 | E28: 1 | F28: 27 | G28: =F28/100 -> 0.27 | H28: 11 | I28: 5 | J28: 6 | K28: 1 | L28: 8 | M28: 0 | N28: 0 | O28: 0 | P28: 2.85 | Q28: 1.74 | R28: 4.75 | S28: 285 | T28: 174 | U28: 0 | V28: 16 | W28: =SUM(S28,T28,V28) -> 475 | X28: 0.39776
A29: 2020 | B29: 160 | C29: 43990 | D29: p14-S2 | E29: 1 | F29: 32 | G29: =F29/100 -> 0.32 | H29: 11 | I29: 6 | J29: 5 | K29: 4 | L29: 1 | M29: 0 | N29: 0 | O29: 0 | P29: 2.74 | Q29: 1.68 | R29: 4.43 | S29: 274 | T29: 168 | U29: 0 | V29: 1 | W29: =SUM(S29,T29,V29) -> 443 | X29: 0.43527
A30: 2020 | B30: 160 | C30: 43990 | D30: p21-S2 | E30: 1 | F30: 33 | G30: =F30/100 -> 0.33 | H30: 11 | I30: 6 | J30: 5 | K30: 2 | L30: 6 | M30: 0 | N30: 0 | O30: 0 | P30: 3.35 | Q30: 2.24 | R30: 5.68 | S30: 335 | T30: 224 | U30: 0 | V30: 9 | W30: =SUM(S30,T30,V30) -> 568 | X30: 0.44982
A31: 2020 | B31: 160 | C31: 43990 | D31: p22-S2 | E31: 1 | F31: 31 | G31: =F31/100 -> 0.31 | H31: 10 | I31: 6 | J31: 4 | K31: 1 | L31: 3 | M31: 0 | N31: 0 | O31: 0 | P31: 2.68 | Q31: 1.69 | R31: 4.41 | S31: 268 | T31: 169 | U31: 0 | V31: 4 | W31: =SUM(S31,T31,V31) -> 441 | X31: 0.4161
A32: 2020 | B32: 160 | C32: 43990 | D32: p23-S2 | E32: 1 | F32: 32 | G32: =F32/100 -> 0.32 | H32: 11 | I32: 5 | J32: 6 | K32: 3 | L32: 5 | M32: 0 | N32: 0 | O32: 0 | P32: 2.58 | Q32: 1.74 | R32: 4.44 | S32: 258 | T32: 174 | U32: 0 | V32: 12 | W32: =SUM(S32,T32,V32) -> 444 | X32: 0.37616
A33: 2020 | B33: 160 | C33: 43990 | D33: p24-S2 | E33: 1 | F33: 33 | G33: =F33/100 -> 0.33 | H33: 12 | I33: 6 | J33: 6 | K33: 0 | L33: 9 | M33: 0 | N33: 0 | O33: 0 | P33: 3.19 | Q33: 2.19 | R33: 5.51 | S33: 319 | T33: 219 | U33: 0 | V33: 13 | W33: =SUM(S33,T33,V33) -> 551 | X33: 0.50663
A34: 2020 | B34: 160 | C34: 43990 | D34: p31-S2 | E34: 1 | F34: 31 | G34: =F34/100 -> 0.31 | H34: 10 | I34: 2 | J34: 5 | K34: 1 | L34: 4 | M34: 0 | N34: 0 | O34: 0 | P34: 1.93 | Q34: 1.27 | R34: 3.21 | S34: 193 | T34: 127 | U34: 0 | V34: 1 | W34: =SUM(S34,T34,V34) -> 321 | X34: 0.296
A35: 2020 | B35: 160 | C35: 43990 | D35: p32-S2 | E35: 1 | F35: 32 | G35: =F35/100 -> 0.32 | H35: 11 | I35: 6 | J35: 5 | K35: 2 | L35: 5 | M35: 0 | N35: 0 | O35: 0 | P35: 3.41 | Q35: 2.21 | R35: 5.65 | S35: 341 | T35: 221 | U35: 0 | V35: 3 | W35: =SUM(S35,T35,V35) -> 565 | X35: 0.49729
A36: 2020 | B36: 160 | C36: 43990 | D36: p33-S2 | E36: 1 | F36: 36 | G36: =F36/100 -> 0.36 | H36: 11 | I36: 6 | J36: 5 | K36: 1 | L36: 7 | M36: 0 | N36: 0 | O36: 0 | P36: 3.65 | Q36: 2.38 | R36: 6.12 | S36: 365 | T36: 238 | U36: 0 | V36: 9 | W36: =SUM(S36,T36,V36) -> 612 | X36: 0.52026
A37: 2020 | B37: 160 | C37: 43990 | D37: p34-S2 | E37: 1 | F37: 28 | G37: =F37/100 -> 0.28 | H37: 12 | I37: 6 | J37: 6 | K37: 3 | L37: 6 | M37: 0 | N37: 0 | O37: 0 | P37: 2.72 | Q37: 1.71 | R37: 4.51 | S37: 272 | T37: 171 | U37: 0 | V37: 8 | W37: =SUM(S37,T37,V37) -> 451 | X37: 0.38953
... A81: 2020 | B81: 188 | C81: 44018 | D81: p24-S4 | E81: 1 | F81: 80 | G81: =F81/100 -> 0.8 | H81: 22 | I81: 6 | J81: 14 | K81: 29 | L81: 39 | M81: 4 | N81: 5 | O81: 0 | P81: 25.22 | Q81: 28.32 | R81: 58.42 | S81: 2522 | T81: 2832 | U81: 0 | V81: 488 | W81: =SUM(S81,T81,V81) -> 5842 | X81: 3.67742
A82: 2020 | B82: 188 | C82: 44018 | D82: p31-S4 | E82: 1 | F82: 79 | G82: =F82/100 -> 0.79 | H82: 20 | I82: 5 | J82: 15 | K82: 19 | L82: 31 | M82: 0 | N82: 14 | O82: 0 | P82: 21.08 | Q82: 22.86 | R82: 59.18 | S82: 2108 | T82: 2286 | U82: 0 | V82: 1524 | W82: =SUM(S82,T82,V82) -> 5918
A83: 2020 | B83: 188 | C83: 44018 | D83: p32-S4 | E83: 1 | F83: 84 | G83: =F83/100 -> 0.84 | H83: 19 | I83: 6 | J83: 13 | K83: 14 | L83: 34 | M83: 1 | N83: 5 | O83: 0 | P83: 19.28 | Q83: 23.53 | R83: 49.1 | S83: 1928 | T83: 2353 | U83: 0 | V83: 629 | W83: =SUM(S83,T83,V83) -> 4910 | X83: 2.67784
A84: 2020 | B84: 188 | C84: 44018 | D84: p33-S4 | E84: 1 | F84: 79 | G84: =F84/100 -> 0.79 | H84: 19 | I84: 5 | J84: 14 | K84: 10 | L84: 18 | M84: 2 | N84: 12 | O84: 0 | P84: 16.24 | Q84: 18.85 | R84: 48.96 | S84: 1624 | T84: 1885 | U84: 0 | V84: 1387 | W84: =SUM(S84,T84,V84) -> 4896 | X84: 2.08838
A85: 2020 | B85: 188 | C85: 44018 | D85: p34-S4 | E85: 1 | F85: 78 | G85: =F85/100 -> 0.78 | H85: 19 | I85: 6 | J85: 13 | K85: 10 | L85: 40 | M85: 0 | N85: 6 | O85: 0 | P85: 18.1 | Q85: 21.01 | R85: 45.73 | S85: 1810 | T85: 2101 | U85: 0 | V85: 662 | W85: =SUM(S85,T85,V85) -> 4573 | X85: 2.78114
A86: 2020 | B86: 188 | C86: 44018 | D86: p41-S4 | E86: 1 | F86: 79 | G86: =F86/100 -> 0.79 | H86: 20 | I86: 5 | J86: 15 | K86: 25 | L86: 31 | M86: 0 | N86: 7 | O86: 0 | P86: 22 | Q86: 24.73 | R86: 59.71 | S86: 2200 | T86: 2473 | U86: 0 | V86: 1298 | W86: =SUM(S86,T86,V86) -> 5971 | X86: 2.76969
A87: 2020 | B87: 188 | C87: 44018 | D87: p42-S4 | E87: 1 | F87: 84 | G87: =F87/100 -> 0.84 | H87: 19 | I87: 5 | J87: 14 | K87: 8 | L87: 45 | M87: 1 | N87: 7 | O87: 0 | P87: 19.99 | Q87: 23.12 | R87: 51.6 | S87: 1999 | T87: 2312 | U87: 0 | V87: 849 | W87: =SUM(S87,T87,V87) -> 5160 | X87: 2.80989
A88: 2020 | B88: 188 | C88: 44018 | D88: p43-S4 | E88: 1 | F88: 65 | G88: =F88/100 -> 0.65 | H88: 18 | I88: 6 | J88: 12 | K88: 5 | L88: 24 | M88: 1 | N88: 6 | O88: 0 | P88: 12.6 | Q88: 13.42 | R88: 31.16 | S88: 1260 | T88: 1342 | U88: 0 | V88: 514 | W88: =SUM(S88,T88,V88) -> 3116 | X88: 1.47549
A89: 2020 | B89: 188 | C89: 44018 | D89: p44-S4 | E89: 1 | F89: 74 | G89: =F89/100 -> 0.74 | H89: 21 | I89: 6 | J89: 15 | K89: 8 | L89: 36 | M89: 1 | N89: 10 | O89: 0 | P89: 18.44 | Q89: 21.08 | R89: 49.04 | S89: 1844 | T89: 2108 | U89: 0 | V89: 952 | W89: =SUM(S89,T89,V89) -> 4904 | X89: 2.46406
A90: 2020 | B90: 188 | C90: 44018 | D90: p51-S4 | E90: 1 | F90: 79 | G90: =F90/100 -> 0.79 | H90: 18 | I90: 6 | J90: 12 | K90: 10 | L90: 21 | M90: 0 | N90: 3 | O90: 0 | P90: 10.6 | Q90: 12.31 | R90: 26.72 | S90: 1060 | T90: 1231 | U90: 0 | V90: 381 | W90: =SUM(S90,T90,V90) -> 2672 | X90: 1.56288
A91: 2020 | B91: 188 | C91: 44018 | D91: p52-S4 | E91: 1 | F91: 84 | G91: =F91/100 -> 0.84 | H91: 20 | I91: 5 | J91: 15 | K91: 21 | L91: 37 | M91: 1 | N91: 3 | O91: 0 | P91: 20.63 | Q91: 23.29 | R91: 48.47 | S91: 2063 | T91: 2329 | U91: 0 | V91: 455 | W91: =SUM(S91,T91,V91) -> 4847 | X91: 2.99099
A92: 2020 | B92: 188 | C92: 44018 | D92: p53-S4 | E92: 1 | F92: 81 | G92: =F92/100 -> 0.81 | H92: 19 | I92: 5 | J92: 14 | K92: 13 | L92: 24 | M92: 0 | N92: 6 | O92: 0 | P92: 14.76 | Q92: 16.28 | R92: 37.46 | S92: 1476 | T92: 1628 | U92: 0 | V92: 642 | W92: =SUM(S92,T92,V92) -> 3746 | X92: 2.24237
A93: 2020 | B93: 188 | C93: 44018 | D93: p54-S4 | E93: 1 | F93: 64 | G93: =F93/100 -> 0.64 | H93: 18 | I93: 6 | J93: 12 | K93: 6 | L93: 27 | M93: 1 | N93: 3 | O93: 0 | P93: 12.38 | Q93: 15.02 | R93: 31.08 | S93: 1238 | T93: 1502 | U93: 0 | V93: 368 | W93: =SUM(S93,T93,V93) -> 3108 | X93: 1.50003
A94: 2020 | B94: 188 | C94: 44018 | D94: p61-S4 | E94: 1 | F94: 83 | G94: =F94/100 -> 0.83 | H94: 20 | I94: 5 | J94: 15 | K94: 11 | L94: 38 | M94: 2 | N94: 8 | O94: 0 | P94: 19.93 | Q94: 24.46 | R94: 56.26 | S94: 1993 | T94: 2446 | U94: 0 | V94: 1187 | W94: =SUM(S94,T94,V94) -> 5626 | X94: 2.49359
...

Sheet d147Mapping
B1: 2020 | C1: F13b4 | E1: Cotton | G1: Irrigation scheduling experiment
B2: Plant sampling and Mapping | G2: processed by: | H2: All by SMM. All done on d147
B4: Sampling Date: | C4: T 26 May 2020 | N4: veg=vegetative branch. May or may not be a split stem | Q4: Seeing some new fruiting patterns this year with the new cotton variety. Multiple fruits on a branch node and multiple branches on mainstem nodes. If 2nd branch on the MS node is a vegetative branch, recorded the fruit under "Fruit on mainstem" and listed the node #. | T4: AA/SS/AA=a branch with 5 nodes. A, A, then a node with 2 Squares, then 2 more nodes. AA-SA=mainstem node with 2 branches. 1st is regular-sized fruiting branch (AA), 2nd is smaller branch (SA) {if just 1 fruit, it seems to be a branch, not just a MS fruit} | AG4: fruit | AH4: = node with a white flower in the 1st position. Need to calculate & enter NAWF,
B5: DOY: | C5: 147 | H5: A = abscised site S = square
B6: Sampling Time: | C6: 1030-1130h | H6: F = white flower G = green boll | N6: missing=no branch at node | AF6: fruit ( / or - ) | AH6: = node with multiple fruit or branches.
B7: Sampled By: | C7: SMM | H7: M = mature (open) boll
B9: Plot | C9: Plant # | D9: DOY Leaf Area Processed | E9: Leaf area of sample (cm2) | H9: Mapping | I9: Above ground height (cm) | J9: Total Main Stem nodes (including coteledonary) | K9: # pre-fruiting nodes | L9: Fruiting branches 1=first branch (above pre-fruiting nodes) | N9: Fruiting branches (cont) | P9: Fruiting branches (cont) | R9: Fruiting branches (cont) | T9: Fruiting branches (cont) | V9: Fruiting branches (cont) | X9: Fruiting branches (cont) | Z9: Fruiting branches (cont) | AB9: Fruiting branches (cont) | AD9: Fruiting branches (cont) | AF9: Fruit on mainstem | AH9: Fruit on non-fruiting branches | AI9: Fruit loose in sample bag | AJ9: NAWF | AK9: Boll with seeds? (Yes/No) | AL9: DOY into oven (stems & repro) | AM9: # branch nodes with more than one fruit | AN9: # mainstem nodes with more than 1 branch | AO9: # abscisions (fruiting branches) | AP9: # abscisions (non-fruiting branches) | AQ9: # abscisions (on main stem) | AR9: # squares (fruiting branches) | AS9: # squares (non-fruiting branches) | AT9: # squares (on main stem) | AU9: # white flowers (fruiting branches) | AV9: # white flowers (non-fruiting branches) | AW9: # white flowers (on main stem) | AX9: # green bolls (fruiting branches) | AY9: # green bolls (non-fruiting branches) | AZ9: # green bolls (on main stem) | BA9: # open bolls (fruiting branches) | BB9: # open bolls (non-fruiting branches) | BC9: # open bolls (on main stem) | BD9: # squares loose in bag | BE9: # flowers loose in bag | BF9: # bolls loose in bag | BG9: # open bolls loose in bag
B10: 01-1 | D10: 147 | E10: 100.37 | H10: Initials - - - - - DOY | AF10: node # | AO10: =SUM(AO11:AO22) -> 0 | AP10: =SUM(AP11:AP22) -> 0 | AQ10: =SUM(AQ11:AQ22) -> 0 | AR10: =SUM(AR11:AR22) -> 0 | AS10: =SUM(AS11:AS22) -> 0 | AT10: =SUM(AT11:AT22) -> 0 | AU10: =SUM(AU11:AU22) -> 0 | AV10: =SUM(AV11:AV22) -> 0 | ... BG10: =SUM(BG11:BG22) -> 0 | BH10: ← plot sums | BK10: =SUM(AO10:AQ10) -> 0 | BL10: =SUM(AR10:AT10,BD10) -> 0 | BM10: =SUM(AU10:AW10,BE10) -> 0 | BN10: =SUM(AX10:AZ10,BF10) -> 0 | BO10: =SUM(BA10:BC10,BG10) -> 0
C11: 1 | H11: smm | I11: 16 | J11: 5 | L11: 1 | N11: 5 | P11: 9 | R11: 13 | T11: 17 | V11: 21 | X11: 25 | Z11: 29 | AB11: 33 | AD11: 37 | AM11: =SUMPRODUCT(LEN($M11:$AE14)-LEN(SUBSTITUTE($M11:$AE14,"/", "")))/2 -> 0 | AN11: =SUMPRODUCT(LEN($M11:$AE14)-LEN(SUBSTITUTE($M11:$AE14,"-", ""))) -> 0 | AO11: =SUMPRODUCT(LEN($M11:$AE14)-LEN(SUBSTITUTE($M11:$AE14,"A", ""))) -> 0 | AP11: =SUMPRODUCT(LEN($AH11:$AH14)-LEN(SUBSTITUTE($AH11:$AH14,"A", ""))) -> 0 | AQ11: =SUMPRODUCT(LEN($AG11:$AG14)-LEN(SUBSTITUTE($AG11:$AG14,"A", ""))) -> 0 | AR11: =SUMPRODUCT(LEN($M11:$AE14)-LEN(SUBSTITUTE($M11:$AE14,"S", ""))) -> 0 | AS11: =SUMPRODUCT(LEN($AH11:$AH14)-LEN(SUBSTITUTE($AH11:$AH14,"S", ""))) -> 0 | AT11: =SUMPRODUCT(LEN($AG11:$AG14)-LEN(SUBSTITUTE($AG11:$AG14,"S", ""))) -> 0 | AU11: =SUMPRODUCT(LEN($M11:$AE14)-LEN(SUBSTITUTE($M11:$AE14,"F", ""))) -> 0 | AV11: =SUMPRODUCT(LEN($AH11:$AH14)-LEN(SUBSTITUTE($AH11:$AH14,"F", ""))) -> 0 | AW11: =SUMPRODUCT(LEN($AG11:$AG14)-LEN(SUBSTITUTE($AG11:$AG14,"F", ""))) -> 0 | AX11: =SUMPRODUCT(LEN($M11:$AE14)-LEN(SUBSTITUTE($M11:$AE14,"G", ""))) -> 0 | AY11: =SUMPRODUCT(LEN($AH11:$AH14)-LEN(SUBSTITUTE($AH11:$AH14,"G", ""))) -> 0 | AZ11: =SUMPRODUCT(LEN($AG11:$AG14)-LEN(SUBSTITUTE($AG11:$AG14,"G", ""))) -> 0 | BA11: =SUMPRODUCT(LEN($M11:$AE14)-LEN(SUBSTITUTE($M11:$AE14,"M", ""))) -> 0 | BB11: =SUMPRODUCT(LEN($AH11:$AH14)-LEN(SUBSTITUTE($AH11:$AH14,"M", ""))) -> 0 | BC11: =SUMPRODUCT(LEN($AG11:$AG14)-LEN(SUBSTITUTE($AG11:$AG14,"M", ""))) -> 0 | BD11: =SUMPRODUCT(LEN($AI11:$AI14)-LEN(SUBSTITUTE($AI11:$AI14,"S", ""))) -> 0 | BE11: =SUMPRODUCT(LEN($AI11:$AI14)-LEN(SUBSTITUTE($AI11:$AI14,"F", ""))) -> 0 | BF11: =SUMPRODUCT(LEN($AI11:$AI14)-LEN(SUBSTITUTE($AI11:$AI14,"G", ""))) -> 0 | BG11: =SUMPRODUCT(LEN($AI11:$AI14)-LEN(SUBSTITUTE($AI11:$AI14,"M", ""))) -> 0
L12: 2 | N12: 6 | P12: 10 | R12: 14 | T12: 18 | V12: 22 | X12: 26 | Z12: 30 | AB12: 34 | AD12: 38
H13: 147 | L13: 3 | N13: 7 | P13: 11 | R13: 15 | T13: 19 | V13: 23 | X13: 27 | Z13: 31 | AB13: 35 | AD13: 39
L14: 4 | N14: 8 | P14: 12 | R14: 16 | T14: 20 | V14: 24 | X14: 28 | Z14: 32 | AB14: 36 | AD14: 40
C15: 2 | L15: 1- | N15: 5- | P15: 9- | R15: 13- | T15: 17- | V15: 21- | X15: 25- | Z15: 29- | AB15: 33- | AD15: 37- | AO15: =SUMPRODUCT(LEN($M15:$AE18)-LEN(SUBSTITUTE($M15:$AE18,"A", ""))) -> 0 | AP15: =SUMPRODUCT(LEN($AH15:$AH18)-LEN(SUBSTITUTE($AH15:$AH18,"A", ""))) -> 0 | AQ15: =SUMPRODUCT(LEN($AG15:$AG18)-LEN(SUBSTITUTE($AG15:$AG18,"A", ""))) -> 0 | AR15: =SUMPRODUCT(LEN($M15:$AE18)-LEN(SUBSTITUTE($M15:$AE18,"S", ""))) -> 0 | AS15: =SUMPRODUCT(LEN($AH15:$AH18)-LEN(SUBSTITUTE($AH15:$AH18,"S", ""))) -> 0 | AT15: =SUMPRODUCT(LEN($AG15:$AG18)-LEN(SUBSTITUTE($AG15:$AG18,"S", ""))) -> 0 | AU15: =SUMPRODUCT(LEN($M15:$AE18)-LEN(SUBSTITUTE($M15:$AE18,"F", ""))) -> 0 | AV15: =SUMPRODUCT(LEN($AH15:$AH18)-LEN(SUBSTITUTE($AH15:$AH18,"F", ""))) -> 0 | AW15: =SUMPRODUCT(LEN($AG15:$AG18)-LEN(SUBSTITUTE($AG15:$AG18,"F", ""))) -> 0 | AX15: =SUMPRODUCT(LEN($M15:$AE18)-LEN(SUBSTITUTE($M15:$AE18,"G", ""))) -> 0 | AY15: =SUMPRODUCT(LEN($AH15:$AH18)-LEN(SUBSTITUTE($AH15:$AH18,"G", ""))) -> 0 | AZ15: =SUMPRODUCT(LEN($AG15:$AG18)-LEN(SUBSTITUTE($AG15:$AG18,"G", ""))) -> 0 | BA15: =SUMPRODUCT(LEN($M15:$AE18)-LEN(SUBSTITUTE($M15:$AE18,"M", ""))) -> 0 | BB15: =SUMPRODUCT(LEN($AH15:$AH18)-LEN(SUBSTITUTE($AH15:$AH18,"M", ""))) -> 0 | BC15: =SUMPRODUCT(LEN($AG15:$AG18)-LEN(SUBSTITUTE($AG15:$AG18,"M", ""))) -> 0 | BD15: =SUMPRODUCT(LEN($AI15:$AI18)-LEN(SUBSTITUTE($AI15:$AI18,"S", ""))) -> 0 | BE15: =SUMPRODUCT(LEN($AI15:$AI18)-LEN(SUBSTITUTE($AI15:$AI18,"F", ""))) -> 0 | BF15: =SUMPRODUCT(LEN($AI15:$AI18)-LEN(SUBSTITUTE($AI15:$AI18,"G", ""))) -> 0 | BG15: =SUMPRODUCT(LEN($AI15:$AI18)-LEN(SUBSTITUTE($AI15:$AI18,"M", ""))) -> 0
G16: If blank, same person → | L16: 2- | N16: 6- | P16: 10- | R16: 14- | T16: 18- | V16: 22- | X16: 26- | Z16: 30- | AB16: 34- | AD16: 38-
G17: mapped plants 1 & 2 → | L17: 3- | N17: 7- | P17: 11- | R17: 15- | T17: 19- | V17: 23- | X17: 27- | Z17: 31- | AB17: 35- | AD17: 39
L18: 4- | N18: 8- | P18: 12- | R18: 16- | T18: 20 | V18: 24- | X18: 28- | Z18: 32- | AB18: 36- | AD18: 40-
C19: 3 | L19: 1- | N19: 5- | P19: 9- | R19: 13- | T19: 17- | V19: 21- | X19: 25- | Z19: 29- | AB19: 33- | AD19: 37- | AO19: =SUMPRODUCT(LEN($M19:$AE22)-LEN(SUBSTITUTE($M19:$AE22,"A", ""))) -> 0 | AP19: =SUMPRODUCT(LEN($AH19:$AH22)-LEN(SUBSTITUTE($AH19:$AH22,"A", ""))) -> 0 | AQ19: =SUMPRODUCT(LEN($AG19:$AG22)-LEN(SUBSTITUTE($AG19:$AG22,"A", ""))) -> 0 | AR19: =SUMPRODUCT(LEN($M19:$AE22)-LEN(SUBSTITUTE($M19:$AE22,"S", ""))) -> 0 | AS19: =SUMPRODUCT(LEN($AH19:$AH22)-LEN(SUBSTITUTE($AH19:$AH22,"S", ""))) -> 0 | AT19: =SUMPRODUCT(LEN($AG19:$AG22)-LEN(SUBSTITUTE($AG19:$AG22,"S", ""))) -> 0 | AU19: =SUMPRODUCT(LEN($M19:$AE22)-LEN(SUBSTITUTE($M19:$AE22,"F", ""))) -> 0 | AV19: =SUMPRODUCT(LEN($AH19:$AH22)-LEN(SUBSTITUTE($AH19:$AH22,"F", ""))) -> 0 | AW19: =SUMPRODUCT(LEN($AG19:$AG22)-LEN(SUBSTITUTE($AG19:$AG22,"F", ""))) -> 0 | AX19: =SUMPRODUCT(LEN($M19:$AE22)-LEN(SUBSTITUTE($M19:$AE22,"G", ""))) -> 0 | AY19: =SUMPRODUCT(LEN($AH19:$AH22)-LEN(SUBSTITUTE($AH19:$AH22,"G", ""))) -> 0 | AZ19: =SUMPRODUCT(LEN($AG19:$AG22)-LEN(SUBSTITUTE($AG19:$AG22,"G", ""))) -> 0 | BA19: =SUMPRODUCT(LEN($M19:$AE22)-LEN(SUBSTITUTE($M19:$AE22,"M", ""))) -> 0 | BB19: =SUMPRODUCT(LEN($AH19:$AH22)-LEN(SUBSTITUTE($AH19:$AH22,"M", ""))) -> 0 | BC19: =SUMPRODUCT(LEN($AG19:$AG22)-LEN(SUBSTITUTE($AG19:$AG22,"M", ""))) -> 0 | BD19: =SUMPRODUCT(LEN($AI19:$AI22)-LEN(SUBSTITUTE($AI19:$AI22,"S", ""))) -> 0 | BE19: =SUMPRODUCT(LEN($AI19:$AI22)-LEN(SUBSTITUTE($AI19:$AI22,"F", ""))) -> 0 | BF19: =SUMPRODUCT(LEN($AI19:$AI22)-LEN(SUBSTITUTE($AI19:$AI22,"G", ""))) -> 0 | BG19: =SUMPRODUCT(LEN($AI19:$AI22)-LEN(SUBSTITUTE($AI19:$AI22,"M", ""))) -> 0
L20: 2- | N20: 6- | P20: 10- | R20: 14- | T20: 18- | V20: 22- | X20: 26- | Z20: 30- | AB20: 34- | AD20: 38-
L21: 3- | N21: 7- | P21: 11- | R21: 15- | T21: 19- | V21: 23- | X21: 27- | Z21: 31- | AB21: 35- | AD21: 39
L22: 4- | N22: 8- | P22: 12- | R22: 16- | T22: 20 | V22: 24- | X22: 28- | Z22: 32- | AB22: 36- | AD22: 40-
B23: Plot | C23: Plant # | D23: DOY Leaf Area Processed | E23: Leaf area of sample (cm2) | H23: Mapping | I23: Above ground height (cm) | J23: Total Main Stem nodes (including coteledonary) | K23: # pre-fruiting nodes | L23: Fruiting branches 1=first branch (above pre-fruiting nodes) | N23: Fruiting branches (cont) | P23: Fruiting branches (cont) | R23: Fruiting branches (cont) | T23: Fruiting branches (cont) | V23: Fruiting branches (cont) | X23: Fruiting branches (cont) | Z23: Fruiting branches (cont) | AB23: Fruiting branches (cont) | AD23: Fruiting branches (cont) | AF23: Fruit on mainstem | AH23: Fruit on non-fruiting branches | AI23: Fruit loose in sample bag | AJ23: NAWF | AK23: Boll with seeds? (Yes/No) | AL23: DOY into oven (stems & repro) | AM23: # branch nodes with more than one fruit | AN23: # mainstem nodes with more than 1 branch | AO23: # abscisions (fruiting branches) | AP23: # abscisions (non-fruiting branches) | AQ23: # abscisions (on main stem) | AR23: # squares (fruiting branches) | AS23: # squares (non-fruiting branches) | AT23: # squares (on main stem) | AU23: # white flowers (fruiting branches) | AV23: # white flowers (non-fruiting branches) | AW23: # white flowers (on main stem) | AX23: # green bolls (fruiting branches) | AY23: # green bolls (non-fruiting branches) | AZ23: # green bolls (on main stem) | BA23: # open bolls (fruiting branches) | BB23: # open bolls (non-fruiting branches) | BC23: # open bolls (on main stem) | BD23: # squares loose in bag | BE23: # flowers loose in bag | BF23: # bolls loose in bag | BG23: # open bolls loose in bag
B24: 01-2 | E24: 98.22 | H24: Initials - - - - - DOY | AF24: node # | AO24: =SUM(AO25:AO36) -> 0 | AP24: =SUM(AP25:AP36) -> 0 | AQ24: =SUM(AQ25:AQ36) -> 0 | AR24: =SUM(AR25:AR36) -> 0 | AS24: =SUM(AS25:AS36) -> 0 | AT24: =SUM(AT25:AT36) -> 0 | AU24: =SUM(AU25:AU36) -> 0 | AV24: =SUM(AV25:AV36) -> 0 | ... BG24: =SUM(BG25:BG36) -> 0 | BH24: ← plot sums | BK24: =SUM(AO24:AQ24) -> 0 | BL24: =SUM(AR24:AT24,BD24) -> 0 | BM24: =SUM(AU24:AW24,BE24) -> 0 | BN24: =SUM(AX24:AZ24,BF24) -> 0 | BO24: =SUM(BA24:BC24,BG24) -> 0
C25: 1 | I25: 15 | J25: 5 | L25: 1 | N25: 5 | P25: 9 | R25: 13 | T25: 17 | V25: 21 | X25: 25 | Z25: 29 | AB25: 33 | AD25: 37 | AM25: =SUMPRODUCT(LEN($M25:$AE28)-LEN(SUBSTITUTE($M25:$AE28,"/", "")))/2 -> 0 | AN25: =SUMPRODUCT(LEN($M25:$AE28)-LEN(SUBSTITUTE($M25:$AE28,"-", ""))) -> 0 | AO25: =SUMPRODUCT(LEN($M25:$AE28)-LEN(SUBSTITUTE($M25:$AE28,"A", ""))) -> 0 | AP25: =SUMPRODUCT(LEN($AH25:$AH28)-LEN(SUBSTITUTE($AH25:$AH28,"A", ""))) -> 0 | AQ25: =SUMPRODUCT(LEN($AG25:$AG28)-LEN(SUBSTITUTE($AG25:$AG28,"A", ""))) -> 0 | AR25: =SUMPRODUCT(LEN($M25:$AE28)-LEN(SUBSTITUTE($M25:$AE28,"S", ""))) -> 0 | AS25: =SUMPRODUCT(LEN($AH25:$AH28)-LEN(SUBSTITUTE($AH25:$AH28,"S", ""))) -> 0 | AT25: =SUMPRODUCT(LEN($AG25:$AG28)-LEN(SUBSTITUTE($AG25:$AG28,"S", ""))) -> 0 | AU25: =SUMPRODUCT(LEN($M25:$AE28)-LEN(SUBSTITUTE($M25:$AE28,"F", ""))) -> 0 | AV25: =SUMPRODUCT(LEN($AH25:$AH28)-LEN(SUBSTITUTE($AH25:$AH28,"F", ""))) -> 0 | AW25: =SUMPRODUCT(LEN($AG25:$AG28)-LEN(SUBSTITUTE($AG25:$AG28,"F", ""))) -> 0 | AX25: =SUMPRODUCT(LEN($M25:$AE28)-LEN(SUBSTITUTE($M25:$AE28,"G", ""))) -> 0 | AY25: =SUMPRODUCT(LEN($AH25:$AH28)-LEN(SUBSTITUTE($AH25:$AH28,"G", ""))) -> 0 | AZ25: =SUMPRODUCT(LEN($AG25:$AG28)-LEN(SUBSTITUTE($AG25:$AG28,"G", ""))) -> 0 | BA25: =SUMPRODUCT(LEN($M25:$AE28)-LEN(SUBSTITUTE($M25:$AE28,"M", ""))) -> 0 | BB25: =SUMPRODUCT(LEN($AH25:$AH28)-LEN(SUBSTITUTE($AH25:$AH28,"M", ""))) -> 0 | BC25: =SUMPRODUCT(LEN($AG25:$AG28)-LEN(SUBSTITUTE($AG25:$AG28,"M", ""))) -> 0 | BD25: =SUMPRODUCT(LEN($AI25:$AI28)-LEN(SUBSTITUTE($AI25:$AI28,"S", ""))) -> 0 | BE25: =SUMPRODUCT(LEN($AI25:$AI28)-LEN(SUBSTITUTE($AI25:$AI28,"F", ""))) -> 0 | BF25: =SUMPRODUCT(LEN($AI25:$AI28)-LEN(SUBSTITUTE($AI25:$AI28,"G", ""))) -> 0 | BG25: =SUMPRODUCT(LEN($AI25:$AI28)-LEN(SUBSTITUTE($AI25:$AI28,"M", ""))) -> 0
L26: 2 | N26: 6 | P26: 10 | R26: 14 | T26: 18 | V26: 22 | X26: 26 | Z26: 30 | AB26: 34 | AD26: 38
L27: 3 | N27: 7 | P27: 11 | R27: 15 | T27: 19 | V27: 23 | X27: 27 | Z27: 31 | AB27: 35 | AD27: 39
L28: 4 | N28: 8 | P28: 12 | R28: 16 | T28: 20 | V28: 24 | X28: 28 | Z28: 32 | AB28: 36 | AD28: 40
C29: 2 | L29: 1- | N29: 5- | P29: 9- | R29: 13- | T29: 17- | V29: 21- | X29: 25- | Z29: 29- | AB29: 33- | AD29: 37- | AO29: =SUMPRODUCT(LEN($M29:$AE32)-LEN(SUBSTITUTE($M29:$AE32,"A", ""))) -> 0 | AP29: =SUMPRODUCT(LEN($AH29:$AH32)-LEN(SUBSTITUTE($AH29:$AH32,"A", ""))) -> 0 | AQ29: =SUMPRODUCT(LEN($AG29:$AG32)-LEN(SUBSTITUTE($AG29:$AG32,"A", ""))) -> 0 | AR29: =SUMPRODUCT(LEN($M29:$AE32)-LEN(SUBSTITUTE($M29:$AE32,"S", ""))) -> 0 | AS29: =SUMPRODUCT(LEN($AH29:$AH32)-LEN(SUBSTITUTE($AH29:$AH32,"S", ""))) -> 0 | AT29: =SUMPRODUCT(LEN($AG29:$AG32)-LEN(SUBSTITUTE($AG29:$AG32,"S", ""))) -> 0 | AU29: =SUMPRODUCT(LEN($M29:$AE32)-LEN(SUBSTITUTE($M29:$AE32,"F", ""))) -> 0 | AV29: =SUMPRODUCT(LEN($AH29:$AH32)-LEN(SUBSTITUTE($AH29:$AH32,"F", ""))) -> 0 | AW29: =SUMPRODUCT(LEN($AG29:$AG32)-LEN(SUBSTITUTE($AG29:$AG32,"F", ""))) -> 0 | AX29: =SUMPRODUCT(LEN($M29:$AE32)-LEN(SUBSTITUTE($M29:$AE32,"G", ""))) -> 0 | AY29: =SUMPRODUCT(LEN($AH29:$AH32)-LEN(SUBSTITUTE($AH29:$AH32,"G", ""))) -> 0 | AZ29: =SUMPRODUCT(LEN($AG29:$AG32)-LEN(SUBSTITUTE($AG29:$AG32,"G", ""))) -> 0 | BA29: =SUMPRODUCT(LEN($M29:$AE32)-LEN(SUBSTITUTE($M29:$AE32,"M", ""))) -> 0 | BB29: =SUMPRODUCT(LEN($AH29:$AH32)-LEN(SUBSTITUTE($AH29:$AH32,"M", ""))) -> 0 | BC29: =SUMPRODUCT(LEN($AG29:$AG32)-LEN(SUBSTITUTE($AG29:$AG32,"M", ""))) -> 0 | BD29: =SUMPRODUCT(LEN($AI29:$AI32)-LEN(SUBSTITUTE($AI29:$AI32,"S", ""))) -> 0 | BE29: =SUMPRODUCT(LEN($AI29:$AI32)-LEN(SUBSTITUTE($AI29:$AI32,"F", ""))) -> 0 | BF29: =SUMPRODUCT(LEN($AI29:$AI32)-LEN(SUBSTITUTE($AI29:$AI32,"G", ""))) -> 0 | BG29: =SUMPRODUCT(LEN($AI29:$AI32)-LEN(SUBSTITUTE($AI29:$AI32,"M", ""))) -> 0
L30: 2- | N30: 6- | P30: 10- | R30: 14- | T30: 18- | V30: 22- | X30: 26- | Z30: 30- | AB30: 34- | AD30: 38-
L31: 3- | N31: 7- | P31: 11- | R31: 15- | T31: 19- | V31: 23- | X31: 27- | Z31: 31- | AB31: 35- | AD31: 39
L32: 4- | N32: 8- | P32: 12- | R32: 16- | T32: 20 | V32: 24- | X32: 28- | Z32: 32- | AB32: 36- | AD32: 40-
C33: 3 | L33: 1- | N33: 5- | P33: 9- | R33: 13- | T33: 17- | V33: 21- | X33: 25- | Z33: 29- | AB33: 33- | AD33: 37- | AO33: =SUMPRODUCT(LEN($M33:$AE36)-LEN(SUBSTITUTE($M33:$AE36,"A", ""))) -> 0 | AP33: =SUMPRODUCT(LEN($AH33:$AH36)-LEN(SUBSTITUTE($AH33:$AH36,"A", ""))) -> 0 | AQ33: =SUMPRODUCT(LEN($AG33:$AG36)-LEN(SUBSTITUTE($AG33:$AG36,"A", ""))) -> 0 | AR33: =SUMPRODUCT(LEN($M33:$AE36)-LEN(SUBSTITUTE($M33:$AE36,"S", ""))) -> 0 | AS33: =SUMPRODUCT(LEN($AH33:$AH36)-LEN(SUBSTITUTE($AH33:$AH36,"S", ""))) -> 0 | AT33: =SUMPRODUCT(LEN($AG33:$AG36)-LEN(SUBSTITUTE($AG33:$AG36,"S", ""))) -> 0 | AU33: =SUMPRODUCT(LEN($M33:$AE36)-LEN(SUBSTITUTE($M33:$AE36,"F", ""))) -> 0 | AV33: =SUMPRODUCT(LEN($AH33:$AH36)-LEN(SUBSTITUTE($AH33:$AH36,"F", ""))) -> 0 | AW33: =SUMPRODUCT(LEN($AG33:$AG36)-LEN(SUBSTITUTE($AG33:$AG36,"F", ""))) -> 0 | AX33: =SUMPRODUCT(LEN($M33:$AE36)-LEN(SUBSTITUTE($M33:$AE36,"G", ""))) -> 0 | AY33: =SUMPRODUCT(LEN($AH33:$AH36)-LEN(SUBSTITUTE($AH33:$AH36,"G", ""))) -> 0 | AZ33: =SUMPRODUCT(LEN($AG33:$AG36)-LEN(SUBSTITUTE($AG33:$AG36,"G", ""))) -> 0 | BA33: =SUMPRODUCT(LEN($M33:$AE36)-LEN(SUBSTITUTE($M33:$AE36,"M", ""))) -> 0 | BB33: =SUMPRODUCT(LEN($AH33:$AH36)-LEN(SUBSTITUTE($AH33:$AH36,"M", ""))) -> 0 | BC33: =SUMPRODUCT(LEN($AG33:$AG36)-LEN(SUBSTITUTE($AG33:$AG36,"M", ""))) -> 0 | BD33: =SUMPRODUCT(LEN($AI33:$AI36)-LEN(SUBSTITUTE($AI33:$AI36,"S", ""))) -> 0 | BE33: =SUMPRODUCT(LEN($AI33:$AI36)-LEN(SUBSTITUTE($AI33:$AI36,"F", ""))) -> 0 | BF33: =SUMPRODUCT(LEN($AI33:$AI36)-LEN(SUBSTITUTE($AI33:$AI36,"G", ""))) -> 0 | BG33: =SUMPRODUCT(LEN($AI33:$AI36)-LEN(SUBSTITUTE($AI33:$AI36,"M", ""))) -> 0
L34: 2- | N34: 6- | P34: 10- | R34: 14- | T34: 18- | V34: 22- | X34: 26- | Z34: 30- | AB34: 34- | AD34: 38-
L35: 3- | N35: 7- | P35: 11- | R35: 15- | T35: 19- | V35: 23- | X35: 27- | Z35: 31- | AB35: 35- | AD35: 39
L36: 4- | N36: 8- | P36: 12- | R36: 16- | T36: 20 | V36: 24- | X36: 28- | Z36: 32- | AB36: 36- | AD36: 40-
B37: Plot | C37: Plant # | D37: DOY Leaf Area Processed | E37: Leaf area of sample (cm2) | H37: Mapping | I37: Above ground height (cm) | J37: Total Main Stem nodes (including coteledonary) | K37: # pre-fruiting nodes | L37: Fruiting branches 1=first branch (above pre-fruiting nodes) | N37: Fruiting branches (cont) | P37: Fruiting branches (cont) | R37: Fruiting branches (cont) | T37: Fruiting branches (cont) | V37: Fruiting branches (cont) | X37: Fruiting branches (cont) | Z37: Fruiting branches (cont) | AB37: Fruiting branches (cont) | AD37: Fruiting branches (cont) | AF37: Fruit on mainstem | AH37: Fruit on non-fruiting branches | AI37: Fruit loose in sample bag | AJ37: NAWF | AK37: Boll with seeds? (Yes/No) | AL37: DOY into oven (stems & repro) | AM37: # branch nodes with more than one fruit | AN37: # mainstem nodes with more than 1 branch | AO37: # abscisions (fruiting branches) | AP37: # abscisions (non-fruiting branches) | AQ37: # abscisions (on main stem) | AR37: # squares (fruiting branches) | AS37: # squares (non-fruiting branches) | AT37: # squares (on main stem) | AU37: # white flowers (fruiting branches) | AV37: # white flowers (non-fruiting branches) | AW37: # white flowers (on main stem) | AX37: # green bolls (fruiting branches) | AY37: # green bolls (non-fruiting branches) | AZ37: # green bolls (on main stem) | BA37: # open bolls (fruiting branches) | BB37: # open bolls (non-fruiting branches) | BC37: # open bolls (on main stem) | BD37: # squares loose in bag | BE37: # flowers loose in bag | BF37: # bolls loose in bag | BG37: # open bolls loose in bag
B38: 01-3 | E38: 52.79 | H38: Initials - - - - - DOY | AF38: node # | AO38: =SUM(AO39:AO50) -> 0 | AP38: =SUM(AP39:AP50) -> 0 | AQ38: =SUM(AQ39:AQ50) -> 0 | AR38: =SUM(AR39:AR50) -> 0 | AS38: =SUM(AS39:AS50) -> 0 | AT38: =SUM(AT39:AT50) -> 0 | AU38: =SUM(AU39:AU50) -> 0 | AV38: =SUM(AV39:AV50) -> 0 | ... BG38: =SUM(BG39:BG50) -> 0 | BH38: ← plot sums | BK38: =SUM(AO38:AQ38) -> 0 | BL38: =SUM(AR38:AT38,BD38) -> 0 | BM38: =SUM(AU38:AW38,BE38) -> 0 | BN38: =SUM(AX38:AZ38,BF38) -> 0 | BO38: =SUM(BA38:BC38,BG38) -> 0
C39: 1 | I39: 12 | J39: 5 | L39: 1 | N39: 5 | P39: 9 | R39: 13 | T39: 17 | V39: 21 | X39: 25 | Z39: 29 | AB39: 33 | AD39: 37 | AM39: =SUMPRODUCT(LEN($M39:$AE42)-LEN(SUBSTITUTE($M39:$AE42,"/", "")))/2 -> 0 | AN39: =SUMPRODUCT(LEN($M39:$AE42)-LEN(SUBSTITUTE($M39:$AE42,"-", ""))) -> 0 | AO39: =SUMPRODUCT(LEN($M39:$AE42)-LEN(SUBSTITUTE($M39:$AE42,"A", ""))) -> 0 | AP39: =SUMPRODUCT(LEN($AH39:$AH42)-LEN(SUBSTITUTE($AH39:$AH42,"A", ""))) -> 0 | AQ39: =SUMPRODUCT(LEN($AG39:$AG42)-LEN(SUBSTITUTE($AG39:$AG42,"A", ""))) -> 0 | AR39: =SUMPRODUCT(LEN($M39:$AE42)-LEN(SUBSTITUTE($M39:$AE42,"S", ""))) -> 0 | AS39: =SUMPRODUCT(LEN($AH39:$AH42)-LEN(SUBSTITUTE($AH39:$AH42,"S", ""))) -> 0 | AT39: =SUMPRODUCT(LEN($AG39:$AG42)-LEN(SUBSTITUTE($AG39:$AG42,"S", ""))) -> 0 | AU39: =SUMPRODUCT(LEN($M39:$AE42)-LEN(SUBSTITUTE($M39:$AE42,"F", ""))) -> 0 | AV39: =SUMPRODUCT(LEN($AH39:$AH42)-LEN(SUBSTITUTE($AH39:$AH42,"F", ""))) -> 0 | AW39: =SUMPRODUCT(LEN($AG39:$AG42)-LEN(SUBSTITUTE($AG39:$AG42,"F", ""))) -> 0 | AX39: =SUMPRODUCT(LEN($M39:$AE42)-LEN(SUBSTITUTE($M39:$AE42,"G", ""))) -> 0 | AY39: =SUMPRODUCT(LEN($AH39:$AH42)-LEN(SUBSTITUTE($AH39:$AH42,"G", ""))) -> 0 | AZ39: =SUMPRODUCT(LEN($AG39:$AG42)-LEN(SUBSTITUTE($AG39:$AG42,"G", ""))) -> 0 | BA39: =SUMPRODUCT(LEN($M39:$AE42)-LEN(SUBSTITUTE($M39:$AE42,"M", ""))) -> 0 | BB39: =SUMPRODUCT(LEN($AH39:$AH42)-LEN(SUBSTITUTE($AH39:$AH42,"M", ""))) -> 0 | BC39: =SUMPRODUCT(LEN($AG39:$AG42)-LEN(SUBSTITUTE($AG39:$AG42,"M", ""))) -> 0 | BD39: =SUMPRODUCT(LEN($AI39:$AI42)-LEN(SUBSTITUTE($AI39:$AI42,"S", ""))) -> 0 | BE39: =SUMPRODUCT(LEN($AI39:$AI42)-LEN(SUBSTITUTE($AI39:$AI42,"F", ""))) -> 0 | BF39: =SUMPRODUCT(LEN($AI39:$AI42)-LEN(SUBSTITUTE($AI39:$AI42,"G", ""))) -> 0 | BG39: =SUMPRODUCT(LEN($AI39:$AI42)-LEN(SUBSTITUTE($AI39:$AI42,"M", ""))) -> 0
L40: 2 | N40: 6 | P40: 10 | R40: 14 | T40: 18 | V40: 22 | X40: 26 | Z40: 30 | AB40: 34 | AD40: 38
L41: 3 | N41: 7 | P41: 11 | R41: 15 | T41: 19 | V41: 23 | X41: 27 | Z41: 31 | AB41: 35 | AD41: 39
L42: 4 | N42: 8 | P42: 12 | R42: 16 | T42: 20 | V42: 24 | X42: 28 | Z42: 32 | AB42: 36 | AD42: 40
...

Sheet d147Weights
A1: 2020 | B1: F13b4 | C1: Cotton | J1: Irrigation scheduling experiment
B2: Plant sampling and Mapping | M2: Field Avg
M3: Density | N3: 10 | O3: plant/m2
B4: Sampling Date: | C4: 26 May 202 | G4: Date(s) weighed: | H4: 44345
B5: DOY: | C5: 147 | G5: Weighed by: | H5: SMM
B6: Comments: | D6: Oven temp: 65 °C
B8: Plot | C8: TRT | D8: DOY out of Oven | E8: Green leaves (g) | F8: Brown leaves (g) | G8: Stems (g) | H8: Squares, Flowers & Green Bolls (g) | I8: Flowers & Green Bolls (g) | J8: Mature Bolls (g) | K8: Leaf Area (cm2) | M8: CWPD | N8: LWAD | O8: SWAD | P8: MBWAD | Q8: PWAD | R8: LAID
B9: 01-1 | E9: 0.96 | G9: 0.39 | K9: =d147Mapping!$E$10 -> 100.37 | M9: =SUM(E9,G9,H9,J9) -> 1.35 | N9: =E9/1000*$N$3*10000 -> 96 | O9: =G9/1000*$N$3*10000 -> 39 | P9: =J9/1000*$N$3*10000 -> 0 | Q9: =(H9+J9)/1000*$N$3*10000 -> 0 | R9: =K9/(100*100)*$N$3 -> 0.10037
B10: 01-2 | E10: 1.02 | G10: 0.33 | K10: =d147Mapping!$E$24 -> 98.22 | M10: =SUM(E10,G10,H10,J10) -> 1.35 | N10: =E10/1000*$N$3*10000 -> 102 | O10: =G10/1000*$N$3*10000 -> 33 | P10: =J10/1000*$N$3*10000 -> 0 | Q10: =(H10+J10)/1000*$N$3*10000 -> 0 | R10: =K10/(100*100)*$N$3 -> 0.09822
B11: 01-3 | E11: 0.46 | G11: 0.16 | K11: =d147Mapping!$E$38 -> 52.79 | M11: =SUM(E11,G11,H11,J11) -> 0.62 | N11: =E11/1000*$N$3*10000 -> 46 | O11: =G11/1000*$N$3*10000 -> 16 | P11: =J11/1000*$N$3*10000 -> 0 | Q11: =(H11+J11)/1000*$N$3*10000 -> 0 | R11: =K11/(100*100)*$N$3 -> 0.05279
B12: 01-4 | E12: 0.73 | G12: 0.29 | K12: =d147Mapping!$E$52 -> 87.6 | M12: =SUM(E12,G12,H12,J12) -> 1.02 | N12: =E12/1000*$N$3*10000 -> 73 | O12: =G12/1000*$N$3*10000 -> 29 | P12: =J12/1000*$N$3*10000 -> 0 | Q12: =(H12+J12)/1000*$N$3*10000 -> 0 | R12: =K12/(100*100)*$N$3 -> 0.0876
B13: 02-1 | E13: 0.66 | G13: 0.24 | K13: =d147Mapping!$E$66 -> 70.44 | M13: =SUM(E13,G13,H13,J13) -> 0.9 | N13: =E13/1000*$N$3*10000 -> 66 | O13: =G13/1000*$N$3*10000 -> 24 | P13: =J13/1000*$N$3*10000 -> 0 | Q13: =(H13+J13)/1000*$N$3*10000 -> 0 | R13: =K13/(100*100)*$N$3 -> 0.07044
B14: 02-2 | E14: 0.63 | G14: 0.23 | K14: =d147Mapping!$E$80 -> 72.78 | M14: =SUM(E14,G14,H14,J14) -> 0.86 | N14: =E14/1000*$N$3*10000 -> 63 | O14: =G14/1000*$N$3*10000 -> 23 | P14: =J14/1000*$N$3*10000 -> 0 | Q14: =(H14+J14)/1000*$N$3*10000 -> 0 | R14: =K14/(100*100)*$N$3 -> 0.07278
B15: 02-3 | E15: 0.9 | G15: 0.29 | K15: =d147Mapping!$E$94 -> 104.42 | M15: =SUM(E15,G15,H15,J15) -> 1.19 | N15: =E15/1000*$N$3*10000 -> 90 | O15: =G15/1000*$N$3*10000 -> 29 | P15: =J15/1000*$N$3*10000 -> 0 | Q15: =(H15+J15)/1000*$N$3*10000 -> 0 | R15: =K15/(100*100)*$N$3 -> 0.10442
B16: 02-4 | E16: 0.65 | G16: 0.22 | K16: =d147Mapping!$E$108 -> 75.13 | M16: =SUM(E16,G16,H16,J16) -> 0.87 | N16: =E16/1000*$N$3*10000 -> 65 | O16: =G16/1000*$N$3*10000 -> 22 | P16: =J16/1000*$N$3*10000 -> 0 | Q16: =(H16+J16)/1000*$N$3*10000 -> 0 | R16: =K16/(100*100)*$N$3 -> 0.07513
B17: 03-1 | E17: 0.57 | G17: 0.2 | K17: =d147Mapping!$E$122 -> 66.76 | M17: =SUM(E17,G17,H17,J17) -> 0.77 | N17: =E17/1000*$N$3*10000 -> 57 | O17: =G17/1000*$N$3*10000 -> 20 | P17: =J17/1000*$N$3*10000 -> 0 | Q17: =(H17+J17)/1000*$N$3*10000 -> 0 | R17: =K17/(100*100)*$N$3 -> 0.06676
B18: 03-2 | E18: 0.46 | G18: 0.15 | K18: =d147Mapping!$E$136 -> 54.08 | M18: =SUM(E18,G18,H18,J18) -> 0.61 | N18: =E18/1000*$N$3*10000 -> 46 | O18: =G18/1000*$N$3*10000 -> 15 | P18: =J18/1000*$N$3*10000 -> 0 | Q18: =(H18+J18)/1000*$N$3*10000 -> 0 | R18: =K18/(100*100)*$N$3 -> 0.05408
B19: 03-3 | E19: 0.51 | G19: 0.14 | K19: =d147Mapping!$E$150 -> 61.45 | M19: =SUM(E19,G19,H19,J19) -> 0.65 | N19: =E19/1000*$N$3*10000 -> 51 | O19: =G19/1000*$N$3*10000 -> 14 | P19: =J19/1000*$N$3*10000 -> 0 | Q19: =(H19+J19)/1000*$N$3*10000 -> 0 | R19: =K19/(100*100)*$N$3 -> 0.06145
B20: 03-4 | E20: 0.5 | G20: 0.16 | K20: =d147Mapping!$E$164 -> 57.94 | M20: =SUM(E20,G20,H20,J20) -> 0.66 | N20: =E20/1000*$N$3*10000 -> 50 | O20: =G20/1000*$N$3*10000 -> 16 | P20: =J20/1000*$N$3*10000 -> 0 | Q20: =(H20+J20)/1000*$N$3*10000 -> 0 | R20: =K20/(100*100)*$N$3 -> 0.05794
B21: 04-1 | E21: 0.66 | G21: 0.23 | K21: =d147Mapping!$E$178 -> 75.54 | M21: =SUM(E21,G21,H21,J21) -> 0.89 | N21: =E21/1000*$N$3*10000 -> 66 | O21: =G21/1000*$N$3*10000 -> 23 | P21: =J21/1000*$N$3*10000 -> 0 | Q21: =(H21+J21)/1000*$N$3*10000 -> 0 | R21: =K21/(100*100)*$N$3 -> 0.07554
B22: 04-2 | E22: 0.92 | G22: 0.34 | K22: =d147Mapping!$E$192 -> 102.39 | M22: =SUM(E22,G22,H22,J22) -> 1.26 | N22: =E22/1000*$N$3*10000 -> 92 | O22: =G22/1000*$N$3*10000 -> 34 | P22: =J22/1000*$N$3*10000 -> 0 | Q22: =(H22+J22)/1000*$N$3*10000 -> 0 | R22: =K22/(100*100)*$N$3 -> 0.10239
B23: 04-3 | E23: 0.61 | G23: 0.25 | K23: =d147Mapping!$E$206 -> 68.02 | M23: =SUM(E23,G23,H23,J23) -> 0.86 | N23: =E23/1000*$N$3*10000 -> 61 | O23: =G23/1000*$N$3*10000 -> 25 | P23: =J23/1000*$N$3*10000 -> 0 | Q23: =(H23+J23)/1000*$N$3*10000 -> 0 | R23: =K23/(100*100)*$N$3 -> 0.06802
B24: 04-4 | E24: 0.41 | G24: 0.17 | K24: =d147Mapping!$E$220 -> 51.53 | M24: =SUM(E24,G24,H24,J24) -> 0.58 | N24: =E24/1000*$N$3*10000 -> 41 | O24: =G24/1000*$N$3*10000 -> 17 | P24: =J24/1000*$N$3*10000 -> 0 | Q24: =(H24+J24)/1000*$N$3*10000 -> 0 | R24: =K24/(100*100)*$N$3 -> 0.05153
B25: 05-1 | E25: 0.55 | G25: 0.22 | K25: =d147Mapping!$E$234 -> 62.97 | M25: =SUM(E25,G25,H25,J25) -> 0.77 | N25: =E25/1000*$N$3*10000 -> 55 | O25: =G25/1000*$N$3*10000 -> 22 | P25: =J25/1000*$N$3*10000 -> 0 | Q25: =(H25+J25)/1000*$N$3*10000 -> 0 | R25: =K25/(100*100)*$N$3 -> 0.06297
B26: 05-2 | E26: 0.42 | G26: 0.15 | K26: =d147Mapping!$E$248 -> 53.47 | M26: =SUM(E26,G26,H26,J26) -> 0.57 | N26: =E26/1000*$N$3*10000 -> 42 | O26: =G26/1000*$N$3*10000 -> 15 | P26: =J26/1000*$N$3*10000 -> 0 | Q26: =(H26+J26)/1000*$N$3*10000 -> 0 | R26: =K26/(100*100)*$N$3 -> 0.05347
B27: 05-3 | E27: 0.7 | G27: 0.26 | K27: =d147Mapping!$E$262 -> 75.9 | M27: =SUM(E27,G27,H27,J27) -> 0.96 | N27: =E27/1000*$N$3*10000 -> 70 | O27: =G27/1000*$N$3*10000 -> 26 | P27: =J27/1000*$N$3*10000 -> 0 | Q27: =(H27+J27)/1000*$N$3*10000 -> 0 | R27: =K27/(100*100)*$N$3 -> 0.0759
B28: 05-4 | E28: 0.31 | G28: 0.1 | K28: =d147Mapping!$E$276 -> 37.51 | M28: =SUM(E28,G28,H28,J28) -> 0.41 | N28: =E28/1000*$N$3*10000 -> 31 | O28: =G28/1000*$N$3*10000 -> 10 | P28: =J28/1000*$N$3*10000 -> 0 | Q28: =(H28+J28)/1000*$N$3*10000 -> 0 | R28: =K28/(100*100)*$N$3 -> 0.03751
B29: 06-1 | E29: 0.52 | G29: 0.2 | K29: =d147Mapping!$E$290 -> 54.76 | M29: =SUM(E29,G29,H29,J29) -> 0.72 | N29: =E29/1000*$N$3*10000 -> 52 | O29: =G29/1000*$N$3*10000 -> 20 | P29: =J29/1000*$N$3*10000 -> 0 | Q29: =(H29+J29)/1000*$N$3*10000 -> 0 | R29: =K29/(100*100)*$N$3 -> 0.05476
B30: 06-2 | E30: 0.89 | G30: 0.37 | K30: =d147Mapping!$E$304 -> 101.87 | M30: =SUM(E30,G30,H30,J30) -> 1.26 | N30: =E30/1000*$N$3*10000 -> 89 | O30: =G30/1000*$N$3*10000 -> 37 | P30: =J30/1000*$N$3*10000 -> 0 | Q30: =(H30+J30)/1000*$N$3*10000 -> 0 | R30: =K30/(100*100)*$N$3 -> 0.10187
B31: 06-3 | E31: 0.94 | G31: 0.29 | K31: =d147Mapping!$E$318 -> 104.65 | M31: =SUM(E31,G31,H31,J31) -> 1.23 | N31: =E31/1000*$N$3*10000 -> 94 | O31: =G31/1000*$N$3*10000 -> 29 | P31: =J31/1000*$N$3*10000 -> 0 | Q31: =(H31+J31)/1000*$N$3*10000 -> 0 | R31: =K31/(100*100)*$N$3 -> 0.10465
B32: 06-4 | E32: 0.41 | G32: 0.15 | K32: =d147Mapping!$E$332 -> 47.71 | M32: =SUM(E32,G32,H32,J32) -> 0.56 | N32: =E32/1000*$N$3*10000 -> 41 | O32: =G32/1000*$N$3*10000 -> 15 | P32: =J32/1000*$N$3*10000 -> 0 | Q32: =(H32+J32)/1000*$N$3*10000 -> 0 | R32: =K32/(100*100)*$N$3 -> 0.04771
B33: 07-1 | C33: 120-60 | N33: =E33/1000*$N$3*10000 -> 0 | P33: =G33/1000*$N$3*10000 -> 0 | Q33: =J33/1000*$N$3*10000 -> 0 | R33: =(H33+J33)/1000*$N$3*10000 -> 0 | S33: =K33/(100*100)*$N$3 -> 0
B34: 07-2 | C34: 80-60 | N34: =E34/1000*$N$3*10000 -> 0 | P34: =G34/1000*$N$3*10000 -> 0 | Q34: =J34/1000*$N$3*10000 -> 0 | R34: =(H34+J34)/1000*$N$3*10000 -> 0 | S34: =K34/(100*100)*$N$3 -> 0
B35: 07-3 | C35: 120-80 | N35: =E35/1000*$N$3*10000 -> 0 | P35: =G35/1000*$N$3*10000 -> 0 | Q35: =J35/1000*$N$3*10000 -> 0 | R35: =(H35+J35)/1000*$N$3*10000 -> 0 | S35: =K35/(100*100)*$N$3 -> 0
B36: 07-4 | C36: 80-80 | N36: =E36/1000*$N$3*10000 -> 0 | P36: =G36/1000*$N$3*10000 -> 0 | Q36: =J36/1000*$N$3*10000 -> 0 | R36: =(H36+J36)/1000*$N$3*10000 -> 0 | S36: =K36/(100*100)*$N$3 -> 0
B37: 08-1 | C37: 80-120 | N37: =E37/1000*$N$3*10000 -> 0 | P37: =G37/1000*$N$3*10000 -> 0 | Q37: =J37/1000*$N$3*10000 -> 0 | R37: =(H37+J37)/1000*$N$3*10000 -> 0 | S37: =K37/(100*100)*$N$3 -> 0
B38: 08-2 | C38: 120-120 | N38: =E38/1000*$N$3*10000 -> 0 | P38: =G38/1000*$N$3*10000 -> 0 | Q38: =J38/1000*$N$3*10000 -> 0 | R38: =(H38+J38)/1000*$N$3*10000 -> 0 | S38: =K38/(100*100)*$N$3 -> 0
B39: 08-3 | C39: 100-100 | N39: =E39/1000*$N$3*10000 -> 0 | P39: =G39/1000*$N$3*10000 -> 0 | Q39: =J39/1000*$N$3*10000 -> 0 | R39: =(H39+J39)/1000*$N$3*10000 -> 0 | S39: =K39/(100*100)*$N$3 -> 0
B40: 08-4 | C40: 100-80 | N40: =E40/1000*$N$3*10000 -> 0 | P40: =G40/1000*$N$3*10000 -> 0 | Q40: =J40/1000*$N$3*10000 -> 0 | R40: =(H40+J40)/1000*$N$3*10000 -> 0 | S40: =K40/(100*100)*$N$3 -> 0
B41: 09-1 | C41: 80-80 | N41: =E41/1000*$N$3*10000 -> 0 | P41: =G41/1000*$N$3*10000 -> 0 | Q41: =J41/1000*$N$3*10000 -> 0 | R41: =(H41+J41)/1000*$N$3*10000 -> 0 | S41: =K41/(100*100)*$N$3 -> 0
...

Sheet d160Mapping
B1: 2020 | C1: F13b4 | E1: Cotton | G1: Irrigation scheduling experiment
B2: Plant sampling and Mapping | G2: processed by: | H2: SMM- all done on d161
B4: Sampling Date: | C4: 43990 | N4: veg=vegetative branch. May or may not be a split stem | Q4: Seeing some new fruiting patterns this year with the new cotton variety. Multiple fruits on a branch node and multiple branches on mainstem nodes. If 2nd branch on the MS node is a vegetative branch, recorded the fruit under "Fruit on mainstem" and listed the node #. | T4: AA/SS/AA=a branch with 5 nodes. A, A, then a node with 2 Squares, then 2 more nodes. AA-SA=mainstem node with 2 branches. 1st is regular-sized fruiting branch (AA), 2nd is smaller branch (SA) {if just 1 fruit, it seems to be a branch, not just a MS fruit} | AG4: fruit | AH4: = node with a white flower in the 1st position. Need to calculate & enter NAWF,
B5: DOY: | C5: 160 | H5: A = abscised site S = square
B6: Sampling Time: | C6: 1000-1045h | H6: F = white flower G = green boll | N6: missing=no branch at node | AF6: fruit ( / or - ) | AH6: = node with multiple fruit or branches.
B7: Sampled By: | C7: SMM | H7: M = mature (open) boll
B9: Plot | C9: Plant # | D9: DOY Leaf Area Processed | E9: Leaf area of sample (cm2) | H9: Mapping | I9: Above ground height (cm) | J9: Total Main Stem nodes (including coteledonary) | K9: # pre-fruiting nodes | L9: Fruiting branches 1=first branch (above pre-fruiting nodes) | N9: Fruiting branches (cont) | P9: Fruiting branches (cont) | R9: Fruiting branches (cont) | T9: Fruiting branches (cont) | V9: Fruiting branches (cont) | X9: Fruiting branches (cont) | Z9: Fruiting branches (cont) | AB9: Fruiting branches (cont) | AD9: Fruiting branches (cont) | AF9: Fruit on mainstem | AH9: Fruit on non-fruiting branches | AI9: Fruit loose in sample bag | AJ9: NAWF | AK9: Boll with seeds? (Yes/No) | AL9: DOY into oven (stems & repro) | AM9: # branch nodes with more than one fruit | AN9: # mainstem nodes with more than 1 branch | AO9: # abscisions (fruiting branches) | AP9: # abscisions (non-fruiting branches) | AQ9: # abscisions (on main stem) | AR9: # squares (fruiting branches) | AS9: # squares (non-fruiting branches) | AT9: # squares (on main stem) | AU9: # white flowers (fruiting branches) | AV9: # white flowers (non-fruiting branches) | AW9: # white flowers (on main stem) | AX9: # green bolls (fruiting branches) | AY9: # green bolls (non-fruiting branches) | AZ9: # green bolls (on main stem) | BA9: # open bolls (fruiting branches) | BB9: # open bolls (non-fruiting branches) | BC9: # open bolls (on main stem) | BD9: # squares loose in bag | BE9: # flowers loose in bag | BF9: # bolls loose in bag | BG9: # open bolls loose in bag
B10: 01-1 | D10: 161 | E10: 432.94 | H10: Initials - - - - - DOY | AF10: node # | AO10: =SUM(AO11:AO22) -> 2 | AP10: =SUM(AP11:AP22) -> 0 | AQ10: =SUM(AQ11:AQ22) -> 0 | AR10: =SUM(AR11:AR22) -> 3 | AS10: =SUM(AS11:AS22) -> 0 | AT10: =SUM(AT11:AT22) -> 0 | AU10: =SUM(AU11:AU22) -> 0 | AV10: =SUM(AV11:AV22) -> 0 | ... BG10: =SUM(BG11:BG22) -> 0 | BH10: ← plot sums | BK10: =SUM(AO10:AQ10) -> 2 | BL10: =SUM(AR10:AT10,BD10) -> 3 | BM10: =SUM(AU10:AW10,BE10) -> 0 | BN10: =SUM(AX10:AZ10,BF10) -> 0 | BO10: =SUM(BA10:BC10,BG10) -> 0
C11: 1 | H11: 161 | I11: 27 | J11: 11 | K11: 6 | L11: 1 | M11: A | N11: 5 | O11: S | P11: 9 | R11: 13 | T11: 17 | V11: 21 | X11: 25 | Z11: 29 | AB11: 33 | AD11: 37 | AM11: =SUMPRODUCT(LEN($M11:$AE14)-LEN(SUBSTITUTE($M11:$AE14,"/", "")))/2 -> 0 | AN11: =SUMPRODUCT(LEN($M11:$AE14)-LEN(SUBSTITUTE($M11:$AE14,"-", ""))) -> 0 | AO11: =SUMPRODUCT(LEN($M11:$AE14)-LEN(SUBSTITUTE($M11:$AE14,"A", ""))) -> 2 | AP11: =SUMPRODUCT(LEN($AH11:$AH14)-LEN(SUBSTITUTE($AH11:$AH14,"A", ""))) -> 0 | AQ11: =SUMPRODUCT(LEN($AG11:$AG14)-LEN(SUBSTITUTE($AG11:$AG14,"A", ""))) -> 0 | AR11: =SUMPRODUCT(LEN($M11:$AE14)-LEN(SUBSTITUTE($M11:$AE14,"S", ""))) -> 3 | AS11: =SUMPRODUCT(LEN($AH11:$AH14)-LEN(SUBSTITUTE($AH11:$AH14,"S", ""))) -> 0 | AT11: =SUMPRODUCT(LEN($AG11:$AG14)-LEN(SUBSTITUTE($AG11:$AG14,"S", ""))) -> 0 | AU11: =SUMPRODUCT(LEN($M11:$AE14)-LEN(SUBSTITUTE($M11:$AE14,"F", ""))) -> 0 | AV11: =SUMPRODUCT(LEN($AH11:$AH14)-LEN(SUBSTITUTE($AH11:$AH14,"F", ""))) -> 0 | AW11: =SUMPRODUCT(LEN($AG11:$AG14)-LEN(SUBSTITUTE($AG11:$AG14,"F", ""))) -> 0 | AX11: =SUMPRODUCT(LEN($M11:$AE14)-LEN(SUBSTITUTE($M11:$AE14,"G", ""))) -> 0 | AY11: =SUMPRODUCT(LEN($AH11:$AH14)-LEN(SUBSTITUTE($AH11:$AH14,"G", ""))) -> 0 | AZ11: =SUMPRODUCT(LEN($AG11:$AG14)-LEN(SUBSTITUTE($AG11:$AG14,"G", ""))) -> 0 | BA11: =SUMPRODUCT(LEN($M11:$AE14)-LEN(SUBSTITUTE($M11:$AE14,"M", ""))) -> 0 | BB11: =SUMPRODUCT(LEN($AH11:$AH14)-LEN(SUBSTITUTE($AH11:$AH14,"M", ""))) -> 0 | BC11: =SUMPRODUCT(LEN($AG11:$AG14)-LEN(SUBSTITUTE($AG11:$AG14,"M", ""))) -> 0 | BD11: =SUMPRODUCT(LEN($AI11:$AI14)-LEN(SUBSTITUTE($AI11:$AI14,"S", ""))) -> 0 | BE11: =SUMPRODUCT(LEN($AI11:$AI14)-LEN(SUBSTITUTE($AI11:$AI14,"F", ""))) -> 0 | BF11: =SUMPRODUCT(LEN($AI11:$AI14)-LEN(SUBSTITUTE($AI11:$AI14,"G", ""))) -> 0 | BG11: =SUMPRODUCT(LEN($AI11:$AI14)-LEN(SUBSTITUTE($AI11:$AI14,"M", ""))) -> 0
L12: 2 | M12: A | N12: 6 | P12: 10 | R12: 14 | T12: 18 | V12: 22 | X12: 26 | Z12: 30 | AB12: 34 | AD12: 38
H13: SMM | L13: 3 | M13: S | N13: 7 | P13: 11 | R13: 15 | T13: 19 | V13: 23 | X13: 27 | Z13: 31 | AB13: 35 | AD13: 39
L14: 4 | M14: S | N14: 8 | P14: 12 | R14: 16 | T14: 20 | V14: 24 | X14: 28 | Z14: 32 | AB14: 36 | AD14: 40
C15: 2 | L15: 1- | N15: 5- | P15: 9- | R15: 13- | T15: 17- | V15: 21- | X15: 25- | Z15: 29- | AB15: 33- | AD15: 37- | AO15: =SUMPRODUCT(LEN($M15:$AE18)-LEN(SUBSTITUTE($M15:$AE18,"A", ""))) -> 0 | AP15: =SUMPRODUCT(LEN($AH15:$AH18)-LEN(SUBSTITUTE($AH15:$AH18,"A", ""))) -> 0 | AQ15: =SUMPRODUCT(LEN($AG15:$AG18)-LEN(SUBSTITUTE($AG15:$AG18,"A", ""))) -> 0 | AR15: =SUMPRODUCT(LEN($M15:$AE18)-LEN(SUBSTITUTE($M15:$AE18,"S", ""))) -> 0 | AS15: =SUMPRODUCT(LEN($AH15:$AH18)-LEN(SUBSTITUTE($AH15:$AH18,"S", ""))) -> 0 | AT15: =SUMPRODUCT(LEN($AG15:$AG18)-LEN(SUBSTITUTE($AG15:$AG18,"S", ""))) -> 0 | AU15: =SUMPRODUCT(LEN($M15:$AE18)-LEN(SUBSTITUTE($M15:$AE18,"F", ""))) -> 0 | AV15: =SUMPRODUCT(LEN($AH15:$AH18)-LEN(SUBSTITUTE($AH15:$AH18,"F", ""))) -> 0 | AW15: =SUMPRODUCT(LEN($AG15:$AG18)-LEN(SUBSTITUTE($AG15:$AG18,"F", ""))) -> 0 | AX15: =SUMPRODUCT(LEN($M15:$AE18)-LEN(SUBSTITUTE($M15:$AE18,"G", ""))) -> 0 | AY15: =SUMPRODUCT(LEN($AH15:$AH18)-LEN(SUBSTITUTE($AH15:$AH18,"G", ""))) -> 0 | AZ15: =SUMPRODUCT(LEN($AG15:$AG18)-LEN(SUBSTITUTE($AG15:$AG18,"G", ""))) -> 0 | BA15: =SUMPRODUCT(LEN($M15:$AE18)-LEN(SUBSTITUTE($M15:$AE18,"M", ""))) -> 0 | BB15: =SUMPRODUCT(LEN($AH15:$AH18)-LEN(SUBSTITUTE($AH15:$AH18,"M", ""))) -> 0 | BC15: =SUMPRODUCT(LEN($AG15:$AG18)-LEN(SUBSTITUTE($AG15:$AG18,"M", ""))) -> 0 | BD15: =SUMPRODUCT(LEN($AI15:$AI18)-LEN(SUBSTITUTE($AI15:$AI18,"S", ""))) -> 0 | BE15: =SUMPRODUCT(LEN($AI15:$AI18)-LEN(SUBSTITUTE($AI15:$AI18,"F", ""))) -> 0 | BF15: =SUMPRODUCT(LEN($AI15:$AI18)-LEN(SUBSTITUTE($AI15:$AI18,"G", ""))) -> 0 | BG15: =SUMPRODUCT(LEN($AI15:$AI18)-LEN(SUBSTITUTE($AI15:$AI18,"M", ""))) -> 0
G16: If blank, same person → | L16: 2- | N16: 6- | P16: 10- | R16: 14- | T16: 18- | V16: 22- | X16: 26- | Z16: 30- | AB16: 34- | AD16: 38-
G17: mapped plants 1 & 2 → | L17: 3- | N17: 7- | P17: 11- | R17: 15- | T17: 19- | V17: 23- | X17: 27- | Z17: 31- | AB17: 35- | AD17: 39
L18: 4- | N18: 8- | P18: 12- | R18: 16- | T18: 20 | V18: 24- | X18: 28- | Z18: 32- | AB18: 36- | AD18: 40-
C19: 3 | L19: 1- | N19: 5- | P19: 9- | R19: 13- | T19: 17- | V19: 21- | X19: 25- | Z19: 29- | AB19: 33- | AD19: 37- | AO19: =SUMPRODUCT(LEN($M19:$AE22)-LEN(SUBSTITUTE($M19:$AE22,"A", ""))) -> 0 | AP19: =SUMPRODUCT(LEN($AH19:$AH22)-LEN(SUBSTITUTE($AH19:$AH22,"A", ""))) -> 0 | AQ19: =SUMPRODUCT(LEN($AG19:$AG22)-LEN(SUBSTITUTE($AG19:$AG22,"A", ""))) -> 0 | AR19: =SUMPRODUCT(LEN($M19:$AE22)-LEN(SUBSTITUTE($M19:$AE22,"S", ""))) -> 0 | AS19: =SUMPRODUCT(LEN($AH19:$AH22)-LEN(SUBSTITUTE($AH19:$AH22,"S", ""))) -> 0 | AT19: =SUMPRODUCT(LEN($AG19:$AG22)-LEN(SUBSTITUTE($AG19:$AG22,"S", ""))) -> 0 | AU19: =SUMPRODUCT(LEN($M19:$AE22)-LEN(SUBSTITUTE($M19:$AE22,"F", ""))) -> 0 | AV19: =SUMPRODUCT(LEN($AH19:$AH22)-LEN(SUBSTITUTE($AH19:$AH22,"F", ""))) -> 0 | AW19: =SUMPRODUCT(LEN($AG19:$AG22)-LEN(SUBSTITUTE($AG19:$AG22,"F", ""))) -> 0 | AX19: =SUMPRODUCT(LEN($M19:$AE22)-LEN(SUBSTITUTE($M19:$AE22,"G", ""))) -> 0 | AY19: =SUMPRODUCT(LEN($AH19:$AH22)-LEN(SUBSTITUTE($AH19:$AH22,"G", ""))) -> 0 | AZ19: =SUMPRODUCT(LEN($AG19:$AG22)-LEN(SUBSTITUTE($AG19:$AG22,"G", ""))) -> 0 | BA19: =SUMPRODUCT(LEN($M19:$AE22)-LEN(SUBSTITUTE($M19:$AE22,"M", ""))) -> 0 | BB19: =SUMPRODUCT(LEN($AH19:$AH22)-LEN(SUBSTITUTE($AH19:$AH22,"M", ""))) -> 0 | BC19: =SUMPRODUCT(LEN($AG19:$AG22)-LEN(SUBSTITUTE($AG19:$AG22,"M", ""))) -> 0 | BD19: =SUMPRODUCT(LEN($AI19:$AI22)-LEN(SUBSTITUTE($AI19:$AI22,"S", ""))) -> 0 | BE19: =SUMPRODUCT(LEN($AI19:$AI22)-LEN(SUBSTITUTE($AI19:$AI22,"F", ""))) -> 0 | BF19: =SUMPRODUCT(LEN($AI19:$AI22)-LEN(SUBSTITUTE($AI19:$AI22,"G", ""))) -> 0 | BG19: =SUMPRODUCT(LEN($AI19:$AI22)-LEN(SUBSTITUTE($AI19:$AI22,"M", ""))) -> 0
L20: 2- | N20: 6- | P20: 10- | R20: 14- | T20: 18- | V20: 22- | X20: 26- | Z20: 30- | AB20: 34- | AD20: 38-
L21: 3- | N21: 7- | P21: 11- | R21: 15- | T21: 19- | V21: 23- | X21: 27- | Z21: 31- | AB21: 35- | AD21: 39
L22: 4- | N22: 8- | P22: 12- | R22: 16- | T22: 20 | V22: 24- | X22: 28- | Z22: 32- | AB22: 36- | AD22: 40-
B23: Plot | C23: Plant # | D23: DOY Leaf Area Processed | E23: Leaf area of sample (cm2) | H23: Mapping | I23: Above ground height (cm) | J23: Total Main Stem nodes (including coteledonary) | K23: # pre-fruiting nodes | L23: Fruiting branches 1=first branch (above pre-fruiting nodes) | N23: Fruiting branches (cont) | P23: Fruiting branches (cont) | R23: Fruiting branches (cont) | T23: Fruiting branches (cont) | V23: Fruiting branches (cont) | X23: Fruiting branches (cont) | Z23: Fruiting branches (cont) | AB23: Fruiting branches (cont) | AD23: Fruiting branches (cont) | AF23: Fruit on mainstem | AH23: Fruit on non-fruiting branches | AI23: Fruit loose in sample bag | AJ23: NAWF | AK23: Boll with seeds? (Yes/No) | AL23: DOY into oven (stems & repro) | AM23: # branch nodes with more than one fruit | AN23: # mainstem nodes with more than 1 branch | AO23: # abscisions (fruiting branches) | AP23: # abscisions (non-fruiting branches) | AQ23: # abscisions (on main stem) | AR23: # squares (fruiting branches) | AS23: # squares (non-fruiting branches) | AT23: # squares (on main stem) | AU23: # white flowers (fruiting branches) | AV23: # white flowers (non-fruiting branches) | AW23: # white flowers (on main stem) | AX23: # green bolls (fruiting branches) | AY23: # green bolls (non-fruiting branches) | AZ23: # green bolls (on main stem) | BA23: # open bolls (fruiting branches) | BB23: # open bolls (non-fruiting branches) | BC23: # open bolls (on main stem) | BD23: # squares loose in bag | BE23: # flowers loose in bag | BF23: # bolls loose in bag | BG23: # open bolls loose in bag
B24: 01-2 | E24: 512.78 | H24: Initials - - - - - DOY | AF24: node # | AO24: =SUM(AO25:AO36) -> 3 | AP24: =SUM(AP25:AP36) -> 0 | AQ24: =SUM(AQ25:AQ36) -> 0 | AR24: =SUM(AR25:AR36) -> 5 | AS24: =SUM(AS25:AS36) -> 0 | AT24: =SUM(AT25:AT36) -> 0 | AU24: =SUM(AU25:AU36) -> 0 | AV24: =SUM(AV25:AV36) -> 0 | ... BG24: =SUM(BG25:BG36) -> 0 | BH24: ← plot sums | BK24: =SUM(AO24:AQ24) -> 3 | BL24: =SUM(AR24:AT24,BD24) -> 5 | BM24: =SUM(AU24:AW24,BE24) -> 0 | BN24: =SUM(AX24:AZ24,BF24) -> 0 | BO24: =SUM(BA24:BC24,BG24) -> 0
C25: 1 | I25: 31 | J25: 10 | K25: 5 | L25: 1 | M25: SA | N25: 5 | O25: S | P25: 9 | R25: 13 | T25: 17 | V25: 21 | X25: 25 | Z25: 29 | AB25: 33 | AD25: 37 | AM25: =SUMPRODUCT(LEN($M25:$AE28)-LEN(SUBSTITUTE($M25:$AE28,"/", "")))/2 -> 0 | AN25: =SUMPRODUCT(LEN($M25:$AE28)-LEN(SUBSTITUTE($M25:$AE28,"-", ""))) -> 0 | AO25: =SUMPRODUCT(LEN($M25:$AE28)-LEN(SUBSTITUTE($M25:$AE28,"A", ""))) -> 3 | AP25: =SUMPRODUCT(LEN($AH25:$AH28)-LEN(SUBSTITUTE($AH25:$AH28,"A", ""))) -> 0 | AQ25: =SUMPRODUCT(LEN($AG25:$AG28)-LEN(SUBSTITUTE($AG25:$AG28,"A", ""))) -> 0 | AR25: =SUMPRODUCT(LEN($M25:$AE28)-LEN(SUBSTITUTE($M25:$AE28,"S", ""))) -> 5 | AS25: =SUMPRODUCT(LEN($AH25:$AH28)-LEN(SUBSTITUTE($AH25:$AH28,"S", ""))) -> 0 | AT25: =SUMPRODUCT(LEN($AG25:$AG28)-LEN(SUBSTITUTE($AG25:$AG28,"S", ""))) -> 0 | AU25: =SUMPRODUCT(LEN($M25:$AE28)-LEN(SUBSTITUTE($M25:$AE28,"F", ""))) -> 0 | AV25: =SUMPRODUCT(LEN($AH25:$AH28)-LEN(SUBSTITUTE($AH25:$AH28,"F", ""))) -> 0 | AW25: =SUMPRODUCT(LEN($AG25:$AG28)-LEN(SUBSTITUTE($AG25:$AG28,"F", ""))) -> 0 | AX25: =SUMPRODUCT(LEN($M25:$AE28)-LEN(SUBSTITUTE($M25:$AE28,"G", ""))) -> 0 | AY25: =SUMPRODUCT(LEN($AH25:$AH28)-LEN(SUBSTITUTE($AH25:$AH28,"G", ""))) -> 0 | AZ25: =SUMPRODUCT(LEN($AG25:$AG28)-LEN(SUBSTITUTE($AG25:$AG28,"G", ""))) -> 0 | BA25: =SUMPRODUCT(LEN($M25:$AE28)-LEN(SUBSTITUTE($M25:$AE28,"M", ""))) -> 0 | BB25: =SUMPRODUCT(LEN($AH25:$AH28)-LEN(SUBSTITUTE($AH25:$AH28,"M", ""))) -> 0 | BC25: =SUMPRODUCT(LEN($AG25:$AG28)-LEN(SUBSTITUTE($AG25:$AG28,"M", ""))) -> 0 | BD25: =SUMPRODUCT(LEN($AI25:$AI28)-LEN(SUBSTITUTE($AI25:$AI28,"S", ""))) -> 0 | BE25: =SUMPRODUCT(LEN($AI25:$AI28)-LEN(SUBSTITUTE($AI25:$AI28,"F", ""))) -> 0 | BF25: =SUMPRODUCT(LEN($AI25:$AI28)-LEN(SUBSTITUTE($AI25:$AI28,"G", ""))) -> 0 | BG25: =SUMPRODUCT(LEN($AI25:$AI28)-LEN(SUBSTITUTE($AI25:$AI28,"M", ""))) -> 0
L26: 2 | M26: AS | N26: 6 | P26: 10 | R26: 14 | T26: 18 | V26: 22 | X26: 26 | Z26: 30 | AB26: 34 | AD26: 38
L27: 3 | M27: AS | N27: 7 | P27: 11 | R27: 15 | T27: 19 | V27: 23 | X27: 27 | Z27: 31 | AB27: 35 | AD27: 39
L28: 4 | M28: S | N28: 8 | P28: 12 | R28: 16 | T28: 20 | V28: 24 | X28: 28 | Z28: 32 | AB28: 36 | AD28: 40
C29: 2 | L29: 1- | N29: 5- | P29: 9- | R29: 13- | T29: 17- | V29: 21- | X29: 25- | Z29: 29- | AB29: 33- | AD29: 37- | AO29: =SUMPRODUCT(LEN($M29:$AE32)-LEN(SUBSTITUTE($M29:$AE32,"A", ""))) -> 0 | AP29: =SUMPRODUCT(LEN($AH29:$AH32)-LEN(SUBSTITUTE($AH29:$AH32,"A", ""))) -> 0 | AQ29: =SUMPRODUCT(LEN($AG29:$AG32)-LEN(SUBSTITUTE($AG29:$AG32,"A", ""))) -> 0 | AR29: =SUMPRODUCT(LEN($M29:$AE32)-LEN(SUBSTITUTE($M29:$AE32,"S", ""))) -> 0 | AS29: =SUMPRODUCT(LEN($AH29:$AH32)-LEN(SUBSTITUTE($AH29:$AH32,"S", ""))) -> 0 | AT29: =SUMPRODUCT(LEN($AG29:$AG32)-LEN(SUBSTITUTE($AG29:$AG32,"S", ""))) -> 0 | AU29: =SUMPRODUCT(LEN($M29:$AE32)-LEN(SUBSTITUTE($M29:$AE32,"F", ""))) -> 0 | AV29: =SUMPRODUCT(LEN($AH29:$AH32)-LEN(SUBSTITUTE($AH29:$AH32,"F", ""))) -> 0 | AW29: =SUMPRODUCT(LEN($AG29:$AG32)-LEN(SUBSTITUTE($AG29:$AG32,"F", ""))) -> 0 | AX29: =SUMPRODUCT(LEN($M29:$AE32)-LEN(SUBSTITUTE($M29:$AE32,"G", ""))) -> 0 | AY29: =SUMPRODUCT(LEN($AH29:$AH32)-LEN(SUBSTITUTE($AH29:$AH32,"G", ""))) -> 0 | AZ29: =SUMPRODUCT(LEN($AG29:$AG32)-LEN(SUBSTITUTE($AG29:$AG32,"G", ""))) -> 0 | BA29: =SUMPRODUCT(LEN($M29:$AE32)-LEN(SUBSTITUTE($M29:$AE32,"M", ""))) -> 0 | BB29: =SUMPRODUCT(LEN($AH29:$AH32)-LEN(SUBSTITUTE($AH29:$AH32,"M", ""))) -> 0 | BC29: =SUMPRODUCT(LEN($AG29:$AG32)-LEN(SUBSTITUTE($AG29:$AG32,"M", ""))) -> 0 | BD29: =SUMPRODUCT(LEN($AI29:$AI32)-LEN(SUBSTITUTE($AI29:$AI32,"S", ""))) -> 0 | BE29: =SUMPRODUCT(LEN($AI29:$AI32)-LEN(SUBSTITUTE($AI29:$AI32,"F", ""))) -> 0 | BF29: =SUMPRODUCT(LEN($AI29:$AI32)-LEN(SUBSTITUTE($AI29:$AI32,"G", ""))) -> 0 | BG29: =SUMPRODUCT(LEN($AI29:$AI32)-LEN(SUBSTITUTE($AI29:$AI32,"M", ""))) -> 0
L30: 2- | N30: 6- | P30: 10- | R30: 14- | T30: 18- | V30: 22- | X30: 26- | Z30: 30- | AB30: 34- | AD30: 38-
L31: 3- | N31: 7- | P31: 11- | R31: 15- | T31: 19- | V31: 23- | X31: 27- | Z31: 31- | AB31: 35- | AD31: 39
L32: 4- | N32: 8- | P32: 12- | R32: 16- | T32: 20 | V32: 24- | X32: 28- | Z32: 32- | AB32: 36- | AD32: 40-
C33: 3 | L33: 1- | N33: 5- | P33: 9- | R33: 13- | T33: 17- | V33: 21- | X33: 25- | Z33: 29- | AB33: 33- | AD33: 37- | AO33: =SUMPRODUCT(LEN($M33:$AE36)-LEN(SUBSTITUTE($M33:$AE36,"A", ""))) -> 0 | AP33: =SUMPRODUCT(LEN($AH33:$AH36)-LEN(SUBSTITUTE($AH33:$AH36,"A", ""))) -> 0 | AQ33: =SUMPRODUCT(LEN($AG33:$AG36)-LEN(SUBSTITUTE($AG33:$AG36,"A", ""))) -> 0 | AR33: =SUMPRODUCT(LEN($M33:$AE36)-LEN(SUBSTITUTE($M33:$AE36,"S", ""))) -> 0 | AS33: =SUMPRODUCT(LEN($AH33:$AH36)-LEN(SUBSTITUTE($AH33:$AH36,"S", ""))) -> 0 | AT33: =SUMPRODUCT(LEN($AG33:$AG36)-LEN(SUBSTITUTE($AG33:$AG36,"S", ""))) -> 0 | AU33: =SUMPRODUCT(LEN($M33:$AE36)-LEN(SUBSTITUTE($M33:$AE36,"F", ""))) -> 0 | AV33: =SUMPRODUCT(LEN($AH33:$AH36)-LEN(SUBSTITUTE($AH33:$AH36,"F", ""))) -> 0 | AW33: =SUMPRODUCT(LEN($AG33:$AG36)-LEN(SUBSTITUTE($AG33:$AG36,"F", ""))) -> 0 | AX33: =SUMPRODUCT(LEN($M33:$AE36)-LEN(SUBSTITUTE($M33:$AE36,"G", ""))) -> 0 | AY33: =SUMPRODUCT(LEN($AH33:$AH36)-LEN(SUBSTITUTE($AH33:$AH36,"G", ""))) -> 0 | AZ33: =SUMPRODUCT(LEN($AG33:$AG36)-LEN(SUBSTITUTE($AG33:$AG36,"G", ""))) -> 0 | BA33: =SUMPRODUCT(LEN($M33:$AE36)-LEN(SUBSTITUTE($M33:$AE36,"M", ""))) -> 0 | BB33: =SUMPRODUCT(LEN($AH33:$AH36)-LEN(SUBSTITUTE($AH33:$AH36,"M", ""))) -> 0 | BC33: =SUMPRODUCT(LEN($AG33:$AG36)-LEN(SUBSTITUTE($AG33:$AG36,"M", ""))) -> 0 | BD33: =SUMPRODUCT(LEN($AI33:$AI36)-LEN(SUBSTITUTE($AI33:$AI36,"S", ""))) -> 0 | BE33: =SUMPRODUCT(LEN($AI33:$AI36)-LEN(SUBSTITUTE($AI33:$AI36,"F", ""))) -> 0 | BF33: =SUMPRODUCT(LEN($AI33:$AI36)-LEN(SUBSTITUTE($AI33:$AI36,"G", ""))) -> 0 | BG33: =SUMPRODUCT(LEN($AI33:$AI36)-LEN(SUBSTITUTE($AI33:$AI36,"M", ""))) -> 0
L34: 2- | N34: 6- | P34: 10- | R34: 14- | T34: 18- | V34: 22- | X34: 26- | Z34: 30- | AB34: 34- | AD34: 38-
L35: 3- | N35: 7- | P35: 11- | R35: 15- | T35: 19- | V35: 23- | X35: 27- | Z35: 31- | AB35: 35- | AD35: 39
L36: 4- | N36: 8- | P36: 12- | R36: 16- | T36: 20 | V36: 24- | X36: 28- | Z36: 32- | AB36: 36- | AD36: 40-
