Workbook

Sheet Height
A1: CCID | B1: DOY154 | C1: DOY167 | D1: DOY181 | E1: DOY195 | F1: DOY209 | G1: DOY224
A2: p01-1 | B2: 18 | C2: 39 | D2: 48 | E2: 68 | F2: 74 | G2: 72
A3: p01-2 | B3: 18 | C3: 39 | D3: 48 | E3: 69 | F3: 62 | G3: 70
A4: p01-3 | B4: 19 | C4: 33 | D4: 57 | E4: 74 | F4: 74 | G4: 84
A5: p01-4 | B5: 19 | C5: 38 | D5: 51 | E5: 68 | F5: 64 | G5: 66
A6: p01-5 | B6: 17 | C6: 38 | D6: 54 | E6: 69 | F6: 69 | G6: 74
A7: p01-6 | B7: 19 | C7: 38 | D7: 46 | E7: 56 | F7: 57 | G7: 62
A8: p02-1 | B8: 19 | C8: 31 | D8: 60 | E8: 88 | F8: 98 | G8: 102
A9: p02-2 | B9: 17 | C9: 39 | D9: 70 | E9: 97 | F9: 110 | G9: 118
A10: p02-3 | B10: 19 | C10: 35 | D10: 68 | E10: 100 | F10: 104 | G10: 102
A11: p02-4 | B11: 16 | C11: 36 | D11: 65 | E11: 92 | F11: 103 | G11: 97
A12: p02-5 | B12: 15 | C12: 33 | D12: 65 | E12: 92 | F12: 98 | G12: 97
A13: p02-6 | B13: 16 | C13: 33 | D13: 55 | E13: 71 | F13: 76 | G13: 77
... A67: p11-6 | B67: 21 | C67: 32 | D67: 50 | E67: 80 | F67: 91 | G67: 93

Sheet Width
A1: CCID | B1: DOY167 | C1: DOY181 | D1: DOY195 | E1: DOY209 | F1: DOY224
A2: p01-1 | B2: 31 | C2: 41 | D2: 58 | E2: 75 | F2: 8
A3: p01-2 | B3: 37 | C3: 39 | D3: 63 | E3: 70 | F3: 81
A4: p01-3 | B4: 34 | C4: 45 | D4: 69 | E4: 73 | F4: 91
A5: p01-4 | B5: 31 | C5: 38 | D5: 51 | E5: 55 | F5: 65
A6: p01-5 | B6: 33 | C6: 44 | D6: 60 | E6: 61 | F6: 76
A7: p01-6 | B7: 29 | C7: 37 | D7: 50 | E7: 64 | F7: 66
A8: p02-1 | B8: 30 | C8: 52 | D8: 71 | E8: 102 | F8: 102
A9: p02-2 | B9: 32 | C9: 58 | D9: 85 | E9: 102 | F9: 102
A10: p02-3 | B10: 34 | C10: 62 | D10: 82 | E10: 102 | F10: 102
A11: p02-4 | B11: 36 | C11: 54 | D11: 85 | E11: 102 | F11: 102
A12: p02-5 | B12: 34 | C12: 52 | D12: 68 | E12: 89 | F12: 102
A13: p02-6 | B13: 34 | C13: 44 | D13: 62 | E13: 74 | F13: 80
... A67: p11-6 | B67: 31 | C67: 37 | D67: 63 | E67: 78 | F67: 102

Sheet Summary-Plant Heights
A1: 2014 | B1: F013 - lateral move irrigation
B2: Cotton | D2: Irrigation Scheduling experiment
B4: Summary of Canopy Heights - all treatments
C5: Heights in cm
D7: Date: | E7: 3 & 4 June | F7: 41806 | G7: 41820 | H7: 41834 | I7: 41848 | J7: 41863
D8: doy: | E8: 154 & 155 | F8: 167 | G8: 181 | H8: 195 | I8: 209 | J8: 224
E9: from top of bed | F9: from top of bed | G9: from top of bed | H9: from top of bed | I9: from top of bed | J9: from top of bed | K9: from top of bed | L9: from top of bed | M9: from top of bed | N9: from top of bed | O9: from top of bed
B10: Span 1 | C10: Trt 1 | D10: NT 1 | E10: 18 | F10: 39 | G10: 48 | H10: 68 | I10: 74 | J10: 72
C11: Stress | D11: NT 2 | E11: 18 | F11: 39 | G11: 48 | H11: 69 | I11: 62 | J11: 70
D12: NT 3 | E12: 19 | F12: 33 | G12: 57 | H12: 74 | I12: 74 | J12: 84
D13: NT 4 | E13: 19 | F13: 38 | G13: 51 | H13: 68 | I13: 64 | J13: 66
D14: NT 5 | E14: 17 | F14: 38 | G14: 54 | H14: 69 | I14: 69 | J14: 74
D15: NT 6 | E15: 19 | F15: 38 | G15: 46 | H15: 56 | I15: 57 | J15: 62
B16: Span 1 | C16: Trt 2 | D16: NT 1 | E16: 19 | F16: 31 | G16: 60 | H16: 88 | I16: 98 | J16: 102
C17: FAO | D17: NT 2 | E17: 17 | F17: 39 | G17: 70 | H17: 97 | I17: 110 | J17: 118
D18: NT 3 | E18: 19 | F18: 35 | G18: 68 | H18: 100 | I18: 104 | J18: 102
D19: NT 4 | E19: 16 | F19: 36 | G19: 65 | H19: 92 | I19: 103 | J19: 97
D20: NT 5 | E20: 15 | F20: 33 | G20: 65 | H20: 92 | I20: 98 | J20: 97
D21: NT 6 | E21: 16 | F21: 33 | G21: 55 | H21: 71 | I21: 76 | J21: 77
B22: Span 2 | C22: Trt 3 | D22: NT 1 | E22: 19 | F22: 35 | G22: 59 | H22: 96 | I22: 111 | J22: 126
C23: CropMod | D23: NT 2 | E23: 17 | F23: 33 | G23: 61 | H23: 99 | I23: 112 | J23: 107
D24: NT 3 | E24: 22 | F24: 39 | G24: 70 | H24: 103 | I24: 116 | J24: 113
D25: NT 4 | E25: 20 | F25: 34 | G25: 54 | H25: 79 | I25: 102 | J25: 101
D26: NT 5 | E26: 21 | F26: 34 | G26: 60 | H26: 86 | I26: 95 | J26: 94
D27: NT 6 | E27: 18 | F27: 33 | G27: 55 | H27: 83 | I27: 88 | J27: 89
B28: Span 2 | C28: Trt 4 | D28: NT 1 | E28: 21 | F28: 42 | G28: 73 | H28: 97 | I28: 114 | J28: 116
C29: SEB | D29: NT 2 | E29: 20 | F29: 41 | G29: 76 | H29: 99 | I29: 109 | J29: 113
D30: NT 3 | E30: 21 | F30: 41 | G30: 78 | H30: 105 | I30: 109 | J30: 111
D31: NT 4 | E31: 21 | F31: 42 | G31: 67 | H31: 86 | I31: 95 | J31: 97
D32: NT 5 | E32: 19 | F32: 29 | G32: 58 | H32: 82 | I32: 90 | J32: 96
D33: NT 6 | E33: 19 | F33: 32 | G33: 51 | H33: 74 | I33: 72 | J33: 77
B34: Span 3 | C34: Trt 5 | D34: NT 1 | E34: 21 | F34: 36 | G34: 62 | H34: 97 | I34: 90 | J34: 110
C35: NDVI | D35: NT 2 | E35: 21 | F35: 40 | G35: 72 | H35: 103 | I35: 110 | J35: 121
D36: NT 3 | E36: 24 | F36: 40 | G36: 75 | H36: 108 | I36: 121 | J36: 124
D37: NT 4 | E37: 22 | F37: 39 | G37: 70 | H37: 100 | I37: 109 | J37: 100
D38: NT 5 | E38: 22 | F38: 40 | G38: 70 | H38: 97 | I38: 107 | J38: 102
D39: NT 6 | E39: 20 | F39: 34 | G39: 61 | H39: 78 | I39: 76 | J39: 91
B40: Span 3 | C40: Trt 6 | D40: NT 1 | E40: 16 | F40: 30 | G40: 46 | H40: 68 | I40: 64 | J40: 69
C41: Stress | D41: NT 2 | E41: 21 | F41: 33 | G41: 55 | H41: 76 | I41: 82 | J41: 83
D42: NT 3 | E42: 22 | F42: 35 | G42: 53 | H42: 68 | I42: 78 | J42: 80
...

Sheet Summary-Bed Heights
A1: 2014 | B1: F013 - lateral move irrigation
B2: Cotton | D2: Irrigation Scheduling experiment
B4: Summary of Canopy Heights from bottom of furrow - all treatments
C5: Heights in cm | O5: No more tractor runs. Did not take bed measurements
D7: Date: | E7: 3 & 4 June | G7: 41806 | I7: 41820 | K7: 41834 | M7: 41848 | O7: 41863
D8: doy: | E8: 154 & 155 | G8: 167 | I8: 181 | K8: 195 | M8: 209
E9: from bottom of furrow | F9: Bed elevation | G9: from bottom of furrow | H9: Bed elevation | I9: from bottom of furrow | J9: Bed elevation | K9: from bottom of furrow | L9: Bed elevation | M9: from bottom of furrow | N9: Bed elevation | O9: from bottom of furrow | P9: Bed elevation | Q9: from bottom of furrow | R9: Bed elevation | S9: from bottom of furrow | T9: Bed elevation | U9: from bottom of furrow | V9: Bed elevation | W9: from bottom of furrow | X9: Bed elevation | Y9: from bottom of furrow | Z9: Bed elevation
B10: Span 1 | C10: Trt 1 | D10: NT 1 | E10: 26 | F10: =E10-'Summary-Plant Heights'!E10 -> 8 | G10: 47 | H10: =G10-'Summary-Plant Heights'!F10 -> 8 | I10: 58 | J10: =I10-'Summary-Plant Heights'!G10 -> 10 | K10: 73 | L10: =K10-'Summary-Plant Heights'!H10 -> 5 | M10: 79 | N10: =M10-'Summary-Plant Heights'!I10 -> 5
C11: Stress | D11: NT 2 | E11: 25 | F11: =E11-'Summary-Plant Heights'!E11 -> 7 | G11: 47 | H11: =G11-'Summary-Plant Heights'!F11 -> 8 | I11: 55 | J11: =I11-'Summary-Plant Heights'!G11 -> 7 | K11: 74 | L11: =K11-'Summary-Plant Heights'!H11 -> 5 | M11: 69 | N11: =M11-'Summary-Plant Heights'!I11 -> 7
D12: NT 3 | E12: 26 | F12: =E12-'Summary-Plant Heights'!E12 -> 7 | G12: 45 | H12: =G12-'Summary-Plant Heights'!F12 -> 12 | I12: 65 | J12: =I12-'Summary-Plant Heights'!G12 -> 8 | K12: 80 | L12: =K12-'Summary-Plant Heights'!H12 -> 6 | M12: 83 | N12: =M12-'Summary-Plant Heights'!I12 -> 9
D13: NT 4 | E13: 25 | F13: =E13-'Summary-Plant Heights'!E13 -> 6 | G13: 46 | H13: =G13-'Summary-Plant Heights'!F13 -> 8 | I13: 59 | J13: =I13-'Summary-Plant Heights'!G13 -> 8 | K13: 71 | L13: =K13-'Summary-Plant Heights'!H13 -> 3 | M13: 72 | N13: =M13-'Summary-Plant Heights'!I13 -> 8
D14: NT 5 | E14: 25 | F14: =E14-'Summary-Plant Heights'!E14 -> 8 | G14: 47 | H14: =G14-'Summary-Plant Heights'!F14 -> 9 | I14: 61 | J14: =I14-'Summary-Plant Heights'!G14 -> 7 | K14: 74 | L14: =K14-'Summary-Plant Heights'!H14 -> 5 | M14: 78 | N14: =M14-'Summary-Plant Heights'!I14 -> 9
D15: NT 6 | E15: 26 | F15: =E15-'Summary-Plant Heights'!E15 -> 7 | G15: 49 | H15: =G15-'Summary-Plant Heights'!F15 -> 11 | I15: 58 | J15: =I15-'Summary-Plant Heights'!G15 -> 12 | K15: 63 | L15: =K15-'Summary-Plant Heights'!H15 -> 7 | M15: 68 | N15: =M15-'Summary-Plant Heights'!I15 -> 11
B16: Span 1 | C16: Trt 2 | D16: NT 1 | E16: 23 | F16: =E16-'Summary-Plant Heights'!E16 -> 4 | G16: 42 | H16: =G16-'Summary-Plant Heights'!F16 -> 11 | I16: 69 | J16: =I16-'Summary-Plant Heights'!G16 -> 9 | K16: 92 | L16: =K16-'Summary-Plant Heights'!H16 -> 4 | M16: 103 | N16: =M16-'Summary-Plant Heights'!I16 -> 5
C17: FAO | D17: NT 2 | E17: 25 | F17: =E17-'Summary-Plant Heights'!E17 -> 8 | G17: 47 | H17: =G17-'Summary-Plant Heights'!F17 -> 8 | I17: 77 | J17: =I17-'Summary-Plant Heights'!G17 -> 7 | K17: 103 | L17: =K17-'Summary-Plant Heights'!H17 -> 6 | M17: 117 | N17: =M17-'Summary-Plant Heights'!I17 -> 7
D18: NT 3 | E18: 23 | F18: =E18-'Summary-Plant Heights'!E18 -> 4 | G18: 43 | H18: =G18-'Summary-Plant Heights'!F18 -> 8 | I18: 73 | J18: =I18-'Summary-Plant Heights'!G18 -> 5 | K18: 107 | L18: =K18-'Summary-Plant Heights'!H18 -> 7 | M18: 114 | N18: =M18-'Summary-Plant Heights'!I18 -> 10
D19: NT 4 | E19: 25 | F19: =E19-'Summary-Plant Heights'!E19 -> 9 | G19: 48 | H19: =G19-'Summary-Plant Heights'!F19 -> 12 | I19: 70 | J19: =I19-'Summary-Plant Heights'!G19 -> 5 | K19: 99 | L19: =K19-'Summary-Plant Heights'!H19 -> 7 | M19: 112 | N19: =M19-'Summary-Plant Heights'!I19 -> 9
D20: NT 5 | E20: 22 | F20: =E20-'Summary-Plant Heights'!E20 -> 7 | G20: 43 | H20: =G20-'Summary-Plant Heights'!F20 -> 10 | I20: 70 | J20: =I20-'Summary-Plant Heights'!G20 -> 5 | K20: 97 | L20: =K20-'Summary-Plant Heights'!H20 -> 5 | M20: 107 | N20: =M20-'Summary-Plant Heights'!I20 -> 9
D21: NT 6 | E21: 24 | F21: =E21-'Summary-Plant Heights'!E21 -> 8 | G21: 46 | H21: =G21-'Summary-Plant Heights'!F21 -> 13 | I21: 63 | J21: =I21-'Summary-Plant Heights'!G21 -> 8 | K21: 78 | L21: =K21-'Summary-Plant Heights'!H21 -> 7 | M21: 80 | N21: =M21-'Summary-Plant Heights'!I21 -> 4
B22: Span 2 | C22: Trt 3 | D22: NT 1 | E22: 25 | F22: =E22-'Summary-Plant Heights'!E22 -> 6 | G22: 43 | H22: =G22-'Summary-Plant Heights'!F22 -> 8 | I22: 69 | J22: =I22-'Summary-Plant Heights'!G22 -> 10 | K22: 103 | L22: =K22-'Summary-Plant Heights'!H22 -> 7 | M22: 121 | N22: =M22-'Summary-Plant Heights'!I22 -> 10
C23: CropMod | D23: NT 2 | E23: 24 | F23: =E23-'Summary-Plant Heights'!E23 -> 7 | G23: 41 | H23: =G23-'Summary-Plant Heights'!F23 -> 8 | I23: 69 | J23: =I23-'Summary-Plant Heights'!G23 -> 8 | K23: 105 | L23: =K23-'Summary-Plant Heights'!H23 -> 6 | M23: 121 | N23: =M23-'Summary-Plant Heights'!I23 -> 9
D24: NT 3 | E24: 27 | F24: =E24-'Summary-Plant Heights'!E24 -> 5 | G24: 54 | H24: =G24-'Summary-Plant Heights'!F24 -> 15 | I24: 77 | J24: =I24-'Summary-Plant Heights'!G24 -> 7 | K24: 110 | L24: =K24-'Summary-Plant Heights'!H24 -> 7 | M24: 124 | N24: =M24-'Summary-Plant Heights'!I24 -> 8
D25: NT 4 | E25: 26 | F25: =E25-'Summary-Plant Heights'!E25 -> 6 | G25: 45 | H25: =G25-'Summary-Plant Heights'!F25 -> 11 | I25: 61 | J25: =I25-'Summary-Plant Heights'!G25 -> 7 | K25: 84 | L25: =K25-'Summary-Plant Heights'!H25 -> 5 | M25: 110 | N25: =M25-'Summary-Plant Heights'!I25 -> 8
D26: NT 5 | E26: 28 | F26: =E26-'Summary-Plant Heights'!E26 -> 7 | G26: 43 | H26: =G26-'Summary-Plant Heights'!F26 -> 9 | I26: 70 | J26: =I26-'Summary-Plant Heights'!G26 -> 10 | K26: 92 | L26: =K26-'Summary-Plant Heights'!H26 -> 6 | M26: 101 | N26: =M26-'Summary-Plant Heights'!I26 -> 6
D27: NT 6 | E27: 24 | F27: =E27-'Summary-Plant Heights'!E27 -> 6 | G27: 44 | H27: =G27-'Summary-Plant Heights'!F27 -> 11 | I27: 66 | J27: =I27-'Summary-Plant Heights'!G27 -> 11 | K27: 90 | L27: =K27-'Summary-Plant Heights'!H27 -> 7 | M27: 96 | N27: =M27-'Summary-Plant Heights'!I27 -> 8
B28: Span 2 | C28: Trt 4 | D28: NT 1 | E28: 28 | F28: =E28-'Summary-Plant Heights'!E28 -> 7 | G28: 55 | H28: =G28-'Summary-Plant Heights'!F28 -> 13 | I28: 81 | J28: =I28-'Summary-Plant Heights'!G28 -> 8 | K28: 104 | L28: =K28-'Summary-Plant Heights'!H28 -> 7 | M28: 121 | N28: =M28-'Summary-Plant Heights'!I28 -> 7
C29: SEB | D29: NT 2 | E29: 25 | F29: =E29-'Summary-Plant Heights'!E29 -> 5 | G29: 50 | H29: =G29-'Summary-Plant Heights'!F29 -> 9 | I29: 81 | J29: =I29-'Summary-Plant Heights'!G29 -> 5 | K29: 103 | L29: =K29-'Summary-Plant Heights'!H29 -> 4 | M29: 118 | N29: =M29-'Summary-Plant Heights'!I29 -> 9
D30: NT 3 | E30: 27 | F30: =E30-'Summary-Plant Heights'!E30 -> 6 | G30: 53 | H30: =G30-'Summary-Plant Heights'!F30 -> 12 | I30: 82 | J30: =I30-'Summary-Plant Heights'!G30 -> 4 | K30: 110 | L30: =K30-'Summary-Plant Heights'!H30 -> 5 | M30: 117 | N30: =M30-'Summary-Plant Heights'!I30 -> 8
D31: NT 4 | E31: 27 | F31: =E31-'Summary-Plant Heights'!E31 -> 6 | G31: 52 | H31: =G31-'Summary-Plant Heights'!F31 -> 10 | I31: 74 | J31: =I31-'Summary-Plant Heights'!G31 -> 7 | K31: 92 | L31: =K31-'Summary-Plant Heights'!H31 -> 6 | M31: 106 | N31: =M31-'Summary-Plant Heights'!I31 -> 11
D32: NT 5 | E32: 23 | F32: =E32-'Summary-Plant Heights'!E32 -> 4 | G32: 38 | H32: =G32-'Summary-Plant Heights'!F32 -> 9 | I32: 64 | J32: =I32-'Summary-Plant Heights'!G32 -> 6 | K32: 88 | L32: =K32-'Summary-Plant Heights'!H32 -> 6 | M32: 97 | N32: =M32-'Summary-Plant Heights'!I32 -> 7
D33: NT 6 | E33: 22 | F33: =E33-'Summary-Plant Heights'!E33 -> 3 | G33: 40 | H33: =G33-'Summary-Plant Heights'!F33 -> 8 | I33: 60 | J33: =I33-'Summary-Plant Heights'!G33 -> 9 | K33: 82 | L33: =K33-'Summary-Plant Heights'!H33 -> 8 | M33: 82 | N33: =M33-'Summary-Plant Heights'!I33 -> 10
B34: Span 3 | C34: Trt 5 | D34: NT 1 | E34: 28 | F34: =E34-'Summary-Plant Heights'!E34 -> 7 | G34: 44 | H34: =G34-'Summary-Plant Heights'!F34 -> 8 | I34: 68 | J34: =I34-'Summary-Plant Heights'!G34 -> 6 | K34: 102 | L34: =K34-'Summary-Plant Heights'!H34 -> 5 | M34: 97 | N34: =M34-'Summary-Plant Heights'!I34 -> 7
C35: NDVI | D35: NT 2 | E35: 29 | F35: =E35-'Summary-Plant Heights'!E35 -> 8 | G35: 49 | H35: =G35-'Summary-Plant Heights'!F35 -> 9 | I35: 79 | J35: =I35-'Summary-Plant Heights'!G35 -> 7 | K35: 110 | L35: =K35-'Summary-Plant Heights'!H35 -> 7 | M35: 118 | N35: =M35-'Summary-Plant Heights'!I35 -> 8
D36: NT 3 | E36: 29 | F36: =E36-'Summary-Plant Heights'!E36 -> 5 | G36: 48 | H36: =G36-'Summary-Plant Heights'!F36 -> 8 | I36: 80 | J36: =I36-'Summary-Plant Heights'!G36 -> 5 | K36: 112 | L36: =K36-'Summary-Plant Heights'!H36 -> 4 | M36: 129 | N36: =M36-'Summary-Plant Heights'!I36 -> 8
D37: NT 4 | E37: 28 | F37: =E37-'Summary-Plant Heights'!E37 -> 6 | G37: 43 | H37: =G37-'Summary-Plant Heights'!F37 -> 4 | I37: 77 | J37: =I37-'Summary-Plant Heights'!G37 -> 7 | K37: 107 | L37: =K37-'Summary-Plant Heights'!H37 -> 7 | M37: 117 | N37: =M37-'Summary-Plant Heights'!I37 -> 8
D38: NT 5 | E38: 28 | F38: =E38-'Summary-Plant Heights'!E38 -> 6 | G38: 45 | H38: =G38-'Summary-Plant Heights'!F38 -> 5 | I38: 74 | J38: =I38-'Summary-Plant Heights'!G38 -> 4 | K38: 101 | L38: =K38-'Summary-Plant Heights'!H38 -> 4 | M38: 116 | N38: =M38-'Summary-Plant Heights'!I38 -> 9
D39: NT 6 | E39: 26 | F39: =E39-'Summary-Plant Heights'!E39 -> 6 | G39: 39 | H39: =G39-'Summary-Plant Heights'!F39 -> 5 | I39: 66 | J39: =I39-'Summary-Plant Heights'!G39 -> 5 | K39: 83 | L39: =K39-'Summary-Plant Heights'!H39 -> 5 | M39: 84 | N39: =M39-'Summary-Plant Heights'!I39 -> 8
B40: Span 3 | C40: Trt 6 | D40: NT 1 | E40: 24 | F40: =E40-'Summary-Plant Heights'!E40 -> 8 | G40: 42 | H40: =G40-'Summary-Plant Heights'!F40 -> 12 | I40: 56 | J40: =I40-'Summary-Plant Heights'!G40 -> 10 | K40: 76 | L40: =K40-'Summary-Plant Heights'!H40 -> 8 | M40: 71 | N40: =M40-'Summary-Plant Heights'!I40 -> 7
C41: Stress | D41: NT 2 | E41: 28 | F41: =E41-'Summary-Plant Heights'!E41 -> 7 | G41: 41 | H41: =G41-'Summary-Plant Heights'!F41 -> 8 | I41: 63 | J41: =I41-'Summary-Plant Heights'!G41 -> 8 | K41: 83 | L41: =K41-'Summary-Plant Heights'!H41 -> 7 | M41: 91 | N41: =M41-'Summary-Plant Heights'!I41 -> 9
D42: NT 3 | E42: 28 | F42: =E42-'Summary-Plant Heights'!E42 -> 6 | G42: 47 | H42: =G42-'Summary-Plant Heights'!F42 -> 12 | I42: 64 | J42: =I42-'Summary-Plant Heights'!G42 -> 11 | K42: 74 | L42: =K42-'Summary-Plant Heights'!H42 -> 6 | M42: 86 | N42: =M42-'Summary-Plant Heights'!I42 -> 8
...

Sheet Summary-Cover
A1: 2014 | B1: F013 - lateral move irrigation
B2: Cotton | D2: Irrigation Scheduling experiment
B4: Summary of Canopy Cover - all treatments
C5: Widths in cm
C6: Did not measure widths the first time I measured heights (3 & 4 June) - smm | K6: Blank = closed canopy
D7: Date: | E7: 41806 | G7: 41820 | I7: 41834 | K7: 41848 | M7: 41863
D8: doy: | E8: 167 | G8: 181 | I8: 195 | K8: 209 | M8: 224
E9: Canopy Cover | F9: Width between rows | G9: Canopy Cover | H9: Width between rows | I9: Canopy Cover | J9: Width between rows | K9: Canopy Cover | L9: Width between rows | M9: Canopy Cover | N9: Width between rows | O9: Canopy Cover | P9: Width between rows | Q9: Canopy Cover | R9: Width between rows | S9: Canopy Cover | T9: Width between rows | U9: Canopy Cover | V9: Width between rows | W9: Canopy Cover | X9: Width between rows | Y9: Canopy Cover | Z9: Width between rows
B10: Span 1 | C10: Trt 1 | D10: NT 1 | E10: 31 | F10: 71 | G10: 41 | H10: 63 | I10: 58 | J10: 45 | K10: 75 | L10: 30 | M10: 8 | N10: 18
C11: Stress | D11: NT 2 | E11: 37 | F11: 68 | G11: 39 | H11: 59 | I11: 63 | J11: 43 | K11: 70 | L11: 34 | M11: 81 | N11: 21
D12: NT 3 | E12: 34 | F12: 63 | G12: 45 | H12: 57 | I12: 69 | J12: 28 | K12: 73 | L12: 32 | M12: 91 | N12: 16
D13: NT 4 | E13: 31 | F13: 67 | G13: 38 | H13: 63 | I13: 51 | J13: 50 | K13: 55 | L13: 46 | M13: 65 | N13: 40
D14: NT 5 | E14: 33 | F14: 64 | G14: 44 | H14: 58 | I14: 60 | J14: 43 | K14: 61 | L14: 34 | M14: 76 | N14: 31
D15: NT 6 | E15: 29 | F15: 72 | G15: 37 | H15: 66 | I15: 50 | J15: 51 | K15: 64 | L15: 40 | M15: 66 | N15: 47
B16: Span 1 | C16: Trt 2 | D16: NT 1 | E16: 30 | F16: 69 | G16: 52 | H16: 48 | I16: 71 | J16: 28 | K16: 102 | M16: 102
C17: FAO | D17: NT 2 | E17: 32 | F17: 69 | G17: 58 | H17: 46 | I17: 85 | J17: 16 | K17: 102 | M17: 102
D18: NT 3 | E18: 34 | F18: 63 | G18: 62 | H18: 35 | I18: 82 | J18: 16 | K18: 102 | M18: 102
D19: NT 4 | E19: 36 | F19: 66 | G19: 54 | H19: 44 | I19: 85 | J19: 18 | K19: 102 | M19: 102
D20: NT 5 | E20: 34 | F20: 62 | G20: 52 | H20: 37 | I20: 68 | J20: 26 | K20: 89 | L20: 12 | M20: 102
D21: NT 6 | E21: 34 | F21: 63 | G21: 44 | H21: 57 | I21: 62 | J21: 40 | K21: 74 | L21: 30 | M21: 80 | N21: 23
B22: Span 2 | C22: Trt 3 | D22: NT 1 | E22: 29 | F22: 64 | G22: 51 | H22: 47 | I22: 81 | J22: 24 | K22: 102 | M22: 102
C23: CropMod | D23: NT 2 | E23: 28 | F23: 70 | G23: 56 | H23: 45 | I23: 73 | J23: 16 | K23: 102 | M23: 102
D24: NT 3 | E24: 36 | F24: 67 | G24: 58 | H24: 44 | I24: 89 | J24: 13 | K24: 102 | M24: 102
D25: NT 4 | E25: 29 | F25: 70 | G25: 51 | H25: 52 | I25: 74 | J25: 24 | K25: 102 | M25: 102
D26: NT 5 | E26: 31 | F26: 69 | G26: 50 | H26: 53 | I26: 68 | J26: 27 | K26: 102 | M26: 102
D27: NT 6 | E27: 27 | F27: 72 | G27: 48 | H27: 57 | I27: 63 | J27: 37 | K27: 69 | L27: 32 | M27: 102
B28: Span 2 | C28: Trt 4 | D28: NT 1 | E28: 36 | F28: 65 | G28: 63 | H28: 33 | I28: 93 | J28: 18 | K28: 102 | M28: 102
C29: SEB | D29: NT 2 | E29: 36 | F29: 63 | G29: 61 | H29: 43 | I29: 93 | J29: 19 | K29: 102 | M29: 102
D30: NT 3 | E30: 38 | F30: 58 | G30: 63 | H30: 43 | I30: 85 | J30: 14 | K30: 102 | M30: 102
D31: NT 4 | E31: 39 | F31: 65 | G31: 62 | H31: 43 | I31: 77 | J31: 22 | K31: 102 | M31: 102
D32: NT 5 | E32: 24 | F32: 75 | G32: 51 | H32: 48 | I32: 75 | J32: 24 | K32: 102 | M32: 102
D33: NT 6 | E33: 27 | F33: 65 | G33: 44 | H33: 54 | I33: 64 | J33: 28 | K33: 79 | L33: 22 | M33: 83 | N33: 21
B34: Span 3 | C34: Trt 5 | D34: NT 1 | E34: 36 | F34: 44 | G34: 52 | H34: 47 | I34: 78 | J34: 15 | K34: 78 | L34: 23 | M34: 102
C35: NDVI | D35: NT 2 | E35: 30 | F35: 72 | G35: 60 | H35: 42 | I35: 91 | J35: 11 | K35: 102 | M35: 102
D36: NT 3 | E36: 34 | F36: 68 | G36: 58 | H36: 41 | I36: 91 | J36: 10 | K36: 102 | M36: 102
D37: NT 4 | E37: 32 | F37: 67 | G37: 63 | H37: 41 | I37: 84 | J37: 16 | K37: 102 | M37: 102
D38: NT 5 | E38: 36 | F38: 66 | G38: 58 | H38: 41 | I38: 85 | J38: 16 | K38: 102 | M38: 102
D39: NT 6 | E39: 31 | F39: 72 | G39: 45 | H39: 57 | I39: 65 | J39: 26 | K39: 72 | L39: 32 | M39: 88 | N39: 14
B40: Span 3 | C40: Trt 6 | D40: NT 1 | E40: 28 | F40: 76 | G40: 38 | H40: 61 | I40: 56 | J40: 39 | K40: 50 | L40: 52 | M40: 70 | N40: 31
C41: Stress | D41: NT 2 | E41: 28 | F41: 76 | G41: 39 | H41: 62 | I41: 58 | J41: 56 | K41: 63 | L41: 40 | M41: 75 | N41: 26
...

Sheet Blank
A1: 2014 | B1: F013 - lateral move irrigation
B2: Cotton | D2: Irrigation Scheduling experiment
B4: Canopy Heights - all treatments | F4: Date: | H4: time: | P4: ← N
C5: Heights in cm | H5: initials:
C7: NT position 1 | G7: NT position 2 | K7: NT position 3 | O7: NT position 4 | S7: NT position 5 | W7: NT position 6
C8: from top of bed | D8: from bottom of furrow | E8: Width of canopy | F8: Between rows | G8: from top of bed | H8: from bottom of furrow | I8: Width of canopy | J8: Between rows | K8: from top of bed | L8: from bottom of furrow | M8: Width of canopy | N8: Between rows | O8: from top of bed | P8: from bottom of furrow | Q8: Width of canopy | R8: Between rows | S8: from top of bed | T8: from bottom of furrow | U8: Width of canopy | V8: Between rows | W8: from top of bed | X8: from bottom of furrow | Y8: Width of canopy | Z8: Between rows
B9: Trt 1
B10: Trt 2
B11: Trt 3
B12: Trt 4
B13: Trt 5
B14: Trt 6
B15: Trt 7
B16: Trt 8
B17: Trt 9
B18: Trt 10
B19: Trt 11
