Workbook

Sheet Height
A1: CCID | B1: DOY153 | C1: DOY166 | D1: DOY180 | E1: DOY194 | F1: DOY208 | G1: DOY223 | H1: DOY236 | I1: DOY251
A2: p02-1 | B2: 14 | C2: 33 | D2: 55 | E2: 74 | F2: 96 | G2: 97 | H2: 93 | I2: 98
A3: p02-2 | B3: 14 | C3: 30 | D3: 51 | E3: 64 | F3: 87 | G3: 96 | H3: 92 | I3: 95
A4: p02-3 | B4: 13 | C4: 29 | D4: 52 | E4: 72 | F4: 87 | G4: 95 | H4: 91 | I4: 84
A5: p02-4 | B5: 14 | C5: 37 | D5: 56 | E5: 69 | F5: 80 | G5: 89 | H5: 84 | I5: 92
A6: p02-5 | B6: 12 | C6: 39 | D6: 50 | E6: 60 | F6: 69 | G6: 84 | H6: 94 | I6: 88
A7: p03-1 | B7: 12 | C7: 31 | D7: 53 | E7: 70 | F7: 84 | G7: 89 | H7: 91 | I7: 101
A8: p03-2 | B8: 14 | C8: 35 | D8: 55 | E8: 78 | F8: 87 | G8: 97 | H8: 99 | I8: 103
A9: p03-3 | B9: 13 | C9: 32 | D9: 47 | E9: 66 | F9: 80 | G9: 90 | H9: 85 | I9: 95
A10: p03-4 | B10: 12 | C10: 31 | D10: 43 | E10: 65 | F10: 80 | G10: 94 | H10: 99 | I10: 96
A11: p03-5 | B11: 11 | C11: 31 | D11: 51 | E11: 66 | F11: 81 | G11: 91 | H11: 106 | I11: 108
A12: p04-1 | B12: 10 | C12: 30 | D12: 56 | E12: 73 | F12: 86 | G12: 97 | H12: 96 | I12: 96
A13: p04-2 | B13: 12 | C13: 28 | D13: 50 | E13: 71 | F13: 86 | G13: 97 | H13: 98 | I13: 95
... A51: p11-5 | B51: 9 | C51: 26 | D51: 38 | E51: 44 | F51: 49 | G51: 58 | H51: 56 | I51: 61

Sheet Width
A1: CCID | B1: DOY153 | C1: DOY166 | D1: DOY180 | E1: DOY194 | F1: DOY208 | G1: DOY223 | H1: DOY236 | I1: DOY251
A2: p02-1 | B2: 11 | C2: 30 | D2: 49 | E2: 63 | F2: 82 | G2: 102 | H2: 89 | I2: 102
A3: p02-2 | B3: 11 | C3: 28 | D3: 43 | E3: 64 | F3: 85 | G3: 102 | H3: 102 | I3: 102
A4: p02-3 | B4: 11 | C4: 23 | D4: 45 | E4: 58 | F4: 72 | G4: 93 | H4: 102 | I4: 102
A5: p02-4 | B5: 12 | C5: 34 | D5: 49 | E5: 62 | F5: 77 | G5: 96 | H5: 102 | I5: 102
A6: p02-5 | B6: 13 | C6: 28 | D6: 45 | E6: 48 | F6: 70 | G6: 79 | H6: 102 | I6: 102
A7: p03-1 | B7: 11 | C7: 26 | D7: 44 | E7: 59 | F7: 78 | G7: 102 | H7: 102 | I7: 102
A8: p03-2 | B8: 12 | C8: 32 | D8: 44 | E8: 72 | F8: 82 | G8: 102 | H8: 102 | I8: 102
A9: p03-3 | B9: 12 | C9: 29 | D9: 43 | E9: 56 | F9: 77 | G9: 86 | H9: 96 | I9: 102
A10: p03-4 | B10: 11 | C10: 25 | D10: 42 | E10: 57 | F10: 80 | G10: 102 | H10: 102 | I10: 102
A11: p03-5 | B11: 11 | C11: 27 | D11: 42 | E11: 52 | F11: 66 | G11: 84 | H11: 102 | I11: 102
A12: p04-1 | B12: 11 | C12: 25 | D12: 49 | E12: 65 | F12: 82 | G12: 102 | H12: 102 | I12: 102
A13: p04-2 | B13: 11 | C13: 25 | D13: 51 | E13: 66 | F13: 81 | G13: 102 | H13: 102 | I13: 102
... A51: p11-5 | B51: 7 | C51: 23 | D51: 38 | E51: 35 | F51: 42 | G51: 53 | H51: 50 | I51: 60

Sheet LAImeter
A1: CCID | B1: DOY166 | C1: DOY181 | D1: DOY195 | E1: DOY209 | F1: DOY224 | G1: DOY237 | H1: DOY252
A2: p02-1 | B2: 0.96 | C2: 1.16 | D2: 2.05 | E2: 3.41 | F2: 4.38 | G2: 5.76 | H2: 4.46
A3: p02-2 | B3: 0.58 | C3: 1.03 | D3: 1.87 | E3: 3.1 | F3: 3.66 | G3: 4.61 | H3: 4.97
A4: p02-3 | B4: 0.42 | C4: 1.19 | D4: 1.78 | E4: 2.86 | F4: 3.4 | G4: 4.46 | H4: 4.33
A5: p02-4 | B5: 0.61 | C5: 1.4 | D5: 2.07 | E5: 3.37 | F5: 4.52 | H5: 5.46
A6: p02-5 | B6: 0.5 | C6: 1.02 | D6: 1.55 | E6: 2.38 | F6: 3.25 | H6: 4.42
A7: p03-1 | B7: 0.54 | C7: 1.22 | D7: 1.87 | E7: 3.33 | F7: 4.2 | H7: 4.72
A8: p03-2 | B8: 0.49 | C8: 1.24 | D8: 2.31 | E8: 2.8 | F8: 6.08 | H8: 6.56
A9: p03-3 | B9: 0.38 | C9: 0.92 | D9: 1.67 | E9: 3.4 | F9: 3.98 | H9: 4.97
A10: p03-4 | B10: 0.69 | C10: 1.25 | D10: 1.8 | F10: 5.23 | H10: 5.83
A11: p03-5 | B11: 0.48 | C11: 1.12 | D11: 1.7 | E11: 2.82 | F11: 3.81 | H11: 4.97
A12: p06-1 | B12: 0.73 | C12: 1.31 | D12: 2.42 | E12: 3.37 | F12: 5.11 | H12: 4.55
A13: p06-2 | B13: 0.42 | C13: 1.34 | D13: 2.26 | E13: 3.16 | F13: 4.13 | H13: 4.96
A14: p06-3 | B14: 0.47 | C14: 1.11 | D14: 1.71 | E14: 3.04 | F14: 4.58 | H14: 4.5
A15: p06-4 | B15: 0.44 | C15: 0.99 | D15: 1.35 | E15: 2.46 | F15: 2.46 | H15: 2.82
A16: p06-5 | B16: 0.97 | C16: 1.3 | D16: 2.09 | E16: 2.96 | F16: 4.39 | H16: 4.53
A17: p07-1 | B17: 0.67 | C17: 1.04 | D17: 1.66 | E17: 3.18 | F17: 4.21 | H17: 5.04
A18: p07-2 | B18: 0.75 | C18: 1.26 | D18: 2.53 | E18: 3.96 | F18: 5.5 | H18: 5.82
A19: p07-3 | B19: 0.33 | C19: 1.12 | D19: 1.51 | E19: 3.35 | F19: 4.72 | H19: 6
A20: p07-4 | B20: 0.98 | C20: 1.28 | D20: 1.99 | E20: 3.77 | F20: 4.9 | H20: 5.66
A21: p07-5 | B21: 0.58 | C21: 0.84 | D21: 1.12 | E21: 1.79 | F21: 2.7 | H21: 3.58
A22: p10-1 | B22: 0.25 | C22: 1.02 | D22: 1.86 | E22: 3.44 | F22: 4.98 | H22: 5.37
... A31: p11-5 | B31: 0.4 | C31: 0.49 | D31: 0.81 | E31: 0.97 | F31: 1.38 | H31: 1.23

Sheet Density
A1: CCID | B1: PLPD
A2: p02-1 | B2: 9.8425197
A3: p02-2 | B3: 9.8425197
A4: p02-3 | B4: 9.8425197
A5: p02-4 | B5: 12.795276
A6: p02-5 | B6: 9.8425197
A7: p03-1 | B7: 12.795276
A8: p03-2 | B8: 10.826772
A9: p03-3 | B9: 10.826772
A10: p03-4 | B10: 9.8425197
A11: p03-5 | B11: 9.8425197
A12: p04-1 | B12: 6.8897638
A13: p04-2 | B13: 9.8425197
... A51: p11-5 | B51: 5.9055118

Sheet Develop
A1: CCID | B1: ADAT | C1: ADOY | D1: NAWF188 | E1: NAWF194 | F1: NAWF203 | G1: NAWF208 | H1: NAWF215 | I1: NAWF223 | J1: NAWF236 | K1: NAWF251
A2: p02-1 | B2: 42184 | C2: 180 | D2: 7 | E2: 6.5 | F2: 5 | G2: 4.5 | H2: 3.5 | I2: 3 | J2: 1.5 | K2: 2.5
A3: p02-2 | B3: 42188 | C3: 183.66667 | D3: 6.5 | E3: 6.5 | F3: 5.5 | G3: 5 | H3: 3.5 | I3: 3.5 | J3: 1.5 | K3: 3.5
A4: p02-3 | B4: 42186 | C4: 182 | D4: 6.5 | E4: 6.5 | F4: 4.5 | G4: 5 | H4: 3 | I4: 3.5 | J4: 1.5 | K4: 3
A5: p02-4 | B5: 42186 | C5: 181.75 | D5: 6 | E5: 5.5 | G5: 4.5 | H5: 3.5 | I5: 4 | J5: 1.5 | K5: 1.5
A6: p02-5 | B6: 42182 | C6: 178.125 | E6: 5 | G6: 3.5 | H6: 4 | I6: 4.5 | J6: 2.5 | K6: 1.5
A7: p03-1 | B7: 42184 | C7: 179.58333 | D7: 6.5 | E7: 6.5 | F7: 5 | G7: 6 | H7: 5 | I7: 4.5 | J7: 3 | K7: 2.5
A8: p03-2 | B8: 42184 | C8: 179.58333 | D8: 7 | E8: 5.5 | F8: 7 | G8: 5.5 | H8: 4 | I8: 4.5 | J8: 3.5 | K8: 2
A9: p03-3 | B9: 42186 | C9: 181.66667 | D9: 7 | E9: 6 | F9: 4 | G9: 6 | H9: 5 | I9: 4 | J9: 3.5 | K9: 2.5
A10: p03-4 | B10: 42183 | C10: 179.16667 | D10: 7.5 | E10: 6 | G10: 4 | H10: 5 | I10: 4.5 | J10: 3 | K10: 2.5
A11: p03-5 | B11: 42184 | C11: 180 | D11: 7.5 | E11: 5.5 | G11: 4.5 | H11: 4.5 | I11: 5.5 | J11: 4.5 | K11: 3.5
A12: p04-1 | B12: 42185 | C12: 181 | E12: 6.5 | G12: 4 | H12: 4.5 | I12: 3.5 | J12: 2 | K12: 3
A13: p04-2 | B13: 42186 | C13: 182 | E13: 6.5 | G13: 5.5 | H13: 4.5 | I13: 4 | J13: 2.5 | K13: 3
A14: p04-3 | B14: 42183 | C14: 179.16667 | E14: 5.5 | G14: 4 | H14: 5 | I14: 4 | J14: 2.5 | K14: 2.5
A15: p04-4 | B15: 42186 | C15: 181.5 | E15: 4.5 | G15: 4 | H15: 4 | I15: 4.5 | J15: 2 | K15: 3.5
A16: p04-5 | B16: 42187 | C16: 183 | E16: 6 | G16: 5 | H16: 3.5 | I16: 5 | J16: 3.5 | K16: 2
A17: p05-1 | B17: 42184 | C17: 180 | E17: 7 | G17: 5.5 | H17: 4 | I17: 3.5 | J17: 3.5 | K17: 2.5
A18: p05-2 | B18: 42186 | C18: 181.5 | E18: 6 | G18: 5 | H18: 4.5 | I18: 5 | J18: 2.5 | K18: 2
A19: p05-3 | B19: 42184 | C19: 179.58333 | E19: 6 | G19: 4.5 | H19: 5 | I19: 3.5 | J19: 2.5 | K19: 2
A20: p05-4 | B20: 42184 | C20: 180 | E20: 6 | G20: 4.5 | H20: 4.5 | I20: 4.5 | J20: 4 | K20: 3.5
A21: p05-5 | B21: 42183 | C21: 178.57143 | E21: 5 | G21: 3.5 | H21: 4.5 | I21: 5 | J21: 4 | K21: 2.5
A22: p06-1 | B22: 42186 | C22: 182 | D22: 7.5 | E22: 7 | F22: 5 | G22: 5 | H22: 4 | I22: 2.5 | J22: 1.5 | K22: 2
A23: p06-2 | B23: 42186 | C23: 182 | D23: 6.5 | E23: 6.5 | F23: 5 | G23: 4.5 | H23: 3 | I23: 2.5 | J23: 2 | K23: 2.5
A24: p06-3 | B24: 42184 | C24: 180.33333 | D24: 6 | E24: 6 | F24: 4 | G24: 4 | H24: 3.5 | I24: 3 | J24: 2 | K24: 2.5
A25: p06-4 | B25: 42183 | C25: 178.57143 | D25: 7.5 | E25: 5.5 | F25: 5 | G25: 3.5 | H25: 3 | I25: 2.5 | J25: 1 | K25: 1
A26: p06-5 | B26: 42184 | C26: 179.58333 | D26: 7 | E26: 6 | G26: 4 | H26: 2.5 | I26: 2.5 | J26: 2 | K26: 2
A27: p07-1 | B27: 42184 | C27: 179.58333 | D27: 8 | E27: 5 | F27: 5 | G27: 5.5 | H27: 5.5 | I27: 4.5 | J27: 4 | K27: 3
A28: p07-2 | B28: 42185 | C28: 181.33333 | D28: 8 | E28: 7 | F28: 6.5 | G28: 6 | H28: 5 | I28: 4.5 | J28: 3 | K28: 2.5
A29: p07-3 | B29: 42185 | C29: 180.625 | D29: 7 | E29: 5 | F29: 6.5 | G29: 4 | H29: 4.5 | I29: 5 | J29: 4.5 | K29: 3.5
A30: p07-4 | B30: 42187 | C30: 183 | D30: 7 | E30: 7 | F30: 5.5 | G30: 5.5 | H30: 4.5 | I30: 5 | J30: 3 | K30: 2
A31: p07-5 | B31: 42184 | C31: 179.64286 | E31: 4.5 | F31: 5.5 | G31: 4.5 | H31: 5 | I31: 4.5 | J31: 3.5 | K31: 1.5
A32: p08-1 | B32: 42187 | C32: 182.625 | E32: 6.5 | G32: 5.5 | H32: 4.5 | I32: 3.5 | J32: 3.5 | K32: 2.5
A33: p08-2 | B33: 42182 | C33: 178.25 | E33: 6.5 | G33: 6 | H33: 4.5 | I33: 4.5 | J33: 3 | K33: 2
A34: p08-3 | B34: 42186 | C34: 181.75 | E34: 6 | G34: 5 | H34: 4 | I34: 4.5 | J34: 4 | K34: 2.5
A35: p08-4 | B35: 42185 | C35: 181.4 | E35: 6 | G35: 5 | H35: 4.5 | I35: 4 | J35: 3 | K35: 2.5
A36: p08-5 | B36: 42187 | C36: 183 | E36: 4.5 | G36: 3.5 | H36: 4 | I36: 4.5 | J36: 4 | K36: 2
A37: p09-1 | B37: 42187 | C37: 182.83333 | E37: 6.5 | G37: 5 | H37: 3.5 | I37: 4.5 | J37: 3.5 | K37: 3
A38: p09-2 | B38: 42184 | C38: 180.33333 | E38: 6.5 | G38: 5.5 | H38: 4.5 | I38: 4.5 | J38: 3 | K38: 3
A39: p09-3 | B39: 42187 | C39: 182.8 | E39: 6 | G39: 4.5 | H39: 5 | I39: 4.5 | J39: 4 | K39: 3
A40: p09-4 | B40: 42185 | C40: 180.7 | E40: 6 | G40: 5.5 | H40: 4 | I40: 4.5 | J40: 3.5 | K40: 2
...

Sheet Summary-Plant Heights
A1: 2015 | B1: F013 - lateral move irrigation
B2: Cotton | D2: Irrigation Scheduling experiment
J3: bolls heavy + winds-branches starting to hang low
B4: Summary of Canopy Heights - all treatments
C5: Heights in cm
D7: Date: | E7: 42157 | F7: 42170 | G7: 42184 | H7: 42198 | I7: 42212 | J7: 42227 | K7: 42243 | L7: 42255
D8: doy: | E8: 153 | F8: 166 | G8: 180 | H8: 194 | I8: 208 | J8: 223 | K8: 236 | L8: 251
E9: from top of bed | F9: from top of bed | G9: from top of bed | H9: from top of bed | I9: from top of bed | J9: from top of bed | K9: from top of bed | L9: from top of bed | M9: from top of bed | N9: from top of bed | O9: from top of bed
B10: Span 1 | C10: Plot 2 | D10: NT 1 | E10: 14 | F10: 33 | G10: 55 | H10: 74 | I10: 96 | J10: 97 | K10: 93 | L10: 98
C11: FAO | D11: NT 2 | E11: 14 | F11: 30 | G11: 51 | H11: 64 | I11: 87 | J11: 96 | K11: 92 | L11: 95
D12: NT 3 | E12: 13 | F12: 29 | G12: 52 | H12: 72 | I12: 87 | J12: 95 | K12: 91 | L12: 84
D13: NT 4 | E13: 14 | F13: 37 | G13: 56 | H13: 69 | I13: 80 | J13: 89 | K13: 84 | L13: 92
D14: NT 5 | E14: 12 | F14: 39 | G14: 50 | H14: 60 | I14: 69 | J14: 84 | K14: 94 | L14: 88
B15: Span 2 | C15: Plot 3 | D15: NT 1 | E15: 12 | F15: 31 | G15: 53 | H15: 70 | I15: 84 | J15: 89 | K15: 91 | L15: 101
C16: CropMod | D16: NT 2 | E16: 14 | F16: 35 | G16: 55 | H16: 78 | I16: 87 | J16: 97 | K16: 99 | L16: 103
D17: NT 3 | E17: 13 | F17: 32 | G17: 47 | H17: 66 | I17: 80 | J17: 90 | K17: 85 | L17: 95
D18: NT 4 | E18: 12 | F18: 31 | G18: 43 | H18: 65 | I18: 80 | J18: 94 | K18: 99 | L18: 96
D19: NT 5 | E19: 11 | F19: 31 | G19: 51 | H19: 66 | I19: 81 | J19: 91 | K19: 106 | L19: 108
B20: Span 2 | C20: Plot 4 | D20: NT 1 | E20: 10 | F20: 30 | G20: 56 | H20: 73 | I20: 86 | J20: 97 | K20: 96 | L20: 96
C21: SEB | D21: NT 2 | E21: 12 | F21: 28 | G21: 50 | H21: 71 | I21: 86 | J21: 97 | K21: 98 | L21: 95
D22: NT 3 | E22: 13 | F22: 35 | G22: 54 | H22: 69 | I22: 88 | J22: 98 | K22: 97 | L22: 92
D23: NT 4 | E23: 14 | F23: 31 | G23: 49 | H23: 62 | I23: 76 | J23: 92 | K23: 87 | L23: 98
D24: NT 5 | E24: 11 | F24: 28 | G24: 47 | H24: 62 | I24: 79 | J24: 92 | K24: 98 | L24: 95
B25: Span 3 | C25: Plot 5 | D25: NT 1 | E25: 11 | F25: 28 | G25: 47 | H25: 64 | I25: 80 | J25: 88 | K25: 85 | L25: 90
C26: NDVI | D26: NT 2 | E26: 13 | F26: 30 | G26: 48 | H26: 69 | I26: 80 | J26: 90 | K26: 91 | L26: 86
D27: NT 3 | E27: 13 | F27: 31 | G27: 53 | H27: 71 | I27: 83 | J27: 86 | K27: 86 | L27: 100
D28: NT 4 | E28: 12 | F28: 29 | G28: 52 | H28: 67 | I28: 81 | J28: 94 | K28: 95 | L28: 98
D29: NT 5 | E29: 13 | F29: 30 | G29: 48 | H29: 59 | I29: 75 | J29: 80 | K29: 81 | L29: 108
B30: Span 3 | C30: Plot 6 | D30: NT 1 | E30: 11 | F30: 30 | G30: 54 | H30: 68 | I30: 94 | J30: 98 | K30: 91 | L30: 98
C31: Stress | D31: NT 2 | E31: 13 | F31: 32 | G31: 55 | H31: 73 | I31: 84 | J31: 86 | K31: 86 | L31: 92
D32: NT 3 | E32: 12 | F32: 35 | G32: 57 | H32: 69 | I32: 82 | J32: 89 | K32: 86 | L32: 88
D33: NT 4 | E33: 13 | F33: 36 | G33: 51 | H33: 59 | I33: 72 | J33: 76 | K33: 78 | L33: 79
D34: NT 5 | E34: 12 | F34: 32 | G34: 57 | H34: 75 | I34: 83 | J34: 84 | K34: 80 | L34: 90
B35: Span 4 | C35: Plot 7 | D35: NT 1 | E35: 11 | F35: 28 | G35: 48 | H35: 62 | I35: 75 | J35: 83 | K35: 93 | L35: 100
C36: CropMod | D36: NT 2 | E36: 12 | F36: 34 | G36: 51 | H36: 74 | I36: 89 | J36: 99 | K36: 107 | L36: 112
D37: NT 3 | E37: 12 | F37: 33 | G37: 48 | H37: 65 | I37: 79 | J37: 88 | K37: 98 | L37: 96
D38: NT 4 | E38: 11 | F38: 31 | G38: 50 | H38: 71 | I38: 88 | J38: 98 | K38: 98 | L38: 102
D39: NT 5 | E39: 12 | F39: 29 | G39: 40 | H39: 46 | I39: 56 | J39: 77 | K39: 84 | L39: 94
B40: Span 4 | C40: Plot 8 | D40: NT 1 | E40: 9 | F40: 33 | G40: 52 | H40: 71 | I40: 90 | J40: 89 | K40: 102 | L40: 99
C41: SEB | D41: NT 2 | E41: 12 | F41: 36 | G41: 61 | H41: 80 | I41: 106 | J41: 121 | K41: 128 | L41: 115
...

Sheet Summary-Bed Heights
A1: 2015 | B1: F013 - lateral move irrigation
B2: Cotton | D2: Irrigation Scheduling experiment
B4: Summary of Canopy Heights from bottom of furrow - all treatments
C5: Heights in cm
E6: cultivation happening - only took furrow measurments plots 2-7 (where cultivated)
D7: Date: | E7: 42157 | G7: 42170 | I7: 42184 | K7: 42198 | M7: 42212 | O7: 42227 | Q7: 42243 | S7: 42255
D8: doy: | E8: 153 | G8: 166 | I8: 180 | K8: 194 | M8: 208 | O8: 223 | Q8: 236 | S8: 251
E9: from bottom of furrow | F9: Bed elevation | G9: from bottom of furrow | H9: Bed elevation | I9: from bottom of furrow | J9: Bed elevation | K9: from bottom of furrow | L9: Bed elevation | M9: from bottom of furrow | N9: Bed elevation | O9: from bottom of furrow | P9: Bed elevation | Q9: from bottom of furrow | R9: Bed elevation | S9: from bottom of furrow | T9: Bed elevation | U9: from bottom of furrow | V9: Bed elevation | W9: from bottom of furrow | X9: Bed elevation | Y9: from bottom of furrow | Z9: Bed elevation
B10: Span 1 | C10: Plot 2 | D10: NT 1 | E10: 30 | F10: =E10-'Summary-Plant Heights'!E10 -> 16 | G10: 45 | H10: =G10-'Summary-Plant Heights'!F10 -> 12 | I10: 70 | J10: =I10-'Summary-Plant Heights'!G10 -> 15 | K10: 88 | L10: =K10-'Summary-Plant Heights'!H10 -> 14 | M10: 105 | N10: =M10-'Summary-Plant Heights'!I10 -> 9 | O10: 110 | P10: =O10-'Summary-Plant Heights'!J10 -> 13 | Q10: 107 | R10: =Q10-'Summary-Plant Heights'!K10 -> 14 | S10: 109 | T10: =S10-'Summary-Plant Heights'!L10 -> 11
C11: FAO | D11: NT 2 | E11: 32 | F11: =E11-'Summary-Plant Heights'!E11 -> 18 | G11: 45 | H11: =G11-'Summary-Plant Heights'!F11 -> 15 | I11: 65 | J11: =I11-'Summary-Plant Heights'!G11 -> 14 | K11: 82 | L11: =K11-'Summary-Plant Heights'!H11 -> 18 | M11: 96 | N11: =M11-'Summary-Plant Heights'!I11 -> 9 | O11: 105 | P11: =O11-'Summary-Plant Heights'!J11 -> 9 | Q11: 106 | R11: =Q11-'Summary-Plant Heights'!K11 -> 14 | S11: 107 | T11: =S11-'Summary-Plant Heights'!L11 -> 12
D12: NT 3 | E12: 31 | F12: =E12-'Summary-Plant Heights'!E12 -> 18 | G12: 45 | H12: =G12-'Summary-Plant Heights'!F12 -> 16 | I12: 67 | J12: =I12-'Summary-Plant Heights'!G12 -> 15 | K12: 83 | L12: =K12-'Summary-Plant Heights'!H12 -> 11 | M12: 97 | N12: =M12-'Summary-Plant Heights'!I12 -> 10 | O12: 104 | P12: =O12-'Summary-Plant Heights'!J12 -> 9 | Q12: 102 | R12: =Q12-'Summary-Plant Heights'!K12 -> 11 | S12: 94 | T12: =S12-'Summary-Plant Heights'!L12 -> 10
D13: NT 4 | E13: 31 | F13: =E13-'Summary-Plant Heights'!E13 -> 17 | G13: 53 | H13: =G13-'Summary-Plant Heights'!F13 -> 16 | I13: 66 | J13: =I13-'Summary-Plant Heights'!G13 -> 10 | K13: 80 | L13: =K13-'Summary-Plant Heights'!H13 -> 11 | M13: 91 | N13: =M13-'Summary-Plant Heights'!I13 -> 11 | O13: 98 | P13: =O13-'Summary-Plant Heights'!J13 -> 9 | Q13: 97 | R13: =Q13-'Summary-Plant Heights'!K13 -> 13 | S13: 103 | T13: =S13-'Summary-Plant Heights'!L13 -> 11
D14: NT 5 | E14: 30 | F14: =E14-'Summary-Plant Heights'!E14 -> 18 | G14: 56 | H14: =G14-'Summary-Plant Heights'!F14 -> 17 | I14: 63 | J14: =I14-'Summary-Plant Heights'!G14 -> 13 | K14: 73 | L14: =K14-'Summary-Plant Heights'!H14 -> 13 | M14: 81 | N14: =M14-'Summary-Plant Heights'!I14 -> 12 | O14: 96 | P14: =O14-'Summary-Plant Heights'!J14 -> 12 | Q14: 105 | R14: =Q14-'Summary-Plant Heights'!K14 -> 11 | S14: 102 | T14: =S14-'Summary-Plant Heights'!L14 -> 14
B15: Span 2 | C15: Plot 3 | D15: NT 1 | E15: 30 | F15: =E15-'Summary-Plant Heights'!E15 -> 18 | G15: 49 | H15: =G15-'Summary-Plant Heights'!F15 -> 18 | I15: 64 | J15: =I15-'Summary-Plant Heights'!G15 -> 11 | K15: 82 | L15: =K15-'Summary-Plant Heights'!H15 -> 12 | M15: 93 | N15: =M15-'Summary-Plant Heights'!I15 -> 9 | O15: 102 | P15: =O15-'Summary-Plant Heights'!J15 -> 13 | Q15: 105 | R15: =Q15-'Summary-Plant Heights'!K15 -> 14 | S15: 113 | T15: =S15-'Summary-Plant Heights'!L15 -> 12
C16: CropMod | D16: NT 2 | E16: 31 | F16: =E16-'Summary-Plant Heights'!E16 -> 17 | G16: 52 | H16: =G16-'Summary-Plant Heights'!F16 -> 17 | I16: 67 | J16: =I16-'Summary-Plant Heights'!G16 -> 12 | K16: 90 | L16: =K16-'Summary-Plant Heights'!H16 -> 12 | M16: 100 | N16: =M16-'Summary-Plant Heights'!I16 -> 13 | O16: 110 | P16: =O16-'Summary-Plant Heights'!J16 -> 13 | Q16: 105 | R16: =Q16-'Summary-Plant Heights'!K16 -> 6 | S16: 114 | T16: =S16-'Summary-Plant Heights'!L16 -> 11
D17: NT 3 | E17: 29 | F17: =E17-'Summary-Plant Heights'!E17 -> 16 | G17: 50 | H17: =G17-'Summary-Plant Heights'!F17 -> 18 | I17: 62 | J17: =I17-'Summary-Plant Heights'!G17 -> 15 | K17: 79 | L17: =K17-'Summary-Plant Heights'!H17 -> 13 | M17: 92 | N17: =M17-'Summary-Plant Heights'!I17 -> 12 | O17: 101 | P17: =O17-'Summary-Plant Heights'!J17 -> 11 | Q17: 97 | R17: =Q17-'Summary-Plant Heights'!K17 -> 12 | S17: 107 | T17: =S17-'Summary-Plant Heights'!L17 -> 12
D18: NT 4 | E18: 29 | F18: =E18-'Summary-Plant Heights'!E18 -> 17 | G18: 49 | H18: =G18-'Summary-Plant Heights'!F18 -> 18 | I18: 60 | J18: =I18-'Summary-Plant Heights'!G18 -> 17 | K18: 79 | L18: =K18-'Summary-Plant Heights'!H18 -> 14 | M18: 92 | N18: =M18-'Summary-Plant Heights'!I18 -> 12 | O18: 106 | P18: =O18-'Summary-Plant Heights'!J18 -> 12 | Q18: 111 | R18: =Q18-'Summary-Plant Heights'!K18 -> 12 | S18: 106 | T18: =S18-'Summary-Plant Heights'!L18 -> 10
D19: NT 5 | E19: 31 | F19: =E19-'Summary-Plant Heights'!E19 -> 20 | G19: 50 | H19: =G19-'Summary-Plant Heights'!F19 -> 19 | I19: 63 | J19: =I19-'Summary-Plant Heights'!G19 -> 12 | K19: 81 | L19: =K19-'Summary-Plant Heights'!H19 -> 15 | M19: 91 | N19: =M19-'Summary-Plant Heights'!I19 -> 10 | O19: 101 | P19: =O19-'Summary-Plant Heights'!J19 -> 10 | Q19: 116 | R19: =Q19-'Summary-Plant Heights'!K19 -> 10 | S19: 120 | T19: =S19-'Summary-Plant Heights'!L19 -> 12
B20: Span 2 | C20: Plot 4 | D20: NT 1 | E20: 32 | F20: =E20-'Summary-Plant Heights'!E20 -> 22 | G20: 44 | H20: =G20-'Summary-Plant Heights'!F20 -> 14 | I20: 69 | J20: =I20-'Summary-Plant Heights'!G20 -> 13 | K20: 86 | L20: =K20-'Summary-Plant Heights'!H20 -> 13 | M20: 97 | N20: =M20-'Summary-Plant Heights'!I20 -> 11 | O20: 108 | P20: =O20-'Summary-Plant Heights'!J20 -> 11 | Q20: 107 | R20: =Q20-'Summary-Plant Heights'!K20 -> 11 | S20: 104 | T20: =S20-'Summary-Plant Heights'!L20 -> 8
C21: SEB | D21: NT 2 | E21: 29 | F21: =E21-'Summary-Plant Heights'!E21 -> 17 | G21: 43 | H21: =G21-'Summary-Plant Heights'!F21 -> 15 | I21: 65 | J21: =I21-'Summary-Plant Heights'!G21 -> 15 | K21: 85 | L21: =K21-'Summary-Plant Heights'!H21 -> 14 | M21: 96 | N21: =M21-'Summary-Plant Heights'!I21 -> 10 | O21: 109 | P21: =O21-'Summary-Plant Heights'!J21 -> 12 | Q21: 108 | R21: =Q21-'Summary-Plant Heights'!K21 -> 10 | S21: 106 | T21: =S21-'Summary-Plant Heights'!L21 -> 11
D22: NT 3 | E22: 31 | F22: =E22-'Summary-Plant Heights'!E22 -> 18 | G22: 53 | H22: =G22-'Summary-Plant Heights'!F22 -> 18 | I22: 68 | J22: =I22-'Summary-Plant Heights'!G22 -> 14 | K22: 82 | L22: =K22-'Summary-Plant Heights'!H22 -> 13 | M22: 100 | N22: =M22-'Summary-Plant Heights'!I22 -> 12 | O22: 111 | P22: =O22-'Summary-Plant Heights'!J22 -> 13 | Q22: 104 | R22: =Q22-'Summary-Plant Heights'!K22 -> 7 | S22: 103 | T22: =S22-'Summary-Plant Heights'!L22 -> 11
D23: NT 4 | E23: 31 | F23: =E23-'Summary-Plant Heights'!E23 -> 17 | G23: 48 | H23: =G23-'Summary-Plant Heights'!F23 -> 17 | I23: 64 | J23: =I23-'Summary-Plant Heights'!G23 -> 15 | K23: 75 | L23: =K23-'Summary-Plant Heights'!H23 -> 13 | M23: 89 | N23: =M23-'Summary-Plant Heights'!I23 -> 13 | O23: 102 | P23: =O23-'Summary-Plant Heights'!J23 -> 10 | Q23: 100 | R23: =Q23-'Summary-Plant Heights'!K23 -> 13 | S23: 108 | T23: =S23-'Summary-Plant Heights'!L23 -> 10
D24: NT 5 | E24: 32 | F24: =E24-'Summary-Plant Heights'!E24 -> 21 | G24: 43 | H24: =G24-'Summary-Plant Heights'!F24 -> 15 | I24: 61 | J24: =I24-'Summary-Plant Heights'!G24 -> 14 | K24: 76 | L24: =K24-'Summary-Plant Heights'!H24 -> 14 | M24: 91 | N24: =M24-'Summary-Plant Heights'!I24 -> 12 | O24: 104 | P24: =O24-'Summary-Plant Heights'!J24 -> 12 | Q24: 109 | R24: =Q24-'Summary-Plant Heights'!K24 -> 11 | S24: 107 | T24: =S24-'Summary-Plant Heights'!L24 -> 12
B25: Span 3 | C25: Plot 5 | D25: NT 1 | E25: 30 | F25: =E25-'Summary-Plant Heights'!E25 -> 19 | G25: 47 | H25: =G25-'Summary-Plant Heights'!F25 -> 19 | I25: 64 | J25: =I25-'Summary-Plant Heights'!G25 -> 17 | K25: 79 | L25: =K25-'Summary-Plant Heights'!H25 -> 15 | M25: 90 | N25: =M25-'Summary-Plant Heights'!I25 -> 10 | O25: 99 | P25: =O25-'Summary-Plant Heights'!J25 -> 11 | Q25: 102 | R25: =Q25-'Summary-Plant Heights'!K25 -> 17 | S25: 101 | T25: =S25-'Summary-Plant Heights'!L25 -> 11
C26: NDVI | D26: NT 2 | E26: 31 | F26: =E26-'Summary-Plant Heights'!E26 -> 18 | G26: 48 | H26: =G26-'Summary-Plant Heights'!F26 -> 18 | I26: 63 | J26: =I26-'Summary-Plant Heights'!G26 -> 15 | K26: 82 | L26: =K26-'Summary-Plant Heights'!H26 -> 13 | M26: 93 | N26: =M26-'Summary-Plant Heights'!I26 -> 13 | O26: 102 | P26: =O26-'Summary-Plant Heights'!J26 -> 12 | Q26: 102 | R26: =Q26-'Summary-Plant Heights'!K26 -> 11 | S26: 98 | T26: =S26-'Summary-Plant Heights'!L26 -> 12
D27: NT 3 | E27: 32 | F27: =E27-'Summary-Plant Heights'!E27 -> 19 | G27: 47 | H27: =G27-'Summary-Plant Heights'!F27 -> 16 | I27: 69 | J27: =I27-'Summary-Plant Heights'!G27 -> 16 | K27: 83 | L27: =K27-'Summary-Plant Heights'!H27 -> 12 | M27: 92 | N27: =M27-'Summary-Plant Heights'!I27 -> 9 | O27: 99 | P27: =O27-'Summary-Plant Heights'!J27 -> 13 | Q27: 98 | R27: =Q27-'Summary-Plant Heights'!K27 -> 12 | S27: 110 | T27: =S27-'Summary-Plant Heights'!L27 -> 10
D28: NT 4 | E28: 31 | F28: =E28-'Summary-Plant Heights'!E28 -> 19 | G28: 47 | H28: =G28-'Summary-Plant Heights'!F28 -> 18 | I28: 64 | J28: =I28-'Summary-Plant Heights'!G28 -> 12 | K28: 81 | L28: =K28-'Summary-Plant Heights'!H28 -> 14 | M28: 95 | N28: =M28-'Summary-Plant Heights'!I28 -> 14 | O28: 103 | P28: =O28-'Summary-Plant Heights'!J28 -> 9 | Q28: 109 | R28: =Q28-'Summary-Plant Heights'!K28 -> 14 | S28: 112 | T28: =S28-'Summary-Plant Heights'!L28 -> 14
D29: NT 5 | E29: 31 | F29: =E29-'Summary-Plant Heights'!E29 -> 18 | G29: 49 | H29: =G29-'Summary-Plant Heights'!F29 -> 19 | I29: 65 | J29: =I29-'Summary-Plant Heights'!G29 -> 17 | K29: 74 | L29: =K29-'Summary-Plant Heights'!H29 -> 15 | M29: 82 | N29: =M29-'Summary-Plant Heights'!I29 -> 7 | O29: 91 | P29: =O29-'Summary-Plant Heights'!J29 -> 11 | Q29: 95 | R29: =Q29-'Summary-Plant Heights'!K29 -> 14 | S29: 121 | T29: =S29-'Summary-Plant Heights'!L29 -> 13
B30: Span 3 | C30: Plot 6 | D30: NT 1 | E30: 30 | F30: =E30-'Summary-Plant Heights'!E30 -> 19 | G30: 47 | H30: =G30-'Summary-Plant Heights'!F30 -> 17 | I30: 69 | J30: =I30-'Summary-Plant Heights'!G30 -> 15 | K30: 91 | L30: =K30-'Summary-Plant Heights'!H30 -> 23 | M30: 102 | N30: =M30-'Summary-Plant Heights'!I30 -> 8 | O30: 111 | P30: =O30-'Summary-Plant Heights'!J30 -> 13 | Q30: 102 | R30: =Q30-'Summary-Plant Heights'!K30 -> 11 | S30: 108 | T30: =S30-'Summary-Plant Heights'!L30 -> 10
C31: Stress | D31: NT 2 | E31: 32 | F31: =E31-'Summary-Plant Heights'!E31 -> 19 | G31: 48 | H31: =G31-'Summary-Plant Heights'!F31 -> 16 | I31: 71 | J31: =I31-'Summary-Plant Heights'!G31 -> 16 | K31: 88 | L31: =K31-'Summary-Plant Heights'!H31 -> 15 | M31: 95 | N31: =M31-'Summary-Plant Heights'!I31 -> 11 | O31: 97 | P31: =O31-'Summary-Plant Heights'!J31 -> 11 | Q31: 97 | R31: =Q31-'Summary-Plant Heights'!K31 -> 11 | S31: 102 | T31: =S31-'Summary-Plant Heights'!L31 -> 10
D32: NT 3 | E32: 31 | F32: =E32-'Summary-Plant Heights'!E32 -> 19 | G32: 50 | H32: =G32-'Summary-Plant Heights'!F32 -> 15 | I32: 71 | J32: =I32-'Summary-Plant Heights'!G32 -> 14 | K32: 83 | L32: =K32-'Summary-Plant Heights'!H32 -> 14 | M32: 91 | N32: =M32-'Summary-Plant Heights'!I32 -> 9 | O32: 102 | P32: =O32-'Summary-Plant Heights'!J32 -> 13 | Q32: 98 | R32: =Q32-'Summary-Plant Heights'!K32 -> 12 | S32: 101 | T32: =S32-'Summary-Plant Heights'!L32 -> 13
D33: NT 4 | E33: 31 | F33: =E33-'Summary-Plant Heights'!E33 -> 18 | G33: 48 | H33: =G33-'Summary-Plant Heights'!F33 -> 12 | I33: 70 | J33: =I33-'Summary-Plant Heights'!G33 -> 19 | K33: 73 | L33: =K33-'Summary-Plant Heights'!H33 -> 14 | M33: 82 | N33: =M33-'Summary-Plant Heights'!I33 -> 10 | O33: 86 | P33: =O33-'Summary-Plant Heights'!J33 -> 10 | Q33: 89 | R33: =Q33-'Summary-Plant Heights'!K33 -> 11 | S33: 91 | T33: =S33-'Summary-Plant Heights'!L33 -> 12
D34: NT 5 | E34: 30 | F34: =E34-'Summary-Plant Heights'!E34 -> 18 | G34: 47 | H34: =G34-'Summary-Plant Heights'!F34 -> 15 | I34: 74 | J34: =I34-'Summary-Plant Heights'!G34 -> 17 | K34: 91 | L34: =K34-'Summary-Plant Heights'!H34 -> 16 | M34: 93 | N34: =M34-'Summary-Plant Heights'!I34 -> 10 | O34: 97 | P34: =O34-'Summary-Plant Heights'!J34 -> 13 | Q34: 92 | R34: =Q34-'Summary-Plant Heights'!K34 -> 12 | S34: 102 | T34: =S34-'Summary-Plant Heights'!L34 -> 12
B35: Span 4 | C35: Plot 7 | D35: NT 1 | E35: 31 | F35: =E35-'Summary-Plant Heights'!E35 -> 20 | G35: 44 | H35: =G35-'Summary-Plant Heights'!F35 -> 16 | I35: 65 | J35: =I35-'Summary-Plant Heights'!G35 -> 17 | K35: 79 | L35: =K35-'Summary-Plant Heights'!H35 -> 17 | M35: 86 | N35: =M35-'Summary-Plant Heights'!I35 -> 11 | O35: 93 | P35: =O35-'Summary-Plant Heights'!J35 -> 10 | Q35: 107 | R35: =Q35-'Summary-Plant Heights'!K35 -> 14 | S35: 113 | T35: =S35-'Summary-Plant Heights'!L35 -> 13
C36: CropMod | D36: NT 2 | E36: 33 | F36: =E36-'Summary-Plant Heights'!E36 -> 21 | G36: 53 | H36: =G36-'Summary-Plant Heights'!F36 -> 19 | I36: 67 | J36: =I36-'Summary-Plant Heights'!G36 -> 16 | K36: 91 | L36: =K36-'Summary-Plant Heights'!H36 -> 17 | M36: 102 | N36: =M36-'Summary-Plant Heights'!I36 -> 13 | O36: 111 | P36: =O36-'Summary-Plant Heights'!J36 -> 12 | Q36: 113 | R36: =Q36-'Summary-Plant Heights'!K36 -> 6 | S36: 125 | T36: =S36-'Summary-Plant Heights'!L36 -> 13
D37: NT 3 | E37: 32 | F37: =E37-'Summary-Plant Heights'!E37 -> 20 | G37: 50 | H37: =G37-'Summary-Plant Heights'!F37 -> 17 | I37: 64 | J37: =I37-'Summary-Plant Heights'!G37 -> 16 | K37: 80 | L37: =K37-'Summary-Plant Heights'!H37 -> 15 | M37: 88 | N37: =M37-'Summary-Plant Heights'!I37 -> 9 | O37: 101 | P37: =O37-'Summary-Plant Heights'!J37 -> 13 | Q37: 113 | R37: =Q37-'Summary-Plant Heights'!K37 -> 15 | S37: 107 | T37: =S37-'Summary-Plant Heights'!L37 -> 11
D38: NT 4 | E38: 30 | F38: =E38-'Summary-Plant Heights'!E38 -> 19 | G38: 44 | H38: =G38-'Summary-Plant Heights'!F38 -> 13 | I38: 68 | J38: =I38-'Summary-Plant Heights'!G38 -> 18 | K38: 88 | L38: =K38-'Summary-Plant Heights'!H38 -> 17 | M38: 100 | N38: =M38-'Summary-Plant Heights'!I38 -> 12 | O38: 111 | P38: =O38-'Summary-Plant Heights'!J38 -> 13 | Q38: 115 | R38: =Q38-'Summary-Plant Heights'!K38 -> 17 | S38: 113 | T38: =S38-'Summary-Plant Heights'!L38 -> 11
D39: NT 5 | E39: 32 | F39: =E39-'Summary-Plant Heights'!E39 -> 20 | G39: 45 | H39: =G39-'Summary-Plant Heights'!F39 -> 16 | I39: 56 | J39: =I39-'Summary-Plant Heights'!G39 -> 16 | K39: 59 | L39: =K39-'Summary-Plant Heights'!H39 -> 13 | M39: 68 | N39: =M39-'Summary-Plant Heights'!I39 -> 12 | O39: 90 | P39: =O39-'Summary-Plant Heights'!J39 -> 13 | Q39: 97 | R39: =Q39-'Summary-Plant Heights'!K39 -> 13 | S39: 106 | T39: =S39-'Summary-Plant Heights'!L39 -> 12
B40: Span 4 | C40: Plot 8 | D40: NT 1 | G40: 49 | H40: =G40-'Summary-Plant Heights'!F40 -> 16 | I40: 70 | J40: =I40-'Summary-Plant Heights'!G40 -> 18 | K40: 86 | L40: =K40-'Summary-Plant Heights'!H40 -> 15 | M40: 102 | N40: =M40-'Summary-Plant Heights'!I40 -> 12 | O40: 101 | P40: =O40-'Summary-Plant Heights'!J40 -> 12 | Q40: 112 | R40: =Q40-'Summary-Plant Heights'!K40 -> 10 | S40: 109 | T40: =S40-'Summary-Plant Heights'!L40 -> 10
C41: SEB | D41: NT 2 | G41: 51 | H41: =G41-'Summary-Plant Heights'!F41 -> 15 | I41: 76 | J41: =I41-'Summary-Plant Heights'!G41 -> 15 | K41: 96 | L41: =K41-'Summary-Plant Heights'!H41 -> 16 | M41: 119 | N41: =M41-'Summary-Plant Heights'!I41 -> 13 | O41: 134 | P41: =O41-'Summary-Plant Heights'!J41 -> 13 | Q41: 141 | R41: =Q41-'Summary-Plant Heights'!K41 -> 13 | S41: 128 | T41: =S41-'Summary-Plant Heights'!L41 -> 13
...

Sheet Summary-Cover
A1: 2015 | B1: F013 - lateral move irrigation
B2: Cotton | D2: Irrigation Scheduling experiment
O3: bolls heavy + winds-branches starting to hang low
B4: Summary of Canopy Cover - all treatments
C5: Widths in cm
K6: Blank = closed canopy
D7: Date: | E7: 42157 | F7: did not take this date | G7: 42170 | I7: 42184 | K7: 42198 | M7: 42212 | O7: 42227 | Q7: 42243 | S7: 42255
D8: doy: | E8: 153 | G8: 166 | I8: 180 | K8: 194 | M8: 208 | O8: 223 | Q8: 236 | S8: 251
E9: Canopy Cover | F9: Width between rows | G9: Canopy Cover | H9: Width between rows | I9: Canopy Cover | J9: Width between rows | K9: Canopy Cover | L9: Width between rows | M9: Canopy Cover | N9: Width between rows | O9: Canopy Cover | P9: Width between rows | Q9: Canopy Cover | R9: Width between rows | S9: Canopy Cover | T9: Width between rows | U9: Canopy Cover | V9: Width between rows | W9: Canopy Cover | X9: Width between rows | Y9: Canopy Cover | Z9: Width between rows
B10: Span 1 | C10: Plot 2 | D10: NT 1 | E10: 11 | G10: 30 | H10: 76 | I10: 49 | J10: 50 | K10: 63 | L10: 40 | M10: 82 | N10: 25 | O10: 102 | Q10: 89 | R10: 11 | S10: 102
C11: FAO | D11: NT 2 | E11: 11 | G11: 28 | H11: 71 | I11: 43 | J11: 53 | K11: 64 | L11: 33 | M11: 85 | N11: 17 | O11: 102 | Q11: 102 | S11: 102
D12: NT 3 | E12: 11 | G12: 23 | H12: 78 | I12: 45 | J12: 54 | K12: 58 | L12: 32 | M12: 72 | N12: 25 | O12: 93 | P12: 8 | Q12: 102 | S12: 102
D13: NT 4 | E13: 12 | G13: 34 | H13: 70 | I13: 49 | J13: 51 | K13: 62 | L13: 39 | M13: 77 | N13: 20 | O13: 96 | P13: 5 | Q13: 102 | S13: 102
D14: NT 5 | E14: 13 | G14: 28 | H14: 74 | I14: 45 | J14: 55 | K14: 48 | L14: 49 | M14: 70 | N14: 31 | O14: 79 | P14: 20 | Q14: 102 | S14: 102
B15: Span 2 | C15: Plot 3 | D15: NT 1 | E15: 11 | G15: 26 | H15: 72 | I15: 44 | J15: 53 | K15: 59 | L15: 38 | M15: 78 | N15: 23 | O15: 102 | Q15: 102 | S15: 102
C16: CropMod | D16: NT 2 | E16: 12 | G16: 32 | H16: 71 | I16: 44 | J16: 55 | K16: 72 | L16: 33 | M16: 82 | N16: 21 | O16: 102 | Q16: 102 | S16: 102
D17: NT 3 | E17: 12 | G17: 29 | H17: 70 | I17: 43 | J17: 56 | K17: 56 | L17: 52 | M17: 77 | N17: 12 | O17: 86 | P17: 18 | Q17: 96 | R17: 7 | S17: 102
D18: NT 4 | E18: 11 | G18: 25 | H18: 73 | I18: 42 | J18: 61 | K18: 57 | L18: 42 | M18: 80 | N18: 22 | O18: 102 | Q18: 102 | S18: 102
D19: NT 5 | E19: 11 | G19: 27 | H19: 76 | I19: 42 | J19: 56 | K19: 52 | L19: 47 | M19: 66 | N19: 38 | O19: 84 | P19: 18 | Q19: 102 | S19: 102
B20: Span 2 | C20: Plot 4 | D20: NT 1 | E20: 11 | G20: 25 | H20: 72 | I20: 49 | J20: 53 | K20: 65 | L20: 34 | M20: 82 | N20: 17 | O20: 102 | Q20: 102 | S20: 102
C21: SEB | D21: NT 2 | E21: 11 | G21: 25 | H21: 76 | I21: 51 | J21: 52 | K21: 66 | L21: 35 | M21: 81 | N21: 18 | O21: 102 | Q21: 102 | S21: 102
D22: NT 3 | E22: 13 | G22: 26 | H22: 73 | I22: 53 | J22: 47 | K22: 65 | L22: 33 | M22: 88 | N22: 16 | O22: 96 | P22: 5 | Q22: 102 | S22: 102
D23: NT 4 | E23: 13 | G23: 31 | H23: 72 | I23: 46 | J23: 55 | K23: 61 | L23: 41 | M23: 85 | N23: 16 | O23: 97 | P23: 5 | Q23: 102 | S23: 102
D24: NT 5 | E24: 10 | G24: 26 | H24: 76 | I24: 45 | J24: 56 | K24: 55 | L24: 47 | M24: 72 | N24: 27 | O24: 92 | P24: 10 | Q24: 102 | S24: 102
B25: Span 3 | C25: Plot 5 | D25: NT 1 | E25: 11 | G25: 25 | H25: 73 | I25: 44 | J25: 57 | K25: 59 | L25: 37 | M25: 73 | N25: 20 | O25: 102 | Q25: 102 | S25: 102
C26: NDVI | D26: NT 2 | E26: 12 | G26: 27 | H26: 73 | I26: 47 | J26: 50 | K26: 56 | L26: 38 | M26: 71 | N26: 27 | O26: 102 | Q26: 102 | S26: 102
D27: NT 3 | E27: 11 | G27: 26 | H27: 72 | I27: 46 | J27: 53 | K27: 53 | L27: 45 | M27: 75 | N27: 23 | O27: 92 | P27: 8 | Q27: 102 | S27: 102
D28: NT 4 | E28: 11 | G28: 27 | H28: 74 | I28: 43 | J28: 56 | K28: 55 | L28: 42 | M28: 65 | N28: 29 | O28: 91 | P28: 10 | Q28: 102 | S28: 102
D29: NT 5 | E29: 11 | G29: 25 | H29: 74 | I29: 46 | J29: 52 | K29: 51 | L29: 50 | M29: 67 | N29: 35 | O29: 85 | P29: 18 | Q29: 102 | S29: 102
B30: Span 3 | C30: Plot 6 | D30: NT 1 | E30: 11 | G30: 26 | H30: 75 | I30: 52 | J30: 51 | K30: 61 | L30: 32 | M30: 86 | N30: 17 | O30: 102 | Q30: 102 | S30: 102
C31: Stress | D31: NT 2 | E31: 12 | G31: 26 | H31: 78 | I31: 53 | J31: 50 | K31: 65 | L31: 29 | M31: 86 | N31: 17 | O31: 102 | Q31: 102 | S31: 102
D32: NT 3 | E32: 11 | G32: 26 | H32: 76 | I32: 46 | J32: 53 | K32: 46 | L32: 48 | M32: 70 | N32: 28 | O32: 102 | Q32: 102 | S32: 102
D33: NT 4 | E33: 12 | G33: 28 | H33: 70 | I33: 46 | J33: 52 | K33: 49 | L33: 48 | M33: 61 | N33: 38 | O33: 66 | P33: 35 | Q33: 68 | R33: 24 | S33: 102
D34: NT 5 | E34: 12 | G34: 29 | H34: 76 | I34: 54 | J34: 50 | K34: 57 | L34: 43 | M34: 82 | N34: 21 | O34: 91 | P34: 10 | Q34: 102 | S34: 102
B35: Span 4 | C35: Plot 7 | D35: NT 1 | E35: 12 | G35: 24 | H35: 75 | I35: 44 | J35: 55 | K35: 52 | L35: 50 | M35: 79 | N35: 23 | O35: 102 | Q35: 102 | S35: 102
C36: CropMod | D36: NT 2 | E36: 13 | G36: 26 | H36: 75 | I36: 51 | J36: 51 | K36: 73 | L36: 30 | M36: 95 | N36: 8 | O36: 102 | Q36: 102 | S36: 102
D37: NT 3 | E37: 12 | G37: 30 | H37: 73 | I37: 43 | J37: 58 | K37: 51 | L37: 48 | M37: 69 | N37: 31 | O37: 102 | Q37: 102 | S37: 102
D38: NT 4 | E38: 11 | G38: 23 | H38: 79 | I38: 48 | J38: 54 | K38: 65 | L38: 34 | M38: 82 | N38: 21 | O38: 95 | P38: 6 | Q38: 102 | S38: 102
D39: NT 5 | E39: 12 | G39: 22 | H39: 79 | I39: 38 | J39: 63 | K39: 43 | L39: 57 | M39: 56 | N39: 47 | O39: 74 | P39: 22 | Q39: 86 | R39: 13 | S39: 102
B40: Span 4 | C40: Plot 8 | D40: NT 1 | E40: 10 | G40: 30 | H40: 71 | I40: 53 | J40: 57 | K40: 62 | L40: 42 | M40: 78 | N40: 28 | O40: 102 | Q40: 102 | S40: 102
...

Sheet Blank
A1: 2015 | B1: F013 - lateral move irrigation
B2: Cotton | D2: Irrigation Scheduling experiment
A4: Canopy Heights - all treatments | F4: Date: | H4: time: | P4: ← N
C5: Measurements in cm | H5: initials:
C6: Taken to the North of the flags
C8: NT position 1 | G8: NT position 2 | K8: NT position 3 | O8: NT position 4 | S8: NT position 5
C9: from top of bed | D9: from bottom of furrow | E9: Width of canopy | F9: Between rows | G9: from top of bed | H9: from bottom of furrow | I9: Width of canopy | J9: Between rows | K9: from top of bed | L9: from bottom of furrow | M9: Width of canopy | N9: Between rows | O9: from top of bed | P9: from bottom of furrow | Q9: Width of canopy | R9: Between rows | S9: from top of bed | T9: from bottom of furrow | U9: Width of canopy | V9: Between rows
B10: Plot 2
B11: Plot 3
B12: Plot 4
B13: Plot 5
B14: Plot 6
B15: Plot 7
B16: Plot 8
B17: Plot 9
B18: Plot 10
B19: Plot 11

Sheet graphs
A1: 2015 | M1: 2014
A2: Date: | C2: 42157 | D2: 42170 | E2: 42184 | F2: 42198 | G2: 42212 | H2: 42227 | I2: 42243 | M2: Date: | O2: 3 & 4 June | P2: 41806 | Q2: 41820 | R2: 41834 | S2: 41848 | T2: 41863
A3: doy: | C3: 153 | D3: 166 | E3: 180 | F3: 194 | G3: 208 | H3: 223 | I3: 236 | M3: doy: | O3: 154 | P3: 167 | Q3: 181 | R3: 195 | S3: 209 | T3: 224
A4: plot 02 | B4: FAO | C4: =AVERAGE('Summary-Plant Heights'!E10:E14) -> 13.4 | D4: =AVERAGE('Summary-Plant Heights'!F10:F14) -> 33.6 | E4: =AVERAGE('Summary-Plant Heights'!G10:G14) -> 52.8 | F4: =AVERAGE('Summary-Plant Heights'!H10:H14) -> 67.8 | G4: =AVERAGE('Summary-Plant Heights'!I10:I14) -> 83.8 | H4: =AVERAGE('Summary-Plant Heights'!J10:J14) -> 92.2 | I4: =AVERAGE('Summary-Plant Heights'!K10:K14) -> 90.8 | M4: plot 01 | N4: Stress | O4: 18.333333 | P4: 37.5 | Q4: 50.666667 | R4: 67.333333 | S4: 66.666667 | T4: 71.333333
A5: plot 03 | B5: CropMod | C5: =AVERAGE('Summary-Plant Heights'!E15:E19) -> 12.4 | D5: =AVERAGE('Summary-Plant Heights'!F15:F19) -> 32 | E5: =AVERAGE('Summary-Plant Heights'!G15:G19) -> 49.8 | F5: =AVERAGE('Summary-Plant Heights'!H15:H19) -> 69 | G5: =AVERAGE('Summary-Plant Heights'!I15:I19) -> 82.4 | H5: =AVERAGE('Summary-Plant Heights'!J15:J19) -> 92.2 | I5: =AVERAGE('Summary-Plant Heights'!K15:K19) -> 96 | M5: plot 02 | N5: FAO | O5: 17 | P5: 34.5 | Q5: 63.833333 | R5: 90 | S5: 98.166667 | T5: 98.833333
A6: plot 04 | B6: SEB | C6: =AVERAGE('Summary-Plant Heights'!E20:E24) -> 12 | D6: =AVERAGE('Summary-Plant Heights'!F20:F24) -> 30.4 | E6: =AVERAGE('Summary-Plant Heights'!G20:G24) -> 51.2 | F6: =AVERAGE('Summary-Plant Heights'!H20:H24) -> 67.4 | G6: =AVERAGE('Summary-Plant Heights'!I20:I24) -> 83 | H6: =AVERAGE('Summary-Plant Heights'!J20:J24) -> 95.2 | I6: =AVERAGE('Summary-Plant Heights'!K20:K24) -> 95.2 | M6: plot 03 | N6: CropMod | O6: 19.5 | P6: 34.666667 | Q6: 59.833333 | R6: 91 | S6: 104 | T6: 105
A7: plot 05 | B7: NDVI | C7: =AVERAGE('Summary-Plant Heights'!E25:E29) -> 12.4 | D7: =AVERAGE('Summary-Plant Heights'!F25:F29) -> 29.6 | E7: =AVERAGE('Summary-Plant Heights'!G25:G29) -> 49.6 | F7: =AVERAGE('Summary-Plant Heights'!H25:H29) -> 66 | G7: =AVERAGE('Summary-Plant Heights'!I25:I29) -> 79.8 | H7: =AVERAGE('Summary-Plant Heights'!J25:J29) -> 87.6 | I7: =AVERAGE('Summary-Plant Heights'!K25:K29) -> 87.6 | M7: plot 04 | N7: SEB | O7: 20.166667 | P7: 37.833333 | Q7: 67.166667 | R7: 90.5 | S7: 98.166667 | T7: 101.66667
A8: plot 06 | B8: Stress | C8: =AVERAGE('Summary-Plant Heights'!E30:E34) -> 12.2 | D8: =AVERAGE('Summary-Plant Heights'!F30:F34) -> 33 | E8: =AVERAGE('Summary-Plant Heights'!G30:G34) -> 54.8 | F8: =AVERAGE('Summary-Plant Heights'!H30:H34) -> 68.8 | G8: =AVERAGE('Summary-Plant Heights'!I30:I34) -> 83 | H8: =AVERAGE('Summary-Plant Heights'!J30:J34) -> 86.6 | I8: =AVERAGE('Summary-Plant Heights'!K30:K34) -> 84.2 | M8: plot 05 | N8: NDVI | O8: 21.666667 | P8: 38.166667 | Q8: 68.333333 | R8: 97.166667 | S8: 102.16667 | T8: 108
A9: plot 07 | B9: CropMod | C9: =AVERAGE('Summary-Plant Heights'!E35:E39) -> 11.6 | D9: =AVERAGE('Summary-Plant Heights'!F35:F39) -> 31 | E9: =AVERAGE('Summary-Plant Heights'!G35:G39) -> 47.4 | F9: =AVERAGE('Summary-Plant Heights'!H35:H39) -> 63.6 | G9: =AVERAGE('Summary-Plant Heights'!I35:I39) -> 77.4 | H9: =AVERAGE('Summary-Plant Heights'!J35:J39) -> 89 | I9: =AVERAGE('Summary-Plant Heights'!K35:K39) -> 96 | M9: plot 06 | N9: Stress | O9: 19.666667 | P9: 33.666667 | Q9: 51.5 | R9: 68.333333 | S9: 70.5 | T9: 75.833333
A10: plot 08 | B10: SEB | C10: =AVERAGE('Summary-Plant Heights'!E40:E44) -> 11.2 | D10: =AVERAGE('Summary-Plant Heights'!F40:F44) -> 34.4 | E10: =AVERAGE('Summary-Plant Heights'!G40:G44) -> 54 | F10: =AVERAGE('Summary-Plant Heights'!H40:H44) -> 70 | G10: =AVERAGE('Summary-Plant Heights'!I40:I44) -> 87.2 | H10: =AVERAGE('Summary-Plant Heights'!J40:J44) -> 96.4 | I10: =AVERAGE('Summary-Plant Heights'!K40:K44) -> 104 | M10: plot 07 | N10: CropMod | O10: 20.666667 | P10: 31.666667 | Q10: 58.166667 | R10: 85.833333 | S10: 102.16667 | T10: 108.5
A11: plot 09 | B11: NDVI | C11: =AVERAGE('Summary-Plant Heights'!E45:E49) -> 11.6 | D11: =AVERAGE('Summary-Plant Heights'!F45:F49) -> 32.8 | E11: =AVERAGE('Summary-Plant Heights'!G45:G49) -> 50.8 | F11: =AVERAGE('Summary-Plant Heights'!H45:H49) -> 70.4 | G11: =AVERAGE('Summary-Plant Heights'!I45:I49) -> 83.8 | H11: =AVERAGE('Summary-Plant Heights'!J45:J49) -> 93.6 | I11: =AVERAGE('Summary-Plant Heights'!K45:K49) -> 95 | M11: plot 08 | N11: SEB | O11: 19.833333 | P11: 36.5 | Q11: 61 | R11: 87.666667 | S11: 92 | T11: 95.833333
A12: plot 10 | B12: FAO | C12: =AVERAGE('Summary-Plant Heights'!E50:E54) -> 12 | D12: =AVERAGE('Summary-Plant Heights'!F50:F54) -> 34.2 | E12: =AVERAGE('Summary-Plant Heights'!G50:G54) -> 54.6 | F12: =AVERAGE('Summary-Plant Heights'!H50:H54) -> 69.2 | G12: =AVERAGE('Summary-Plant Heights'!I50:I54) -> 83 | H12: =AVERAGE('Summary-Plant Heights'!J50:J54) -> 94 | I12: =AVERAGE('Summary-Plant Heights'!K50:K54) -> 99.6 | M12: plot 09 | N12: NDVI | O12: 20.666667 | P12: 35.333333 | Q12: 58.166667 | R12: 86.166667 | S12: 97.833333 | T12: 105
A13: plot 11 | B13: Stress | C13: =AVERAGE('Summary-Plant Heights'!E55:E59) -> 10.4 | D13: =AVERAGE('Summary-Plant Heights'!F55:F59) -> 29.6 | E13: =AVERAGE('Summary-Plant Heights'!G55:G59) -> 50.6 | F13: =AVERAGE('Summary-Plant Heights'!H55:H59) -> 66 | G13: =AVERAGE('Summary-Plant Heights'!I55:I59) -> 74.4 | H13: =AVERAGE('Summary-Plant Heights'!J55:J59) -> 76.4 | I13: =AVERAGE('Summary-Plant Heights'!K55:K59) -> 78 | M13: plot 10 | N13: FAO | O13: 22.166667 | P13: 37.333333 | Q13: 61.666667 | R13: 79.5 | S13: 84.166667 | T13: 91.666667
M14: plot 11 | N14: CroMod | O14: 19.5 | P14: 35 | Q14: 53 | R14: 76.166667 | S14: 89.333333 | T14: 94

Sheet Emergence
A1: 2015 | B1: F13 | C1: Cotton
B3: Emergence
B5: 42129 | C5: 42130 | D5: 42131 | E5: 42132 | F5: 42135 | G5: 42137 | H5: 42139 | I5: 42143 | J5: 42144
B6: d125 | C6: d126 | D6: d127 | E6: d128 | F6: d131 | G6: d133 | H6: 135 | I6: 139 | J6: 140
A7: plot | B7: 1500-1610 | C7: 1400-1415 | D7: 1510-1525 | E7: 1500-1515 | F7: 1100-1115 | G7: 1100-1115 | H7: 1000-1015 | I7: 0-1015 | J7: 0945-1000
A8: 2 | B8: 12 | C8: 13 | D8: 13 | E8: 13 | F8: 14 | G8: 14 | H8: 14 | I8: 14 | J8: 14
A9: 3 | B9: 3 | C9: 4 | D9: 4 | E9: 4 | F9: 5 | G9: 7 | H9: 7 | I9: 7 | J9: 7
A10: 4 | B10: 9 | C10: 9 | D10: 10 | E10: 10 | F10: 10 | G10: 10 | H10: 11 | I10: 11 | J10: 11
A11: 5 | B11: 1 | C11: 3 | D11: 6 | E11: 7 | F11: 8 | G11: 8 | H11: 8 | I11: 9 | J11: 9
A12: 6 | B12: 3 | C12: 6 | D12: 7 | E12: 7 | F12: 9 | G12: 9 | H12: 9 | I12: 10 | J12: 10
A13: 7 | B13: 5 | C13: 8 | D13: 8 | E13: 8 | F13: 10 | G13: 10 | H13: 10 | I13: 9 | J13: 9
A14: 8 | B14: 4 | C14: 6 | D14: 8 | E14: 9 | F14: 10 | G14: 11 | H14: 11 | I14: 12 | J14: 12
A15: 9 | B15: 4 | C15: 5 | D15: 6 | E15: 7 | F15: 8 | G15: 8 | H15: 9 | I15: 9 | J15: 9
A16: 10 | B16: 4 | C16: 7 | D16: 7 | E16: 7 | F16: 7 | G16: 7 | H16: 8 | I16: 8 | J16: 8
A17: 11 | B17: 6 | C17: 7 | D17: 8 | E17: 8 | F17: 9 | G17: 9 | H17: 9 | I17: 9 | J17: 9
B19: =AVERAGE(B8:B17) -> 5.1 | C19: =AVERAGE(C8:C17) -> 6.8 | D19: =AVERAGE(D8:D17) -> 7.7 | E19: =AVERAGE(E8:E17) -> 8 | F19: =AVERAGE(F8:F17) -> 9 | G19: =AVERAGE(G8:G17) -> 9.3 | H19: =AVERAGE(H8:H17) -> 9.6 | I19: =AVERAGE(I8:I17) -> 9.8 | J19: =AVERAGE(J8:J17) -> 9.8
J23: =J19/1.02 -> 9.6078431

Sheet 1stLeaf
A1: 2015 | B1: F13 | C1: Cotton
B3: First true leaf unfolded
B5: 42139 | C5: 42143 | D5: 42144
B6: 135 | C6: 139 | D6: 140
B7: 1000-1015 | C7: 0-1015 | D7: 0945-1000
A8: plot | B8: (#/total plants) | C8: (#/total plants) | D8: (#/total plants) | G8: 135 | I8: 139 | K8: 140
A9: 2 | B9: 4/14 | C9: 11/14 | D9: 13/14 | F9: 4 | G9: 14 | H9: 11 | I9: 14 | J9: 13 | K9: 14
A10: 3 | B10: 0/7 | C10: 3/7 | D10: 3/7 | F10: 0 | G10: 7 | H10: 3 | I10: 7 | J10: 3 | K10: 7
A11: 4 | B11: 1/11 | C11: 8/11 | D11: 10/11 | F11: 1 | G11: 11 | H11: 8 | I11: 11 | J11: 10 | K11: 11
A12: 5 | B12: 0/8 | C12: 5/9 | D12: 6/9 | F12: 0 | G12: 8 | H12: 5 | I12: 9 | J12: 6 | K12: 9
A13: 6 | B13: 1/9 | C13: 1/10 | D13: 2/10 | F13: 1 | G13: 9 | H13: 1 | I13: 10 | J13: 2 | K13: 10
A14: 7 | B14: 2/10 | C14: 6/9 | D14: 6/9 | F14: 2 | G14: 10 | H14: 6 | I14: 9 | J14: 6 | K14: 9
A15: 8 | B15: 1/11 | C15: 4/12 | D15: 6/12 | F15: 1 | G15: 11 | H15: 4 | I15: 12 | J15: 6 | K15: 12
A16: 9 | B16: 2/9 | C16: 5/9 | D16: 6/9 | F16: 2 | G16: 9 | H16: 5 | I16: 9 | J16: 6 | K16: 9
A17: 10 | B17: 0/8 | C17: 3/8 | D17: 5/8 | F17: 0 | G17: 8 | H17: 3 | I17: 8 | J17: 5 | K17: 8
A18: 11 | B18: 0/9 | C18: 5/9 | D18: 7/9 | F18: 0 | G18: 9 | H18: 5 | I18: 9 | J18: 7 | K18: 9
F19: =SUM(F9:F18) -> 11 | G19: =SUM(G9:G18) -> 96 | H19: =SUM(H9:H18) -> 51 | I19: =SUM(I9:I18) -> 98 | J19: =SUM(J9:J18) -> 64 | K19: =SUM(K9:K18) -> 98
G21: =F19/G19*100 -> 11.458333 | I21: =H19/I19*100 -> 52.040816 | K21: =J19/K19*100 -> 65.306122

Sheet Density at flags
A1: 2015 | B1: F013 - lateral move irrigation
B2: Cotton | D2: Irrigation Scheduling experiment
B4: Density of cotton plants at the marked locations
D7: Date: | E7: 42157
D8: doy: | E8: 153
E9: plants per meter (from flag to the North)
B10: Span 1 | C10: Plot 2 | D10: NT 1 | E10: 10 | G10: =E10/1.016 -> 9.8425197
C11: FAO | D11: NT 2 | E11: 10 | G11: =E11/1.016 -> 9.8425197
D12: NT 3 | E12: 10 | G12: =E12/1.016 -> 9.8425197
D13: NT 4 | E13: 13 | G13: =E13/1.016 -> 12.795276
D14: NT 5 | E14: 10 | G14: =E14/1.016 -> 9.8425197
B15: Span 2 | C15: Plot 3 | D15: NT 1 | E15: 13 | G15: =E15/1.016 -> 12.795276
C16: CropMod | D16: NT 2 | E16: 11 | G16: =E16/1.016 -> 10.826772
D17: NT 3 | E17: 11 | G17: =E17/1.016 -> 10.826772
D18: NT 4 | E18: 10 | G18: =E18/1.016 -> 9.8425197
D19: NT 5 | E19: 10 | G19: =E19/1.016 -> 9.8425197
B20: Span 2 | C20: Plot 4 | D20: NT 1 | E20: 7 | G20: =E20/1.016 -> 6.8897638
C21: SEB | D21: NT 2 | E21: 10 | G21: =E21/1.016 -> 9.8425197
D22: NT 3 | E22: 10 | G22: =E22/1.016 -> 9.8425197
D23: NT 4 | E23: 11 | G23: =E23/1.016 -> 10.826772
D24: NT 5 | E24: 12 | G24: =E24/1.016 -> 11.811024
B25: Span 3 | C25: Plot 5 | D25: NT 1 | E25: 8 | G25: =E25/1.016 -> 7.8740157
C26: NDVI | D26: NT 2 | E26: 12 | G26: =E26/1.016 -> 11.811024
D27: NT 3 | E27: 11 | G27: =E27/1.016 -> 10.826772
D28: NT 4 | E28: 12 | G28: =E28/1.016 -> 11.811024
D29: NT 5 | E29: 10 | G29: =E29/1.016 -> 9.8425197
B30: Span 3 | C30: Plot 6 | D30: NT 1 | E30: 10 | G30: =E30/1.016 -> 9.8425197
C31: Stress | D31: NT 2 | E31: 10 | G31: =E31/1.016 -> 9.8425197
D32: NT 3 | E32: 9 | G32: =E32/1.016 -> 8.8582677
D33: NT 4 | E33: 10 | G33: =E33/1.016 -> 9.8425197
D34: NT 5 | E34: 11 | G34: =E34/1.016 -> 10.826772
B35: Span 4 | C35: Plot 7 | D35: NT 1 | E35: 11 | G35: =E35/1.016 -> 10.826772
C36: CropMod | D36: NT 2 | E36: 12 | G36: =E36/1.016 -> 11.811024
D37: NT 3 | E37: 9 | G37: =E37/1.016 -> 8.8582677
D38: NT 4 | E38: 12 | G38: =E38/1.016 -> 11.811024
D39: NT 5 | E39: 13 | G39: =E39/1.016 -> 12.795276
B40: Span 4 | C40: Plot 8 | D40: NT 1 | E40: 7 | G40: =E40/1.016 -> 6.8897638
C41: SEB | D41: NT 2 | E41: 12 | G41: =E41/1.016 -> 11.811024
D42: NT 3 | E42: 9 | G42: =E42/1.016 -> 8.8582677
D43: NT 4 | E43: 8 | G43: =E43/1.016 -> 7.8740157
...

Sheet Density counts
A1: 2015 | B1: F013 - lateral move irrigation
B2: Cotton | D2: Irrigation Scheduling experiment
B4: Plant Density Counts - 1.5 meter - in line with neutron tubes
C5: Row 1 starts on the East side of each span, directly to the West side of the tire track. Row numbering contines through beds between the harvest and sampling halves of the treatment plots and through the buffer rows between the treatments.
G6: Plants per 1.5 meters
E7: Bed | F7: between NTs 1-2 | G7: NT 3 | H7: between NTs 4-5 | J7: Average per 1 meter
B8: Span 1 | C8: Trt 2 | D8: FAO | E8: 3 | F8: 15 | G8: 16 | H8: 18 | J8: ="Ave "&TEXT(C8,)&" "&"("&TEXT(D8,)&")=" -> Ave Trt 2 (FAO)= | K8: =AVERAGE(F8:H11)/1.5 -> 11.222222 | N8: Averaage ALL= | O8: =AVERAGE(F8:H47)/1.5 -> 10.166667
B9: 42151 | E9: 9 | F9: 16 | G9: 17 | H9: 18 | N9: per 1 meter
E10: 15 | F10: 17 | G10: 15 | H10: 17
E11: 21 | F11: 18 | G11: 17 | H11: 18
B12: Span 2 | C12: Trt 3 | D12: CropMod | E12: 3 | F12: 17 | G12: 16 | H12: 18 | J12: ="Ave "&TEXT(C12,)&" "&"("&TEXT(D12,)&")=" -> Ave Trt 3 (CropMod)= | K12: =AVERAGE(F12:H15)/1.5 -> 10.944444
B13: 42151 | E13: 9 | F13: 16 | G13: 19 | H13: 16
E14: 15 | F14: 15 | G14: 17 | H14: 17
E15: 21 | F15: 16 | G15: 15 | H15: 15
B16: Span 2 | C16: Trt 4 | D16: SEB | E16: 3 | F16: 19 | G16: 17 | H16: 12 | J16: ="Ave "&TEXT(C16,)&" "&"("&TEXT(D16,)&")=" -> Ave Trt 4 (SEB)= | K16: =AVERAGE(F16:H19)/1.5 -> 10.111111
B17: 42151 | E17: 9 | F17: 15 | G17: 15 | H17: 16
E18: 15 | F18: 15 | G18: 10 | H18: 10
E19: 21 | F19: 18 | G19: 19 | H19: 16
B20: Span 3 | C20: Trt 5 | D20: NDVI | E20: 3 | F20: 15 | G20: 16 | H20: 16 | J20: ="Ave "&TEXT(C20,)&" "&"("&TEXT(D20,)&")=" -> Ave Trt 5 (NDVI)= | K20: =AVERAGE(F20:H23)/1.5 -> 10.222222
B21: 42151 | E21: 9 | F21: 12 | G21: 12 | H21: 16
E22: 15 | F22: 15 | G22: 17 | H22: 18
E23: 21 | F23: 16 | G23: 15 | H23: 16
B24: Span 3 | C24: Trt 6 | D24: Stress | E24: 3 | F24: 15 | G24: 13 | H24: 13 | J24: ="Ave "&TEXT(C24,)&" "&"("&TEXT(D24,)&")=" -> Ave Trt 6 (Stress)= | K24: =AVERAGE(F24:H27)/1.5 -> 9.9444444
B25: 42151 | E25: 9 | F25: 17 | G25: 13 | H25: 17
E26: 15 | F26: 11 | G26: 19 | H26: 14
E27: 21 | F27: 17 | G27: 17 | H27: 13
B28: Span 4 | C28: Trt 7 | D28: CropMod | E28: 3 | F28: 13 | G28: 15 | H28: 17 | J28: ="Ave "&TEXT(C28,)&" "&"("&TEXT(D28,)&")=" -> Ave Trt 7 (CropMod)= | K28: =AVERAGE(F28:H31)/1.5 -> 10.277778
B29: 42150 | E29: 9 | F29: 19 | G29: 13 | H29: 19
E30: 15 | F30: 15 | G30: 15 | H30: 16
E31: 21 | F31: 10 | G31: 16 | H31: 17
B32: Span 4 | C32: Trt 8 | D32: SEB | E32: 3 | F32: 17 | G32: 17 | H32: 15 | J32: ="Ave "&TEXT(C32,)&" "&"("&TEXT(D32,)&")=" -> Ave Trt 8 (SEB)= | K32: =AVERAGE(F32:H35)/1.5 -> 10.777778
B33: 42150 | E33: 9 | F33: 13 | G33: 18 | H33: 17
E34: 15 | F34: 18 | G34: 16 | H34: 16
E35: 21 | F35: 14 | G35: 16 | H35: 17
B36: Span 5 | C36: Trt 9 | D36: NDVI | E36: 3 | F36: 10 | G36: 15 | H36: 16 | J36: ="Ave "&TEXT(C36,)&" "&"("&TEXT(D36,)&")=" -> Ave Trt 9 (NDVI)= | K36: =AVERAGE(F36:H39)/1.5 -> 9.6111111
B37: 42150 | E37: 9 | F37: 16 | G37: 14 | H37: 14
E38: 15 | F38: 16 | G38: 12 | H38: 15
E39: 21 | F39: 15 | G39: 15 | H39: 15
B40: Span 5 | C40: Trt 10 | D40: FAO | E40: 3 | F40: 13 | G40: 16 | H40: 16 | J40: ="Ave "&TEXT(C40,)&" "&"("&TEXT(D40,)&")=" -> Ave Trt 10 (FAO)= | K40: =AVERAGE(F40:H43)/1.5 -> 9.7777778
B41: 42150 | E41: 9 | F41: 14 | G41: 14 | H41: 16
...

Sheet Flowering
A1: 2015 | B1: F013 - lateral move irrigation
B2: Cotton | D2: Irrigation Scheduling experiment
B4: Flowering of cotton plants at the marked locations
D7: Date: | E7: 42157 | F7: 42177 | G7: 42179 | H7: 42184 | I7: 42186 | J7: 42191
D8: doy: | E8: 153 | F8: 173 | G8: 175 | H8: 180 | I8: 182 | J8: 187 | N8: 173 | O8: 175 | P8: 180 | Q8: 182 | R8: 187
E9: plants per meter (from flag to the North) | F9: # flowering plants (per 1 m) | G9: # flowering plants (per 1 m) | H9: # flowering plants (per 1 m) | I9: # flowering plants (per 1 m) | J9: # flowering plants (per 1 m) | K9: # flowering plants (per 1 m) | L9: # flowering plants (per 1 m) | T9: 0.5 | U9: 50% DOY
B10: Span 1 | C10: Plot 2 | D10: NT 1 | E10: 10 | F10: 0 | G10: 0 | H10: 5 | I10: 7 | J10: 9 | T10: =E10/2 -> 5 | U10: =G$8+(T10-G10)/(H10-G10)*(H$8-G$8) -> 180
C11: FAO | D11: NT 2 | E11: 10 | F11: 0 | G11: 0 | H11: 1 | I11: 4 | J11: 7 | T11: =E11/2 -> 5 | U11: =I$8+(T11-I11)/(J11-I11)*(J$8-I$8) -> 183.66667
D12: NT 3 | E12: 10 | F12: 0 | G12: 0 | H12: 4 | I12: 5 | J12: 9 | T12: =E12/2 -> 5 | U12: =H$8+(T12-H12)/(I12-H12)*(I$8-H$8) -> 182
D13: NT 4 | E13: 13 | F13: 0 | G13: 0 | H13: 5 | I13: -- | J13: 11 | T13: =E13/2 -> 6.5 | U13: =H$8+(T13-H13)/(J13-H13)*(J$8-H$8) -> 181.75
D14: NT 5 | E14: 10 | F14: 0 | G14: 0 | H14: 8 | I14: -- | J14: 10 | N14: =SUM(F10:F14)/SUM($E10:$E14)*100 -> 0 | O14: =SUM(G10:G14)/SUM($E10:$E14)*100 -> 0 | P14: =SUM(H10:H14)/SUM($E10:$E14)*100 -> 43.396226 | Q14: =SUM(I10:I14)/SUM($E10:$E14)*100 -> 30.188679 | R14: =SUM(J10:J14)/SUM($E10:$E14)*100 -> 86.792453 | T14: =E14/2 -> 5 | U14: =G$8+(T14-G14)/(H14-G14)*(H$8-G$8) -> 178.125
B15: Span 2 | C15: Plot 3 | D15: NT 1 | E15: 13 | F15: 0 | G15: 1 | H15: 7 | I15: 10 | J15: 13 | T15: =E15/2 -> 6.5 | U15: =G$8+(T15-G15)/(H15-G15)*(H$8-G$8) -> 179.58333
C16: CropMod | D16: NT 2 | E16: 11 | F16: 0 | G16: 0 | H16: 6 | I16: 9 | J16: 10 | T16: =E16/2 -> 5.5 | U16: =G$8+(T16-G16)/(H16-G16)*(H$8-G$8) -> 179.58333
D17: NT 3 | E17: 11 | F17: 0 | G17: 0 | H17: 3 | I17: 6 | J17: 8 | T17: =E17/2 -> 5.5 | U17: =H$8+(T17-H17)/(I17-H17)*(I$8-H$8) -> 181.66667
D18: NT 4 | E18: 10 | F18: 0 | G18: 0 | H18: 6 | I18: -- | J18: 8 | T18: =E18/2 -> 5 | U18: =G$8+(T18-G18)/(H18-G18)*(H$8-G$8) -> 179.16667
D19: NT 5 | E19: 10 | F19: 0 | G19: 0 | H19: 5 | I19: -- | J19: 10 | N19: =SUM(F15:F19)/SUM($E15:$E19)*100 -> 0 | O19: =SUM(G15:G19)/SUM($E15:$E19)*100 -> 1.8181818 | P19: =SUM(H15:H19)/SUM($E15:$E19)*100 -> 49.090909 | Q19: =SUM(I15:I19)/SUM($E15:$E19)*100 -> 45.454545 | R19: =SUM(J15:J19)/SUM($E15:$E19)*100 -> 89.090909 | T19: =E19/2 -> 5 | U19: =G$8+(T19-G19)/(H19-G19)*(H$8-G$8) -> 180
B20: Span 2 | C20: Plot 4 | D20: NT 1 | E20: 7 | F20: 0 | G20: 1 | H20: 3 | I20: 4 | J20: 6 | T20: =E20/2 -> 3.5 | U20: =H$8+(T20-H20)/(I20-H20)*(I$8-H$8) -> 181
C21: SEB | D21: NT 2 | E21: 10 | F21: 0 | G21: 0 | H21: 3 | I21: 5 | J21: 10 | T21: =E21/2 -> 5 | U21: =H$8+(T21-H21)/(I21-H21)*(I$8-H$8) -> 182
D22: NT 3 | E22: 10 | F22: 0 | G22: 0 | H22: 6 | I22: 7 | J22: 9 | T22: =E22/2 -> 5 | U22: =G$8+(T22-G22)/(H22-G22)*(H$8-G$8) -> 179.16667
D23: NT 4 | E23: 11 | F23: 0 | G23: 0 | H23: 4 | I23: -- | J23: 11 | T23: =E23/2 -> 5.5 | U23: =H$8+(T23-H23)/(J23-H23)*(J$8-H$8) -> 181.5
D24: NT 5 | E24: 12 | F24: 0 | G24: 0 | H24: 3 | I24: -- | J24: 10 | N24: =SUM(F20:F24)/SUM($E20:$E24)*100 -> 0 | O24: =SUM(G20:G24)/SUM($E20:$E24)*100 -> 2 | P24: =SUM(H20:H24)/SUM($E20:$E24)*100 -> 38 | Q24: =SUM(I20:I24)/SUM($E20:$E24)*100 -> 32 | R24: =SUM(J20:J24)/SUM($E20:$E24)*100 -> 92 | T24: =E24/2 -> 6 | U24: =H$8+(T24-H24)/(J24-H24)*(J$8-H$8) -> 183
B25: Span 3 | C25: Plot 5 | D25: NT 1 | E25: 8 | F25: 0 | G25: 0 | H25: 4 | I25: 5 | J25: 8 | T25: =E25/2 -> 4 | U25: =G$8+(T25-G25)/(H25-G25)*(H$8-G$8) -> 180
C26: NDVI | D26: NT 2 | E26: 12 | F26: 0 | G26: 0 | H26: 3 | I26: 7 | J26: 10 | T26: =E26/2 -> 6 | U26: =H$8+(T26-H26)/(I26-H26)*(I$8-H$8) -> 181.5
D27: NT 3 | E27: 11 | F27: 0 | G27: 0 | H27: 6 | I27: 8 | J27: 10 | T27: =E27/2 -> 5.5 | U27: =G$8+(T27-G27)/(H27-G27)*(H$8-G$8) -> 179.58333
D28: NT 4 | E28: 12 | F28: 0 | G28: 0 | H28: 6 | I28: -- | J28: 12 | T28: =E28/2 -> 6 | U28: =G$8+(T28-G28)/(H28-G28)*(H$8-G$8) -> 180
D29: NT 5 | E29: 10 | F29: 0 | G29: 0 | H29: 7 | I29: -- | J29: 10 | N29: =SUM(F25:F29)/SUM($E25:$E29)*100 -> 0 | O29: =SUM(G25:G29)/SUM($E25:$E29)*100 -> 0 | P29: =SUM(H25:H29)/SUM($E25:$E29)*100 -> 49.056604 | Q29: =SUM(I25:I29)/SUM($E25:$E29)*100 -> 37.735849 | R29: =SUM(J25:J29)/SUM($E25:$E29)*100 -> 94.339623 | T29: =E29/2 -> 5 | U29: =G$8+(T29-G29)/(H29-G29)*(H$8-G$8) -> 178.57143
B30: Span 3 | C30: Plot 6 | D30: NT 1 | E30: 10 | F30: 0 | G30: 0 | H30: 4 | I30: 5 | J30: 9 | T30: =E30/2 -> 5 | U30: =H$8+(T30-H30)/(I30-H30)*(I$8-H$8) -> 182
C31: Stress | D31: NT 2 | E31: 10 | F31: 0 | G31: 0 | H31: 3 | I31: 5 | J31: 9 | T31: =E31/2 -> 5 | U31: =H$8+(T31-H31)/(I31-H31)*(I$8-H$8) -> 182
D32: NT 3 | E32: 9 | F32: 0 | G32: 0 | H32: 4 | I32: 7 | J32: 8 | T32: =E32/2 -> 4.5 | U32: =H$8+(T32-H32)/(I32-H32)*(I$8-H$8) -> 180.33333
D33: NT 4 | E33: 10 | F33: 0 | G33: 0 | H33: 7 | I33: -- | J33: 10 | T33: =E33/2 -> 5 | U33: =G$8+(T33-G33)/(H33-G33)*(H$8-G$8) -> 178.57143
D34: NT 5 | E34: 11 | F34: 0 | G34: 0 | H34: 6 | I34: -- | J34: 10 | N34: =SUM(F30:F34)/SUM($E30:$E34)*100 -> 0 | O34: =SUM(G30:G34)/SUM($E30:$E34)*100 -> 0 | P34: =SUM(H30:H34)/SUM($E30:$E34)*100 -> 48 | Q34: =SUM(I30:I34)/SUM($E30:$E34)*100 -> 34 | R34: =SUM(J30:J34)/SUM($E30:$E34)*100 -> 92 | T34: =E34/2 -> 5.5 | U34: =G$8+(T34-G34)/(H34-G34)*(H$8-G$8) -> 179.58333
B35: Span 4 | C35: Plot 7 | D35: NT 1 | E35: 11 | F35: 0 | G35: 0 | H35: 6 | I35: 7 | J35: 9 | T35: =E35/2 -> 5.5 | U35: =G$8+(T35-G35)/(H35-G35)*(H$8-G$8) -> 179.58333
C36: CropMod | D36: NT 2 | E36: 12 | F36: 0 | G36: 0 | H36: 4 | I36: 7 | J36: 11 | T36: =E36/2 -> 6 | U36: =H$8+(T36-H36)/(I36-H36)*(I$8-H$8) -> 181.33333
D37: NT 3 | E37: 9 | F37: 0 | G37: 0 | H37: 4 | I37: -- | J37: 9 | T37: =E37/2 -> 4.5 | U37: =G$8+(T37-G37)/(H37-G37)*(H$8-G$8) -> 180.625
D38: NT 4 | E38: 12 | F38: 0 | G38: 0 | H38: 3 | I38: -- | J38: 10 | T38: =E38/2 -> 6 | U38: =H$8+(T38-H38)/(J38-H38)*(J$8-H$8) -> 183
D39: NT 5 | E39: 13 | F39: 0 | G39: 0 | H39: 7 | I39: -- | J39: 12 | N39: =SUM(F35:F39)/SUM($E35:$E39)*100 -> 0 | O39: =SUM(G35:G39)/SUM($E35:$E39)*100 -> 0 | P39: =SUM(H35:H39)/SUM($E35:$E39)*100 -> 42.105263 | Q39: =SUM(I35:I39)/SUM($E35:$E39)*100 -> 24.561404 | R39: =SUM(J35:J39)/SUM($E35:$E39)*100 -> 89.473684 | T39: =E39/2 -> 6.5 | U39: =G$8+(T39-G39)/(H39-G39)*(H$8-G$8) -> 179.64286
B40: Span 4 | C40: Plot 8 | D40: NT 1 | E40: 7 | F40: 0 | G40: -- | H40: 3 | I40: 3 | J40: 7 | T40: =E40/2 -> 3.5 | U40: =I$8+(T40-I40)/(J40-I40)*(J$8-I$8) -> 182.625
C41: SEB | D41: NT 2 | E41: 12 | F41: 0 | G41: -- | H41: 8 | I41: 8 | J41: 11 | T41: =E41/2 -> 6 | U41: =F$8+(T41-F41)/(H41-F41)*(H$8-F$8) -> 178.25
D42: NT 3 | E42: 9 | F42: 0 | G42: -- | H42: 3 | I42: -- | J42: 9 | T42: =E42/2 -> 4.5 | U42: =H$8+(T42-H42)/(J42-H42)*(J$8-H$8) -> 181.75
D43: NT 4 | E43: 8 | F43: 0 | G43: -- | H43: 3 | I43: -- | J43: 8 | T43: =E43/2 -> 4 | U43: =H$8+(T43-H43)/(J43-H43)*(J$8-H$8) -> 181.4
...

Sheet NAWF
A1: 2015 | B1: F013 - lateral move irrigation
B2: Cotton | D2: Irrigation Scheduling experiment
B4: Nodes Above White Flower
E5: Counted the number on nodes above the highest white flower in the 1st position on 2 plants near each flag
D6: Date: | E6: 42192 | G6: 42198 | I6: 42207 | K6: 42212 | M6: 42219 | O6: 42227 | Q6: 42240 | S6: 42255
D7: doy: | E7: 188 | G7: 194 | I7: 203 | K7: 208 | M7: 215 | O7: 223 | Q7: 236 | S7: 251
E8: NAWF | G8: NAWF | I8: NAWF | K8: NAWF | M8: NAWF | O8: NAWF | Q8: NAWF | S8: NAWF | V8: NAWF188 | W8: NAWF194 | X8: NAWF203 | Y8: NAWF208 | Z8: NAWF215 | AA8: NAWF223 | AB8: NAWF236 | AC8: NAWF251
B9: Span 1 | C9: Plot 2 | D9: NT 1 | E9: 7 | F9: 7 | G9: 7 | H9: 6 | I9: 4 | J9: 6 | K9: 5 | L9: 4 | M9: 4 | N9: 3 | O9: 3 | P9: 3 | Q9: 1 | R9: 2 | S9: 2 | T9: 3 | V9: =AVERAGE(E9:F9) -> 7 | W9: =AVERAGE(G9:H9) -> 6.5 | X9: =AVERAGE(I9:J9) -> 5 | Y9: =AVERAGE(K9:L9) -> 4.5 | Z9: =AVERAGE(M9:N9) -> 3.5 | AA9: =AVERAGE(O9:P9) -> 3 | AB9: =AVERAGE(Q9:R9) -> 1.5 | AC9: =AVERAGE(S9:T9) -> 2.5
C10: FAO | D10: NT 2 | E10: 7 | F10: 6 | G10: 6 | H10: 7 | I10: 5 | J10: 6 | K10: 4 | L10: 6 | M10: 3 | N10: 4 | O10: 4 | P10: 3 | Q10: 2 | R10: 1 | S10: 4 | T10: 3 | V10: =AVERAGE(E10:F10) -> 6.5 | W10: =AVERAGE(G10:H10) -> 6.5 | X10: =AVERAGE(I10:J10) -> 5.5 | Y10: =AVERAGE(K10:L10) -> 5 | Z10: =AVERAGE(M10:N10) -> 3.5 | AA10: =AVERAGE(O10:P10) -> 3.5 | AB10: =AVERAGE(Q10:R10) -> 1.5 | AC10: =AVERAGE(S10:T10) -> 3.5
D11: NT 3 | E11: 7 | F11: 6 | G11: 6 | H11: 7 | I11: 4 | J11: 5 | K11: 5 | L11: 5 | M11: 3 | N11: 3 | O11: 3 | P11: 4 | Q11: 1 | R11: 2 | S11: 3 | T11: 3 | V11: =AVERAGE(E11:F11) -> 6.5 | W11: =AVERAGE(G11:H11) -> 6.5 | X11: =AVERAGE(I11:J11) -> 4.5 | Y11: =AVERAGE(K11:L11) -> 5 | Z11: =AVERAGE(M11:N11) -> 3 | AA11: =AVERAGE(O11:P11) -> 3.5 | AB11: =AVERAGE(Q11:R11) -> 1.5 | AC11: =AVERAGE(S11:T11) -> 3
D12: NT 4 | E12: 6 | G12: 5 | H12: 6 | K12: 4 | L12: 5 | M12: 4 | N12: 3 | O12: 4 | P12: 4 | Q12: 2 | R12: 1 | S12: 2 | T12: 1 | V12: =AVERAGE(E12:F12) -> 6 | W12: =AVERAGE(G12:H12) -> 5.5 | Y12: =AVERAGE(K12:L12) -> 4.5 | Z12: =AVERAGE(M12:N12) -> 3.5 | AA12: =AVERAGE(O12:P12) -> 4 | AB12: =AVERAGE(Q12:R12) -> 1.5 | AC12: =AVERAGE(S12:T12) -> 1.5
D13: NT 5 | G13: 5 | H13: 5 | K13: 4 | L13: 3 | M13: 4 | N13: 4 | O13: 4 | P13: 5 | Q13: 3 | R13: 2 | S13: 2 | T13: 1 | W13: =AVERAGE(G13:H13) -> 5 | Y13: =AVERAGE(K13:L13) -> 3.5 | Z13: =AVERAGE(M13:N13) -> 4 | AA13: =AVERAGE(O13:P13) -> 4.5 | AB13: =AVERAGE(Q13:R13) -> 2.5 | AC13: =AVERAGE(S13:T13) -> 1.5
B14: Span 2 | C14: Plot 3 | D14: NT 1 | E14: 6 | F14: 7 | G14: 6 | H14: 7 | I14: 5 | J14: 5 | K14: 6 | L14: 6 | M14: 5 | N14: 5 | O14: 5 | P14: 4 | Q14: 2 | R14: 4 | S14: 3 | T14: 2 | V14: =AVERAGE(E14:F14) -> 6.5 | W14: =AVERAGE(G14:H14) -> 6.5 | X14: =AVERAGE(I14:J14) -> 5 | Y14: =AVERAGE(K14:L14) -> 6 | Z14: =AVERAGE(M14:N14) -> 5 | AA14: =AVERAGE(O14:P14) -> 4.5 | AB14: =AVERAGE(Q14:R14) -> 3 | AC14: =AVERAGE(S14:T14) -> 2.5
