Workbook
Name trt.: SPADDOY192!$U$9
Name trt.: SPADDOY197!$U$9
Name trt.: SPADDOY206!$U$9
Name trt.: SPADDOY224!$U$9
Name trt.: SPADDOY227!$U$9
Name trt.: SPADDOY242!$U$9
Name trt.: SPADDOY249!$U$9
Name trt.: SPADDOY256!$U$9
Name trt.: SPADDOY266!$U$9
Name trt.: SPADDOY186!$U$9

Sheet Height
A1: CCID | B1: DOY163 | C1: DOY170 | D1: DOY176 | E1: DOY183 | F1: DOY190 | G1: DOY199 | H1: DOY204 | I1: DOY212 | J1: DOY218 | K1: DOY225 | L1: DOY232 | M1: DOY239 | N1: DOY246 | O1: DOY260
A2: p101-1 | B2: 31.5 | C2: 36.5 | D2: 48 | E2: 54 | F2: 69 | G2: 80 | H2: 88 | I2: 100 | J2: 107 | K2: 102 | L2: 110 | M2: 110 | N2: 110 | O2: 109
A3: p101-2 | B3: 33 | C3: 40.5 | D3: 55 | E3: 60 | F3: 75 | G3: 81 | H3: 93 | I3: 93 | J3: 93 | K3: 101 | L3: 96 | M3: 98 | N3: 98 | O3: 93
A4: p101-3 | B4: 35 | C4: 47 | D4: 56 | E4: 61 | F4: 78 | G4: 90 | H4: 96 | I4: 84 | J4: 98 | K4: 103 | L4: 98 | M4: 100 | N4: 103 | O4: 103
A5: p101-4 | B5: 34 | C5: 47 | D5: 53.5 | E5: 53 | F5: 76 | G5: 86 | H5: 92 | I5: 97 | J5: 99 | K5: 114 | L5: 103 | M5: 109 | N5: 119 | O5: 118
A6: p101-5 | B6: 36.5 | C6: 48 | D6: 56 | E6: 59 | F6: 81 | G6: 86 | H6: 88 | I6: 86 | J6: 110 | K6: 113 | L6: 86 | M6: 112 | N6: 115 | O6: 110
A7: p101-6 | B7: 28.5 | C7: 37 | D7: 48 | E7: 56 | F7: 66 | G7: 79 | H7: 84 | I7: 92 | J7: 123 | K7: 98 | L7: 104 | M7: 115 | N7: 129 | O7: 121
A8: p102-1 | B8: 34 | C8: 38.5 | D8: 51 | E8: 55 | F8: 66 | G8: 77 | H8: 83 | I8: 91 | J8: 96 | K8: 100 | L8: 100 | M8: 103 | N8: 100 | O8: 96
A9: p102-2 | B9: 38 | C9: 46 | D9: 57.5 | E9: 60 | F9: 80 | G9: 91 | H9: 97 | I9: 97 | J9: 96 | K9: 103 | L9: 112 | M9: 116 | N9: 118 | O9: 126
A10: p102-3 | B10: 32.5 | C10: 33 | D10: 40 | E10: 60 | F10: 66 | G10: 79 | H10: 93 | I10: 93 | J10: 108 | K10: 104 | L10: 121 | M10: 116 | N10: 125 | O10: 125
A11: p102-4 | B11: 25.5 | C11: 35 | D11: 55 | E11: 55 | F11: 71 | G11: 85 | H11: 94 | I11: 102 | J11: 101 | K11: 109 | L11: 102 | M11: 110 | N11: 108 | O11: 105
A12: p102-5 | B12: 28.5 | C12: 36 | D12: 48.5 | E12: 56 | F12: 69 | G12: 87 | H12: 84 | I12: 90 | J12: 103 | K12: 88 | L12: 103 | M12: 106 | N12: 105 | O12: 106
A13: p102-6 | B13: 24 | C13: 43 | D13: 48 | E13: 58 | F13: 76 | G13: 86 | H13: 92 | I13: 104 | J13: 100 | K13: 106 | L13: 104 | M13: 103 | N13: 102 | O13: 99
... A192: p408-5 | B192: 33 | C192: 36 | D192: 45.5 | E192: 52 | F192: 60 | G192: 66 | H192: 62 | I192: 67 | J192: 62 | K192: 70 | L192: 77 | M192: 86 | N192: 87 | O192: 89
A193: p408-6 | B193: 23 | C193: 34.5 | D193: 53 | E193: 47 | G193: 70 | H193: 71 | I193: 92 | J193: 87 | K193: 82 | L193: 94 | M193: 91 | N193: 91 | O193: 83
A194: p902-1 | B194: 30.5 | C194: 39 | D194: 53.5 | E194: 61 | F194: 68 | G194: 68 | H194: 87 | I194: 85 | J194: 86 | K194: 91 | L194: 91 | M194: 91 | N194: 87 | O194: 105
A195: p902-2 | B195: 31.5 | C195: 41 | D195: 51 | E195: 59 | F195: 71 | G195: 67 | H195: 74 | I195: 81 | J195: 83 | K195: 83 | L195: 81 | M195: 80 | N195: 81 | O195: 82
A196: p902-3 | B196: 30 | C196: 38.5 | D196: 50.5 | E196: 57 | F196: 84 | G196: 63 | H196: 83 | I196: 87 | J196: 98 | K196: 97 | L196: 93 | M196: 94 | N196: 96 | O196: 97
A197: p902-4 | B197: 29 | C197: 48.5 | D197: 48 | E197: 56 | F197: 68 | G197: 73 | H197: 99 | I197: 103 | J197: 103 | K197: 103 | L197: 102 | M197: 106 | N197: 103 | O197: 99
A198: p902-5 | B198: 34.5 | C198: 48 | D198: 50.5 | E198: 52 | F198: 66 | G198: 77 | H198: 89 | I198: 94 | J198: 94 | K198: 96 | L198: 95 | M198: 97 | N198: 99 | O198: 98
A199: p902-6 | B199: 32 | C199: 44 | D199: 47.5 | E199: 51 | F199: 68 | G199: 80 | H199: 88 | I199: 101 | J199: 104 | K199: 107 | L199: 106 | M199: 107 | N199: 107 | O199: 104
A200: p904-1 | B200: 26 | C200: 37 | D200: 38.5 | E200: 50 | F200: 49 | G200: 54 | H200: 56 | I200: 60 | J200: 61 | K200: 61 | L200: 58 | M200: 63 | N200: 61 | O200: 46
A201: p904-2 | B201: 39 | C201: 51 | D201: 49 | E201: 44 | F201: 43 | G201: 61 | H201: 60 | I201: 43 | J201: 60 | K201: 48 | L201: 58 | M201: 47 | N201: 60 | O201: 61
A202: p904-3 | B202: 28 | C202: 48 | D202: 42.5 | E202: 45 | F202: 44 | G202: 58 | H202: 50 | I202: 58 | J202: 55 | K202: 55 | L202: 57 | M202: 57 | N202: 57 | O202: 58
A203: p904-4 | B203: 31 | C203: 41 | D203: 42 | E203: 54 | F203: 52 | G203: 39 | H203: 41 | I203: 42 | J203: 42 | K203: 44 | L203: 43 | M203: 50 | N203: 48 | O203: 68
A204: p904-5 | B204: 28.5 | C204: 40 | D204: 48.5 | E204: 51 | F204: 59 | G204: 47 | H204: 48 | I204: 50 | J204: 43 | K204: 40 | L204: 47 | M204: 50 | N204: 48 | O204: 65
A205: p904-6 | B205: 32 | C205: 45.5 | D205: 47 | E205: 49 | F205: 46 | G205: 46 | H205: 51 | I205: 46 | J205: 50 | K205: 50 | L205: 50 | M205: 53 | N205: 41 | O205: 55
... A217: p908-6 | B217: 30 | C217: 41.5 | D217: 45.5 | E217: 49 | F217: 48 | G217: 46 | H217: 48 | I217: 52 | J217: 46 | K217: 53 | L217: 50 | M217: 48 | N217: 51 | O217: 46

Sheet Width
A1: CCID | B1: DOY163 | C1: DOY170 | D1: DOY176 | E1: DOY183 | F1: DOY190 | G1: DOY199 | H1: DOY204 | I1: DOY212 | J1: DOY218 | K1: DOY225 | L1: DOY232 | M1: DOY239 | N1: DOY246 | O1: DOY260
A2: p101-1 | B2: 34.5 | C2: 40.5 | D2: 50.5 | E2: 38 | F2: 70 | G2: 83 | H2: 86 | I2: 82 | J2: 88 | K2: 107 | L2: 92 | M2: 105 | N2: 100 | O2: 100
A3: p101-2 | B3: 32.5 | C3: 44 | D3: 56 | E3: 60 | F3: 82 | G3: 84 | H3: 91 | I3: 91 | J3: 100 | K3: 105 | L3: 85 | M3: 105 | N3: 100 | O3: 100
A4: p101-3 | B4: 36 | C4: 43.5 | D4: 60.5 | E4: 54 | F4: 70 | G4: 80 | H4: 82 | I4: 88 | J4: 93 | K4: 103 | L4: 105 | M4: 100 | N4: 100 | O4: 100
A5: p101-4 | B5: 32 | C5: 45 | D5: 50 | E5: 63 | F5: 77 | G5: 80 | H5: 80 | I5: 83 | J5: 103 | K5: 105 | L5: 95 | M5: 100 | N5: 100 | O5: 100
A6: p101-5 | B6: 36 | C6: 48.5 | D6: 60 | E6: 60 | F6: 75 | G6: 80 | H6: 97 | I6: 88 | J6: 100 | K6: 103 | L6: 93 | M6: 105 | N6: 100 | O6: 100
A7: p101-6 | B7: 29 | C7: 34 | D7: 39 | E7: 52 | F7: 63 | G7: 70 | H7: 85 | I7: 86 | J7: 89 | K7: 97 | L7: 88 | M7: 105 | N7: 100 | O7: 100
A8: p102-1 | B8: 38 | C8: 36 | D8: 40 | E8: 44 | F8: 72 | G8: 79 | H8: 95 | I8: 94 | J8: 100 | K8: 100 | L8: 104 | M8: 92 | N8: 100 | O8: 100
A9: p102-2 | B9: 41.5 | C9: 41 | D9: 49 | E9: 45 | F9: 68 | G9: 76 | H9: 83 | I9: 76 | J9: 83 | K9: 96 | L9: 83 | M9: 91 | N9: 100 | O9: 92
A10: p102-3 | B10: 27.5 | C10: 41 | D10: 53 | E10: 50 | F10: 66 | G10: 70 | H10: 71 | I10: 73 | J10: 78 | K10: 95 | L10: 87 | M10: 93 | N10: 100 | O10: 79
A11: p102-4 | B11: 22 | C11: 34 | D11: 53.5 | E11: 42 | F11: 73 | G11: 74 | H11: 86 | I11: 90 | J11: 85 | K11: 108 | L11: 98 | M11: 100 | N11: 100 | O11: 101
A12: p102-5 | B12: 28 | C12: 35 | D12: 44.5 | E12: 48 | F12: 66 | G12: 74 | H12: 72 | I12: 83 | J12: 83 | K12: 88 | L12: 79 | M12: 81 | N12: 100 | O12: 84
A13: p102-6 | B13: 30 | C13: 47 | D13: 58 | E13: 43 | F13: 74 | G13: 86 | H13: 87 | I13: 75 | J13: 93 | K13: 93 | L13: 88 | M13: 100 | N13: 100 | O13: 99
... A38: p107-1 | B38: 35 | C38: 38.5 | D38: 49.5 | E38: 42 | F38: 72 | G38: 80 | H38: 86 | I38: 79 | J38: 85 | K38: 91 | L38: 94 | M38: 105 | N38: 100 | O38: 94
A39: p107-2 | B39: 31.5 | C39: 36 | D39: 54 | E39: 44 | F39: 81 | G39: 85 | H39: 88 | I39: 90 | J39: 93 | K39: 104 | L39: 101 | M39: 105 | N39: 100
A40: p107-3 | B40: 29 | C40: 32 | D40: 49.5 | E40: 53 | F40: 73 | G40: 80 | H40: 82 | I40: 93 | J40: 89 | K40: 90 | L40: 95 | M40: 101 | N40: 100
A41: p107-4 | B41: 30.5 | C41: 40 | D41: 50 | E41: 44 | F41: 79 | G41: 78 | H41: 94 | I41: 98 | J41: 105 | K41: 103 | L41: 104 | M41: 102 | N41: 100
A42: p107-5 | B42: 36 | C42: 31 | D42: 49 | E42: 57 | F42: 72 | G42: 78 | H42: 87 | I42: 99 | J42: 95 | K42: 103 | L42: 94 | M42: 105 | N42: 100
A43: p107-6 | B43: 33 | C43: 33.5 | D43: 51.5 | E43: 42 | F43: 62 | G43: 69 | H43: 74 | I43: 78 | J43: 84 | K43: 90 | L43: 85 | M43: 86 | N43: 100
A44: p108-1 | B44: 42.5 | C44: 45 | D44: 59 | E44: 47 | F44: 76 | G44: 83 | H44: 84 | I44: 84 | J44: 90 | K44: 99 | L44: 105 | M44: 105 | N44: 100 | O44: 100
A45: p108-2 | B45: 34 | C45: 33 | D45: 48 | E45: 57 | F45: 69 | G45: 73 | H45: 73 | I45: 85 | J45: 87 | K45: 98 | L45: 105 | M45: 100 | N45: 100
A46: p108-3 | B46: 32 | C46: 34 | D46: 47 | E46: 62 | F46: 73 | G46: 84 | H46: 87 | I46: 92 | J46: 92 | K46: 110 | L46: 95 | M46: 100 | N46: 100
A47: p108-4 | B47: 36 | C47: 40 | D47: 56 | E47: 56 | F47: 72 | G47: 79 | H47: 93 | I47: 94 | J47: 102 | K47: 110 | L47: 105 | M47: 105 | N47: 100
A48: p108-5 | B48: 37.5 | C48: 43 | D48: 58 | E48: 50 | F48: 71 | G48: 79 | H48: 78 | I48: 87 | J48: 92 | K48: 98 | L48: 94 | M48: 105 | N48: 100
A49: p108-6 | B49: 33.5 | C49: 40 | D49: 54 | E49: 57 | F49: 68 | G49: 74 | H49: 78 | I49: 85 | J49: 92 | K49: 95 | L49: 105 | M49: 105 | N49: 100
A50: p201-1 | B50: 44 | C50: 58 | D50: 62 | E50: 62 | F50: 87 | G50: 89 | H50: 90 | I50: 88 | J50: 92 | K50: 106 | L50: 100 | M50: 97 | N50: 100 | O50: 82
A51: p201-2 | B51: 54 | C51: 61.5 | D51: 71.5 | E51: 68 | F51: 84 | G51: 88 | H51: 83 | I51: 92 | J51: 98 | K51: 88 | L51: 99 | M51: 99 | N51: 100
A52: p201-3 | B52: 53 | C52: 62 | D52: 66 | E52: 65 | F52: 86 | G52: 88 | H52: 91 | I52: 93 | J52: 99 | K52: 104 | L52: 100 | M52: 107 | N52: 100
A53: p201-4 | B53: 48.5 | C53: 60 | D53: 61 | E53: 61 | F53: 74 | G53: 82 | H53: 83 | I53: 88 | J53: 83 | K53: 91 | L53: 88 | M53: 92 | N53: 100
A54: p201-5 | B54: 56.5 | C54: 67 | D54: 65 | E54: 64 | F54: 80 | G54: 89 | H54: 92 | I54: 98 | J54: 88 | K54: 99 | L54: 100 | M54: 99 | N54: 100
A55: p201-6 | B55: 52 | C55: 53 | D55: 63 | E55: 63 | F55: 76 | G55: 79 | H55: 83 | I55: 87 | J55: 92 | K55: 83 | L55: 100 | M55: 98 | N55: 100
A56: p202-1 | B56: 44 | C56: 55 | D56: 46.5 | E56: 46 | F56: 61 | G56: 70 | H56: 75 | I56: 79 | J56: 94 | K56: 92 | L56: 96 | M56: 101 | N56: 107 | O56: 100
A57: p202-2 | B57: 42.5 | C57: 45 | D57: 48 | E57: 42 | F57: 63 | G57: 68 | H57: 72 | I57: 90 | J57: 93 | K57: 99 | L57: 92 | M57: 91 | N57: 92
A58: p202-3 | B58: 27.5 | C58: 28 | D58: 52 | E58: 35 | F58: 51 | G58: 69 | H58: 73 | I58: 83 | J58: 94 | K58: 94 | L58: 95 | M58: 93 | N58: 100
A59: p202-4 | B59: 30.5 | C59: 26.5 | D59: 34 | E59: 63 | F59: 53 | G59: 62 | H59: 80 | I59: 77 | J59: 87 | K59: 83 | L59: 98 | M59: 86 | N59: 100
A60: p202-5 | B60: 37 | C60: 40 | D60: 46 | E60: 38 | F60: 64 | G60: 75 | H60: 74 | I60: 87 | J60: 82 | K60: 92 | L60: 87 | M60: 91 | N60: 98
A61: p202-6 | B61: 35 | C61: 42 | D61: 43 | E61: 39 | F61: 55 | G61: 70 | H61: 85 | I61: 76 | J61: 83 | K61: 83 | L61: 86 | M61: 100 | N61: 100
A62: p203-1 | B62: 40.5 | C62: 52 | D62: 56 | E62: 55 | F62: 73 | G62: 87 | H62: 90 | I62: 90 | J62: 95 | K62: 102 | L62: 100 | M62: 105 | N62: 100 | O62: 100
A63: p203-2 | B63: 31 | C63: 46 | D63: 53.5 | E63: 53 | F63: 73 | G63: 72 | H63: 82 | I63: 86 | J63: 95 | K63: 99 | L63: 100 | M63: 105 | N63: 100
A64: p203-3 | B64: 42 | C64: 45 | D64: 55 | E64: 56 | F64: 75 | G64: 91 | H64: 93 | I64: 88 | J64: 96 | K64: 93 | L64: 100 | M64: 101 | N64: 100
...

Sheet SPAD
A1: CCID | B1: DOY186 | C1: DOY192 | D1: DOY197 | E1: DOY206 | F1: DOY224 | G1: DOY227 | H1: DOY242 | I1: DOY249 | J1: DOY256 | K1: DOY266
A2: p101-3 | B2: 44.1 | C2: 40.4 | D2: 41 | E2: 40 | F2: 43.2 | G2: 45.2 | H2: 42.9 | I2: 44.2 | J2: 46.9 | K2: 44.8
A3: p102-3 | B3: 41.6 | C3: 38.3 | D3: 38.5 | E3: 37.4 | F3: 40.7 | G3: 40.5 | H3: 37.4 | I3: 38.7 | J3: 40.6 | K3: 39.1
A4: p103-3 | B4: 43.3 | C4: 37.2 | D4: 36.8 | E4: 39.7 | F4: 39.2 | G4: 41.4 | H4: 38 | I4: 41.2 | J4: 44.1 | K4: 39.7
A5: p104-3 | B5: 40.7 | C5: 47.3 | D5: 40 | E5: 39.1 | F5: 39.7 | G5: 41.5 | H5: 38.3 | I5: 40.5 | J5: 43.1 | K5: 41.4
A6: p105-3 | B6: 39 | C6: 36.5 | D6: 36.7 | E6: 35.1 | F6: 36.6 | G6: 38.7 | H6: 37.9 | I6: 32.7 | J6: 38.4 | K6: 38.3
A7: p106-3 | B7: 40.6 | C7: 45.4 | D7: 42.2 | E7: 37.3 | F7: 42.6 | G7: 39.9 | H7: 43.1 | I7: 43.4 | J7: 48.6 | K7: 47.9
A8: p107-3 | B8: 39.2 | C8: 41.7 | D8: 41 | E8: 38.4 | F8: 42.9 | G8: 40.2 | H8: 39.6 | I8: 41.3 | J8: 43.1 | K8: 42.5
A9: p108-3 | B9: 44.2 | C9: 39.8 | D9: 36.2 | E9: 38.3 | F9: 42.3 | G9: 40.7 | H9: 39.5 | I9: 47.4 | J9: 43.7 | K9: 42.2
A10: p201-3 | B10: 40.9 | C10: 37.5 | D10: 37.1 | E10: 37.8 | F10: 38.7 | G10: 38.2 | H10: 39 | I10: 39.3 | J10: 38.9 | K10: 38
A11: p202-3 | B11: 43.2 | C11: 45.3 | D11: 41.2 | E11: 39.6 | F11: 39.8 | G11: 43.8 | H11: 42.1 | I11: 45.4 | J11: 46.7 | K11: 43.9
A12: p203-3 | B12: 41.9 | C12: 42.3 | D12: 40.5 | E12: 41.6 | F12: 43.1 | G12: 42 | H12: 41.4 | I12: 42.8 | J12: 46.5 | K12: 42.9
A13: p204-3 | B13: 41.3 | C13: 38.9 | D13: 39.5 | E13: 39.2 | F13: 41.2 | G13: 40.9 | H13: 40.4 | I13: 42.4 | J13: 43.6 | K13: 42.3
... A37: p908-3 | B37: 48 | C37: 52.3 | D37: 53.8 | E37: 55.3 | F37: 55.3 | G37: 54 | H37: 55.7 | I37: 54.9 | J37: 53.9 | K37: 57.5

Sheet Density
A1: CCID | B1: PLPD
A2: p101-1 | B2: 6.3976378
A3: p101-2 | B3: 4.9212598
A4: p101-3 | B4: 4.9212598
A5: p101-4 | B5: 5.4133858
A6: p101-5 | B6: 4.4291339
A7: p101-6 | B7: 4.9212598
A8: p102-1 | B8: 11.811024
A9: p102-2 | B9: 12.30315
A10: p102-3 | B10: 13.287402
A11: p102-4 | B11: 8.8582677
A12: p102-5 | B12: 12.795276
A13: p102-6 | B13: 8.3661417
... A217: p908-6 | B217: 14.271654

Sheet Develop
A1: CCID | B1: EDATE | C1: PLYRE | D1: PLDOE
A2: p102-2 | B2: 37374 | C2: 2002 | D2: 118.33333
A3: p101-3 | B3: 37375 | C3: 2002 | D3: 118.5
A4: p102-3 | B4: 37390 | C4: 2002 | D4: 134.375
A5: p103-3 | B5: 37385 | C5: 2002 | D5: 129
A6: p104-3 | B6: 37375 | C6: 2002 | D6: 119.16667
A7: p105-3 | B7: 37376 | C7: 2002 | D7: 119.66667
A8: p106-3 | B8: 37376 | C8: 2002 | D8: 120.25
A9: p107-3 | B9: 37375 | C9: 2002 | D9: 118.66667
A10: p108-3 | B10: 37386 | C10: 2002 | D10: 130.05263
A11: p201-3 | B11: 37384 | C11: 2002 | D11: 127.85714
A12: p202-3 | B12: 37376 | C12: 2002 | D12: 119.75
A13: p203-3 | B13: 37374 | C13: 2002 | D13: 118
... A74: p908-4 | B74: 37375 | C74: 2002 | D74: 119.35714

Sheet template
A1: F105 | J1: F105
A2: Overflight | J2: Overflight | M2: page 2
A5: Plant Canopy Measurements | J5: Plant Canopy Measurements
F7: Plant Height Cm) | O7: Plant Canopy Width (cm)
A8: Plot | B8: acron | C8: trt. | D8: 1 | E8: 2 | F8: 3 | G8: 4 | H8: 5 | I8: 6 | J8: Plot | K8: acron | L8: trt. | M8: 1 | N8: 2 | O8: 3 | P8: 4 | Q8: 5 | R8: 6
A9: 101 | B9: FSH | C9: 1 | J9: 101 | K9: FSH | L9: 1
A10: 102 | B10: FTL | C10: 4 | J10: 102 | K10: FTL | L10: 4
A11: 103 | B11: FDH | C11: 5 | J11: 103 | K11: FDH | L11: 5
A12: 104 | B12: NTL | C12: 10 | J12: 104 | K12: NTL | L12: 10
A13: 105 | B13: NDL | C13: 12 | J13: 105 | K13: NDL | L13: 12
A14: 106 | B14: NTH | C14: 9 | J14: 106 | K14: NTH | L14: 9
A15: 107 | B15: NTL | C15: 10 | J15: 107 | K15: NTL | L15: 10
A16: 108 | B16: FTH | C16: 3 | J16: 108 | K16: FTH | L16: 3
A17: 201 | B17: NDL | C17: 12 | J17: 201 | K17: NDL | L17: 12
A18: 202 | B18: NTH | C18: 9 | J18: 202 | K18: NTH | L18: 9
A19: 203 | B19: FTH | C19: 3 | J19: 203 | K19: FTH | L19: 3
A20: 204 | B20: NDH | C20: 11 | J20: 204 | K20: NDH | L20: 11
... A41: 901 | B41: WS | C41: 32 | J41: 901 | K41: WS | L41: 32
A42: 902 | B42: 37452 | C42: 22 | J42: 902 | K42: 37452 | L42: 22
A43: 903 | B43: DS | C43: 31 | J43: 903 | K43: DS | L43: 31
A44: 904 | B44: 37408 | C44: 21 | J44: 904 | K44: 37408 | L44: 21
A45: 905 | B45: WS | C45: 32 | J45: 905 | K45: WS | L45: 32
A46: 906 | B46: 37452 | C46: 22 | J46: 906 | K46: 37452 | L46: 22
A47: 907 | B47: DS | C47: 31 | J47: 907 | K47: DS | L47: 31
A48: 908 | B48: 37408 | C48: 21 | J48: 908 | K48: 37408 | L48: 21

Sheet HgtDOY163
A1: F105
A2: Overflight 2
A3: June 12 2002
E4: R= harvest row number
A5: Plant Canopy Measurements
F7: Plant Height Cm) | M7: Plant Canopy Width (cm)
A8: Plot | B8: acron | C8: trt. | D8: R3 | E8: R4 | F8: R5 | G8: R6 | H8: R7 | I8: R8 | J8: average ht | K8: R3 | L8: R4 | M8: R5 | N8: R6 | O8: R7 | P8: R8 | Q8: average width
A9: 101 | B9: FSH | C9: 1 | D9: 31.5 | E9: 33 | F9: 35 | G9: 34 | H9: 36.5 | I9: 28.5 | J9: =AVERAGE(D9:I9) -> 33.083333 | K9: 34.5 | L9: 32.5 | M9: 36 | N9: 32 | O9: 36 | P9: 29 | Q9: =AVERAGE(K9:P9) -> 33.333333
A10: 102 | B10: FTL | C10: 4 | D10: 34 | E10: 38 | F10: 32.5 | G10: 25.5 | H10: 28.5 | I10: 24 | J10: =AVERAGE(D10:I10) -> 30.416667 | K10: 38 | L10: 41.5 | M10: 27.5 | N10: 22 | O10: 28 | P10: 30 | Q10: =AVERAGE(K10:P10) -> 31.166667
A11: 103 | B11: FDH | C11: 5 | D11: 25.5 | E11: 36 | F11: 27.5 | G11: 38 | H11: 31.5 | I11: 35 | J11: =AVERAGE(D11:I11) -> 32.25 | K11: 47.5 | L11: 58 | M11: 47 | N11: 54 | O11: 57 | P11: 53.5 | Q11: =AVERAGE(K11:P11) -> 52.833333
A12: 104 | B12: NTL | C12: 10 | D12: 32.5 | E12: 34 | F12: 33 | G12: 33.5 | H12: 30 | I12: 29.5 | J12: =AVERAGE(D12:I12) -> 32.083333 | K12: 43 | L12: 37 | M12: 34 | N12: 42 | O12: 37 | P12: 38.5 | Q12: =AVERAGE(K12:P12) -> 38.583333
A13: 105 | B13: NDL | C13: 12 | D13: 29 | E13: 36 | F13: 31 | G13: 26.5 | H13: 30.5 | I13: 32 | J13: =AVERAGE(D13:I13) -> 30.833333 | K13: 50 | L13: 57.5 | M13: 55 | N13: 53 | O13: 53.5 | P13: 58 | Q13: =AVERAGE(K13:P13) -> 54.5
A14: 106 | B14: NTH | C14: 9 | D14: 33 | E14: 26 | F14: 30 | G14: 29.5 | H14: 30 | I14: 25 | J14: =AVERAGE(D14:I14) -> 28.916667 | K14: 42 | L14: 31 | M14: 40 | N14: 36.5 | O14: 44.5 | P14: 35 | Q14: =AVERAGE(K14:P14) -> 38.166667
A15: 107 | B15: NTL | C15: 10 | D15: 31 | E15: 30 | F15: 25.5 | G15: 28 | H15: 30 | I15: 31.5 | J15: =AVERAGE(D15:I15) -> 29.333333 | K15: 35 | L15: 31.5 | M15: 29 | N15: 30.5 | O15: 36 | P15: 33 | Q15: =AVERAGE(K15:P15) -> 32.5
A16: 108 | B16: FTH | C16: 3 | D16: 31.5 | E16: 28 | F16: 27 | G16: 31.5 | H16: 31 | I16: 24 | J16: =AVERAGE(D16:I16) -> 28.833333 | K16: 42.5 | L16: 34 | M16: 32 | N16: 36 | O16: 37.5 | P16: 33.5 | Q16: =AVERAGE(K16:P16) -> 35.916667
A17: 201 | B17: NDL | C17: 12 | D17: 31.5 | E17: 33 | F17: 29.5 | G17: 30 | H17: 32 | I17: 29.5 | J17: =AVERAGE(D17:I17) -> 30.916667 | K17: 44 | L17: 54 | M17: 53 | N17: 48.5 | O17: 56.5 | P17: 52 | Q17: =AVERAGE(K17:P17) -> 51.333333
A18: 202 | B18: NTH | C18: 9 | D18: 38 | E18: 35 | F18: 23.5 | G18: 30.5 | H18: 32 | I18: 30.5 | J18: =AVERAGE(D18:I18) -> 31.583333 | K18: 44 | L18: 42.5 | M18: 27.5 | N18: 30.5 | O18: 37 | P18: 35 | Q18: =AVERAGE(K18:P18) -> 36.083333
A19: 203 | B19: FTH | C19: 3 | D19: 37 | E19: 32.5 | F19: 21 | G19: 33 | H19: 36.5 | I19: 24 | J19: =AVERAGE(D19:I19) -> 30.666667 | K19: 40.5 | L19: 31 | M19: 42 | N19: 27.5 | O19: 41 | P19: 38.5 | Q19: =AVERAGE(K19:P19) -> 36.75
A20: 204 | B20: NDH | C20: 11 | D20: 28.5 | E20: 30 | F20: 27.5 | G20: 34 | H20: 35 | I20: 28 | J20: =AVERAGE(D20:I20) -> 30.5 | K20: 50.5 | L20: 55 | M20: 69.5 | N20: 58.5 | O20: 58 | P20: 44 | Q20: =AVERAGE(K20:P20) -> 55.916667
... A41: 901 | B41: WS | C41: 32 | D41: 0 | E41: 0 | F41: 0 | G41: 0 | H41: 0 | I41: 0 | J41: =AVERAGE(D41:I41) -> 0 | K41: 0 | L41: 0 | M41: 0 | N41: 0 | O41: 0 | P41: 0 | Q41: =AVERAGE(K41:P41) -> 0
A42: 902 | B42: 37452 | C42: 22 | D42: 30.5 | E42: 31.5 | F42: 30 | G42: 29 | H42: 34.5 | I42: 32 | J42: =AVERAGE(D42:I42) -> 31.25 | K42: 36 | L42: 33.5 | M42: 36.5 | N42: 40 | O42: 38.5 | P42: 34 | Q42: =AVERAGE(K42:P42) -> 36.416667
A43: 903 | B43: DS | C43: 31 | D43: 0 | E43: 0 | F43: 0 | G43: 0 | H43: 0 | I43: 0 | J43: =AVERAGE(D43:I43) -> 0 | K43: 0 | L43: 0 | M43: 0 | N43: 0 | O43: 0 | P43: 0 | Q43: =AVERAGE(K43:P43) -> 0
A44: 904 | B44: 37408 | C44: 21 | D44: 26 | E44: 39 | F44: 28 | G44: 31 | H44: 28.5 | I44: 32 | J44: =AVERAGE(D44:I44) -> 30.75 | K44: 30 | L44: 42 | M44: 36 | N44: 36 | O44: 45 | P44: 36 | Q44: =AVERAGE(K44:P44) -> 37.5
A45: 905 | B45: WS | C45: 32 | D45: 0 | E45: 0 | F45: 0 | G45: 0 | H45: 0 | I45: 0 | J45: =AVERAGE(D45:I45) -> 0 | K45: 0 | L45: 0 | M45: 0 | N45: 0 | O45: 0 | P45: 0 | Q45: =AVERAGE(K45:P45) -> 0
A46: 906 | B46: 37452 | C46: 22 | D46: 32.5 | E46: 31 | F46: 29 | G46: 35.5 | H46: 30.5 | I46: 21 | J46: =AVERAGE(D46:I46) -> 29.916667 | K46: 37 | L46: 40 | M46: 31 | N46: 40.5 | O46: 37 | P46: 24 | Q46: =AVERAGE(K46:P46) -> 34.916667
A47: 907 | B47: DS | C47: 31 | D47: 0 | E47: 0 | F47: 0 | G47: 0 | H47: 0 | I47: 0 | J47: =AVERAGE(D47:I47) -> 0 | K47: 0 | L47: 0 | M47: 0 | N47: 0 | O47: 0 | P47: 0 | Q47: =AVERAGE(K47:P47) -> 0
A48: 908 | B48: 37408 | C48: 21 | D48: 33 | E48: 28.5 | F48: 35 | G48: 34.5 | H48: 32 | I48: 30 | J48: =AVERAGE(D48:I48) -> 32.166667 | K48: 36 | L48: 35 | M48: 39 | N48: 37.5 | O48: 45 | P48: 38 | Q48: =AVERAGE(K48:P48) -> 38.416667

Sheet HgtDOY170
A1: F105
A2: No overflight week
A3: June 19 2002
A4: DOY 170 | E4: R= harvest row number
A5: Plant Canopy Measurements
F7: Plant Height Cm) | M7: Plant Canopy Width (cm)
A8: Plot | B8: acron | C8: trt. | D8: R3 | E8: R4 | F8: R5 | G8: R6 | H8: R7 | I8: R8 | J8: average ht | K8: R3 | L8: R4 | M8: R5 | N8: R6 | O8: R7 | P8: R8 | Q8: average width
A9: 101 | B9: FSH | C9: 1 | D9: 36.5 | E9: 40.5 | F9: 47 | G9: 47 | H9: 48 | I9: 37 | J9: =AVERAGE(D9:I9) -> 42.666667 | K9: 40.5 | L9: 44 | M9: 43.5 | N9: 45 | O9: 48.5 | P9: 34 | Q9: =AVERAGE(K9:P9) -> 42.583333
A10: 102 | B10: FTL | C10: 4 | D10: 38.5 | E10: 46 | F10: 33 | G10: 35 | H10: 36 | I10: 43 | J10: =AVERAGE(D10:I10) -> 38.583333 | K10: 36 | L10: 41 | M10: 41 | N10: 34 | O10: 35 | P10: 47 | Q10: =AVERAGE(K10:P10) -> 39
A11: 103 | B11: FDH | C11: 5 | D11: 37.5 | E11: 34 | F11: 40 | G11: 45 | H11: 43 | I11: 41 | J11: =AVERAGE(D11:I11) -> 40.083333 | K11: 51 | L11: 58 | M11: 52 | N11: 55 | O11: 60 | P11: 62 | Q11: =AVERAGE(K11:P11) -> 56.333333
A12: 104 | B12: NTL | C12: 10 | D12: 42 | E12: 41 | F12: 42 | G12: 43 | H12: 40 | I12: 38.5 | J12: =AVERAGE(D12:I12) -> 41.083333 | K12: 39 | L12: 37.5 | M12: 38 | N12: 43.5 | O12: 37 | P12: 39 | Q12: =AVERAGE(K12:P12) -> 39
A13: 105 | B13: NDL | C13: 12 | D13: 40 | E13: 40 | F13: 43 | G13: 34 | H13: 40 | I13: 44 | J13: =AVERAGE(D13:I13) -> 40.166667 | K13: 53 | L13: 60 | M13: 60 | N13: 49 | O13: 53 | P13: 61 | Q13: =AVERAGE(K13:P13) -> 56
A14: 106 | B14: NTH | C14: 9 | D14: 42.5 | E14: 31 | F14: 42 | G14: 34 | H14: 39 | I14: 33 | J14: =AVERAGE(D14:I14) -> 36.916667 | K14: 43 | L14: 31 | M14: 45 | N14: 30 | O14: 43 | P14: 31 | Q14: =AVERAGE(K14:P14) -> 37.166667
A15: 107 | B15: NTL | C15: 10 | D15: 39 | E15: 38 | F15: 33 | G15: 43 | H15: 37 | I15: 39.5 | J15: =AVERAGE(D15:I15) -> 38.25 | K15: 38.5 | L15: 36 | M15: 32 | N15: 40 | O15: 31 | P15: 33.5 | Q15: =AVERAGE(K15:P15) -> 35.166667
A16: 108 | B16: FTH | C16: 3 | D16: 43 | E16: 35 | F16: 35 | G16: 36 | H16: 38 | I16: 34 | J16: =AVERAGE(D16:I16) -> 36.833333 | K16: 45 | L16: 33 | M16: 34 | N16: 40 | O16: 43 | P16: 40 | Q16: =AVERAGE(K16:P16) -> 39.166667
A17: 201 | B17: NDL | C17: 12 | D17: 44.5 | E17: 46 | F17: 38.5 | G17: 42.5 | H17: 47 | I17: 37.5 | J17: =AVERAGE(D17:I17) -> 42.666667 | K17: 58 | L17: 61.5 | M17: 62 | N17: 60 | O17: 67 | P17: 53 | Q17: =AVERAGE(K17:P17) -> 60.25
A18: 202 | B18: NTH | C18: 9 | D18: 43.5 | E18: 39 | F18: 29.5 | G18: 28.5 | H18: 37 | I18: 39.5 | J18: =AVERAGE(D18:I18) -> 36.166667 | K18: 55 | L18: 45 | M18: 28 | N18: 26.5 | O18: 40 | P18: 42 | Q18: =AVERAGE(K18:P18) -> 39.416667
A19: 203 | B19: FTH | C19: 3 | D19: 48 | E19: 41 | F19: 46 | G19: 43 | H19: 47.5 | I19: 36.5 | J19: =AVERAGE(D19:I19) -> 43.666667 | K19: 52 | L19: 46 | M19: 45 | N19: 44.5 | O19: 43 | P19: 45 | Q19: =AVERAGE(K19:P19) -> 45.916667
A20: 204 | B20: NDH | C20: 11 | D20: 35.5 | E20: 40 | F20: 40.5 | G20: 45 | H20: 43 | I20: 38.5 | J20: =AVERAGE(D20:I20) -> 40.416667 | K20: 60 | L20: 51 | M20: 63 | N20: 64 | O20: 59.5 | P20: 45 | Q20: =AVERAGE(K20:P20) -> 57.083333
... A37: 405 | B37: FDL | C37: 6 | D37: 38 | E37: 36 | F37: 44 | G37: 42 | H37: 42 | I37: 39.5 | J37: =AVERAGE(D37:I37) -> 40.25 | K37: 50 | L37: 56 | M37: 59 | N37: 56 | O37: 56 | P37: 55 | Q37: =AVERAGE(K37:P37) -> 55.333333
A38: 406 | B38: FTH | C38: 3 | D38: 43.5 | E38: 44 | F38: 51 | G38: 47.5 | H38: 44 | I38: 37 | J38: =AVERAGE(D38:I38) -> 44.5 | K38: 43.5 | L38: 44 | M38: 46.5 | N38: 45 | O38: 44 | P38: 40.5 | Q38: =AVERAGE(K38:P38) -> 43.916667 | S38: Plot 408 @ 7:10-begin measurements
A39: 407 | B39: NSH | C39: 7 | D39: 42 | E39: 38 | F39: 37 | G39: 32.5 | H39: 34 | I39: 37.5 | J39: =AVERAGE(D39:I39) -> 36.833333 | K39: 44 | L39: 32 | M39: 35 | N39: 28.5 | O39: 38.5 | P39: 37.5 | Q39: =AVERAGE(K39:P39) -> 35.916667 | S39: Plot 408 @ 8:23 am-end
A40: 408 | B40: NTL | C40: 10 | D40: 33 | E40: 36 | F40: 38.5 | G40: 38 | H40: 36 | I40: 34.5 | J40: =AVERAGE(D40:I40) -> 36 | K40: 26.5 | L40: 30.5 | M40: 41 | N40: 41 | O40: 28 | P40: 37 | Q40: =AVERAGE(K40:P40) -> 34 | R40: ht | S40: 34 | T40: 36 | U40: 40 | V40: 41 | W40: 37.5 | X40: 39 | Y40: wdth | Z40: 33 | AA40: 38 | AB40: 41.5 | AC40: 40 | AD40: 38 | AE40: 37
A41: 901 | B41: WS | C41: 32 | D41: 0 | E41: 0 | F41: 0 | G41: 0 | H41: 0 | I41: 0 | J41: =AVERAGE(D41:I41) -> 0 | K41: 0 | L41: 0 | M41: 0 | N41: 0 | O41: 0 | P41: 0 | Q41: =AVERAGE(K41:P41) -> 0
A42: 902 | B42: 37452 | C42: 22 | D42: 39 | E42: 41 | F42: 38.5 | G42: 48.5 | H42: 48 | I42: 44 | J42: =AVERAGE(D42:I42) -> 43.166667 | K42: 40 | L42: 40 | M42: 45 | N42: 49 | O42: 51 | P42: 50 | Q42: =AVERAGE(K42:P42) -> 45.833333
A43: 903 | B43: DS | C43: 31 | D43: 0 | E43: 0 | F43: 0 | G43: 0 | H43: 0 | I43: 0 | J43: =AVERAGE(D43:I43) -> 0 | K43: 0 | L43: 0 | M43: 0 | N43: 0 | O43: 0 | P43: 0 | Q43: =AVERAGE(K43:P43) -> 0
A44: 904 | B44: 37408 | C44: 21 | D44: 37 | E44: 51 | F44: 48 | G44: 41 | H44: 40 | I44: 45.5 | J44: =AVERAGE(D44:I44) -> 43.75 | K44: 37 | L44: 47 | M44: 44 | N44: 47 | O44: 41 | P44: 47.5 | Q44: =AVERAGE(K44:P44) -> 43.916667
A45: 905 | B45: WS | C45: 32 | D45: 0 | E45: 0 | F45: 0 | G45: 0 | H45: 0 | I45: 0 | J45: =AVERAGE(D45:I45) -> 0 | K45: 0 | L45: 0 | M45: 0 | N45: 0 | O45: 0 | P45: 0 | Q45: =AVERAGE(K45:P45) -> 0
A46: 906 | B46: 37452 | C46: 22 | D46: 43 | E46: 44 | F46: 45 | G46: 52 | H46: 41 | I46: 30 | J46: =AVERAGE(D46:I46) -> 42.5 | K46: 40 | L46: 38 | M46: 40 | N46: 45 | O46: 40 | P46: 27.5 | Q46: =AVERAGE(K46:P46) -> 38.416667
A47: 907 | B47: DS | C47: 31 | D47: 0 | E47: 0 | F47: 0 | G47: 0 | H47: 0 | I47: 0 | J47: =AVERAGE(D47:I47) -> 0 | K47: 0 | L47: 0 | M47: 0 | N47: 0 | O47: 0 | P47: 0 | Q47: =AVERAGE(K47:P47) -> 0
A48: 908 | B48: 37408 | C48: 21 | D48: 42 | E48: 34.5 | F48: 44 | G48: 43 | H48: 42 | I48: 41.5 | J48: =AVERAGE(D48:I48) -> 41.166667 | K48: 47 | L48: 46 | M48: 42 | N48: 42 | O48: 41 | P48: 45 | Q48: =AVERAGE(K48:P48) -> 43.833333

Sheet HgtDOY176
A1: F105
A2: Overflight 3
A3: 37432
A4: Doy 176 | E4: R= harvest row number
A5: Plant Canopy Measurements
F7: Plant Height Cm) | M7: Plant Canopy Width (cm)
A8: Plot | B8: acron | C8: trt. | D8: R3 | E8: R4 | F8: R5 | G8: R6 | H8: R7 | I8: R8 | J8: average ht | K8: R3 | L8: R4 | M8: R5 | N8: R6 | O8: R7 | P8: R8 | Q8: average width
A9: 101 | B9: FSH | C9: 1 | D9: 48 | E9: 55 | F9: 56 | G9: 53.5 | H9: 56 | I9: 48 | J9: =AVERAGE(D9:I9) -> 52.75 | K9: 50.5 | L9: 56 | M9: 60.5 | N9: 50 | O9: 60 | P9: 39 | Q9: =AVERAGE(K9:P9) -> 52.666667
A10: 102 | B10: FTL | C10: 4 | D10: 51 | E10: 57.5 | F10: 40 | G10: 55 | H10: 48.5 | I10: 48 | J10: =AVERAGE(D10:I10) -> 50 | K10: 40 | L10: 49 | M10: 53 | N10: 53.5 | O10: 44.5 | P10: 58 | Q10: =AVERAGE(K10:P10) -> 49.666667
A11: 103 | B11: FDH | C11: 5 | D11: 45 | E11: 52 | F11: 45.5 | G11: 50 | H11: 51 | I11: 53 | J11: =AVERAGE(D11:I11) -> 49.416667 | K11: 58 | L11: 67 | M11: 65 | N11: 65.5 | O11: 69.5 | P11: 71 | Q11: =AVERAGE(K11:P11) -> 66
A12: 104 | B12: NTL | C12: 10 | D12: 50 | E12: 50 | F12: 50 | G12: 54 | H12: 50.5 | I12: 49.5 | J12: =AVERAGE(D12:I12) -> 50.666667 | K12: 53 | L12: 42 | M12: 47.5 | N12: 46 | O12: 52 | P12: 48 | Q12: =AVERAGE(K12:P12) -> 48.083333
A13: 105 | B13: NDL | C13: 12 | D13: 44 | E13: 48 | F13: 47.5 | G13: 57 | H13: 43.5 | I13: 45 | J13: =AVERAGE(D13:I13) -> 47.5 | K13: 58.5 | L13: 71 | M13: 69.5 | N13: 56 | O13: 63 | P13: 68 | Q13: =AVERAGE(K13:P13) -> 64.333333
A14: 106 | B14: NTH | C14: 9 | D14: 53 | E14: 45 | F14: 55 | G14: 49.5 | H14: 51.5 | I14: 48.5 | J14: =AVERAGE(D14:I14) -> 50.416667 | K14: 54 | L14: 42 | M14: 51.5 | N14: 51 | O14: 55 | P14: 49 | Q14: =AVERAGE(K14:P14) -> 50.416667
A15: 107 | B15: NTL | C15: 10 | D15: 50.5 | E15: 51.5 | F15: 47 | G15: 47.5 | H15: 51 | I15: 60 | J15: =AVERAGE(D15:I15) -> 51.25 | K15: 49.5 | L15: 54 | M15: 49.5 | N15: 50 | O15: 49 | P15: 51.5 | Q15: =AVERAGE(K15:P15) -> 50.583333
A16: 108 | B16: FTH | C16: 3 | D16: 53 | E16: 45 | F16: 43 | G16: 53 | H16: 54 | I16: 48.5 | J16: =AVERAGE(D16:I16) -> 49.416667 | K16: 59 | L16: 48 | M16: 47 | N16: 56 | O16: 58 | P16: 54 | Q16: =AVERAGE(K16:P16) -> 53.666667
A17: 201 | B17: NDL | C17: 12 | D17: 53.5 | E17: 51 | F17: 49.5 | G17: 54.5 | H17: 49 | I17: 48.5 | J17: =AVERAGE(D17:I17) -> 51 | K17: 62 | L17: 71.5 | M17: 66 | N17: 61 | O17: 65 | P17: 63 | Q17: =AVERAGE(K17:P17) -> 64.75
A18: 202 | B18: NTH | C18: 9 | D18: 51.5 | E18: 49 | F18: 44 | G18: 39 | H18: 46.5 | I18: 49.5 | J18: =AVERAGE(D18:I18) -> 46.583333 | K18: 46.5 | L18: 48 | M18: 52 | N18: 34 | O18: 46 | P18: 43 | Q18: =AVERAGE(K18:P18) -> 44.916667
A19: 203 | B19: FTH | C19: 3 | D19: 58 | E19: 53 | F19: 56.5 | G19: 55 | H19: 62.5 | I19: 45 | J19: =AVERAGE(D19:I19) -> 55 | K19: 56 | L19: 53.5 | M19: 55 | N19: 59 | O19: 59 | P19: 53 | Q19: =AVERAGE(K19:P19) -> 55.916667
A20: 204 | B20: NDH | C20: 11 | D20: 49.5 | E20: 56.5 | F20: 57 | G20: 52.5 | H20: 48 | I20: 48 | J20: =AVERAGE(D20:I20) -> 51.916667 | K20: 65 | L20: 58 | M20: 69.5 | N20: 63 | O20: 62.5 | P20: 56 | Q20: =AVERAGE(K20:P20) -> 62.333333
... A41: 901 | B41: WS | C41: 32 | D41: 0 | E41: 0 | F41: 0 | G41: 0 | H41: 0 | I41: 0 | J41: =AVERAGE(D41:I41) -> 0 | K41: 0 | L41: 0 | M41: 0 | N41: 0 | O41: 0 | P41: 0 | Q41: =AVERAGE(K41:P41) -> 0
A42: 902 | B42: 37452 | C42: 22 | D42: 53.5 | E42: 51 | F42: 50.5 | G42: 48 | H42: 50.5 | I42: 47.5 | J42: =AVERAGE(D42:I42) -> 50.166667 | K42: 47.5 | L42: 51 | M42: 47 | N42: 42 | O42: 50 | P42: 50.5 | Q42: =AVERAGE(K42:P42) -> 48
A43: 903 | B43: DS | C43: 31 | D43: 0 | E43: 0 | F43: 0 | G43: 0 | H43: 0 | I43: 0 | J43: =AVERAGE(D43:I43) -> 0 | K43: 0 | L43: 0 | M43: 0 | N43: 0 | O43: 0 | P43: 0 | Q43: =AVERAGE(K43:P43) -> 0
A44: 904 | B44: 37408 | C44: 21 | D44: 38.5 | E44: 49 | F44: 42.5 | G44: 42 | H44: 48.5 | I44: 47 | J44: =AVERAGE(D44:I44) -> 44.583333 | K44: 39 | L44: 46 | M44: 43 | N44: 40 | O44: 45 | P44: 44.5 | Q44: =AVERAGE(K44:P44) -> 42.916667
A45: 905 | B45: WS | C45: 32 | D45: 0 | E45: 0 | F45: 0 | G45: 0 | H45: 0 | I45: 0 | J45: =AVERAGE(D45:I45) -> 0 | K45: 0 | L45: 0 | M45: 0 | N45: 0 | O45: 0 | P45: 0 | Q45: =AVERAGE(K45:P45) -> 0
A46: 906 | B46: 37452 | C46: 22 | D46: 58 | E46: 56.5 | F46: 55 | G46: 65.5 | H46: 57 | I46: 48 | J46: =AVERAGE(D46:I46) -> 56.666667 | K46: 56.5 | L46: 57 | M46: 50 | N46: 53 | O46: 52.5 | P46: 44.5 | Q46: =AVERAGE(K46:P46) -> 52.25
A47: 907 | B47: DS | C47: 31 | D47: 0 | E47: 0 | F47: 0 | G47: 0 | H47: 0 | I47: 0 | J47: =AVERAGE(D47:I47) -> 0 | K47: 0 | L47: 0 | M47: 0 | N47: 0 | O47: 0 | P47: 0 | Q47: =AVERAGE(K47:P47) -> 0
A48: 908 | B48: 37408 | C48: 21 | D48: 47.5 | E48: 41 | F48: 48.5 | G48: 45.5 | H48: 47 | I48: 45.5 | J48: =AVERAGE(D48:I48) -> 45.833333 | K48: 45 | L48: 36 | M48: 46 | N48: 48 | O48: 44 | P48: 40.5 | Q48: =AVERAGE(K48:P48) -> 43.25

Sheet HgtDOY183
A1: F105
A2: Overflight - no
A3: 37439
A4: Doy 183 | E4: R= harvest row number
A5: Plant Canopy Measurements
F7: Plant Height Cm) | M7: Plant Canopy Width (cm)
A8: Plot | B8: acron | C8: trt. | D8: R3 | E8: R4 | F8: R5 | G8: R6 | H8: R7 | I8: R8 | J8: average ht | K8: R3 | L8: R4 | M8: R5 | N8: R6 | O8: R7 | P8: R8 | Q8: average width
A9: 101 | B9: FSH | C9: 1 | D9: 54 | E9: 60 | F9: 61 | G9: 53 | H9: 59 | I9: 56 | J9: =AVERAGE(D9:I9) -> 57.166667 | K9: 38 | L9: 60 | M9: 54 | N9: 63 | O9: 60 | P9: 52 | Q9: =AVERAGE(K9:P9) -> 54.5
A10: 102 | B10: FTL | C10: 4 | D10: 55 | E10: 60 | F10: 60 | G10: 55 | H10: 56 | I10: 58 | J10: =AVERAGE(D10:I10) -> 57.333333 | K10: 44 | L10: 45 | M10: 50 | N10: 42 | O10: 48 | P10: 43 | Q10: =AVERAGE(K10:P10) -> 45.333333
A11: 103 | B11: FDH | C11: 5 | D11: 57 | E11: 61 | F11: 58 | G11: 53 | H11: 55 | I11: 54 | J11: =AVERAGE(D11:I11) -> 56.333333 | K11: 69 | L11: 70 | M11: 66 | N11: 66 | O11: 65 | P11: 61 | Q11: =AVERAGE(K11:P11) -> 66.166667
A12: 104 | B12: NTL | C12: 10 | D12: 56 | E12: 54 | F12: 59 | G12: 55 | H12: 47 | I12: 46 | J12: =AVERAGE(D12:I12) -> 52.833333 | K12: 42 | L12: 40 | M12: 44 | N12: 41 | O12: 40 | P12: 42 | Q12: =AVERAGE(K12:P12) -> 41.5
A13: 105 | B13: NDL | C13: 12 | D13: 49 | E13: 50 | F13: 57 | G13: 56 | H13: 58 | I13: 56 | J13: =AVERAGE(D13:I13) -> 54.333333 | K13: 67 | L13: 62 | M13: 63 | N13: 700 | O13: 69 | P13: 57 | Q13: =AVERAGE(K13:P13) -> 169.66667
A14: 106 | B14: NTH | C14: 9 | D14: 54 | E14: 58 | F14: 58 | G14: 60 | H14: 56 | I14: 60 | J14: =AVERAGE(D14:I14) -> 57.666667 | K14: 40 | L14: 60 | M14: 51 | N14: 48 | O14: 38 | P14: 48 | Q14: =AVERAGE(K14:P14) -> 47.5
A15: 107 | B15: NTL | C15: 10 | D15: 47 | E15: 55 | F15: 55 | G15: 54 | H15: 55 | I15: 53 | J15: =AVERAGE(D15:I15) -> 53.166667 | K15: 42 | L15: 44 | M15: 53 | N15: 44 | O15: 57 | P15: 42 | Q15: =AVERAGE(K15:P15) -> 47
A16: 108 | B16: FTH | C16: 3 | D16: 56 | E16: 65 | F16: 55 | G16: 58 | H16: 54 | I16: 65 | J16: =AVERAGE(D16:I16) -> 58.833333 | K16: 47 | L16: 57 | M16: 62 | N16: 56 | O16: 50 | P16: 57 | Q16: =AVERAGE(K16:P16) -> 54.833333
A17: 201 | B17: NDL | C17: 12 | D17: 60 | E17: 55 | F17: 59 | G17: 65 | H17: 62 | I17: 56 | J17: =AVERAGE(D17:I17) -> 59.5 | K17: 62 | L17: 68 | M17: 65 | N17: 61 | O17: 64 | P17: 63 | Q17: =AVERAGE(K17:P17) -> 63.833333
A18: 202 | B18: NTH | C18: 9 | D18: 50 | E18: 50 | F18: 41 | G18: 45 | H18: 50 | I18: 59 | J18: =AVERAGE(D18:I18) -> 49.166667 | K18: 46 | L18: 42 | M18: 35 | N18: 63 | O18: 38 | P18: 39 | Q18: =AVERAGE(K18:P18) -> 43.833333
A19: 203 | B19: FTH | C19: 3 | D19: 71 | E19: 55 | F19: 67 | G19: 59 | H19: 63 | I19: 58 | J19: =AVERAGE(D19:I19) -> 62.166667 | K19: 55 | L19: 53 | M19: 56 | N19: 55 | O19: 53 | P19: 55 | Q19: =AVERAGE(K19:P19) -> 54.5
A20: 204 | B20: NDH | C20: 11 | D20: 53 | E20: 56 | F20: 60 | G20: 57 | H20: 50 | I20: 46 | J20: =AVERAGE(D20:I20) -> 53.666667 | K20: 62 | L20: 59 | M20: 69 | N20: 64 | O20: 67 | P20: 55 | Q20: =AVERAGE(K20:P20) -> 62.666667
... A41: 901 | B41: WS | C41: 32 | D41: 0 | E41: 0 | F41: 0 | G41: 0 | H41: 0 | I41: 0 | J41: =AVERAGE(D41:I41) -> 0 | K41: 0 | L41: 0 | M41: 0 | N41: 0 | O41: 0 | P41: 0 | Q41: =AVERAGE(K41:P41) -> 0
A42: 902 | B42: 37452 | C42: 22 | D42: 61 | E42: 59 | F42: 57 | G42: 56 | H42: 52 | I42: 51 | J42: =AVERAGE(D42:I42) -> 56 | K42: 52 | L42: 55 | M42: 49 | N42: 45 | O42: 49 | P42: 48 | Q42: =AVERAGE(K42:P42) -> 49.666667
A43: 903 | B43: DS | C43: 31 | D43: 0 | E43: 0 | F43: 0 | G43: 0 | H43: 0 | I43: 0 | J43: =AVERAGE(D43:I43) -> 0 | K43: 0 | L43: 0 | M43: 0 | N43: 0 | O43: 0 | P43: 0 | Q43: =AVERAGE(K43:P43) -> 0
A44: 904 | B44: 37408 | C44: 21 | D44: 50 | E44: 44 | F44: 45 | G44: 54 | H44: 51 | I44: 49 | J44: =AVERAGE(D44:I44) -> 48.833333 | K44: 42 | L44: 46 | M44: 38 | N44: 40 | O44: 46 | P44: 40 | Q44: =AVERAGE(K44:P44) -> 42
A45: 905 | B45: WS | C45: 32 | D45: 0 | E45: 0 | F45: 0 | G45: 0 | H45: 0 | I45: 0 | J45: =AVERAGE(D45:I45) -> 0 | K45: 0 | L45: 0 | M45: 0 | N45: 0 | O45: 0 | P45: 0 | Q45: =AVERAGE(K45:P45) -> 0
A46: 906 | B46: 37452 | C46: 22 | D46: 61 | E46: 65 | F46: 70 | G46: 62 | H46: 60 | I46: 64 | J46: =AVERAGE(D46:I46) -> 63.666667 | K46: 44 | L46: 52 | M46: 51 | N46: 54 | O46: 43 | P46: 56 | Q46: =AVERAGE(K46:P46) -> 50
A47: 907 | B47: DS | C47: 31 | D47: 0 | E47: 0 | F47: 0 | G47: 0 | H47: 0 | I47: 0 | J47: =AVERAGE(D47:I47) -> 0 | K47: 0 | L47: 0 | M47: 0 | N47: 0 | O47: 0 | P47: 0 | Q47: =AVERAGE(K47:P47) -> 0
A48: 908 | B48: 37408 | C48: 21 | D48: 45 | E48: 48 | F48: 42 | G48: 41 | H48: 37 | I48: 49 | J48: =AVERAGE(D48:I48) -> 43.666667 | K48: 34 | L48: 48 | M48: 35 | N48: 34 | O48: 30 | P48: 40 | Q48: =AVERAGE(K48:P48) -> 36.833333

Sheet HgtDOY190
A1: F105
A2: Overflight #4
A3: 37446
A4: DOY190 | E4: R= harvest row number
A5: Plant Canopy Measurements
F7: Plant Height Cm) | M7: Plant Canopy Width (cm)
A8: Plot | B8: acron | C8: trt. | D8: R3 | E8: R4 | F8: R5 | G8: R6 | H8: R7 | I8: R8 | J8: average ht | K8: R3 | L8: R4 | M8: R5 | N8: R6 | O8: R7 | P8: R8 | Q8: average width
A9: 101 | B9: FSH | C9: 1 | D9: 69 | E9: 75 | F9: 78 | G9: 76 | H9: 81 | I9: 66 | J9: =AVERAGE(D9:I9) -> 74.166667 | K9: 70 | L9: 82 | M9: 70 | N9: 77 | O9: 75 | P9: 63 | Q9: =AVERAGE(K9:P9) -> 72.833333
A10: 102 | B10: FTL | C10: 4 | D10: 66 | E10: 80 | F10: 66 | G10: 71 | H10: 69 | I10: 76 | J10: =AVERAGE(D10:I10) -> 71.333333 | K10: 72 | L10: 68 | M10: 66 | N10: 73 | O10: 66 | P10: 74 | Q10: =AVERAGE(K10:P10) -> 69.833333
A11: 103 | B11: FDH | C11: 5 | D11: 63 | E11: 77 | F11: 67 | G11: 75 | H11: 68 | I11: 69 | J11: =AVERAGE(D11:I11) -> 69.833333 | K11: 73 | L11: 77 | M11: 69 | N11: 80 | O11: 83.5 | P11: 86 | Q11: =AVERAGE(K11:P11) -> 78.083333
A12: 104 | B12: NTL | C12: 10 | D12: 58 | E12: 61 | F12: 60 | G12: 73.5 | H12: 74 | I12: 62 | J12: =AVERAGE(D12:I12) -> 64.75 | K12: 61.5 | L12: 51 | M12: 59 | N12: 68 | O12: 57 | P12: 63 | Q12: =AVERAGE(K12:P12) -> 59.916667
A13: 105 | B13: NDL | C13: 12 | D13: 75 | E13: 82 | F13: 76 | G13: 74 | H13: 67 | I13: 73 | J13: =AVERAGE(D13:I13) -> 74.5 | K13: 81 | L13: 87 | M13: 87 | N13: 76 | O13: 81 | P13: 80 | Q13: =AVERAGE(K13:P13) -> 82
A14: 106 | B14: NTH | C14: 9 | D14: 75 | E14: 67 | F14: 77 | G14: 70 | H14: 72 | I14: 73 | J14: =AVERAGE(D14:I14) -> 72.333333 | K14: 67 | L14: 62 | M14: 79 | N14: 71 | O14: 73 | P14: 71 | Q14: =AVERAGE(K14:P14) -> 70.5
A15: 107 | B15: NTL | C15: 10 | D15: 80 | E15: 68 | F15: 75 | G15: 78 | H15: 77 | I15: 80 | J15: =AVERAGE(D15:I15) -> 76.333333 | K15: 72 | L15: 81 | M15: 73 | N15: 79 | O15: 72 | P15: 62 | Q15: =AVERAGE(K15:P15) -> 73.166667
A16: 108 | B16: FTH | C16: 3 | D16: 77 | E16: 66 | F16: 66 | G16: 70 | H16: 77 | I16: 73 | J16: =AVERAGE(D16:I16) -> 71.5 | K16: 76 | L16: 69 | M16: 73 | N16: 72 | O16: 71 | P16: 68 | Q16: =AVERAGE(K16:P16) -> 71.5
A17: 201 | B17: NDL | C17: 12 | D17: 71 | E17: 70 | F17: 63 | G17: 69 | H17: 69 | I17: 68 | J17: =AVERAGE(D17:I17) -> 68.333333 | K17: 87 | L17: 84 | M17: 86 | N17: 74 | O17: 80 | P17: 76 | Q17: =AVERAGE(K17:P17) -> 81.166667
A18: 202 | B18: NTH | C18: 9 | D18: 60 | E18: 57 | F18: 53 | G18: 58 | H18: 65 | I18: 62 | J18: =AVERAGE(D18:I18) -> 59.166667 | K18: 61 | L18: 63 | M18: 51 | N18: 53 | O18: 64 | P18: 55 | Q18: =AVERAGE(K18:P18) -> 57.833333
A19: 203 | B19: FTH | C19: 3 | D19: 68 | E19: 83 | F19: 76 | G19: 80 | H19: 72 | I19: 76 | J19: =AVERAGE(D19:I19) -> 75.833333 | K19: 73 | L19: 73 | M19: 75 | N19: 82 | O19: 81 | P19: 69 | Q19: =AVERAGE(K19:P19) -> 75.5
A20: 204 | B20: NDH | C20: 11 | D20: 66 | E20: 69 | F20: 74 | G20: 74 | H20: 77 | I20: 63 | J20: =AVERAGE(D20:I20) -> 70.5 | K20: 74 | L20: 76 | M20: 82 | N20: 75 | O20: 85 | P20: 81 | Q20: =AVERAGE(K20:P20) -> 78.833333
... A41: 901 | B41: WS | C41: 32 | D41: 0 | E41: 0 | F41: 0 | G41: 0 | H41: 0 | I41: 0 | J41: =AVERAGE(D41:I41) -> 0 | K41: 0 | L41: 0 | M41: 0 | N41: 0 | O41: 0 | P41: 0 | Q41: =AVERAGE(K41:P41) -> 0
A42: 902 | B42: 37452 | C42: 22 | D42: 68 | E42: 71 | F42: 84 | G42: 68 | H42: 66 | I42: 68 | J42: =AVERAGE(D42:I42) -> 70.833333 | K42: 63 | L42: 70 | M42: 68 | N42: 59 | O42: 64 | P42: 69 | Q42: =AVERAGE(K42:P42) -> 65.5
A43: 903 | B43: DS | C43: 31 | D43: 0 | E43: 0 | F43: 0 | G43: 0 | H43: 0 | I43: 0 | J43: =AVERAGE(D43:I43) -> 0 | K43: 0 | L43: 0 | M43: 0 | N43: 0 | O43: 0 | P43: 0 | Q43: =AVERAGE(K43:P43) -> 0
A44: 904 | B44: 37408 | C44: 21 | D44: 49 | E44: 43 | F44: 44 | G44: 52 | H44: 59 | I44: 46 | J44: =AVERAGE(D44:I44) -> 48.833333 | K44: 48 | L44: 59 | M44: 44 | N44: 47 | O44: 56 | P44: 49 | Q44: =AVERAGE(K44:P44) -> 50.5
A45: 905 | B45: WS | C45: 32 | D45: 0 | E45: 0 | F45: 0 | G45: 0 | H45: 0 | I45: 0 | J45: =AVERAGE(D45:I45) -> 0 | K45: 0 | L45: 0 | M45: 0 | N45: 0 | O45: 0 | P45: 0 | Q45: =AVERAGE(K45:P45) -> 0
A46: 906 | B46: 37452 | C46: 22 | D46: 70 | E46: 83 | F46: 91 | G46: 80 | H46: 77 | I46: 75 | J46: =AVERAGE(D46:I46) -> 79.333333 | K46: 69 | L46: 68 | M46: 74 | N46: 69 | O46: 64 | P46: 69 | Q46: =AVERAGE(K46:P46) -> 68.833333
A47: 907 | B47: DS | C47: 31 | D47: 0 | E47: 0 | F47: 0 | G47: 0 | H47: 0 | I47: 0 | J47: =AVERAGE(D47:I47) -> 0 | K47: 0 | L47: 0 | M47: 0 | N47: 0 | O47: 0 | P47: 0 | Q47: =AVERAGE(K47:P47) -> 0
A48: 908 | B48: 37408 | C48: 21 | D48: 39 | E48: 45 | F48: 48 | G48: 52 | H48: 41 | I48: 48 | J48: =AVERAGE(D48:I48) -> 45.5 | K48: 33 | L48: 54 | M48: 48 | N48: 51 | O48: 42 | P48: 51 | Q48: =AVERAGE(K48:P48) -> 46.5

Sheet HgtDOY199
A1: F105
A2: Overflight - no
A3: 37455
A4: DOY 199 | E4: R= harvest row number
A5: Plant Canopy Measurements
F7: Plant Height Cm) | M7: Plant Canopy Width (cm)
A8: Plot | B8: acron | C8: trt. | D8: R3 | E8: R4 | F8: R5 | G8: R6 | H8: R7 | I8: R8 | J8: average ht | K8: R3 | L8: R4 | M8: R5 | N8: R6 | O8: R7 | P8: R8 | Q8: average width
A9: 101 | B9: FSH | C9: 1 | D9: 80 | E9: 81 | F9: 90 | G9: 86 | H9: 86 | I9: 79 | J9: =AVERAGE(D9:I9) -> 83.666667 | K9: 83 | L9: 84 | M9: 80 | N9: 80 | O9: 80 | P9: 70 | Q9: =AVERAGE(K9:P9) -> 79.5
A10: 102 | B10: FTL | C10: 4 | D10: 77 | E10: 91 | F10: 79 | G10: 85 | H10: 87 | I10: 86 | J10: =AVERAGE(D10:I10) -> 84.166667 | K10: 79 | L10: 76 | M10: 70 | N10: 74 | O10: 74 | P10: 86 | Q10: =AVERAGE(K10:P10) -> 76.5
A11: 103 | B11: FDH | C11: 5 | D11: 82 | E11: 83 | F11: 88 | G11: 93 | H11: 80 | I11: 80 | J11: =AVERAGE(D11:I11) -> 84.333333 | K11: 80 | L11: 98 | M11: 84 | N11: 91 | O11: 91 | P11: 97 | Q11: =AVERAGE(K11:P11) -> 90.166667
A12: 104 | B12: NTL | C12: 10 | D12: 67 | E12: 64 | F12: 75 | G12: 77 | H12: 74 | I12: 75 | J12: =AVERAGE(D12:I12) -> 72 | K12: 74 | L12: 71 | M12: 68 | N12: 77 | O12: 77 | P12: 72 | Q12: =AVERAGE(K12:P12) -> 73.166667
A13: 105 | B13: NDL | C13: 12 | D13: 85 | E13: 101 | F13: 83 | G13: 90 | H13: 82 | I13: 83 | J13: =AVERAGE(D13:I13) -> 87.333333 | K13: 75 | L13: 98 | M13: 94 | N13: 95 | O13: 95 | P13: 84 | Q13: =AVERAGE(K13:P13) -> 90.166667
A14: 106 | B14: NTH | C14: 9 | D14: 80 | E14: 83 | F14: 83 | G14: 86 | H14: 77 | I14: 85 | J14: =AVERAGE(D14:I14) -> 82.333333 | K14: 76 | L14: 66 | M14: 90 | N14: 84 | O14: 84 | P14: 81 | Q14: =AVERAGE(K14:P14) -> 80.166667
A15: 107 | B15: NTL | C15: 10 | D15: 93 | E15: 76 | F15: 78 | G15: 86 | H15: 75 | I15: 82 | J15: =AVERAGE(D15:I15) -> 81.666667 | K15: 80 | L15: 85 | M15: 80 | N15: 78 | O15: 78 | P15: 69 | Q15: =AVERAGE(K15:P15) -> 78.333333
A16: 108 | B16: FTH | C16: 3 | D16: 82 | E16: 78 | F16: 80 | G16: 85 | H16: 86 | I16: 93 | J16: =AVERAGE(D16:I16) -> 84 | K16: 83 | L16: 73 | M16: 84 | N16: 79 | O16: 79 | P16: 74 | Q16: =AVERAGE(K16:P16) -> 78.666667
A17: 201 | B17: NDL | C17: 12 | D17: 85 | E17: 81 | F17: 72 | G17: 82 | H17: 81 | I17: 78 | J17: =AVERAGE(D17:I17) -> 79.833333 | K17: 89 | L17: 88 | M17: 88 | N17: 82 | O17: 89 | P17: 79 | Q17: =AVERAGE(K17:P17) -> 85.833333
A18: 202 | B18: NTH | C18: 9 | D18: 68 | E18: 74 | F18: 69 | G18: 76 | H18: 70 | I18: 68 | J18: =AVERAGE(D18:I18) -> 70.833333 | K18: 70 | L18: 68 | M18: 69 | N18: 62 | O18: 75 | P18: 70 | Q18: =AVERAGE(K18:P18) -> 69
A19: 203 | B19: FTH | C19: 3 | D19: 94 | E19: 93 | F19: 90 | G19: 84 | H19: 84 | I19: 81 | J19: =AVERAGE(D19:I19) -> 87.666667 | K19: 87 | L19: 72 | M19: 91 | N19: 87 | O19: 76 | P19: 75 | Q19: =AVERAGE(K19:P19) -> 81.333333
A20: 204 | B20: NDH | C20: 11 | D20: 87 | E20: 82 | F20: 81 | G20: 86 | H20: 87 | I20: 84 | J20: =AVERAGE(D20:I20) -> 84.5 | K20: 82 | L20: 81 | M20: 85 | N20: 78 | O20: 85 | P20: 86 | Q20: =AVERAGE(K20:P20) -> 82.833333
... A41: 901 | B41: WS | C41: 32 | D41: 0 | E41: 0 | F41: 0 | G41: 0 | H41: 0 | I41: 0 | J41: =AVERAGE(D41:I41) -> 0 | K41: 0 | L41: 0 | M41: 0 | N41: 0 | O41: 0 | P41: 0 | Q41: =AVERAGE(K41:P41) -> 0
A42: 902 | B42: 37452 | C42: 22 | D42: 68 | E42: 67 | F42: 63 | G42: 73 | H42: 77 | I42: 80 | J42: =AVERAGE(D42:I42) -> 71.333333 | K42: 67 | L42: 69 | M42: 74 | N42: 75 | O42: 86 | P42: 82 | Q42: =AVERAGE(K42:P42) -> 75.5
A43: 903 | B43: DS | C43: 31 | D43: 0 | E43: 0 | F43: 0 | G43: 0 | H43: 0 | I43: 0 | J43: =AVERAGE(D43:I43) -> 0 | K43: 0 | L43: 0 | M43: 0 | N43: 0 | O43: 0 | P43: 0 | Q43: =AVERAGE(K43:P43) -> 0
A44: 904 | B44: 37408 | C44: 21 | D44: 54 | E44: 61 | F44: 58 | G44: 39 | H44: 47 | I44: 46 | J44: =AVERAGE(D44:I44) -> 50.833333 | K44: 55 | L44: 56 | M44: 55 | N44: 48 | O44: 62 | P44: 48 | Q44: =AVERAGE(K44:P44) -> 54
A45: 905 | B45: WS | C45: 32 | D45: 0 | E45: 0 | F45: 0 | G45: 0 | H45: 0 | I45: 0 | J45: =AVERAGE(D45:I45) -> 0 | K45: 0 | L45: 0 | M45: 0 | N45: 96 | O45: 0 | P45: 0 | Q45: =AVERAGE(K45:P45) -> 16
A46: 906 | B46: 37452 | C46: 22 | D46: 91 | E46: 82 | F46: 87 | G46: 103 | H46: 88 | I46: 84 | J46: =AVERAGE(D46:I46) -> 89.166667 | K46: 85 | L46: 76 | M46: 98 | N46: 96 | O46: 81 | P46: 78 | Q46: =AVERAGE(K46:P46) -> 85.666667
A47: 907 | B47: DS | C47: 31 | D47: 0 | E47: 0 | F47: 0 | G47: 0 | H47: 0 | I47: 0 | J47: =AVERAGE(D47:I47) -> 0 | K47: 0 | L47: 0 | M47: 0 | N47: 0 | O47: 0 | P47: 0 | Q47: =AVERAGE(K47:P47) -> 0
A48: 908 | B48: 37408 | C48: 21 | D48: 62 | E48: 41 | F48: 51 | G48: 50 | H48: 52 | I48: 46 | J48: =AVERAGE(D48:I48) -> 50.333333 | K48: 53 | L48: 54 | M48: 64 | N48: 53 | O48: 55 | P48: 41 | Q48: =AVERAGE(K48:P48) -> 53.333333
J49: =AVERAGE(J9:J48) -> 70.816667

Sheet HgtDOY204
A1: F105
A2: Overflight - no
A3: 37460
A4: DOY 204 | E4: R= harvest row number
A5: Plant Canopy Measurements
F7: Plant Height Cm) | M7: Plant Canopy Width (cm)
A8: Plot | B8: acron | C8: trt. | D8: R3 | E8: R4 | F8: R5 | G8: R6 | H8: R7 | I8: R8 | J8: average ht | K8: R3 | L8: R4 | M8: R5 | N8: R6 | O8: R7 | P8: R8 | Q8: average width
A9: 101 | B9: FSH | C9: 1 | D9: 88 | E9: 93 | F9: 96 | G9: 92 | H9: 88 | I9: 84 | J9: =AVERAGE(D9:I9) -> 90.166667 | K9: 86 | L9: 91 | M9: 82 | N9: 80 | O9: 97 | P9: 85 | Q9: =AVERAGE(K9:P9) -> 86.833333
A10: 102 | B10: FTL | C10: 4 | D10: 83 | E10: 97 | F10: 93 | G10: 94 | H10: 84 | I10: 92 | J10: =AVERAGE(D10:I10) -> 90.5 | K10: 95 | L10: 83 | M10: 71 | N10: 86 | O10: 72 | P10: 87 | Q10: =AVERAGE(K10:P10) -> 82.333333
A11: 103 | B11: FDH | C11: 5 | D11: 91 | E11: 97 | F11: 96 | G11: 95 | H11: 87 | I11: 86 | J11: =AVERAGE(D11:I11) -> 92 | K11: 86 | L11: 93 | M11: 86 | N11: 88 | O11: 95 | P11: 95 | Q11: =AVERAGE(K11:P11) -> 90.5
A12: 104 | B12: NTL | C12: 10 | D12: 72 | E12: 68 | F12: 78 | G12: 90 | H12: 70 | I12: 94 | J12: =AVERAGE(D12:I12) -> 78.666667 | K12: 73 | L12: 72 | M12: 66 | N12: 84 | O12: 76 | P12: 81 | Q12: =AVERAGE(K12:P12) -> 75.333333
A13: 105 | B13: NDL | C13: 12 | D13: 88 | E13: 100 | F13: 88 | G13: 94 | H13: 83 | I13: 90 | J13: =AVERAGE(D13:I13) -> 90.5 | K13: 78 | L13: 95 | M13: 98 | N13: 85 | O13: 91 | P13: 85 | Q13: =AVERAGE(K13:P13) -> 88.666667
A14: 106 | B14: NTH | C14: 9 | D14: 92 | E14: 77 | F14: 86 | G14: 85 | H14: 98 | I14: 85 | J14: =AVERAGE(D14:I14) -> 87.166667 | K14: 68 | L14: 89 | M14: 83 | N14: 87 | O14: 81 | P14: 85 | Q14: =AVERAGE(K14:P14) -> 82.166667
A15: 107 | B15: NTL | C15: 10 | D15: 89 | E15: 83 | F15: 95 | G15: 96 | H15: 82 | I15: 92 | J15: =AVERAGE(D15:I15) -> 89.5 | K15: 86 | L15: 88 | M15: 82 | N15: 94 | O15: 87 | P15: 74 | Q15: =AVERAGE(K15:P15) -> 85.166667
A16: 108 | B16: FTH | C16: 3 | D16: 88 | E16: 86 | F16: 91 | G16: 92 | H16: 91 | I16: 104 | J16: =AVERAGE(D16:I16) -> 92 | K16: 84 | L16: 73 | M16: 87 | N16: 93 | O16: 78 | P16: 78 | Q16: =AVERAGE(K16:P16) -> 82.166667
A17: 201 | B17: NDL | C17: 12 | D17: 90 | E17: 88 | F17: 79 | G17: 92 | H17: 90 | I17: 83 | J17: =AVERAGE(D17:I17) -> 87 | K17: 90 | L17: 83 | M17: 91 | N17: 83 | O17: 92 | P17: 83 | Q17: =AVERAGE(K17:P17) -> 87
A18: 202 | B18: NTH | C18: 9 | D18: 78 | E18: 71 | F18: 69 | G18: 77 | H18: 84 | I18: 73 | J18: =AVERAGE(D18:I18) -> 75.333333 | K18: 75 | L18: 72 | M18: 73 | N18: 80 | O18: 74 | P18: 85 | Q18: =AVERAGE(K18:P18) -> 76.5
A19: 203 | B19: FTH | C19: 3 | D19: 91 | E19: 96 | F19: 91 | G19: 94 | H19: 90 | I19: 97 | J19: =AVERAGE(D19:I19) -> 93.166667 | K19: 90 | L19: 82 | M19: 93 | N19: 86 | O19: 77 | P19: 90 | Q19: =AVERAGE(K19:P19) -> 86.333333
A20: 204 | B20: NDH | C20: 11 | D20: 97 | E20: 90 | F20: 93 | G20: 105 | H20: 93 | I20: 92 | J20: =AVERAGE(D20:I20) -> 95 | K20: 92 | L20: 92 | M20: 98 | N20: 90 | O20: 96 | P20: 84 | Q20: =AVERAGE(K20:P20) -> 92
... A41: 901 | B41: WS | C41: 32 | D41: 0 | E41: 0 | F41: 0 | G41: 0 | H41: 0 | I41: 0 | J41: =AVERAGE(D41:I41) -> 0 | K41: 0 | L41: 0 | M41: 0 | N41: 0 | O41: 0 | P41: 0 | Q41: =AVERAGE(K41:P41) -> 0
A42: 902 | B42: 37452 | C42: 22 | D42: 87 | E42: 74 | F42: 83 | G42: 99 | H42: 89 | I42: 88 | J42: =AVERAGE(D42:I42) -> 86.666667 | K42: 88 | L42: 84 | M42: 73 | N42: 82 | O42: 93 | P42: 80 | Q42: =AVERAGE(K42:P42) -> 83.333333
A43: 903 | B43: DS | C43: 31 | D43: 0 | E43: 0 | F43: 0 | G43: 0 | H43: 0 | I43: 0 | J43: =AVERAGE(D43:I43) -> 0 | K43: 0 | L43: 0 | M43: 0 | N43: 0 | O43: 0 | P43: 0 | Q43: =AVERAGE(K43:P43) -> 0
A44: 904 | B44: 37408 | C44: 21 | D44: 56 | E44: 60 | F44: 50 | G44: 41 | H44: 48 | I44: 51 | J44: =AVERAGE(D44:I44) -> 51 | K44: 53 | L44: 66 | M44: 57 | N44: 47 | O44: 51 | P44: 48 | Q44: =AVERAGE(K44:P44) -> 53.666667
A45: 905 | B45: WS | C45: 32 | D45: 0 | E45: 0 | F45: 0 | G45: 0 | H45: 0 | I45: 0 | J45: =AVERAGE(D45:I45) -> 0 | K45: 0 | L45: 0 | M45: 0 | N45: 0 | O45: 0 | P45: 0 | Q45: =AVERAGE(K45:P45) -> 0
A46: 906 | B46: 37452 | C46: 22 | D46: 91 | E46: 97 | F46: 98 | G46: 99 | H46: 92 | I46: 103 | J46: =AVERAGE(D46:I46) -> 96.666667 | K46: 92 | L46: 86 | M46: 100 | N46: 91 | O46: 92 | P46: 76 | Q46: =AVERAGE(K46:P46) -> 89.5
A47: 907 | B47: DS | C47: 31 | D47: 0 | E47: 0 | F47: 0 | G47: 0 | H47: 0 | I47: 0 | J47: =AVERAGE(D47:I47) -> 0 | K47: 0 | L47: 0 | M47: 0 | N47: 0 | O47: 0 | P47: 0 | Q47: =AVERAGE(K47:P47) -> 0
A48: 908 | B48: 37408 | C48: 21 | D48: 43 | E48: 59 | F48: 51 | G48: 45 | H48: 51 | I48: 48 | J48: =AVERAGE(D48:I48) -> 49.5 | K48: 49 | L48: 44 | M48: 56 | N48: 48 | O48: 50 | P48: 46 | Q48: =AVERAGE(K48:P48) -> 48.833333

Sheet HgtDOY212
A1: F105
A3: 37468
A4: DOY 212 | E4: R= harvest row number
A5: Plant Canopy Measurements
F7: Plant Height Cm) | M7: Plant Canopy Width (cm)
A8: Plot | B8: acron | C8: trt. | D8: R3 | E8: R4 | F8: R5 | G8: R6 | H8: R7 | I8: R8 | J8: average ht | K8: R3 | L8: R4 | M8: R5 | N8: R6 | O8: R7 | P8: R8 | Q8: average width
A9: 101 | B9: FSH | C9: 1 | D9: 100 | E9: 93 | F9: 84 | G9: 97 | H9: 86 | I9: 92 | J9: =AVERAGE(D9:I9) -> 92 | K9: 82 | L9: 91 | M9: 88 | N9: 83 | O9: 88 | P9: 86 | Q9: =AVERAGE(K9:P9) -> 86.333333
A10: 102 | B10: FTL | C10: 4 | D10: 91 | E10: 97 | F10: 93 | G10: 102 | H10: 90 | I10: 104 | J10: =AVERAGE(D10:I10) -> 96.166667 | K10: 94 | L10: 76 | M10: 73 | N10: 90 | O10: 83 | P10: 75 | Q10: =AVERAGE(K10:P10) -> 81.833333
A11: 103 | B11: FDH | C11: 5 | D11: 99 | E11: 102 | F11: 107 | G11: 98 | H11: 92 | I11: 91 | J11: =AVERAGE(D11:I11) -> 98.166667 | K11: 87 | L11: 96 | M11: 86 | N11: 94 | O11: 87 | P11: 101 | Q11: =AVERAGE(K11:P11) -> 91.833333
A12: 104 | B12: NTL | C12: 10 | D12: 75 | E12: 72 | F12: 88 | G12: 99 | H12: 87 | I12: 87 | J12: =AVERAGE(D12:I12) -> 84.666667 | K12: 78 | L12: 79 | M12: 79 | N12: 89 | O12: 80 | P12: 85 | Q12: =AVERAGE(K12:P12) -> 81.666667
A13: 105 | B13: NDL | C13: 12 | D13: 100 | E13: 106 | F13: 94 | G13: 91 | H13: 93 | I13: 93 | J13: =AVERAGE(D13:I13) -> 96.166667 | K13: 87 | L13: 99 | M13: 102 | N13: 93 | O13: 93 | P13: 90 | Q13: =AVERAGE(K13:P13) -> 94
A14: 106 | B14: NTH | C14: 9 | D14: 93 | E14: 100 | F14: 88 | G14: 96 | H14: 94 | I14: 107 | J14: =AVERAGE(D14:I14) -> 96.333333 | K14: 91 | L14: 82 | M14: 92 | N14: 88 | O14: 95 | P14: 89 | Q14: =AVERAGE(K14:P14) -> 89.5
A15: 107 | B15: NTL | C15: 10 | D15: 95 | E15: 95 | F15: 95 | G15: 90 | H15: 99 | I15: 104 | J15: =AVERAGE(D15:I15) -> 96.333333 | K15: 79 | L15: 90 | M15: 93 | N15: 98 | O15: 99 | P15: 78 | Q15: =AVERAGE(K15:P15) -> 89.5
A16: 108 | B16: FTH | C16: 3 | D16: 94 | E16: 92 | F16: 96 | G16: 98 | H16: 97 | I16: 120 | J16: =AVERAGE(D16:I16) -> 99.5 | K16: 84 | L16: 85 | M16: 92 | N16: 94 | O16: 87 | P16: 85 | Q16: =AVERAGE(K16:P16) -> 87.833333
A17: 201 | B17: NDL | C17: 12 | D17: 95 | E17: 96 | F17: 90 | G17: 81 | H17: 84 | I17: 87 | J17: =AVERAGE(D17:I17) -> 88.833333 | K17: 88 | L17: 92 | M17: 93 | N17: 88 | O17: 98 | P17: 87 | Q17: =AVERAGE(K17:P17) -> 91
A18: 202 | B18: NTH | C18: 9 | D18: 83 | E18: 81 | F18: 92 | G18: 100 | H18: 99 | I18: 86 | J18: =AVERAGE(D18:I18) -> 90.166667 | K18: 79 | L18: 90 | M18: 83 | N18: 77 | O18: 87 | P18: 76 | Q18: =AVERAGE(K18:P18) -> 82
A19: 203 | B19: FTH | C19: 3 | D19: 119 | E19: 112 | F19: 99 | G19: 103 | H19: 96 | I19: 98 | J19: =AVERAGE(D19:I19) -> 104.5 | K19: 90 | L19: 86 | M19: 88 | N19: 95 | O19: 80 | P19: 85 | Q19: =AVERAGE(K19:P19) -> 87.333333
A20: 204 | B20: NDH | C20: 11 | D20: 104 | E20: 94 | F20: 97 | G20: 112 | H20: 109 | I20: 103 | J20: =AVERAGE(D20:I20) -> 103.16667 | K20: 90 | L20: 93 | M20: 96 | N20: 90 | O20: 95 | P20: 91 | Q20: =AVERAGE(K20:P20) -> 92.5
... A41: 901 | B41: WS | C41: 32 | D41: 0 | E41: 0 | F41: 0 | G41: 0 | H41: 0 | I41: 0 | J41: =AVERAGE(D41:I41) -> 0 | K41: 0 | L41: 0 | M41: 0 | N41: 0 | O41: 0 | P41: 0 | Q41: =AVERAGE(K41:P41) -> 0
A42: 902 | B42: 37452 | C42: 22 | D42: 85 | E42: 81 | F42: 87 | G42: 103 | H42: 94 | I42: 101 | J42: =AVERAGE(D42:I42) -> 91.833333 | K42: 93 | L42: 83 | M42: 82 | N42: 89 | O42: 93 | P42: 89 | Q42: =AVERAGE(K42:P42) -> 88.166667
A43: 903 | B43: DS | C43: 31 | D43: 0 | E43: 0 | F43: 0 | G43: 0 | H43: 0 | I43: 0 | J43: =AVERAGE(D43:I43) -> 0 | K43: 0 | L43: 0 | M43: 0 | N43: 0 | O43: 0 | P43: 0 | Q43: =AVERAGE(K43:P43) -> 0
A44: 904 | B44: 37408 | C44: 21 | D44: 60 | E44: 43 | F44: 58 | G44: 42 | H44: 50 | I44: 46 | J44: =AVERAGE(D44:I44) -> 49.833333 | K44: 61 | L44: 49 | M44: 61 | N44: 45 | O44: 66 | P44: 51 | Q44: =AVERAGE(K44:P44) -> 55.5
A45: 905 | B45: WS | C45: 32 | D45: 0 | E45: 0 | F45: 0 | G45: 0 | H45: 0 | I45: 0 | J45: =AVERAGE(D45:I45) -> 0 | K45: 0 | L45: 0 | M45: 0 | N45: 0 | O45: 0 | P45: 0 | Q45: =AVERAGE(K45:P45) -> 0
A46: 906 | B46: 37452 | C46: 22 | D46: 100 | E46: 96 | F46: 105 | G46: 110 | H46: 98 | I46: 106 | J46: =AVERAGE(D46:I46) -> 102.5 | K46: 88 | L46: 80 | M46: 96 | N46: 92 | O46: 97 | P46: 88 | Q46: =AVERAGE(K46:P46) -> 90.166667
A47: 907 | B47: DS | C47: 31 | D47: 0 | E47: 0 | F47: 0 | G47: 0 | H47: 0 | I47: 0 | J47: =AVERAGE(D47:I47) -> 0 | K47: 0 | L47: 0 | M47: 0 | N47: 0 | O47: 0 | P47: 0 | Q47: =AVERAGE(K47:P47) -> 0
A48: 908 | B48: 37408 | C48: 21 | D48: 61 | E48: 45 | F48: 50 | G48: 42 | H48: 51 | I48: 52 | J48: =AVERAGE(D48:I48) -> 50.166667 | K48: 54 | L48: 58 | M48: 51 | N48: 51 | O48: 52 | P48: 41 | Q48: =AVERAGE(K48:P48) -> 51.166667

Sheet HgtDOY218
A1: F105
A3: 37474
A4: DOY 218 | E4: R= harvest row number
A5: Plant Canopy Measurements
F7: Plant Height Cm) | M7: Plant Canopy Width (cm)
A8: Plot | B8: acron | C8: trt. | D8: R3 | E8: R4 | F8: R5 | G8: R6 | H8: R7 | I8: R8 | J8: average ht | K8: R3 | L8: R4 | M8: R5 | N8: R6 | O8: R7 | P8: R8 | Q8: average width
A9: 101 | B9: FSH | C9: 1 | D9: 107 | E9: 93 | F9: 98 | G9: 99 | H9: 110 | I9: 123 | J9: =AVERAGE(D9:I9) -> 105 | K9: 88 | L9: 100 | M9: 93 | N9: 103 | O9: 100 | P9: 89 | Q9: =AVERAGE(K9:P9) -> 95.5
A10: 102 | B10: FTL | C10: 4 | D10: 96 | E10: 96 | F10: 108 | G10: 101 | H10: 103 | I10: 100 | J10: =AVERAGE(D10:I10) -> 100.66667 | K10: 100 | L10: 83 | M10: 78 | N10: 85 | O10: 83 | P10: 93 | Q10: =AVERAGE(K10:P10) -> 87
A11: 103 | B11: FDH | C11: 5 | D11: 102 | E11: 107 | F11: 105 | G11: 103 | H11: 101 | I11: 100 | J11: =AVERAGE(D11:I11) -> 103 | K11: 87 | L11: 101 | M11: 103 | N11: 98 | O11: 95 | P11: 109 | Q11: =AVERAGE(K11:P11) -> 98.833333
A12: 104 | B12: NTL | C12: 10 | D12: 73 | E12: 71 | F12: 86 | G12: 100 | H12: 87 | I12: 88 | J12: =AVERAGE(D12:I12) -> 84.166667 | K12: 74 | L12: 88 | M12: 86 | N12: 88 | O12: 93 | P12: 86 | Q12: =AVERAGE(K12:P12) -> 85.833333
A13: 105 | B13: NDL | C13: 12 | D13: 93 | E13: 106 | F13: 94 | G13: 94 | H13: 88 | I13: 91 | J13: =AVERAGE(D13:I13) -> 94.333333 | K13: 88 | L13: 95 | M13: 103 | N13: 97 | O13: 95 | P13: 95 | Q13: =AVERAGE(K13:P13) -> 95.5
A14: 106 | B14: NTH | C14: 9 | D14: 93 | E14: 113 | F14: 96 | G14: 99 | H14: 94 | I14: 103 | J14: =AVERAGE(D14:I14) -> 99.666667 | K14: 89 | L14: 86 | M14: 96 | N14: 92 | O14: 98 | P14: 92 | Q14: =AVERAGE(K14:P14) -> 92.166667
A15: 107 | B15: NTL | C15: 10 | D15: 98 | E15: 95 | F15: 95 | G15: 92 | H15: 100 | I15: 105 | J15: =AVERAGE(D15:I15) -> 97.5 | K15: 85 | L15: 93 | M15: 89 | N15: 105 | O15: 95 | P15: 84 | Q15: =AVERAGE(K15:P15) -> 91.833333
A16: 108 | B16: FTH | C16: 3 | D16: 95 | E16: 97 | F16: 108 | G16: 103 | H16: 103 | I16: 105 | J16: =AVERAGE(D16:I16) -> 101.83333 | K16: 90 | L16: 87 | M16: 92 | N16: 102 | O16: 92 | P16: 92 | Q16: =AVERAGE(K16:P16) -> 92.5
A17: 201 | B17: NDL | C17: 12 | D17: 98 | E17: 98 | F17: 90 | G17: 83 | H17: 87 | I17: 85 | J17: =AVERAGE(D17:I17) -> 90.166667 | K17: 92 | L17: 98 | M17: 99 | N17: 83 | O17: 88 | P17: 92 | Q17: =AVERAGE(K17:P17) -> 92
A18: 202 | B18: NTH | C18: 9 | D18: 88 | E18: 81 | F18: 99 | G18: 108 | H18: 85 | I18: 90 | J18: =AVERAGE(D18:I18) -> 91.833333 | K18: 94 | L18: 93 | M18: 94 | N18: 87 | O18: 82 | P18: 83 | Q18: =AVERAGE(K18:P18) -> 88.833333
A19: 203 | B19: FTH | C19: 3 | D19: 120 | E19: 121 | F19: 107 | G19: 106 | H19: 100 | I19: 104 | J19: =AVERAGE(D19:I19) -> 109.66667 | K19: 95 | L19: 95 | M19: 96 | N19: 98 | O19: 95 | P19: 94 | Q19: =AVERAGE(K19:P19) -> 95.5
A20: 204 | B20: NDH | C20: 11 | D20: 112 | E20: 100 | F20: 102 | G20: 105 | H20: 106 | I20: 105 | J20: =AVERAGE(D20:I20) -> 105 | K20: 100 | L20: 100 | M20: 100 | N20: 100 | O20: 100 | P20: 100 | Q20: =AVERAGE(K20:P20) -> 100
... A41: 901 | B41: WS | C41: 32 | D41: 0 | E41: 0 | F41: 0 | G41: 0 | H41: 0 | I41: 0 | J41: =AVERAGE(D41:I41) -> 0 | K41: 0 | L41: 0 | M41: 0 | N41: 0 | O41: 0 | P41: 0 | Q41: =AVERAGE(K41:P41) -> 0
A42: 902 | B42: 37452 | C42: 22 | D42: 86 | E42: 83 | F42: 98 | G42: 103 | H42: 94 | I42: 104 | J42: =AVERAGE(D42:I42) -> 94.666667 | K42: 83 | L42: 93 | M42: 86 | N42: 79 | O42: 101 | P42: 91 | Q42: =AVERAGE(K42:P42) -> 88.833333
A43: 903 | B43: DS | C43: 31 | D43: 0 | E43: 0 | F43: 0 | G43: 0 | H43: 0 | I43: 0 | J43: =AVERAGE(D43:I43) -> 0 | K43: 0 | L43: 0 | M43: 0 | N43: 0 | O43: 0 | P43: 0 | Q43: =AVERAGE(K43:P43) -> 0
A44: 904 | B44: 37408 | C44: 21 | D44: 61 | E44: 60 | F44: 55 | G44: 42 | H44: 43 | I44: 50 | J44: =AVERAGE(D44:I44) -> 51.833333 | K44: 68 | L44: 60 | M44: 60 | N44: 46 | O44: 60 | P44: 57 | Q44: =AVERAGE(K44:P44) -> 58.5
A45: 905 | B45: WS | C45: 32 | D45: 0 | E45: 0 | F45: 0 | G45: 0 | H45: 0 | I45: 0 | J45: =AVERAGE(D45:I45) -> 0 | K45: 0 | L45: 0 | M45: 0 | N45: 0 | O45: 0 | P45: 0 | Q45: =AVERAGE(K45:P45) -> 0
A46: 906 | B46: 37452 | C46: 22 | D46: 101 | E46: 101 | F46: 107 | G46: 110 | H46: 93 | I46: 128 | J46: =AVERAGE(D46:I46) -> 106.66667 | K46: 91 | L46: 103 | M46: 101 | N46: 102 | O46: 95 | P46: 98 | Q46: =AVERAGE(K46:P46) -> 98.333333
A47: 907 | B47: DS | C47: 31 | D47: 0 | E47: 0 | F47: 0 | G47: 0 | H47: 0 | I47: 0 | J47: =AVERAGE(D47:I47) -> 0 | K47: 0 | L47: 0 | M47: 0 | N47: 0 | O47: 0 | P47: 0 | Q47: =AVERAGE(K47:P47) -> 0
A48: 908 | B48: 37408 | C48: 21 | D48: 46 | E48: 46 | F48: 50 | G48: 45 | H48: 53 | I48: 46 | J48: =AVERAGE(D48:I48) -> 47.666667 | K48: 53 | L48: 56 | M48: 62 | N48: 51 | O48: 52 | P48: 46 | Q48: =AVERAGE(K48:P48) -> 53.333333

Sheet HgtDOY225
A1: F105
A3: 37481
A4: DOY 225 | E4: R= harvest row number
A5: Plant Canopy Measurements
F7: Plant Height Cm) | M7: Plant Canopy Width (cm)
A8: Plot | B8: acron | C8: trt. | D8: R3 | E8: R4 | F8: R5 | G8: R6 | H8: R7 | I8: R8 | J8: average ht | K8: R3 | L8: R4 | M8: R5 | N8: R6 | O8: R7 | P8: R8 | Q8: average width
A9: 101 | B9: FSH | C9: 1 | D9: 102 | E9: 101 | F9: 103 | G9: 114 | H9: 113 | I9: 98 | J9: =AVERAGE(D9:I9) -> 105.16667 | K9: 107 | L9: 105 | M9: 103 | N9: 105 | O9: 103 | P9: 97 | Q9: =AVERAGE(K9:P9) -> 103.33333
A10: 102 | B10: FTL | C10: 4 | D10: 100 | E10: 103 | F10: 104 | G10: 109 | H10: 88 | I10: 106 | J10: =AVERAGE(D10:I10) -> 101.66667 | K10: 100 | L10: 96 | M10: 95 | N10: 108 | O10: 88 | P10: 93 | Q10: =AVERAGE(K10:P10) -> 96.666667
