Workbook

Sheet PlantDF
A1: Year | B1: DOY | C1: PSDATE | D1: SID | E1: NumPlts | F1: Height | G1: PHTD1 | H1: STDD1 | I1: MSNODE1 | J1: PFNODE1 | K1: VBNUM1 | L1: VBNODE1 | M1: Height | N1: PHTD2 | O1: STDD2 | P1: MSNODE2 | Q1: PFNODE2 | R1: VBNUM2 | S1: VBNODE2 | T1: Height | U1: PHTD3 | V1: STDD3 | W1: MSNODE3 | X1: PFNODE3 | Y1: VBNUM3 | Z1: VBNODE3 | AA1: Height | AB1: PHTD4 | AC1: STDD4 | AD1: MSNODE4 | AE1: PFNODE4 | AF1: VBNUM4 | AG1: VBNODE4 | AH1: Height | AI1: PHTD5 | AJ1: STDD5 | AK1: MSNODE5 | AL1: PFNODE5 | AM1: VBNUM5 | AN1: VBNODE5 | AO1: Height | AP1: PHTD6 | AQ1: STDD6 | AR1: MSNODE6 | AS1: PFNODE6 | AT1: VBNUM6 | AU1: VBNODE6 | AV1: SQRNUM | AW1: FLRNUM | AX1: GBNUM | AY1: MBNUM | AZ1: LWPD | BA1: SWPD | BB1: CWPD | BC1: LWAD | BD1: SWAD | BE1: MBWAD | BF1: PWAD | BG1: CWAD | BH1: LAIDL
A2: 2003 | B2: 147 | C2: 37768 | D2: p101-S01 | E2: 6 | F2: 6.5 | G2: 0.065 | H2: 3 | I2: 2 | K2: 1 | L2: 0 | M2: 5.5 | N2: 0.055 | O2: 2.8 | P2: 3 | R2: 0 | S2: 0 | T2: 15 | U2: 0.15 | V2: 3.6 | W2: 5 | Y2: 0 | Z2: 0 | AA2: 5 | AB2: 0.05 | AC2: 2.4 | AD2: 1 | AF2: 0 | AG2: 0 | AH2: 8.5 | AI2: 0.085 | AJ2: 3 | AK2: 2 | AM2: 1 | AN2: 0 | AO2: 6 | AP2: 0.06 | AQ2: 2.2 | AR2: 1 | AT2: 1 | AU2: 0 | AV2: 0 | AW2: 0 | AX2: 0 | AY2: 0 | AZ2: 0.35833333 | BA2: 0.11666667 | BB2: 0.475 | BC2: 18.589717 | BD2: 6.0524661 | BE2: 0 | BF2: 0 | BG2: 24.642183 | BH2: 0.026453731
A3: 2003 | B3: 147 | C3: 37768 | D3: p102-S01 | E3: 6 | F3: 7 | G3: 0.07 | H3: 2.5 | I3: 2 | K3: 2 | L3: 0 | M3: 9 | N3: 0.09 | O3: 3.1 | P3: 4 | R3: 0 | S3: 0 | T3: 6.5 | U3: 0.065 | V3: 3.1 | W3: 0 | Y3: 0 | Z3: 0 | AA3: 7 | AB3: 0.07 | AC3: 2.8 | AD3: 2 | AF3: 2 | AG3: 0 | AH3: 4 | AI3: 0.04 | AJ3: 2.7 | AK3: 0 | AM3: 0 | AN3: 0 | AO3: 4.5 | AP3: 0.045 | AQ3: 2.5 | AR3: 0 | AT3: 0 | AU3: 0 | AV3: 0 | AW3: 0 | AX3: 0 | AY3: 0 | AZ3: 0.205 | BA3: 0.091666667 | BB3: 0.29666667 | BC3: 19.392498 | BD3: 8.6714421 | BE3: 0 | BF3: 0 | BG3: 28.06394 | BH3: 0.027254321
A4: 2003 | B4: 147 | C4: 37768 | D4: p103-S01 | E4: 6 | F4: 10 | G4: 0.1 | H4: 2.7 | I4: 4 | K4: 0 | L4: 0 | M4: 9.5 | N4: 0.095 | O4: 2.8 | P4: 4 | R4: 0 | S4: 0 | T4: 10 | U4: 0.1 | V4: 3.1 | W4: 2 | Y4: 0 | Z4: 0 | AA4: 12 | AB4: 0.12 | AC4: 3.3 | AD4: 5 | AF4: 0 | AG4: 0 | AH4: 10.5 | AI4: 0.105 | AJ4: 3.1 | AK4: 4 | AM4: 0 | AN4: 0 | AO4: 11 | AP4: 0.11 | AQ4: 3 | AR4: 3 | AT4: 0 | AU4: 0 | AV4: 0 | AW4: 0 | AX4: 0 | AY4: 0 | AZ4: 0.39833333 | BA4: 0.16 | BB4: 0.55833333 | BC4: 89.847168 | BD4: 36.089239 | BE4: 0 | BF4: 0 | BG4: 125.93641 | BH4: 0.1327985
A5: 2003 | B5: 147 | C5: 37768 | D5: p104-S01 | E5: 6 | F5: 9.6 | G5: 0.096 | H5: 3.8 | I5: 5 | K5: 1 | L5: 0 | M5: 8.8 | N5: 0.088 | O5: 2.6 | P5: 5 | R5: 0 | S5: 0 | T5: 10.4 | U5: 0.104 | V5: 3.4 | W5: 6 | Y5: 1 | Z5: 0 | AA5: 11.4 | AB5: 0.114 | AC5: 3 | AD5: 6 | AF5: 0 | AG5: 0 | AH5: 9.8 | AI5: 0.098 | AJ5: 2.8 | AK5: 5 | AM5: 0 | AN5: 0 | AO5: 7.2 | AP5: 0.072 | AQ5: 3 | AR5: 2 | AT5: 2 | AU5: 0 | AV5: 0 | AW5: 0 | AX5: 0 | AY5: 0 | AZ5: 0.475 | BA5: 0.17333333 | BB5: 0.64833333 | BC5: 57.574183 | BD5: 21.009527 | BE5: 0 | BF5: 0 | BG5: 78.58371 | BH5: 0.076400941
A6: 2003 | B6: 147 | C6: 37768 | D6: p105-S01 | E6: 6 | F6: 8.6 | G6: 0.086 | H6: 3.3 | I6: 2 | K6: 2 | L6: 0 | M6: 10.6 | N6: 0.106 | O6: 3.5 | P6: 4 | R6: 1 | S6: 0 | T6: 13.3 | U6: 0.133 | V6: 3.4 | W6: 5 | Y6: 0 | Z6: 0 | AA6: 8.6 | AB6: 0.086 | AC6: 3.1 | AD6: 4 | AF6: 1 | AG6: 0 | AH6: 9.6 | AI6: 0.096 | AJ6: 3.3 | AK6: 4 | AM6: 2 | AN6: 0 | AO6: 10.3 | AP6: 0.103 | AQ6: 3.1 | AR6: 4 | AT6: 1 | AU6: 0 | AV6: 0 | AW6: 0 | AX6: 0 | AY6: 0 | AZ6: 0.49666667 | BA6: 0.19666667 | BB6: 0.69333333 | BC6: 116.68915 | BD6: 46.205769 | BE6: 0 | BF6: 0 | BG6: 162.89492 | BH6: 0.13571596
A7: 2003 | B7: 147 | C7: 37768 | D7: p106-S01 | E7: 6 | F7: 8.5 | G7: 0.085 | H7: 2.9 | I7: 2 | K7: 1 | L7: 0 | M7: 11 | N7: 0.11 | O7: 3.2 | P7: 3 | R7: 0 | S7: 0 | T7: 7 | U7: 0.07 | V7: 3.2 | W7: 2 | Y7: 1 | Z7: 0 | AA7: 11 | AB7: 0.11 | AC7: 2.6 | AD7: 4 | AF7: 0 | AG7: 0 | AH7: 10 | AI7: 0.1 | AJ7: 2.5 | AK7: 5 | AM7: 0 | AN7: 0 | AO7: 5.5 | AP7: 0.055 | AQ7: 2.7 | AR7: 1 | AT7: 0 | AU7: 0 | AV7: 0 | AW7: 0 | AX7: 0 | AY7: 0 | AZ7: 0.37166667 | BA7: 0.14333333 | BB7: 0.515 | BC7: 45.421861 | BD7: 17.516951 | BE7: 0 | BF7: 0 | BG7: 62.938812 | BH7: 0.064120528
A8: 2003 | B8: 147 | C8: 37768 | D8: p107-S01 | E8: 6 | F8: 11 | G8: 0.11 | H8: 2.7 | I8: 3 | K8: 0 | L8: 0 | M8: 10.1 | N8: 0.101 | O8: 3.6 | P8: 4 | R8: 1 | S8: 0 | T8: 11.9 | U8: 0.119 | V8: 3 | W8: 5 | Y8: 0 | Z8: 0 | AA8: 10.6 | AB8: 0.106 | AC8: 3 | AD8: 5 | AF8: 1 | AG8: 0 | AH8: 5.1 | AI8: 0.051 | AJ8: 3 | AK8: 2 | AM8: 0 | AN8: 0 | AO8: 10.3 | AP8: 0.103 | AQ8: 2.9 | AR8: 4 | AT8: 2 | AU8: 0 | AV8: 0 | AW8: 0 | AX8: 0 | AY8: 0 | AZ8: 0.44666667 | BA8: 0.17 | BB8: 0.61666667 | BC8: 51.249757 | BD8: 19.505505 | BE8: 0 | BF8: 0 | BG8: 70.755261 | BH8: 0.060045645
A9: 2003 | B9: 147 | C9: 37768 | D9: p108-S01 | E9: 6 | F9: 11.6 | G9: 0.116 | H9: 3.2 | I9: 5 | K9: 0 | L9: 0 | M9: 11.6 | N9: 0.116 | O9: 2.9 | P9: 5 | R9: 0 | S9: 0 | T9: 7.2 | U9: 0.072 | V9: 3.3 | W9: 2 | Y9: 1 | Z9: 0 | AA9: 9 | AB9: 0.09 | AC9: 3.1 | AD9: 2 | AF9: 2 | AG9: 0 | AH9: 7 | AI9: 0.07 | AJ9: 2.6 | AK9: 3 | AM9: 1 | AN9: 0 | AO9: 7 | AP9: 0.07 | AQ9: 2.7 | AR9: 3 | AT9: 2 | AU9: 0 | AV9: 0 | AW9: 0 | AX9: 0 | AY9: 0 | AZ9: 0.34833333 | BA9: 0.14166667 | BB9: 0.49 | BC9: 41.61791 | BD9: 16.925944 | BE9: 0 | BF9: 0 | BG9: 58.543854 | BH9: 0.056288223
A10: 2003 | B10: 147 | C10: 37768 | D10: p201-S01 | E10: 6 | F10: 11 | G10: 0.11 | H10: 2.7 | I10: 3 | K10: 1 | L10: 0 | M10: 12 | N10: 0.12 | O10: 3.6 | P10: 6 | R10: 0 | S10: 0 | T10: 9 | U10: 0.09 | V10: 2.6 | W10: 4 | Y10: 0 | Z10: 0 | AA10: 6.5 | AB10: 0.065 | AC10: 2.3 | AD10: 3 | AF10: 0 | AG10: 0 | AH10: 8.5 | AI10: 0.085 | AJ10: 2.8 | AK10: 2 | AM10: 2 | AN10: 0 | AO10: 9 | AP10: 0.09 | AQ10: 3 | AR10: 3 | AT10: 0 | AU10: 0 | AV10: 0 | AW10: 0 | AX10: 0 | AY10: 0 | AZ10: 0.34666667 | BA10: 0.13666667 | BB10: 0.48333333 | BC10: 76.329348 | BD10: 30.091377 | BE10: 0 | BF10: 0 | BG10: 106.42073 | BH10: 0.10959622
A11: 2003 | B11: 147 | C11: 37768 | D11: p202-S01 | E11: 6 | F11: 10.5 | G11: 0.105 | H11: 3.7 | I11: 3 | K11: 1 | L11: 0 | M11: 11 | N11: 0.11 | O11: 3.6 | P11: 5 | R11: 0 | S11: 0 | T11: 11 | U11: 0.11 | V11: 3 | W11: 5 | Y11: 0 | Z11: 0 | AA11: 8.5 | AB11: 0.085 | AC11: 2.6 | AD11: 2 | AF11: 1 | AG11: 0 | AH11: 5 | AI11: 0.05 | AJ11: 2.5 | AK11: 0 | AM11: 0 | AN11: 0 | AO11: 5 | AP11: 0.05 | AQ11: 2.2 | AR11: 0 | AT11: 0 | AU11: 0 | AV11: 0 | AW11: 0 | AX11: 0 | AY11: 0 | AZ11: 0.43833333 | BA11: 0.16833333 | BB11: 0.60666667 | BC11: 54.927487 | BD11: 21.093826 | BE11: 0 | BF11: 0 | BG11: 76.021313 | BH11: 0.070706656
A12: 2003 | B12: 147 | C12: 37768 | D12: p203-S01 | E12: 6 | F12: 10 | G12: 0.1 | H12: 2.9 | I12: 5 | K12: 0 | L12: 0 | M12: 10 | N12: 0.1 | O12: 2.8 | P12: 4 | R12: 0 | S12: 0 | T12: 9 | U12: 0.09 | V12: 3.7 | W12: 3 | Y12: 3 | Z12: 0 | AA12: 9 | AB12: 0.09 | AC12: 3 | AD12: 3 | AF12: 2 | AG12: 0 | AH12: 14 | AI12: 0.14 | AJ12: 3.3 | AK12: 6 | AM12: 0 | AN12: 0 | AO12: 4.2 | AP12: 0.042 | AQ12: 1.6 | AR12: 3 | AT12: 0 | AU12: 0 | AV12: 0 | AW12: 0 | AX12: 0 | AY12: 0 | AZ12: 0.425 | BA12: 0.16166667 | BB12: 0.58666667 | BC12: 46.01378 | BD12: 17.503281 | BE12: 0 | BF12: 0 | BG12: 63.51706 | BH12: 0.069577115
A13: 2003 | B13: 147 | C13: 37768 | D13: p204-S01 | E13: 6 | F13: 11 | G13: 0.11 | H13: 3.6 | I13: 3 | K13: 2 | L13: 0 | M13: 10 | N13: 0.1 | O13: 3.3 | P13: 5 | R13: 0 | S13: 0 | T13: 9.5 | U13: 0.095 | V13: 2.9 | W13: 3 | Y13: 2 | Z13: 0 | AA13: 8 | AB13: 0.08 | AC13: 3 | AD13: 3 | AF13: 0 | AG13: 0 | AH13: 10 | AI13: 0.1 | AJ13: 2.9 | AK13: 3 | AM13: 0 | AN13: 0 | AO13: 8.5 | AP13: 0.085 | AQ13: 2.5 | AR13: 5 | AT13: 0 | AU13: 0 | AV13: 0 | AW13: 0 | AX13: 0 | AY13: 0 | AZ13: 0.36 | BA13: 0.14 | BB13: 0.5 | BC13: 87.040682 | BD13: 33.849154 | BE13: 0 | BF13: 0 | BG13: 120.88984 | BH13: 0.12767579
... A36: 2003 | B36: 153 | C36: 37774 | D36: p103-S02 | E36: 6 | F36: 15.9 | G36: 0.159 | H36: 4.7 | I36: 7 | K36: 1 | L36: 0 | M36: 11.4 | N36: 0.114 | O36: 3.5 | P36: 6 | R36: 3 | S36: 0 | T36: 18 | U36: 0.18 | V36: 4.3 | W36: 9 | Y36: 1 | Z36: 0 | AA36: 19.2 | AB36: 0.192 | AC36: 4.4 | AD36: 6 | AF36: 2 | AG36: 0 | AH36: 14 | AI36: 0.14 | AJ36: 4.1 | AK36: 7 | AM36: 1 | AN36: 0 | AO36: 17.8 | AP36: 0.178 | AQ36: 4.4 | AR36: 10 | AT36: 3 | AU36: 0 | AV36: 0 | AW36: 0 | AX36: 0 | AY36: 0 | AZ36: 1.0233333 | BA36: 0.485 | BB36: 1.5083333 | BC36: 230.82076 | BD36: 109.39551 | BE36: 0 | BF36: 0 | BG36: 340.21626 | BH36: 0.34382034
A37: 2003 | B37: 153 | C37: 37774 | D37: p104-S02 | E37: 6 | F37: 10.3 | G37: 0.103 | H37: 5 | I37: 4 | K37: 2 | L37: 0 | M37: 15.1 | N37: 0.151 | O37: 4.3 | P37: 6 | R37: 4 | S37: 0 | T37: 15.4 | U37: 0.154 | V37: 5 | W37: 7 | Y37: 1 | Z37: 0 | AA37: 15 | AB37: 0.15 | AC37: 4.1 | AD37: 5 | AF37: 1 | AG37: 0 | AH37: 14.2 | AI37: 0.142 | AJ37: 4.4 | AK37: 7 | AM37: 0 | AN37: 0 | AO37: 14.1 | AP37: 0.141 | AR37: 5 | AT37: 1 | AU37: 0 | AV37: 0 | AW37: 0 | AX37: 0 | AY37: 0 | AZ37: 0.94333333 | BA37: 0.40833333 | BB37: 1.3516667 | BC37: 114.34031 | BD37: 49.493596 | BE37: 0 | BF37: 0 | BG37: 163.8339 | BH37: 0.1786422
A38: 2003 | B38: 153 | C38: 37774 | D38: p105-S02 | E38: 6 | F38: 18.5 | G38: 0.185 | H38: 4.5 | I38: 8 | K38: 0 | L38: 0 | M38: 14 | N38: 0.14 | O38: 4.2 | P38: 4 | R38: 1 | S38: 0 | T38: 15 | U38: 0.15 | V38: 4.6 | W38: 5 | Y38: 1 | Z38: 0 | AA38: 25 | AB38: 0.25 | AC38: 5.4 | AD38: 8 | AF38: 4 | AG38: 0 | AH38: 16 | AI38: 0.16 | AJ38: 3.8 | AK38: 6 | AM38: 2 | AN38: 0 | AO38: 16 | AP38: 0.16 | AQ38: 4 | AR38: 6 | AT38: 1 | AU38: 0 | AV38: 0 | AW38: 0 | AX38: 0 | AY38: 0 | AZ38: 1.2116667 | BA38: 0.6 | BB38: 1.8116667 | BC38: 284.67453 | BD38: 140.96675 | BE38: 0 | BF38: 0 | BG38: 425.64128 | BH38: 0.41371249
A39: 2003 | B39: 153 | C39: 37774 | D39: p106-S02 | E39: 6 | F39: 14 | G39: 0.14 | H39: 5 | I39: 5 | K39: 2 | L39: 0 | M39: 16 | N39: 0.16 | O39: 4.4 | P39: 6 | R39: 2 | S39: 0 | T39: 12 | U39: 0.12 | V39: 3.7 | W39: 3 | Y39: 2 | Z39: 0 | AA39: 15 | AB39: 0.15 | AC39: 4.2 | AD39: 3 | AF39: 1 | AG39: 0 | AH39: 14.5 | AI39: 0.145 | AJ39: 4 | AK39: 4 | AM39: 1 | AN39: 0 | AO39: 16 | AP39: 0.16 | AQ39: 4.8 | AR39: 3 | AT39: 1 | AU39: 0 | AV39: 0 | AW39: 0 | AX39: 0 | AY39: 0 | AZ39: 1.0133333 | BA39: 0.47833333 | BB39: 1.4916667 | BC39: 123.84077 | BD39: 58.457732 | BE39: 0 | BF39: 0 | BG39: 182.2985 | BH39: 0.17529098
A40: 2003 | B40: 153 | C40: 37774 | D40: p107-S02 | E40: 6 | F40: 15 | G40: 0.15 | H40: 3.2 | I40: 6 | K40: 1 | L40: 0 | M40: 19 | N40: 0.19 | O40: 5.4 | P40: 3 | R40: 1 | S40: 0 | T40: 20 | U40: 0.2 | V40: 5.2 | W40: 8 | Y40: 2 | Z40: 0 | AA40: 13 | AB40: 0.13 | AC40: 4.6 | AD40: 4 | AF40: 1 | AG40: 0 | AH40: 15 | AI40: 0.15 | AJ40: 4 | AK40: 5 | AM40: 3 | AN40: 0 | AO40: 10 | AP40: 0.1 | AQ40: 2.7 | AR40: 4 | AT40: 0 | AU40: 0 | AV40: 0 | AW40: 0 | AX40: 0 | AY40: 0 | AZ40: 1.02 | BA40: 0.48833333 | BB40: 1.5083333 | BC40: 117.03303 | BD40: 56.030518 | BE40: 0 | BF40: 0 | BG40: 173.06355 | BH40: 0.1508093
A41: 2003 | B41: 153 | C41: 37774 | D41: p108-S02 | E41: 6 | F41: 19 | G41: 0.19 | H41: 5.2 | I41: 8 | K41: 3 | L41: 0 | M41: 11 | N41: 0.11 | O41: 3.1 | P41: 6 | R41: 0 | S41: 0 | T41: 15 | U41: 0.15 | V41: 4.5 | W41: 4 | Y41: 0 | Z41: 0 | AA41: 10 | AB41: 0.1 | AC41: 4.4 | AD41: 4 | AF41: 2 | AG41: 0 | AH41: 16 | AI41: 0.16 | AJ41: 4.6 | AK41: 7 | AM41: 3 | AN41: 0 | AO41: 14 | AP41: 0.14 | AQ41: 3.8 | AR41: 6 | AT41: 0 | AU41: 0 | AV41: 0 | AW41: 0 | AX41: 0 | AY41: 0 | AZ41: 0.91333333 | BA41: 0.43333333 | BB41: 1.3466667 | BC41: 109.12256 | BD41: 51.773476 | BE41: 0 | BF41: 0 | BG41: 160.89603 | BH41: 0.15109992
A42: 2003 | B42: 153 | C42: 37774 | D42: p201-S02 | E42: 6 | F42: 13.5 | G42: 0.135 | H42: 4.1 | I42: 6 | K42: 0 | L42: 0 | M42: 12 | N42: 0.12 | O42: 3.9 | P42: 3 | R42: 1 | S42: 0 | T42: 18 | U42: 0.18 | V42: 5.6 | W42: 6 | Y42: 6 | Z42: 0 | AA42: 18 | AB42: 0.18 | AC42: 5.2 | AD42: 5 | AF42: 1 | AG42: 0 | AH42: 13 | AI42: 0.13 | AJ42: 4 | AK42: 3 | AM42: 1 | AN42: 0 | AO42: 9.5 | AP42: 0.095 | AQ42: 3.7 | AR42: 5 | AT42: 0 | AU42: 0 | AV42: 0 | AW42: 0 | AX42: 0 | AY42: 0 | AZ42: 1.04 | BA42: 0.48166667 | BB42: 1.5216667 | BC42: 228.98804 | BD42: 106.05376 | BE42: 0 | BF42: 0 | BG42: 335.0418 | BH42: 0.33114794
A43: 2003 | B43: 153 | C43: 37774 | D43: p202-S02 | E43: 6 | F43: 17 | G43: 0.17 | H43: 4.6 | I43: 4 | K43: 2 | L43: 0 | M43: 10 | N43: 0.1 | O43: 3.3 | P43: 4 | R43: 1 | S43: 0 | T43: 16 | U43: 0.16 | V43: 4.9 | W43: 4 | Y43: 2 | Z43: 0 | AA43: 10 | AB43: 0.1 | AC43: 3.9 | AD43: 3 | AF43: 2 | AG43: 0 | AH43: 14 | AI43: 0.14 | AJ43: 3.7 | AK43: 4 | AM43: 2 | AN43: 0 | AO43: 8 | AP43: 0.08 | AQ43: 2.6 | AR43: 2 | AT43: 0 | AU43: 0 | AV43: 0 | AW43: 0 | AX43: 0 | AY43: 0 | AZ43: 0.735 | BA43: 0.36833333 | BB43: 1.1033333 | BC43: 92.102745 | BD43: 46.155797 | BE43: 0 | BF43: 0 | BG43: 138.25854 | BH43: 0.13432171
A44: 2003 | B44: 153 | C44: 37774 | D44: p203-S02 | E44: 6 | F44: 12.5 | G44: 0.125 | H44: 3.8 | I44: 5 | K44: 2 | L44: 0 | M44: 12 | N44: 0.12 | O44: 4.1 | P44: 6 | R44: 0 | S44: 0 | T44: 13 | U44: 0.13 | V44: 3.6 | W44: 5 | Y44: 0 | Z44: 0 | AA44: 15.5 | AB44: 0.155 | AC44: 5 | AD44: 4 | AF44: 1 | AG44: 0 | AH44: 11 | AI44: 0.11 | AJ44: 4.1 | AK44: 5 | AM44: 0 | AN44: 0 | AO44: 13 | AP44: 0.13 | AQ44: 3 | AR44: 6 | AT44: 0 | AU44: 0 | AV44: 0 | AW44: 0 | AX44: 0 | AY44: 0 | AZ44: 0.85833333 | BA44: 0.355 | BB44: 1.2133333 | BC44: 92.92979 | BD44: 38.435039 | BE44: 0 | BF44: 0 | BG44: 131.36483 | BH44: 0.13404849
A45: 2003 | B45: 153 | C45: 37774 | D45: p204-S02 | E45: 6 | F45: 15.5 | G45: 0.155 | H45: 3.8 | I45: 5 | K45: 2 | L45: 0 | M45: 16 | N45: 0.16 | O45: 4.1 | P45: 4 | R45: 1 | S45: 0 | T45: 17 | U45: 0.17 | V45: 4.3 | W45: 4 | Y45: 1 | Z45: 0 | AA45: 14 | AB45: 0.14 | AC45: 4.5 | AD45: 4 | AF45: 1 | AG45: 0 | AH45: 8 | AI45: 0.08 | AJ45: 3 | AK45: 4 | AM45: 0 | AN45: 0 | AO45: 16 | AP45: 0.16 | AQ45: 3.7 | AR45: 4 | AT45: 1 | AU45: 0 | AV45: 0 | AW45: 0 | AX45: 0 | AY45: 0 | AZ45: 0.94166667 | BA45: 0.45166667 | BB45: 1.3933333 | BC45: 227.67586 | BD45: 109.20382 | BE45: 0 | BF45: 0 | BG45: 336.87968 | BH45: 0.34506445
A46: 2003 | B46: 153 | C46: 37774 | D46: p205-S02 | E46: 6 | F46: 14 | G46: 0.14 | H46: 4.4 | I46: 4 | K46: 0 | L46: 0 | M46: 14 | N46: 0.14 | O46: 4.4 | P46: 4 | R46: 1 | S46: 0 | T46: 10 | U46: 0.1 | V46: 3.5 | W46: 4 | Y46: 0 | Z46: 0 | AA46: 13 | AB46: 0.13 | AC46: 3.7 | AD46: 6 | AF46: 1 | AG46: 0 | AH46: 10.5 | AI46: 0.105 | AJ46: 3.9 | AK46: 4 | AM46: 0 | AN46: 0 | AO46: 9.5 | AP46: 0.095 | AQ46: 3.4 | AR46: 3 | AT46: 1 | AU46: 0 | AV46: 0 | AW46: 0 | AX46: 0 | AY46: 0 | AZ46: 0.77666667 | BA46: 0.27666667 | BB46: 1.0533333 | BC46: 38.221785 | BD46: 13.615486 | BE46: 0 | BF46: 0 | BG46: 51.83727 | BH46: 0.05129711
A47: 2003 | B47: 153 | C47: 37774 | D47: p206-S02 | E47: 6 | F47: 14 | G47: 0.14 | H47: 4.4 | I47: 6 | K47: 1 | L47: 0 | M47: 12 | N47: 0.12 | O47: 4.2 | P47: 3 | R47: 1 | S47: 0 | T47: 11 | U47: 0.11 | V47: 3.6 | W47: 3 | Y47: 1 | Z47: 0 | AA47: 15 | AB47: 0.15 | AC47: 4.8 | AD47: 5 | AF47: 1 | AG47: 0 | AH47: 13 | AI47: 0.13 | AJ47: 4.2 | AK47: 4 | AM47: 1 | AN47: 0 | AO47: 18 | AP47: 0.18 | AQ47: 5.7 | AR47: 8 | AT47: 3 | AU47: 0 | AV47: 0 | AW47: 0 | AX47: 0 | AY47: 0 | AZ47: 0.97 | BA47: 0.475 | BB47: 1.445 | BC47: 49.924131 | BD47: 24.447384 | BE47: 0 | BF47: 0 | BG47: 74.371514 | BH47: 0.062931835
A48: 2003 | B48: 153 | C48: 37774 | D48: p207-S02 | E48: 4 | F48: 14.4 | G48: 0.144 | H48: 4.2 | I48: 5 | K48: 0 | L48: 0 | M48: 19.5 | N48: 0.195 | O48: 4.6 | P48: 4 | R48: 2 | S48: 0 | T48: 15 | U48: 0.15 | V48: 4.6 | W48: 4 | Y48: 1 | Z48: 0 | AA48: 12 | AB48: 0.12 | AC48: 3.7 | AD48: 2 | AF48: 2 | AG48: 0 | AV48: 0 | AW48: 0 | AX48: 0 | AY48: 0 | AZ48: 0.91 | BA48: 0.4775 | BB48: 1.3875 | BC48: 107.48031 | BD48: 56.397638 | BE48: 0 | BF48: 0 | BG48: 163.87795 | BH48: 0.14382028
A49: 2003 | B49: 153 | C49: 37774 | D49: p208-S02 | E49: 6 | F49: 12 | G49: 0.12 | H49: 3.6 | I49: 6 | K49: 0 | L49: 0 | M49: 14 | N49: 0.14 | O49: 4.8 | P49: 4 | R49: 2 | S49: 0 | T49: 8 | U49: 0.08 | V49: 3 | W49: 2 | Y49: 0 | Z49: 0 | AA49: 11 | AB49: 0.11 | AC49: 3.9 | AD49: 4 | AF49: 0 | AG49: 0 | AH49: 12 | AI49: 0.12 | AJ49: 3.6 | AK49: 5 | AM49: 0 | AN49: 0 | AO49: 9 | AP49: 0.09 | AQ49: 3.1 | AR49: 3 | AT49: 0 | AU49: 0 | AV49: 0 | AW49: 0 | AX49: 0 | AY49: 0 | AZ49: 0.625 | BA49: 0.27833333 | BB49: 0.90333333 | BC49: 30.886032 | BD49: 13.75458 | BE49: 0 | BF49: 0 | BG49: 44.640611 | BH49: 0.039541061
A50: 2003 | B50: 153 | C50: 37774 | D50: p301-S02 | E50: 6 | F50: 16 | G50: 0.16 | H50: 4.3 | I50: 4 | K50: 1 | L50: 0 | M50: 13 | N50: 0.13 | O50: 4.4 | P50: 4 | R50: 2 | S50: 0 | T50: 16.5 | U50: 0.165 | V50: 4.5 | W50: 6 | Y50: 3 | Z50: 0 | AA50: 17 | AB50: 0.17 | AC50: 3.7 | AD50: 2 | AF50: 2 | AG50: 0 | AH50: 18 | AI50: 0.18 | AJ50: 4.6 | AK50: 7 | AL50: 5 | AM50: 1 | AN50: 0 | AO50: 10 | AP50: 0.1 | AQ50: 3.4 | AR50: 4 | AT50: 1 | AU50: 0 | AV50: 0.16666667 | AW50: 0 | AX50: 0 | AY50: 0 | AZ50: 0.83833333 | BA50: 0.38833333 | BB50: 1.2283333 | BC50: 92.063253 | BD50: 42.645602 | BE50: 0 | BF50: 0.18302834 | BG50: 134.89188 | BH50: 0.16118494
A51: 2003 | B51: 153 | C51: 37774 | D51: p302-S02 | E51: 6 | F51: 13.5 | G51: 0.135 | H51: 4.7 | I51: 4 | K51: 1 | L51: 0 | M51: 14 | N51: 0.14 | O51: 4.5 | P51: 6 | R51: 2 | S51: 0 | T51: 8 | U51: 0.08 | V51: 3.4 | W51: 2 | Y51: 1 | Z51: 0 | AA51: 12.5 | AB51: 0.125 | AC51: 3.7 | AD51: 5 | AF51: 0 | AG51: 0 | AH51: 15.5 | AI51: 0.155 | AJ51: 4.7 | AK51: 6 | AM51: 2 | AN51: 0 | AO51: 16.5 | AP51: 0.165 | AQ51: 5 | AR51: 5 | AT51: 1 | AU51: 0 | AV51: 0 | AW51: 0 | AX51: 0 | AY51: 0 | AZ51: 0.90666667 | BA51: 0.41 | BB51: 1.3166667 | BC51: 104.27724 | BD51: 47.154783 | BE51: 0 | BF51: 0 | BG51: 151.43203 | BH51: 0.1624859
A52: 2003 | B52: 153 | C52: 37774 | D52: p303-S02 | E52: 6 | F52: 13.5 | G52: 0.135 | H52: 4.2 | I52: 5 | K52: 5 | L52: 0 | M52: 14 | N52: 0.14 | O52: 4.7 | P52: 4 | R52: 2 | S52: 0 | T52: 16 | U52: 0.16 | V52: 5.2 | W52: 7 | Y52: 3 | Z52: 0 | AA52: 11 | AB52: 0.11 | AC52: 3.7 | AD52: 3 | AF52: 1 | AG52: 0 | AH52: 11.5 | AI52: 0.115 | AJ52: 3.7 | AK52: 5 | AM52: 0 | AN52: 0 | AO52: 11 | AP52: 0.11 | AQ52: 3.4 | AR52: 3 | AT52: 1 | AU52: 0 | AV52: 0 | AW52: 0 | AX52: 0 | AY52: 0 | AZ52: 0.92166667 | BA52: 0.395 | BB52: 1.3166667 | BC52: 48.759432 | BD52: 20.8969 | BE52: 0 | BF52: 0 | BG52: 69.656332 | BH52: 0.076416662
A53: 2003 | B53: 153 | C53: 37774 | D53: p304-S02 | E53: 6 | F53: 14 | G53: 0.14 | H53: 4.7 | I53: 3 | K53: 2 | L53: 0 | M53: 8 | N53: 0.08 | O53: 3 | P53: 4 | R53: 1 | S53: 0 | T53: 12.5 | U53: 0.125 | V53: 4.2 | W53: 7 | Y53: 1 | Z53: 0 | AA53: 11.5 | AB53: 0.115 | AC53: 4.3 | AD53: 3 | AF53: 3 | AG53: 0 | AH53: 14 | AI53: 0.14 | AJ53: 4.5 | AK53: 7 | AM53: 2 | AN53: 0 | AO53: 15 | AP53: 0.15 | AQ53: 4.7 | AR53: 5 | AT53: 5 | AU53: 0 | AV53: 0 | AW53: 0 | AX53: 0 | AY53: 0 | AZ53: 0.95166667 | BA53: 0.39166667 | BB53: 1.3433333 | BC53: 48.395122 | BD53: 19.917432 | BE53: 0 | BF53: 0 | BG53: 68.312555 | BH53: 0.065275997
A54: 2003 | B54: 153 | C54: 37774 | D54: p305-S02 | E54: 6 | F54: 17 | G54: 0.17 | H54: 4.2 | I54: 7 | K54: 1 | L54: 0 | M54: 16 | N54: 0.16 | O54: 4 | P54: 7 | R54: 4 | S54: 0 | T54: 18 | U54: 0.18 | V54: 4.5 | W54: 5 | Y54: 1 | Z54: 0 | AA54: 17 | AB54: 0.17 | AC54: 4.2 | AD54: 4 | AF54: 1 | AG54: 0 | AH54: 17 | AI54: 0.17 | AJ54: 4.5 | AK54: 3 | AM54: 2 | AN54: 0 | AO54: 10.5 | AP54: 0.105 | AQ54: 3.2 | AR54: 3 | AT54: 1 | AU54: 0 | AV54: 0 | AW54: 0 | AX54: 0 | AY54: 0 | AZ54: 1.0383333 | BA54: 0.42666667 | BB54: 1.465 | BC54: 258.33424 | BD54: 106.1534 | BE54: 0 | BF54: 0 | BG54: 364.48764 | BH54: 0.35232298
A55: 2003 | B55: 153 | C55: 37774 | D55: p306-S02 | E55: 6 | F55: 14 | G55: 0.14 | H55: 4.7 | I55: 3 | K55: 1 | L55: 0 | M55: 12 | N55: 0.12 | O55: 5 | P55: 3 | R55: 1 | S55: 0 | T55: 15.5 | U55: 0.155 | V55: 4.4 | W55: 4 | Y55: 2 | Z55: 0 | AA55: 16 | AB55: 0.16 | AC55: 4.6 | AD55: 5 | AF55: 4 | AG55: 0 | AH55: 15 | AI55: 0.15 | AJ55: 4.5 | AK55: 6 | AM55: 0 | AN55: 0 | AO55: 14 | AP55: 0.14 | AQ55: 4.1 | AR55: 4 | AT55: 2 | AU55: 0 | AV55: 0 | AW55: 0 | AX55: 0 | AY55: 0 | AZ55: 0.96666667 | BA55: 0.41666667 | BB55: 1.3833333 | BC55: 119.01854 | BD55: 51.301096 | BE55: 0 | BF55: 0 | BG55: 170.31964 | BH55: 0.19755726
A56: 2003 | B56: 153 | C56: 37774 | D56: p307-S02 | E56: 6 | F56: 15.5 | G56: 0.155 | H56: 4.1 | I56: 7 | K56: 4 | L56: 0 | M56: 12 | N56: 0.12 | O56: 3.3 | P56: 3 | R56: 1 | S56: 0 | T56: 16 | U56: 0.16 | V56: 4.9 | W56: 6 | Y56: 2 | Z56: 0 | AA56: 14 | AB56: 0.14 | AC56: 4.6 | AD56: 5 | AF56: 2 | AG56: 0 | AH56: 13 | AI56: 0.13 | AJ56: 3.9 | AK56: 4 | AM56: 2 | AN56: 0 | AO56: 12 | AP56: 0.12 | AQ56: 3.7 | AR56: 6 | AT56: 0 | AU56: 0 | AV56: 0 | AW56: 0 | AX56: 0 | AY56: 0 | AZ56: 0.96166667 | BA56: 0.43 | BB56: 1.3916667 | BC56: 111.56694 | BD56: 49.886082 | BE56: 0 | BF56: 0 | BG56: 161.45302 | BH56: 0.17590007
A57: 2003 | B57: 153 | C57: 37774 | D57: p308-S02 | E57: 6 | F57: 12 | G57: 0.12 | H57: 3.1 | I57: 5 | K57: 0 | L57: 0 | M57: 9.5 | N57: 0.095 | O57: 2.7 | P57: 5 | R57: 0 | S57: 0 | T57: 17 | U57: 0.17 | V57: 4.7 | W57: 5 | Y57: 3 | Z57: 0 | AA57: 13 | AB57: 0.13 | AC57: 3.7 | AD57: 4 | AF57: 2 | AG57: 0 | AH57: 14.5 | AI57: 0.145 | AJ57: 4 | AK57: 3 | AM57: 1 | AN57: 0 | AO57: 19 | AP57: 0.19 | AQ57: 5.2 | AR57: 8 | AS57: 6 | AT57: 1 | AU57: 0 | AV57: 0.16666667 | AW57: 0 | AX57: 0 | AY57: 0 | AZ57: 0.9 | BA57: 0.455 | BB57: 1.3566667 | BC57: 204.72441 | BD57: 103.49956 | BE57: 0 | BF57: 0.37911928 | BG57: 308.60309 | BH57: 0.32110421
A58: 2003 | B58: 153 | C58: 37774 | D58: p401-S02 | E58: 5 | F58: 8 | G58: 0.08 | H58: 2.9 | I58: 2 | K58: 0 | L58: 0 | M58: 10.5 | N58: 0.105 | O58: 3.1 | P58: 4 | R58: 0 | S58: 0 | T58: 11.5 | U58: 0.115 | V58: 3.5 | W58: 3 | Y58: 2 | Z58: 0 | AA58: 10.5 | AB58: 0.105 | AC58: 3 | AD58: 4 | AF58: 0 | AG58: 0 | AH58: 13.5 | AI58: 0.135 | AJ58: 4.4 | AK58: 5 | AM58: 1 | AN58: 0 | AV58: 0 | AW58: 0 | AX58: 0 | AY58: 0 | AZ58: 0.658 | BA58: 0.236 | BB58: 0.894 | BC58: 31.572343 | BD58: 11.323819 | BE58: 0 | BF58: 0 | BG58: 42.896161 | BH58: 0.041044045
A59: 2003 | B59: 153 | C59: 37774 | D59: p402-S02 | E59: 6 | F59: 11.5 | G59: 0.115 | H59: 3.7 | I59: 3 | K59: 1 | L59: 0 | M59: 10 | N59: 0.1 | O59: 3.9 | P59: 3 | R59: 1 | S59: 0 | T59: 18 | U59: 0.18 | V59: 5.1 | W59: 9 | Y59: 4 | Z59: 0 | AA59: 10 | AB59: 0.1 | AC59: 3.6 | AD59: 2 | AF59: 2 | AG59: 0 | AH59: 12.5 | AI59: 0.125 | AJ59: 3.2 | AK59: 3 | AM59: 1 | AN59: 0 | AO59: 6.5 | AP59: 0.065 | AQ59: 3.8 | AR59: 2 | AT59: 1 | AU59: 0 | AV59: 0 | AW59: 0 | AX59: 0 | AY59: 0 | AZ59: 0.79833333 | BA59: 0.295 | BB59: 1.0933333 | BC59: 90.144266 | BD59: 33.310094 | BE59: 0 | BF59: 0 | BG59: 123.45436 | BH59: 0.13866764
A60: 2003 | B60: 153 | C60: 37774 | D60: p403-S02 | E60: 6 | F60: 21 | G60: 0.21 | H60: 4.9 | I60: 7 | K60: 1 | L60: 0 | M60: 12 | N60: 0.12 | O60: 4.4 | P60: 2 | R60: 2 | S60: 0 | T60: 13.5 | U60: 0.135 | V60: 4.1 | W60: 3 | Y60: 2 | Z60: 0 | AA60: 12 | AB60: 0.12 | AC60: 4.5 | AD60: 3 | AF60: 2 | AG60: 0 | AH60: 14.5 | AI60: 0.145 | AJ60: 4.2 | AK60: 6 | AM60: 0 | AN60: 0 | AO60: 16 | AP60: 0.16 | AQ60: 4.8 | AR60: 5 | AT60: 2 | AU60: 0 | AV60: 0 | AW60: 0 | AX60: 0 | AY60: 0 | AZ60: 1.11 | BA60: 0.43166667 | BB60: 1.5416667 | BC60: 244.19838 | BD60: 94.966037 | BE60: 0 | BF60: 0 | BG60: 339.16442 | BH60: 0.33379393
A61: 2003 | B61: 153 | C61: 37774 | D61: p404-S02 | E61: 6 | F61: 17 | G61: 0.17 | H61: 4.3 | I61: 6 | K61: 4 | L61: 0 | M61: 11.5 | N61: 0.115 | O61: 3.4 | P61: 3 | R61: 0 | S61: 0 | T61: 9 | U61: 0.09 | V61: 3.6 | W61: 2 | Y61: 1 | Z61: 0 | AA61: 13 | AB61: 0.13 | AC61: 4 | AD61: 6 | AF61: 1 | AG61: 0 | AH61: 12 | AI61: 0.12 | AJ61: 3.7 | AK61: 5 | AM61: 2 | AN61: 0 | AO61: 9.5 | AP61: 0.095 | AQ61: 3 | AR61: 3 | AT61: 1 | AU61: 0 | AV61: 0 | AW61: 0 | AX61: 0 | AY61: 0 | AZ61: 0.725 | BA61: 0.28833333 | BB61: 1.0133333 | BC61: 78.09766 | BD61: 31.059529 | BE61: 0 | BF61: 0 | BG61: 109.15719 | BH61: 0.10946689
A62: 2003 | B62: 153 | C62: 37774 | D62: p405-S02 | E62: 6 | F62: 18.5 | G62: 0.185 | H62: 4.3 | I62: 7 | K62: 2 | L62: 0 | M62: 11.5 | N62: 0.115 | O62: 3.6 | P62: 3 | R62: 2 | S62: 0 | T62: 9 | U62: 0.09 | V62: 4.9 | W62: 8 | Y62: 3 | Z62: 0 | AA62: 10.5 | AB62: 0.105 | AC62: 3.8 | AD62: 4 | AF62: 2 | AG62: 0 | AH62: 11 | AI62: 0.11 | AJ62: 3.8 | AK62: 3 | AM62: 2 | AN62: 0 | AO62: 13 | AP62: 0.13 | AQ62: 3.8 | AR62: 4 | AT62: 2 | AU62: 0 | AV62: 0 | AW62: 0 | AX62: 0 | AY62: 0 | AZ62: 0.98 | BA62: 0.44666667 | BB62: 1.4266667 | BC62: 231.0495 | BD62: 105.30828 | BE62: 0 | BF62: 0 | BG62: 336.35778 | BH62: 0.33777816
...

Sheet d147Data100
A1: FISE2003GrowthDOYXXX.xls | G1: Cotton Growth & Development Data for Field 105
A3: Sampling Date: | D3: 37768 | H3: Sampling Time: | I3: 7:45 to 9:45 | M3: Data entered by: | N3: Stacy
A5: Sampling DOY: | D5: =VALUE(D3-37621) -> 147 | E5: =VALUE(F5)-37621 -> -37621 | H5: Sampled By: | I5: stacy | M5: Data proofed by: | N5: Carrie
A7: Comments: | D7: First sampling.Plants are small and weird.Lots of forked plants (2 or more main stems).
B11: Plot | C11: Plant | D11: Initials | E11: DOY Wet Process | F11: Leaf area of Subsmple | G11: Stem Diameter (mm) | H11: Abvegrnd Height (cm) | I11: Tap Root Length (cm) | J11: MS Node of First Fruit Branch | K11: No. of MS Nodes | L11: No. of Veg. Branches | M11: No. nodes on Veg. Branches | N11: Abscisions in reference positions | O11: No. of Squares | P11: No. of White Flowers | Q11: No. of Green Bolls | R11: No. of Mature Bolls | S11: Codes | T11: DOY into Oven | U11: DOY out of Oven | V11: Oven Temp (°C) | W11: Leaf Ssample BM | X11: Remainder Leaf BM | Y11: Square BM | Z11: Flwr & GBoll BM | AA11: Mature Boll BM | AB11: Seed Cotton BM | AC11: StemBM | AD11: Tap Root BM | AF11: NumPlts | AG11: Height | AH11: PHTD1 | AI11: STDD1 | AJ11: MSNODE1 | AK11: PFNODE1 | AL11: VBNUM1 | AM11: VBNODE1 | AN11: Height | AO11: PHTD2 | AP11: STDD2 | AQ11: MSNODE2 | AR11: PFNODE2 | AS11: VBNUM2 | AT11: VBNODE2 | AU11: Height | AV11: PHTD3 | AW11: STDD3 | AX11: MSNODE3 | AY11: PFNODE3 | AZ11: VBNUM3 | BA11: VBNODE3 | BB11: Height | BC11: PHTD4 | BD11: STDD4 | BE11: MSNODE4 | BF11: PFNODE4 | BG11: VBNUM4 | BH11: VBNODE4 | BI11: Height | BJ11: PHTD5 | BK11: STDD5 | BL11: MSNODE5 | BM11: PFNODE5 | BN11: VBNUM5 | BO11: VBNODE5 | BP11: Height | BQ11: PHTD6 | BR11: STDD56 | BS11: MSNODE6 | BT11: PFNODE6 | BU11: VBNUM6 | BV11: VBNODE6 | BW11: SQRNUM | BX11: FLRNUM | BY11: GBNUM | BZ11: MBNUM
B13: 101 | C13: A | D13: sr | E13: 147 | F13: 46.96 | G13: 3 | H13: 6.5 | I13: 5.5 | K13: 2 | L13: 1 | M13: 0 | N13: 0 | O13: 0 | P13: 0 | Q13: 0 | R13: 0 | T13: 147 | U13: 150 | V13: 100 | W13: 0.33 | X13: 1.82 | AC13: 0.7 | AD13: 0.24 | AF13: 6 | AG13: =IF($H13="","",$H13) -> 6.5 | AH13: =IF(AG13="","",AG13/100) -> 0.065 | AI13: =IF($G13="","",$G13) -> 3 | AJ13: =IF($K13="","",$K13) -> 2 | AK13: =IF(J13="","",J13-1) | AL13: =IF($L13="","",$L13) -> 1 | AM13: =IF($M13="","",$M13) -> 0 | AN13: =IF($H14="","",$H14) -> 5.5 | AO13: =IF(AN13="","",AN13/100) -> 0.055 | AP13: =IF($G14="","",$G14) -> 2.8 | AQ13: =IF($K14="","",$K14) -> 3 | AR13: =IF(J14="","",J14-1) | AS13: =IF($L14="","",$L14) -> 0 | AT13: =IF($M14="","",$M14) -> 0 | AU13: =IF($H15="","",$H15) -> 15 | AV13: =IF(AU13="","",AU13/100) -> 0.15 | AW13: =IF($G15="","",$G15) -> 3.6 | AX13: =IF($K15="","",$K15) -> 5 | AY13: =IF(J15="","",J15-1) | AZ13: =IF($L15="","",$L15) -> 0 | BA13: =IF($M15="","",$M15) -> 0 | BB13: =IF($H16="","",$H16) -> 5 | BC13: =IF(BB13="","",BB13/100) -> 0.05 | BD13: =IF($G16="","",$G16) -> 2.4 | BE13: =IF($K16="","",$K16) -> 1 | BF13: =IF(J16="","",J16-1) | BG13: =IF($L16="","",$L16) -> 0 | BH13: =IF($M16="","",$M16) -> 0 | BI13: =IF($H17="","",$H17) -> 8.5 | BJ13: =IF(BI13="","",BI13/100) -> 0.085 | BK13: =IF($G17="","",$G17) -> 3 | BL13: =IF($K17="","",$K17) -> 2 | BM13: =IF(J17="","",J17-1) | BN13: =IF($L17="","",$L17) -> 1 | BO13: =IF($M17="","",$M17) -> 0 | BP13: =IF($H18="","",$H18) -> 6 | BQ13: =IF(BP13="","",BP13/100) -> 0.06 | BR13: =IF($G18="","",$G18) -> 2.2 | BS13: =IF($K18="","",$K18) -> 1 | BT13: =IF(J18="","",J18-1) | BU13: =IF($L18="","",$L18) -> 1 | BV13: =IF($M18="","",$M18) -> 0 | BW13: =SUM(O13:O18)/AF13 -> 0 | BX13: =SUM(P13:P18)/AF13 -> 0 | BY13: =SUM(Q13:Q18)/AF13 -> 0 | BZ13: =SUM(R13:R18)/AF13 -> 0
C14: B | E14: 148 | G14: 2.8 | H14: 5.5 | I14: 6 | K14: 3 | L14: 0 | M14: 0 | N14: 0 | O14: 0 | P14: 0 | Q14: 0 | R14: 0 | T14: 148 | U14: 150 | V14: 100
C15: C | D15: =D14 -> 0 | E15: =E14 -> 148 | G15: 3.6 | H15: 15 | I15: 12 | K15: 5 | L15: 0 | M15: 0 | N15: 0 | O15: 0 | P15: 0 | Q15: 0 | R15: 0 | T15: 148 | U15: 150 | V15: 100
C16: D | D16: =D15 -> 0 | E16: =E15 -> 148 | G16: 2.4 | H16: 5 | I16: 6.5 | K16: 1 | L16: 0 | M16: 0 | N16: 0 | O16: 0 | P16: 0 | Q16: 0 | R16: 0 | T16: 148 | U16: 150 | V16: 100
C17: E | D17: =D16 -> 0 | E17: =E16 -> 148 | G17: 3 | H17: 8.5 | I17: 10.5 | K17: 2 | L17: 1 | M17: 0 | N17: 0 | O17: 0 | P17: 0 | Q17: 0 | R17: 0 | T17: 148 | U17: 150 | V17: 100
C18: F | D18: =D17 -> 0 | E18: =E17 -> 148 | G18: 2.2 | H18: 6 | I18: 4 | K18: 1 | L18: 1 | M18: 0 | N18: 0 | O18: 0 | P18: 0 | Q18: 0 | R18: 0 | T18: 148 | U18: 150 | V18: 100
B20: FSH | C20: mean | E20: =AVERAGE(E14:E18) -> 148 | F20: =F13 -> 46.96 | G20: =AVERAGE(G13:G18) -> 2.8333333 | H20: =AVERAGE(H13:H18) -> 7.75 | I20: =AVERAGE(I13:I18) -> 7.4166667 | J20: =AVERAGE(J13:J18) -> #DIV/0! | K20: =AVERAGE(K13:K18) -> 2.3333333 | L20: =AVERAGE(L13:L18) -> 0.5 | M20: =AVERAGE(M13:M18) -> 0 | N20: =AVERAGE(N13:N18) -> 0 | ... R20: =AVERAGE(R13:R18) -> 0
C21: std err | G21: =STDEV(G13:G18)/SQRT(COUNT(G13:G18)) -> 0.20275875 | H21: =STDEV(H13:H18)/SQRT(COUNT(H13:H18)) -> 1.5316114 | I21: =STDEV(I13:I18)/SQRT(COUNT(I13:I18)) -> 1.27421 | J21: =STDEV(J13:J18)/SQRT(COUNT(J13:J18)) -> #DIV/0! | K21: =STDEV(K13:K18)/SQRT(COUNT(K13:K18)) -> 0.6146363 | L21: =STDEV(L13:L18)/SQRT(COUNT(L13:L18)) -> 0.2236068 | M21: =STDEV(M13:M18)/SQRT(COUNT(M13:M18)) -> 0 | N21: =STDEV(N13:N18)/SQRT(COUNT(N13:N18)) -> 0 | ... R21: =STDEV(R13:R18)/SQRT(COUNT(R13:R18)) -> 0
B23: 102 | C23: A | E23: 147 | F23: 52 | G23: 2.5 | H23: 7 | I23: 9 | K23: 2 | L23: 2 | M23: 0 | N23: 0 | O23: 0 | P23: 0 | Q23: 0 | R23: 0 | T23: 147 | U23: 150 | V23: 100 | W23: 0.37 | X23: 0.86 | AC23: 0.55 | AD23: 0.16 | AF23: 6 | AG23: =IF($H23="","",$H23) -> 7 | AH23: =IF(AG23="","",AG23/100) -> 0.07 | AI23: =IF($G23="","",$G23) -> 2.5 | AJ23: =IF($K23="","",$K23) -> 2 | AK23: =IF(J23="","",J23-1) | AL23: =IF($L23="","",$L23) -> 2 | AM23: =IF($M23="","",$M23) -> 0 | AN23: =IF($H24="","",$H24) -> 9 | AO23: =IF(AN23="","",AN23/100) -> 0.09 | AP23: =IF($G24="","",$G24) -> 3.1 | AQ23: =IF($K24="","",$K24) -> 4 | AR23: =IF(J24="","",J24-1) | AS23: =IF($L24="","",$L24) -> 0 | AT23: =IF($M24="","",$M24) -> 0 | AU23: =IF($H25="","",$H25) -> 6.5 | AV23: =IF(AU23="","",AU23/100) -> 0.065 | AW23: =IF($G25="","",$G25) -> 3.1 | AX23: =IF($K25="","",$K25) -> 0 | AY23: =IF(J25="","",J25-1) | AZ23: =IF($L25="","",$L25) -> 0 | BA23: =IF($M25="","",$M25) -> 0 | BB23: =IF($H26="","",$H26) -> 7 | BC23: =IF(BB23="","",BB23/100) -> 0.07 | BD23: =IF($G26="","",$G26) -> 2.8 | BE23: =IF($K26="","",$K26) -> 2 | BF23: =IF(J26="","",J26-1) | BG23: =IF($L26="","",$L26) -> 2 | BH23: =IF($M26="","",$M26) -> 0 | BI23: =IF($H27="","",$H27) -> 4 | BJ23: =IF(BI23="","",BI23/100) -> 0.04 | BK23: =IF($G27="","",$G27) -> 2.7 | BL23: =IF($K27="","",$K27) -> 0 | BM23: =IF(J27="","",J27-1) | BN23: =IF($L27="","",$L27) -> 0 | BO23: =IF($M27="","",$M27) -> 0 | BP23: =IF($H28="","",$H28) -> 4.5 | BQ23: =IF(BP23="","",BP23/100) -> 0.045 | BR23: =IF($G28="","",$G28) -> 2.5 | BS23: =IF($K28="","",$K28) -> 0 | BT23: =IF(J28="","",J28-1) | BU23: =IF($L28="","",$L28) -> 0 | BV23: =IF($M28="","",$M28) -> 0 | BW23: =SUM(O23:O28)/AF23 -> 0 | BX23: =SUM(P23:P28)/AF23 -> 0 | BY23: =SUM(Q23:Q28)/AF23 -> 0 | BZ23: =SUM(R23:R28)/AF23 -> 0
C24: B | E24: 148 | G24: 3.1 | H24: 9 | I24: 5.5 | K24: 4 | L24: 0 | M24: 0 | N24: 0 | O24: 0 | P24: 0 | Q24: 0 | R24: 0 | T24: 148 | U24: 150 | V24: 100
C25: C | D25: =D24 -> 0 | E25: =E24 -> 148 | G25: 3.1 | H25: 6.5 | I25: 5 | K25: 0 | L25: 0 | M25: 0 | N25: 0 | O25: 0 | P25: 0 | Q25: 0 | R25: 0 | T25: 148 | U25: 150 | V25: 100
C26: D | D26: =D25 -> 0 | E26: =E25 -> 148 | G26: 2.8 | H26: 7 | I26: 5 | K26: 2 | L26: 2 | M26: 0 | N26: 0 | O26: 0 | P26: 0 | Q26: 0 | R26: 0 | T26: 148 | U26: 150 | V26: 100
C27: E | D27: =D26 -> 0 | E27: =E26 -> 148 | G27: 2.7 | H27: 4 | I27: 3 | K27: 0 | L27: 0 | M27: 0 | N27: 0 | O27: 0 | P27: 0 | Q27: 0 | R27: 0 | S27: cotyledon | T27: 148 | U27: 150 | V27: 100
C28: F | D28: =D27 -> 0 | E28: =E27 -> 148 | G28: 2.5 | H28: 4.5 | I28: 5 | K28: 0 | L28: 0 | M28: 0 | N28: 0 | O28: 0 | P28: 0 | Q28: 0 | R28: 0 | S28: cotyledon | T28: 148 | U28: 150 | V28: 100
B30: FTL | C30: mean | E30: =AVERAGE(E24:E28) -> 148 | F30: =F23 -> 52 | G30: =AVERAGE(G23:G28) -> 2.7833333 | H30: =AVERAGE(H23:H28) -> 6.3333333 | I30: =AVERAGE(I23:I28) -> 5.4166667 | J30: =AVERAGE(J23:J28) -> #DIV/0! | K30: =AVERAGE(K23:K28) -> 1.3333333 | L30: =AVERAGE(L23:L28) -> 0.66666667 | M30: =AVERAGE(M23:M28) -> 0 | N30: =AVERAGE(N23:N28) -> 0 | ... R30: =AVERAGE(R23:R28) -> 0
C31: std err | G31: =STDEV(G23:G28)/SQRT(COUNT(G23:G28)) -> 0.11080513 | H31: =STDEV(H23:H28)/SQRT(COUNT(H23:H28)) -> 0.7490735 | I31: =STDEV(I23:I28)/SQRT(COUNT(I23:I28)) -> 0.80017359 | J31: =STDEV(J23:J28)/SQRT(COUNT(J23:J28)) -> #DIV/0! | K31: =STDEV(K23:K28)/SQRT(COUNT(K23:K28)) -> 0.66666667 | L31: =STDEV(L23:L28)/SQRT(COUNT(L23:L28)) -> 0.42163702 | M31: =STDEV(M23:M28)/SQRT(COUNT(M23:M28)) -> 0 | N31: =STDEV(N23:N28)/SQRT(COUNT(N23:N28)) -> 0 | ... R31: =STDEV(R23:R28)/SQRT(COUNT(R23:R28)) -> 0
B33: 103 | C33: A | E33: 147 | F33: 60.6 | G33: 2.7 | H33: 10 | I33: 6 | K33: 4 | L33: 0 | M33: 0 | N33: 0 | O33: 0 | P33: 0 | Q33: 0 | R33: 0 | T33: 147 | U33: 150 | V33: 100 | W33: 0.41 | X33: 1.98 | AC33: 0.96 | AD33: 0.34 | AF33: 6 | AG33: =IF($H33="","",$H33) -> 10 | AH33: =IF(AG33="","",AG33/100) -> 0.1 | AI33: =IF($G33="","",$G33) -> 2.7 | AJ33: =IF($K33="","",$K33) -> 4 | AK33: =IF(J33="","",J33-1) | AL33: =IF($L33="","",$L33) -> 0 | AM33: =IF($M33="","",$M33) -> 0 | AN33: =IF($H34="","",$H34) -> 9.5 | AO33: =IF(AN33="","",AN33/100) -> 0.095 | AP33: =IF($G34="","",$G34) -> 2.8 | AQ33: =IF($K34="","",$K34) -> 4 | AR33: =IF(J34="","",J34-1) | AS33: =IF($L34="","",$L34) -> 0 | AT33: =IF($M34="","",$M34) -> 0 | AU33: =IF($H35="","",$H35) -> 10 | AV33: =IF(AU33="","",AU33/100) -> 0.1 | AW33: =IF($G35="","",$G35) -> 3.1 | AX33: =IF($K35="","",$K35) -> 2 | AY33: =IF(J35="","",J35-1) | AZ33: =IF($L35="","",$L35) -> 0 | BA33: =IF($M35="","",$M35) -> 0 | BB33: =IF($H36="","",$H36) -> 12 | BC33: =IF(BB33="","",BB33/100) -> 0.12 | BD33: =IF($G36="","",$G36) -> 3.3 | BE33: =IF($K36="","",$K36) -> 5 | BF33: =IF(J36="","",J36-1) | BG33: =IF($L36="","",$L36) -> 0 | BH33: =IF($M36="","",$M36) -> 0 | BI33: =IF($H37="","",$H37) -> 10.5 | BJ33: =IF(BI33="","",BI33/100) -> 0.105 | BK33: =IF($G37="","",$G37) -> 3.1 | BL33: =IF($K37="","",$K37) -> 4 | BM33: =IF(J37="","",J37-1) | BN33: =IF($L37="","",$L37) -> 0 | BO33: =IF($M37="","",$M37) -> 0 | BP33: =IF($H38="","",$H38) -> 11 | BQ33: =IF(BP33="","",BP33/100) -> 0.11 | BR33: =IF($G38="","",$G38) -> 3 | BS33: =IF($K38="","",$K38) -> 3 | BT33: =IF(J38="","",J38-1) | BU33: =IF($L38="","",$L38) -> 0 | BV33: =IF($M38="","",$M38) -> 0 | BW33: =SUM(O33:O38)/AF33 -> 0 | BX33: =SUM(P33:P38)/AF33 -> 0 | BY33: =SUM(Q33:Q38)/AF33 -> 0 | BZ33: =SUM(R33:R38)/AF33 -> 0
C34: B | E34: 148 | G34: 2.8 | H34: 9.5 | I34: 9 | K34: 4 | L34: 0 | M34: 0 | N34: 0 | O34: 0 | P34: 0 | Q34: 0 | R34: 0 | T34: 148 | U34: 150 | V34: 100
C35: C | D35: =D34 -> 0 | E35: =E34 -> 148 | G35: 3.1 | H35: 10 | I35: 3.5 | K35: 2 | L35: 0 | M35: 0 | N35: 0 | O35: 0 | P35: 0 | Q35: 0 | R35: 0 | T35: 148 | U35: 150 | V35: 100
C36: D | D36: =D35 -> 0 | E36: =E35 -> 148 | G36: 3.3 | H36: 12 | I36: 14 | K36: 5 | L36: 0 | M36: 0 | N36: 0 | O36: 0 | P36: 0 | Q36: 0 | R36: 0 | T36: 148 | U36: 150 | V36: 100
C37: E | D37: =D36 -> 0 | E37: =E36 -> 148 | G37: 3.1 | H37: 10.5 | I37: 9 | K37: 4 | L37: 0 | M37: 0 | N37: 0 | O37: 0 | P37: 0 | Q37: 0 | R37: 0 | T37: 148 | U37: 150 | V37: 100
C38: F | D38: =D37 -> 0 | E38: =E37 -> 148 | G38: 3 | H38: 11 | I38: 4 | K38: 3 | L38: 0 | M38: 0 | N38: 0 | O38: 0 | P38: 0 | Q38: 0 | R38: 0 | T38: 148 | U38: 150 | V38: 100
B40: FDH | C40: mean | E40: =AVERAGE(E34:E38) -> 148 | F40: =F33 -> 60.6 | G40: =AVERAGE(G33:G38) -> 3 | H40: =AVERAGE(H33:H38) -> 10.5 | I40: =AVERAGE(I33:I38) -> 7.5833333 | J40: =AVERAGE(J33:J38) -> #DIV/0! | K40: =AVERAGE(K33:K38) -> 3.6666667 | L40: =AVERAGE(L33:L38) -> 0 | M40: =AVERAGE(M33:M38) -> 0 | N40: =AVERAGE(N33:N38) -> 0 | ... R40: =AVERAGE(R33:R38) -> 0
C41: std err | G41: =STDEV(G33:G38)/SQRT(COUNT(G33:G38)) -> 0.089442719 | H41: =STDEV(H33:H38)/SQRT(COUNT(H33:H38)) -> 0.36514837 | I41: =STDEV(I33:I38)/SQRT(COUNT(I33:I38)) -> 1.6042478 | J41: =STDEV(J33:J38)/SQRT(COUNT(J33:J38)) -> #DIV/0! | K41: =STDEV(K33:K38)/SQRT(COUNT(K33:K38)) -> 0.42163702 | L41: =STDEV(L33:L38)/SQRT(COUNT(L33:L38)) -> 0 | M41: =STDEV(M33:M38)/SQRT(COUNT(M33:M38)) -> 0 | N41: =STDEV(N33:N38)/SQRT(COUNT(N33:N38)) -> 0 | ... R41: =STDEV(R33:R38)/SQRT(COUNT(R33:R38)) -> 0
B43: 104 | C43: A | E43: 147 | F43: 66.35 | G43: 3.8 | H43: 9.6 | I43: 6.5 | K43: 5 | L43: 1 | M43: 0 | N43: 0 | O43: 0 | P43: 0 | Q43: 0 | R43: 0 | T43: 147 | U43: 150 | V43: 100 | W43: 0.5 | X43: 2.35 | AC43: 1.04 | AD43: 0.34 | AF43: 6 | AG43: =IF($H43="","",$H43) -> 9.6 | AH43: =IF(AG43="","",AG43/100) -> 0.096 | AI43: =IF($G43="","",$G43) -> 3.8 | AJ43: =IF($K43="","",$K43) -> 5 | AK43: =IF(J43="","",J43-1) | AL43: =IF($L43="","",$L43) -> 1 | AM43: =IF($M43="","",$M43) -> 0 | AN43: =IF($H44="","",$H44) -> 8.8 | AO43: =IF(AN43="","",AN43/100) -> 0.088 | AP43: =IF($G44="","",$G44) -> 2.6 | AQ43: =IF($K44="","",$K44) -> 5 | AR43: =IF(J44="","",J44-1) | AS43: =IF($L44="","",$L44) -> 0 | AT43: =IF($M44="","",$M44) -> 0 | AU43: =IF($H45="","",$H45) -> 10.4 | AV43: =IF(AU43="","",AU43/100) -> 0.104 | AW43: =IF($G45="","",$G45) -> 3.4 | AX43: =IF($K45="","",$K45) -> 6 | AY43: =IF(J45="","",J45-1) | AZ43: =IF($L45="","",$L45) -> 1 | BA43: =IF($M45="","",$M45) -> 0 | BB43: =IF($H46="","",$H46) -> 11.4 | BC43: =IF(BB43="","",BB43/100) -> 0.114 | BD43: =IF($G46="","",$G46) -> 3 | BE43: =IF($K46="","",$K46) -> 6 | BF43: =IF(J46="","",J46-1) | BG43: =IF($L46="","",$L46) -> 0 | BH43: =IF($M46="","",$M46) -> 0 | BI43: =IF($H47="","",$H47) -> 9.8 | BJ43: =IF(BI43="","",BI43/100) -> 0.098 | BK43: =IF($G47="","",$G47) -> 2.8 | BL43: =IF($K47="","",$K47) -> 5 | BM43: =IF(J47="","",J47-1) | BN43: =IF($L47="","",$L47) -> 0 | BO43: =IF($M47="","",$M47) -> 0 | BP43: =IF($H48="","",$H48) -> 7.2 | BQ43: =IF(BP43="","",BP43/100) -> 0.072 | BR43: =IF($G48="","",$G48) -> 3 | BS43: =IF($K48="","",$K48) -> 2 | BT43: =IF(J48="","",J48-1) | BU43: =IF($L48="","",$L48) -> 2 | BV43: =IF($M48="","",$M48) -> 0 | BW43: =SUM(O43:O48)/AF43 -> 0 | BX43: =SUM(P43:P48)/AF43 -> 0 | BY43: =SUM(Q43:Q48)/AF43 -> 0 | BZ43: =SUM(R43:R48)/AF43 -> 0
C44: B | E44: 148 | G44: 2.6 | H44: 8.8 | I44: 6.4 | K44: 5 | L44: 0 | M44: 0 | N44: 0 | O44: 0 | P44: 0 | Q44: 0 | R44: 0 | T44: 148 | U44: 150 | V44: 100
C45: C | D45: =D44 -> 0 | E45: =E44 -> 148 | G45: 3.4 | H45: 10.4 | I45: 7.2 | K45: 6 | L45: 1 | M45: 0 | N45: 0 | O45: 0 | P45: 0 | Q45: 0 | R45: 0 | T45: 148 | U45: 150 | V45: 100
C46: D | D46: =D45 -> 0 | E46: =E45 -> 148 | G46: 3 | H46: 11.4 | I46: 8.9 | K46: 6 | L46: 0 | M46: 0 | N46: 0 | O46: 0 | P46: 0 | Q46: 0 | R46: 0 | T46: 148 | U46: 150 | V46: 100
C47: E | D47: =D46 -> 0 | E47: =E46 -> 148 | G47: 2.8 | H47: 9.8 | I47: 7.2 | K47: 5 | L47: 0 | M47: 0 | N47: 0 | O47: 0 | P47: 0 | Q47: 0 | R47: 0 | T47: 148 | U47: 150 | V47: 100
C48: F | D48: =D47 -> 0 | E48: =E47 -> 148 | G48: 3 | H48: 7.2 | I48: 10.7 | K48: 2 | L48: 2 | M48: 0 | N48: 0 | O48: 0 | P48: 0 | Q48: 0 | R48: 0 | T48: 148 | U48: 150 | V48: 100
B50: NTL | C50: mean | E50: =AVERAGE(E44:E48) -> 148 | F50: =F43 -> 66.35 | G50: =AVERAGE(G43:G48) -> 3.1 | H50: =AVERAGE(H43:H48) -> 9.5333333 | I50: =AVERAGE(I43:I48) -> 7.8166667 | J50: =AVERAGE(J43:J48) -> #DIV/0! | K50: =AVERAGE(K43:K48) -> 4.8333333 | L50: =AVERAGE(L43:L48) -> 0.66666667 | M50: =AVERAGE(M43:M48) -> 0 | N50: =AVERAGE(N43:N48) -> 0 | ... R50: =AVERAGE(R43:R48) -> 0
C51: std err | G51: =STDEV(G43:G48)/SQRT(COUNT(G43:G48)) -> 0.17701224 | H51: =STDEV(H43:H48)/SQRT(COUNT(H43:H48)) -> 0.58575687 | I51: =STDEV(I43:I48)/SQRT(COUNT(I43:I48)) -> 0.68284535 | J51: =STDEV(J43:J48)/SQRT(COUNT(J43:J48)) -> #DIV/0! | K51: =STDEV(K43:K48)/SQRT(COUNT(K43:K48)) -> 0.60092521 | L51: =STDEV(L43:L48)/SQRT(COUNT(L43:L48)) -> 0.33333333 | M51: =STDEV(M43:M48)/SQRT(COUNT(M43:M48)) -> 0 | N51: =STDEV(N43:N48)/SQRT(COUNT(N43:N48)) -> 0 | ... R51: =STDEV(R43:R48)/SQRT(COUNT(R43:R48)) -> 0
B53: 105 | C53: A | D53: sm | E53: 147 | F53: 41.87 | G53: 3.3 | H53: 8.6 | I53: 13.4 | K53: 2 | L53: 2 | M53: 0 | N53: 0 | O53: 0 | P53: 0 | Q53: 0 | R53: 0 | T53: 147 | U53: 150 | V53: 100 | W53: 0.36 | X53: 2.62 | AC53: 1.18 | AD53: 0.45 | AF53: 6 | AG53: =IF($H53="","",$H53) -> 8.6 | AH53: =IF(AG53="","",AG53/100) -> 0.086 | AI53: =IF($G53="","",$G53) -> 3.3 | AJ53: =IF($K53="","",$K53) -> 2 | AK53: =IF(J53="","",J53-1) | AL53: =IF($L53="","",$L53) -> 2 | AM53: =IF($M53="","",$M53) -> 0 | AN53: =IF($H54="","",$H54) -> 10.6 | AO53: =IF(AN53="","",AN53/100) -> 0.106 | AP53: =IF($G54="","",$G54) -> 3.5 | AQ53: =IF($K54="","",$K54) -> 4 | AR53: =IF(J54="","",J54-1) | AS53: =IF($L54="","",$L54) -> 1 | AT53: =IF($M54="","",$M54) -> 0 | AU53: =IF($H55="","",$H55) -> 13.3 | AV53: =IF(AU53="","",AU53/100) -> 0.133 | AW53: =IF($G55="","",$G55) -> 3.4 | AX53: =IF($K55="","",$K55) -> 5 | AY53: =IF(J55="","",J55-1) | AZ53: =IF($L55="","",$L55) -> 0 | BA53: =IF($M55="","",$M55) -> 0 | BB53: =IF($H56="","",$H56) -> 8.6 | BC53: =IF(BB53="","",BB53/100) -> 0.086 | BD53: =IF($G56="","",$G56) -> 3.1 | BE53: =IF($K56="","",$K56) -> 4 | BF53: =IF(J56="","",J56-1) | BG53: =IF($L56="","",$L56) -> 1 | BH53: =IF($M56="","",$M56) -> 0 | BI53: =IF($H57="","",$H57) -> 9.6 | BJ53: =IF(BI53="","",BI53/100) -> 0.096 | BK53: =IF($G57="","",$G57) -> 3.3 | BL53: =IF($K57="","",$K57) -> 4 | BM53: =IF(J57="","",J57-1) | BN53: =IF($L57="","",$L57) -> 2 | BO53: =IF($M57="","",$M57) -> 0 | BP53: =IF($H58="","",$H58) -> 10.3 | BQ53: =IF(BP53="","",BP53/100) -> 0.103 | BR53: =IF($G58="","",$G58) -> 3.1 | BS53: =IF($K58="","",$K58) -> 4 | BT53: =IF(J58="","",J58-1) | BU53: =IF($L58="","",$L58) -> 1 | BV53: =IF($M58="","",$M58) -> 0 | BW53: =SUM(O53:O58)/AF53 -> 0 | BX53: =SUM(P53:P58)/AF53 -> 0 | BY53: =SUM(Q53:Q58)/AF53 -> 0 | BZ53: =SUM(R53:R58)/AF53 -> 0
C54: B | E54: 148 | G54: 3.5 | H54: 10.6 | I54: 18.9 | K54: 4 | L54: 1 | M54: 0 | N54: 0 | O54: 0 | P54: 0 | Q54: 0 | R54: 0 | T54: 148 | U54: 150 | V54: 100
C55: C | D55: =D54 -> 0 | E55: =E54 -> 148 | G55: 3.4 | H55: 13.3 | I55: 13.9 | K55: 5 | L55: 0 | M55: 0 | N55: 0 | O55: 0 | P55: 0 | Q55: 0 | R55: 0 | T55: 148 | U55: 150 | V55: 100
...

Sheet d147Data200
B11: Plot | C11: Plant | D11: Initials | E11: DOY Wet Process | F11: Leaf area of Subsmple | G11: Stem Diameter (mm) | H11: Abvegrnd Height (cm) | I11: Tap Root Length (cm) | J11: MS Node of First Fruit Branch | K11: No. of MS Nodes | L11: No. of Veg. Branches | M11: No. nodes on Veg. Branches | N11: Abscisions in reference positions | O11: No. of Squares | P11: No. of White Flowers | Q11: No. of Green Bolls | R11: No. of Mature Bolls | S11: Codes | T11: DOY into Oven | U11: DOY out of Oven | V11: Oven Temp (°C) | W11: Leaf Ssample BM | X11: Remainder Leaf BM | Y11: Square BM | Z11: Flwr & GBoll BM | AA11: Mature Boll BM | AB11: Seed Cotton BM | AC11: StemBM | AD11: Tap Root BM | AF11: NumPlts | AG11: Height | AH11: PHTD1 | AI11: STDD1 | AJ11: MSNODE1 | AK11: PFNODE1 | AL11: VBNUM1 | AM11: VBNODE1 | AN11: Height | AO11: PHTD2 | AP11: STDD2 | AQ11: MSNODE2 | AR11: PFNODE2 | AS11: VBNUM2 | AT11: VBNODE2 | AU11: Height | AV11: PHTD3 | AW11: STDD3 | AX11: MSNODE3 | AY11: PFNODE3 | AZ11: VBNUM3 | BA11: VBNODE3 | BB11: Height | BC11: PHTD4 | BD11: STDD4 | BE11: MSNODE4 | BF11: PFNODE4 | BG11: VBNUM4 | BH11: VBNODE4 | BI11: Height | BJ11: PHTD5 | BK11: STDD5 | BL11: MSNODE5 | BM11: PFNODE5 | BN11: VBNUM5 | BO11: VBNODE5 | BP11: Height | BQ11: PHTD6 | BR11: STDD56 | BS11: MSNODE6 | BT11: PFNODE6 | BU11: VBNUM6 | BV11: VBNODE6 | BW11: SQRNUM | BX11: FLRNUM | BY11: GBNUM | BZ11: MBNUM
B13: 201 | C13: A | D13: s/s | E13: 147 | F13: 51.69 | G13: 2.7 | H13: 11 | I13: 8.5 | K13: 3 | L13: 1 | M13: 0 | N13: 0 | O13: 0 | P13: 0 | Q13: 0 | R13: 0 | T13: 148 | U13: 150 | V13: 100 | W13: 0.36 | X13: 1.72 | AC13: 0.82 | AD13: 0.29 | AF13: 6 | AG13: =IF($H13="","",$H13) -> 11 | AH13: =IF(AG13="","",AG13/100) -> 0.11 | AI13: =IF($G13="","",$G13) -> 2.7 | AJ13: =IF($K13="","",$K13) -> 3 | AK13: =IF(J13="","",J13-1) | AL13: =IF($L13="","",$L13) -> 1 | AM13: =IF($M13="","",$M13) -> 0 | AN13: =IF($H14="","",$H14) -> 12 | AO13: =IF(AN13="","",AN13/100) -> 0.12 | AP13: =IF($G14="","",$G14) -> 3.6 | AQ13: =IF($K14="","",$K14) -> 6 | AR13: =IF(J14="","",J14-1) | AS13: =IF($L14="","",$L14) -> 0 | AT13: =IF($M14="","",$M14) -> 0 | AU13: =IF($H15="","",$H15) -> 9 | AV13: =IF(AU13="","",AU13/100) -> 0.09 | AW13: =IF($G15="","",$G15) -> 2.6 | AX13: =IF($K15="","",$K15) -> 4 | AY13: =IF(J15="","",J15-1) | AZ13: =IF($L15="","",$L15) -> 0 | BA13: =IF($M15="","",$M15) -> 0 | BB13: =IF($H16="","",$H16) -> 6.5 | BC13: =IF(BB13="","",BB13/100) -> 0.065 | BD13: =IF($G16="","",$G16) -> 2.3 | BE13: =IF($K16="","",$K16) -> 3 | BF13: =IF(J16="","",J16-1) | BG13: =IF($L16="","",$L16) -> 0 | BH13: =IF($M16="","",$M16) -> 0 | BI13: =IF($H17="","",$H17) -> 8.5 | BJ13: =IF(BI13="","",BI13/100) -> 0.085 | BK13: =IF($G17="","",$G17) -> 2.8 | BL13: =IF($K17="","",$K17) -> 2 | BM13: =IF(J17="","",J17-1) | BN13: =IF($L17="","",$L17) -> 2 | BO13: =IF($M17="","",$M17) -> 0 | BP13: =IF($H18="","",$H18) -> 9 | BQ13: =IF(BP13="","",BP13/100) -> 0.09 | BR13: =IF($G18="","",$G18) -> 3 | BS13: =IF($K18="","",$K18) -> 3 | BT13: =IF(J18="","",J18-1) | BU13: =IF($L18="","",$L18) -> 0 | BV13: =IF($M18="","",$M18) -> 0 | BW13: =SUM(O13:O18)/AF13 -> 0 | BX13: =SUM(P13:P18)/AF13 -> 0 | BY13: =SUM(Q13:Q18)/AF13 -> 0 | BZ13: =SUM(R13:R18)/AF13 -> 0
C14: B | G14: 3.6 | H14: 12 | I14: 9 | K14: 6 | L14: 0 | M14: 0 | N14: 0 | O14: 0 | P14: 0 | Q14: 0 | R14: 0
C15: C | D15: =D14 -> 0 | E15: =E14 -> 0 | G15: 2.6 | H15: 9 | I15: 9.5 | K15: 4 | L15: 0 | M15: 0 | N15: 0 | O15: 0 | P15: 0 | Q15: 0 | R15: 0
C16: D | D16: =D15 -> 0 | E16: =E15 -> 0 | G16: 2.3 | H16: 6.5 | I16: 8 | K16: 3 | L16: 0 | M16: 0 | N16: 0 | O16: 0 | P16: 0 | Q16: 0 | R16: 0
C17: E | D17: =D16 -> 0 | E17: =E16 -> 0 | G17: 2.8 | H17: 8.5 | I17: 11 | K17: 2 | L17: 2 | M17: 0 | N17: 0 | O17: 0 | P17: 0 | Q17: 0 | R17: 0
C18: F | D18: =D17 -> 0 | E18: =E17 -> 0 | G18: 3 | H18: 9 | I18: 6.5 | K18: 3 | L18: 0 | M18: 0 | N18: 0 | O18: 0 | P18: 0 | Q18: 0 | R18: 0
B20: NDL | C20: mean | E20: =AVERAGE(E14:E18) -> 0 | F20: =F13 -> 51.69 | G20: =AVERAGE(G13:G18) -> 2.8333333 | H20: =AVERAGE(H13:H18) -> 9.3333333 | I20: =AVERAGE(I13:I18) -> 8.75 | J20: =AVERAGE(J13:J18) -> #DIV/0! | K20: =AVERAGE(K13:K18) -> 3.5 | L20: =AVERAGE(L13:L18) -> 0.5 | M20: =AVERAGE(M13:M18) -> 0 | N20: =AVERAGE(N13:N18) -> 0 | ... R20: =AVERAGE(R13:R18) -> 0
C21: std err | G21: =STDEV(G13:G18)/SQRT(COUNT(G13:G18)) -> 0.18012341 | H21: =STDEV(H13:H18)/SQRT(COUNT(H13:H18)) -> 0.79232429 | I21: =STDEV(I13:I18)/SQRT(COUNT(I13:I18)) -> 0.61576511 | J21: =STDEV(J13:J18)/SQRT(COUNT(J13:J18)) -> #DIV/0! | K21: =STDEV(K13:K18)/SQRT(COUNT(K13:K18)) -> 0.56273143 | L21: =STDEV(L13:L18)/SQRT(COUNT(L13:L18)) -> 0.34156503 | M21: =STDEV(M13:M18)/SQRT(COUNT(M13:M18)) -> 0 | N21: =STDEV(N13:N18)/SQRT(COUNT(N13:N18)) -> 0 | ... R21: =STDEV(R13:R18)/SQRT(COUNT(R13:R18)) -> 0
B23: =B13+1 -> 202 | C23: A | E23: 147 | F23: 113.28 | G23: 3.7 | H23: 10.5 | I23: 14.5 | K23: 3 | L23: 1 | M23: 0 | N23: 0 | O23: 0 | P23: 0 | Q23: 0 | R23: 0 | T23: 148 | U23: 150 | V23: 100 | W23: 0.88 | X23: 1.75 | AC23: 1.01 | AD23: 0.41 | AF23: 6 | AG23: =IF($H23="","",$H23) -> 10.5 | AH23: =IF(AG23="","",AG23/100) -> 0.105 | AI23: =IF($G23="","",$G23) -> 3.7 | AJ23: =IF($K23="","",$K23) -> 3 | AK23: =IF(J23="","",J23-1) | AL23: =IF($L23="","",$L23) -> 1 | AM23: =IF($M23="","",$M23) -> 0 | AN23: =IF($H24="","",$H24) -> 11 | AO23: =IF(AN23="","",AN23/100) -> 0.11 | AP23: =IF($G24="","",$G24) -> 3.6 | AQ23: =IF($K24="","",$K24) -> 5 | AR23: =IF(J24="","",J24-1) | AS23: =IF($L24="","",$L24) -> 0 | AT23: =IF($M24="","",$M24) -> 0 | AU23: =IF($H25="","",$H25) -> 11 | AV23: =IF(AU23="","",AU23/100) -> 0.11 | AW23: =IF($G25="","",$G25) -> 3 | AX23: =IF($K25="","",$K25) -> 5 | AY23: =IF(J25="","",J25-1) | AZ23: =IF($L25="","",$L25) -> 0 | BA23: =IF($M25="","",$M25) -> 0 | BB23: =IF($H26="","",$H26) -> 8.5 | BC23: =IF(BB23="","",BB23/100) -> 0.085 | BD23: =IF($G26="","",$G26) -> 2.6 | BE23: =IF($K26="","",$K26) -> 2 | BF23: =IF(J26="","",J26-1) | BG23: =IF($L26="","",$L26) -> 1 | BH23: =IF($M26="","",$M26) -> 0 | BI23: =IF($H27="","",$H27) -> 5 | BJ23: =IF(BI23="","",BI23/100) -> 0.05 | BK23: =IF($G27="","",$G27) -> 2.5 | BL23: =IF($K27="","",$K27) -> 0 | BM23: =IF(J27="","",J27-1) | BN23: =IF($L27="","",$L27) -> 0 | BO23: =IF($M27="","",$M27) -> 0 | BP23: =IF($H28="","",$H28) -> 5 | BQ23: =IF(BP23="","",BP23/100) -> 0.05 | BR23: =IF($G28="","",$G28) -> 2.2 | BS23: =IF($K28="","",$K28) -> 0 | BT23: =IF(J28="","",J28-1) | BU23: =IF($L28="","",$L28) -> 0 | BV23: =IF($M28="","",$M28) -> 0 | BW23: =SUM(O23:O28)/AF23 -> 0 | BX23: =SUM(P23:P28)/AF23 -> 0 | BY23: =SUM(Q23:Q28)/AF23 -> 0 | BZ23: =SUM(R23:R28)/AF23 -> 0
C24: B | E24: 148 | G24: 3.6 | H24: 11 | I24: 11 | K24: 5 | L24: 0 | M24: 0 | N24: 0 | O24: 0 | P24: 0 | Q24: 0 | R24: 0
C25: C | D25: =D24 -> 0 | E25: =E24 -> 148 | G25: 3 | H25: 11 | I25: 10 | K25: 5 | L25: 0 | M25: 0 | N25: 0 | O25: 0 | P25: 0 | Q25: 0 | R25: 0
C26: D | D26: =D25 -> 0 | E26: =E25 -> 148 | G26: 2.6 | H26: 8.5 | I26: 13 | K26: 2 | L26: 1 | M26: 0 | N26: 0 | O26: 0 | P26: 0 | Q26: 0 | R26: 0
C27: E | D27: =D26 -> 0 | E27: =E26 -> 148 | G27: 2.5 | H27: 5 | I27: 5.5 | K27: 0 | L27: 0 | M27: 0 | N27: 0 | O27: 0 | P27: 0 | Q27: 0 | R27: 0
C28: F | D28: =D27 -> 0 | E28: =E27 -> 148 | G28: 2.2 | H28: 5 | I28: 3 | K28: 0 | L28: 0 | M28: 0 | N28: 0 | O28: 0 | P28: 0 | Q28: 0 | R28: 0 | S28: cotyledons
B30: NTH | C30: mean | E30: =AVERAGE(E24:E28) -> 148 | F30: =F23 -> 113.28 | G30: =AVERAGE(G23:G28) -> 2.9333333 | H30: =AVERAGE(H23:H28) -> 8.5 | I30: =AVERAGE(I23:I28) -> 9.5 | J30: =AVERAGE(J23:J28) -> #DIV/0! | K30: =AVERAGE(K23:K28) -> 2.5 | L30: =AVERAGE(L23:L28) -> 0.33333333 | M30: =AVERAGE(M23:M28) -> 0 | N30: =AVERAGE(N23:N28) -> 0 | ... R30: =AVERAGE(R23:R28) -> 0
C31: std err | G31: =STDEV(G23:G28)/SQRT(COUNT(G23:G28)) -> 0.24988886 | H31: =STDEV(H23:H28)/SQRT(COUNT(H23:H28)) -> 1.1690452 | I31: =STDEV(I23:I28)/SQRT(COUNT(I23:I28)) -> 1.8073922 | J31: =STDEV(J23:J28)/SQRT(COUNT(J23:J28)) -> #DIV/0! | K31: =STDEV(K23:K28)/SQRT(COUNT(K23:K28)) -> 0.92195445 | L31: =STDEV(L23:L28)/SQRT(COUNT(L23:L28)) -> 0.21081851 | M31: =STDEV(M23:M28)/SQRT(COUNT(M23:M28)) -> 0 | N31: =STDEV(N23:N28)/SQRT(COUNT(N23:N28)) -> 0 | ... R31: =STDEV(R23:R28)/SQRT(COUNT(R23:R28)) -> 0
B33: =B23+1 -> 203 | C33: A | E33: 147 | F33: 65.02 | G33: 2.9 | H33: 10 | I33: 11 | K33: 5 | L33: 0 | M33: 0 | N33: 0 | O33: 0 | P33: 0 | Q33: 0 | R33: 0 | T33: 148 | U33: 150 | V33: 100 | W33: 0.43 | X33: 2.12 | AC33: 0.97 | AD33: 0.35 | AF33: 6 | AG33: =IF($H33="","",$H33) -> 10 | AH33: =IF(AG33="","",AG33/100) -> 0.1 | AI33: =IF($G33="","",$G33) -> 2.9 | AJ33: =IF($K33="","",$K33) -> 5 | AK33: =IF(J33="","",J33-1) | AL33: =IF($L33="","",$L33) -> 0 | AM33: =IF($M33="","",$M33) -> 0 | AN33: =IF($H34="","",$H34) -> 10 | AO33: =IF(AN33="","",AN33/100) -> 0.1 | AP33: =IF($G34="","",$G34) -> 2.8 | AQ33: =IF($K34="","",$K34) -> 4 | AR33: =IF(J34="","",J34-1) | AS33: =IF($L34="","",$L34) -> 0 | AT33: =IF($M34="","",$M34) -> 0 | AU33: =IF($H35="","",$H35) -> 9 | AV33: =IF(AU33="","",AU33/100) -> 0.09 | AW33: =IF($G35="","",$G35) -> 3.7 | AX33: =IF($K35="","",$K35) -> 3 | AY33: =IF(J35="","",J35-1) | AZ33: =IF($L35="","",$L35) -> 3 | BA33: =IF($M35="","",$M35) -> 0 | BB33: =IF($H36="","",$H36) -> 9 | BC33: =IF(BB33="","",BB33/100) -> 0.09 | BD33: =IF($G36="","",$G36) -> 3 | BE33: =IF($K36="","",$K36) -> 3 | BF33: =IF(J36="","",J36-1) | BG33: =IF($L36="","",$L36) -> 2 | BH33: =IF($M36="","",$M36) -> 0 | BI33: =IF($H37="","",$H37) -> 14 | BJ33: =IF(BI33="","",BI33/100) -> 0.14 | BK33: =IF($G37="","",$G37) -> 3.3 | BL33: =IF($K37="","",$K37) -> 6 | BM33: =IF(J37="","",J37-1) | BN33: =IF($L37="","",$L37) -> 0 | BO33: =IF($M37="","",$M37) -> 0 | BP33: =IF($H38="","",$H38) -> 4.2 | BQ33: =IF(BP33="","",BP33/100) -> 0.042 | BR33: =IF($G38="","",$G38) -> 1.6 | BS33: =IF($K38="","",$K38) -> 3 | BT33: =IF(J38="","",J38-1) | BU33: =IF($L38="","",$L38) -> 0 | BV33: =IF($M38="","",$M38) -> 0 | BW33: =SUM(O33:O38)/AF33 -> 0 | BX33: =SUM(P33:P38)/AF33 -> 0 | BY33: =SUM(Q33:Q38)/AF33 -> 0 | BZ33: =SUM(R33:R38)/AF33 -> 0
C34: B | E34: 148 | G34: 2.8 | H34: 10 | I34: 9 | K34: 4 | L34: 0 | M34: 0 | N34: 0 | O34: 0 | P34: 0 | Q34: 0 | R34: 0
C35: C | D35: =D34 -> 0 | E35: =E34 -> 148 | G35: 3.7 | H35: 9 | I35: 6.5 | K35: 3 | L35: 3 | M35: 0 | N35: 0 | O35: 0 | P35: 0 | Q35: 0 | R35: 0
C36: D | D36: =D35 -> 0 | E36: =E35 -> 148 | G36: 3 | H36: 9 | I36: 9.5 | K36: 3 | L36: 2 | M36: 0 | N36: 0 | O36: 0 | P36: 0 | Q36: 0 | R36: 0
C37: E | D37: =D36 -> 0 | E37: =E36 -> 148 | G37: 3.3 | H37: 14 | I37: 15 | K37: 6 | L37: 0 | M37: 0 | N37: 0 | O37: 0 | P37: 0 | Q37: 0 | R37: 0
C38: F | D38: =D37 -> 0 | E38: =E37 -> 148 | G38: 1.6 | H38: 4.2 | I38: 5.5 | K38: 3 | L38: 0 | M38: 0 | N38: 0 | O38: 0 | P38: 0 | Q38: 0 | R38: 0
M39: 0 | N39: 0 | O39: 0 | P39: 0 | Q39: 0 | R39: 0
B40: FTH | C40: mean | E40: =AVERAGE(E34:E38) -> 148 | F40: =F33 -> 65.02 | G40: =AVERAGE(G33:G38) -> 2.8833333 | H40: =AVERAGE(H33:H38) -> 9.3666667 | I40: =AVERAGE(I33:I38) -> 9.4166667 | J40: =AVERAGE(J33:J38) -> #DIV/0! | K40: =AVERAGE(K33:K38) -> 4 | L40: =AVERAGE(L33:L38) -> 0.83333333 | M40: =AVERAGE(M33:M38) -> 0 | N40: =AVERAGE(N33:N38) -> 0 | ... R40: =AVERAGE(R33:R38) -> 0
C41: std err | G41: =STDEV(G33:G38)/SQRT(COUNT(G33:G38)) -> 0.28915586 | H41: =STDEV(H33:H38)/SQRT(COUNT(H33:H38)) -> 1.2810586 | I41: =STDEV(I33:I38)/SQRT(COUNT(I33:I38)) -> 1.3869431 | J41: =STDEV(J33:J38)/SQRT(COUNT(J33:J38)) -> #DIV/0! | K41: =STDEV(K33:K38)/SQRT(COUNT(K33:K38)) -> 0.51639778 | L41: =STDEV(L33:L38)/SQRT(COUNT(L33:L38)) -> 0.54262735 | M41: =STDEV(M33:M38)/SQRT(COUNT(M33:M38)) -> 0 | N41: =STDEV(N33:N38)/SQRT(COUNT(N33:N38)) -> 0 | ... R41: =STDEV(R33:R38)/SQRT(COUNT(R33:R38)) -> 0
B43: =B33+1 -> 204 | C43: A | D43: sr | E43: 147 | F43: 79.21 | G43: 3.6 | H43: 11 | I43: 14 | K43: 3 | L43: 2 | M43: 0 | N43: 0 | O43: 0 | P43: 0 | Q43: 0 | R43: 0 | T43: 148 | U43: 150 | V43: 100 | W43: 0.54 | X43: 1.62 | AC43: 0.84 | AD43: 0.37 | AF43: 6 | AG43: =IF($H43="","",$H43) -> 11 | AH43: =IF(AG43="","",AG43/100) -> 0.11 | AI43: =IF($G43="","",$G43) -> 3.6 | AJ43: =IF($K43="","",$K43) -> 3 | AK43: =IF(J43="","",J43-1) | AL43: =IF($L43="","",$L43) -> 2 | AM43: =IF($M43="","",$M43) -> 0 | AN43: =IF($H44="","",$H44) -> 10 | AO43: =IF(AN43="","",AN43/100) -> 0.1 | AP43: =IF($G44="","",$G44) -> 3.3 | AQ43: =IF($K44="","",$K44) -> 5 | AR43: =IF(J44="","",J44-1) | AS43: =IF($L44="","",$L44) -> 0 | AT43: =IF($M44="","",$M44) -> 0 | AU43: =IF($H45="","",$H45) -> 9.5 | AV43: =IF(AU43="","",AU43/100) -> 0.095 | AW43: =IF($G45="","",$G45) -> 2.9 | AX43: =IF($K45="","",$K45) -> 3 | AY43: =IF(J45="","",J45-1) | AZ43: =IF($L45="","",$L45) -> 2 | BA43: =IF($M45="","",$M45) -> 0 | BB43: =IF($H46="","",$H46) -> 8 | BC43: =IF(BB43="","",BB43/100) -> 0.08 | BD43: =IF($G46="","",$G46) -> 3 | BE43: =IF($K46="","",$K46) -> 3 | BF43: =IF(J46="","",J46-1) | BG43: =IF($L46="","",$L46) -> 0 | BH43: =IF($M46="","",$M46) -> 0 | BI43: =IF($H47="","",$H47) -> 10 | BJ43: =IF(BI43="","",BI43/100) -> 0.1 | BK43: =IF($G47="","",$G47) -> 2.9 | BL43: =IF($K47="","",$K47) -> 3 | BM43: =IF(J47="","",J47-1) | BN43: =IF($L47="","",$L47) -> 0 | BO43: =IF($M47="","",$M47) -> 0 | BP43: =IF($H48="","",$H48) -> 8.5 | BQ43: =IF(BP43="","",BP43/100) -> 0.085 | BR43: =IF($G48="","",$G48) -> 2.5 | BS43: =IF($K48="","",$K48) -> 5 | BT43: =IF(J48="","",J48-1) | BU43: =IF($L48="","",$L48) -> 0 | BV43: =IF($M48="","",$M48) -> 0 | BW43: =SUM(O43:O48)/AF43 -> 0 | BX43: =SUM(P43:P48)/AF43 -> 0 | BY43: =SUM(Q43:Q48)/AF43 -> 0 | BZ43: =SUM(R43:R48)/AF43 -> 0
C44: B | E44: 148 | G44: 3.3 | H44: 10 | I44: 18 | K44: 5 | L44: 0 | M44: 0 | N44: 0 | O44: 0 | P44: 0 | Q44: 0 | R44: 0
C45: C | D45: =D44 -> 0 | E45: =E44 -> 148 | G45: 2.9 | H45: 9.5 | I45: 9.5 | K45: 3 | L45: 2 | M45: 0 | N45: 0 | O45: 0 | P45: 0 | Q45: 0 | R45: 0
C46: D | D46: =D45 -> 0 | E46: =E45 -> 148 | G46: 3 | H46: 8 | I46: 15 | K46: 3 | L46: 0 | M46: 0 | N46: 0 | O46: 0 | P46: 0 | Q46: 0 | R46: 0
C47: E | D47: =D46 -> 0 | E47: =E46 -> 148 | G47: 2.9 | H47: 10 | I47: 10 | K47: 3 | L47: 0 | M47: 0 | N47: 0 | O47: 0 | P47: 0 | Q47: 0 | R47: 0
C48: F | D48: =D47 -> 0 | E48: =E47 -> 148 | G48: 2.5 | H48: 8.5 | I48: 7 | K48: 5 | L48: 0 | M48: 0 | N48: 0 | O48: 0 | P48: 0 | Q48: 0 | R48: 0
B50: NDH | C50: mean | E50: =AVERAGE(E44:E48) -> 148 | F50: =F43 -> 79.21 | G50: =AVERAGE(G43:G48) -> 3.0333333 | H50: =AVERAGE(H43:H48) -> 9.5 | I50: =AVERAGE(I43:I48) -> 12.25 | J50: =AVERAGE(J43:J48) -> #DIV/0! | K50: =AVERAGE(K43:K48) -> 3.6666667 | L50: =AVERAGE(L43:L48) -> 0.66666667 | M50: =AVERAGE(M43:M48) -> 0 | N50: =AVERAGE(N43:N48) -> 0 | ... R50: =AVERAGE(R43:R48) -> 0
C51: std err | G51: =STDEV(G43:G48)/SQRT(COUNT(G43:G48)) -> 0.15420045 | H51: =STDEV(H43:H48)/SQRT(COUNT(H43:H48)) -> 0.4472136 | I51: =STDEV(I43:I48)/SQRT(COUNT(I43:I48)) -> 1.6720746 | J51: =STDEV(J43:J48)/SQRT(COUNT(J43:J48)) -> #DIV/0! | K51: =STDEV(K43:K48)/SQRT(COUNT(K43:K48)) -> 0.42163702 | L51: =STDEV(L43:L48)/SQRT(COUNT(L43:L48)) -> 0.42163702 | M51: =STDEV(M43:M48)/SQRT(COUNT(M43:M48)) -> 0 | N51: =STDEV(N43:N48)/SQRT(COUNT(N43:N48)) -> 0 | ... R51: =STDEV(R43:R48)/SQRT(COUNT(R43:R48)) -> 0
