Workbook

Sheet Height
A1: CCID | B1: DOY168 | C1: DOY176 | D1: DOY189 | E1: DOY209 | F1: DOY217 | G1: DOY233 | H1: DOY259 | I1: DOY287
A2: p101-1 | B2: 35 | C2: 41 | D2: 70 | E2: 79 | F2: 96 | G2: 114 | H2: 141 | I2: 148
A3: p101-2 | B3: 35 | C3: 45 | D3: 65 | E3: 89 | F3: 104 | G3: 131 | H3: 141 | I3: 142
A4: p101-3 | B4: 30 | C4: 47 | D4: 69 | E4: 85 | F4: 86 | G4: 90 | H4: 126 | I4: 129
A5: p101-4 | B5: 26 | C5: 32 | D5: 60 | E5: 83 | F5: 92 | G5: 104 | H5: 85 | I5: 121
A6: p101-5 | B6: 26 | C6: 34 | D6: 58 | E6: 76 | F6: 87 | G6: 88 | H6: 117 | I6: 101
A7: p101-6 | B7: 32 | C7: 42 | D7: 71 | E7: 96 | F7: 76 | G7: 86 | H7: 114 | I7: 113
A8: p102-1 | B8: 34 | C8: 45 | D8: 74 | E8: 82 | F8: 90 | G8: 112 | H8: 127 | I8: 127
A9: p102-2 | B9: 32 | C9: 46 | D9: 75 | E9: 80 | F9: 87 | G9: 85 | H9: 108 | I9: 112
A10: p102-3 | B10: 31 | C10: 42 | D10: 69 | E10: 77 | F10: 80 | G10: 80 | H10: 81 | I10: 82
A11: p102-4 | B11: 33 | C11: 31 | E11: 86 | F11: 90 | G11: 97 | H11: 121 | I11: 103
A12: p102-5 | B12: 33 | C12: 44 | D12: 63 | E12: 75 | F12: 102 | G12: 100 | H12: 101 | I12: 104
A13: p102-6 | B13: 32 | C13: 44 | D13: 72 | E13: 86 | F13: 91 | G13: 91 | H13: 103 | I13: 102
A14: p103-1 | B14: 35 | C14: 45 | D14: 71 | E14: 84 | F14: 89 | G14: 116 | H14: 119 | I14: 124
A15: p103-2 | B15: 35 | C15: 40 | D15: 67 | E15: 91 | F15: 106 | G15: 121 | H15: 112 | I15: 121
A16: p103-3 | B16: 38 | C16: 42 | D16: 60 | E16: 84 | F16: 92 | G16: 94 | H16: 93 | I16: 111
A17: p103-4 | B17: 34 | C17: 39 | D17: 62 | E17: 83 | F17: 91 | G17: 100 | H17: 105 | I17: 113
A18: p103-5 | B18: 34 | C18: 38 | D18: 57 | E18: 73 | F18: 80 | G18: 92 | H18: 96 | I18: 92
A19: p103-6 | B19: 38 | C19: 41 | D19: 66 | E19: 77 | F19: 85 | G19: 88 | H19: 100 | I19: 94
A20: p104-1 | B20: 36 | C20: 45 | D20: 74 | E20: 93 | F20: 96 | G20: 98 | H20: 92 | I20: 94
A21: p104-2 | B21: 40 | C21: 50 | D21: 75 | E21: 89 | F21: 84 | G21: 89 | H21: 90 | I21: 96
A22: p104-3 | B22: 29 | C22: 51 | D22: 75 | E22: 87 | F22: 98 | G22: 97 | H22: 101 | I22: 98
A23: p104-4 | B23: 35 | C23: 46 | D23: 75 | E23: 88 | F23: 98 | G23: 98 | H23: 110 | I23: 102
... A93: p208-2 | B93: 36 | C93: 38 | D93: 70 | E93: 81 | F93: 86 | G93: 93 | H93: 115 | I93: 101
A94: p208-3 | C94: 38 | D94: 62 | E94: 81 | F94: 84 | G94: 89 | H94: 106 | I94: 97
A95: p208-4 | B95: 32 | C95: 42 | D95: 66 | E95: 76 | F95: 83 | G95: 81 | H95: 99 | I95: 101
A96: p208-5 | B96: 41 | C96: 49 | D96: 69 | E96: 84 | F96: 89 | G96: 92 | H96: 118 | I96: 126
A97: p208-6 | B97: 28 | C97: 39 | D97: 72 | E97: 76 | F97: 96 | G97: 79 | H97: 95 | I97: 93
A98: p301-1 | B98: 36 | C98: 46 | D98: 71 | E98: 89 | F98: 104 | G98: 82 | H98: 103 | I98: 89
A99: p301-2 | B99: 39 | C99: 53 | D99: 79 | E99: 87 | F99: 101 | G99: 93 | H99: 111 | I99: 105
A100: p301-3 | B100: 36 | C100: 46 | D100: 72 | E100: 90 | F100: 101 | G100: 95 | H100: 107 | I100: 98
A101: p301-4 | B101: 44 | C101: 50 | D101: 78 | E101: 95 | F101: 101 | G101: 87 | H101: 98 | I101: 97
A102: p301-5 | B102: 44 | C102: 38 | D102: 84 | E102: 89 | F102: 99 | G102: 94 | H102: 97 | I102: 94
A103: p301-6 | B103: 39 | C103: 52 | D103: 76 | E103: 85 | F103: 98 | G103: 98 | H103: 92 | I103: 98
A104: p302-1 | B104: 32 | C104: 54 | D104: 74 | E104: 83 | F104: 101 | G104: 93 | H104: 102 | I104: 97
A105: p302-2 | B105: 33 | C105: 45 | D105: 83 | E105: 96 | F105: 96 | G105: 112 | H105: 104 | I105: 113
A106: p302-3 | B106: 26 | C106: 44 | D106: 80 | E106: 89 | F106: 95 | G106: 90 | H106: 94 | I106: 96
... A193: p408-6 | B193: 33 | C193: 40 | D193: 68 | E193: 78 | F193: 86 | G193: 122 | H193: 121 | I193: 122
A194: p902-1 | B194: 38 | C194: 45 | D194: 66 | F194: 82 | G194: 90 | H194: 88 | I194: 84
A195: p902-2 | B195: 40 | C195: 48 | D195: 64 | F195: 84 | G195: 69 | H195: 73 | I195: 82
...

Sheet Width
A1: CCID | B1: DOY168 | C1: DOY176 | D1: DOY189 | E1: DOY209 | F1: DOY217 | G1: DOY233 | H1: DOY259 | I1: DOY287
A2: p101-1 | B2: 39 | C2: 54 | D2: 72 | E2: 85 | F2: 83 | G2: 114 | H2: 100 | I2: 91
A3: p101-2 | B3: 53 | C3: 63 | D3: 79 | E3: 94 | F3: 93 | G3: 131 | H3: 82 | I3: 98
A4: p101-3 | B4: 38 | C4: 50 | D4: 71 | E4: 94 | F4: 95 | G4: 90 | H4: 70 | I4: 98
A5: p101-4 | B5: 35 | C5: 55 | D5: 75 | E5: 98 | F5: 86 | G5: 104 | H5: 100 | I5: 97
A6: p101-5 | B6: 35 | C6: 49 | D6: 73 | E6: 89 | F6: 83 | G6: 88 | H6: 82 | I6: 93
A7: p101-6 | B7: 44 | C7: 59 | D7: 81 | E7: 82 | F7: 95 | G7: 86 | H7: 86 | I7: 73
A8: p102-1 | B8: 46 | C8: 62 | D8: 75 | E8: 94 | F8: 84 | G8: 79 | H8: 100 | I8: 86
A9: p102-2 | B9: 45 | C9: 57 | D9: 91 | E9: 93 | F9: 87 | G9: 97 | H9: 94 | I9: 88
A10: p102-3 | B10: 40 | C10: 55 | D10: 69 | E10: 64 | F10: 80 | G10: 87 | H10: 87 | I10: 81
A11: p102-4 | B11: 38 | C11: 46 | D11: 71 | E11: 79 | F11: 79 | G11: 89 | H11: 93 | I11: 80
A12: p102-5 | B12: 38 | C12: 51 | D12: 70 | E12: 80 | F12: 85 | G12: 92 | H12: 90 | I12: 79
A13: p102-6 | B13: 51 | C13: 68 | D13: 83 | E13: 99 | F13: 105 | G13: 93 | H13: 99 | I13: 91
... A193: p408-6 | B193: 47 | C193: 53 | D193: 73 | E193: 92 | F193: 96 | G193: 99 | H193: 92 | I193: 73
A194: p902-1 | B194: 44 | C194: 58 | D194: 69 | F194: 85 | G194: 84 | H194: 84 | I194: 66
A195: p902-2 | B195: 50 | C195: 62 | D195: 77 | F195: 68 | G195: 78 | H195: 82 | I195: 73
A196: p902-3 | B196: 48 | C196: 55 | D196: 67 | F196: 64 | G196: 73 | H196: 70 | I196: 63
A197: p902-4 | B197: 50 | C197: 65 | D197: 83 | F197: 67 | G197: 101 | H197: 100 | I197: 79
A198: p902-5 | B198: 41 | C198: 48 | D198: 66 | F198: 65 | G198: 76 | H198: 65 | I198: 55
A199: p902-6 | B199: 49 | C199: 60 | D199: 73 | F199: 67 | G199: 78 | H199: 100 | I199: 72
A200: p904-1 | B200: 57 | C200: 55 | D200: 63 | F200: 58 | G200: 70 | H200: 68 | I200: 63
A201: p904-2 | B201: 56 | C201: 62 | D201: 63 | F201: 56 | G201: 61 | H201: 64 | I201: 61
A202: p904-3 | B202: 44 | C202: 53 | D202: 56 | F202: 51 | G202: 57 | H202: 57 | I202: 53
A203: p904-4 | B203: 41 | C203: 53 | D203: 55 | F203: 66 | G203: 70 | H203: 74 | I203: 63
A204: p904-5 | B204: 44 | C204: 59 | D204: 61 | F204: 71 | G204: 73 | H204: 75 | I204: 68
A205: p904-6 | B205: 45 | C205: 53 | D205: 53 | F205: 51 | G205: 75 | H205: 70 | I205: 58
... A217: p908-6 | B217: 49 | C217: 60 | D217: 59 | F217: 71 | G217: 73 | H217: 43 | I217: 67

Sheet SPAD
A1: CCID | B1: DOY176 | C1: DOY190 | D1: DOY217 | E1: DOY233 | F1: DOY241 | G1: DOY259
A2: p101-3 | B2: 48.866667 | C2: 36.771 | D2: 44.716133 | E2: 48.696439 | F2: 45.204082 | G2: 47.72295
A3: p102-3 | B3: 45.083333 | C3: 37.7495 | D3: 39.361673 | E3: 41.304441 | F3: 42.137906 | G3: 39.769125
A4: p103-3 | B4: 47.683333 | C4: 38.934 | D4: 42.583826 | E4: 45.900748 | F4: 42.439737 | G4: 45.311145
A5: p104-3 | B5: 42.391667 | C5: 33.7325 | D5: 37.655827 | E5: 41.399211 | F5: 39.414991 | G5: 38.434935
A6: p105-3 | B6: 41.5375 | C6: 35.0715 | D6: 36.376443 | E6: 41.683518 | F6: 37.715959 | G6: 37.35732
A7: p106-3 | B7: 44.516667 | C7: 32.754 | D7: 36.423828 | E7: 45.237363 | F7: 43.964822 | G7: 42.848025
A8: p107-3 | B8: 44.8375 | C8: 35.9985 | D8: 34.860136 | E8: 40.87798 | F8: 38.928833 | G8: 38.537565
A9: p108-3 | B9: 45.791667 | C9: 33.166 | D9: 38.745673 | E9: 46.801055 | F9: 44.421594 | G9: 45.003255
A10: p201-3 | B10: 41.6375 | C10: 34.7625 | D10: 40.972749 | E10: 40.783211 | F10: 39.426471 | G10: 35.356035
A11: p202-3 | B11: 47.75 | C11: 38.522 | D11: 43.531518 | E11: 45.995517 | F11: 43.79342 | G11: 43.771695
A12: p203-3 | B12: 45.975 | C12: 33.3205 | D12: 42.062595 | E12: 46.516747 | F12: 43.322308 | G12: 45.208515
A13: p204-3 | B13: 41.583333 | C13: 36.7195 | D13: 40.87798 | E13: 43.531518 | F13: 40.639353 | G13: 43.053285
... A33: p408-3 | B33: 45.583333 | C33: 36.359 | D33: 40.119826 | E33: 42.751474 | F33: 42.529032 | G33: 39.728335
A34: p902-3 | D34: 46.516747 | E34: 50.850636 | F34: 50.79646 | G34: 52.165925
A35: p904-3 | B35: 47.041667 | C35: 53.972 | D35: 51.349977 | E35: 52.136973 | F35: 54.463583 | G35: 54.06754
A36: p906-3 | D36: 44.289671 | E36: 49.897793 | F36: 49.137931 | G36: 50.212915
A37: p908-3 | B37: 46.758333 | C37: 53.9205 | D37: 50.402285 | E37: 53.804447 | F37: 52.39645 | G37: 52.885455

Sheet ChlA
A1: CCID | B1: DOY176 | C1: DOY190 | D1: DOY217 | E1: DOY233 | F1: DOY241 | G1: DOY259
A2: p101-3 | B2: 46.335836 | C2: 33.809459 | D2: 51.795826 | E2: 60.703554 | F2: 42.906745 | G2: 55.238429
A3: p102-3 | B3: 44.578742 | C3: 36.374177 | D3: 47.567672 | E3: 53.999832 | F3: 47.362338 | G3: 45.181951
A4: p103-3 | B4: 46.408118 | C4: 37.41124 | D4: 48.148111 | E4: 56.136992 | F4: 49.704773 | G4: 52.610212
A5: p104-3 | B5: 44.397491 | C5: 30.710003 | D5: 41.889976 | E5: 50.361364 | F5: 44.395435 | G5: 38.753601
A6: p105-3 | B6: 42.328105 | C6: 33.130622 | D6: 38.906018 | E6: 49.477415 | F6: 37.371881 | G6: 35.857005
A7: p106-3 | B7: 42.363235 | C7: 28.498772 | D7: 35.645596 | E7: 54.327435 | F7: 47.663903 | G7: 49.329273
A8: p107-3 | B8: 44.827302 | C8: 34.431557 | D8: 34.274168 | E8: 52.13579 | F8: 41.163304 | G8: 39.735947
A9: p108-3 | B9: 48.210681 | C9: 30.369574 | D9: 39.454278 | E9: 60.675185 | F9: 49.396095 | G9: 53.843604
A10: p201-3 | B10: 44.065612 | C10: 31.342906 | D10: 54.076853 | E10: 48.473693 | F10: 37.343042 | G10: 35.167132
A11: p202-3 | B11: 49.996144 | C11: 36.136653 | D11: 50.46629 | E11: 53.495717 | F11: 44.489836 | G11: 51.507628
A12: p203-3 | B12: 45.720266 | C12: 29.094755 | D12: 48.628132 | E12: 56.066964 | F12: 47.311774 | G12: 52.664464
A13: p204-3 | B13: 49.265077 | C13: 33.015357 | D13: 47.750712 | E13: 50.291336 | F13: 41.617333 | G13: 50.3553
... A33: p408-3 | B33: 43.589635 | C33: 31.437028 | D33: 46.98226 | E33: 54.746675 | F33: 48.114182 | G33: 39.781649
A34: p902-3 | D34: 55.488778 | E34: 69.782426 | F34: 64.983229 | G34: 53.582683
A35: p904-3 | B35: 50.011455 | C35: 63.248221 | D35: 59.472183 | E35: 65.960918 | F35: 67.014009 | G35: 65.142955
A36: p906-3 | D36: 53.371204 | E36: 63.013647 | F36: 55.90833 | G36: 53.691652
A37: p908-3 | B37: 43.681735 | C37: 61.362339 | D37: 58.869671 | E37: 64.035631 | F37: 64.817312 | G37: 63.929381

Sheet Density
A1: CCID | B1: PLPD
A2: p101-1 | B2: 4.7982283
A3: p101-2 | B3: 5.4133858
A4: p101-3 | B4: 5.2903543
A5: p101-4 | B5: 4.9212598
A6: p101-5 | B6: 5.7824803
A7: p101-6 | B7: 4.9212598
A8: p102-1 | B8: 12.467192
A9: p102-2 | B9: 7.5459318
A10: p102-3 | B10: 6.0695538
A11: p102-4 | B11: 8.0380577
A12: p102-5 | B12: 9.8425197
A13: p102-6 | B13: 11.154856
... A217: p908-6 | B217: 12.467192

Sheet Develop
A1: CCID | B1: EDATE | C1: PLYRE | D1: PLDOE
A2: p101-1 | B2: 37736 | C2: 2003 | D2: 114.5
A3: p101-2 | B3: 37736 | C3: 2003 | D3: 114.53571
A4: p101-3 | B4: 37737 | C4: 2003 | D4: 116.43182
A5: p101-4 | B5: 37739 | C5: 2003 | D5: 117.75
A6: p101-5 | B6: 37739 | C6: 2003 | D6: 118.01562
A7: p101-6 | B7: 37736 | C7: 2003 | D7: 114.83333
A8: p102-1 | B8: 37736 | C8: 2003 | D8: 114.52778
A9: p102-2 | B9: 37738 | C9: 2003 | D9: 117
A10: p102-3 | B10: 37739 | C10: 2003 | D10: 118.08333
A11: p102-4 | B11: 37739 | C11: 2003 | D11: 118.23333
A12: p102-5 | B12: 37739 | C12: 2003 | D12: 118.13462
A13: p102-6 | B13: 37734 | C13: 2003 | D13: 113.25
... A17: p103-4 | B17: 37734 | C17: 2003 | D17: 113.1875
A18: p103-5
A19: p103-6
A20: p104-1 | B20: 37736 | C20: 2003 | D20: 115.27273
A21: p104-2 | B21: 37735 | C21: 2003 | D21: 114.125
A22: p104-3 | B22: 37736 | C22: 2003 | D22: 114.875
A23: p104-4 | B23: 37737 | C23: 2003 | D23: 116.3125
A24: p104-5 | B24: 37735 | C24: 2003 | D24: 114.45
A25: p104-6 | B25: 37735 | C25: 2003 | D25: 114.125
A26: p105-1 | B26: 37735 | C26: 2003 | D26: 113.75
A27: p105-2 | B27: 37736 | C27: 2003 | D27: 115
A28: p105-3 | B28: 37735 | C28: 2003 | D28: 114.10714
A29: p105-4 | B29: 37735 | C29: 2003 | D29: 114.27778
A30: p105-5 | B30: 37735 | C30: 2003 | D30: 113.59375
A31: p105-6 | B31: 37734 | C31: 2003 | D31: 112.8
... A37: p106-6 | B37: 37734 | C37: 2003 | D37: 113.4375
A38: p107-1
A39: p107-2 | B39: 37735 | C39: 2003 | D39: 113.54167
A40: p107-3 | B40: 37734 | C40: 2003 | D40: 112.5
A41: p107-4 | B41: 37734 | C41: 2003 | D41: 113.25
A42: p107-5 | B42: 37735 | C42: 2003 | D42: 113.58333
A43: p107-6 | B43: 37735 | C43: 2003 | D43: 114
A44: p108-1 | B44: 37733 | C44: 2003 | D44: 111.625
A45: p108-2 | B45: 37735 | C45: 2003 | D45: 114
A46: p108-3 | B46: 37736 | C46: 2003 | D46: 114.55
A47: p108-4 | B47: 37735 | C47: 2003 | D47: 114.34375
A48: p108-5 | B48: 37734 | C48: 2003 | D48: 112.75
...

Sheet PlotDevelop
A1: Plot | B1: EDATE | C1: PLYRE | D1: PLDOE
A2: p101 | B2: 37737 | C2: 2003 | D2: 116.01108
A3: p102 | B3: 37737 | C3: 2003 | D3: 116.53818
A4: p103 | B4: 37734 | C4: 2003 | D4: 113.00104
A5: p104 | B5: 37735 | C5: 2003 | D5: 114.86004
A6: p105 | B6: 37735 | C6: 2003 | D6: 113.92145
A7: p106 | B7: 37734 | C7: 2003 | D7: 113.49554
A8: p107 | B8: 37734 | C8: 2003 | D8: 113.375
A9: p108 | B9: 37734 | C9: 2003 | D9: 113.35729
A10: p201 | B10: 37735 | C10: 2003 | D10: 114.42024
A11: p202 | B11: 37736 | C11: 2003 | D11: 115.45627
A12: p203 | B12: 37734 | C12: 2003 | D12: 113.37029
A13: p204 | B13: 37733 | C13: 2003 | D13: 112.68874
... A37: p908 | B37: 37737 | C37: 2003 | D37: 115.93631

Sheet HgtDOY168
A1: FISE2003 Plant Cover and Heights
X2: Date: | Y2: 37789
B3: Comments: | J3: stacy measured,carrie wrote,suzette carried stick
X4: By: | Y4: sr,cob,sm
AT5: Legend
B6: Plot | C6: Acron | D6: Trt. | E6: Irrig. | F6: Pop. | G6: N | H6: Block | I6: Exotech Code | J6: Time | K6: Meas. | L6: Row 3 | N6: Row 4 | P6: Row 5 (Picture Row) | U6: Row 6 | W6: Row 7 | Y6: Row 8 | AA6: PictureRow Mean | AB6: Plot Mean | AC6: Plot SE | AT6: Irrigation
J7: Position ⇒ | L7: 25 cm | M7: 75 cm | N7: 25 cm | O7: 75 cm | P7: 0 cm | Q7: 25 cm | R7: 50 cm | S7: 75 cm | T7: 100 cm | U7: 25 cm | V7: 75 cm | W7: 25 cm | X7: 75 cm | Y7: 25 cm | Z7: 75 cm | AT7: Code | AU7: Schedule | AV7: notes
B8: Plot | C8: Acron | D8: Trt | E8: Irr | F8: Pop | G8: Nit | H8: Block | I8: ExotechCode | J8: Time | K8: Meas | L8: 3.25 | M8: 3.75 | N8: 4.25 | O8: 4.75 | P8: 5.00 | Q8: 5.25 | R8: 5.50 | S8: 5.75 | T8: 5.100 | U8: 6.25 | V8: 6.75 | W8: 7.25 | X8: 7.75 | Y8: 8.25 | Z8: 8.75 | AA8: PicRowMean | AB8: PlotMean | AC8: PlotSE
B9: 108 | C9: FTH | D9: 3 | E9: 1 | F9: 2 | G9: 2 | H9: 2 | I9: 122.2 | J9: 0.45138889 | K9: Cover | L9: 42 | N9: 46 | P9: 44 | Q9: 44 | R9: 41 | S9: 48 | T9: 47 | U9: 56 | W9: 56 | Y9: 39 | AA9: =AVERAGE(P9:U9) -> 46.666667 | AB9: =AVERAGE(AVERAGE(L9:M9),AVERAGE(N9:O9),AVERAGE(P9:U9),AVERAGE(U9:V9),AVERAGE(W9:X9),AVERAGE(Y9:Z9)) -> 47.611111 | AC9: =STDEV(AVERAGE(L9:M9),AVERAGE(N9:O9),AVERAGE(P9:U9),AVERAGE(U9:V9),AVERAGE(W9:X9),AVERAGE(Y9:Z9))/SQRT(6) -> 2.8860028 | AT9: 1 | AU9: FAO
B10: 108 | C10: FTH | D10: 3 | E10: 1 | F10: 2 | G10: 2 | H10: 2 | I10: 122.2 | K10: Height | L10: 41 | N10: 37 | P10: 32 | Q10: 32 | R10: 35 | S10: 39 | T10: 40 | U10: 36.5 | W10: 36.5 | Y10: 45 | AA10: =AVERAGE(P10:U10) -> 35.75 | AB10: =AVERAGE(AVERAGE(L10:M10),AVERAGE(N10:O10),AVERAGE(P10:U10),AVERAGE(U10:V10),AVERAGE(W10:X10),AVERAGE(Y10:Z10)) -> 38.625 | AC10: =STDEV(AVERAGE(L10:M10),AVERAGE(N10:O10),AVERAGE(P10:U10),AVERAGE(U10:V10),AVERAGE(W10:X10),AVERAGE(Y10:Z10))/SQRT(6) -> 1.4856957 | AT10: 2 | AU10: NDVI
B11: =B9-1 -> 107 | C11: NTL | D11: 10 | E11: 2 | F11: 2 | G11: 1 | H11: 2 | I11: 221.2 | K11: Cover | L11: 45 | N11: 50 | P11: 52 | Q11: 42 | R11: 45 | S11: 50 | T11: 59 | U11: 48 | W11: 48 | Y11: 49 | AA11: =AVERAGE(P11:U11) -> 49.333333 | AB11: =AVERAGE(AVERAGE(L11:M11),AVERAGE(N11:O11),AVERAGE(P11:U11),AVERAGE(U11:V11),AVERAGE(W11:X11),AVERAGE(Y11:Z11)) -> 48.222222 | AC11: =STDEV(AVERAGE(L11:M11),AVERAGE(N11:O11),AVERAGE(P11:U11),AVERAGE(U11:V11),AVERAGE(W11:X11),AVERAGE(Y11:Z11))/SQRT(6) -> 0.71836577 | AT11: 3 | AU11: None>1Jun | AV11: ad hoc
B12: =B10-1 -> 107 | C12: NTL | D12: 10 | E12: 2 | F12: 2 | G12: 1 | H12: 2 | I12: 221.2 | K12: Height | L12: 35 | N12: 47 | P12: 32 | Q12: 32 | R12: 29 | S12: 31 | T12: 32 | U12: 42 | W12: 42 | Y12: 34 | AA12: =AVERAGE(P12:U12) -> 33 | AB12: =AVERAGE(AVERAGE(L12:M12),AVERAGE(N12:O12),AVERAGE(P12:U12),AVERAGE(U12:V12),AVERAGE(W12:X12),AVERAGE(Y12:Z12)) -> 38.833333 | AC12: =STDEV(AVERAGE(L12:M12),AVERAGE(N12:O12),AVERAGE(P12:U12),AVERAGE(U12:V12),AVERAGE(W12:X12),AVERAGE(Y12:Z12))/SQRT(6) -> 2.300966 | AT12: 4 | AU12: None>15Jul | AV12: ad hoc
B13: =B11-1 -> 106 | C13: NTH | D13: 9 | E13: 2 | F13: 2 | G13: 2 | H13: 2 | I13: 222.2 | K13: Cover | L13: 50 | N13: 42 | P13: 59 | Q13: 44 | R13: 40 | S13: 52 | T13: 52 | U13: 45 | W13: 45 | Y13: 42 | AA13: =AVERAGE(P13:U13) -> 48.666667 | AB13: =AVERAGE(AVERAGE(L13:M13),AVERAGE(N13:O13),AVERAGE(P13:U13),AVERAGE(U13:V13),AVERAGE(W13:X13),AVERAGE(Y13:Z13)) -> 45.444444 | AC13: =STDEV(AVERAGE(L13:M13),AVERAGE(N13:O13),AVERAGE(P13:U13),AVERAGE(U13:V13),AVERAGE(W13:X13),AVERAGE(Y13:Z13))/SQRT(6) -> 1.3571939 | AT13: 8 | AU13: Dry Soil | AV13: never
B14: =B12-1 -> 106 | C14: NTH | D14: 9 | E14: 2 | F14: 2 | G14: 2 | H14: 2 | I14: 222.2 | K14: Height | L14: 37 | N14: 42 | P14: 38 | Q14: 33 | R14: 25 | S14: 37 | T14: 34 | U14: 40 | W14: 40 | Y14: 37.5 | AA14: =AVERAGE(P14:U14) -> 34.5 | AB14: =AVERAGE(AVERAGE(L14:M14),AVERAGE(N14:O14),AVERAGE(P14:U14),AVERAGE(U14:V14),AVERAGE(W14:X14),AVERAGE(Y14:Z14)) -> 38.5 | AC14: =STDEV(AVERAGE(L14:M14),AVERAGE(N14:O14),AVERAGE(P14:U14),AVERAGE(U14:V14),AVERAGE(W14:X14),AVERAGE(Y14:Z14))/SQRT(6) -> 1.0954451 | AT14: 9 | AU14: Wet Soil | AV14: often
B15: =B13-1 -> 105 | C15: NDL | D15: 12 | E15: 2 | F15: 3 | G15: 1 | H15: 2 | I15: 231.2 | K15: Cover | L15: 68 | N15: 67 | P15: 70 | Q15: 72 | R15: 73 | U15: 60 | W15: 60 | Y15: 68 | AA15: =AVERAGE(P15:U15) -> 68.75 | AB15: =AVERAGE(AVERAGE(L15:M15),AVERAGE(N15:O15),AVERAGE(P15:U15),AVERAGE(U15:V15),AVERAGE(W15:X15),AVERAGE(Y15:Z15)) -> 65.291667 | AC15: =STDEV(AVERAGE(L15:M15),AVERAGE(N15:O15),AVERAGE(P15:U15),AVERAGE(U15:V15),AVERAGE(W15:X15),AVERAGE(Y15:Z15))/SQRT(6) -> 1.6887084
B16: =B14-1 -> 105 | C16: NDL | D16: 12 | E16: 2 | F16: 3 | G16: 1 | H16: 2 | I16: 231.2 | K16: Height | L16: 34 | N16: 38 | P16: 38 | Q16: 33 | R16: 32 | U16: 35.5 | W16: 35.5 | Y16: 32 | AA16: =AVERAGE(P16:U16) -> 34.625 | AB16: =AVERAGE(AVERAGE(L16:M16),AVERAGE(N16:O16),AVERAGE(P16:U16),AVERAGE(U16:V16),AVERAGE(W16:X16),AVERAGE(Y16:Z16)) -> 34.9375 | AC16: =STDEV(AVERAGE(L16:M16),AVERAGE(N16:O16),AVERAGE(P16:U16),AVERAGE(U16:V16),AVERAGE(W16:X16),AVERAGE(Y16:Z16))/SQRT(6) -> 0.8086447 | AT16: Population
B17: =B15-1 -> 104 | C17: NTL | D17: 10 | E17: 2 | F17: 2 | G17: 1 | H17: 1 | I17: 221.1 | K17: Cover | L17: 45 | N17: 60 | P17: 56 | Q17: 45 | R17: 53 | S17: 60 | T17: 41 | U17: 49 | W17: 49 | Y17: 49 | AA17: =AVERAGE(P17:U17) -> 50.666667 | AB17: =AVERAGE(AVERAGE(L17:M17),AVERAGE(N17:O17),AVERAGE(P17:U17),AVERAGE(U17:V17),AVERAGE(W17:X17),AVERAGE(Y17:Z17)) -> 50.444444 | AC17: =STDEV(AVERAGE(L17:M17),AVERAGE(N17:O17),AVERAGE(P17:U17),AVERAGE(U17:V17),AVERAGE(W17:X17),AVERAGE(Y17:Z17))/SQRT(6) -> 2.0596056 | AT17: Code | AU17: no./meter | AV17: lines/bed
B18: =B16-1 -> 104 | C18: NTL | D18: 10 | E18: 2 | F18: 2 | G18: 1 | H18: 1 | I18: 221.1 | K18: Height | L18: 36 | N18: 40 | P18: 37.5 | Q18: 29 | R18: 30 | S18: 45 | T18: 37 | U18: 35 | W18: 35 | Y18: 38 | AA18: =AVERAGE(P18:U18) -> 35.583333 | AB18: =AVERAGE(AVERAGE(L18:M18),AVERAGE(N18:O18),AVERAGE(P18:U18),AVERAGE(U18:V18),AVERAGE(W18:X18),AVERAGE(Y18:Z18)) -> 36.597222 | AC18: =STDEV(AVERAGE(L18:M18),AVERAGE(N18:O18),AVERAGE(P18:U18),AVERAGE(U18:V18),AVERAGE(W18:X18),AVERAGE(Y18:Z18))/SQRT(6) -> 0.81718143 | AT18: 0 | AU18: 0 | AV18: na
B19: =B17-1 -> 103 | C19: FDH | D19: 5 | E19: 1 | F19: 3 | G19: 2 | H19: 1 | I19: 132.1 | K19: Cover | L19: 70 | N19: 71 | P19: 67 | Q19: 70 | R19: 61 | S19: 66 | T19: 65 | U19: 63 | W19: 63 | Y19: 60 | AA19: =AVERAGE(P19:U19) -> 65.333333 | AB19: =AVERAGE(AVERAGE(L19:M19),AVERAGE(N19:O19),AVERAGE(P19:U19),AVERAGE(U19:V19),AVERAGE(W19:X19),AVERAGE(Y19:Z19)) -> 65.388889 | AC19: =STDEV(AVERAGE(L19:M19),AVERAGE(N19:O19),AVERAGE(P19:U19),AVERAGE(U19:V19),AVERAGE(W19:X19),AVERAGE(Y19:Z19))/SQRT(6) -> 1.7626089 | AT19: 1 | AU19: 5 | AV19: Single
B20: =B18-1 -> 103 | C20: FDH | D20: 5 | E20: 1 | F20: 3 | G20: 2 | H20: 1 | I20: 132.1 | K20: Height | L20: 35 | N20: 35 | P20: 39 | Q20: 38 | R20: 37 | S20: 36 | T20: 42 | U20: 34 | W20: 34 | Y20: 38 | AA20: =AVERAGE(P20:U20) -> 37.666667 | AB20: =AVERAGE(AVERAGE(L20:M20),AVERAGE(N20:O20),AVERAGE(P20:U20),AVERAGE(U20:V20),AVERAGE(W20:X20),AVERAGE(Y20:Z20)) -> 35.611111 | AC20: =STDEV(AVERAGE(L20:M20),AVERAGE(N20:O20),AVERAGE(P20:U20),AVERAGE(U20:V20),AVERAGE(W20:X20),AVERAGE(Y20:Z20))/SQRT(6) -> 0.72733235 | AT20: 2 | AU20: 10 | AV20: Single
B21: =B19-1 -> 102 | C21: FTL | D21: 4 | E21: 1 | F21: 2 | G21: 1 | H21: 1 | I21: 121.1 | K21: Cover | L21: 46 | N21: 45 | P21: 37 | Q21: 40 | R21: 25 | S21: 0 | T21: 32 | U21: 38 | W21: 38 | Y21: 51 | AA21: =AVERAGE(P21:U21) -> 28.666667 | AB21: =AVERAGE(AVERAGE(L21:M21),AVERAGE(N21:O21),AVERAGE(P21:U21),AVERAGE(U21:V21),AVERAGE(W21:X21),AVERAGE(Y21:Z21)) -> 41.111111 | AC21: =STDEV(AVERAGE(L21:M21),AVERAGE(N21:O21),AVERAGE(P21:U21),AVERAGE(U21:V21),AVERAGE(W21:X21),AVERAGE(Y21:Z21))/SQRT(6) -> 3.2199226 | AT21: 3 | AU21: 20 | AV21: Double
B22: =B20-1 -> 102 | C22: FTL | D22: 4 | E22: 1 | F22: 2 | G22: 1 | H22: 1 | I22: 121.1 | K22: Height | L22: 34 | N22: 32 | P22: 31 | Q22: 31 | R22: 17 | S22: 0 | T22: 20 | U22: 33 | W22: 33 | Y22: 32 | AA22: =AVERAGE(P22:U22) -> 22 | AB22: =AVERAGE(AVERAGE(L22:M22),AVERAGE(N22:O22),AVERAGE(P22:U22),AVERAGE(U22:V22),AVERAGE(W22:X22),AVERAGE(Y22:Z22)) -> 31 | AC22: =STDEV(AVERAGE(L22:M22),AVERAGE(N22:O22),AVERAGE(P22:U22),AVERAGE(U22:V22),AVERAGE(W22:X22),AVERAGE(Y22:Z22))/SQRT(6) -> 1.8257419
B23: =B21-1 -> 101 | C23: FSH | D23: 1 | E23: 1 | F23: 1 | G23: 2 | H23: 1 | I23: 112.1 | K23: Cover | L23: 39 | N23: 53 | P23: 40 | Q23: 38 | R23: 41 | S23: 43 | T23: 52 | U23: 35 | W23: 35 | Y23: 44 | AA23: =AVERAGE(P23:U23) -> 41.5 | AB23: =AVERAGE(AVERAGE(L23:M23),AVERAGE(N23:O23),AVERAGE(P23:U23),AVERAGE(U23:V23),AVERAGE(W23:X23),AVERAGE(Y23:Z23)) -> 41.25 | AC23: =STDEV(AVERAGE(L23:M23),AVERAGE(N23:O23),AVERAGE(P23:U23),AVERAGE(U23:V23),AVERAGE(W23:X23),AVERAGE(Y23:Z23))/SQRT(6) -> 2.7620946 | AT23: Nitrogen
B24: =B22-1 -> 101 | C24: FSH | D24: 1 | E24: 1 | F24: 1 | G24: 2 | H24: 1 | I24: 112.1 | K24: Height | L24: 35 | N24: 35 | P24: 33 | Q24: 30 | R24: 34 | S24: 26 | T24: 33 | U24: 26 | W24: 26 | Y24: 32 | AA24: =AVERAGE(P24:U24) -> 30.333333 | AB24: =AVERAGE(AVERAGE(L24:M24),AVERAGE(N24:O24),AVERAGE(P24:U24),AVERAGE(U24:V24),AVERAGE(W24:X24),AVERAGE(Y24:Z24)) -> 30.722222 | AC24: =STDEV(AVERAGE(L24:M24),AVERAGE(N24:O24),AVERAGE(P24:U24),AVERAGE(U24:V24),AVERAGE(W24:X24),AVERAGE(Y24:Z24))/SQRT(6) -> 1.6631444 | AT24: Code | AU24: Descript | AV24: kg N/ha
B25: =B23+100 -> 201 | C25: NDL | D25: 12 | E25: 2 | F25: 3 | G25: 1 | H25: 1 | I25: 231.1 | J25: 0.46666667 | K25: Cover | L25: 69 | N25: 74 | O25: wet | P25: 71 | Q25: 70 | R25: 69 | U25: 65 | W25: 65 | Y25: 61 | AA25: =AVERAGE(P25:U25) -> 68.75 | AB25: =AVERAGE(AVERAGE(L25:M25),AVERAGE(N25:O25),AVERAGE(P25:U25),AVERAGE(U25:V25),AVERAGE(W25:X25),AVERAGE(Y25:Z25)) -> 67.125 | AC25: =STDEV(AVERAGE(L25:M25),AVERAGE(N25:O25),AVERAGE(P25:U25),AVERAGE(U25:V25),AVERAGE(W25:X25),AVERAGE(Y25:Z25))/SQRT(6) -> 1.8254566 | AT25: 1 | AU25: Low | AV25: 0
B26: =B24+100 -> 201 | C26: NDL | D26: 12 | E26: 2 | F26: 3 | G26: 1 | H26: 1 | I26: 231.1 | K26: Height | L26: 38 | N26: 38 | O26: 0.51527778 | P26: 31 | Q26: 38 | R26: 33 | U26: 42 | W26: 42 | Y26: 37 | AA26: =AVERAGE(P26:T26) -> 34 | AB26: =AVERAGE(AVERAGE(L26:M26),AVERAGE(N26:O26),AVERAGE(P26:T26),AVERAGE(U26:V26),AVERAGE(W26:X26),AVERAGE(Y26:Z26)) -> 35.376273 | AC26: =STDEV(AVERAGE(L26:M26),AVERAGE(N26:O26),AVERAGE(P26:T26),AVERAGE(U26:V26),AVERAGE(W26:X26),AVERAGE(Y26:Z26))/SQRT(6) -> 3.4591543 | AT26: 2 | AU26: High | AV26: 150
B27: =B25+1 -> 202 | C27: NTH | D27: 9 | E27: 2 | F27: 2 | G27: 2 | H27: 1 | I27: 222.1 | K27: Cover | L27: 44 | N27: 50 | P27: 47 | Q27: 51 | R27: 51 | S27: 45 | T27: 58 | U27: 53 | W27: 53 | Y27: 49 | AA27: =AVERAGE(P27:U27) -> 50.833333 | AB27: =AVERAGE(AVERAGE(L27:M27),AVERAGE(N27:O27),AVERAGE(P27:U27),AVERAGE(U27:V27),AVERAGE(W27:X27),AVERAGE(Y27:Z27)) -> 49.972222 | AC27: =STDEV(AVERAGE(L27:M27),AVERAGE(N27:O27),AVERAGE(P27:U27),AVERAGE(U27:V27),AVERAGE(W27:X27),AVERAGE(Y27:Z27))/SQRT(6) -> 1.362471
B28: =B26+1 -> 202 | C28: NTH | D28: 9 | E28: 2 | F28: 2 | G28: 2 | H28: 1 | I28: 222.1 | K28: Height | L28: 40 | N28: 35 | P28: 28 | Q28: 30 | R28: 27 | S28: 38 | T28: 33 | U28: 41 | W28: 41 | Y28: 41 | AA28: =AVERAGE(P28:U28) -> 32.833333 | AB28: =AVERAGE(AVERAGE(L28:M28),AVERAGE(N28:O28),AVERAGE(P28:U28),AVERAGE(U28:V28),AVERAGE(W28:X28),AVERAGE(Y28:Z28)) -> 38.472222 | AC28: =STDEV(AVERAGE(L28:M28),AVERAGE(N28:O28),AVERAGE(P28:U28),AVERAGE(U28:V28),AVERAGE(W28:X28),AVERAGE(Y28:Z28))/SQRT(6) -> 1.475991
B29: =B27+1 -> 203 | C29: FTH | D29: 3 | E29: 1 | F29: 2 | G29: 2 | H29: 1 | I29: 122.1 | K29: Cover | L29: 41 | N29: 59 | P29: 55 | Q29: 53 | R29: 53 | S29: 48 | T29: 43 | U29: 56 | W29: 56 | Y29: 50 | AA29: =AVERAGE(P29:U29) -> 51.333333 | AB29: =AVERAGE(AVERAGE(L29:M29),AVERAGE(N29:O29),AVERAGE(P29:U29),AVERAGE(U29:V29),AVERAGE(W29:X29),AVERAGE(Y29:Z29)) -> 52.222222 | AC29: =STDEV(AVERAGE(L29:M29),AVERAGE(N29:O29),AVERAGE(P29:U29),AVERAGE(U29:V29),AVERAGE(W29:X29),AVERAGE(Y29:Z29))/SQRT(6) -> 2.6213746
B30: =B28+1 -> 203 | C30: FTH | D30: 3 | E30: 1 | F30: 2 | G30: 2 | H30: 1 | I30: 122.1 | K30: Height | L30: 27.5 | N30: 35 | P30: 38 | Q30: 42 | R30: 40 | S30: 36 | T30: 37 | U30: 46 | W30: 46 | Y30: 32 | AA30: =AVERAGE(P30:U30) -> 39.833333 | AB30: =AVERAGE(AVERAGE(L30:M30),AVERAGE(N30:O30),AVERAGE(P30:U30),AVERAGE(U30:V30),AVERAGE(W30:X30),AVERAGE(Y30:Z30)) -> 37.722222 | AC30: =STDEV(AVERAGE(L30:M30),AVERAGE(N30:O30),AVERAGE(P30:U30),AVERAGE(U30:V30),AVERAGE(W30:X30),AVERAGE(Y30:Z30))/SQRT(6) -> 3.0884092
B31: =B29+1 -> 204 | C31: NDH | D31: 11 | E31: 2 | F31: 3 | G31: 2 | H31: 1 | I31: 232.1 | K31: Cover | L31: 72 | N31: 73 | O31: wet | P31: 78 | Q31: 71 | R31: 61 | U31: 46 | W31: 69 | Y31: 77 | AA31: =AVERAGE(P31:U31) -> 64 | AB31: =AVERAGE(AVERAGE(L31:M31),AVERAGE(N31:O31),AVERAGE(P31:U31),AVERAGE(U31:V31),AVERAGE(W31:X31),AVERAGE(Y31:Z31)) -> 66.833333 | AC31: =STDEV(AVERAGE(L31:M31),AVERAGE(N31:O31),AVERAGE(P31:U31),AVERAGE(U31:V31),AVERAGE(W31:X31),AVERAGE(Y31:Z31))/SQRT(6) -> 4.527079
B32: =B30+1 -> 204 | C32: NDH | D32: 11 | E32: 2 | F32: 3 | G32: 2 | H32: 1 | I32: 232.1 | K32: Height | L32: 41 | N32: 38 | P32: 30 | Q32: 34 | R32: 30 | U32: 69 | W32: 43 | Y32: 43 | AA32: =AVERAGE(P32:U32) -> 40.75 | AB32: =AVERAGE(AVERAGE(L32:M32),AVERAGE(N32:O32),AVERAGE(P32:U32),AVERAGE(U32:V32),AVERAGE(W32:X32),AVERAGE(Y32:Z32)) -> 45.791667 | AC32: =STDEV(AVERAGE(L32:M32),AVERAGE(N32:O32),AVERAGE(P32:U32),AVERAGE(U32:V32),AVERAGE(W32:X32),AVERAGE(Y32:Z32))/SQRT(6) -> 4.7021346
B33: =B31+1 -> 205 | C33: FSH | D33: 1 | E33: 1 | F33: 1 | G33: 2 | H33: 2 | I33: 112.2 | K33: Cover | L33: 38 | N33: 41 | P33: 35 | Q33: 51 | R33: 52 | S33: 36 | T33: 49 | U33: 38 | W33: 59 | Y33: 48 | AA33: =AVERAGE(P33:U33) -> 43.5 | AB33: =AVERAGE(AVERAGE(L33:M33),AVERAGE(N33:O33),AVERAGE(P33:U33),AVERAGE(U33:V33),AVERAGE(W33:X33),AVERAGE(Y33:Z33)) -> 44.583333 | AC33: =STDEV(AVERAGE(L33:M33),AVERAGE(N33:O33),AVERAGE(P33:U33),AVERAGE(U33:V33),AVERAGE(W33:X33),AVERAGE(Y33:Z33))/SQRT(6) -> 3.2670493
B34: =B32+1 -> 205 | C34: FSH | D34: 1 | E34: 1 | F34: 1 | G34: 2 | H34: 2 | I34: 112.2 | K34: Height | L34: 27 | N34: 38 | P34: 29 | Q34: 28 | R34: 32 | S34: 31 | T34: 36 | U34: 26 | W34: 43 | Y34: 33 | AA34: =AVERAGE(P34:U34) -> 30.333333 | AB34: =AVERAGE(AVERAGE(L34:M34),AVERAGE(N34:O34),AVERAGE(P34:U34),AVERAGE(U34:V34),AVERAGE(W34:X34),AVERAGE(Y34:Z34)) -> 32.888889 | AC34: =STDEV(AVERAGE(L34:M34),AVERAGE(N34:O34),AVERAGE(P34:U34),AVERAGE(U34:V34),AVERAGE(W34:X34),AVERAGE(Y34:Z34))/SQRT(6) -> 2.6897152
B35: =B33+1 -> 206 | C35: NSL | D35: 8 | E35: 2 | F35: 1 | G35: 1 | H35: 2 | I35: 211.2 | K35: Cover | L35: 33 | N35: 39 | O35: wet | P35: 35 | Q35: 44 | R35: 46 | U35: 48 | W35: 42 | Y35: 41 | AA35: =AVERAGE(P35:U35) -> 43.25 | AB35: =AVERAGE(AVERAGE(L35:M35),AVERAGE(N35:O35),AVERAGE(P35:U35),AVERAGE(U35:V35),AVERAGE(W35:X35),AVERAGE(Y35:Z35)) -> 41.041667 | AC35: =STDEV(AVERAGE(L35:M35),AVERAGE(N35:O35),AVERAGE(P35:U35),AVERAGE(U35:V35),AVERAGE(W35:X35),AVERAGE(Y35:Z35))/SQRT(6) -> 2.0252743
B36: =B34+1 -> 206 | C36: NSL | D36: 8 | E36: 2 | F36: 1 | G36: 1 | H36: 2 | I36: 211.2 | K36: Height | L36: 28 | N36: 32 | P36: 25 | Q36: 32 | R36: 41 | U36: 34 | W36: 36 | Y36: 30 | AA36: =AVERAGE(P36:U36) -> 33 | AB36: =AVERAGE(AVERAGE(L36:M36),AVERAGE(N36:O36),AVERAGE(P36:U36),AVERAGE(U36:V36),AVERAGE(W36:X36),AVERAGE(Y36:Z36)) -> 32.166667 | AC36: =STDEV(AVERAGE(L36:M36),AVERAGE(N36:O36),AVERAGE(P36:U36),AVERAGE(U36:V36),AVERAGE(W36:X36),AVERAGE(Y36:Z36))/SQRT(6) -> 1.1666667
B37: =B35+1 -> 207 | C37: FTL | D37: 4 | E37: 1 | F37: 2 | G37: 1 | H37: 2 | I37: 121.2 | K37: Cover | L37: 54 | N37: 55 | P37: 60 | Q37: 49 | R37: 53 | S37: 50 | T37: 53 | U37: 62 | W37: 53 | Y37: 58 | AA37: =AVERAGE(P37:U37) -> 54.5 | AB37: =AVERAGE(AVERAGE(L37:M37),AVERAGE(N37:O37),AVERAGE(P37:U37),AVERAGE(U37:V37),AVERAGE(W37:X37),AVERAGE(Y37:Z37)) -> 56.083333 | AC37: =STDEV(AVERAGE(L37:M37),AVERAGE(N37:O37),AVERAGE(P37:U37),AVERAGE(U37:V37),AVERAGE(W37:X37),AVERAGE(Y37:Z37))/SQRT(6) -> 1.3687991
B38: =B36+1 -> 207 | C38: FTL | D38: 4 | E38: 1 | F38: 2 | G38: 1 | H38: 2 | I38: 121.2 | K38: Height | L38: 38 | N38: 43 | P38: 36 | Q38: 33 | R38: 38 | S38: 39 | T38: 38 | U38: 46 | W38: 42 | Y38: 41 | AA38: =AVERAGE(P38:U38) -> 38.333333 | AB38: =AVERAGE(AVERAGE(L38:M38),AVERAGE(N38:O38),AVERAGE(P38:U38),AVERAGE(U38:V38),AVERAGE(W38:X38),AVERAGE(Y38:Z38)) -> 41.388889 | AC38: =STDEV(AVERAGE(L38:M38),AVERAGE(N38:O38),AVERAGE(P38:U38),AVERAGE(U38:V38),AVERAGE(W38:X38),AVERAGE(Y38:Z38))/SQRT(6) -> 1.2275138
B39: =B37+1 -> 208 | C39: FSL | D39: 2 | E39: 1 | F39: 1 | G39: 1 | H39: 2 | I39: 111.2 | K39: Cover | L39: 41 | N39: 47 | P39: 37 | Q39: 0 | R39: 36 | S39: 22 | T39: 19 | U39: 44 | W39: 40 | Y39: 39 | AA39: =AVERAGE(P39:U39) -> 26.333333 | AB39: =AVERAGE(AVERAGE(L39:M39),AVERAGE(N39:O39),AVERAGE(P39:U39),AVERAGE(U39:V39),AVERAGE(W39:X39),AVERAGE(Y39:Z39)) -> 39.555556 | AC39: =STDEV(AVERAGE(L39:M39),AVERAGE(N39:O39),AVERAGE(P39:U39),AVERAGE(U39:V39),AVERAGE(W39:X39),AVERAGE(Y39:Z39))/SQRT(6) -> 2.9016811
B40: =B38+1 -> 208 | C40: FSL | D40: 2 | E40: 1 | F40: 1 | G40: 1 | H40: 2 | I40: 111.2 | K40: Height | L40: 29 | N40: 36 | P40: 29 | Q40: 0 | R40: 26 | S40: 18 | T40: 13 | U40: 32 | W40: 41 | Y40: 28 | AA40: =AVERAGE(P40:U40) -> 19.666667 | AB40: =AVERAGE(AVERAGE(L40:M40),AVERAGE(N40:O40),AVERAGE(P40:U40),AVERAGE(U40:V40),AVERAGE(W40:X40),AVERAGE(Y40:Z40)) -> 30.944444 | AC40: =STDEV(AVERAGE(L40:M40),AVERAGE(N40:O40),AVERAGE(P40:U40),AVERAGE(U40:V40),AVERAGE(W40:X40),AVERAGE(Y40:Z40))/SQRT(6) -> 2.9856653
...

Sheet HgtDOY176
A1: FISE2003 Plant Cover and Heights
X2: Date: | Y2: 37797
B3: Comments: | J3: all NDVI plots were full of water .only one position in row 5 was collected because of the instability of the boards in the water.
J4: plots that have 3 measurements for row 5 did not have standing water in them, but they were too damp to walk in -50 cm was all I could reach from the board walk. | X4: By: | Y4: 176
AT5: Legend
B6: Plot | C6: Acron | D6: Trt. | E6: Irrig. | F6: Pop. | G6: N | H6: Block | I6: Exotech Code | J6: Time | K6: Meas. | L6: Row 3 | N6: Row 4 | P6: Row 5 (Picture Row) | U6: Row 6 | W6: Row 7 | Y6: Row 8 | AA6: PictureRow Mean | AB6: Plot Mean | AC6: Plot SE | AT6: Irrigation
J7: Position ⇒ | L7: 25 cm | M7: 75 cm | N7: 25 cm | O7: 75 cm | P7: 0 cm | Q7: 25 cm | R7: 50 cm | S7: 75 cm | T7: 100 cm | U7: 25 cm | V7: 75 cm | W7: 25 cm | X7: 75 cm | Y7: 25 cm | Z7: 75 cm | AT7: Code | AU7: Schedule | AV7: notes
B8: Plot | C8: Acron | D8: Trt | E8: Irr | F8: Pop | G8: Nit | H8: Block | I8: ExotechCode | J8: Time | K8: Meas | L8: 3.25 | M8: 3.75 | N8: 4.25 | O8: 4.75 | P8: 5.00 | Q8: 5.25 | R8: 5.50 | S8: 5.75 | T8: 5.100 | U8: 6.25 | V8: 6.75 | W8: 7.25 | X8: 7.75 | Y8: 8.25 | Z8: 8.75 | AA8: PicRowMean | AB8: PlotMean | AC8: PlotSE
B9: 108 | C9: FTH | D9: 3 | E9: 1 | F9: 2 | G9: 2 | H9: 2 | I9: 122.2 | K9: Cover | L9: 56 | N9: 58 | P9: 56 | Q9: 53 | R9: 53 | U9: 62 | W9: 63 | Y9: 56 | AA9: =AVERAGE(P9:U9) -> 56 | AB9: =AVERAGE(AVERAGE(L9:M9),AVERAGE(N9:O9),AVERAGE(P9:U9),AVERAGE(U9:V9),AVERAGE(W9:X9),AVERAGE(Y9:Z9)) -> 58.5 | AC9: =STDEV(AVERAGE(L9:M9),AVERAGE(N9:O9),AVERAGE(P9:U9),AVERAGE(U9:V9),AVERAGE(W9:X9),AVERAGE(Y9:Z9))/SQRT(6) -> 1.3102163 | AT9: 1 | AU9: FAO
B10: 108 | C10: FTH | D10: 3 | E10: 1 | F10: 2 | G10: 2 | H10: 2 | I10: 122.2 | K10: Height | L10: 52 | N10: 49 | P10: 42 | Q10: 45 | R10: 43 | U10: 50 | W10: 46 | Y10: 50 | AA10: =AVERAGE(P10:U10) -> 45 | AB10: =AVERAGE(AVERAGE(L10:M10),AVERAGE(N10:O10),AVERAGE(P10:U10),AVERAGE(U10:V10),AVERAGE(W10:X10),AVERAGE(Y10:Z10)) -> 48.666667 | AC10: =STDEV(AVERAGE(L10:M10),AVERAGE(N10:O10),AVERAGE(P10:U10),AVERAGE(U10:V10),AVERAGE(W10:X10),AVERAGE(Y10:Z10))/SQRT(6) -> 1.0852547 | AT10: 2 | AU10: NDVI
B11: =B9-1 -> 107 | C11: NTL | D11: 10 | E11: 2 | F11: 2 | G11: 1 | H11: 2 | I11: 221.2 | K11: Cover | L11: 58 | N11: 62 | Q11: 61 | U11: 61 | W11: 57 | Y11: 55 | AA11: =AVERAGE(P11:T11) -> 61 | AB11: =AVERAGE(AVERAGE(L11:M11),AVERAGE(N11:O11),AVERAGE(P11:T11),AVERAGE(U11:V11),AVERAGE(W11:X11),AVERAGE(Y11:Z11)) -> 59 | AC11: =STDEV(AVERAGE(L11:M11),AVERAGE(N11:O11),AVERAGE(P11:T11),AVERAGE(U11:V11),AVERAGE(W11:X11),AVERAGE(Y11:Z11))/SQRT(6) -> 1.1254629 | AT11: 3 | AU11: None>1Jun | AV11: ad hoc
B12: =B10-1 -> 107 | C12: NTL | D12: 10 | E12: 2 | F12: 2 | G12: 1 | H12: 2 | I12: 221.2 | K12: Height | L12: 48 | N12: 57 | Q12: 45 | U12: 52 | W12: 55 | Y12: 43 | AA12: =AVERAGE(P12:T12) -> 45 | AB12: =AVERAGE(AVERAGE(L12:M12),AVERAGE(N12:O12),AVERAGE(P12:T12),AVERAGE(U12:V12),AVERAGE(W12:X12),AVERAGE(Y12:Z12)) -> 50 | AC12: =STDEV(AVERAGE(L12:M12),AVERAGE(N12:O12),AVERAGE(P12:T12),AVERAGE(U12:V12),AVERAGE(W12:X12),AVERAGE(Y12:Z12))/SQRT(6) -> 2.2803509 | AT12: 4 | AU12: None>15Jul | AV12: ad hoc
B13: =B11-1 -> 106 | C13: NTH | D13: 9 | E13: 2 | F13: 2 | G13: 2 | H13: 2 | I13: 222.2 | K13: Cover | L13: 65 | N13: 51 | Q13: 58 | U13: 62 | W13: 63 | Y13: 66 | AA13: =AVERAGE(P13:T13) -> 58 | AB13: =AVERAGE(AVERAGE(L13:M13),AVERAGE(N13:O13),AVERAGE(P13:T13),AVERAGE(U13:V13),AVERAGE(W13:X13),AVERAGE(Y13:Z13)) -> 60.833333 | AC13: =STDEV(AVERAGE(L13:M13),AVERAGE(N13:O13),AVERAGE(P13:T13),AVERAGE(U13:V13),AVERAGE(W13:X13),AVERAGE(Y13:Z13))/SQRT(6) -> 2.2718079 | AT13: 8 | AU13: Dry Soil | AV13: never
B14: =B12-1 -> 106 | C14: NTH | D14: 9 | E14: 2 | F14: 2 | G14: 2 | H14: 2 | I14: 222.2 | K14: Height | L14: 46 | N14: 45 | Q14: 50 | U14: 43 | W14: 50 | Y14: 45 | AA14: =AVERAGE(P14:T14) -> 50 | AB14: =AVERAGE(AVERAGE(L14:M14),AVERAGE(N14:O14),AVERAGE(P14:T14),AVERAGE(U14:V14),AVERAGE(W14:X14),AVERAGE(Y14:Z14)) -> 46.5 | AC14: =STDEV(AVERAGE(L14:M14),AVERAGE(N14:O14),AVERAGE(P14:T14),AVERAGE(U14:V14),AVERAGE(W14:X14),AVERAGE(Y14:Z14))/SQRT(6) -> 1.1761519 | AT14: 9 | AU14: Wet Soil | AV14: often
B15: =B13-1 -> 105 | C15: NDL | D15: 12 | E15: 2 | F15: 3 | G15: 1 | H15: 2 | I15: 231.2 | K15: Cover | L15: 77 | N15: 61 | Q15: 72 | U15: 82 | W15: 78 | Y15: 72 | AA15: =AVERAGE(P15:T15) -> 72 | AB15: =AVERAGE(AVERAGE(L15:M15),AVERAGE(N15:O15),AVERAGE(P15:T15),AVERAGE(U15:V15),AVERAGE(W15:X15),AVERAGE(Y15:Z15)) -> 73.666667 | AC15: =STDEV(AVERAGE(L15:M15),AVERAGE(N15:O15),AVERAGE(P15:T15),AVERAGE(U15:V15),AVERAGE(W15:X15),AVERAGE(Y15:Z15))/SQRT(6) -> 2.9739611
B16: =B14-1 -> 105 | C16: NDL | D16: 12 | E16: 2 | F16: 3 | G16: 1 | H16: 2 | I16: 231.2 | K16: Height | L16: 50 | N16: 48 | Q16: 43 | U16: 45 | W16: 46 | Y16: 45 | AA16: =AVERAGE(P16:T16) -> 43 | AB16: =AVERAGE(AVERAGE(L16:M16),AVERAGE(N16:O16),AVERAGE(P16:T16),AVERAGE(U16:V16),AVERAGE(W16:X16),AVERAGE(Y16:Z16)) -> 46.166667 | AC16: =STDEV(AVERAGE(L16:M16),AVERAGE(N16:O16),AVERAGE(P16:T16),AVERAGE(U16:V16),AVERAGE(W16:X16),AVERAGE(Y16:Z16))/SQRT(6) -> 1.0137938 | AT16: Population
B17: =B15-1 -> 104 | C17: NTL | D17: 10 | E17: 2 | F17: 2 | G17: 1 | H17: 1 | I17: 221.1 | K17: Cover | L17: 53 | N17: 65 | Q17: 68 | U17: 50 | W17: 62 | Y17: 59 | AA17: =AVERAGE(P17:T17) -> 68 | AB17: =AVERAGE(AVERAGE(L17:M17),AVERAGE(N17:O17),AVERAGE(P17:T17),AVERAGE(U17:V17),AVERAGE(W17:X17),AVERAGE(Y17:Z17)) -> 59.5 | AC17: =STDEV(AVERAGE(L17:M17),AVERAGE(N17:O17),AVERAGE(P17:T17),AVERAGE(U17:V17),AVERAGE(W17:X17),AVERAGE(Y17:Z17))/SQRT(6) -> 2.8372522 | AT17: Code | AU17: no./meter | AV17: lines/bed
B18: =B16-1 -> 104 | C18: NTL | D18: 10 | E18: 2 | F18: 2 | G18: 1 | H18: 1 | I18: 221.1 | K18: Height | L18: 45 | N18: 50 | Q18: 51 | U18: 46 | W18: 45 | Y18: 46 | AA18: =AVERAGE(P18:T18) -> 51 | AB18: =AVERAGE(AVERAGE(L18:M18),AVERAGE(N18:O18),AVERAGE(P18:T18),AVERAGE(U18:V18),AVERAGE(W18:X18),AVERAGE(Y18:Z18)) -> 47.166667 | AC18: =STDEV(AVERAGE(L18:M18),AVERAGE(N18:O18),AVERAGE(P18:T18),AVERAGE(U18:V18),AVERAGE(W18:X18),AVERAGE(Y18:Z18))/SQRT(6) -> 1.0775487 | AT18: 0 | AU18: 0 | AV18: na
B19: =B17-1 -> 103 | C19: FDH | D19: 5 | E19: 1 | F19: 3 | G19: 2 | H19: 1 | I19: 132.1 | K19: Cover | L19: 76 | N19: 72 | P19: 73 | Q19: 71 | R19: 67 | U19: 73 | W19: 72 | Y19: 67 | AA19: =AVERAGE(P19:U19) -> 71 | AB19: =AVERAGE(AVERAGE(L19:M19),AVERAGE(N19:O19),AVERAGE(P19:U19),AVERAGE(U19:V19),AVERAGE(W19:X19),AVERAGE(Y19:Z19)) -> 71.833333 | AC19: =STDEV(AVERAGE(L19:M19),AVERAGE(N19:O19),AVERAGE(P19:U19),AVERAGE(U19:V19),AVERAGE(W19:X19),AVERAGE(Y19:Z19))/SQRT(6) -> 1.1948966 | AT19: 1 | AU19: 5 | AV19: Single
B20: =B18-1 -> 103 | C20: FDH | D20: 5 | E20: 1 | F20: 3 | G20: 2 | H20: 1 | I20: 132.1 | K20: Height | L20: 45 | N20: 40 | P20: 40 | Q20: 42 | R20: 49 | U20: 39 | W20: 38 | Y20: 41 | AA20: =AVERAGE(P20:U20) -> 42.5 | AB20: =AVERAGE(AVERAGE(L20:M20),AVERAGE(N20:O20),AVERAGE(P20:U20),AVERAGE(U20:V20),AVERAGE(W20:X20),AVERAGE(Y20:Z20)) -> 40.916667 | AC20: =STDEV(AVERAGE(L20:M20),AVERAGE(N20:O20),AVERAGE(P20:U20),AVERAGE(U20:V20),AVERAGE(W20:X20),AVERAGE(Y20:Z20))/SQRT(6) -> 1.0361521 | AT20: 2 | AU20: 10 | AV20: Single
B21: =B19-1 -> 102 | C21: FTL | D21: 4 | E21: 1 | F21: 2 | G21: 1 | H21: 1 | I21: 121.1 | K21: Cover | L21: 62 | N21: 57 | P21: 38 | Q21: 55 | R21: 33 | U21: 46 | W21: 51 | Y21: 68 | AA21: =AVERAGE(P21:U21) -> 43 | AB21: =AVERAGE(AVERAGE(L21:M21),AVERAGE(N21:O21),AVERAGE(P21:U21),AVERAGE(U21:V21),AVERAGE(W21:X21),AVERAGE(Y21:Z21)) -> 54.5 | AC21: =STDEV(AVERAGE(L21:M21),AVERAGE(N21:O21),AVERAGE(P21:U21),AVERAGE(U21:V21),AVERAGE(W21:X21),AVERAGE(Y21:Z21))/SQRT(6) -> 3.9221593 | AT21: 3 | AU21: 20 | AV21: Double
B22: =B20-1 -> 102 | C22: FTL | D22: 4 | E22: 1 | F22: 2 | G22: 1 | H22: 1 | I22: 121.1 | K22: Height | L22: 45 | N22: 46 | P22: 27 | Q22: 42 | R22: 25 | U22: 31 | W22: 44 | Y22: 44 | AA22: =AVERAGE(P22:U22) -> 31.25 | AB22: =AVERAGE(AVERAGE(L22:M22),AVERAGE(N22:O22),AVERAGE(P22:U22),AVERAGE(U22:V22),AVERAGE(W22:X22),AVERAGE(Y22:Z22)) -> 40.208333 | AC22: =STDEV(AVERAGE(L22:M22),AVERAGE(N22:O22),AVERAGE(P22:U22),AVERAGE(U22:V22),AVERAGE(W22:X22),AVERAGE(Y22:Z22))/SQRT(6) -> 2.8884949
B23: =B21-1 -> 101 | C23: FSH | D23: 1 | E23: 1 | F23: 1 | G23: 2 | H23: 1 | I23: 112.1 | K23: Cover | L23: 54 | N23: 63 | P23: 57 | Q23: 50 | R23: 48 | U23: 55 | W23: 49 | Y23: 59 | AA23: =AVERAGE(P23:U23) -> 52.5 | AB23: =AVERAGE(AVERAGE(L23:M23),AVERAGE(N23:O23),AVERAGE(P23:U23),AVERAGE(U23:V23),AVERAGE(W23:X23),AVERAGE(Y23:Z23)) -> 55.416667 | AC23: =STDEV(AVERAGE(L23:M23),AVERAGE(N23:O23),AVERAGE(P23:U23),AVERAGE(U23:V23),AVERAGE(W23:X23),AVERAGE(Y23:Z23))/SQRT(6) -> 2.0183189 | AT23: Nitrogen
B24: =B22-1 -> 101 | C24: FSH | D24: 1 | E24: 1 | F24: 1 | G24: 2 | H24: 1 | I24: 112.1 | K24: Height | L24: 41 | N24: 45 | P24: 45 | Q24: 47 | R24: 39 | U24: 32 | W24: 34 | Y24: 42 | AA24: =AVERAGE(P24:U24) -> 40.75 | AB24: =AVERAGE(AVERAGE(L24:M24),AVERAGE(N24:O24),AVERAGE(P24:U24),AVERAGE(U24:V24),AVERAGE(W24:X24),AVERAGE(Y24:Z24)) -> 39.125 | AC24: =STDEV(AVERAGE(L24:M24),AVERAGE(N24:O24),AVERAGE(P24:U24),AVERAGE(U24:V24),AVERAGE(W24:X24),AVERAGE(Y24:Z24))/SQRT(6) -> 2.049136 | AT24: Code | AU24: Descript | AV24: kg N/ha
B25: =B23+100 -> 201 | C25: NDL | D25: 12 | E25: 2 | F25: 3 | G25: 1 | H25: 1 | I25: 231.1 | K25: Cover | L25: 50 | N25: 57 | Q25: 77 | U25: 79 | W25: 75 | Y25: 83 | AA25: =AVERAGE(P25:T25) -> 77 | AB25: =AVERAGE(AVERAGE(L25:M25),AVERAGE(N25:O25),AVERAGE(P25:T25),AVERAGE(U25:V25),AVERAGE(W25:X25),AVERAGE(Y25:Z25)) -> 70.166667 | AC25: =STDEV(AVERAGE(L25:M25),AVERAGE(N25:O25),AVERAGE(P25:T25),AVERAGE(U25:V25),AVERAGE(W25:X25),AVERAGE(Y25:Z25))/SQRT(6) -> 5.4553745 | AT25: 1 | AU25: Low | AV25: 0
B26: =B24+100 -> 201 | C26: NDL | D26: 12 | E26: 2 | F26: 3 | G26: 1 | H26: 1 | I26: 231.1 | K26: Height | L26: 75 | N26: 82 | Q26: 52 | U26: 52 | W26: 55 | Y26: 62 | AA26: =AVERAGE(P26:T26) -> 52 | AB26: =AVERAGE(AVERAGE(L26:M26),AVERAGE(N26:O26),AVERAGE(P26:T26),AVERAGE(U26:V26),AVERAGE(W26:X26),AVERAGE(Y26:Z26)) -> 63 | AC26: =STDEV(AVERAGE(L26:M26),AVERAGE(N26:O26),AVERAGE(P26:T26),AVERAGE(U26:V26),AVERAGE(W26:X26),AVERAGE(Y26:Z26))/SQRT(6) -> 5.2025635 | AT26: 2 | AU26: High | AV26: 150
B27: =B25+1 -> 202 | C27: NTH | D27: 9 | E27: 2 | F27: 2 | G27: 2 | H27: 1 | I27: 222.1 | K27: Cover | L27: 58 | N27: 59 | Q27: 54 | U27: 49 | W27: 56 | Y27: 59 | AA27: =AVERAGE(P27:T27) -> 54 | AB27: =AVERAGE(AVERAGE(L27:M27),AVERAGE(N27:O27),AVERAGE(P27:T27),AVERAGE(U27:V27),AVERAGE(W27:X27),AVERAGE(Y27:Z27)) -> 55.833333 | AC27: =STDEV(AVERAGE(L27:M27),AVERAGE(N27:O27),AVERAGE(P27:T27),AVERAGE(U27:V27),AVERAGE(W27:X27),AVERAGE(Y27:Z27))/SQRT(6) -> 1.579381
B28: =B26+1 -> 202 | C28: NTH | D28: 9 | E28: 2 | F28: 2 | G28: 2 | H28: 1 | I28: 222.1 | K28: Height | L28: 49 | N28: 42 | Q28: 39 | U28: 42 | W28: 54 | Y28: 48 | AA28: =AVERAGE(P28:T28) -> 39 | AB28: =AVERAGE(AVERAGE(L28:M28),AVERAGE(N28:O28),AVERAGE(P28:T28),AVERAGE(U28:V28),AVERAGE(W28:X28),AVERAGE(Y28:Z28)) -> 45.666667 | AC28: =STDEV(AVERAGE(L28:M28),AVERAGE(N28:O28),AVERAGE(P28:T28),AVERAGE(U28:V28),AVERAGE(W28:X28),AVERAGE(Y28:Z28))/SQRT(6) -> 2.2900752
B29: =B27+1 -> 203 | C29: FTH | D29: 3 | E29: 1 | F29: 2 | G29: 2 | H29: 1 | I29: 122.1 | K29: Cover | L29: 46 | N29: 66 | P29: 66 | Q29: 60 | R29: 55 | U29: 52 | W29: 67 | Y29: 61 | AA29: =AVERAGE(P29:U29) -> 58.25 | AB29: =AVERAGE(AVERAGE(L29:M29),AVERAGE(N29:O29),AVERAGE(P29:U29),AVERAGE(U29:V29),AVERAGE(W29:X29),AVERAGE(Y29:Z29)) -> 58.375 | AC29: =STDEV(AVERAGE(L29:M29),AVERAGE(N29:O29),AVERAGE(P29:U29),AVERAGE(U29:V29),AVERAGE(W29:X29),AVERAGE(Y29:Z29))/SQRT(6) -> 3.3327604
B30: =B28+1 -> 203 | C30: FTH | D30: 3 | E30: 1 | F30: 2 | G30: 2 | H30: 1 | I30: 122.1 | K30: Height | L30: 39 | N30: 55 | P30: 49 | Q30: 57 | R30: 51 | U30: 52 | W30: 53 | Y30: 41 | AA30: =AVERAGE(P30:U30) -> 52.25 | AB30: =AVERAGE(AVERAGE(L30:M30),AVERAGE(N30:O30),AVERAGE(P30:U30),AVERAGE(U30:V30),AVERAGE(W30:X30),AVERAGE(Y30:Z30)) -> 48.708333 | AC30: =STDEV(AVERAGE(L30:M30),AVERAGE(N30:O30),AVERAGE(P30:U30),AVERAGE(U30:V30),AVERAGE(W30:X30),AVERAGE(Y30:Z30))/SQRT(6) -> 2.7991194
B31: =B29+1 -> 204 | C31: NDH | D31: 11 | E31: 2 | F31: 3 | G31: 2 | H31: 1 | I31: 232.1 | K31: Cover | L31: 79 | N31: 76 | Q31: 82 | U31: 73 | W31: 78 | Y31: 82 | AA31: =AVERAGE(P31:T31) -> 82 | AB31: =AVERAGE(AVERAGE(L31:M31),AVERAGE(N31:O31),AVERAGE(P31:T31),AVERAGE(U31:V31),AVERAGE(W31:X31),AVERAGE(Y31:Z31)) -> 78.333333 | AC31: =STDEV(AVERAGE(L31:M31),AVERAGE(N31:O31),AVERAGE(P31:T31),AVERAGE(U31:V31),AVERAGE(W31:X31),AVERAGE(Y31:Z31))/SQRT(6) -> 1.4298407
B32: =B30+1 -> 204 | C32: NDH | D32: 11 | E32: 2 | F32: 3 | G32: 2 | H32: 1 | I32: 232.1 | K32: Height | L32: 48 | N32: 49 | Q32: 51 | U32: 61 | W32: 56 | Y32: 55 | AA32: =AVERAGE(P32:T32) -> 51 | AB32: =AVERAGE(AVERAGE(L32:M32),AVERAGE(N32:O32),AVERAGE(P32:T32),AVERAGE(U32:V32),AVERAGE(W32:X32),AVERAGE(Y32:Z32)) -> 53.333333 | AC32: =STDEV(AVERAGE(L32:M32),AVERAGE(N32:O32),AVERAGE(P32:T32),AVERAGE(U32:V32),AVERAGE(W32:X32),AVERAGE(Y32:Z32))/SQRT(6) -> 2.0110804
B33: =B31+1 -> 205 | C33: FSH | D33: 1 | E33: 1 | F33: 1 | G33: 2 | H33: 2 | I33: 112.2 | K33: Cover | L33: 58 | N33: 51 | P33: 59 | Q33: 62 | R33: 62 | U33: 53 | W33: 60 | Y33: 57 | AA33: =AVERAGE(P33:U33) -> 59 | AB33: =AVERAGE(AVERAGE(L33:M33),AVERAGE(N33:O33),AVERAGE(P33:U33),AVERAGE(U33:V33),AVERAGE(W33:X33),AVERAGE(Y33:Z33)) -> 56.333333 | AC33: =STDEV(AVERAGE(L33:M33),AVERAGE(N33:O33),AVERAGE(P33:U33),AVERAGE(U33:V33),AVERAGE(W33:X33),AVERAGE(Y33:Z33))/SQRT(6) -> 1.4529663
B34: =B32+1 -> 205 | C34: FSH | D34: 1 | E34: 1 | F34: 1 | G34: 2 | H34: 2 | I34: 112.2 | K34: Height | L34: 42 | N34: 44 | P34: 38 | Q34: 42 | R34: 45 | U34: 36 | W34: 55 | Y34: 49 | AA34: =AVERAGE(P34:U34) -> 40.25 | AB34: =AVERAGE(AVERAGE(L34:M34),AVERAGE(N34:O34),AVERAGE(P34:U34),AVERAGE(U34:V34),AVERAGE(W34:X34),AVERAGE(Y34:Z34)) -> 44.375 | AC34: =STDEV(AVERAGE(L34:M34),AVERAGE(N34:O34),AVERAGE(P34:U34),AVERAGE(U34:V34),AVERAGE(W34:X34),AVERAGE(Y34:Z34))/SQRT(6) -> 2.7520825
B35: =B33+1 -> 206 | C35: NSL | D35: 8 | E35: 2 | F35: 1 | G35: 1 | H35: 2 | I35: 211.2 | K35: Cover | L35: 55 | N35: 53 | P35: 51 | Q35: 59 | R35: 52 | S35: 57 | T35: 61 | U35: 59 | W35: 55 | Y35: 60 | AA35: =AVERAGE(P35:U35) -> 56.5 | AB35: =AVERAGE(AVERAGE(L35:M35),AVERAGE(N35:O35),AVERAGE(P35:U35),AVERAGE(U35:V35),AVERAGE(W35:X35),AVERAGE(Y35:Z35)) -> 56.416667 | AC35: =STDEV(AVERAGE(L35:M35),AVERAGE(N35:O35),AVERAGE(P35:U35),AVERAGE(U35:V35),AVERAGE(W35:X35),AVERAGE(Y35:Z35))/SQRT(6) -> 1.0833333
B36: =B34+1 -> 206 | C36: NSL | D36: 8 | E36: 2 | F36: 1 | G36: 1 | H36: 2 | I36: 211.2 | K36: Height | L36: 44 | N36: 46 | P36: 34 | Q36: 51 | R36: 53 | S36: 43 | T36: 40 | U36: 48 | W36: 46 | Y36: 46 | AA36: =AVERAGE(P36:U36) -> 44.833333 | AB36: =AVERAGE(AVERAGE(L36:M36),AVERAGE(N36:O36),AVERAGE(P36:U36),AVERAGE(U36:V36),AVERAGE(W36:X36),AVERAGE(Y36:Z36)) -> 45.805556 | AC36: =STDEV(AVERAGE(L36:M36),AVERAGE(N36:O36),AVERAGE(P36:U36),AVERAGE(U36:V36),AVERAGE(W36:X36),AVERAGE(Y36:Z36))/SQRT(6) -> 0.55179281
B37: =B35+1 -> 207 | C37: FTL | D37: 4 | E37: 1 | F37: 2 | G37: 1 | H37: 2 | I37: 121.2 | K37: Cover | L37: 63 | N37: 66 | P37: 65 | Q37: 57 | R37: 62 | U37: 73 | W37: 67 | Y37: 66 | AA37: =AVERAGE(P37:U37) -> 64.25 | AB37: =AVERAGE(AVERAGE(L37:M37),AVERAGE(N37:O37),AVERAGE(P37:U37),AVERAGE(U37:V37),AVERAGE(W37:X37),AVERAGE(Y37:Z37)) -> 66.541667 | AC37: =STDEV(AVERAGE(L37:M37),AVERAGE(N37:O37),AVERAGE(P37:U37),AVERAGE(U37:V37),AVERAGE(W37:X37),AVERAGE(Y37:Z37))/SQRT(6) -> 1.4177692
B38: =B36+1 -> 207 | C38: FTL | D38: 4 | E38: 1 | F38: 2 | G38: 1 | H38: 2 | I38: 121.2 | K38: Height | L38: 49 | N38: 57 | P38: 48 | Q38: 50 | R38: 51 | U38: 60 | W38: 46 | Y38: 50 | AA38: =AVERAGE(P38:U38) -> 52.25 | AB38: =AVERAGE(AVERAGE(L38:M38),AVERAGE(N38:O38),AVERAGE(P38:U38),AVERAGE(U38:V38),AVERAGE(W38:X38),AVERAGE(Y38:Z38)) -> 52.375 | AC38: =STDEV(AVERAGE(L38:M38),AVERAGE(N38:O38),AVERAGE(P38:U38),AVERAGE(U38:V38),AVERAGE(W38:X38),AVERAGE(Y38:Z38))/SQRT(6) -> 2.1386814
B39: =B37+1 -> 208 | C39: FSL | D39: 2 | E39: 1 | F39: 1 | G39: 1 | H39: 2 | I39: 111.2 | K39: Cover | L39: 55 | N39: 59 | P39: 46 | Q39: 49 | R39: 55 | U39: 53 | W39: 49 | Y39: 48 | AA39: =AVERAGE(P39:U39) -> 50.75 | AB39: =AVERAGE(AVERAGE(L39:M39),AVERAGE(N39:O39),AVERAGE(P39:U39),AVERAGE(U39:V39),AVERAGE(W39:X39),AVERAGE(Y39:Z39)) -> 52.458333 | AC39: =STDEV(AVERAGE(L39:M39),AVERAGE(N39:O39),AVERAGE(P39:U39),AVERAGE(U39:V39),AVERAGE(W39:X39),AVERAGE(Y39:Z39))/SQRT(6) -> 1.6763262
B40: =B38+1 -> 208 | C40: FSL | D40: 2 | E40: 1 | F40: 1 | G40: 1 | H40: 2 | I40: 111.2 | K40: Height | L40: 46 | N40: 38 | P40: 38 | Q40: 38 | R40: 41 | U40: 42 | W40: 49 | Y40: 39 | AA40: =AVERAGE(P40:U40) -> 39.75 | AB40: =AVERAGE(AVERAGE(L40:M40),AVERAGE(N40:O40),AVERAGE(P40:U40),AVERAGE(U40:V40),AVERAGE(W40:X40),AVERAGE(Y40:Z40)) -> 42.291667 | AC40: =STDEV(AVERAGE(L40:M40),AVERAGE(N40:O40),AVERAGE(P40:U40),AVERAGE(U40:V40),AVERAGE(W40:X40),AVERAGE(Y40:Z40))/SQRT(6) -> 1.775313
...

Sheet HgtDOY189
A1: FISE2003 Plant Cover and Heights
X2: Date: | Y2: 37810 | AA2: DOY 189
B3: Comments: | J3: Extremely hot and stifeling
J4: some muddy plots | X4: By: | Y4: SR , COB
AT5: Legend
B6: Plot | C6: Acron | D6: Trt. | E6: Irrig. | F6: Pop. | G6: N | H6: Block | I6: Exotech Code | J6: Time | K6: Meas. | L6: Row 3 | N6: Row 4 | P6: Row 5 (Picture Row) | U6: Row 6 | W6: Row 7 | Y6: Row 8 | AA6: PictureRow Mean | AB6: Plot Mean | AC6: Plot SE | AT6: Irrigation
J7: Position ⇒ | L7: 25 cm | M7: 75 cm | N7: 25 cm | O7: 75 cm | P7: 0 cm | Q7: 25 cm | R7: 50 cm | S7: 75 cm | T7: 100 cm | U7: 25 cm | V7: 75 cm | W7: 25 cm | X7: 75 cm | Y7: 25 cm | Z7: 75 cm | AT7: Code | AU7: Schedule | AV7: notes
B8: Plot | C8: Acron | D8: Trt | E8: Irr | F8: Pop | G8: Nit | H8: Block | I8: ExotechCode | J8: Time | K8: Meas | L8: 3.25 | M8: 3.75 | N8: 4.25 | O8: 4.75 | P8: 5.00 | Q8: 5.25 | R8: 5.50 | S8: 5.75 | T8: 5.100 | U8: 6.25 | V8: 6.75 | W8: 7.25 | X8: 7.75 | Y8: 8.25 | Z8: 8.75 | AA8: PicRowMean | AB8: PlotMean | AC8: PlotSE
B9: 108 | C9: FTH | D9: 3 | E9: 1 | F9: 2 | G9: 2 | H9: 2 | I9: 122.2 | J9: 0.44791667 | K9: Cover | L9: 85 | N9: 87 | P9: 79 | Q9: 77 | R9: 83 | S9: 74 | T9: 73 | U9: 86 | W9: 91 | Y9: 90 | AA9: =AVERAGE(P9:U9) -> 78.666667 | AB9: =AVERAGE(AVERAGE(L9:M9),AVERAGE(N9:O9),AVERAGE(P9:U9),AVERAGE(U9:V9),AVERAGE(W9:X9),AVERAGE(Y9:Z9)) -> 86.277778 | AC9: =STDEV(AVERAGE(L9:M9),AVERAGE(N9:O9),AVERAGE(P9:U9),AVERAGE(U9:V9),AVERAGE(W9:X9),AVERAGE(Y9:Z9))/SQRT(6) -> 1.7917851 | AT9: 1 | AU9: FAO
B10: 108 | C10: FTH | D10: 3 | E10: 1 | F10: 2 | G10: 2 | H10: 2 | I10: 122.2 | K10: Height | L10: 86 | N10: 75 | P10: 66 | Q10: 68 | R10: 81 | S10: 81 | T10: 70 | U10: 81 | W10: 76 | Y10: 85.5 | AA10: =AVERAGE(P10:U10) -> 74.5 | AB10: =AVERAGE(AVERAGE(L10:M10),AVERAGE(N10:O10),AVERAGE(P10:U10),AVERAGE(U10:V10),AVERAGE(W10:X10),AVERAGE(Y10:Z10)) -> 79.666667 | AC10: =STDEV(AVERAGE(L10:M10),AVERAGE(N10:O10),AVERAGE(P10:U10),AVERAGE(U10:V10),AVERAGE(W10:X10),AVERAGE(Y10:Z10))/SQRT(6) -> 2.1434655 | AT10: 2 | AU10: NDVI
B11: =B9-1 -> 107 | C11: NTL | D11: 10 | E11: 2 | F11: 2 | G11: 1 | H11: 2 | I11: 221.2 | K11: Cover | L11: 78 | N11: 84 | P11: 82 | Q11: 73 | R11: 76 | S11: 81 | T11: 83 | U11: 81 | W11: 86 | Y11: 80 | AA11: =AVERAGE(P11:U11) -> 79.333333 | AB11: =AVERAGE(AVERAGE(L11:M11),AVERAGE(N11:O11),AVERAGE(P11:U11),AVERAGE(U11:V11),AVERAGE(W11:X11),AVERAGE(Y11:Z11)) -> 81.388889 | AC11: =STDEV(AVERAGE(L11:M11),AVERAGE(N11:O11),AVERAGE(P11:U11),AVERAGE(U11:V11),AVERAGE(W11:X11),AVERAGE(Y11:Z11))/SQRT(6) -> 1.2365324 | AT11: 3 | AU11: None>1Jun | AV11: ad hoc
B12: =B10-1 -> 107 | C12: NTL | D12: 10 | E12: 2 | F12: 2 | G12: 1 | H12: 2 | I12: 221.2 | K12: Height | L12: 76 | N12: 92 | P12: 72 | Q12: 74 | R12: 77 | S12: 75 | T12: 82 | U12: 80 | W12: 82 | Y12: 78 | AA12: =AVERAGE(P12:U12) -> 76.666667 | AB12: =AVERAGE(AVERAGE(L12:M12),AVERAGE(N12:O12),AVERAGE(P12:U12),AVERAGE(U12:V12),AVERAGE(W12:X12),AVERAGE(Y12:Z12)) -> 80.777778 | AC12: =STDEV(AVERAGE(L12:M12),AVERAGE(N12:O12),AVERAGE(P12:U12),AVERAGE(U12:V12),AVERAGE(W12:X12),AVERAGE(Y12:Z12))/SQRT(6) -> 2.4185497 | AT12: 4 | AU12: None>15Jul | AV12: ad hoc
B13: =B11-1 -> 106 | C13: NTH | D13: 9 | E13: 2 | F13: 2 | G13: 2 | H13: 2 | I13: 222.2 | K13: Cover | L13: 85 | N13: 72 | P13: 85 | Q13: 88 | R13: 81 | S13: 89 | T13: 87 | U13: 81 | W13: 93 | Y13: 90 | AA13: =AVERAGE(P13:U13) -> 85.166667 | AB13: =AVERAGE(AVERAGE(L13:M13),AVERAGE(N13:O13),AVERAGE(P13:U13),AVERAGE(U13:V13),AVERAGE(W13:X13),AVERAGE(Y13:Z13)) -> 84.361111 | AC13: =STDEV(AVERAGE(L13:M13),AVERAGE(N13:O13),AVERAGE(P13:U13),AVERAGE(U13:V13),AVERAGE(W13:X13),AVERAGE(Y13:Z13))/SQRT(6) -> 3.0087578 | AT13: 8 | AU13: Dry Soil | AV13: never
B14: =B12-1 -> 106 | C14: NTH | D14: 9 | E14: 2 | F14: 2 | G14: 2 | H14: 2 | I14: 222.2 | K14: Height | L14: 83 | N14: 81 | P14: 81 | Q14: 79 | R14: 73 | S14: 80 | T14: 78 | U14: 77 | W14: 89 | Y14: 79 | AA14: =AVERAGE(P14:U14) -> 78 | AB14: =AVERAGE(AVERAGE(L14:M14),AVERAGE(N14:O14),AVERAGE(P14:U14),AVERAGE(U14:V14),AVERAGE(W14:X14),AVERAGE(Y14:Z14)) -> 81.166667 | AC14: =STDEV(AVERAGE(L14:M14),AVERAGE(N14:O14),AVERAGE(P14:U14),AVERAGE(U14:V14),AVERAGE(W14:X14),AVERAGE(Y14:Z14))/SQRT(6) -> 1.7966017 | AT14: 9 | AU14: Wet Soil | AV14: often
B15: =B13-1 -> 105 | C15: NDL | D15: 12 | E15: 2 | F15: 3 | G15: 1 | H15: 2 | I15: 231.2 | K15: Cover | L15: 97 | N15: 85 | P15: 94 | Q15: 92 | R15: 88 | S15: 85 | T15: 92 | U15: 86 | W15: 93 | Y15: 83 | AA15: =AVERAGE(P15:U15) -> 89.5 | AB15: =AVERAGE(AVERAGE(L15:M15),AVERAGE(N15:O15),AVERAGE(P15:U15),AVERAGE(U15:V15),AVERAGE(W15:X15),AVERAGE(Y15:Z15)) -> 88.916667 | AC15: =STDEV(AVERAGE(L15:M15),AVERAGE(N15:O15),AVERAGE(P15:U15),AVERAGE(U15:V15),AVERAGE(W15:X15),AVERAGE(Y15:Z15))/SQRT(6) -> 2.1695494
B16: =B14-1 -> 105 | C16: NDL | D16: 12 | E16: 2 | F16: 3 | G16: 1 | H16: 2 | I16: 231.2 | K16: Height | L16: 73 | N16: 77 | P16: 72 | Q16: 69 | R16: 68 | S16: 65 | T16: 67 | U16: 72 | W16: 67 | Y16: 69 | AA16: =AVERAGE(P16:U16) -> 68.833333 | AB16: =AVERAGE(AVERAGE(L16:M16),AVERAGE(N16:O16),AVERAGE(P16:U16),AVERAGE(U16:V16),AVERAGE(W16:X16),AVERAGE(Y16:Z16)) -> 71.138889 | AC16: =STDEV(AVERAGE(L16:M16),AVERAGE(N16:O16),AVERAGE(P16:U16),AVERAGE(U16:V16),AVERAGE(W16:X16),AVERAGE(Y16:Z16))/SQRT(6) -> 1.4784982 | AT16: Population
B17: =B15-1 -> 104 | C17: NTL | D17: 10 | E17: 2 | F17: 2 | G17: 1 | H17: 1 | I17: 221.1 | K17: Cover | L17: 81 | N17: 92 | P17: 88 | Q17: 82 | R17: 82 | S17: 83 | T17: 80 | U17: 79 | W17: 81 | Y17: 86 | AA17: =AVERAGE(P17:U17) -> 82.333333 | AB17: =AVERAGE(AVERAGE(L17:M17),AVERAGE(N17:O17),AVERAGE(P17:U17),AVERAGE(U17:V17),AVERAGE(W17:X17),AVERAGE(Y17:Z17)) -> 83.555556 | AC17: =STDEV(AVERAGE(L17:M17),AVERAGE(N17:O17),AVERAGE(P17:U17),AVERAGE(U17:V17),AVERAGE(W17:X17),AVERAGE(Y17:Z17))/SQRT(6) -> 1.9372884 | AT17: Code | AU17: no./meter | AV17: lines/bed
B18: =B16-1 -> 104 | C18: NTL | D18: 10 | E18: 2 | F18: 2 | G18: 1 | H18: 1 | I18: 221.1 | K18: Height | L18: 74 | N18: 75 | P18: 79 | Q18: 75 | R18: 91 | S18: 73 | T18: 74 | U18: 75 | W18: 83 | Y18: 80 | AA18: =AVERAGE(P18:U18) -> 77.833333 | AB18: =AVERAGE(AVERAGE(L18:M18),AVERAGE(N18:O18),AVERAGE(P18:U18),AVERAGE(U18:V18),AVERAGE(W18:X18),AVERAGE(Y18:Z18)) -> 77.472222 | AC18: =STDEV(AVERAGE(L18:M18),AVERAGE(N18:O18),AVERAGE(P18:U18),AVERAGE(U18:V18),AVERAGE(W18:X18),AVERAGE(Y18:Z18))/SQRT(6) -> 1.4301105 | AT18: 0 | AU18: 0 | AV18: na
B19: =B17-1 -> 103 | C19: FDH | D19: 5 | E19: 1 | F19: 3 | G19: 2 | H19: 1 | I19: 132.1 | K19: Cover | L19: 83 | N19: 89 | P19: 93 | Q19: 85 | R19: 84 | S19: 85 | T19: 86 | U19: 87 | W19: 82 | Y19: 90 | AA19: =AVERAGE(P19:U19) -> 86.666667 | AB19: =AVERAGE(AVERAGE(L19:M19),AVERAGE(N19:O19),AVERAGE(P19:U19),AVERAGE(U19:V19),AVERAGE(W19:X19),AVERAGE(Y19:Z19)) -> 86.277778 | AC19: =STDEV(AVERAGE(L19:M19),AVERAGE(N19:O19),AVERAGE(P19:U19),AVERAGE(U19:V19),AVERAGE(W19:X19),AVERAGE(Y19:Z19))/SQRT(6) -> 1.3036037 | AT19: 1 | AU19: 5 | AV19: Single
B20: =B18-1 -> 103 | C20: FDH | D20: 5 | E20: 1 | F20: 3 | G20: 2 | H20: 1 | I20: 132.1 | K20: Height | L20: 71 | N20: 67 | P20: 58 | Q20: 60 | R20: 59 | S20: 63 | T20: 66 | U20: 62 | W20: 57 | Y20: 66 | AA20: =AVERAGE(P20:U20) -> 61.333333 | AB20: =AVERAGE(AVERAGE(L20:M20),AVERAGE(N20:O20),AVERAGE(P20:U20),AVERAGE(U20:V20),AVERAGE(W20:X20),AVERAGE(Y20:Z20)) -> 64.055556 | AC20: =STDEV(AVERAGE(L20:M20),AVERAGE(N20:O20),AVERAGE(P20:U20),AVERAGE(U20:V20),AVERAGE(W20:X20),AVERAGE(Y20:Z20))/SQRT(6) -> 2.0173629 | AT20: 2 | AU20: 10 | AV20: Single
B21: =B19-1 -> 102 | C21: FTL | D21: 4 | E21: 1 | F21: 2 | G21: 1 | H21: 1 | I21: 121.1 | K21: Cover | L21: 75 | N21: 91 | P21: 58 | Q21: 69 | R21: 52 | S21: 71 | T21: 65 | U21: 71 | W21: 70 | Y21: 83 | AA21: =AVERAGE(P21:U21) -> 64.333333 | AB21: =AVERAGE(AVERAGE(L21:M21),AVERAGE(N21:O21),AVERAGE(P21:U21),AVERAGE(U21:V21),AVERAGE(W21:X21),AVERAGE(Y21:Z21)) -> 75.722222 | AC21: =STDEV(AVERAGE(L21:M21),AVERAGE(N21:O21),AVERAGE(P21:U21),AVERAGE(U21:V21),AVERAGE(W21:X21),AVERAGE(Y21:Z21))/SQRT(6) -> 3.9650479 | AT21: 3 | AU21: 20 | AV21: Double
B22: =B20-1 -> 102 | C22: FTL | D22: 4 | E22: 1 | F22: 2 | G22: 1 | H22: 1 | I22: 121.1 | K22: Height | L22: 74 | N22: 75 | P22: 66 | Q22: 69 | R22: 49 | S22: 55 | T22: 58 | U22: 6 | W22: 63 | Y22: 72 | AA22: =AVERAGE(P22:U22) -> 50.5 | AB22: =AVERAGE(AVERAGE(L22:M22),AVERAGE(N22:O22),AVERAGE(P22:U22),AVERAGE(U22:V22),AVERAGE(W22:X22),AVERAGE(Y22:Z22)) -> 56.75 | AC22: =STDEV(AVERAGE(L22:M22),AVERAGE(N22:O22),AVERAGE(P22:U22),AVERAGE(U22:V22),AVERAGE(W22:X22),AVERAGE(Y22:Z22))/SQRT(6) -> 10.827242
B23: =B21-1 -> 101 | C23: FSH | D23: 1 | E23: 1 | F23: 1 | G23: 2 | H23: 1 | I23: 112.1 | K23: Cover | L23: 72 | N23: 79 | P23: 62 | Q23: 71 | R23: 77 | S23: 75 | T23: 78 | U23: 75 | W23: 73 | Y23: 81 | AA23: =AVERAGE(P23:U23) -> 73 | AB23: =AVERAGE(AVERAGE(L23:M23),AVERAGE(N23:O23),AVERAGE(P23:U23),AVERAGE(U23:V23),AVERAGE(W23:X23),AVERAGE(Y23:Z23)) -> 75.5 | AC23: =STDEV(AVERAGE(L23:M23),AVERAGE(N23:O23),AVERAGE(P23:U23),AVERAGE(U23:V23),AVERAGE(W23:X23),AVERAGE(Y23:Z23))/SQRT(6) -> 1.5 | AT23: Nitrogen
B24: =B22-1 -> 101 | C24: FSH | D24: 1 | E24: 1 | F24: 1 | G24: 2 | H24: 1 | I24: 112.1 | K24: Height | L24: 70 | N24: 65 | P24: 75 | Q24: 69 | R24: 63 | S24: 61 | T24: 71 | U24: 60 | W24: 58 | Y24: 71 | AA24: =AVERAGE(P24:U24) -> 66.5 | AB24: =AVERAGE(AVERAGE(L24:M24),AVERAGE(N24:O24),AVERAGE(P24:U24),AVERAGE(U24:V24),AVERAGE(W24:X24),AVERAGE(Y24:Z24)) -> 65.083333 | AC24: =STDEV(AVERAGE(L24:M24),AVERAGE(N24:O24),AVERAGE(P24:U24),AVERAGE(U24:V24),AVERAGE(W24:X24),AVERAGE(Y24:Z24))/SQRT(6) -> 2.1386003 | AT24: Code | AU24: Descript | AV24: kg N/ha
B25: =B23+100 -> 201 | C25: NDL | D25: 12 | E25: 2 | F25: 3 | G25: 1 | H25: 1 | I25: 231.1 | K25: Cover | L25: 86 | N25: 86 | P25: 95 | Q25: 85 | R25: 91 | S25: 90 | T25: 96 | U25: 89 | W25: 85 | Y25: 98 | AA25: =AVERAGE(P25:U25) -> 91 | AB25: =AVERAGE(AVERAGE(L25:M25),AVERAGE(N25:O25),AVERAGE(P25:U25),AVERAGE(U25:V25),AVERAGE(W25:X25),AVERAGE(Y25:Z25)) -> 89.166667 | AC25: =STDEV(AVERAGE(L25:M25),AVERAGE(N25:O25),AVERAGE(P25:U25),AVERAGE(U25:V25),AVERAGE(W25:X25),AVERAGE(Y25:Z25))/SQRT(6) -> 1.990254 | AT25: 1 | AU25: Low | AV25: 0
B26: =B24+100 -> 201 | C26: NDL | D26: 12 | E26: 2 | F26: 3 | G26: 1 | H26: 1 | I26: 231.1 | K26: Height | L26: 72 | N26: 72 | P26: 68 | Q26: 67 | R26: 69 | S26: 78 | T26: 75 | U26: 75 | W26: 73 | Y26: 89 | AA26: =AVERAGE(P26:U26) -> 72 | AB26: =AVERAGE(AVERAGE(L26:M26),AVERAGE(N26:O26),AVERAGE(P26:U26),AVERAGE(U26:V26),AVERAGE(W26:X26),AVERAGE(Y26:Z26)) -> 75.5 | AC26: =STDEV(AVERAGE(L26:M26),AVERAGE(N26:O26),AVERAGE(P26:U26),AVERAGE(U26:V26),AVERAGE(W26:X26),AVERAGE(Y26:Z26))/SQRT(6) -> 2.741654 | AT26: 2 | AU26: High | AV26: 150
B27: =B25+1 -> 202 | C27: NTH | D27: 9 | E27: 2 | F27: 2 | G27: 2 | H27: 1 | I27: 222.1 | K27: Cover | L27: 81 | N27: 69 | P27: 79 | Q27: 75 | R27: 78 | S27: 73 | T27: 80 | U27: 69 | W27: 77 | Y27: 69 | AA27: =AVERAGE(P27:U27) -> 75.666667 | AB27: =AVERAGE(AVERAGE(L27:M27),AVERAGE(N27:O27),AVERAGE(P27:U27),AVERAGE(U27:V27),AVERAGE(W27:X27),AVERAGE(Y27:Z27)) -> 73.444444 | AC27: =STDEV(AVERAGE(L27:M27),AVERAGE(N27:O27),AVERAGE(P27:U27),AVERAGE(U27:V27),AVERAGE(W27:X27),AVERAGE(Y27:Z27))/SQRT(6) -> 2.1128648
B28: =B26+1 -> 202 | C28: NTH | D28: 9 | E28: 2 | F28: 2 | G28: 2 | H28: 1 | I28: 222.1 | K28: Height | L28: 76 | N28: 77 | P28: 63 | Q28: 60 | R28: 61 | S28: 73 | T28: 72 | U28: 64 | W28: 83 | Y28: 76 | AA28: =AVERAGE(P28:U28) -> 65.5 | AB28: =AVERAGE(AVERAGE(L28:M28),AVERAGE(N28:O28),AVERAGE(P28:U28),AVERAGE(U28:V28),AVERAGE(W28:X28),AVERAGE(Y28:Z28)) -> 73.583333 | AC28: =STDEV(AVERAGE(L28:M28),AVERAGE(N28:O28),AVERAGE(P28:U28),AVERAGE(U28:V28),AVERAGE(W28:X28),AVERAGE(Y28:Z28))/SQRT(6) -> 2.9955986
