Workbook

Sheet Summary
A1: Year | B1: DOY | C1: Experiment | D1: Tube | E1: d290cm | F1: d270cm | G1: d250cm | H1: d230cm | I1: d210cm | J1: d190cm | K1: d170cm | L1: d150cm | M1: d130cm | N1: d110cm | O1: d090cm | P1: d070cm | Q1: d050cm | R1: d015cm
A2: 2003 | B2: 104 | C2: FISE | D2: 101 | E2: 0.194 | F2: 0.195 | G2: 0.197 | H2: 0.145 | I2: 0.095 | J2: 0.094 | K2: 0.101 | L2: 0.094 | M2: 0.093 | N2: 0.075 | O2: 0.071 | P2: 0.086 | Q2: 0.093 | R2: 0.082
A3: 2003 | B3: 104 | C3: FISE | D3: 102 | E3: 0.182 | F3: 0.181 | G3: 0.186 | H3: 0.166 | I3: 0.127 | J3: 0.113 | K3: 0.101 | L3: 0.099 | M3: 0.096 | N3: 0.083 | O3: 0.067 | P3: 0.072 | Q3: 0.094 | R3: 0.077
A4: 2003 | B4: 104 | C4: FISE | D4: 103 | E4: 0.17 | F4: 0.178 | G4: 0.163 | H4: 0.166 | I4: 0.134 | J4: 0.118 | K4: 0.14 | L4: 0.133 | M4: 0.144 | N4: 0.139 | O4: 0.143 | P4: 0.121 | Q4: 0.093 | R4: 0.073
A5: 2003 | B5: 104 | C5: FISE | D5: 104 | E5: 0.182 | F5: 0.186 | G5: 0.194 | H5: 0.196 | I5: 0.142 | J5: 0.106 | K5: 0.115 | L5: 0.133 | M5: 0.152 | N5: 0.151 | O5: 0.13 | P5: 0.115 | Q5: 0.105 | R5: 0.092
A6: 2003 | B6: 104 | C6: FISE | D6: 105 | E6: 0.17 | F6: 0.174 | G6: 0.192 | H6: 0.199 | I6: 0.134 | J6: 0.133 | K6: 0.139 | L6: 0.153 | M6: 0.149 | N6: 0.145 | O6: 0.154 | P6: 0.124 | Q6: 0.105 | R6: 0.081
A7: 2003 | B7: 104 | C7: FISE | D7: 106 | E7: 0.18 | F7: 0.181 | G7: 0.193 | H7: 0.188 | I7: 0.186 | J7: 0.128 | K7: 0.119 | L7: 0.122 | M7: 0.142 | N7: 0.151 | O7: 0.14 | P7: 0.116 | Q7: 0.096 | R7: 0.065
A8: 2003 | B8: 104 | C8: FISE | D8: 107 | E8: 0.172 | F8: 0.172 | G8: 0.194 | H8: 0.19 | I8: 0.145 | J8: 0.121 | K8: 0.107 | L8: 0.101 | M8: 0.115 | N8: 0.106 | O8: 0.099 | P8: 0.096 | Q8: 0.096 | R8: 0.077
A9: 2003 | B9: 104 | C9: FISE | D9: 108 | E9: 0.136 | F9: 0.128 | G9: 0.143 | H9: 0.118 | I9: 0.099 | J9: 0.1 | K9: 0.105 | L9: 0.128 | M9: 0.149 | N9: 0.152 | O9: 0.118 | P9: 0.095 | Q9: 0.088 | R9: 0.078
A10: 2003 | B10: 104 | C10: FISE | D10: 201 | E10: 0.182 | F10: 0.184 | G10: 0.182 | H10: 0.161 | I10: 0.112 | J10: 0.103 | K10: 0.107 | L10: 0.121 | M10: 0.132 | N10: 0.136 | O10: 0.13 | P10: 0.122 | Q10: 0.104 | R10: 0.093
A11: 2003 | B11: 104 | C11: FISE | D11: 202 | E11: 0.184 | F11: 0.187 | G11: 0.157 | H11: 0.132 | I11: 0.105 | J11: 0.102 | K11: 0.076 | L11: 0.071 | M11: 0.067 | N11: 0.07 | O11: 0.07 | P11: 0.08 | Q11: 0.092 | R11: 0.069
A12: 2003 | B12: 104 | C12: FISE | D12: 203 | E12: 0.187 | F12: 0.186 | G12: 0.185 | H12: 0.188 | I12: 0.139 | J12: 0.119 | K12: 0.114 | L12: 0.118 | M12: 0.143 | N12: 0.138 | O12: 0.123 | P12: 0.107 | Q12: 0.095 | R12: 0.087
A13: 2003 | B13: 104 | C13: FISE | D13: 204 | E13: 0.184 | F13: 0.185 | G13: 0.185 | H13: 0.198 | I13: 0.139 | J13: 0.119 | K13: 0.116 | L13: 0.118 | M13: 0.142 | N13: 0.138 | O13: 0.131 | P13: 0.103 | Q13: 0.098 | R13: 0.071
... A1159: 2003 | B1159: 279 | C1159: FISE | D1159: 106 | E1159: 0.194 | F1159: 0.207 | G1159: 0.207 | H1159: 0.199 | I1159: 0.139 | J1159: 0.13 | K1159: 0.131 | L1159: 0.158 | M1159: 0.166 | N1159: 0.15 | O1159: 0.127 | P1159: 0.103 | Q1159: 0.073 | R1159: 0.104
A1160: 2003 | B1160: 279 | C1160: FISE | D1160: 107 | E1160: 0.189 | F1160: 0.211 | G1160: 0.204 | H1160: 0.16 | I1160: 0.13 | J1160: 0.126 | K1160: 0.126 | L1160: 0.146 | M1160: 0.136 | N1160: 0.125 | O1160: 0.109 | P1160: 0.109 | Q1160: 0.069
A1161: 2003 | B1161: 279 | C1161: FISE | D1161: 108 | E1161: 0.151 | F1161: 0.154 | G1161: 0.127 | H1161: 0.107 | I1161: 0.108 | J1161: 0.116 | K1161: 0.139 | L1161: 0.16 | M1161: 0.167 | N1161: 0.141 | O1161: 0.102 | P1161: 0.096 | Q1161: 0.061 | R1161: 0.099
A1162: 2003 | B1162: 279 | C1162: FISE | D1162: 201 | E1162: 0.208 | F1162: 0.202 | G1162: 0.173 | H1162: 0.13 | I1162: 0.124 | J1162: 0.143 | K1162: 0.15 | L1162: 0.17 | M1162: 0.163 | N1162: 0.148 | O1162: 0.134 | P1162: 0.113 | Q1162: 0.073 | R1162: 0.09
A1163: 2003 | B1163: 279 | C1163: FISE | D1163: 202 | E1163: 0.202 | F1163: 0.17 | G1163: 0.145 | H1163: 0.116 | I1163: 0.111 | J1163: 0.084 | K1163: 0.077 | L1163: 0.075 | M1163: 0.076 | N1163: 0.077 | O1163: 0.086 | P1163: 0.099 | Q1163: 0.067 | R1163: 0.097
A1164: 2003 | B1164: 279 | C1164: FISE | D1164: 203 | E1164: 0.204 | F1164: 0.205 | G1164: 0.202 | H1164: 0.149 | I1164: 0.128 | J1164: 0.133 | K1164: 0.144 | L1164: 0.164 | M1164: 0.159 | N1164: 0.143 | O1164: 0.12 | P1164: 0.102 | Q1164: 0.067 | R1164: 0.1
A1165: 2003 | B1165: 279 | C1165: FISE | D1165: 204 | E1165: 0.198 | F1165: 0.201 | G1165: 0.213 | H1165: 0.149 | I1165: 0.128 | J1165: 0.135 | K1165: 0.141 | L1165: 0.163 | M1165: 0.163 | N1165: 0.154 | O1165: 0.115 | P1165: 0.105 | Q1165: 0.071 | R1165: 0.071
A1166: 2003 | B1166: 279 | C1166: FISE | D1166: 205 | E1166: 0.212 | F1166: 0.213 | G1166: 0.206 | H1166: 0.178 | I1166: 0.124 | J1166: 0.118 | K1166: 0.128 | L1166: 0.154 | M1166: 0.178 | N1166: 0.169 | O1166: 0.167 | P1166: 0.118 | Q1166: 0.069 | R1166: 0.099
A1167: 2003 | B1167: 279 | C1167: FISE | D1167: 206 | E1167: 0.177 | F1167: 0.187 | G1167: 0.18 | H1167: 0.189 | I1167: 0.147 | J1167: 0.149 | K1167: 0.152 | L1167: 0.156 | M1167: 0.149 | O1167: 0.118 | P1167: 0.107 | Q1167: 0.072 | R1167: 0.061
A1168: 2003 | B1168: 279 | C1168: FISE | D1168: 207 | E1168: 0.177 | F1168: 0.178 | G1168: 0.166 | H1168: 0.136 | I1168: 0.133 | J1168: 0.142 | K1168: 0.148 | L1168: 0.167 | M1168: 0.167 | N1168: 0.159 | O1168: 0.111 | P1168: 0.112 | Q1168: 0.076 | R1168: 0.097
A1169: 2003 | B1169: 279 | C1169: FISE | D1169: 208 | E1169: 0.203 | F1169: 0.201 | G1169: 0.16 | H1169: 0.13 | I1169: 0.122 | J1169: 0.119 | K1169: 0.107 | L1169: 0.117 | M1169: 0.125 | N1169: 0.101 | O1169: 0.092 | P1169: 0.099 | Q1169: 0.069 | R1169: 0.07
A1170: 2003 | B1170: 279 | C1170: FISE | D1170: 301 | E1170: 0.205 | F1170: 0.234 | G1170: 0.231 | H1170: 0.225 | I1170: 0.21 | J1170: 0.121 | K1170: 0.102 | L1170: 0.123 | M1170: 0.165 | N1170: 0.174 | O1170: 0.16 | P1170: 0.125 | Q1170: 0.075 | R1170: 0.077
A1171: 2003 | B1171: 279 | C1171: FISE | D1171: 302 | E1171: 0.243 | F1171: 0.232 | G1171: 0.234 | H1171: 0.251 | I1171: 0.204 | J1171: 0.172 | K1171: 0.164 | L1171: 0.165 | M1171: 0.186 | N1171: 0.175 | O1171: 0.129 | P1171: 0.117 | Q1171: 0.072 | R1171: 0.109
A1172: 2003 | B1172: 279 | C1172: FISE | D1172: 303 | E1172: 0.236 | F1172: 0.223 | G1172: 0.232 | H1172: 0.227 | I1172: 0.15 | J1172: 0.155 | K1172: 0.156 | L1172: 0.181 | M1172: 0.189 | N1172: 0.181 | O1172: 0.163 | P1172: 0.117 | Q1172: 0.074 | R1172: 0.086
A1173: 2003 | B1173: 279 | C1173: FISE | D1173: 304 | E1173: 0.207 | F1173: 0.215 | G1173: 0.212 | H1173: 0.192 | I1173: 0.173 | J1173: 0.181 | K1173: 0.179 | L1173: 0.172 | M1173: 0.172 | N1173: 0.173 | O1173: 0.159 | P1173: 0.123 | Q1173: 0.071 | R1173: 0.069
A1174: 2003 | B1174: 279 | C1174: FISE | D1174: 305 | E1174: 0.223 | F1174: 0.232 | G1174: 0.235 | H1174: 0.238 | I1174: 0.177 | J1174: 0.136 | K1174: 0.129 | L1174: 0.122 | M1174: 0.128 | N1174: 0.127 | O1174: 0.129 | P1174: 0.105 | Q1174: 0.071 | R1174: 0.074
A1175: 2003 | B1175: 279 | C1175: FISE | D1175: 306 | E1175: 0.225 | F1175: 0.231 | G1175: 0.243 | H1175: 0.231 | I1175: 0.156 | J1175: 0.167 | K1175: 0.164 | L1175: 0.16 | M1175: 0.187 | N1175: 0.188 | O1175: 0.179 | P1175: 0.135 | Q1175: 0.085 | R1175: 0.067
A1176: 2003 | B1176: 279 | C1176: FISE | D1176: 307 | E1176: 0.207 | F1176: 0.221 | G1176: 0.224 | H1176: 0.223 | I1176: 0.187 | J1176: 0.128 | K1176: 0.127 | L1176: 0.145 | M1176: 0.154 | N1176: 0.154 | O1176: 0.12 | P1176: 0.101 | Q1176: 0.066 | R1176: 0.051
A1177: 2003 | B1177: 279 | C1177: FISE | D1177: 308 | E1177: 0.222 | F1177: 0.23 | G1177: 0.229 | H1177: 0.208 | I1177: 0.201 | J1177: 0.132 | K1177: 0.094 | L1177: 0.091 | M1177: 0.079 | N1177: 0.078 | O1177: 0.074 | P1177: 0.088 | Q1177: 0.069 | R1177: 0.078
A1178: 2003 | B1178: 279 | C1178: FISE | D1178: 401 | E1178: 0.211 | F1178: 0.235 | G1178: 0.239 | H1178: 0.243 | I1178: 0.196 | J1178: 0.135 | K1178: 0.112 | L1178: 0.13 | M1178: 0.13 | N1178: 0.136 | O1178: 0.137 | P1178: 0.107 | Q1178: 0.066 | R1178: 0.067
A1179: 2003 | B1179: 279 | C1179: FISE | D1179: 402 | E1179: 0.186 | F1179: 0.211 | G1179: 0.21 | H1179: 0.22 | I1179: 0.215 | J1179: 0.115 | K1179: 0.121 | L1179: 0.111 | M1179: 0.149 | N1179: 0.154 | O1179: 0.146 | P1179: 0.123 | Q1179: 0.078 | R1179: 0.095
... A1217: 2003 | B1217: 282 | C1217: FISE | D1217: 408 | E1217: 0.209 | F1217: 0.186 | G1217: 0.188 | H1217: 0.186 | I1217: 0.163 | J1217: 0.14 | K1217: 0.107 | L1217: 0.122 | M1217: 0.143 | N1217: 0.182 | O1217: 0.182 | P1217: 0.162 | Q1217: 0.119 | R1217: 0.09

Sheet A
A1: DOY (Julian) | F1: 104 | M1: 115 | U1: 120 | AC1: 127 | AK1: 132 | AS1: 136 | BA1: 141 | BI1: 143 | BQ1: 147 | BY1: 149 | CG1: 151 | CO1: 152 | CW1: 155 | DE1: 156 | DM1: 159 | DU1: 161 | EC1: 162 | EK1: 163 | ES1: 164 | FA1: 166 | FI1: 167 | FQ1: 168 | FY1: 169 | GG1: 171 | GO1: 173 | GW1: 176 | HE1: 177 | HM1: 178 | HU1: 181 | IC1: 184 | IK1: 185 | IS1: 188
A2: RS cotton 2003 | C2: Neutron/TDR readings | H2: RS cotton 2003 | J2: Neutron/TDR readings | P2: RS cotton 2003 | R2: Neutron/TDR readings | X2: RS cotton 2003 | Z2: Neutron/TDR readings | AF2: RS cotton 2003 | AH2: Neutron/TDR readings | AN2: RS cotton 2003 | AP2: Neutron/TDR readings | AV2: RS cotton 2003 | AX2: Neutron/TDR readings | BD2: RS cotton 2003 | BF2: Neutron/TDR readings | BL2: RS cotton 2003 | BN2: Neutron/TDR readings | BT2: RS cotton 2003 | BV2: Neutron/TDR readings | CB2: RS cotton 2003 | CD2: Neutron/TDR readings | CJ2: RS cotton 2003 | CL2: Neutron/TDR readings | CR2: RS cotton 2003 | CT2: Neutron/TDR readings | CZ2: RS cotton 2003 | DB2: Neutron/TDR readings | DH2: RS cotton 2003 | DJ2: Neutron/TDR readings | DP2: RS cotton 2003 | DR2: Neutron/TDR readings | DX2: RS cotton 2003 | DZ2: Neutron/TDR readings | EF2: RS cotton 2003 | EH2: Neutron/TDR readings | EN2: RS cotton 2003 | EP2: Neutron/TDR readings | EV2: RS cotton 2003 | EX2: Neutron/TDR readings | FD2: RS cotton 2003 | FF2: Neutron/TDR readings | FL2: RS cotton 2003 | FN2: Neutron/TDR readings | FT2: RS cotton 2003 | FV2: Neutron/TDR readings | GB2: RS cotton 2003 | GD2: Neutron/TDR readings | GJ2: RS cotton 2003 | GL2: Neutron/TDR readings | GR2: RS cotton 2003 | GT2: Neutron/TDR readings | GZ2: RS cotton 2003 | HB2: Neutron/TDR readings | HH2: RS cotton 2003 | HJ2: Neutron/TDR readings | HP2: RS cotton 2003 | HR2: Neutron/TDR readings | HX2: RS cotton 2003 | HZ2: Neutron/TDR readings | IF2: RS cotton 2003 | IH2: Neutron/TDR readings | IN2: RS cotton 2003 | IP2: Neutron/TDR readings
A3: Treatdment summary | C3: 0-170 cm depth | H3: Treatdment summary | J3: 0-170 cm depth | L3: After irrig. | P3: Treatdment summary | R3: 0-170 cm depth | T3: Before irrig. | X3: Treatdment summary | Z3: 0-170 cm depth | AB3: After irrig. | AF3: Treatdment summary | AH3: 0-170 cm depth | AJ3: After irrig. | AN3: Treatdment summary | AP3: 0-170 cm depth | AR3: After irrig. | AV3: Treatdment summary | AX3: 0-170 cm depth | BD3: Treatdment summary | BF3: 0-170 cm depth | BL3: Treatdment summary | BN3: 0-170 cm depth | BT3: Treatdment summary | BV3: 0-170 cm depth | CB3: Treatdment summary | CD3: 0-170 cm depth | CJ3: Treatdment summary | CL3: 0-170 cm depth | CR3: Treatdment summary | CT3: 0-170 cm depth | CZ3: Treatdment summary | DB3: 0-170 cm depth | DH3: Treatdment summary | DJ3: 0-170 cm depth | DP3: Treatdment summary | DR3: 0-170 cm depth | DX3: Treatdment summary | DZ3: 0-170 cm depth | EF3: Treatdment summary | EH3: 0-170 cm depth | EN3: Treatdment summary | EP3: 0-170 cm depth | EV3: Treatdment summary | EX3: 0-170 cm depth | FD3: Treatdment summary | FF3: 0-170 cm depth | FL3: Treatdment summary | FN3: 0-170 cm depth | FT3: Treatdment summary | FV3: 0-170 cm depth | GB3: Treatdment summary | GD3: 0-170 cm depth | GJ3: Treatdment summary | GL3: 0-170 cm depth | GR3: Treatdment summary | GT3: 0-170 cm depth | GZ3: Treatdment summary | HB3: 0-170 cm depth | HH3: Treatdment summary | HJ3: 0-170 cm depth | HP3: Treatdment summary | HR3: 0-170 cm depth | HX3: Treatdment summary | HZ3: 0-170 cm depth | IF3: Treatdment summary | IH3: 0-170 cm depth | IN3: Treatdment summary | IP3: 0-170 cm depth
A4: Date: 14-Apr-03 | C4: File name: RS10403 | F4: Cum | H4: Date: 25-Apr-03 | J4: File name: RS11503 | M4: Cum | N4: Accum. | P4: Date: 30-Apr-03 | R4: File name: RS12003 | U4: Cum | V4: Accum. | X4: Date: 7-May-03 | Z4: File name: RS12703 | AC4: Cum | AD4: Accum. | AF4: Date: 12-May-03 | AH4: File name: RS13203 | AK4: Cum | AL4: Accum. | AN4: Date: 16-May-03 | AP4: File name: RS13603 | AS4: Cum | AT4: Accum. | AV4: Date: 21-May-03 | AX4: File name: RS14103 | BA4: Cum | BB4: Accum. | BD4: Date: 23-May-03 | BF4: File name: RS14303 | BI4: Cum | BJ4: Accum. | BL4: Date: 27-May-03 | BN4: File name: RS14703 | BQ4: Cum | BR4: Accum. | BT4: Date: 29-May-03 | BV4: File name: RS14903 | BY4: Cum | BZ4: Accum. | CB4: Date: 31-May-03 | CD4: File name: RS15103 | CG4: Cum | CH4: Accum. | CJ4: Date: 01-Jun-03 | CL4: File name: RS15203 | CO4: Cum | CP4: Accum. | CR4: Date: 04-Jun-03 | CT4: File name: RS15503 | CW4: Cum | CX4: Accum. | CZ4: Date: 05-Jun-03 | DB4: File name: RS15603 | DE4: Cum | DF4: Accum. | DH4: Date: 08-Jun-03 | DJ4: File name: RS15903 | DM4: Cum | DN4: Accum. | DP4: Date: 10-Jun-03 | DR4: File name: RS16103 | DU4: Cum | DV4: Accum. | DX4: Date: 11-Jun-03 | DZ4: File name: RS16203 | EC4: Cum | ED4: Accum. | EF4: Date: 12-Jun-03 | EH4: File name: RS16303 | EK4: Cum | EL4: Accum. | EN4: Date: 13-Jun-03 | EP4: File name: RS16403 | ES4: Cum | ET4: Accum. | EV4: Date: 15-Jun-03 | EX4: File name: RS16603 | FA4: Cum | FB4: Accum. | FD4: Date: 16-Jun-03 | FF4: File name: RS16703 | FI4: Cum | FJ4: Accum. | FL4: Date: 17-Jun-03 | FN4: File name: RS16903 | FQ4: Cum | FR4: Accum. | FT4: Date: 18-Jun-03 | FV4: File name: RS16903 | FY4: Cum | FZ4: Accum. | GB4: Date: 20-Jun-03 | GD4: File name: RS17103 | GG4: Cum | GH4: Accum. | GJ4: Date: 22-Jun-03 | GL4: File name: RS17303 | GO4: Cum | GP4: Accum. | GR4: Date: 25-Jun-03 | GT4: File name: RS17603 | GW4: Cum | GX4: Accum. | GZ4: Date: 26-Jun-03 | HB4: File name: RS17703 | HE4: Cum | HF4: Accum. | HH4: Date: 27-Jun-03 | HJ4: File name: RS17803 | HM4: Cum | HN4: Accum. | HP4: Date: 30-Jun-03 | HR4: File name: RS18103 | HU4: Cum | HV4: Accum. | HX4: Date: 03-Jul-03 | HZ4: File name: RS18403 | IC4: Cum | ID4: Accum. | IF4: Date: 04-Jul-03 | IH4: File name: RS18803 | II4: RS18503 | IK4: Cum | IL4: Accum. | IN4: Date: 07-Jul-03 | IP4: File name: RS18803 | IS4: Cum | IT4: Accum.
C5: ALL | F5: Storage | J5: ALL | M5: Storage | N5: diff | U5: Storage | V5: diff | AC5: Storage | AD5: diff | AK5: Storage | AL5: diff | AS5: Storage | AT5: diff | AX5: ALL | BA5: Storage | BB5: diff | BF5: NDH-L | BI5: Storage | BJ5: diff | BN5: ALL | BQ5: Storage | BR5: diff | BV5: NSH-L | BY5: Storage | BZ5: diff | CD5: FAO-NTH-L | CG5: Storage | CH5: diff | CL5: NDH-L-NSH-L | CO5: Storage | CP5: diff | CT5: NDH-L | CW5: Storage | CX5: diff | DB5: ALL BUT NDH-L | DE5: Storage | DF5: diff | DJ5: NDH-L | DM5: Storage | DN5: diff | DR5: FAO | DU5: Storage | DV5: diff | DZ5: 2 NTH-L | EC5: Storage | ED5: diff | EH5: NTH-L | EK5: Storage | EL5: diff | EP5: FAO and 1 NTH-L | ES5: Storage | ET5: diff | EX5: NDVI and FSH | FA5: Storage | FB5: diff | FF5: NTH-L | FI5: Storage | FJ5: diff | FN5: All but NSH | FQ5: Storage | FR5: diff | FV5: All but NSH | FY5: Storage | FZ5: diff | GD5: NSH | GG5: Storage | GH5: diff | GL5: FAO | GO5: Storage | GP5: diff | GT5: NDH-L & NTH | GW5: Storage | GX5: diff | HB5: FAO | HE5: Storage | HF5: diff | HJ5: NTH | HM5: Storage | HN5: diff | HR5: All | HU5: Storage | HV5: diff | HZ5: All but NSL, 1NTL and 1NTH | IC5: Storage | ID5: diff | IH5: NDH-L | IK5: Storage | IL5: diff | IP5: NDH-L | IS5: Storage | IT5: diff
A6: Tube no. | B6: Trt/Rep | C6: Depth cm | D6: % H2O | E6: H2O cm | F6: cm | H6: Tube no. | I6: Trt/Rep | J6: Depth cm | K6: % H2O | L6: H2O cm | M6: cm | N6: cm | P6: Tube no. | Q6: Trt/Rep | R6: Depth cm | S6: % H2O | T6: H2O cm | U6: cm | V6: cm | X6: Tube no. | Y6: Trt/Rep | Z6: Depth cm | AA6: % H2O | AB6: H2O cm | AC6: cm | AD6: cm | AF6: Tube no. | AG6: Trt/Rep | AH6: Depth cm | AI6: % H2O | AJ6: H2O cm | AK6: cm | AL6: cm | AN6: Tube no. | AO6: Trt/Rep | AP6: Depth cm | AQ6: % H2O | AR6: H2O cm | AS6: cm | AT6: cm | AV6: Tube no. | AW6: Trt/Rep | AX6: Depth cm | AY6: % H2O | AZ6: H2O cm | BA6: cm | BB6: cm | BD6: Tube no. | BE6: Trt/Rep | BF6: Depth cm | BG6: % H2O | BH6: H2O cm | BI6: cm | BJ6: cm | BL6: Tube no. | BM6: Trt/Rep | BN6: Depth cm | BO6: % H2O | BP6: H2O cm | BQ6: cm | BR6: cm | BT6: Tube no. | BU6: Trt/Rep | BV6: Depth cm | BW6: % H2O | BX6: H2O cm | BY6: cm | BZ6: cm | CB6: Tube no. | CC6: Trt/Rep | CD6: Depth cm | CE6: % H2O | CF6: H2O cm | CG6: cm | CH6: cm | CJ6: Tube no. | CK6: Trt/Rep | CL6: Depth cm | CM6: % H2O | CN6: H2O cm | CO6: cm | CP6: cm | CR6: Tube no. | CS6: Trt/Rep | CT6: Depth cm | CU6: % H2O | CV6: H2O cm | CW6: cm | CX6: cm | CZ6: Tube no. | DA6: Trt/Rep | DB6: Depth cm | DC6: % H2O | DD6: H2O cm | DE6: cm | DF6: cm | DH6: Tube no. | DI6: Trt/Rep | DJ6: Depth cm | DK6: % H2O | DL6: H2O cm | DM6: cm | DN6: cm | DP6: Tube no. | DQ6: Trt/Rep | DR6: Depth cm | DS6: % H2O | DT6: H2O cm | DU6: cm | DV6: cm | DX6: Tube no. | DY6: Trt/Rep | DZ6: Depth cm | EA6: % H2O | EB6: H2O cm | EC6: cm | ED6: cm | EF6: Tube no. | EG6: Trt/Rep | EH6: Depth cm | EI6: % H2O | EJ6: H2O cm | EK6: cm | EL6: cm | EN6: Tube no. | EO6: Trt/Rep | EP6: Depth cm | EQ6: % H2O | ER6: H2O cm | ES6: cm | ET6: cm | EV6: Tube no. | EW6: Trt/Rep | EX6: Depth cm | EY6: % H2O | EZ6: H2O cm | FA6: cm | FB6: cm | FD6: Tube no. | FE6: Trt/Rep | FF6: Depth cm | FG6: % H2O | FH6: H2O cm | FI6: cm | FJ6: cm | FL6: Tube no. | FM6: Trt/Rep | FN6: Depth cm | FO6: % H2O | FP6: H2O cm | FQ6: cm | FR6: cm | FT6: Tube no. | FU6: Trt/Rep | FV6: Depth cm | FW6: % H2O | FX6: H2O cm | FY6: cm | FZ6: cm | GB6: Tube no. | GC6: Trt/Rep | GD6: Depth cm | GE6: % H2O | GF6: H2O cm | GG6: cm | GH6: cm | GJ6: Tube no. | GK6: Trt/Rep | GL6: Depth cm | GM6: % H2O | GN6: H2O cm | GO6: cm | GP6: cm | GR6: Tube no. | GS6: Trt/Rep | GT6: Depth cm | GU6: % H2O | GV6: H2O cm | GW6: cm | GX6: cm | GZ6: Tube no. | HA6: Trt/Rep | HB6: Depth cm | HC6: % H2O | HD6: H2O cm | HE6: cm | HF6: cm | HH6: Tube no. | HI6: Trt/Rep | HJ6: Depth cm | HK6: % H2O | HL6: H2O cm | HM6: cm | HN6: cm | HP6: Tube no. | HQ6: Trt/Rep | HR6: Depth cm | HS6: % H2O | HT6: H2O cm | HU6: cm | HV6: cm | HX6: Tube no. | HY6: Trt/Rep | HZ6: Depth cm | IA6: % H2O | IB6: H2O cm | IC6: cm | ID6: cm | IF6: Tube no. | IG6: Trt/Rep | IH6: Depth cm | II6: % H2O | IJ6: H2O cm | IK6: cm | IL6: cm | IN6: Tube no. | IO6: Trt/Rep | IP6: Depth cm | IQ6: % H2O | IR6: H2O cm | IS6: cm | IT6: cm
A7: 101 | B7: T1R1 | C7: 30 | D7: 0.082 | E7: =D7*30 -> 2.46 | F7: =E7 -> 2.46 | H7: 101 | I7: T1R1 | J7: 30 | K7: 0.192 | L7: =K7*30 -> 5.76 | M7: =L7 -> 5.76 | N7: =F7-M7 -> -3.3 | P7: 101 | Q7: T1R1 | R7: 30 | S7: 0.173 | T7: =S7*30 -> 5.19 | U7: =T7 -> 5.19 | V7: =M7-U7 -> 0.57 | X7: 101 | Y7: T1R1 | Z7: 30 | AA7: 0.142 | AB7: =AA7*30 -> 4.26 | AC7: =AB7 -> 4.26 | AD7: =U7-AC7 -> 0.93 | AF7: 101 | AG7: T1R1 | AH7: 30 | AI7: 0.208 | AJ7: =AI7*30 -> 6.24 | AK7: =AJ7 -> 6.24 | AL7: =AC7-AK7 -> -1.98 | AN7: 101 | AO7: T1R1 | AP7: 30 | AQ7: 0.192 | AR7: =AQ7*30 -> 5.76 | AS7: =AR7 -> 5.76 | AT7: =AK7-AS7 -> 0.48 | AV7: 101 | AW7: T1R1 | AX7: 30 | AY7: 0.177 | AZ7: =AY7*30 -> 5.31 | BA7: =AZ7 -> 5.31 | BB7: =AS7-BA7 -> 0.45 | BD7: 101 | BE7: T1R1 | BF7: 30 | BG7: 0 | BH7: =BG7*30 -> 0 | BI7: =BH7 -> 0 | BJ7: 0 | BL7: 101 | BM7: T1R1 | BN7: 30 | BO7: 0.16 | BP7: =BO7*30 -> 4.8 | BQ7: =BP7 -> 4.8 | BR7: =BA7-BQ7 -> 0.51 | BT7: 101 | BU7: T1R1 | BV7: 30 | BW7: 0 | BX7: =BW7*30 -> 0 | BY7: =BX7 -> 0 | BZ7: 0 | CB7: 101 | CC7: T1R1 | CD7: 30 | CE7: 0 | CF7: =CE7*30 -> 0 | CG7: =CF7 -> 0 | CH7: =BY7-CG7 -> 0 | CJ7: 101 | CK7: T1R1 | CL7: 30 | CM7: 0 | CN7: =CM7*30 -> 0 | CO7: =CN7 -> 0 | CP7: =CG7-CO7 -> 0 | CR7: 101 | CS7: T1R1 | CT7: 30 | CU7: 0 | CV7: =CU7*30 -> 0 | CW7: =CV7 -> 0 | CX7: =CO7-CW7 -> 0 | CZ7: 101 | DA7: T1R1 | DB7: 30 | DC7: 0.173 | DD7: =DC7*30 -> 5.19 | DE7: =DD7 -> 5.19 | DF7: =BQ7-DE7 -> -0.39 | DH7: 101 | DI7: T1R1 | DJ7: 30 | DK7: 0 | DL7: =DK7*30 -> 0 | DM7: =DL7 -> 0 | DN7: 0 | DP7: 101 | DQ7: T1R1 | DR7: 30 | DS7: 0.145 | DT7: =DS7*30 -> 4.35 | DU7: =DT7 -> 4.35 | DV7: =DE7-DU7 -> 0.84 | DX7: 101 | DY7: T1R1 | DZ7: 30 | EA7: 0 | EB7: =EA7*30 -> 0 | EC7: =EB7 -> 0 | ED7: 0 | EF7: 101 | EG7: T1R1 | EH7: 30 | EI7: 0 | EJ7: =EI7*30 -> 0 | EK7: =EJ7 -> 0 | EL7: =EC459-EK7 -> 0 | EN7: 101 | EO7: T1R1 | EP7: 30 | EQ7: 0.204 | ER7: =EQ7*30 -> 6.12 | ES7: =ER7 -> 6.12 | ET7: =DU7-ES7 -> -1.77 | EV7: 101 | EW7: T1R1 | EX7: 30 | EY7: 0 | EZ7: =EY7*30 -> 0 | FA7: =EZ7 -> 0 | FB7: 0 | FD7: 101 | FE7: T1R1 | FF7: 30 | FG7: 0 | FH7: =FG7*30 -> 0 | FI7: =FH7 -> 0 | FJ7: 0 | FL7: 101 | FM7: T1R1 | FN7: 30 | FO7: 0 | FP7: =FO7*30 -> 0 | FQ7: =FP7 -> 0 | FR7: 0 | FT7: 101 | FU7: T1R1 | FV7: 30 | FW7: 0.166 | FX7: =FW7*30 -> 4.98 | FY7: =FX7 -> 4.98 | FZ7: =ES7-FY7 -> 1.14 | GB7: 101 | GC7: T1R1 | GD7: 30 | GE7: 0 | GF7: =GE7*30 -> 0 | GG7: =GF7 -> 0 | GH7: 0 | GJ7: 101 | GK7: T1R1 | GL7: 30 | GM7: 0.122 | GN7: =GM7*30 -> 3.66 | GO7: =GN7 -> 3.66 | GP7: =FY7-GO7 -> 1.32 | GR7: 101 | GS7: T1R1 | GT7: 30 | GU7: 0 | GV7: =GU7*30 -> 0 | GW7: =GV7 -> 0 | GX7: 0 | GZ7: 101 | HA7: T1R1 | HB7: 30 | HC7: 0.192 | HD7: =HC7*30 -> 5.76 | HE7: =HD7 -> 5.76 | HF7: =GO7-HE7 -> -2.1 | HH7: 101 | HI7: T1R1 | HJ7: 30 | HK7: 0 | HL7: =HK7*30 -> 0 | HM7: =HL7 -> 0 | HN7: 0 | HP7: 101 | HQ7: T1R1 | HR7: 30 | HS7: 0.148 | HT7: =HS7*30 -> 4.44 | HU7: =HT7 -> 4.44 | HV7: =HE7-HU7 -> 1.32 | HX7: 101 | HY7: T1R1 | HZ7: 30 | IA7: 0.128 | IB7: =IA7*30 -> 3.84 | IC7: =IB7 -> 3.84 | ID7: =HU7-IC7 -> 0.6 | IF7: 101 | IG7: T1R1 | IH7: 30 | II7: 0 | IJ7: =II7*30 -> 0 | IK7: =IJ7 -> 0 | IL7: 0 | IN7: 101 | IO7: T1R1 | IP7: 30 | IQ7: 0.197 | IR7: =IQ7*30 -> 5.91 | IS7: =IR7 -> 5.91 | IT7: =IC7-IS7 -> -2.07
A8: W to E | C8: 50 | D8: 0.093 | E8: =D8*20 -> 1.86 | F8: =F7+E8 -> 4.32 | H8: W to E | J8: 50 | K8: 0.17125005 | L8: =K8*20 -> 3.4250009 | M8: =M7+L8 -> 9.1850009 | N8: =F8-M8 -> -4.8650009 | P8: W to E | R8: 50 | S8: 0.16257909 | T8: =S8*20 -> 3.2515817 | U8: =U7+T8 -> 8.4415817 | V8: =M8-U8 -> 0.74341924 | X8: W to E | Z8: 50 | AA8: 0.16474516 | AB8: =AA8*20 -> 3.2949032 | AC8: =AC7+AB8 -> 7.5549032 | AD8: =U8-AC8 -> 0.88667849 | AF8: W to E | AH8: 50 | AI8: 0.18636273 | AJ8: =AI8*20 -> 3.7272546 | AK8: =AK7+AJ8 -> 9.9672546 | AL8: =AC8-AK8 -> -2.4123514 | AN8: W to E | AP8: 50 | AQ8: 0.17996669 | AR8: =AQ8*20 -> 3.5993338 | AS8: =AS7+AR8 -> 9.3593338 | AT8: =AK8-AS8 -> 0.60792083 | AV8: W to E | AX8: 50 | AY8: 0.17726916 | AZ8: =AY8*20 -> 3.5453832 | BA8: =BA7+AZ8 -> 8.8553832 | BB8: =AS8-BA8 -> 0.5039506 | BD8: W to E | BF8: 50 | BG8: 0 | BH8: =BG8*20 -> 0 | BI8: =BI7+BH8 -> 0 | BJ8: 0 | BL8: W to E | BN8: 50 | BO8: 0.16797553 | BP8: =BO8*20 -> 3.3595106 | BQ8: =BQ7+BP8 -> 8.1595106 | BR8: =BA8-BQ8 -> 0.69587258 | BT8: W to E | BV8: 50 | BW8: 0 | BX8: =BW8*20 -> 0 | BY8: =BY7+BX8 -> 0 | BZ8: 0 | CB8: W to E | CD8: 50 | CE8: 0 | CF8: =CE8*20 -> 0 | CG8: =CG7+CF8 -> 0 | CH8: =BY8-CG8 -> 0 | CJ8: W to E | CL8: 50 | CM8: 0 | CN8: =CM8*20 -> 0 | CO8: =CO7+CN8 -> 0 | CP8: =CG8-CO8 -> 0 | CR8: W to E | CT8: 50 | CU8: 0 | CV8: =CU8*20 -> 0 | CW8: =CW7+CV8 -> 0 | CX8: =CO8-CW8 -> 0 | CZ8: W to E | DB8: 50 | DC8: 0.17133762 | DD8: =DC8*20 -> 3.4267523 | DE8: =DE7+DD8 -> 8.6167523 | DF8: =BQ8-DE8 -> -0.45724175 | DH8: W to E | DJ8: 50 | DK8: 0 | DL8: =DK8*20 -> 0 | DM8: =DM7+DL8 -> 0 | DN8: 0 | DP8: W to E | DR8: 50 | DS8: 0.15261779 | DT8: =DS8*20 -> 3.0523559 | DU8: =DU7+DT8 -> 7.4023559 | DV8: =DE8-DU8 -> 1.2143964 | DX8: W to E | DZ8: 50 | EA8: 0 | EB8: =EA8*20 -> 0 | EC8: =EC7+EB8 -> 0 | ED8: 0 | EF8: W to E | EH8: 50 | EI8: 0 | EJ8: =EI8*20 -> 0 | EK8: =EK7+EJ8 -> 0 | EL8: =EC460-EK8 -> 0 | EN8: W to E | EP8: 50 | EQ8: 0.18681171 | ER8: =EQ8*20 -> 3.7362342 | ES8: =ES7+ER8 -> 9.8562342 | ET8: =DU8-ES8 -> -2.4538783 | EV8: W to E | EX8: 50 | EY8: 0 | EZ8: =EY8*20 -> 0 | FA8: =FA7+EZ8 -> 0 | FB8: 0 | FD8: W to E | FF8: 50 | FG8: 0 | FH8: =FG8*20 -> 0 | FI8: =FI7+FH8 -> 0 | FJ8: 0 | FL8: W to E | FN8: 50 | FO8: 0 | FP8: =FO8*20 -> 0 | FQ8: =FQ7+FP8 -> 0 | FR8: 0 | FT8: W to E | FV8: 50 | FW8: 0.15678036 | FX8: =FW8*20 -> 3.1356073 | FY8: =FY7+FX8 -> 8.1156073 | FZ8: =ES8-FY8 -> 1.7406269 | GB8: W to E | GD8: 50 | GE8: 0 | GF8: =GE8*20 -> 0 | GG8: =GG7+GF8 -> 0 | GH8: 0 | GJ8: W to E | GL8: 50 | GM8: 0.12316134 | GN8: =GM8*20 -> 2.4632269 | GO8: =GO7+GN8 -> 6.1232269 | GP8: =FY8-GO8 -> 1.9923804 | GR8: W to E | GT8: 50 | GU8: 0 | GV8: =GU8*20 -> 0 | GW8: =GW7+GV8 -> 0 | GX8: 0 | GZ8: W to E | HB8: 50 | HC8: 0.18444103 | HD8: =HC8*20 -> 3.6888207 | HE8: =HE7+HD8 -> 9.4488207 | HF8: =GO8-HE8 -> -3.3255938 | HH8: W to E | HJ8: 50 | HK8: 0 | HL8: =HK8*20 -> 0 | HM8: =HM7+HL8 -> 0 | HN8: 0 | HP8: W to E | HR8: 50 | HS8: 0.15427731 | HT8: =HS8*20 -> 3.0855462 | HU8: =HU7+HT8 -> 7.5255462 | HV8: =HE8-HU8 -> 1.9232745 | HX8: W to E | HZ8: 50 | IA8: 0.11879648 | IB8: =IA8*20 -> 2.3759296 | IC8: =IC7+IB8 -> 6.2159296 | ID8: =HU8-IC8 -> 1.3096166 | IF8: W to E | IH8: 50 | II8: 0 | IJ8: =II8*20 -> 0 | IK8: =IK7+IJ8 -> 0 | IL8: 0 | IN8: W to E | IP8: 50 | IQ8: 0.1870427 | IR8: =IQ8*20 -> 3.7408539 | IS8: =IS7+IR8 -> 9.6508539 | IT8: =IC8-IS8 -> -3.4349243
C9: 70 | D9: 0.086 | E9: =D9*20 -> 1.72 | F9: =F8+E9 -> 6.04 | J9: 70 | K9: 0.16017439 | L9: =K9*20 -> 3.2034879 | M9: =M8+L9 -> 12.388489 | N9: =F9-M9 -> -6.3484888 | R9: 70 | S9: 0.1569982 | T9: =S9*20 -> 3.1399639 | U9: =U8+T9 -> 11.581546 | V9: =M9-U9 -> 0.80694321 | Z9: 70 | AA9: 0.15351189 | AB9: =AA9*20 -> 3.0702378 | AC9: =AC8+AB9 -> 10.625141 | AD9: =U9-AC9 -> 0.95640461 | AH9: 70 | AI9: 0.17246814 | AJ9: =AI9*20 -> 3.4493628 | AK9: =AK8+AJ9 -> 13.416617 | AL9: =AC9-AK9 -> -2.7914764 | AP9: 70 | AQ9: 0.16896844 | AR9: =AQ9*20 -> 3.3793687 | AS9: =AS8+AR9 -> 12.738703 | AT9: =AK9-AS9 -> 0.67791491 | AX9: 70 | AY9: 0.1653688 | AZ9: =AY9*20 -> 3.307376 | BA9: =BA8+AZ9 -> 12.162759 | BB9: =AS9-BA9 -> 0.57594338 | BF9: 70 | BG9: 0 | BH9: =BG9*20 -> 0 | BI9: =BI8+BH9 -> 0 | BJ9: 0 | BN9: 70 | BO9: 0.15320185 | BP9: =BO9*20 -> 3.0640371 | BQ9: =BQ8+BP9 -> 11.223548 | BR9: =BA9-BQ9 -> 0.93921146 | BV9: 70 | BW9: 0 | BX9: =BW9*20 -> 0 | BY9: =BY8+BX9 -> 0 | BZ9: 0 | CD9: 70 | CE9: 0 | CF9: =CE9*20 -> 0 | CG9: =CG8+CF9 -> 0 | CH9: =BY9-CG9 -> 0 | CL9: 70 | CM9: 0 | CN9: =CM9*20 -> 0 | CO9: =CO8+CN9 -> 0 | CP9: =CG9-CO9 -> 0 | CT9: 70 | CU9: 0 | CV9: =CU9*20 -> 0 | CW9: =CW8+CV9 -> 0 | CX9: =CO9-CW9 -> 0 | DB9: 70 | DC9: 0.1621389 | DD9: =DC9*20 -> 3.2427779 | DE9: =DE8+DD9 -> 11.85953 | DF9: =BQ9-DE9 -> -0.63598258 | DJ9: 70 | DK9: 0 | DL9: =DK9*20 -> 0 | DM9: =DM8+DL9 -> 0 | DN9: 0 | DR9: 70 | DS9: 0.14875646 | DT9: =DS9*20 -> 2.9751291 | DU9: =DU8+DT9 -> 10.377485 | DV9: =DE9-DU9 -> 1.4820452 | DZ9: 70 | EA9: 0 | EB9: =EA9*20 -> 0 | EC9: =EC8+EB9 -> 0 | ED9: 0 | EH9: 70 | EI9: 0 | EJ9: =EI9*20 -> 0 | EK9: =EK8+EJ9 -> 0 | EL9: =EC461-EK9 -> 0 | EP9: 70 | EQ9: 0.17465364 | ER9: =EQ9*20 -> 3.4930728 | ES9: =ES8+ER9 -> 13.349307 | ET9: =DU9-ES9 -> -2.971822 | EX9: 70 | EY9: 0 | EZ9: =EY9*20 -> 0 | FA9: =FA8+EZ9 -> 0 | FB9: 0 | FF9: 70 | FG9: 0 | FH9: =FG9*20 -> 0 | FI9: =FI8+FH9 -> 0 | FJ9: 0 | FN9: 70 | FO9: 0 | FP9: =FO9*20 -> 0 | FQ9: =FQ8+FP9 -> 0 | FR9: 0 | FV9: 70 | FW9: 0.15065604 | FX9: =FW9*20 -> 3.0131209 | FY9: =FY8+FX9 -> 11.128728 | FZ9: =ES9-FY9 -> 2.2205788 | GD9: 70 | GE9: 0 | GF9: =GE9*20 -> 0 | GG9: =GG8+GF9 -> 0 | GH9: 0 | GL9: 70 | GM9: 0.12912855 | GN9: =GM9*20 -> 2.582571 | GO9: =GO8+GN9 -> 8.7057979 | GP9: =FY9-GO9 -> 2.4229303 | GT9: 70 | GU9: 0 | GV9: =GU9*20 -> 0 | GW9: =GW8+GV9 -> 0 | GX9: 0 | HB9: 70 | HC9: 0.17200287 | HD9: =HC9*20 -> 3.4400574 | HE9: =HE8+HD9 -> 12.888878 | HF9: =GO9-HE9 -> -4.1830802 | HJ9: 70 | HK9: 0 | HL9: =HK9*20 -> 0 | HM9: =HM8+HL9 -> 0 | HN9: 0 | HR9: 70 | HS9: 0.15022711 | HT9: =HS9*20 -> 3.0045421 | HU9: =HU8+HT9 -> 10.530088 | HV9: =HE9-HU9 -> 2.3587898 | HZ9: 70 | IA9: 0.12179237 | IB9: =IA9*20 -> 2.4358473 | IC9: =IC8+IB9 -> 8.6517769 | ID9: =HU9-IC9 -> 1.8783113 | IH9: 70 | II9: 0 | IJ9: =II9*20 -> 0 | IK9: =IK8+IJ9 -> 0 | IL9: 0 | IP9: 70 | IQ9: 0.17146395 | IR9: =IQ9*20 -> 3.4292789 | IS9: =IS8+IR9 -> 13.080133 | IT9: =IC9-IS9 -> -4.4283559
C10: 90 | D10: 0.071 | E10: =D10*20 -> 1.42 | F10: =F9+E10 -> 7.46 | J10: 90 | K10: 0.15740548 | L10: =K10*20 -> 3.1481096 | M10: =M9+L10 -> 15.536598 | N10: =F10-M10 -> -8.0765985 | R10: 90 | S10: 0.14862686 | T10: =S10*20 -> 2.9725373 | U10: =U9+T10 -> 14.554083 | V10: =M10-U10 -> 0.98251559 | Z10: 90 | AA10: 0.14602304 | AB10: =AA10*20 -> 2.9204609 | AC10: =AC9+AB10 -> 13.545602 | AD10: =U10-AC10 -> 1.008481 | AH10: 90 | AI10: 0.16552085 | AJ10: =AI10*20 -> 3.3104169 | AK10: =AK9+AJ10 -> 16.727034 | AL10: =AC10-AK10 -> -3.1814325 | AP10: 90 | AQ10: 0.16296939 | AR10: =AQ10*20 -> 3.2593878 | AS10: =AS9+AR10 -> 15.99809 | AT10: =AK10-AS10 -> 0.72894401 | AX10: 90 | AY10: 0.15446014 | AZ10: =AY10*20 -> 3.0892027 | BA10: =BA9+AZ10 -> 15.251962 | BB10: =AS10-BA10 -> 0.7461285 | BF10: 90 | BG10: 0 | BH10: =BG10*20 -> 0 | BI10: =BI9+BH10 -> 0 | BJ10: 0 | BN10: 90 | BO10: 0.14926221 | BP10: =BO10*20 -> 2.9852442 | BQ10: =BQ9+BP10 -> 14.208792 | BR10: =BA10-BQ10 -> 1.04317 | BV10: 90 | BW10: 0 | BX10: =BW10*20 -> 0 | BY10: =BY9+BX10 -> 0 | BZ10: 0 | CD10: 90 | CE10: 0 | CF10: =CE10*20 -> 0 | CG10: =CG9+CF10 -> 0 | CH10: =BY10-CG10 -> 0 | CL10: 90 | CM10: 0 | CN10: =CM10*20 -> 0 | CO10: =CO9+CN10 -> 0 | CP10: =CG10-CO10 -> 0 | CT10: 90 | CU10: 0 | CV10: =CU10*20 -> 0 | CW10: =CW9+CV10 -> 0 | CX10: =CO10-CW10 -> 0 | DB10: 90 | DC10: 0.15089602 | DD10: =DC10*20 -> 3.0179203 | DE10: =DE9+DD10 -> 14.877451 | DF10: =BQ10-DE10 -> -0.66865873 | DJ10: 90 | DK10: 0 | DL10: =DK10*20 -> 0 | DM10: =DM9+DL10 -> 0 | DN10: 0 | DR10: 90 | DS10: 0.14392978 | DT10: =DS10*20 -> 2.8785956 | DU10: =DU9+DT10 -> 13.256081 | DV10: =DE10-DU10 -> 1.6213699 | DZ10: 90 | EA10: 0 | EB10: =EA10*20 -> 0 | EC10: =EC9+EB10 -> 0 | ED10: 0 | EH10: 90 | EI10: 0 | EJ10: =EI10*20 -> 0 | EK10: =EK9+EJ10 -> 0 | EL10: =EC462-EK10 -> 0 | EP10: 90 | EQ10: 0.16249557 | ER10: =EQ10*20 -> 3.2499113 | ES10: =ES9+ER10 -> 16.599218 | ET10: =DU10-ES10 -> -3.3431377 | EX10: 90 | EY10: 0 | EZ10: =EY10*20 -> 0 | FA10: =FA9+EZ10 -> 0 | FB10: 0 | FF10: 90 | FG10: 0 | FH10: =FG10*20 -> 0 | FI10: =FI9+FH10 -> 0 | FJ10: 0 | FN10: 90 | FO10: 0 | FP10: =FO10*20 -> 0 | FQ10: =FQ9+FP10 -> 0 | FR10: 0 | FV10: 90 | FW10: 0.15167676 | FX10: =FW10*20 -> 3.0335353 | FY10: =FY9+FX10 -> 14.162263 | FZ10: =ES10-FY10 -> 2.4369549 | GD10: 90 | GE10: 0 | GF10: =GE10*20 -> 0 | GG10: =GG9+GF10 -> 0 | GH10: 0 | GL10: 90 | GM10: 0.1420575 | GN10: =GM10*20 -> 2.84115 | GO10: =GO9+GN10 -> 11.546948 | GP10: =FY10-GO10 -> 2.6153156 | GT10: 90 | GU10: 0 | GV10: =GU10*20 -> 0 | GW10: =GW9+GV10 -> 0 | GX10: 0 | HB10: 90 | HC10: 0.16785682 | HD10: =HC10*20 -> 3.3571363 | HE10: =HE9+HD10 -> 16.246014 | HF10: =GO10-HE10 -> -4.6990665 | HJ10: 90 | HK10: 0 | HL10: =HK10*20 -> 0 | HM10: =HM9+HL10 -> 0 | HN10: 0 | HR10: 90 | HS10: 0.14718945 | HT10: =HS10*20 -> 2.9437891 | HU10: =HU9+HT10 -> 13.473877 | HV10: =HE10-HU10 -> 2.7721371 | HZ10: 90 | IA10: 0.1297814 | IB10: =IA10*20 -> 2.595628 | IC10: =IC9+IB10 -> 11.247405 | ID10: =HU10-IC10 -> 2.2264724 | IH10: 90 | II10: 0 | IJ10: =II10*20 -> 0 | IK10: =IK9+IJ10 -> 0 | IL10: 0 | IP10: 90 | IQ10: 0.16938678 | IR10: =IQ10*20 -> 3.3877356 | IS10: =IS9+IR10 -> 16.467868 | IT10: =IC10-IS10 -> -5.2204635
C11: 110 | D11: 0.075 | E11: =D11*20 -> 1.5 | F11: =F10+E11 -> 8.96 | J11: 110 | K11: 0.15940411 | L11: =K11*20 -> 3.1880821 | M11: =M10+L11 -> 18.724681 | N11: =F11-M11 -> -9.7646806 | R11: 110 | S11: 0.15792834 | T11: =S11*20 -> 3.1585669 | U11: =U10+T11 -> 17.71265 | V11: =M11-U11 -> 1.0120308 | Z11: 110 | AA11: 0.1553841 | AB11: =AA11*20 -> 3.107682 | AC11: =AC10+AB11 -> 16.653284 | AD11: =U11-AC11 -> 1.0593658 | AH11: 110 | AI11: 0.17544555 | AJ11: =AI11*20 -> 3.5089111 | AK11: =AK10+AJ11 -> 20.235945 | AL11: =AC11-AK11 -> -3.5826615 | AP11: 110 | AQ11: 0.17096812 | AR11: =AQ11*20 -> 3.4193624 | AS11: =AS10+AR11 -> 19.417453 | AT11: =AK11-AS11 -> 0.81849269 | AX11: 110 | AY11: 0.16834389 | AZ11: =AY11*20 -> 3.3668778 | BA11: =BA10+AZ11 -> 18.61884 | BB11: =AS11-BA11 -> 0.79861312 | BF11: 110 | BG11: 0 | BH11: =BG11*20 -> 0 | BI11: =BI10+BH11 -> 0 | BJ11: 0 | BN11: 110 | BO11: 0.16108115 | BP11: =BO11*20 -> 3.2216229 | BQ11: =BQ10+BP11 -> 17.430415 | BR11: =BA11-BQ11 -> 1.1884248 | BV11: 110 | BW11: 0 | BX11: =BW11*20 -> 0 | BY11: =BY10+BX11 -> 0 | BZ11: 0 | CD11: 110 | CE11: 0 | CF11: =CE11*20 -> 0 | CG11: =CG10+CF11 -> 0 | CH11: =BY11-CG11 -> 0 | CL11: 110 | CM11: 0 | CN11: =CM11*20 -> 0 | CO11: =CO10+CN11 -> 0 | CP11: =CG11-CO11 -> 0 | CT11: 110 | CU11: 0 | CV11: =CU11*20 -> 0 | CW11: =CW10+CV11 -> 0 | CX11: =CO11-CW11 -> 0 | DB11: 110 | DC11: 0.1672493 | DD11: =DC11*20 -> 3.3449859 | DE11: =DE10+DD11 -> 18.222436 | DF11: =BQ11-DE11 -> -0.79202171 | DJ11: 110 | DK11: 0 | DL11: =DK11*20 -> 0 | DM11: =DM10+DL11 -> 0 | DN11: 0 | DR11: 110 | DS11: 0.1555138 | DT11: =DS11*20 -> 3.110276 | DU11: =DU10+DT11 -> 16.366357 | DV11: =DE11-DU11 -> 1.8560798 | DZ11: 110 | EA11: 0 | EB11: =EA11*20 -> 0 | EC11: =EC10+EB11 -> 0 | ED11: 0 | EH11: 110 | EI11: 0 | EJ11: =EI11*20 -> 0 | EK11: =EK10+EJ11 -> 0 | EL11: =EC463-EK11 -> 0 | EP11: 110 | EQ11: 0.1685746 | ER11: =EQ11*20 -> 3.371492 | ES11: =ES10+ER11 -> 19.97071 | ET11: =DU11-ES11 -> -3.6043537 | EX11: 110 | EY11: 0 | EZ11: =EY11*20 -> 0 | FA11: =FA10+EZ11 -> 0 | FB11: 0 | FF11: 110 | FG11: 0 | FH11: =FG11*20 -> 0 | FI11: =FI10+FH11 -> 0 | FJ11: 0 | FN11: 110 | FO11: 0 | FP11: =FO11*20 -> 0 | FQ11: =FQ10+FP11 -> 0 | FR11: 0 | FV11: 110 | FW11: 0.16188396 | FX11: =FW11*20 -> 3.2376793 | FY11: =FY10+FX11 -> 17.399943 | FZ11: =ES11-FY11 -> 2.5707676 | GD11: 110 | GE11: 0 | GF11: =GE11*20 -> 0 | GG11: =GG10+GF11 -> 0 | GH11: 0 | GL11: 110 | GM11: 0.15697552 | GN11: =GM11*20 -> 3.1395104 | GO11: =GO10+GN11 -> 14.686458 | GP11: =FY11-GO11 -> 2.7134844 | GT11: 110 | GU11: 0 | GV11: =GU11*20 -> 0 | GW11: =GW10+GV11 -> 0 | GX11: 0 | HB11: 110 | HC11: 0.17511241 | HD11: =HC11*20 -> 3.5022482 | HE11: =HE10+HD11 -> 19.748263 | HF11: =GO11-HE11 -> -5.0618043 | HJ11: 110 | HK11: 0 | HL11: =HK11*20 -> 0 | HM11: =HM10+HL11 -> 0 | HN11: 0 | HR11: 110 | HS11: 0.16339026 | HT11: =HS11*20 -> 3.2678053 | HU11: =HU10+HT11 -> 16.741683 | HV11: =HE11-HU11 -> 3.00658 | HZ11: 110 | IA11: 0.14775672 | IB11: =IA11*20 -> 2.9551344 | IC11: =IC10+IB11 -> 14.202539 | ID11: =HU11-IC11 -> 2.5391432 | IH11: 110 | II11: 0 | IJ11: =II11*20 -> 0 | IK11: =IK10+IJ11 -> 0 | IL11: 0 | IP11: 110 | IQ11: 0.1745797 | IR11: =IQ11*20 -> 3.4915939 | IS11: =IS10+IR11 -> 19.959462 | IT11: =IC11-IS11 -> -5.756923
C12: 130 | D12: 0.093 | E12: =D12*20 -> 1.86 | F12: =F11+E12 -> 10.82 | J12: 130 | K12: 0.1847865 | L12: =K12*20 -> 3.6957299 | M12: =M11+L12 -> 22.420411 | N12: =F12-M12 -> -11.600411 | R12: 130 | S12: 0.18490264 | T12: =S12*20 -> 3.6980528 | U12: =U11+T12 -> 21.410703 | V12: =M12-U12 -> 1.0097079 | Z12: 130 | AA12: 0.18346728 | AB12: =AA12*20 -> 3.6693456 | AC12: =AC11+AB12 -> 20.322629 | AD12: =U12-AC12 -> 1.0880731 | AH12: 130 | AI12: 0.20323473 | AJ12: =AI12*20 -> 4.0646946 | AK12: =AK11+AJ12 -> 24.30064 | AL12: =AC12-AK12 -> -3.9780105 | AP12: 130 | AQ12: 0.20396287 | AR12: =AQ12*20 -> 4.0792574 | AS12: =AS11+AR12 -> 23.49671 | AT12: =AK12-AS12 -> 0.80392986 | AX12: 130 | AY12: 0.19710309 | AZ12: =AY12*20 -> 3.9420618 | BA12: =BA11+AZ12 -> 22.560901 | BB12: =AS12-BA12 -> 0.93580874 | BF12: 130 | BG12: 0 | BH12: =BG12*20 -> 0 | BI12: =BI11+BH12 -> 0 | BJ12: 0 | BN12: 130 | BO12: 0.19161341 | BP12: =BO12*20 -> 3.8322681 | BQ12: =BQ11+BP12 -> 21.262683 | BR12: =BA12-BQ12 -> 1.2982185 | BV12: 130 | BW12: 0 | BX12: =BW12*20 -> 0 | BY12: =BY11+BX12 -> 0 | BZ12: 0 | CD12: 130 | CE12: 0 | CF12: =CE12*20 -> 0 | CG12: =CG11+CF12 -> 0 | CH12: =BY12-CG12 -> 0 | CL12: 130 | CM12: 0 | CN12: =CM12*20 -> 0 | CO12: =CO11+CN12 -> 0 | CP12: =CG12-CO12 -> 0 | CT12: 130 | CU12: 0 | CV12: =CU12*20 -> 0 | CW12: =CW11+CV12 -> 0 | CX12: =CO12-CW12 -> 0 | DB12: 130 | DC12: 0.1979117 | DD12: =DC12*20 -> 3.9582339 | DE12: =DE11+DD12 -> 22.18067 | DF12: =BQ12-DE12 -> -0.91798749 | DJ12: 130 | DK12: 0 | DL12: =DK12*20 -> 0 | DM12: =DM11+DL12 -> 0 | DN12: 0 | DR12: 130 | DS12: 0.19219652 | DT12: =DS12*20 -> 3.8439304 | DU12: =DU11+DT12 -> 20.210287 | DV12: =DE12-DU12 -> 1.9703833 | DZ12: 130 | EA12: 0 | EB12: =EA12*20 -> 0 | EC12: =EC11+EB12 -> 0 | ED12: 0 | EH12: 130 | EI12: 0 | EJ12: =EI12*20 -> 0 | EK12: =EK11+EJ12 -> 0 | EL12: =EC464-EK12 -> 0 | EP12: 130 | EQ12: 0.20302247 | ER12: =EQ12*20 -> 4.0604495 | ES12: =ES11+ER12 -> 24.03116 | ET12: =DU12-ES12 -> -3.8208728 | EX12: 130 | EY12: 0 | EZ12: =EY12*20 -> 0 | FA12: =FA11+EZ12 -> 0 | FB12: 0 | FF12: 130 | FG12: 0 | FH12: =FG12*20 -> 0 | FI12: =FI11+FH12 -> 0 | FJ12: 0 | FN12: 130 | FO12: 0 | FP12: =FO12*20 -> 0 | FQ12: =FQ11+FP12 -> 0 | FR12: 0 | FV12: 130 | FW12: 0.19352628 | FX12: =FW12*20 -> 3.8705257 | FY12: =FY11+FX12 -> 21.270468 | FZ12: =ES12-FY12 -> 2.7606914 | GD12: 130 | GE12: 0 | GF12: =GE12*20 -> 0 | GG12: =GG11+GF12 -> 0 | GH12: 0 | GL12: 130 | GM12: 0.19277877 | GN12: =GM12*20 -> 3.8555754 | GO12: =GO11+GN12 -> 18.542034 | GP12: =FY12-GO12 -> 2.7284347 | GT12: 130 | GU12: 0 | GV12: =GU12*20 -> 0 | GW12: =GW11+GV12 -> 0 | GX12: 0 | HB12: 130 | HC12: 0.20309828 | HD12: =HC12*20 -> 4.0619656 | HE12: =HE11+HD12 -> 23.810228 | HF12: =GO12-HE12 -> -5.2681946 | HJ12: 130 | HK12: 0 | HL12: =HK12*20 -> 0 | HM12: =HM11+HL12 -> 0 | HN12: 0 | HR12: 130 | HS12: 0.19781698 | HT12: =HS12*20 -> 3.9563397 | HU12: =HU11+HT12 -> 20.698022 | HV12: =HE12-HU12 -> 3.112206 | HZ12: 130 | IA12: 0.18570463 | IB12: =IA12*20 -> 3.7140925 | IC12: =IC11+IB12 -> 17.916632 | ID12: =HU12-IC12 -> 2.7813904 | IH12: 130 | II12: 0 | IJ12: =II12*20 -> 0 | IK12: =IK11+IJ12 -> 0 | IL12: 0 | IP12: 130 | IQ12: 0.20262145 | IR12: =IQ12*20 -> 4.0524289 | IS12: =IS11+IR12 -> 24.011891 | IT12: =IC12-IS12 -> -6.0952594
C13: 150 | D13: 0.094 | E13: =D13*20 -> 1.88 | F13: =F12+E13 -> 12.7 | J13: 150 | K13: 0.18140273 | L13: =K13*20 -> 3.6280546 | M13: =M12+L13 -> 26.048465 | N13: =F13-M13 -> -13.348465 | R13: 150 | S13: 0.1821122 | T13: =S13*20 -> 3.6422439 | U13: =U12+T13 -> 25.052947 | V13: =M13-U13 -> 0.99551855 | Z13: 150 | AA13: 0.18065896 | AB13: =AA13*20 -> 3.6131792 | AC13: =AC12+AB13 -> 23.935809 | AD13: =U13-AC13 -> 1.1171378 | AH13: 150 | AI13: 0.19502573 | AJ13: =AI13*20 -> 3.9005146 | AK13: =AK12+AJ13 -> 28.201155 | AL13: =AC13-AK13 -> -4.2653459 | AP13: 150 | AQ13: 0.19096414 | AR13: =AQ13*20 -> 3.8192829 | AS13: =AS12+AR13 -> 27.315993 | AT13: =AK13-AS13 -> 0.88516163 | AX13: 150 | AY13: 0.19214461 | AZ13: =AY13*20 -> 3.8428921 | BA13: =BA12+AZ13 -> 26.403794 | BB13: =AS13-BA13 -> 0.91219947 | BF13: 150 | BG13: 0 | BH13: =BG13*20 -> 0 | BI13: =BI12+BH13 -> 0 | BJ13: 0 | BN13: 150 | BO13: 0.18964358 | BP13: =BO13*20 -> 3.7928717 | BQ13: =BQ12+BP13 -> 25.055555 | BR13: =BA13-BQ13 -> 1.348239 | BV13: 150 | BW13: 0 | BX13: =BW13*20 -> 0 | BY13: =BY12+BX13 -> 0 | BZ13: 0 | CD13: 150 | CE13: 0 | CF13: =CE13*20 -> 0 | CG13: =CG12+CF13 -> 0 | CH13: =BY13-CG13 -> 0 | CL13: 150 | CM13: 0 | CN13: =CM13*20 -> 0 | CO13: =CO12+CN13 -> 0 | CP13: =CG13-CO13 -> 0 | CT13: 150 | CU13: 0 | CV13: =CU13*20 -> 0 | CW13: =CW12+CV13 -> 0 | CX13: =CO13-CW13 -> 0 | DB13: 150 | DC13: 0.19484546 | DD13: =DC13*20 -> 3.8969091 | DE13: =DE12+DD13 -> 26.07758 | DF13: =BQ13-DE13 -> -1.0220249 | DJ13: 150 | DK13: 0 | DL13: =DK13*20 -> 0 | DM13: =DM12+DL13 -> 0 | DN13: 0 | DR13: 150 | DS13: 0.18447384 | DT13: =DS13*20 -> 3.6894769 | DU13: =DU12+DT13 -> 23.899764 | DV13: =DE13-DU13 -> 2.1778156 | DZ13: 150 | EA13: 0 | EB13: =EA13*20 -> 0 | EC13: =EC12+EB13 -> 0 | ED13: 0 | EH13: 150 | EI13: 0 | EJ13: =EI13*20 -> 0 | EK13: =EK12+EJ13 -> 0 | EL13: =EC465-EK13 -> 0 | EP13: 150 | EQ13: 0.19896978 | ER13: =EQ13*20 -> 3.9793957 | ES13: =ES12+ER13 -> 28.010556 | ET13: =DU13-ES13 -> -4.1107915 | EX13: 150 | EY13: 0 | EZ13: =EY13*20 -> 0 | FA13: =FA12+EZ13 -> 0 | FB13: 0 | FF13: 150 | FG13: 0 | FH13: =FG13*20 -> 0 | FI13: =FI12+FH13 -> 0 | FJ13: 0 | FN13: 150 | FO13: 0 | FP13: =FO13*20 -> 0 | FQ13: =FQ12+FP13 -> 0 | FR13: 0 | FV13: 150 | FW13: 0.19250556 | FX13: =FW13*20 -> 3.8501113 | FY13: =FY12+FX13 -> 25.12058 | FZ13: =ES13-FY13 -> 2.8899758 | GD13: 150 | GE13: 0 | GF13: =GE13*20 -> 0 | GG13: =GG12+GF13 -> 0 | GH13: 0 | GL13: 150 | GM13: 0.18681156 | GN13: =GM13*20 -> 3.7362312 | GO13: =GO12+GN13 -> 22.278265 | GP13: =FY13-GO13 -> 2.8423148 | GT13: 150 | GU13: 0 | GV13: =GU13*20 -> 0 | GW13: =GW12+GV13 -> 0 | GX13: 0 | HB13: 150 | HC13: 0.20102525 | HD13: =HC13*20 -> 4.0205051 | HE13: =HE12+HD13 -> 27.830733 | HF13: =GO13-HE13 -> -5.5524685 | HJ13: 150 | HK13: 0 | HL13: =HK13*20 -> 0 | HM13: =HM12+HL13 -> 0 | HN13: 0 | HR13: 150 | HS13: 0.19781698 | HT13: =HS13*20 -> 3.9563397 | HU13: =HU12+HT13 -> 24.654362 | HV13: =HE13-HU13 -> 3.1763714 | HZ13: 150 | IA13: 0.1916964 | IB13: =IA13*20 -> 3.833928 | IC13: =IC12+IB13 -> 21.75056 | ID13: =HU13-IC13 -> 2.9038021 | IH13: 150 | II13: 0 | IJ13: =II13*20 -> 0 | IK13: =IK12+IJ13 -> 0 | IL13: 0 | IP13: 150 | IQ13: 0.20158286 | IR13: =IQ13*20 -> 4.0316573 | IS13: =IS12+IR13 -> 28.043549 | IT13: =IC13-IS13 -> -6.2929887
C14: 170 | D14: 0.101 | E14: =D14*20 -> 2.02 | F14: =F13+E14 -> 14.72 | J14: 170 | K14: 0.19155541 | L14: =K14*20 -> 3.8311082 | M14: =M13+L14 -> 29.879573 | N14: =F14-M14 -> -15.159573 | R14: 170 | S14: 0.19420412 | T14: =S14*20 -> 3.8840824 | U14: =U13+T14 -> 28.937029 | V14: =M14-U14 -> 0.9425443 | Z14: 170 | AA14: 0.19657276 | AB14: =AA14*20 -> 3.9314552 | AC14: =AC13+AB14 -> 27.867264 | AD14: =U14-AC14 -> 1.0697651 | AH14: 170 | AI14: 0.20918955 | AJ14: =AI14*20 -> 4.1837911 | AK14: =AK13+AJ14 -> 32.384946 | AL14: =AC14-AK14 -> -4.5176818 | AP14: 170 | AQ14: 0.21396128 | AR14: =AQ14*20 -> 4.2792256 | AS14: =AS13+AR14 -> 31.595219 | AT14: =AK14-AS14 -> 0.78972709 | AX14: 170 | AY14: 0.21098684 | AZ14: =AY14*20 -> 4.2197368 | BA14: =BA13+AZ14 -> 30.62353 | BB14: =AS14-BA14 -> 0.97168823 | BF14: 170 | BG14: 0 | BH14: =BG14*20 -> 0 | BI14: =BI13+BH14 -> 0 | BJ14: 0 | BN14: 170 | BO14: 0.20638708 | BP14: =BO14*20 -> 4.1277416 | BQ14: =BQ13+BP14 -> 29.183296 | BR14: =BA14-BQ14 -> 1.4402342 | BV14: 170 | BW14: 0 | BX14: =BW14*20 -> 0 | BY14: =BY13+BX14 -> 0 | BZ14: 0 | CD14: 170 | CE14: 0 | CF14: =CE14*20 -> 0 | CG14: =CG13+CF14 -> 0 | CH14: =BY14-CG14 -> 0 | CL14: 170 | CM14: 0 | CN14: =CM14*20 -> 0 | CO14: =CO13+CN14 -> 0 | CP14: =CG14-CO14 -> 0 | CT14: 170 | CU14: 0 | CV14: =CU14*20 -> 0 | CW14: =CW13+CV14 -> 0 | CX14: =CO14-CW14 -> 0 | DB14: 170 | DC14: 0.20608834 | DD14: =DC14*20 -> 4.1217667 | DE14: =DE13+DD14 -> 30.199346 | DF14: =BQ14-DE14 -> -1.0160501 | DJ14: 170 | DK14: 0 | DL14: =DK14*20 -> 0 | DM14: =DM13+DL14 -> 0 | DN14: 0 | DR14: 170 | DS14: 0.1999192 | DT14: =DS14*20 -> 3.998384 | DU14: =DU13+DT14 -> 27.898148 | DV14: =DE14-DU14 -> 2.3011983 | DZ14: 170 | EA14: 0 | EB14: =EA14*20 -> 0 | EC14: =EC13+EB14 -> 0 | ED14: 0 | EH14: 170 | EI14: 0 | EJ14: =EI14*20 -> 0 | EK14: =EK13+EJ14 -> 0 | EL14: =EC466-EK14 -> 0 | EP14: 170 | EQ14: 0.21112786 | ER14: =EQ14*20 -> 4.2225571 | ES14: =ES13+ER14 -> 32.233113 | ET14: =DU14-ES14 -> -4.3349646 | EX14: 170 | EY14: 0 | EZ14: =EY14*20 -> 0 | FA14: =FA13+EZ14 -> 0 | FB14: 0 | FF14: 170 | FG14: 0 | FH14: =FG14*20 -> 0 | FI14: =FI13+FH14 -> 0 | FJ14: 0 | FN14: 170 | FO14: 0 | FP14: =FO14*20 -> 0 | FQ14: =FQ13+FP14 -> 0 | FR14: 0 | FV14: 170 | FW14: 0.20883708 | FX14: =FW14*20 -> 4.1767417 | FY14: =FY13+FX14 -> 29.297321 | FZ14: =ES14-FY14 -> 2.9357913 | GD14: 170 | GE14: 0 | GF14: =GE14*20 -> 0 | GG14: =GG13+GF14 -> 0 | GH14: 0 | GL14: 170 | GM14: 0.20471318 | GN14: =GM14*20 -> 4.0942637 | GO14: =GO13+GN14 -> 26.372529 | GP14: =FY14-GO14 -> 2.9247928 | GT14: 170 | GU14: 0 | GV14: =GU14*20 -> 0 | GW14: =GW13+GV14 -> 0 | GX14: 0 | HB14: 170 | HC14: 0.21657296 | HD14: =HC14*20 -> 4.3314592 | HE14: =HE13+HD14 -> 32.162193 | HF14: =GO14-HE14 -> -5.789664 | HJ14: 170 | HK14: 0 | HL14: =HK14*20 -> 0 | HM14: =HM13+HL14 -> 0 | HN14: 0 | HR14: 170 | HS14: 0.21503034 | HT14: =HS14*20 -> 4.3006069 | HU14: =HU13+HT14 -> 28.954969 | HV14: =HE14-HU14 -> 3.2072237 | HZ14: 170 | IA14: 0.20467858 | IB14: =IA14*20 -> 4.0935715 | IC14: =IC13+IB14 -> 25.844131 | ID14: =HU14-IC14 -> 3.1108375 | IH14: 170 | II14: 0 | IJ14: =II14*20 -> 0 | IK14: =IK13+IJ14 -> 0 | IL14: 0 | IP14: 170 | IQ14: 0.21716161 | IR14: =IQ14*20 -> 4.3432323 | IS14: =IS13+IR14 -> 32.386781 | IT14: =IC14-IS14 -> -6.5426494
C15: 190 | D15: 0.094 | E15: =D15*20 -> 1.88 | F15: =F14+E15 -> 16.6 | J15: 190 | K15: 0.17863382 | L15: =K15*20 -> 3.5726763 | M15: =M14+L15 -> 33.45225 | N15: =F15-M15 -> -16.85225 | R15: 190 | S15: 0.18490264 | T15: =S15*20 -> 3.6980528 | U15: =U14+T15 -> 32.635082 | V15: =M15-U15 -> 0.81716779 | Z15: 190 | AA15: 0.18346728 | AB15: =AA15*20 -> 3.6693456 | AC15: =AC14+AB15 -> 31.536609 | AD15: =U15-AC15 -> 1.0984723 | AH15: 190 | AI15: 0.19929496 | AJ15: =AI15*20 -> 3.9858993 | AK15: =AK14+AJ15 -> 36.370845 | AL15: =AC15-AK15 -> -4.8342355 | AP15: 190 | AQ15: 0.19796383 | AR15: =AQ15*20 -> 3.9592765 | AS15: =AS14+AR15 -> 35.554495 | AT15: =AK15-AS15 -> 0.81634988 | AX15: 190 | AY15: 0.1951197 | AZ15: =AY15*20 -> 3.9023939 | BA15: =BA14+AZ15 -> 34.525924 | BB15: =AS15-BA15 -> 1.0285708 | BF15: 190 | BG15: 0 | BH15: =BG15*20 -> 0 | BI15: =BI14+BH15 -> 0 | BJ15: 0 | BN15: 190 | BO15: 0.18668885 | BP15: =BO15*20 -> 3.733777 | BQ15: =BQ14+BP15 -> 32.917073 | BR15: =BA15-BQ15 -> 1.6088511 | BV15: 190 | BW15: 0 | BX15: =BW15*20 -> 0 | BY15: =BY14+BX15 -> 0 | BZ15: 0 | CD15: 190 | CE15: 0 | CF15: =CE15*20 -> 0 | CG15: =CG14+CF15 -> 0 | CH15: =BY15-CG15 -> 0 | CL15: 190 | CM15: 0 | CN15: =CM15*20 -> 0 | CO15: =CO14+CN15 -> 0 | CP15: =CG15-CO15 -> 0 | CT15: 190 | CU15: 0 | CV15: =CU15*20 -> 0 | CW15: =CW14+CV15 -> 0 | CX15: =CO15-CW15 -> 0 | DB15: 190 | DC15: 0.19075714 | DD15: =DC15*20 -> 3.8151427 | DE15: =DE14+DD15 -> 34.014489 | DF15: =BQ15-DE15 -> -1.0974158 | DJ15: 190 | DK15: 0 | DL15: =DK15*20 -> 0 | DM15: =DM14+DL15 -> 0 | DN15: 0 | DR15: 190 | DS15: 0.18157784 | DT15: =DS15*20 -> 3.6315568 | DU15: =DU14+DT15 -> 31.529705 | DV15: =DE15-DU15 -> 2.4847842 | DZ15: 190 | EA15: 0 | EB15: =EA15*20 -> 0 | EC15: =EC14+EB15 -> 0 | ED15: 0 | EH15: 190 | EI15: 0 | EJ15: =EI15*20 -> 0 | EK15: =EK14+EJ15 -> 0 | EL15: =EC467-EK15 -> 0 | EP15: 190 | EQ15: 0.19187757 | ER15: =EQ15*20 -> 3.8375515 | ES15: =ES14+ER15 -> 36.070664 | ET15: =DU15-ES15 -> -4.5409593 | EX15: 190 | EY15: 0 | EZ15: =EY15*20 -> 0 | FA15: =FA14+EZ15 -> 0 | FB15: 0 | FF15: 190 | FG15: 0 | FH15: =FG15*20 -> 0 | FI15: =FI14+FH15 -> 0 | FJ15: 0 | FN15: 190 | FO15: 0 | FP15: =FO15*20 -> 0 | FQ15: =FQ14+FP15 -> 0 | FR15: 0 | FV15: 190 | FW15: 0.19046412 | FX15: =FW15*20 -> 3.8092825 | FY15: =FY14+FX15 -> 33.106604 | FZ15: =ES15-FY15 -> 2.9640603 | GD15: 190 | GE15: 0 | GF15: =GE15*20 -> 0 | GG15: =GG14+GF15 -> 0 | GH15: 0 | GL15: 190 | GM15: 0.18482249 | GN15: =GM15*20 -> 3.6964498 | GO15: =GO14+GN15 -> 30.068978 | GP15: =FY15-GO15 -> 3.0376255 | GT15: 190 | GU15: 0 | GV15: =GU15*20 -> 0 | GW15: =GW14+GV15 -> 0 | GX15: 0 | HB15: 190 | HC15: 0.19769658 | HD15: =HC15*20 -> 3.9539316 | HE15: =HE14+HD15 -> 36.116124 | HF15: =GO15-HE15 -> -6.0471457 | HJ15: 190 | HK15: 0 | HL15: =HK15*20 -> 0 | HM15: =HM14+HL15 -> 0 | HN15: 0 | HR15: 190 | HS15: 0.19072913 | HT15: =HS15*20 -> 3.8145826 | HU15: =HU14+HT15 -> 32.769551 | HV15: =HE15-HU15 -> 3.3465727 | HZ15: 190 | IA15: 0.19068406 | IB15: =IA15*20 -> 3.8136812 | IC15: =IC14+IB15 -> 29.657813 | ID15: =HU15-IC15 -> 3.1117388 | IH15: 190 | II15: 0 | IJ15: =II15*20 -> 0 | IK15: =IK14+IJ15 -> 0 | IL15: 0 | IP15: 190 | IQ15: 0.2057372 | IR15: =IQ15*20 -> 4.1147439 | IS15: =IS14+IR15 -> 36.501525 | IT15: =IC15-IS15 -> -6.8437121
C16: 210 | D16: 0.095 | E16: =D16*20 -> 1.9 | F16: =F15+E16 -> 18.5 | J16: 210 | K16: 0.1537136 | L16: =K16*20 -> 3.074272 | M16: =M15+L16 -> 36.526522 | N16: =F16-M16 -> -18.026522 | R16: 210 | S16: 0.1551379 | T16: =S16*20 -> 3.102758 | U16: =U15+T16 -> 35.73784 | V16: =M16-U16 -> 0.78868174 | Z16: 210 | AA16: 0.16193684 | AB16: =AA16*20 -> 3.2387369 | AC16: =AC15+AB16 -> 34.775346 | AD16: =U16-AC16 -> 0.96249346 | AH16: 210 | AI16: 0.1724832 | AJ16: =AI16*20 -> 3.449664 | AK16: =AK15+AJ16 -> 39.820509 | AL16: =AC16-AK16 -> -5.0451627 | AP16: 210 | AQ16: 0.17096812 | AR16: =AQ16*20 -> 3.4193624 | AS16: =AS15+AR16 -> 38.973857 | AT16: =AK16-AS16 -> 0.84665149 | AX16: 210 | AY16: 0.1653688 | AZ16: =AY16*20 -> 3.307376 | BA16: =BA15+AZ16 -> 37.8333 | BB16: =AS16-BA16 -> 1.1405572 | BF16: 210 | BG16: 0 | BH16: =BG16*20 -> 0 | BI16: =BI15+BH16 -> 0 | BJ16: 0 | BN16: 210 | BO16: 0.16600571 | BP16: =BO16*20 -> 3.3201141 | BQ16: =BQ15+BP16 -> 36.237187 | BR16: =BA16-BQ16 -> 1.596113 | BV16: 210 | BW16: 0 | BX16: =BW16*20 -> 0 | BY16: =BY15+BX16 -> 0 | BZ16: 0 | CD16: 210 | CE16: 0 | CF16: =CE16*20 -> 0 | CG16: =CG15+CF16 -> 0 | CH16: =BY16-CG16 -> 0 | CL16: 210 | CM16: 0 | CN16: =CM16*20 -> 0 | CO16: =CO15+CN16 -> 0 | CP16: =CG16-CO16 -> 0 | CT16: 210 | CU16: 0 | CV16: =CU16*20 -> 0 | CW16: =CW15+CV16 -> 0 | CX16: =CO16-CW16 -> 0 | DB16: 210 | DC16: 0.16520514 | DD16: =DC16*20 -> 3.3041027 | DE16: =DE15+DD16 -> 37.318592 | DF16: =BQ16-DE16 -> -1.0814044 | DJ16: 210 | DK16: 0 | DL16: =DK16*20 -> 0 | DM16: =DM15+DL16 -> 0 | DN16: 0 | DR16: 210 | DS16: 0.15937514 | DT16: =DS16*20 -> 3.1875028 | DU16: =DU15+DT16 -> 34.717208 | DV16: =DE16-DU16 -> 2.6013842 | DZ16: 210 | EA16: 0 | EB16: =EA16*20 -> 0 | EC16: =EC15+EB16 -> 0 | ED16: 0 | EH16: 210 | EI16: 0 | EJ16: =EI16*20 -> 0 | EK16: =EK15+EJ16 -> 0 | EL16: =EC468-EK16 -> 0 | EP16: 210 | EQ16: 0.17060095 | ER16: =EQ16*20 -> 3.412019 | ES16: =ES15+ER16 -> 39.482683 | ET16: =DU16-ES16 -> -4.7654755 | EX16: 210 | EY16: 0 | EZ16: =EY16*20 -> 0 | FA16: =FA15+EZ16 -> 0 | FB16: 0 | FF16: 210 | FG16: 0 | FH16: =FG16*20 -> 0 | FI16: =FI15+FH16 -> 0 | FJ16: 0 | FN16: 210 | FO16: 0 | FP16: =FO16*20 -> 0 | FQ16: =FQ15+FP16 -> 0 | FR16: 0 | FV16: 210 | FW16: 0.16596684 | FX16: =FW16*20 -> 3.3193369 | FY16: =FY15+FX16 -> 36.425941 | FZ16: =ES16-FY16 -> 3.0567423 | GD16: 210 | GE16: 0 | GF16: =GE16*20 -> 0 | GG16: =GG15+GF16 -> 0 | GH16: 0 | GL16: 210 | GM16: 0.16194819 | GN16: =GM16*20 -> 3.2389639 | GO16: =GO15+GN16 -> 33.307942 | GP16: =FY16-GO16 -> 3.1179985 | GT16: 210 | GU16: 0 | GV16: =GU16*20 -> 0 | GW16: =GW15+GV16 -> 0 | GX16: 0 | HB16: 210 | HC16: 0.17758977 | HD16: =HC16*20 -> 3.5517954 | HE16: =HE15+HD16 -> 39.66792 | HF16: =GO16-HE16 -> -6.3599773 | HJ16: 210 | HK16: 0 | HL16: =HK16*20 -> 0 | HM16: =HM15+HL16 -> 0 | HN16: 0 | HR16: 210 | HS16: 0.17149067 | HT16: =HS16*20 -> 3.4298134 | HU16: =HU15+HT16 -> 36.199365 | HV16: =HE16-HU16 -> 3.4685547 | HZ16: 210 | IA16: 0.16373479 | IB16: =IA16*20 -> 3.2746957 | IC16: =IC15+IB16 -> 32.932508 | ID16: =HU16-IC16 -> 3.2668565 | IH16: 210 | II16: 0 | IJ16: =II16*20 -> 0 | IK16: =IK15+IJ16 -> 0 | IL16: 0 | IP16: 210 | IQ16: 0.1795797 | IR16: =IQ16*20 -> 3.5915939 | IS16: =IS15+IR16 -> 40.093119 | IT16: =IC16-IS16 -> -7.1606103
C17: 230 | D17: 0.145 | E17: =D17*20 -> 2.9 | F17: =F16+E17 -> 21.4 | J17: 230 | K17: 0.16109737 | L17: =K17*20 -> 3.2219473 | M17: =M16+L17 -> 39.748469 | N17: =F17-M17 -> -18.348469 | R17: 230 | S17: 0.17002027 | T17: =S17*20 -> 3.4004054 | U17: =U16+T17 -> 39.138245 | V17: =M17-U17 -> 0.61022366 | Z17: 230 | AA17: 0.17410622 | AB17: =AA17*20 -> 3.4821244 | AC17: =AC16+AB17 -> 38.257471 | AD17: =U17-AC17 -> 0.88077449 | AH17: 230 | AI17: 0.18537026 | AJ17: =AI17*20 -> 3.7074052 | AK17: =AK16+AJ17 -> 43.527914 | AL17: =AC17-AK17 -> -5.2704435 | AP17: 230 | AQ17: 0.1899651 | AR17: =AQ17*20 -> 3.7993019 | AS17: =AS16+AR17 -> 42.773159 | AT17: =AK17-AS17 -> 0.75475472 | AX17: 230 | AY17: 0.18817782 | AZ17: =AY17*20 -> 3.7635564 | BA17: =BA16+AZ17 -> 41.596857 | BB17: =AS17-BA17 -> 1.1763028 | BF17: 230 | BG17: 0 | BH17: =BG17*20 -> 0 | BI17: =BI16+BH17 -> 0 | BJ17: 0 | BN17: 230 | BO17: 0.1827492 | BP17: =BO17*20 -> 3.654984 | BQ17: =BQ16+BP17 -> 39.892171 | BR17: =BA17-BQ17 -> 1.7046854 | BV17: 230 | BW17: 0 | BX17: =BW17*20 -> 0 | BY17: =BY16+BX17 -> 0 | BZ17: 0 | CD17: 230 | CE17: 0 | CF17: =CE17*20 -> 0 | CG17: =CG16+CF17 -> 0 | CH17: =BY17-CG17 -> 0 | CL17: 230 | CM17: 0 | CN17: =CM17*20 -> 0 | CO17: =CO16+CN17 -> 0 | CP17: =CG17-CO17 -> 0 | CT17: 230 | CU17: 0 | CV17: =CU17*20 -> 0 | CW17: =CW16+CV17 -> 0 | CX17: =CO17-CW17 -> 0 | DB17: 230 | DC17: 0.1876909 | DD17: =DC17*20 -> 3.7538179 | DE17: =DE16+DD17 -> 41.07241 | DF17: =BQ17-DE17 -> -1.1802383 | DJ17: 230 | DK17: 0 | DL17: =DK17*20 -> 0 | DM17: =DM16+DL17 -> 0 | DN17: 0 | DR17: 230 | DS17: 0.1777165 | DT17: =DS17*20 -> 3.55433 | DU17: =DU16+DT17 -> 38.271538 | DV17: =DE17-DU17 -> 2.8008721 | DZ17: 230 | EA17: 0 | EB17: =EA17*20 -> 0 | EC17: =EC16+EB17 -> 0 | ED17: 0 | EH17: 230 | EI17: 0 | EJ17: =EI17*20 -> 0 | EK17: =EK16+EJ17 -> 0 | EL17: =EC469-EK17 -> 0 | EP17: 230 | EQ17: 0.18745847 | ER17: =EQ17*20 -> 3.7491695 | ES17: =ES16+ER17 -> 43.231853 | ET17: =DU17-ES17 -> -4.960315 | EX17: 230 | EY17: 0 | EZ17: =EY17*20 -> 0 | FA17: =FA16+EZ17 -> 0 | FB17: 0 | FF17: 230 | FG17: 0 | FH17: =FG17*20 -> 0 | FI17: =FI16+FH17 -> 0 | FJ17: 0 | FN17: 230 | FO17: 0 | FP17: =FO17*20 -> 0 | FQ17: =FQ16+FP17 -> 0 | FR17: 0 | FV17: 230 | FW17: 0.18740196 | FX17: =FW17*20 -> 3.7480393 | FY17: =FY16+FX17 -> 40.17398 | FZ17: =ES17-FY17 -> 3.0578725 | GD17: 230 | GE17: 0 | GF17: =GE17*20 -> 0 | GG17: =GG16+GF17 -> 0 | GH17: 0 | GL17: 230 | GM17: 0.18283342 | GN17: =GM17*20 -> 3.6566684 | GO17: =GO16+GN17 -> 36.964611 | GP17: =FY17-GO17 -> 3.2093693 | GT17: 230 | GU17: 0 | GV17: =GU17*20 -> 0 | GW17: =GW16+GV17 -> 0 | GX17: 0 | HB17: 230 | HC17: 0.19973314 | HD17: =HC17*20 -> 3.9946629 | HE17: =HE16+HD17 -> 43.662582 | HF17: =GO17-HE17 -> -6.6979717 | HJ17: 230 | HK17: 0 | HL17: =HK17*20 -> 0 | HM17: =HM16+HL17 -> 0 | HN17: 0 | HR17: 230 | HS17: 0.19174168 | HT17: =HS17*20 -> 3.8348336 | HU17: =HU16+HT17 -> 40.034198 | HV17: =HE17-HU17 -> 3.628384 | HZ17: 230 | IA17: 0.17871422 | IB17: =IA17*20 -> 3.5742844 | IC17: =IC16+IB17 -> 36.506793 | ID17: =HU17-IC17 -> 3.5274056 | IH17: 230 | II17: 0 | IJ17: =II17*20 -> 0 | IK17: =IK16+IJ17 -> 0 | IL17: 0 | IP17: 230 | IQ17: 0.18496553 | IR17: =IQ17*20 -> 3.6993106 | IS17: =IS16+IR17 -> 43.792429 | IT17: =IC17-IS17 -> -7.2856364
C18: 250 | D18: 0.197 | E18: =D18*20 -> 3.94 | F18: =F17+E18 -> 25.34 | J18: 250 | K18: 0.21980162 | L18: =K18*20 -> 4.3960324 | M18: =M17+L18 -> 44.144501 | N18: =F18-M18 -> -18.804501 | R18: 250 | S18: 0.22117842 | T18: =S18*20 -> 4.4235684 | U18: =U17+T18 -> 43.561814 | V18: =M18-U18 -> 0.5826877 | Z18: 250 | AA18: 0.22559204 | AB18: =AA18*20 -> 4.5118408 | AC18: =AC17+AB18 -> 42.769312 | AD18: =U18-AC18 -> 0.79250202 | AH18: 250 | AI18: 0.23598626 | AJ18: =AI18*20 -> 4.7197252 | AK18: =AK17+AJ18 -> 48.247639 | AL18: =AC18-AK18 -> -5.4783278 | AP18: 250 | AQ18: 0.24295667 | AR18: =AQ18*20 -> 4.8591334 | AS18: =AS17+AR18 -> 47.632293 | AT18: =AK18-AS18 -> 0.61534654 | AX18: 250 | AY18: 0.24073774 | AZ18: =AY18*20 -> 4.8147548 | BA18: =BA17+AZ18 -> 46.411611 | BB18: =AS18-BA18 -> 1.2206813 | BF18: 250 | BG18: 0 | BH18: =BG18*20 -> 0 | BI18: =BI17+BH18 -> 0 | BJ18: 0 | BN18: 250 | BO18: 0.23790425 | BP18: =BO18*20 -> 4.758085 | BQ18: =BQ17+BP18 -> 44.650256 | BR18: =BA18-BQ18 -> 1.7613552 | BV18: 250 | BW18: 0 | BX18: =BW18*20 -> 0 | BY18: =BY17+BX18 -> 0 | BZ18: 0 | CD18: 250 | CE18: 0 | CF18: =CE18*20 -> 0 | CG18: =CG17+CF18 -> 0 | CH18: =BY18-CG18 -> 0 | CL18: 250 | CM18: 0 | CN18: =CM18*20 -> 0 | CO18: =CO17+CN18 -> 0 | CP18: =CG18-CO18 -> 0 | CT18: 250 | CU18: 0 | CV18: =CU18*20 -> 0 | CW18: =CW17+CV18 -> 0 | CX18: =CO18-CW18 -> 0 | DB18: 250 | DC18: 0.2387949 | DD18: =DC18*20 -> 4.7758979 | DE18: =DE17+DD18 -> 45.848308 | DF18: =BQ18-DE18 -> -1.1980512 | DJ18: 250 | DK18: 0 | DL18: =DK18*20 -> 0 | DM18: =DM17+DL18 -> 0 | DN18: 0 | DR18: 250 | DS18: 0.23370592 | DT18: =DS18*20 -> 4.6741184 | DU18: =DU17+DT18 -> 42.945656 | DV18: =DE18-DU18 -> 2.9026516 | DZ18: 250 | EA18: 0 | EB18: =EA18*20 -> 0 | EC18: =EC17+EB18 -> 0 | ED18: 0 | EH18: 250 | EI18: 0 | EJ18: =EI18*20 -> 0 | EK18: =EK17+EJ18 -> 0 | EL18: =EC470-EK18 -> 0 | EP18: 250 | EQ18: 0.24152304 | ER18: =EQ18*20 -> 4.8304607 | ES18: =ES17+ER18 -> 48.062313 | ET18: =DU18-ES18 -> -5.1166573 | EX18: 250 | EY18: 0 | EZ18: =EY18*20 -> 0 | FA18: =FA17+EZ18 -> 0 | FB18: 0 | FF18: 250 | FG18: 0 | FH18: =FG18*20 -> 0 | FI18: =FI17+FH18 -> 0 | FJ18: 0 | FN18: 250 | FO18: 0 | FP18: =FO18*20 -> 0 | FQ18: =FQ17+FP18 -> 0 | FR18: 0 | FV18: 250 | FW18: 0.23741724 | FX18: =FW18*20 -> 4.7483449 | FY18: =FY17+FX18 -> 44.922325 | FZ18: =ES18-FY18 -> 3.1399884 | GD18: 250 | GE18: 0 | GF18: =GE18*20 -> 0 | GG18: =GG17+GF18 -> 0 | GH18: 0 | GL18: 250 | GM18: 0.23053283 | GN18: =GM18*20 -> 4.6106566 | GO18: =GO17+GN18 -> 41.575267 | GP18: =FY18-GO18 -> 3.3470576 | GT18: 250 | GU18: 0 | GV18: =GU18*20 -> 0 | GW18: =GW17+GV18 -> 0 | GX18: 0 | HB18: 250 | HC18: 0.24652232 | HD18: =HC18*20 -> 4.9304463 | HE18: =HE17+HD18 -> 48.593029 | HF18: =GO18-HE18 -> -7.0177615 | HJ18: 250 | HK18: 0 | HL18: =HK18*20 -> 0 | HM18: =HM17+HL18 -> 0 | HN18: 0 | HR18: 250 | HS18: 0.24135666 | HT18: =HS18*20 -> 4.8271332 | HU18: =HU17+HT18 -> 44.861332 | HV18: =HE18-HU18 -> 3.7316971 | HZ18: 250 | IA18: 0.23763333 | IB18: =IA18*20 -> 4.7526667 | IC18: =IC17+IB18 -> 41.259459 | ID18: =HU18-IC18 -> 3.6018721 | IH18: 250 | II18: 0 | IJ18: =II18*20 -> 0 | IK18: =IK17+IJ18 -> 0 | IL18: 0 | IP18: 250 | IQ18: 0.24624195 | IR18: =IQ18*20 -> 4.9248389 | IS18: =IS17+IR18 -> 48.717268 | IT18: =IC18-IS18 -> -7.4578086
